Workbook

Sheet Combined P&L
A1: Keystone Bookkeepers
A2: Combined Monthly Income Statement ($000s) — Jan 2024 through Jul 2026
A3: Source: Target-provided QuickBooks Online P&L exports — Keystone P&L 2024.xlsx, Keystone P&L 2025.xlsx, Keystone P&L 2026.xlsx (accrual basis). All figures on this tab are live formulas linking to the "Raw - 20XX PL" tabs (each detail cell = raw cell / 1,000; every subtotal and FY total is a SUM/difference formula, never a hardcoded number), so this tab recalculates automatically if the raw tabs are updated. Values are in $000s. FY2026 reflects Jan–Jul only (YTD, 7 months) as that is the period the target has reported to date. Blank monthly cells indicate the account did not yet exist in the chart of accounts for that period (treated as $0 in subtotals). See the Tie-Out / Check section at the bottom of this tab, which foots every FY total back to each Raw tab's own reported Total column.
A6: Line Item | B6: FY2024 ($000s) | C6: FY2025 ($000s) | D6: FY2026 YTD (7 mo., $000s) | F6: 45292 | G6: 45323 | H6: 45352 | I6: 45383 | J6: 45413 | K6: 45444 | L6: 45474 | M6: 45505 | N6: 45536 | O6: 45566 | P6: 45597 | Q6: 45627 | R6: 45658 | S6: 45689 | T6: 45717 | U6: 45748 | V6: 45778 | W6: 45809 | X6: 45839 | Y6: 45870 | Z6: 45901 | AA6: 45931 | AB6: 45962 | AC6: 45992 | AD6: 46023 | AE6: 46054 | AF6: 46082 | AG6: 46113 | AH6: 46143 | AI6: 46174 | AJ6: 46204
A7: Income
A8: Income Tax Revenue | B8: =SUM(F8:Q8) -> 0 | C8: =SUM(R8:AC8) -> 0 | D8: =SUM(AD8:AJ8) -> 0 | R8: ='Raw - 2025 PL'!B7/1000 -> 0 | S8: ='Raw - 2025 PL'!C7/1000 -> 0 | T8: ='Raw - 2025 PL'!D7/1000 -> 0 | U8: ='Raw - 2025 PL'!E7/1000 -> 0 | V8: ='Raw - 2025 PL'!F7/1000 -> 0 | W8: ='Raw - 2025 PL'!G7/1000 -> 0 | X8: ='Raw - 2025 PL'!H7/1000 -> 0 | Y8: ='Raw - 2025 PL'!I7/1000 -> 0 | ... AC8: ='Raw - 2025 PL'!M7/1000 -> 0 | AD8: ='Raw - 2026 PL'!B7/1000 -> 0 | AE8: ='Raw - 2026 PL'!C7/1000 -> 0 | AF8: ='Raw - 2026 PL'!D7/1000 -> 0 | AG8: ='Raw - 2026 PL'!E7/1000 -> 0 | AH8: ='Raw - 2026 PL'!F7/1000 -> 0 | AI8: ='Raw - 2026 PL'!G7/1000 -> 0 | AJ8: ='Raw - 2026 PL'!H7/1000 -> 0
A9: Business Income Tax | B9: =SUM(F9:Q9) -> 0 | C9: =SUM(R9:AC9) -> 1.75 | D9: =SUM(AD9:AJ9) -> 21.59 | R9: ='Raw - 2025 PL'!B8/1000 -> 0 | S9: ='Raw - 2025 PL'!C8/1000 -> 0 | T9: ='Raw - 2025 PL'!D8/1000 -> 0 | U9: ='Raw - 2025 PL'!E8/1000 -> 0 | V9: ='Raw - 2025 PL'!F8/1000 -> 0 | W9: ='Raw - 2025 PL'!G8/1000 -> 0 | X9: ='Raw - 2025 PL'!H8/1000 -> 0 | Y9: ='Raw - 2025 PL'!I8/1000 -> 0 | ... AC9: ='Raw - 2025 PL'!M8/1000 -> 0.875 | AD9: ='Raw - 2026 PL'!B8/1000 -> 0 | AE9: ='Raw - 2026 PL'!C8/1000 -> 0 | AF9: ='Raw - 2026 PL'!D8/1000 -> 14.19 | AG9: ='Raw - 2026 PL'!E8/1000 -> 4.3 | AH9: ='Raw - 2026 PL'!F8/1000 -> 0 | AI9: ='Raw - 2026 PL'!G8/1000 -> 3.1 | AJ9: ='Raw - 2026 PL'!H8/1000 -> 0
A10: Individual Income Tax | B10: =SUM(F10:Q10) -> 0 | C10: =SUM(R10:AC10) -> 1.65 | D10: =SUM(AD10:AJ10) -> 2.325 | R10: ='Raw - 2025 PL'!B9/1000 -> 0 | S10: ='Raw - 2025 PL'!C9/1000 -> 0 | T10: ='Raw - 2025 PL'!D9/1000 -> 0 | U10: ='Raw - 2025 PL'!E9/1000 -> 0 | V10: ='Raw - 2025 PL'!F9/1000 -> 0 | W10: ='Raw - 2025 PL'!G9/1000 -> 0 | X10: ='Raw - 2025 PL'!H9/1000 -> 0 | Y10: ='Raw - 2025 PL'!I9/1000 -> 0 | ... AC10: ='Raw - 2025 PL'!M9/1000 -> 0 | AD10: ='Raw - 2026 PL'!B9/1000 -> 0 | AE10: ='Raw - 2026 PL'!C9/1000 -> 0 | AF10: ='Raw - 2026 PL'!D9/1000 -> 0 | AG10: ='Raw - 2026 PL'!E9/1000 -> 2.325 | AH10: ='Raw - 2026 PL'!F9/1000 -> 0 | AI10: ='Raw - 2026 PL'!G9/1000 -> 0 | AJ10: ='Raw - 2026 PL'!H9/1000 -> 0
A11: Total Income Tax Revenue | B11: =SUM(F11:Q11) -> 0 | C11: =SUM(R11:AC11) -> 3.4 | D11: =SUM(AD11:AJ11) -> 23.915 | F11: =SUM(F8,F9,F10) -> 0 | G11: =SUM(G8,G9,G10) -> 0 | H11: =SUM(H8,H9,H10) -> 0 | I11: =SUM(I8,I9,I10) -> 0 | J11: =SUM(J8,J9,J10) -> 0 | K11: =SUM(K8,K9,K10) -> 0 | L11: =SUM(L8,L9,L10) -> 0 | M11: =SUM(M8,M9,M10) -> 0 | ... AJ11: =SUM(AJ8,AJ9,AJ10) -> 0
A12: Non-Recurring Revenue | B12: =SUM(F12:Q12) -> 0 | C12: =SUM(R12:AC12) -> 0 | D12: =SUM(AD12:AJ12) -> 0 | F12: ='Raw - 2024 PL'!B7/1000 -> 0 | G12: ='Raw - 2024 PL'!C7/1000 -> 0 | H12: ='Raw - 2024 PL'!D7/1000 -> 0 | I12: ='Raw - 2024 PL'!E7/1000 -> 0 | J12: ='Raw - 2024 PL'!F7/1000 -> 0 | K12: ='Raw - 2024 PL'!G7/1000 -> 0 | L12: ='Raw - 2024 PL'!H7/1000 -> 0 | M12: ='Raw - 2024 PL'!I7/1000 -> 0 | ... Q12: ='Raw - 2024 PL'!M7/1000 -> 0 | R12: ='Raw - 2025 PL'!B11/1000 -> 0 | S12: ='Raw - 2025 PL'!C11/1000 -> 0 | T12: ='Raw - 2025 PL'!D11/1000 -> 0 | U12: ='Raw - 2025 PL'!E11/1000 -> 0 | V12: ='Raw - 2025 PL'!F11/1000 -> 0 | W12: ='Raw - 2025 PL'!G11/1000 -> 0 | X12: ='Raw - 2025 PL'!H11/1000 -> 0 | Y12: ='Raw - 2025 PL'!I11/1000 -> 0 | ... AC12: ='Raw - 2025 PL'!M11/1000 -> 0 | AD12: ='Raw - 2026 PL'!B11/1000 -> 0 | AE12: ='Raw - 2026 PL'!C11/1000 -> 0 | AF12: ='Raw - 2026 PL'!D11/1000 -> 0 | AG12: ='Raw - 2026 PL'!E11/1000 -> 0 | AH12: ='Raw - 2026 PL'!F11/1000 -> 0 | AI12: ='Raw - 2026 PL'!G11/1000 -> 0 | AJ12: ='Raw - 2026 PL'!H11/1000 -> 0
A13: 1099 Filing | B13: =SUM(F13:Q13) -> 10.475 | C13: =SUM(R13:AC13) -> 23.55 | D13: =SUM(AD13:AJ13) -> 38.7015 | F13: ='Raw - 2024 PL'!B8/1000 -> 6.945 | G13: ='Raw - 2024 PL'!C8/1000 -> 3.38 | H13: ='Raw - 2024 PL'!D8/1000 -> 0.045 | I13: ='Raw - 2024 PL'!E8/1000 -> 0.06 | J13: ='Raw - 2024 PL'!F8/1000 -> 0.015 | K13: ='Raw - 2024 PL'!G8/1000 -> 0 | L13: ='Raw - 2024 PL'!H8/1000 -> 0 | M13: ='Raw - 2024 PL'!I8/1000 -> 0.015 | ... Q13: ='Raw - 2024 PL'!M8/1000 -> 0 | R13: ='Raw - 2025 PL'!B12/1000 -> 13.485 | S13: ='Raw - 2025 PL'!C12/1000 -> 9.915 | T13: ='Raw - 2025 PL'!D12/1000 -> 0.06 | U13: ='Raw - 2025 PL'!E12/1000 -> 0.03 | V13: ='Raw - 2025 PL'!F12/1000 -> 0 | W13: ='Raw - 2025 PL'!G12/1000 -> 0 | X13: ='Raw - 2025 PL'!H12/1000 -> 0 | Y13: ='Raw - 2025 PL'!I12/1000 -> 0.03 | ... AC13: ='Raw - 2025 PL'!M12/1000 -> 0 | AD13: ='Raw - 2026 PL'!B12/1000 -> 6.105 | AE13: ='Raw - 2026 PL'!C12/1000 -> 31.1565 | AF13: ='Raw - 2026 PL'!D12/1000 -> 1.26 | AG13: ='Raw - 2026 PL'!E12/1000 -> 0.18 | AH13: ='Raw - 2026 PL'!F12/1000 -> 0 | AI13: ='Raw - 2026 PL'!G12/1000 -> 0 | AJ13: ='Raw - 2026 PL'!H12/1000 -> 0
A14: Billable Expense Income | B14: =SUM(F14:Q14) -> 0.3747 | C14: =SUM(R14:AC14) -> 1.12194 | D14: =SUM(AD14:AJ14) -> 0.25783 | F14: ='Raw - 2024 PL'!B9/1000 -> 0.05 | G14: ='Raw - 2024 PL'!C9/1000 -> 0 | H14: ='Raw - 2024 PL'!D9/1000 -> 0 | I14: ='Raw - 2024 PL'!E9/1000 -> 0.025 | J14: ='Raw - 2024 PL'!F9/1000 -> 0 | K14: ='Raw - 2024 PL'!G9/1000 -> 0 | L14: ='Raw - 2024 PL'!H9/1000 -> 0.2997 | M14: ='Raw - 2024 PL'!I9/1000 -> 0 | ... Q14: ='Raw - 2024 PL'!M9/1000 -> 0 | R14: ='Raw - 2025 PL'!B13/1000 -> 0.025 | S14: ='Raw - 2025 PL'!C13/1000 -> 0.3996 | T14: ='Raw - 2025 PL'!D13/1000 -> 0 | U14: ='Raw - 2025 PL'!E13/1000 -> 0 | V14: ='Raw - 2025 PL'!F13/1000 -> 0.07294 | W14: ='Raw - 2025 PL'!G13/1000 -> 0 | X14: ='Raw - 2025 PL'!H13/1000 -> 0.28971 | Y14: ='Raw - 2025 PL'!I13/1000 -> 0.30969 | ... AC14: ='Raw - 2025 PL'!M13/1000 -> 0.025 | AD14: ='Raw - 2026 PL'!B13/1000 -> 0.15984 | AE14: ='Raw - 2026 PL'!C13/1000 -> 0 | AF14: ='Raw - 2026 PL'!D13/1000 -> 0.075 | AG14: ='Raw - 2026 PL'!E13/1000 -> 0 | AH14: ='Raw - 2026 PL'!F13/1000 -> 0 | AI14: ='Raw - 2026 PL'!G13/1000 -> 0.02299 | AJ14: ='Raw - 2026 PL'!H13/1000 -> 0
A15: Offshore Recruiting | B15: =SUM(F15:Q15) -> 23.6 | C15: =SUM(R15:AC15) -> 0.2 | D15: =SUM(AD15:AJ15) -> 0 | F15: ='Raw - 2024 PL'!B10/1000 -> 0.5 | G15: ='Raw - 2024 PL'!C10/1000 -> 3 | H15: ='Raw - 2024 PL'!D10/1000 -> 0 | I15: ='Raw - 2024 PL'!E10/1000 -> 0 | J15: ='Raw - 2024 PL'!F10/1000 -> 3 | K15: ='Raw - 2024 PL'!G10/1000 -> 0.565 | L15: ='Raw - 2024 PL'!H10/1000 -> 10.5 | M15: ='Raw - 2024 PL'!I10/1000 -> 6.5 | ... Q15: ='Raw - 2024 PL'!M10/1000 -> 0 | R15: ='Raw - 2025 PL'!B14/1000 -> 0.1 | S15: ='Raw - 2025 PL'!C14/1000 -> 0 | T15: ='Raw - 2025 PL'!D14/1000 -> 0.1 | U15: ='Raw - 2025 PL'!E14/1000 -> 0 | V15: ='Raw - 2025 PL'!F14/1000 -> 0 | W15: ='Raw - 2025 PL'!G14/1000 -> 0 | X15: ='Raw - 2025 PL'!H14/1000 -> 0 | Y15: ='Raw - 2025 PL'!I14/1000 -> 0 | ... AC15: ='Raw - 2025 PL'!M14/1000 -> 0
A16: Profit Share | B16: =SUM(F16:Q16) -> 6.2004 | C16: =SUM(R16:AC16) -> 23.26179 | D16: =SUM(AD16:AJ16) -> 8.07938 | F16: ='Raw - 2024 PL'!B11/1000 -> 0.0686 | G16: ='Raw - 2024 PL'!C11/1000 -> 0.1312 | H16: ='Raw - 2024 PL'!D11/1000 -> 0.0712 | I16: ='Raw - 2024 PL'!E11/1000 -> 0.0556 | J16: ='Raw - 2024 PL'!F11/1000 -> 0.577 | K16: ='Raw - 2024 PL'!G11/1000 -> 0.8068 | L16: ='Raw - 2024 PL'!H11/1000 -> 0.6656 | M16: ='Raw - 2024 PL'!I11/1000 -> 0.8264 | ... Q16: ='Raw - 2024 PL'!M11/1000 -> 0.2468 | R16: ='Raw - 2025 PL'!B15/1000 -> 7.3584 | S16: ='Raw - 2025 PL'!C15/1000 -> 1.29335 | T16: ='Raw - 2025 PL'!D15/1000 -> 0.96833 | U16: ='Raw - 2025 PL'!E15/1000 -> 1.1656 | V16: ='Raw - 2025 PL'!F15/1000 -> 0.96093 | W16: ='Raw - 2025 PL'!G15/1000 -> 1.71127 | X16: ='Raw - 2025 PL'!H15/1000 -> 1.04707 | Y16: ='Raw - 2025 PL'!I15/1000 -> 2.04088 | ... AC16: ='Raw - 2025 PL'!M15/1000 -> 2.26793 | AD16: ='Raw - 2026 PL'!B14/1000 -> 2.67784 | AE16: ='Raw - 2026 PL'!C14/1000 -> 2.35401 | AF16: ='Raw - 2026 PL'!D14/1000 -> 0.2276 | AG16: ='Raw - 2026 PL'!E14/1000 -> 1.47836 | AH16: ='Raw - 2026 PL'!F14/1000 -> 0.66824 | AI16: ='Raw - 2026 PL'!G14/1000 -> 0.58613 | AJ16: ='Raw - 2026 PL'!H14/1000 -> 0.0872
A17: Total Non-Recurring Revenue | B17: =SUM(F17:Q17) -> 40.6501 | C17: =SUM(R17:AC17) -> 48.13373 | D17: =SUM(AD17:AJ17) -> 47.03871 | F17: =SUM(F12,F13,F14,F15,F16) -> 7.5636 | G17: =SUM(G12,G13,G14,G15,G16) -> 6.5112 | H17: =SUM(H12,H13,H14,H15,H16) -> 0.1162 | I17: =SUM(I12,I13,I14,I15,I16) -> 0.1406 | J17: =SUM(J12,J13,J14,J15,J16) -> 3.592 | K17: =SUM(K12,K13,K14,K15,K16) -> 1.3718 | L17: =SUM(L12,L13,L14,L15,L16) -> 11.4653 | M17: =SUM(M12,M13,M14,M15,M16) -> 7.3414 | ... AJ17: =SUM(AJ12,AJ13,AJ14,AJ15,AJ16) -> 0.0872
A18: Onboarding Revenue | B18: =SUM(F18:Q18) -> 0 | C18: =SUM(R18:AC18) -> 0 | D18: =SUM(AD18:AJ18) -> 0 | F18: ='Raw - 2024 PL'!B13/1000 -> 0 | G18: ='Raw - 2024 PL'!C13/1000 -> 0 | H18: ='Raw - 2024 PL'!D13/1000 -> 0 | I18: ='Raw - 2024 PL'!E13/1000 -> 0 | J18: ='Raw - 2024 PL'!F13/1000 -> 0 | K18: ='Raw - 2024 PL'!G13/1000 -> 0 | L18: ='Raw - 2024 PL'!H13/1000 -> 0 | M18: ='Raw - 2024 PL'!I13/1000 -> 0 | ... Q18: ='Raw - 2024 PL'!M13/1000 -> 0 | R18: ='Raw - 2025 PL'!B17/1000 -> 0 | S18: ='Raw - 2025 PL'!C17/1000 -> 0 | T18: ='Raw - 2025 PL'!D17/1000 -> 0 | U18: ='Raw - 2025 PL'!E17/1000 -> 0 | V18: ='Raw - 2025 PL'!F17/1000 -> 0 | W18: ='Raw - 2025 PL'!G17/1000 -> 0 | X18: ='Raw - 2025 PL'!H17/1000 -> 0 | Y18: ='Raw - 2025 PL'!I17/1000 -> 0 | ... AC18: ='Raw - 2025 PL'!M17/1000 -> 0 | AD18: ='Raw - 2026 PL'!B16/1000 -> 0 | AE18: ='Raw - 2026 PL'!C16/1000 -> 0 | AF18: ='Raw - 2026 PL'!D16/1000 -> 0 | AG18: ='Raw - 2026 PL'!E16/1000 -> 0 | AH18: ='Raw - 2026 PL'!F16/1000 -> 0 | AI18: ='Raw - 2026 PL'!G16/1000 -> 0 | AJ18: ='Raw - 2026 PL'!H16/1000 -> 0
A19: Historical Cleanup | B19: =SUM(F19:Q19) -> 17.624 | C19: =SUM(R19:AC19) -> 5.03375 | D19: =SUM(AD19:AJ19) -> 0 | F19: ='Raw - 2024 PL'!B14/1000 -> 1.2 | G19: ='Raw - 2024 PL'!C14/1000 -> 1.7625 | H19: ='Raw - 2024 PL'!D14/1000 -> 0.66 | I19: ='Raw - 2024 PL'!E14/1000 -> 0.395 | J19: ='Raw - 2024 PL'!F14/1000 -> 2.465 | K19: ='Raw - 2024 PL'!G14/1000 -> 1.275 | L19: ='Raw - 2024 PL'!H14/1000 -> 1.4625 | M19: ='Raw - 2024 PL'!I14/1000 -> 0 | ... Q19: ='Raw - 2024 PL'!M14/1000 -> 4 | R19: ='Raw - 2025 PL'!B18/1000 -> 1.08375 | S19: ='Raw - 2025 PL'!C18/1000 -> 2 | T19: ='Raw - 2025 PL'!D18/1000 -> 1.355 | U19: ='Raw - 2025 PL'!E18/1000 -> 0 | V19: ='Raw - 2025 PL'!F18/1000 -> 0 | W19: ='Raw - 2025 PL'!G18/1000 -> 0 | X19: ='Raw - 2025 PL'!H18/1000 -> 0 | Y19: ='Raw - 2025 PL'!I18/1000 -> 0 | ... AC19: ='Raw - 2025 PL'!M18/1000 -> 0
A20: Onboarding | B20: =SUM(F20:Q20) -> 44.0585 | C20: =SUM(R20:AC20) -> 74.5193 | D20: =SUM(AD20:AJ20) -> 59.055 | F20: ='Raw - 2024 PL'!B15/1000 -> 5.465 | G20: ='Raw - 2024 PL'!C15/1000 -> 3.9 | H20: ='Raw - 2024 PL'!D15/1000 -> 2.755 | I20: ='Raw - 2024 PL'!E15/1000 -> 3.502 | J20: ='Raw - 2024 PL'!F15/1000 -> 4.659 | K20: ='Raw - 2024 PL'!G15/1000 -> 3.937 | L20: ='Raw - 2024 PL'!H15/1000 -> 4.602 | M20: ='Raw - 2024 PL'!I15/1000 -> 4.738 | ... Q20: ='Raw - 2024 PL'!M15/1000 -> 3.305 | R20: ='Raw - 2025 PL'!B19/1000 -> 3.079 | S20: ='Raw - 2025 PL'!C19/1000 -> 0.7 | T20: ='Raw - 2025 PL'!D19/1000 -> 10.43855 | U20: ='Raw - 2025 PL'!E19/1000 -> 4.3 | V20: ='Raw - 2025 PL'!F19/1000 -> 11.14 | W20: ='Raw - 2025 PL'!G19/1000 -> 6.1625 | X20: ='Raw - 2025 PL'!H19/1000 -> 6.434 | Y20: ='Raw - 2025 PL'!I19/1000 -> 3.965 | ... AC20: ='Raw - 2025 PL'!M19/1000 -> 9.99 | AD20: ='Raw - 2026 PL'!B17/1000 -> 10.2105 | AE20: ='Raw - 2026 PL'!C17/1000 -> 6.675 | AF20: ='Raw - 2026 PL'!D17/1000 -> 9.099 | AG20: ='Raw - 2026 PL'!E17/1000 -> 8.9545 | AH20: ='Raw - 2026 PL'!F17/1000 -> 12.606 | AI20: ='Raw - 2026 PL'!G17/1000 -> 5.4115 | AJ20: ='Raw - 2026 PL'!H17/1000 -> 6.0985
A21: Total Onboarding Revenue | B21: =SUM(F21:Q21) -> 61.6825 | C21: =SUM(R21:AC21) -> 79.55305 | D21: =SUM(AD21:AJ21) -> 59.055 | F21: =SUM(F18,F19,F20) -> 6.665 | G21: =SUM(G18,G19,G20) -> 5.6625 | H21: =SUM(H18,H19,H20) -> 3.415 | I21: =SUM(I18,I19,I20) -> 3.897 | J21: =SUM(J18,J19,J20) -> 7.124 | K21: =SUM(K18,K19,K20) -> 5.212 | L21: =SUM(L18,L19,L20) -> 6.0645 | M21: =SUM(M18,M19,M20) -> 4.738 | ... AJ21: =SUM(AJ18,AJ19,AJ20) -> 6.0985
A22: SMB Bookkeeping Subscription | B22: =SUM(F22:Q22) -> 224.791 | C22: =SUM(R22:AC22) -> 149.77 | D22: =SUM(AD22:AJ22) -> 73.4185 | F22: ='Raw - 2024 PL'!B17/1000 -> 22.001 | G22: ='Raw - 2024 PL'!C17/1000 -> 22.036 | H22: ='Raw - 2024 PL'!D17/1000 -> 22.111 | I22: ='Raw - 2024 PL'!E17/1000 -> 22.146 | J22: ='Raw - 2024 PL'!F17/1000 -> 21.966 | K22: ='Raw - 2024 PL'!G17/1000 -> 17.816 | L22: ='Raw - 2024 PL'!H17/1000 -> 17.621 | M22: ='Raw - 2024 PL'!I17/1000 -> 17.536 | ... Q22: ='Raw - 2024 PL'!M17/1000 -> 15.0755 | R22: ='Raw - 2025 PL'!B21/1000 -> 14.5625 | S22: ='Raw - 2025 PL'!C21/1000 -> 12.8025 | T22: ='Raw - 2025 PL'!D21/1000 -> 12.4025 | U22: ='Raw - 2025 PL'!E21/1000 -> 12.6025 | V22: ='Raw - 2025 PL'!F21/1000 -> 12.7525 | W22: ='Raw - 2025 PL'!G21/1000 -> 12.7925 | X22: ='Raw - 2025 PL'!H21/1000 -> 12.5375 | Y22: ='Raw - 2025 PL'!I21/1000 -> 11.8575 | ... AC22: ='Raw - 2025 PL'!M21/1000 -> 11.7475 | AD22: ='Raw - 2026 PL'!B19/1000 -> 11.2805 | AE22: ='Raw - 2026 PL'!C19/1000 -> 10.9305 | AF22: ='Raw - 2026 PL'!D19/1000 -> 10.6255 | AG22: ='Raw - 2026 PL'!E19/1000 -> 10.3155 | AH22: ='Raw - 2026 PL'!F19/1000 -> 10.3155 | AI22: ='Raw - 2026 PL'!G19/1000 -> 9.9755 | AJ22: ='Raw - 2026 PL'!H19/1000 -> 9.9755
A23: STR Recurring Revenue | B23: =SUM(F23:Q23) -> 0 | C23: =SUM(R23:AC23) -> 0 | D23: =SUM(AD23:AJ23) -> 0 | F23: ='Raw - 2024 PL'!B18/1000 -> 0 | G23: ='Raw - 2024 PL'!C18/1000 -> 0 | H23: ='Raw - 2024 PL'!D18/1000 -> 0 | I23: ='Raw - 2024 PL'!E18/1000 -> 0 | J23: ='Raw - 2024 PL'!F18/1000 -> 0 | K23: ='Raw - 2024 PL'!G18/1000 -> 0 | L23: ='Raw - 2024 PL'!H18/1000 -> 0 | M23: ='Raw - 2024 PL'!I18/1000 -> 0 | ... Q23: ='Raw - 2024 PL'!M18/1000 -> 0 | R23: ='Raw - 2025 PL'!B22/1000 -> 0 | S23: ='Raw - 2025 PL'!C22/1000 -> 0 | T23: ='Raw - 2025 PL'!D22/1000 -> 0 | U23: ='Raw - 2025 PL'!E22/1000 -> 0 | V23: ='Raw - 2025 PL'!F22/1000 -> 0 | W23: ='Raw - 2025 PL'!G22/1000 -> 0 | X23: ='Raw - 2025 PL'!H22/1000 -> 0 | Y23: ='Raw - 2025 PL'!I22/1000 -> 0 | ... AC23: ='Raw - 2025 PL'!M22/1000 -> 0 | AD23: ='Raw - 2026 PL'!B20/1000 -> 0 | AE23: ='Raw - 2026 PL'!C20/1000 -> 0 | AF23: ='Raw - 2026 PL'!D20/1000 -> 0 | AG23: ='Raw - 2026 PL'!E20/1000 -> 0 | AH23: ='Raw - 2026 PL'!F20/1000 -> 0 | AI23: ='Raw - 2026 PL'!G20/1000 -> 0 | AJ23: ='Raw - 2026 PL'!H20/1000 -> 0
A24: Controller Services | B24: =SUM(F24:Q24) -> 13.75 | C24: =SUM(R24:AC24) -> 46.4 | D24: =SUM(AD24:AJ24) -> 24.25 | F24: ='Raw - 2024 PL'!B19/1000 -> 0 | G24: ='Raw - 2024 PL'!C19/1000 -> 0 | H24: ='Raw - 2024 PL'!D19/1000 -> 0 | I24: ='Raw - 2024 PL'!E19/1000 -> 0 | J24: ='Raw - 2024 PL'!F19/1000 -> 0 | K24: ='Raw - 2024 PL'!G19/1000 -> 0 | L24: ='Raw - 2024 PL'!H19/1000 -> 1.25 | M24: ='Raw - 2024 PL'!I19/1000 -> 1.25 | ... Q24: ='Raw - 2024 PL'!M19/1000 -> 3 | R24: ='Raw - 2025 PL'!B23/1000 -> 4.45 | S24: ='Raw - 2025 PL'!C23/1000 -> 3.45 | T24: ='Raw - 2025 PL'!D23/1000 -> 3.45 | U24: ='Raw - 2025 PL'!E23/1000 -> 5.95 | V24: ='Raw - 2025 PL'!F23/1000 -> 5.2 | W24: ='Raw - 2025 PL'!G23/1000 -> 5 | X24: ='Raw - 2025 PL'!H23/1000 -> 4 | Y24: ='Raw - 2025 PL'!I23/1000 -> 2.95 | ... AC24: ='Raw - 2025 PL'!M23/1000 -> 2.95 | AD24: ='Raw - 2026 PL'!B21/1000 -> 2.75 | AE24: ='Raw - 2026 PL'!C21/1000 -> 3.5 | AF24: ='Raw - 2026 PL'!D21/1000 -> 2.75 | AG24: ='Raw - 2026 PL'!E21/1000 -> 4.75 | AH24: ='Raw - 2026 PL'!F21/1000 -> 3.5 | AI24: ='Raw - 2026 PL'!G21/1000 -> 3.5 | AJ24: ='Raw - 2026 PL'!H21/1000 -> 3.5
A25: Occupancy Taxes | B25: =SUM(F25:Q25) -> 0.56 | C25: =SUM(R25:AC25) -> 55.0805 | D25: =SUM(AD25:AJ25) -> 91.65114 | F25: ='Raw - 2024 PL'!B20/1000 -> 0 | G25: ='Raw - 2024 PL'!C20/1000 -> 0 | H25: ='Raw - 2024 PL'!D20/1000 -> 0 | I25: ='Raw - 2024 PL'!E20/1000 -> 0 | J25: ='Raw - 2024 PL'!F20/1000 -> 0 | K25: ='Raw - 2024 PL'!G20/1000 -> 0 | L25: ='Raw - 2024 PL'!H20/1000 -> 0 | M25: ='Raw - 2024 PL'!I20/1000 -> 0 | ... Q25: ='Raw - 2024 PL'!M20/1000 -> 0.48 | R25: ='Raw - 2025 PL'!B24/1000 -> 1.13 | S25: ='Raw - 2025 PL'!C24/1000 -> 2.14 | T25: ='Raw - 2025 PL'!D24/1000 -> 2.66 | U25: ='Raw - 2025 PL'!E24/1000 -> 3.65 | V25: ='Raw - 2025 PL'!F24/1000 -> 3.623 | W25: ='Raw - 2025 PL'!G24/1000 -> 4.964 | X25: ='Raw - 2025 PL'!H24/1000 -> 5.0585 | Y25: ='Raw - 2025 PL'!I24/1000 -> 4.73 | ... AC25: ='Raw - 2025 PL'!M24/1000 -> 8.885 | AD25: ='Raw - 2026 PL'!B22/1000 -> 10.90952 | AE25: ='Raw - 2026 PL'!C22/1000 -> 10.33497 | AF25: ='Raw - 2026 PL'!D22/1000 -> 11.175 | AG25: ='Raw - 2026 PL'!E22/1000 -> 11.95311 | AH25: ='Raw - 2026 PL'!F22/1000 -> 15.04071 | AI25: ='Raw - 2026 PL'!G22/1000 -> 16.16868 | AJ25: ='Raw - 2026 PL'!H22/1000 -> 16.06915
A26: STR Bill Pay | B26: =SUM(F26:Q26) -> 0.06 | C26: =SUM(R26:AC26) -> 36.6065 | D26: =SUM(AD26:AJ26) -> 45.13 | F26: ='Raw - 2024 PL'!B21/1000 -> 0 | G26: ='Raw - 2024 PL'!C21/1000 -> 0 | H26: ='Raw - 2024 PL'!D21/1000 -> 0 | I26: ='Raw - 2024 PL'!E21/1000 -> 0 | J26: ='Raw - 2024 PL'!F21/1000 -> 0 | K26: ='Raw - 2024 PL'!G21/1000 -> 0 | L26: ='Raw - 2024 PL'!H21/1000 -> 0 | M26: ='Raw - 2024 PL'!I21/1000 -> 0 | ... Q26: ='Raw - 2024 PL'!M21/1000 -> 0.06 | R26: ='Raw - 2025 PL'!B25/1000 -> 0.97 | S26: ='Raw - 2025 PL'!C25/1000 -> 1.1 | T26: ='Raw - 2025 PL'!D25/1000 -> 1.735 | U26: ='Raw - 2025 PL'!E25/1000 -> 2.14 | V26: ='Raw - 2025 PL'!F25/1000 -> 2.363 | W26: ='Raw - 2025 PL'!G25/1000 -> 3.2635 | X26: ='Raw - 2025 PL'!H25/1000 -> 3.92 | Y26: ='Raw - 2025 PL'!I25/1000 -> 3.905 | ... AC26: ='Raw - 2025 PL'!M25/1000 -> 5.305 | AD26: ='Raw - 2026 PL'!B23/1000 -> 6.3 | AE26: ='Raw - 2026 PL'!C23/1000 -> 6.39 | AF26: ='Raw - 2026 PL'!D23/1000 -> 6.425 | AG26: ='Raw - 2026 PL'!E23/1000 -> 6.08 | AH26: ='Raw - 2026 PL'!F23/1000 -> 6.325 | AI26: ='Raw - 2026 PL'!G23/1000 -> 6.655 | AJ26: ='Raw - 2026 PL'!H23/1000 -> 6.955
A27: STR Bookkeeping Subscription | B27: =SUM(F27:Q27) -> 793.47225 | C27: =SUM(R27:AC27) -> 1450.4923 | D27: =SUM(AD27:AJ27) -> 1261.4769 | F27: ='Raw - 2024 PL'!B22/1000 -> 44.6835 | G27: ='Raw - 2024 PL'!C22/1000 -> 47.046 | H27: ='Raw - 2024 PL'!D22/1000 -> 52.47 | I27: ='Raw - 2024 PL'!E22/1000 -> 57.1697 | J27: ='Raw - 2024 PL'!F22/1000 -> 57.51415 | K27: ='Raw - 2024 PL'!G22/1000 -> 65.516 | L27: ='Raw - 2024 PL'!H22/1000 -> 68.28125 | M27: ='Raw - 2024 PL'!I22/1000 -> 73.25135 | ... Q27: ='Raw - 2024 PL'!M22/1000 -> 89.58455 | R27: ='Raw - 2025 PL'!B26/1000 -> 92.4189 | S27: ='Raw - 2025 PL'!C26/1000 -> 94.00215 | T27: ='Raw - 2025 PL'!D26/1000 -> 101.50605 | U27: ='Raw - 2025 PL'!E26/1000 -> 106.1375 | V27: ='Raw - 2025 PL'!F26/1000 -> 115.93875 | W27: ='Raw - 2025 PL'!G26/1000 -> 119.43125 | X27: ='Raw - 2025 PL'!H26/1000 -> 122.094 | Y27: ='Raw - 2025 PL'!I26/1000 -> 130.08525 | ... AC27: ='Raw - 2025 PL'!M26/1000 -> 150.39825 | AD27: ='Raw - 2026 PL'!B24/1000 -> 156.5388 | AE27: ='Raw - 2026 PL'!C24/1000 -> 164.9034 | AF27: ='Raw - 2026 PL'!D24/1000 -> 170.34425 | AG27: ='Raw - 2026 PL'!E24/1000 -> 183.662 | AH27: ='Raw - 2026 PL'!F24/1000 -> 190.7844 | AI27: ='Raw - 2026 PL'!G24/1000 -> 194.4065 | AJ27: ='Raw - 2026 PL'!H24/1000 -> 200.8375
A28: Topkey Subscription | B28: =SUM(F28:Q28) -> 0 | C28: =SUM(R28:AC28) -> 9.947 | D28: =SUM(AD28:AJ28) -> 45.086 | R28: ='Raw - 2025 PL'!B27/1000 -> 0 | S28: ='Raw - 2025 PL'!C27/1000 -> 0 | T28: ='Raw - 2025 PL'!D27/1000 -> 0 | U28: ='Raw - 2025 PL'!E27/1000 -> 0 | V28: ='Raw - 2025 PL'!F27/1000 -> 0 | W28: ='Raw - 2025 PL'!G27/1000 -> 0 | X28: ='Raw - 2025 PL'!H27/1000 -> 0 | Y28: ='Raw - 2025 PL'!I27/1000 -> 0 | ... AC28: ='Raw - 2025 PL'!M27/1000 -> 4.259 | AD28: ='Raw - 2026 PL'!B25/1000 -> 5.254 | AE28: ='Raw - 2026 PL'!C25/1000 -> 5.652 | AF28: ='Raw - 2026 PL'!D25/1000 -> 5.324 | AG28: ='Raw - 2026 PL'!E25/1000 -> 6.321 | AH28: ='Raw - 2026 PL'!F25/1000 -> 6.959 | AI28: ='Raw - 2026 PL'!G25/1000 -> 7.673 | AJ28: ='Raw - 2026 PL'!H25/1000 -> 7.903
A29: Total STR Recurring Revenue | B29: =SUM(F29:Q29) -> 807.84225 | C29: =SUM(R29:AC29) -> 1598.5264 | D29: =SUM(AD29:AJ29) -> 1467.594 | F29: =SUM(F23,F24,F25,F26,F27,F28) -> 44.6835 | G29: =SUM(G23,G24,G25,G26,G27,G28) -> 47.046 | H29: =SUM(H23,H24,H25,H26,H27,H28) -> 52.47 | I29: =SUM(I23,I24,I25,I26,I27,I28) -> 57.1697 | J29: =SUM(J23,J24,J25,J26,J27,J28) -> 57.51415 | K29: =SUM(K23,K24,K25,K26,K27,K28) -> 65.516 | L29: =SUM(L23,L24,L25,L26,L27,L28) -> 69.53125 | M29: =SUM(M23,M24,M25,M26,M27,M28) -> 74.50135 | ... AJ29: =SUM(AJ23,AJ24,AJ25,AJ26,AJ27,AJ28) -> 235.26465
A30: Total Income | B30: =SUM(F30:Q30) -> 1134.9659 | C30: =SUM(R30:AC30) -> 1879.3831 | D30: =SUM(AD30:AJ30) -> 1671.0212 | F30: =SUM(F11,F17,F21,F22,F29) -> 80.9131 | G30: =SUM(G11,G17,G21,G22,G29) -> 81.2557 | H30: =SUM(H11,H17,H21,H22,H29) -> 78.1122 | I30: =SUM(I11,I17,I21,I22,I29) -> 83.3533 | J30: =SUM(J11,J17,J21,J22,J29) -> 90.19615 | K30: =SUM(K11,K17,K21,K22,K29) -> 89.9158 | L30: =SUM(L11,L17,L21,L22,L29) -> 104.68205 | M30: =SUM(M11,M17,M21,M22,M29) -> 104.11675 | ... AJ30: =SUM(AJ11,AJ17,AJ21,AJ22,AJ29) -> 251.42585
A31: Cost of Goods Sold
A32: 1099 Filing Fees | B32: =SUM(F32:Q32) -> 1.34593 | C32: =SUM(R32:AC32) -> 2.49433 | D32: =SUM(AD32:AJ32) -> 3.20461 | F32: ='Raw - 2024 PL'!B26/1000 -> 1.29934 | G32: ='Raw - 2024 PL'!C26/1000 -> 0.03012 | H32: ='Raw - 2024 PL'!D26/1000 -> 0.01063 | I32: ='Raw - 2024 PL'!E26/1000 -> 0.00325 | J32: ='Raw - 2024 PL'!F26/1000 -> 0.00065 | K32: ='Raw - 2024 PL'!G26/1000 -> 0 | L32: ='Raw - 2024 PL'!H26/1000 -> 0 | M32: ='Raw - 2024 PL'!I26/1000 -> 0.00194 | ... Q32: ='Raw - 2024 PL'!M26/1000 -> 0 | R32: ='Raw - 2025 PL'!B31/1000 -> 1.22655 | S32: ='Raw - 2025 PL'!C31/1000 -> 0 | T32: ='Raw - 2025 PL'!D31/1000 -> 1.15433 | U32: ='Raw - 2025 PL'!E31/1000 -> 0 | V32: ='Raw - 2025 PL'!F31/1000 -> 0 | W32: ='Raw - 2025 PL'!G31/1000 -> 0 | X32: ='Raw - 2025 PL'!H31/1000 -> 0 | Y32: ='Raw - 2025 PL'!I31/1000 -> 0 | ... AC32: ='Raw - 2025 PL'!M31/1000 -> 0 | AD32: ='Raw - 2026 PL'!B29/1000 -> 2.4948 | AE32: ='Raw - 2026 PL'!C29/1000 -> 0 | AF32: ='Raw - 2026 PL'!D29/1000 -> 0 | AG32: ='Raw - 2026 PL'!E29/1000 -> 0.70981 | AH32: ='Raw - 2026 PL'!F29/1000 -> 0 | AI32: ='Raw - 2026 PL'!G29/1000 -> 0 | AJ32: ='Raw - 2026 PL'!H29/1000 -> 0
A33: Contract Labor - Tax | B33: =SUM(F33:Q33) -> 0 | C33: =SUM(R33:AC33) -> 1.5875 | D33: =SUM(AD33:AJ33) -> 30.5155 | R33: ='Raw - 2025 PL'!B32/1000 -> 0 | S33: ='Raw - 2025 PL'!C32/1000 -> 0 | T33: ='Raw - 2025 PL'!D32/1000 -> 0 | U33: ='Raw - 2025 PL'!E32/1000 -> 0 | V33: ='Raw - 2025 PL'!F32/1000 -> 0 | W33: ='Raw - 2025 PL'!G32/1000 -> 0 | X33: ='Raw - 2025 PL'!H32/1000 -> 0 | Y33: ='Raw - 2025 PL'!I32/1000 -> 0 | ... AC33: ='Raw - 2025 PL'!M32/1000 -> 0 | AD33: ='Raw - 2026 PL'!B30/1000 -> 0 | AE33: ='Raw - 2026 PL'!C30/1000 -> 3 | AF33: ='Raw - 2026 PL'!D30/1000 -> 16.2655 | AG33: ='Raw - 2026 PL'!E30/1000 -> 2.8 | AH33: ='Raw - 2026 PL'!F30/1000 -> 0 | AI33: ='Raw - 2026 PL'!G30/1000 -> 8.45 | AJ33: ='Raw - 2026 PL'!H30/1000 -> 0
A34: Direct Labor | B34: =SUM(F34:Q34) -> 0 | C34: =SUM(R34:AC34) -> 0 | D34: =SUM(AD34:AJ34) -> 0 | F34: ='Raw - 2024 PL'!B27/1000 -> 0 | G34: ='Raw - 2024 PL'!C27/1000 -> 0 | H34: ='Raw - 2024 PL'!D27/1000 -> 0 | I34: ='Raw - 2024 PL'!E27/1000 -> 0 | J34: ='Raw - 2024 PL'!F27/1000 -> 0 | K34: ='Raw - 2024 PL'!G27/1000 -> 0 | L34: ='Raw - 2024 PL'!H27/1000 -> 0 | M34: ='Raw - 2024 PL'!I27/1000 -> 0 | ... Q34: ='Raw - 2024 PL'!M27/1000 -> 0 | R34: ='Raw - 2025 PL'!B33/1000 -> 0 | S34: ='Raw - 2025 PL'!C33/1000 -> 0 | T34: ='Raw - 2025 PL'!D33/1000 -> 0 | U34: ='Raw - 2025 PL'!E33/1000 -> 0 | V34: ='Raw - 2025 PL'!F33/1000 -> 0 | W34: ='Raw - 2025 PL'!G33/1000 -> 0 | X34: ='Raw - 2025 PL'!H33/1000 -> 0 | Y34: ='Raw - 2025 PL'!I33/1000 -> 0 | ... AC34: ='Raw - 2025 PL'!M33/1000 -> 0 | AD34: ='Raw - 2026 PL'!B31/1000 -> 0 | AE34: ='Raw - 2026 PL'!C31/1000 -> 0 | AF34: ='Raw - 2026 PL'!D31/1000 -> 0 | AG34: ='Raw - 2026 PL'!E31/1000 -> 0 | AH34: ='Raw - 2026 PL'!F31/1000 -> 0 | AI34: ='Raw - 2026 PL'!G31/1000 -> 0 | AJ34: ='Raw - 2026 PL'!H31/1000 -> 0
A35: Bookkeeper Wages | B35: =SUM(F35:Q35) -> 183.36903 | C35: =SUM(R35:AC35) -> 316.18462 | D35: =SUM(AD35:AJ35) -> 267.7574 | F35: ='Raw - 2024 PL'!B28/1000 -> 9.555 | G35: ='Raw - 2024 PL'!C28/1000 -> 9.555 | H35: ='Raw - 2024 PL'!D28/1000 -> 10.3972 | I35: ='Raw - 2024 PL'!E28/1000 -> 14.99967 | J35: ='Raw - 2024 PL'!F28/1000 -> 18.0098 | K35: ='Raw - 2024 PL'!G28/1000 -> 13.89127 | L35: ='Raw - 2024 PL'!H28/1000 -> 14.04824 | M35: ='Raw - 2024 PL'!I28/1000 -> 13.39091 | ... Q35: ='Raw - 2024 PL'!M28/1000 -> 21.78143 | R35: ='Raw - 2025 PL'!B34/1000 -> 19.40233 | S35: ='Raw - 2025 PL'!C34/1000 -> 16.40053 | T35: ='Raw - 2025 PL'!D34/1000 -> 19.56983 | U35: ='Raw - 2025 PL'!E34/1000 -> 22.1542 | V35: ='Raw - 2025 PL'!F34/1000 -> 20.79154 | W35: ='Raw - 2025 PL'!G34/1000 -> 21.04079 | X35: ='Raw - 2025 PL'!H34/1000 -> 27.90891 | Y35: ='Raw - 2025 PL'!I34/1000 -> 29.547 | ... AC35: ='Raw - 2025 PL'!M34/1000 -> 34.06458 | AD35: ='Raw - 2026 PL'!B32/1000 -> 38.37888 | AE35: ='Raw - 2026 PL'!C32/1000 -> 29.70152 | AF35: ='Raw - 2026 PL'!D32/1000 -> 37.4225 | AG35: ='Raw - 2026 PL'!E32/1000 -> 38.7723 | AH35: ='Raw - 2026 PL'!F32/1000 -> 38.29477 | AI35: ='Raw - 2026 PL'!G32/1000 -> 40.69983 | AJ35: ='Raw - 2026 PL'!H32/1000 -> 44.4876
A36: Client Lead Wages | B36: =SUM(F36:Q36) -> 286.16129 | C36: =SUM(R36:AC36) -> 352.95844 | D36: =SUM(AD36:AJ36) -> 202.05309 | F36: ='Raw - 2024 PL'!B29/1000 -> 9.96108 | G36: ='Raw - 2024 PL'!C29/1000 -> 13.85026 | H36: ='Raw - 2024 PL'!D29/1000 -> 12.79054 | I36: ='Raw - 2024 PL'!E29/1000 -> 14.57145 | J36: ='Raw - 2024 PL'!F29/1000 -> 28.28563 | K36: ='Raw - 2024 PL'!G29/1000 -> 26.54254 | L36: ='Raw - 2024 PL'!H29/1000 -> 28.31119 | M36: ='Raw - 2024 PL'!I29/1000 -> 28.18746 | ... Q36: ='Raw - 2024 PL'!M29/1000 -> 32.72211 | R36: ='Raw - 2025 PL'!B35/1000 -> 32.78076 | S36: ='Raw - 2025 PL'!C35/1000 -> 23.36184 | T36: ='Raw - 2025 PL'!D35/1000 -> 26.91427 | U36: ='Raw - 2025 PL'!E35/1000 -> 28.81298 | V36: ='Raw - 2025 PL'!F35/1000 -> 30.65875 | W36: ='Raw - 2025 PL'!G35/1000 -> 29.2716 | X36: ='Raw - 2025 PL'!H35/1000 -> 29.47963 | Y36: ='Raw - 2025 PL'!I35/1000 -> 26.83064 | ... AC36: ='Raw - 2025 PL'!M35/1000 -> 32.66971 | AD36: ='Raw - 2026 PL'!B33/1000 -> 26.1149 | AE36: ='Raw - 2026 PL'!C33/1000 -> 21.9055 | AF36: ='Raw - 2026 PL'!D33/1000 -> 30.75844 | AG36: ='Raw - 2026 PL'!E33/1000 -> 31.59038 | AH36: ='Raw - 2026 PL'!F33/1000 -> 27.69992 | AI36: ='Raw - 2026 PL'!G33/1000 -> 31.24024 | AJ36: ='Raw - 2026 PL'!H33/1000 -> 32.74371
A37: Occupancy Tax Specialist | B37: =SUM(F37:Q37) -> 1.11335 | C37: =SUM(R37:AC37) -> 29.56415 | D37: =SUM(AD37:AJ37) -> 42.08505 | F37: ='Raw - 2024 PL'!B30/1000 -> 0 | G37: ='Raw - 2024 PL'!C30/1000 -> 0 | H37: ='Raw - 2024 PL'!D30/1000 -> 0 | I37: ='Raw - 2024 PL'!E30/1000 -> 0 | J37: ='Raw - 2024 PL'!F30/1000 -> 0 | K37: ='Raw - 2024 PL'!G30/1000 -> 0 | L37: ='Raw - 2024 PL'!H30/1000 -> 0 | M37: ='Raw - 2024 PL'!I30/1000 -> 0 | ... Q37: ='Raw - 2024 PL'!M30/1000 -> 1.11335 | R37: ='Raw - 2025 PL'!B36/1000 -> 2.17917 | S37: ='Raw - 2025 PL'!C36/1000 -> 1.82504 | T37: ='Raw - 2025 PL'!D36/1000 -> 1.97853 | U37: ='Raw - 2025 PL'!E36/1000 -> 2.06213 | V37: ='Raw - 2025 PL'!F36/1000 -> 2.06213 | W37: ='Raw - 2025 PL'!G36/1000 -> 1.98968 | X37: ='Raw - 2025 PL'!H36/1000 -> 2.17917 | Y37: ='Raw - 2025 PL'!I36/1000 -> 2.12293 | ... AC37: ='Raw - 2025 PL'!M36/1000 -> 3.15033 | AD37: ='Raw - 2026 PL'!B34/1000 -> 1.69116 | AE37: ='Raw - 2026 PL'!C34/1000 -> 5.54919 | AF37: ='Raw - 2026 PL'!D34/1000 -> 7.1999 | AG37: ='Raw - 2026 PL'!E34/1000 -> 8.1927 | AH37: ='Raw - 2026 PL'!F34/1000 -> 8.28335 | AI37: ='Raw - 2026 PL'!G34/1000 -> 5.49265 | AJ37: ='Raw - 2026 PL'!H34/1000 -> 5.6761
A38: Onboarding Team Wages | B38: =SUM(F38:Q38) -> 122.81255 | C38: =SUM(R38:AC38) -> 152.16972 | D38: =SUM(AD38:AJ38) -> 111.27999 | F38: ='Raw - 2024 PL'!B31/1000 -> 9.13728 | G38: ='Raw - 2024 PL'!C31/1000 -> 8.96296 | H38: ='Raw - 2024 PL'!D31/1000 -> 10.19584 | I38: ='Raw - 2024 PL'!E31/1000 -> 15.04429 | J38: ='Raw - 2024 PL'!F31/1000 -> 16.63744 | K38: ='Raw - 2024 PL'!G31/1000 -> 7.49499 | L38: ='Raw - 2024 PL'!H31/1000 -> 7.98202 | M38: ='Raw - 2024 PL'!I31/1000 -> 5.90274 | ... Q38: ='Raw - 2024 PL'!M31/1000 -> 12.85047 | R38: ='Raw - 2025 PL'!B37/1000 -> 10.34556 | S38: ='Raw - 2025 PL'!C37/1000 -> 8.08798 | T38: ='Raw - 2025 PL'!D37/1000 -> 9.75287 | U38: ='Raw - 2025 PL'!E37/1000 -> 10.28 | V38: ='Raw - 2025 PL'!F37/1000 -> 11.13632 | W38: ='Raw - 2025 PL'!G37/1000 -> 10.87432 | X38: ='Raw - 2025 PL'!H37/1000 -> 13.47257 | Y38: ='Raw - 2025 PL'!I37/1000 -> 12.70407 | ... AC38: ='Raw - 2025 PL'!M37/1000 -> 20.93052 | AD38: ='Raw - 2026 PL'!B35/1000 -> 16.55394 | AE38: ='Raw - 2026 PL'!C35/1000 -> 11.52661 | AF38: ='Raw - 2026 PL'!D35/1000 -> 14.93883 | AG38: ='Raw - 2026 PL'!E35/1000 -> 15.58352 | AH38: ='Raw - 2026 PL'!F35/1000 -> 19.6034 | AI38: ='Raw - 2026 PL'!G35/1000 -> 16.64457 | AJ38: ='Raw - 2026 PL'!H35/1000 -> 16.42912
A39: Sr. Client Lead Wages | B39: =SUM(F39:Q39) -> 0 | C39: =SUM(R39:AC39) -> 0 | D39: =SUM(AD39:AJ39) -> 7.995 | AD39: ='Raw - 2026 PL'!B36/1000 -> 0 | AE39: ='Raw - 2026 PL'!C36/1000 -> 0 | AF39: ='Raw - 2026 PL'!D36/1000 -> 0 | AG39: ='Raw - 2026 PL'!E36/1000 -> 0 | AH39: ='Raw - 2026 PL'!F36/1000 -> 2.51706 | AI39: ='Raw - 2026 PL'!G36/1000 -> 2.72117 | AJ39: ='Raw - 2026 PL'!H36/1000 -> 2.75677
A40: Total Direct Labor | B40: =SUM(F40:Q40) -> 593.45622 | C40: =SUM(R40:AC40) -> 850.87693 | D40: =SUM(AD40:AJ40) -> 631.17053 | F40: =SUM(F34,F35,F36,F37,F38,F39) -> 28.65336 | G40: =SUM(G34,G35,G36,G37,G38,G39) -> 32.36822 | H40: =SUM(H34,H35,H36,H37,H38,H39) -> 33.38358 | I40: =SUM(I34,I35,I36,I37,I38,I39) -> 44.61541 | J40: =SUM(J34,J35,J36,J37,J38,J39) -> 62.93287 | K40: =SUM(K34,K35,K36,K37,K38,K39) -> 47.9288 | L40: =SUM(L34,L35,L36,L37,L38,L39) -> 50.34145 | M40: =SUM(M34,M35,M36,M37,M38,M39) -> 47.48111 | ... AJ40: =SUM(AJ34,AJ35,AJ36,AJ37,AJ38,AJ39) -> 102.0933
A41: Occupancy Tax Filing Fees | B41: =SUM(F41:Q41) -> 0 | C41: =SUM(R41:AC41) -> 1.75591 | D41: =SUM(AD41:AJ41) -> 1.53949 | R41: ='Raw - 2025 PL'!B39/1000 -> 0.1 | S41: ='Raw - 2025 PL'!C39/1000 -> 0 | T41: ='Raw - 2025 PL'!D39/1000 -> 0 | U41: ='Raw - 2025 PL'!E39/1000 -> 0.1498 | V41: ='Raw - 2025 PL'!F39/1000 -> 0.05975 | W41: ='Raw - 2025 PL'!G39/1000 -> 0.0697 | X41: ='Raw - 2025 PL'!H39/1000 -> 0.1597 | Y41: ='Raw - 2025 PL'!I39/1000 -> 0.31085 | ... AC41: ='Raw - 2025 PL'!M39/1000 -> 0.1095 | AD41: ='Raw - 2026 PL'!B38/1000 -> 0.2294 | AE41: ='Raw - 2026 PL'!C38/1000 -> 0.1194 | AF41: ='Raw - 2026 PL'!D38/1000 -> 0.17935 | AG41: ='Raw - 2026 PL'!E38/1000 -> 0.0699 | AH41: ='Raw - 2026 PL'!F38/1000 -> 0.0699 | AI41: ='Raw - 2026 PL'!G38/1000 -> 0.16398 | AJ41: ='Raw - 2026 PL'!H38/1000 -> 0.70756
A42: Payment Collection Fees | B42: =SUM(F42:Q42) -> 8.67099 | C42: =SUM(R42:AC42) -> 13.35153 | D42: =SUM(AD42:AJ42) -> 9.02684 | F42: ='Raw - 2024 PL'!B33/1000 -> 0.6179 | G42: ='Raw - 2024 PL'!C33/1000 -> 0.8374 | H42: ='Raw - 2024 PL'!D33/1000 -> 0.62936 | I42: ='Raw - 2024 PL'!E33/1000 -> 0.68245 | J42: ='Raw - 2024 PL'!F33/1000 -> 0.72151 | K42: ='Raw - 2024 PL'!G33/1000 -> 0.78747 | L42: ='Raw - 2024 PL'!H33/1000 -> 0.65562 | M42: ='Raw - 2024 PL'!I33/1000 -> 0.79491 | ... Q42: ='Raw - 2024 PL'!M33/1000 -> 0.79818 | R42: ='Raw - 2025 PL'!B40/1000 -> 0.83546 | S42: ='Raw - 2025 PL'!C40/1000 -> 1.05394 | T42: ='Raw - 2025 PL'!D40/1000 -> 0.87069 | U42: ='Raw - 2025 PL'!E40/1000 -> 0.90555 | V42: ='Raw - 2025 PL'!F40/1000 -> 0.91157 | W42: ='Raw - 2025 PL'!G40/1000 -> 1.00249 | X42: ='Raw - 2025 PL'!H40/1000 -> 1.22475 | Y42: ='Raw - 2025 PL'!I40/1000 -> 1.10438 | ... AC42: ='Raw - 2025 PL'!M40/1000 -> 1.30514 | AD42: ='Raw - 2026 PL'!B39/1000 -> 1.22974 | AE42: ='Raw - 2026 PL'!C39/1000 -> 1.73847 | AF42: ='Raw - 2026 PL'!D39/1000 -> 1.35348 | AG42: ='Raw - 2026 PL'!E39/1000 -> 1.23399 | AH42: ='Raw - 2026 PL'!F39/1000 -> 1.17137 | AI42: ='Raw - 2026 PL'!G39/1000 -> 1.15392 | AJ42: ='Raw - 2026 PL'!H39/1000 -> 1.14587
...

Sheet Raw - 2024 PL
A1: Keystone Bookkeepers
A2: Profit and Loss
A3: January - December 2024
B5: Jan 2024 | C5: Feb 2024 | D5: Mar 2024 | E5: Apr 2024 | F5: May 2024 | G5: Jun 2024 | H5: Jul 2024 | I5: Aug 2024 | J5: Sep 2024 | K5: Oct 2024 | L5: Nov 2024 | M5: Dec 2024 | N5: Total
A6: Income
A7: Non-Recurring Revenue | N7: 0
A8: 1099 Filing | B8: 6945 | C8: 3380 | D8: 45 | E8: 60 | F8: 15 | I8: 15 | L8: 15 | N8: 10475
A9: Billable Expense Income | B9: 50 | E9: 25 | H9: 299.7 | N9: 374.7
A10: Offshore Recruiting | B10: 500 | C10: 3000 | F10: 3000 | G10: 565 | H10: 10500 | I10: 6500 | J10: 500 | K10: -965 | L10: 0 | N10: 23600
A11: Profit Share | B11: 68.6 | C11: 131.2 | D11: 71.2 | E11: 55.6 | F11: 577 | G11: 806.8 | H11: 665.6 | I11: 826.4 | J11: 1380.8 | K11: 860.4 | L11: 510 | M11: 246.8 | N11: 6200.4
A12: Total Non-Recurring Revenue | B12: 7563.6 | C12: 6511.2 | D12: 116.2 | E12: 140.6 | F12: 3592 | G12: 1371.8 | H12: 11465.3 | I12: 7341.4 | J12: 1880.8 | K12: -104.6 | L12: 525 | M12: 246.8 | N12: 40650.1
A13: Onboarding Revenue | N13: 0
A14: Historical Cleanup | B14: 1200 | C14: 1762.5 | D14: 660 | E14: 395 | F14: 2465 | G14: 1275 | H14: 1462.5 | J14: 1145.25 | K14: 1355.25 | L14: 1903.5 | M14: 4000 | N14: 17624
A15: Onboarding | B15: 5465 | C15: 3900 | D15: 2755 | E15: 3502 | F15: 4659 | G15: 3937 | H15: 4602 | I15: 4738 | J15: 2119 | K15: 2064 | L15: 3012.5 | M15: 3305 | N15: 44058.5
A16: Total Onboarding Revenue | B16: 6665 | C16: 5662.5 | D16: 3415 | E16: 3897 | F16: 7124 | G16: 5212 | H16: 6064.5 | I16: 4738 | J16: 3264.25 | K16: 3419.25 | L16: 4916 | M16: 7305 | N16: 61682.5
A17: SMB Bookkeeping Subscription | B17: 22001 | C17: 22036 | D17: 22111 | E17: 22146 | F17: 21966 | G17: 17816 | H17: 17621 | I17: 17536 | J17: 16426 | K17: 15381 | L17: 14675.5 | M17: 15075.5 | N17: 224791
A18: STR Recurring Revenue | N18: 0
A19: Controller Services | H19: 1250 | I19: 1250 | J19: 1250 | K19: 1250 | L19: 5750 | M19: 3000 | N19: 13750
A20: Occupancy Taxes | L20: 80 | M20: 480 | N20: 560
A21: STR Bill Pay | M21: 60 | N21: 60
A22: STR Bookkeeping Subscription | B22: 44683.5 | C22: 47046 | D22: 52470 | E22: 57169.7 | F22: 57514.15 | G22: 65516 | H22: 68281.25 | I22: 73251.35 | J22: 75551.7 | K22: 79113.25 | L22: 83290.8 | M22: 89584.55 | N22: 793472.25
A23: Total STR Recurring Revenue | B23: 44683.5 | C23: 47046 | D23: 52470 | E23: 57169.7 | F23: 57514.15 | G23: 65516 | H23: 69531.25 | I23: 74501.35 | J23: 76801.7 | K23: 80363.25 | L23: 89120.8 | M23: 93124.55 | N23: 807842.25
A24: Total Income | B24: 80913.1 | C24: 81255.7 | D24: 78112.2 | E24: 83353.3 | F24: 90196.15 | G24: 89915.8 | H24: 104682.05 | I24: 104116.75 | J24: 98372.75 | K24: 99058.9 | L24: 109237.3 | M24: 115751.85 | N24: 1134965.9
A25: Cost of Goods Sold
A26: 1099 Filing Fees | B26: 1299.34 | C26: 30.12 | D26: 10.63 | E26: 3.25 | F26: 0.65 | I26: 1.94 | N26: 1345.93
A27: Direct Labor | N27: 0
A28: Bookkeeper Wages | B28: 9555 | C28: 9555 | D28: 10397.2 | E28: 14999.67 | F28: 18009.8 | G28: 13891.27 | H28: 14048.24 | I28: 13390.91 | J28: 14669.31 | K28: 15882.53 | L28: 27188.67 | M28: 21781.43 | N28: 183369.03
A29: Client Lead Wages | B29: 9961.08 | C29: 13850.26 | D29: 12790.54 | E29: 14571.45 | F29: 28285.63 | G29: 26542.54 | H29: 28311.19 | I29: 28187.46 | J29: 30868.01 | K29: 31621.28 | L29: 28449.74 | M29: 32722.11 | N29: 286161.29
A30: Occupancy Tax Specialist | M30: 1113.35 | N30: 1113.35
A31: Onboarding Team Wages | B31: 9137.28 | C31: 8962.96 | D31: 10195.84 | E31: 15044.29 | F31: 16637.44 | G31: 7494.99 | H31: 7982.02 | I31: 5902.74 | J31: 7767.63 | K31: 8214.17 | L31: 12622.72 | M31: 12850.47 | N31: 122812.55
A32: Total Direct Labor | B32: 28653.36 | C32: 32368.22 | D32: 33383.58 | E32: 44615.41 | F32: 62932.87 | G32: 47928.8 | H32: 50341.45 | I32: 47481.11 | J32: 53304.95 | K32: 55717.98 | L32: 68261.13 | M32: 68467.36 | N32: 593456.22
A33: Payment Collection Fees | B33: 617.9 | C33: 837.4 | D33: 629.36 | E33: 682.45 | F33: 721.51 | G33: 787.47 | H33: 655.62 | I33: 794.91 | J33: 690.63 | K33: 717.61 | L33: 737.95 | M33: 798.18 | N33: 8670.99
A34: Referral Fees | B34: 2210 | C34: 2735 | D34: 2715 | E34: 2735 | F34: 780 | G34: 3245 | H34: 1280 | I34: 1300 | J34: 1810 | K34: 1820 | L34: 1835 | M34: 2355 | N34: 24820
A35: Software & Apps - COGS | B35: 7073 | C35: 7018.18 | D35: 7777.88 | E35: 7761.24 | F35: 7718.21 | G35: 8912.64 | H35: 10846.68 | I35: 11135.14 | J35: 11034.5 | K35: 11728.73 | L35: 11446.91 | M35: 11969.58 | N35: 114422.69
A36: Total Cost of Goods Sold | B36: 39853.6 | C36: 42988.92 | D36: 44516.45 | E36: 55797.35 | F36: 72153.24 | G36: 60873.91 | H36: 63123.75 | I36: 60713.1 | J36: 66840.08 | K36: 69984.32 | L36: 82280.99 | M36: 83590.12 | N36: 742715.83
A37: Gross Profit | B37: 41059.5 | C37: 38266.78 | D37: 33595.75 | E37: 27555.95 | F37: 18042.91 | G37: 29041.89 | H37: 41558.3 | I37: 43403.65 | J37: 31532.67 | K37: 29074.58 | L37: 26956.31 | M37: 32161.73 | N37: 392250.02
A38: Expenses
A39: General & Admin Expenses | N39: 0
A40: Bank Fees | B40: 1 | C40: 1 | D40: 1 | E40: 96 | F40: 2 | G40: 1 | H40: 5.63 | I40: 1 | J40: 1 | K40: 4.17 | L40: 9.42 | M40: 24.67 | N40: 147.89
A41: Employee Benefits | N41: 0
...

Sheet Raw - 2025 PL
A1: Keystone Bookkeepers
A2: Profit and Loss
A3: January - December 2025
B5: Jan 2025 | C5: Feb 2025 | D5: Mar 2025 | E5: Apr 2025 | F5: May 2025 | G5: Jun 2025 | H5: Jul 2025 | I5: Aug 2025 | J5: Sep 2025 | K5: Oct 2025 | L5: Nov 2025 | M5: Dec 2025 | N5: Total
A6: Income
A7: Income Tax Revenue | N7: 0
A8: Business Income Tax | J8: 875 | K8: 0 | L8: 0 | M8: 875 | N8: 1750
A9: Individual Income Tax | J9: 0 | K9: 1650 | N9: 1650
A10: Total Income Tax Revenue | B10: 0 | C10: 0 | D10: 0 | E10: 0 | F10: 0 | G10: 0 | H10: 0 | I10: 0 | J10: 875 | K10: 1650 | L10: 0 | M10: 875 | N10: 3400
A11: Non-Recurring Revenue | N11: 0
A12: 1099 Filing | B12: 13485 | C12: 9915 | D12: 60 | E12: 30 | I12: 30 | J12: 30 | N12: 23550
A13: Billable Expense Income | B13: 25 | C13: 399.6 | F13: 72.94 | H13: 289.71 | I13: 309.69 | M13: 25 | N13: 1121.94
A14: Offshore Recruiting | B14: 100 | D14: 100 | N14: 200
A15: Profit Share | B15: 7358.4 | C15: 1293.35 | D15: 968.33 | E15: 1165.6 | F15: 960.93 | G15: 1711.27 | H15: 1047.07 | I15: 2040.88 | J15: 1136.21 | K15: 2014.24 | L15: 1297.58 | M15: 2267.93 | N15: 23261.79
A16: Total Non-Recurring Revenue | B16: 20968.4 | C16: 11607.95 | D16: 1128.33 | E16: 1195.6 | F16: 1033.87 | G16: 1711.27 | H16: 1336.78 | I16: 2380.57 | J16: 1166.21 | K16: 2014.24 | L16: 1297.58 | M16: 2292.93 | N16: 48133.73
A17: Onboarding Revenue | N17: 0
A18: Historical Cleanup | B18: 1083.75 | C18: 2000 | D18: 1355 | K18: 595 | N18: 5033.75
A19: Onboarding | B19: 3079 | C19: 700 | D19: 10438.55 | E19: 4300 | F19: 11140 | G19: 6162.5 | H19: 6434 | I19: 3965 | J19: 3920 | K19: 9136.5 | L19: 5253.75 | M19: 9990 | N19: 74519.3
A20: Total Onboarding Revenue | B20: 4162.75 | C20: 2700 | D20: 11793.55 | E20: 4300 | F20: 11140 | G20: 6162.5 | H20: 6434 | I20: 3965 | J20: 3920 | K20: 9731.5 | L20: 5253.75 | M20: 9990 | N20: 79553.05
A21: SMB Bookkeeping Subscription | B21: 14562.5 | C21: 12802.5 | D21: 12402.5 | E21: 12602.5 | F21: 12752.5 | G21: 12792.5 | H21: 12537.5 | I21: 11857.5 | J21: 12302.5 | K21: 11692.5 | L21: 11717.5 | M21: 11747.5 | N21: 149770
A22: STR Recurring Revenue | N22: 0
A23: Controller Services | B23: 4450 | C23: 3450 | D23: 3450 | E23: 5950 | F23: 5200 | G23: 5000 | H23: 4000 | I23: 2950 | J23: 3025 | K23: 3025 | L23: 2950 | M23: 2950 | N23: 46400
A24: Occupancy Taxes | B24: 1130 | C24: 2140 | D24: 2660 | E24: 3650 | F24: 3623 | G24: 4964 | H24: 5058.5 | I24: 4730 | J24: 4820 | K24: 5370 | L24: 8050 | M24: 8885 | N24: 55080.5
A25: STR Bill Pay | B25: 970 | C25: 1100 | D25: 1735 | E25: 2140 | F25: 2363 | G25: 3263.5 | H25: 3920 | I25: 3905 | J25: 3780 | K25: 3795 | L25: 4330 | M25: 5305 | N25: 36606.5
A26: STR Bookkeeping Subscription | B26: 92418.9 | C26: 94002.15 | D26: 101506.05 | E26: 106137.5 | F26: 115938.75 | G26: 119431.25 | H26: 122094 | I26: 130085.25 | J26: 133590.5 | K26: 139609 | L26: 145280.75 | M26: 150398.25 | N26: 1450492.4
A27: Topkey Subscription | J27: 520 | K27: 2357 | L27: 2811 | M27: 4259 | N27: 9947
A28: Total STR Recurring Revenue | B28: 98968.9 | C28: 100692.15 | D28: 109351.05 | E28: 117877.5 | F28: 127124.75 | G28: 132658.75 | H28: 135072.5 | I28: 141670.25 | J28: 145735.5 | K28: 154156 | L28: 163421.75 | M28: 171797.25 | N28: 1598526.4
A29: Total Income | B29: 138662.55 | C29: 127802.6 | D29: 134675.43 | E29: 135975.6 | F29: 152051.12 | G29: 153325.02 | H29: 155380.78 | I29: 159873.32 | J29: 163999.21 | K29: 179244.24 | L29: 181690.58 | M29: 196702.68 | N29: 1879383.1
A30: Cost of Goods Sold
A31: 1099 Filing Fees | B31: 1226.55 | C31: 0 | D31: 1154.33 | E31: 0 | F31: 0 | G31: 0 | H31: 0 | I31: 0 | J31: 0 | K31: 113.45 | L31: 0 | M31: 0 | N31: 2494.33
A32: Contract Labor - Tax | K32: 1150 | L32: 437.5 | N32: 1587.5
A33: Direct Labor | N33: 0
A34: Bookkeeper Wages | B34: 19402.33 | C34: 16400.53 | D34: 19569.83 | E34: 22154.2 | F34: 20791.54 | G34: 21040.79 | H34: 27908.91 | I34: 29547 | J34: 33447.27 | K34: 37794.32 | L34: 34063.32 | M34: 34064.58 | N34: 316184.62
A35: Client Lead Wages | B35: 32780.76 | C35: 23361.84 | D35: 26914.27 | E35: 28812.98 | F35: 30658.75 | G35: 29271.6 | H35: 29479.63 | I35: 26830.64 | J35: 29785.55 | K35: 32899.37 | L35: 29493.34 | M35: 32669.71 | N35: 352958.44
A36: Occupancy Tax Specialist | B36: 2179.17 | C36: 1825.04 | D36: 1978.53 | E36: 2062.13 | F36: 2062.13 | G36: 1989.68 | H36: 2179.17 | I36: 2122.93 | J36: 3104.2 | K36: 3271.37 | L36: 3639.47 | M36: 3150.33 | N36: 29564.15
A37: Onboarding Team Wages | B37: 10345.56 | C37: 8087.98 | D37: 9752.87 | E37: 10280 | F37: 11136.32 | G37: 10874.32 | H37: 13472.57 | I37: 12704.07 | J37: 14698.84 | K37: 15543.06 | L37: 14343.61 | M37: 20930.52 | N37: 152169.72
A38: Total Direct Labor | B38: 64707.82 | C38: 49675.39 | D38: 58215.5 | E38: 63309.31 | F38: 64648.74 | G38: 63176.39 | H38: 73040.28 | I38: 71204.64 | J38: 81035.86 | K38: 89508.12 | L38: 81539.74 | M38: 90815.14 | N38: 850876.93
A39: Occupancy Tax Filing Fees | B39: 100 | E39: 149.8 | F39: 59.75 | G39: 69.7 | H39: 159.7 | I39: 310.85 | J39: 467.51 | K39: 517.51 | L39: -188.41 | M39: 109.5 | N39: 1755.91
A40: Payment Collection Fees | B40: 835.46 | C40: 1053.94 | D40: 870.69 | E40: 905.55 | F40: 911.57 | G40: 1002.49 | H40: 1224.75 | I40: 1104.38 | J40: 1297.23 | K40: 1217.39 | L40: 1622.94 | M40: 1305.14 | N40: 13351.53
A41: Referral Fees | B41: 1470.25 | C41: 1665 | D41: 2627.75 | E41: 1248.75 | F41: 2154 | G41: 4154 | H41: 3769.75 | I41: 1696 | J41: 2227.5 | K41: 1664.5 | L41: 1718.79 | M41: 2757.45 | N41: 27153.74
...

Sheet Raw - 2026 PL
A1: Keystone Bookkeepers
A2: Profit and Loss
A3: January - July, 2026
B5: Jan 2026 | C5: Feb 2026 | D5: Mar 2026 | E5: Apr 2026 | F5: May 2026 | G5: Jun 2026 | H5: Jul 2026 | I5: Total
A6: Income
A7: Income Tax Revenue | I7: 0
A8: Business Income Tax | B8: 0 | C8: 0 | D8: 14190 | E8: 4300 | G8: 3100 | I8: 21590
A9: Individual Income Tax | B9: 0 | C9: 0 | D9: 0 | E9: 2325 | I9: 2325
A10: Total Income Tax Revenue | B10: 0 | C10: 0 | D10: 14190 | E10: 6625 | F10: 0 | G10: 3100 | H10: 0 | I10: 23915
A11: Non-Recurring Revenue | I11: 0
A12: 1099 Filing | B12: 6105 | C12: 31156.5 | D12: 1260 | E12: 180 | I12: 38701.5
A13: Billable Expense Income | B13: 159.84 | D13: 75 | G13: 22.99 | I13: 257.83
A14: Profit Share | B14: 2677.84 | C14: 2354.01 | D14: 227.6 | E14: 1478.36 | F14: 668.24 | G14: 586.13 | H14: 87.2 | I14: 8079.38
A15: Total Non-Recurring Revenue | B15: 8942.68 | C15: 33510.51 | D15: 1562.6 | E15: 1658.36 | F15: 668.24 | G15: 609.12 | H15: 87.2 | I15: 47038.71
A16: Onboarding Revenue | I16: 0
A17: Onboarding | B17: 10210.5 | C17: 6675 | D17: 9099 | E17: 8954.5 | F17: 12606 | G17: 5411.5 | H17: 6098.5 | I17: 59055
A18: Total Onboarding Revenue | B18: 10210.5 | C18: 6675 | D18: 9099 | E18: 8954.5 | F18: 12606 | G18: 5411.5 | H18: 6098.5 | I18: 59055
A19: SMB Bookkeeping Subscription | B19: 11280.5 | C19: 10930.5 | D19: 10625.5 | E19: 10315.5 | F19: 10315.5 | G19: 9975.5 | H19: 9975.5 | I19: 73418.5
A20: STR Recurring Revenue | I20: 0
A21: Controller Services | B21: 2750 | C21: 3500 | D21: 2750 | E21: 4750 | F21: 3500 | G21: 3500 | H21: 3500 | I21: 24250
A22: Occupancy Taxes | B22: 10909.52 | C22: 10334.97 | D22: 11175 | E22: 11953.11 | F22: 15040.71 | G22: 16168.68 | H22: 16069.15 | I22: 91651.14
A23: STR Bill Pay | B23: 6300 | C23: 6390 | D23: 6425 | E23: 6080 | F23: 6325 | G23: 6655 | H23: 6955 | I23: 45130
A24: STR Bookkeeping Subscription | B24: 156538.8 | C24: 164903.4 | D24: 170344.25 | E24: 183662 | F24: 190784.4 | G24: 194406.5 | H24: 200837.5 | I24: 1261476.9
A25: Topkey Subscription | B25: 5254 | C25: 5652 | D25: 5324 | E25: 6321 | F25: 6959 | G25: 7673 | H25: 7903 | I25: 45086
A26: Total STR Recurring Revenue | B26: 181752.32 | C26: 190780.37 | D26: 196018.25 | E26: 212766.11 | F26: 222609.11 | G26: 228403.18 | H26: 235264.65 | I26: 1467594
A27: Total Income | B27: 212186 | C27: 241896.38 | D27: 231495.35 | E27: 240319.47 | F27: 246198.85 | G27: 247499.3 | H27: 251425.85 | I27: 1671021.2
A28: Cost of Goods Sold
A29: 1099 Filing Fees | B29: 2494.8 | C29: 0 | D29: 0 | E29: 709.81 | F29: 0 | G29: 0 | H29: 0 | I29: 3204.61
A30: Contract Labor - Tax | C30: 3000 | D30: 16265.5 | E30: 2800 | G30: 8450 | I30: 30515.5
A31: Direct Labor | I31: 0
A32: Bookkeeper Wages | B32: 38378.88 | C32: 29701.52 | D32: 37422.5 | E32: 38772.3 | F32: 38294.77 | G32: 40699.83 | H32: 44487.6 | I32: 267757.4
A33: Client Lead Wages | B33: 26114.9 | C33: 21905.5 | D33: 30758.44 | E33: 31590.38 | F33: 27699.92 | G33: 31240.24 | H33: 32743.71 | I33: 202053.09
A34: Occupancy Tax Specialist | B34: 1691.16 | C34: 5549.19 | D34: 7199.9 | E34: 8192.7 | F34: 8283.35 | G34: 5492.65 | H34: 5676.1 | I34: 42085.05
A35: Onboarding Team Wages | B35: 16553.94 | C35: 11526.61 | D35: 14938.83 | E35: 15583.52 | F35: 19603.4 | G35: 16644.57 | H35: 16429.12 | I35: 111279.99
A36: Sr. Client Lead Wages | F36: 2517.06 | G36: 2721.17 | H36: 2756.77 | I36: 7995
A37: Total Direct Labor | B37: 82738.88 | C37: 68682.82 | D37: 90319.67 | E37: 94138.9 | F37: 96398.5 | G37: 96798.46 | H37: 102093.3 | I37: 631170.53
A38: Occupancy Tax Filing Fees | B38: 229.4 | C38: 119.4 | D38: 179.35 | E38: 69.9 | F38: 69.9 | G38: 163.98 | H38: 707.56 | I38: 1539.49
A39: Payment Collection Fees | B39: 1229.74 | C39: 1738.47 | D39: 1353.48 | E39: 1233.99 | F39: 1171.37 | G39: 1153.92 | H39: 1145.87 | I39: 9026.84
A40: Referral Fees | B40: 1868.8 | C40: 4439.91 | D40: 2393.61 | E40: 3657.86 | F40: 2933.79 | G40: 1566.2 | H40: 3769.52 | I40: 20629.69
A41: Software & Apps - COGS | B41: 18468.3 | C41: 17920.27 | D41: 18409.06 | E41: 21387.75 | F41: 23445.84 | G41: 24674.67 | H41: 27975.68 | I41: 152281.57
...
