Workbook
Name __CF96: #REF!
Name __CF96: #REF!
Name _apr1: #REF!
Name _apr1: #REF!
Name _apr2: #REF!
Name _apr2: #REF!
Name _aug1: #REF!
Name _AUG3: #REF!
Name _CF96: #REF!
Name _feb021: #REF!
Name _feb023: #REF!
Name _IS96: #REF!
Name _jan021: #REF!
Name _JAN023: #REF!
Name _JF1: #REF!
Name _jul1: #REF!
Name _JUL3: #REF!
Name _may1: #REF!
Name _MAY3: #REF!
Name _NOV2: #REF!
Name _OCT1: #REF!
Name _OCT3: #REF!
Name _QTR32: #REF!
Name _QTR32: #REF!
Name _yr011: #REF!
Name _yr011: #REF!
Name _YR012: #REF!
Name _YR012: #REF!
Name a: #REF!
Name amparo: #REF!
Name amparo1: #REF!
Name amparo2: #REF!
Name area1: #REF!
Name area2: #REF!
Name area3: #REF!
Name area3: #REF!
Name awqwqw: #REF!
Name CF: #REF!
Name CompName: #REF!
Name FEB01YTD1: #REF!
Name FEB01YTD1: #REF!
Name JULY2: #REF!
Name LAST: #REF!
Name mr: #REF!
Name mr: #REF!
Name new: #REF!
Name new: #REF!
Name NINE1: #REF!
Name NINE2: #REF!
Name nov1st: #REF!
Name nov2nd: #REF!
Name OK: #REF!
Name old: #REF!
Name PeriodEnd: #REF!
Name Q3ONE: #REF!
Name Q3ONE: #REF!
Name Q3TWO: #REF!
Name Q3TWO: #REF!
Name q4one: #REF!
Name q4one: #REF!

Sheet Cover
B24: Keystone Bookkeepers
B25: Pre-LOI Business Analysis
B26: ="As of "&TEXT(TODAY(),"mm/dd/yy") -> As of 09/27/26

Sheet Offer Overview
B2: Keystone Bookkeepers
B3: Offer & Equity Upside Scenarios ($000s) | G3: Print | H3: 0
B5: Offer Price | C5: Today
B6: Run-Rate Revenue (PF Jul'26) | C6: 2998.541
B7: (x) Revenue Multiple — Implied | C7: 1.0004
B8: Total Valuation | C8: =C6*C7 -> 2999.7404
B10: Offer Components | C10: Amount | D10: % Total
B11: Topkey Equity | C11: 1450 | D11: =C11/$C$14 -> 0.48333333
B12: Rolled Keystone Equity | C12: =+C14-C13-C11 -> 900 | D12: =C12/$C$14 -> 0.3
B13: Cash at Close | C13: 650 | D13: =C13/$C$14 -> 0.21666667
B14: Total Valuation | C14: 3000 | D14: =C14/$C$14 -> 1
B15: Note: Total Valuation is calculated as 1.0x run-rate July'26 recurring revenue
B17: Future Value - Partnership
B18: Topkey Equity | D18: =C18/$C$21 -> 0
B19: Rolled Keystone Equity | D19: =C19/$C$21 -> 0
B20: Cash at Close | C20: =+C13 -> 650 | D20: =C20/$C$21 -> 1
B21: Total Valuation | C21: =SUM(C18:C20) -> 650 | D21: =C21/$C$21 -> 1
B23: Future Value - Standalone
B24: Topkey Equity | C24: 0 | D24: =C24/$C$21 -> 0
B25: Keystone Equity | D25: =C25/$C$21 -> 0
B26: Cash at Close | C26: 0 | D26: =C26/$C$21 -> 0
B27: Total Valuation | C27: =SUM(C24:C26) -> 0 | D27: =C27/$C$21 -> 0
B29: Partnership vs. Standalone | C29: Variance | D29: % Change
B30: Increase in Revenue | C30: =+'Ben''s Partnership Model'!C42 -> 2993.6651
B31: Increase in Valuation | C31: =+C21-C27 -> 650
B32: Increase in Annual Net Client Wins
B33: Increase in Annual Net CFO Client Wins
B49: (-) Cash at Close | C49: 650
B50: Topkey Equity Consideration | C50: =C8-C49 -> 2349.7404
B52: Topkey Pre-Deal Valuation | C52: 50000
B53: (+) Keystone Value Acquired | C53: =$C$8 -> 2999.7404
B54: (-) Cash Paid at Close | C54: =$C$49 -> 650
B55: Topkey Post-Money Valuation | C55: =C52+C53-C54 -> 52349.74
B56: Ben's Implied Topkey Ownership % | C56: =IFERROR($C$50/$C$55,0) -> 0.044885427
B57: Keystone Enterprise Value Today | C57: =$C$8 -> 2999.7404
B58: Existing Shareholders' Value Post-Close | C58: =(1-$C$56)*$C$55 -> 50000
B60: Topkey Pre-Deal Valuation | C60: =$C$52 -> 50000
B61: (-) Cash Paid at Close | C61: =$C$54 -> 650
B62: Topkey ex-Keystone Growth Base | C62: =C60-C61 -> 49350
B64: Scenario 1 — Ben Retains 100% of Keystone | C64: Today | D64: 2.0x Valuation | E64: 3.0x Valuation
...

Sheet Ben's Partnership Model
B2: Keystone Bookkeepers
B3: Partnership Rollover Scenarios ($000s) | G3: Print | H3: 0
B5: General Assumptions | C5: Value | F5: Rationale / Notes
B6: Ben's Rollover % — Keystone | C6: 0.3 | F6: Input — share of Keystone Ben keeps; Topkey buys the rest for cash + Topkey equity
B7: Horizon (Years) | C7: 5 | F7: Input — projection horizon for the Year 5 columns
B8: Est. Topkey Dilution — Ben's Stake (Year 5) | C8: 0.1 | F8: Input — future Topkey equity issuance (capital raise, option pool, acquisitions) reduces Ben's Topkey % by this share by Year 5
B9: Current Topkey Valuation | C9: 50000
B10: Topkey - Current Monthly Revenue | C10: 261.5 | F10: Based on Aug'26 financials
B11: Topkey - Current Run-Rate Revenue | C11: =C10*12 -> 3138
B12: Topkey - Current ARR Revenue Multiple | C12: =C9/C11 -> 15.933716
B13: Topkey - Future ARR Revenue Multiple | C13: =C12 -> 15.933716 | F13: Held flat at the current implied multiple
B14: Topkey - Current Client Count | C14: 325 | F14: Input — Topkey-provided client count; pending confirmation
B15: Topkey - Avg. Revenue Per Client | C15: =C11/C14 -> 9.6553846
B16: Topkey - Annual Net Client Wins | C16: ='Offer Comparison'!$C$20 -> 65 | F16: Input on Offer Comparison (C20). AMB placeholder; pending confirmation
B17: Total Net Client Wins | C17: =C16*$C$7 -> 325
B18: Total Additional Revenue | C18: =C17*C15 -> 3138
B19: ="Check - "&$C$7&" Year Topkey Valuation Growth" -> Check - 5 Year Topkey Valuation Growth | C19: =IFERROR(D80/C80-1,0) -> 1.0131712 | F19: % growth in Topkey ex-Keystone value (row 84), today → Year 5; value net of cash paid, not revenue
B21: Keystone Standalone Assumptions
B22: Revenue Multiple | C22: 1 | F22: Input — Keystone valued at 1.0x revenue today
B23: Scaled Revenue Multiple | C23: 1.25 | F23: Input — Keystone standalone revenue multiple at Year 5
B24: Avg. Revenue Per Client | C24: 16.631473 | F24: Input — Sep'26 annualized fee per non-tax client
B25: Target Monthly Net Client Wins | C25: 3 | F25: Input — Core bookkeeping net client growth: FY24 not tracked at core level; FY25 +44 (~3.7/month); LTM Sep'26 +26 (~2.2/month). See build at rows 167-172
B26: Annual Net Client Wins | C26: =C25*12 -> 36
B27: Total Net Client Wins | C27: =C26*$C$7 -> 180
B28: Total Additional Revenue | C28: =C27*C24 -> 2993.6651
B30: Keystone Partnership Assumptions
B31: Software-Integration Revenue Multiple | C31: 2 | F31: Input — revenue multiple with Topkey software integration
B32: VR Platform Run-Rate Tech Cost | C32: 240 | F32: Input — run-rate tech cost provided by Keystone; see platform-fee memo (rows 174-185)
B33: VR Platform Cost / Client
B35: =+B24 -> Avg. Revenue Per Client | C35: =+C24 -> 16.631473
B37: =+B26 -> Annual Net Client Wins | C37: =+C26 -> 36
B38: (+) Additional Annual Net Client Wins From Topkey | C38: 36
B39: Total Annual Net Client Wins | C39: =SUM(C37:C38) -> 72
B40: Total Net Client Wins | C40: =C39*$C$7 -> 360
B41: Total Additional Revenue | C41: =C40*C35 -> 5987.3303
B42: Increase in Keystone Revenue vs. Standalone | C42: =C41-C28 -> 2993.6651
B44: Cash Earnout — Year 3 Keystone Revenue (Sliding Scale)
B45: Earnout Measurement Year | C45: 3 | F45: Earnout measured on Year 3 run-rate: average of months 34–36 × 12 (window in C60)
B46: Keystone Revenue at Close | C46: =C148 -> 2998.541 | F46: PF Jul'26 run-rate revenue at close (C152)
B47: Year 3 Run-Rate Revenue Target | C47: =C46+C41*(C45-(C56-1)/2/12)/C7 -> 6491.1503 | F47: Run-rate at close + partnership added revenue ramped to the midpoint of the averaging window (month 35 ÷ 60); same basis as the earnout measurement
...

Sheet Condensed P&L
A1: Topkey, Inc.
A2: Profit and Loss
A3: For the month ended August, 2026
B5: Jan 2023 | C5: Feb 2023 | D5: Mar 2023 | E5: Apr 2023 | F5: May 2023 | G5: Jun 2023 | H5: Jul 2023 | I5: Aug 2023 | J5: Sep 2023 | K5: Oct 2023 | L5: Nov 2023 | M5: Dec 2023 | N5: Jan 2024 | O5: Feb 2024 | P5: Mar 2024 | Q5: Apr 2024 | R5: May 2024 | S5: Jun 2024 | T5: Jul 2024 | U5: Aug 2024 | V5: Sep 2024 | W5: Oct 2024 | X5: Nov 2024 | Y5: Dec 2024 | Z5: Jan 2025 | AA5: Feb 2025 | AB5: Mar 2025 | AC5: Apr 2025 | AD5: May 2025 | AE5: Jun 2025 | AF5: Jul 2025 | AG5: Aug 2025 | AH5: Sep 2025 | AI5: Oct 2025 | AJ5: Nov 2025 | AK5: Dec 2025 | AL5: Jan 2026 | AM5: Feb 2026 | AN5: Mar 2026 | AO5: Apr 2026 | AP5: May 2026 | AQ5: Jun 2026 | AR5: Jul 2026 | AS5: Aug 2026 | AT5: YTD 2026 | AU5: 2025
A6: Income
A7: Customer Platform Fee - Revenue | B7: 0 | C7: 0 | D7: 0 | E7: 0 | F7: 0 | G7: 0 | H7: 0 | I7: 2964.93 | J7: 3441.94 | K7: 4592.17 | L7: 8712.13 | M7: 13095.5 | N7: 18089.37 | O7: 21184.19 | P7: 25553.9 | Q7: 24988.4 | R7: 24939.4 | S7: 29681.83 | T7: 30558.73 | U7: 31772.21 | V7: 34937.13 | W7: 34861.03 | X7: 36603.28 | Y7: 40226.09 | Z7: 47634.09 | AA7: 50486.44 | AB7: 63798.6 | AC7: 69443.49 | AD7: 71040.58 | AE7: 79098.82 | AF7: 85201.02 | AG7: 85244.04 | AH7: 100429.94 | AI7: 107351.74 | AJ7: 110416.22 | AK7: 125776.14 | AL7: 133115.98 | AM7: 137271.13 | AN7: 149658.79 | AO7: 154471.08 | AP7: 159780.56 | AQ7: 179120.57 | AR7: 203261.24 | AS7: 212201.09 | AT7: 1328880.4 | AU7: 995921.12
A8: Implementation Fees | B8: 0 | C8: 0 | D8: 0 | E8: 0 | F8: 0 | G8: 0 | H8: 0 | I8: 0 | J8: 0 | K8: 0 | L8: 0 | M8: 0 | N8: 0 | O8: 0 | P8: 0 | Q8: 0 | R8: 0 | S8: 0 | T8: 0 | U8: 0 | V8: 0 | W8: 0 | X8: 0 | Y8: 0 | Z8: 126.92 | AA8: 265.38 | AB8: 384.62 | AC8: 604.31 | AD8: 654.31 | AE8: 801.23 | AF8: 876.23 | AG8: 1053.15 | AH8: 1186.79 | AI8: 1475.48 | AJ8: 1713.94 | AK8: 1779.33 | AL8: 1867.79 | AM8: 1871.63 | AN8: 2294.71 | AO8: 2508.33 | AP8: 3149.94 | AQ8: 2511.71 | AR8: 2497.48 | AS8: 2568.63 | AT8: 19270.22 | AU8: 10921.69
A9: Interchange Revenue - AMEX | B9: 0 | C9: 0 | D9: 0 | E9: 0 | F9: 0 | G9: 0 | H9: 0 | I9: 0 | J9: 0 | K9: 0 | L9: 0 | M9: 0 | N9: 0 | O9: 0 | P9: 0 | Q9: 0 | R9: 0 | S9: 0 | T9: 0 | U9: 0 | V9: 0 | W9: 0 | X9: 0 | Y9: 0 | Z9: 0 | AA9: 0 | AB9: 0 | AC9: 0 | AD9: 0 | AE9: 0 | AF9: 0 | AG9: 0 | AH9: 0 | AI9: 0 | AJ9: 0 | AK9: 0 | AL9: 0 | AM9: 0 | AN9: 0 | AO9: 0 | AP9: 0 | AQ9: 0 | AR9: 8134.58 | AS9: 0 | AT9: 8134.58 | AU9: 0
A10: Interchange Share - Topkey | B10: 135.2 | C10: 261.48 | D10: 1317.57 | E10: 2070.4 | F10: 2114.53 | G10: 3267.79 | H10: 4339.31 | I10: 6467.25 | J10: 6648.08 | K10: 8248.23 | L10: 8771.72 | M10: -38811.91 | N10: 12769.28 | O10: 16478.9 | P10: 18637.52 | Q10: 20532.37 | R10: 22739.95 | S10: 23382.47 | T10: 26033.3 | U10: 29459.13 | V10: 25779.82 | W10: 26287.6 | X10: 25803.15 | Y10: 27760.46 | Z10: 33608.01 | AA10: 29675.68 | AB10: 35213.78 | AC10: 36939.21 | AD10: 39085.7 | AE10: 36427.74 | AF10: 44250.65 | AG10: 45918.22 | AH10: 42126.21 | AI10: 42006.24 | AJ10: 36722.11 | AK10: 51189.95 | AL10: 51748.98 | AM10: 52865.02 | AN10: 61141.18 | AO10: 63756.3 | AP10: 64086.66 | AQ10: 67902.07 | AR10: 68489.46 | AS10: 63912.68 | AT10: 493902.35 | AU10: 473163.5
A11: Contra Interchange Share | B11: 0 | C11: 0 | D11: 0 | E11: 0 | F11: 0 | G11: 0 | H11: 0 | I11: 0 | J11: 0 | K11: 0 | L11: 0 | M11: -50255.02 | N11: -12769 | O11: -14581 | P11: -17079 | Q11: -19313 | R11: -20735 | S11: -21576 | T11: -24561 | U11: -27348 | V11: -23678 | W11: -24265 | X11: -23674.94 | Y11: -42095.37 | Z11: -28649.48 | AA11: -21384.94 | AB11: -31827.62 | AC11: -33976.97 | AD11: -29041.63 | AE11: -34882.34 | AF11: -42616.89 | AG11: -41763.49 | AH11: -33072.73 | AI11: -38846.08 | AJ11: -35394.95 | AK11: -44157.49 | AL11: -44244.5 | AM11: -40994.38 | AN11: -47407.6 | AO11: -49195.06 | AP11: -50991.46 | AQ11: -51624.59 | AR11: -54391.74 | AS11: -49152.17 | AT11: -388001.5 | AU11: -415614.61
A12: Total Interchange Share - Topkey | B12: 135.2 | C12: 261.48 | D12: 1317.57 | E12: 2070.4 | F12: 2114.53 | G12: 3267.79 | H12: 4339.31 | I12: 6467.25 | J12: 6648.08 | K12: 8248.23 | L12: 8771.72 | M12: -38811.91 | N12: 0.28 | O12: 1897.9 | P12: 1558.52 | Q12: 1219.37 | R12: 2004.95 | S12: 1806.47 | T12: 1472.3 | U12: 2111.13 | V12: 2101.82 | W12: 2022.6 | X12: 2128.21 | Y12: -14334.91 | Z12: 4958.53 | AA12: 8290.74 | AB12: 3386.16 | AC12: 2962.24 | AD12: 10044.07 | AE12: 1545.4 | AF12: 1633.76 | AG12: 4154.73 | AH12: 9053.48 | AI12: 3160.16 | AJ12: 1327.16 | AK12: 7032.46 | AL12: 7504.48 | AM12: 11870.64 | AN12: 13733.58 | AO12: 14561.24 | AP12: 13095.2 | AQ12: 16277.48 | AR12: 14097.72 | AS12: 14760.51 | AT12: 105900.85 | AU12: 57548.89
A13: Operating Interest Income | B13: 0 | C13: 0 | D13: 0 | E13: 0 | F13: 0 | G13: 0 | H13: 0 | I13: 0 | J13: 0 | K13: 0 | L13: 0 | M13: 0 | N13: 0 | O13: 0 | P13: 0 | Q13: 0 | R13: 0 | S13: 0 | T13: 0 | U13: 0 | V13: 0 | W13: 0 | X13: 0 | Y13: 0 | Z13: 9045.22 | AA13: 8878.46 | AB13: 8678.27 | AC13: 10880.59 | AD13: 12861.95 | AE13: 15553.39 | AF13: 17422.54 | AG13: 22961.15 | AH13: 24701.44 | AI13: 18056.34 | AJ13: 17173.84 | AK13: 15651.18 | AL13: 13741.14 | AM13: 16372.14 | AN13: 15465.63 | AO13: 19055.24 | AP13: 19664.68 | AQ13: 21848.02 | AR13: 24995.1 | AS13: 31986.15 | AT13: 163128.1 | AU13: 181864.37
A14: Total Revenue | B14: 135.2 | C14: 261.48 | D14: 1317.57 | E14: 2070.4 | F14: 2114.53 | G14: 3267.79 | H14: 4339.31 | I14: 9432.18 | J14: 10090.02 | K14: 12840.4 | L14: 17483.85 | M14: -25716.41 | N14: 18089.65 | O14: 23082.09 | P14: 27112.42 | Q14: 26207.77 | R14: 26944.35 | S14: 31488.3 | T14: 32031.03 | U14: 33883.34 | V14: 37038.95 | W14: 36883.63 | X14: 38731.49 | Y14: 25891.18 | Z14: 61764.76 | AA14: 67921.02 | AB14: 76247.65 | AC14: 83890.63 | AD14: 94600.91 | AE14: 96998.84 | AF14: 105133.55 | AG14: 113413.07 | AH14: 135371.65 | AI14: 130043.72 | AJ14: 130631.16 | AK14: 150239.11 | AL14: 156229.39 | AM14: 167385.54 | AN14: 181152.71 | AO14: 190595.89 | AP14: 195690.38 | AQ14: 219757.78 | AR14: 252986.12 | AS14: 261516.38 | AT14: 1625314.2 | AU14: 1246256.1
A15: Cost of Goods Sold | M15: 0 | N15: 1762.03 | O15: 8164.9 | P15: 6045.75 | Q15: 5884.61 | R15: 6032.76 | S15: 6565.42 | T15: 5865.95 | U15: 5222.5 | V15: 5576.1 | W15: 5731.87 | X15: 6082.66 | Y15: 6283.77 | Z15: 12555.58 | AA15: 10728.93 | AB15: 13506.71 | AC15: 13785.76 | AD15: 15133.23 | AE15: 14820.05 | AF15: 19832.55 | AG15: 19724.73 | AH15: 22963.42 | AI15: 21069.45 | AJ15: 20882.85 | AK15: 20993.31 | AL15: 22418.19 | AM15: 21117.04 | AN15: 22635.94 | AO15: 23078.3 | AP15: 23901.23 | AQ15: 24059.21 | AR15: 25625.39 | AS15: 26236.49 | AT15: 189071.79 | AU15: 205996.57
A16: Gross Profit | B16: 135.2 | C16: 261.48 | D16: 1317.57 | E16: 2070.4 | F16: 2114.53 | G16: 3267.79 | H16: 4339.31 | I16: 9432.18 | J16: 10090.02 | K16: 12840.4 | L16: 17483.85 | M16: -25716.41 | N16: 16327.62 | O16: 14917.19 | P16: 21066.67 | Q16: 20323.16 | R16: 20911.59 | S16: 24922.88 | T16: 26165.08 | U16: 28660.84 | V16: 31462.85 | W16: 31151.76 | X16: 32648.83 | Y16: 19607.41 | Z16: 49209.18 | AA16: 57192.09 | AB16: 62740.94 | AC16: 70104.87 | AD16: 79467.68 | AE16: 82178.79 | AF16: 85301 | AG16: 93688.34 | AH16: 112408.23 | AI16: 108974.27 | AJ16: 109748.31 | AK16: 129245.8 | AL16: 133811.2 | AM16: 146268.5 | AN16: 158516.77 | AO16: 167517.59 | AP16: 171789.15 | AQ16: 195698.57 | AR16: 227360.73 | AS16: 235279.89 | AT16: 1436242.4 | AU16: 1040259.5
A18: Operating Expenses
A19: Personnel | B19: 26996.64 | C19: 25199.36 | D19: 16690.42 | E19: 32072.55 | F19: 58139.65 | G19: 56525.89 | H19: 52094.4 | I19: 41179.64 | J19: 44182.22 | K19: 46570.86 | L19: 32655.49 | M19: 63594.62 | N19: 56935.52 | O19: 58842.55 | P19: 59021.71 | Q19: 58903.41 | R19: 95941.7 | S19: 64429.87 | T19: 79591.57 | U19: 83469.76 | V19: 78799.31 | W19: 72583.64 | X19: 94251.31 | Y19: 79983.68 | Z19: 88098.15 | AA19: 111545.07 | AB19: 94617.1 | AC19: 116343.01 | AD19: 120406.67 | AE19: 116916.48 | AF19: 113732.56 | AG19: 156380.56 | AH19: 143198.3 | AI19: 117971.66 | AJ19: 147759 | AK19: 170966.44 | AL19: 145774.2 | AM19: 128955.32 | AN19: 155547.48 | AO19: 160134.68 | AP19: 153570.33 | AQ19: 151976.51 | AR19: 149483.09 | AS19: 159372.43 | AT19: 1204814 | AU19: 1497935
A20: Professional & Other Services | B20: 28231.56 | C20: 28110.76 | D20: 53083.12 | E20: 29433.31 | F20: 41370.43 | G20: 42673.81 | H20: 60062.77 | I20: 56208.52 | J20: 57859.86 | K20: 55752.11 | L20: 54126.76 | M20: 63425.01 | N20: 60043.59 | O20: 51244.87 | P20: 44939.41 | Q20: 51595.66 | R20: 51556.73 | S20: 50645.2 | T20: 59702.05 | U20: 51472.05 | V20: 59848.05 | W20: 59065.05 | X20: 58230.3 | Y20: 83261.52 | Z20: 51021.73 | AA20: 55469.82 | AB20: 73605.8 | AC20: 65540.3 | AD20: 58845.3 | AE20: 69511.45 | AF20: 103903.8 | AG20: 74193.3 | AH20: 66966.3 | AI20: 71369.3 | AJ20: 88436.8 | AK20: 113061.76 | AL20: 78788.06 | AM20: 71422.2 | AN20: 77643.63 | AO20: 78073.65 | AP20: 80965.59 | AQ20: 84513.34 | AR20: 70857.17 | AS20: 65389.36 | AT20: 607653 | AU20: 891925.66
A21: General & Administrative Expenses | B21: 4209.26 | C21: 5976.39 | D21: 20985.52 | E21: 17292.07 | F21: 16789.84 | G21: 20837.73 | H21: 12846.41 | I21: 13789.59 | J21: 11901.22 | K21: 17980.22 | L21: 14356.61 | M21: 21523.38 | N21: 20665.24 | O21: 8095.46 | P21: 14564.28 | Q21: 18472 | R21: 25789.83 | S21: 17751.24 | T21: 29244.41 | U21: 13760.17 | V21: 29976.1 | W21: 25652.27 | X21: 20577.7 | Y21: 33015.78 | Z21: 25330.08 | AA21: 25538.53 | AB21: 36041.05 | AC21: 24107.14 | AD21: 44449.41 | AE21: 36695.62 | AF21: 40107.18 | AG21: 27254.81 | AH21: 50799.13 | AI21: 45464.07 | AJ21: 33007.12 | AK21: 53186.26 | AL21: 61269.04 | AM21: 55468.76 | AN21: 50052.16 | AO21: 40308.41 | AP21: 23001.25 | AQ21: 49673.43 | AR21: 40106.72 | AS21: 41056.15 | AT21: 360935.92 | AU21: 441980.4
A22: Other Operating Expenses | B22: 1911.16 | C22: 4898.83 | D22: 1364.74 | E22: 17802.68 | F22: 1334.92 | G22: 9881.05 | H22: 1389.74 | I22: 2960.06 | J22: 5012.51 | K22: 5314.06 | L22: 7043.13 | M22: 12267.81 | N22: 20309.48 | O22: 9665.45 | P22: 12444.16 | Q22: 4498.2 | R22: 11675.39 | S22: 11832.65 | T22: 3700.92 | U22: 7423.43 | V22: 3082.82 | W22: 7344.55 | X22: 6990.99 | Y22: 1514.39 | Z22: 12902.26 | AA22: 1794.87 | AB22: 4687.89 | AC22: 3587.56 | AD22: 3441.46 | AE22: 4529.3 | AF22: 9737.83 | AG22: 5672.93 | AH22: 3576.23 | AI22: 2633.15 | AJ22: 3447.48 | AK22: 1726.02 | AL22: 3885.85 | AM22: 2358.98 | AN22: 1801.28 | AO22: 801.72 | AP22: 2044.55 | AQ22: 3227.73 | AR22: 1847.95 | AS22: 1750.38 | AT22: 17718.44 | AU22: 57736.98
A24: Total Operating Expenses | B24: 61348.62 | C24: 64185.34 | D24: 92123.8 | E24: 96600.61 | F24: 117634.84 | G24: 129918.48 | H24: 126393.32 | I24: 114137.81 | J24: 118955.81 | K24: 125617.25 | L24: 108181.99 | M24: 160810.82 | N24: 157953.83 | O24: 127848.33 | P24: 130969.56 | Q24: 133469.27 | R24: 184963.65 | S24: 144658.96 | T24: 172238.95 | U24: 156125.41 | V24: 171706.28 | W24: 164645.51 | X24: 180050.3 | Y24: 197775.37 | Z24: 177352.22 | AA24: 194348.29 | AB24: 208951.84 | AC24: 209578.01 | AD24: 227142.84 | AE24: 227652.85 | AF24: 267481.37 | AG24: 263501.6 | AH24: 264539.96 | AI24: 237438.18 | AJ24: 272650.4 | AK24: 338940.48 | AL24: 289717.15 | AM24: 258205.26 | AN24: 285044.55 | AO24: 279318.46 | AP24: 259581.72 | AQ24: 289391.01 | AR24: 262294.93 | AS24: 267568.32 | AT24: 2191121.4 | AU24: 2889578
A25: EBITDA | B25: -61213.42 | C25: -63923.86 | D25: -90806.23 | E25: -94530.21 | F25: -115520.31 | G25: -126650.69 | H25: -122054.01 | I25: -104705.63 | J25: -108865.79 | K25: -112776.85 | L25: -90698.14 | M25: -186527.23 | N25: -141626.21 | O25: -112931.14 | P25: -109902.89 | Q25: -113146.11 | R25: -164052.06 | S25: -119736.08 | T25: -146073.87 | U25: -127464.57 | V25: -140243.43 | W25: -133493.75 | X25: -147401.47 | Y25: -178167.96 | Z25: -128143.04 | AA25: -137156.2 | AB25: -146210.9 | AC25: -139473.14 | AD25: -147675.16 | AE25: -145474.06 | AF25: -182180.37 | AG25: -169813.26 | AH25: -152131.73 | AI25: -128463.91 | AJ25: -162902.09 | AK25: -209694.68 | AL25: -155905.95 | AM25: -111936.76 | AN25: -126527.78 | AO25: -111800.87 | AP25: -87792.57 | AQ25: -93692.44 | AR25: -34934.2 | AS25: -32288.43 | AT25: -754879 | AU25: -1849318.5
A27: Interest, Taxes, Depreciation & Amortization | B27: 0 | C27: 0 | D27: 1328805 | E27: 825 | F27: 0 | G27: 0 | H27: 0 | I27: 0 | J27: 0 | K27: 0 | L27: 0 | M27: 9073.51 | N27: 1987.3 | O27: 4622.56 | P27: 2095.65 | Q27: 3220.64 | R27: 2070.63 | S27: 2070.62 | T27: 2445.61 | U27: 2117.18 | V27: 2217.19 | W27: 3394.68 | X27: 3120.7 | Y27: 2234.68 | Z27: 2234.68 | AA27: 4026 | AB27: 1257.89 | AC27: 1650.42 | AD27: 500.41 | AE27: 500.41 | AF27: 500.41 | AG27: 4419.3 | AH27: 4528.68 | AI27: 4644.67 | AJ27: 4572.24 | AK27: 4850.73 | AL27: 7750.42 | AM27: 5345.29 | AN27: 4900.42 | AO27: 6473.71 | AP27: 4900.42 | AQ27: 4773.71 | AR27: 4900.42 | AS27: 5000.42 | AT27: 44044.81 | AU27: 33685.84
A28: Operating Income (Loss) | B28: -61213.42 | C28: -63923.86 | D28: -1419611.2 | E28: -95355.21 | F28: -115520.31 | G28: -126650.69 | H28: -122054.01 | I28: -104705.63 | J28: -108865.79 | K28: -112776.85 | L28: -90698.14 | M28: -195600.74 | N28: -143613.51 | O28: -117553.7 | P28: -111998.54 | Q28: -116366.75 | R28: -166122.69 | S28: -121806.7 | T28: -148519.48 | U28: -129581.75 | V28: -142460.62 | W28: -136888.43 | X28: -150522.17 | Y28: -180402.64 | Z28: -130377.72 | AA28: -141182.2 | AB28: -147468.79 | AC28: -141123.56 | AD28: -148175.57 | AE28: -145974.47 | AF28: -182680.78 | AG28: -174232.56 | AH28: -156660.41 | AI28: -133108.58 | AJ28: -167474.33 | AK28: -214545.41 | AL28: -163656.37 | AM28: -117282.05 | AN28: -131428.2 | AO28: -118274.58 | AP28: -92692.99 | AQ28: -98466.15 | AR28: -39834.62 | AS28: -37288.85 | AT28: -798923.81 | AU28: -1883004.4
A30: Other Income | B30: 2365.48 | C30: 2140.12 | D30: 5771.04 | E30: 12188.38 | F30: 14108.62 | G30: 16084.31 | H30: 19328.48 | I30: 16211.08 | J30: 15571.01 | K30: 15509.79 | L30: 19737.4 | M30: 20697.51 | N30: 15584.31 | O30: 13807.27 | P30: 14226.52 | Q30: 16360.45 | R30: 14867.77 | S30: 15766.29 | T30: 18103.7 | U30: 16947.05 | V30: 16719.07 | W30: 14915.06 | X30: 13378.36 | Y30: 12654.88 | Z30: 3081.79 | AA30: 3207.46 | AB30: 2974.96 | AC30: 3453.99 | AD30: 6922.21 | AE30: 1679.2 | AF30: 474.32 | AG30: 2553.27 | AH30: 3044.56 | AI30: 4350.84 | AJ30: 4519.59 | AK30: 2068.21 | AL30: 3681.49 | AM30: 3137.78 | AN30: 4206.68 | AO30: 3375.3 | AP30: 2978.98 | AQ30: 3873.66 | AR30: 2623.04 | AS30: 3725.1 | AT30: 27602.03 | AU30: 38330.4
A31: Other Expenses | M31: 0 | N31: 0 | O31: 0 | P31: 0 | Q31: 0 | R31: 0 | S31: 34.58 | T31: 0 | U31: 41.32 | V31: 0 | W31: 0 | X31: 0 | Y31: 0 | Z31: 0 | AA31: 0 | AB31: 0 | AC31: 0 | AD31: 0 | AE31: 0 | AF31: 0 | AG31: 0 | AH31: 0 | AI31: 0 | AJ31: 0 | AK31: 0 | AL31: 0 | AM31: 0 | AN31: 0 | AO31: 0 | AP31: 0 | AQ31: 0 | AR31: 0 | AS31: 0 | AT31: 0 | AU31: 0
A32: Net Income (Loss) | B32: -58847.94 | C32: -61783.74 | D32: -1413840.2 | E32: -83166.83 | F32: -101411.69 | G32: -110566.38 | H32: -102725.53 | I32: -88494.55 | J32: -93294.78 | K32: -97267.06 | L32: -70960.74 | M32: -174903.23 | N32: -128029.2 | O32: -103746.43 | P32: -97772.02 | Q32: -100006.3 | R32: -151254.92 | S32: -106074.99 | T32: -130415.78 | U32: -112676.02 | V32: -125741.55 | W32: -121973.37 | X32: -137143.81 | Y32: -167747.76 | Z32: -127295.93 | AA32: -137974.74 | AB32: -144493.83 | AC32: -137669.57 | AD32: -141253.36 | AE32: -144295.27 | AF32: -182206.46 | AG32: -171679.29 | AH32: -153615.85 | AI32: -128757.74 | AJ32: -162954.74 | AK32: -212477.2 | AL32: -159974.88 | AM32: -114144.27 | AN32: -127221.52 | AO32: -114899.28 | AP32: -89714.01 | AQ32: -94592.49 | AR32: -37211.58 | AS32: -33563.75 | AT32: -771321.78 | AU32: -1844674
A35: Check Balance | B35: 0 | C35: 0 | D35: 0 | E35: 0 | F35: 0 | G35: 0 | H35: 0 | I35: 0 | J35: 0 | K35: 0 | L35: 0 | M35: 0 | N35: 0 | O35: 0 | P35: 0 | Q35: -670.66 | R35: -5 | S35: 0 | T35: 0 | U35: 0 | V35: 0 | W35: 0 | X35: 0 | Y35: 0 | Z35: 0 | AA35: 0 | AB35: 0 | AC35: 0 | AD35: 0 | AE35: 0 | AF35: 0 | AG35: 0 | AH35: 0 | AI35: 0 | AJ35: 0 | AK35: 0 | AL35: 0 | AM35: 0 | AN35: 0 | AO35: 0 | AP35: 0 | AQ35: 0 | AR35: 5.8207661e-11 | AS35: -5.8207661e-11
A37: Total Cash at End of Period | N37: 4394800.4 | O37: 4349809.8 | P37: 4168717 | Q37: 4061391.4 | R37: 3855622.6 | S37: 3723791 | T37: 3666813.7 | U37: 3504737.6 | V37: 3434417 | W37: 3356034.6 | X37: 3207939.8 | Y37: 3058500.5 | Z37: 2939136.8 | AA37: 2857256 | AB37: 2609063.5 | AC37: 2630200.5 | AD37: 2985816 | AE37: 2843294.9 | AF37: 3305383.5 | AG37: 3417314 | AH37: 3548725.8 | AI37: 3273845.2 | AJ37: 3233279.3 | AK37: 3061884.5 | AL37: 2801240.4 | AM37: 2691873.6 | AN37: 2639816.1 | AO37: 2534741.6 | AP37: 2264014.6 | AQ37: 2707565.8 | AR37: 2687899.9 | AS37: 2521756.4
A38: Unrestricted cash at end of Period * | N38: 4354800.4 | O38: 4309809.8 | P38: 4128717 | Q38: 4021391.4 | R38: 3815622.6 | S38: 3683791 | T38: 3626813.7 | U38: 3464737.6 | V38: 3394417 | W38: 3316034.6 | X38: 3167939.8 | Y38: 3018500.5 | Z38: 2899136.8 | AA38: 2817256 | AB38: 2569063.5 | AC38: 2590200.5 | AD38: 2945816 | AE38: 2803294.9 | AF38: 3265383.5 | AG38: 2877314 | AH38: 3008725.8 | AI38: 2733845.2 | AJ38: 2693279.3 | AK38: 2521884.5 | AL38: 2261240.4 | AM38: 2151873.6 | AN38: 2099816.1 | AO38: 1994741.6 | AP38: 1724014.6 | AQ38: 2167565.8 | AR38: 2147899.9 | AS38: 1981756.4
A39: Cash burn *** | N39: 142600.6 | O39: 44990.95 | P39: 181092.49 | Q39: 107325.02 | R39: 205768.42 | S39: 131832.02 | T39: 56977.29 | U39: 162075.79 | V39: 70320.64 | W39: 78382.35 | X39: 148094.84 | Y39: 149439.31 | Z39: 119363.66 | AA39: 81880.81 | AB39: 248192.5 | AC39: 78862.98 | AD39: 394384.48 | AE39: 142521.13 | AF39: 77911.43 | AG39: 388069.51 | AH39: -131411.79 | AI39: 274880.52 | AJ39: 40565.97 | AK39: 171394.82 | AL39: 260644.05 | AM39: 110519.45 | AN39: 52057.49 | AO39: 105074.45 | AP39: 270727.05 | AQ39: 3399.93 | AR39: 19665.88 | AS39: 166143.51
A40: Normalized Cash Burn (3 month average) | N40: 142600.6 | O40: 93795.775 | P40: 122894.68 | Q40: 111136.15 | R40: 164728.64 | S40: 148308.49 | T40: 131525.91 | U40: 116961.7 | V40: 96457.907 | W40: 103592.93 | X40: 98932.61 | Y40: 125305.5 | Z40: 138965.94 | AA40: 116894.59 | AB40: 149812.32 | AC40: 136312.1 | AD40: 240479.99 | AE40: 205256.2 | AF40: 204939.01 | AG40: 202834.02 | AH40: 111523.05 | AI40: 177179.41 | AJ40: 61344.9 | AK40: 162280.44 | AL40: 157534.95 | AM40: 180852.77 | AN40: 141073.66 | AO40: 89217.13 | AP40: 142619.66 | AQ40: 126400.48 | AR40: 97930.953 | AS40: 63069.773
A41: Cash runway **** | N41: 30.538444 | O41: 45.948869 | P41: 33.595572 | Q41: 36.184367 | R41: 23.163079 | S41: 24.838706 | T41: 27.574899 | U41: 29.622839 | V41: 35.190655 | W41: 32.010241 | X41: 32.021189 | Y41: 24.08913 | Z41: 20.862212 | AA41: 24.100824 | AB41: 17.148546 | AC41: 19.001986 | AD41: 12.249735 | AE41: 13.657541 | AF41: 15.93344 | AG41: 14.185559 | AH41: 26.97851 | AI41: 15.429813 | AJ41: 43.903882 | AK41: 15.540286 | AL41: 14.353897 | AM41: 11.898483 | AN41: 14.884536 | AO41: 22.358281 | AP41: 12.088197 | AQ41: 17.148399 | AR41: 21.932799 | AS41: 31.421651
A43: Net Quick Assets ** | N43: 4847670.5 | O43: 4744076.3 | P43: 4646456.6 | Q43: 4546603 | R43: 4395501.4 | S43: 4289579.4 | T43: 4157640 | U43: 4045163.1 | V43: 3912791.3 | W43: 3791134.8 | X43: 3654307.6 | Y43: 3486876.4 | Z43: 3354809.6 | AA43: 3217292.7 | AB43: 3071726.2 | AC43: 3034557.1 | AD43: 3643804.1 | AE43: 3504545.2 | AF43: 3857927.2 | AG43: 3683493.9 | AH43: 3530500.1 | AI43: 3399057.8 | AJ43: 3233147.3 | AK43: 3016112.4 | AL43: 2857583 | AM43: 2745563.7 | AN43: 2619314.6 | AO43: 2505387.6 | AP43: 2416645.9 | AQ43: 2323025.8 | AR43: 2286786.6 | AS43: 2254195.1
A44: Increase (Decrease) in Quick Assets | Y44: -167431.18 | Z44: -132066.84 | AA44: -137516.84 | AB44: -145566.51 | AC44: -37169.15 | AD44: 609247.05 | AE44: -139258.86 | AF44: 353381.99 | AG44: -174433.36 | AH44: -152993.74 | AI44: -131442.3 | AJ44: -165910.58 | AK44: -217034.85 | AL44: -158529.37 | AM44: -112019.3 | AN44: -126249.18 | AO44: -113926.94 | AP44: -88741.67 | AQ44: -93620.15 | AR44: -36239.24 | AS44: -32591.41
A45: Normalized Increase (Decrease) in Quick Assets (3 month average) | Y45: -167431.18 | Z45: -149749.01 | AA45: -145671.62 | AB45: -138383.4 | AC45: -106750.83 | AD45: 142170.46 | AE45: 144273.01 | AF45: 274456.73 | AG45: 13229.923 | AH45: 8651.63 | AI45: -152956.47 | AJ45: -150115.54 | AK45: -171462.58 | AL45: -180491.6 | AM45: -162527.84 | AN45: -132265.95 | AO45: -117398.47 | AP45: -109639.26 | AQ45: -98762.92 | AR45: -72867.02 | AS45: -54150.267
A46: Quick Assets Runway | Y46: 20.825729 | Z46: 22.402883 | AA46: 22.085927 | AB46: 22.197216 | AC46: 28.426542 | AD46: -25.629825 | AE46: -24.291066 | AF46: -14.056596 | AG46: -278.42141 | AH46: -408.07341 | AI46: 22.222387 | AJ46: 21.537725 | AK46: 17.5905 | AL46: 15.832222 | AM46: 16.892883 | AN46: 19.803393 | AO46: 21.340888 | AP46: 22.041793 | AQ46: 23.521234 | AR46: 31.383012 | AS46: 41.628514
A48: Number of FTEs | N48: 4 | O48: 4 | P48: 4 | Q48: 4 | R48: 4 | S48: 5 | T48: 4 | U48: 5 | V48: 5 | W48: 5 | X48: 5 | Y48: 12 | Z48: 14 | AA48: 14 | AB48: 14 | AC48: 15 | AD48: 15 | AE48: 15 | AF48: 17 | AG48: 17 | AH48: 15 | AI48: 16 | AJ48: 17 | AK48: 17 | AL48: 16 | AM48: 16 | AN48: 17 | AO48: 17 | AP48: 17 | AQ48: 16 | AR48: 16 | AS48: 17
A50: * Unrestricted Cash balance includes Total Cash (per the Balance Sheet) - $40k (Minimum balance to be maintained in 0792 account) -$500K (Warehouse Line Payable)
A51: ** Net Quick Assets = Unrestricted Cash (as defined above) + Accounts Receivable + Dispute Receivable + Felicis Pledge Receivable - Accounts Payable - Accrued Expenses - Payable to Bank - Credit Cards - Deferred Implementation Fees - Payroll liability - Earnings Credit Liability - Rewards Points Liability]
...

Sheet Offer Comparison
B2: =Cover!$B$24 -> Keystone Bookkeepers
B3: Offer Comparison — Partnership vs. 100% Buyout ($000s) | H3: Print | I3: 0
B5: Deal Assumptions | C5: Partnership | D5: 100% Buyout | E5: Variance | G5: Notes
B7: Horizon (Years) | C7: 5 | D7: =C7 -> 5 | E7: =C7-D7 -> 0 | G7: Input — drives Partnership and Buyout tabs (D = C)
B8: Est. Topkey Dilution — Ben's Stake (Year 5) | C8: 0.05 | D8: =C8 -> 0.05 | E8: =C8-D8 -> 0 | G8: Input — drives Partnership and Buyout tabs (D = C)
B9: Topkey Valuation Today — Pre-Deal | C9: 50000 | D9: =C9 -> 50000 | E9: =C9-D9 -> 0 | G9: Input — single Topkey valuation; drives Offer Overview, Partnership and Buyout tabs
B10: Topkey 5-Year Valuation Growth (ex-Keystone) | C10: ='Partnership Analysis'!$C$19 -> 1.0131712 | D10: ='100% Buyout Analysis'!$C$18 -> 1 | E10: =C10-D10 -> 0.013171226 | G10: Differs because each offer's cash at close is netted from Topkey's ex-Keystone base; measures value growth, not revenue
B11: Keystone 5-Yr Revenue Increase — Standalone (% of Start) | C11: =IFERROR('Partnership Analysis'!$C$28/'Partnership Analysis'!$C$47,0) -> 0.99837392 | D11: =IFERROR('100% Buyout Analysis'!$C$27/'100% Buyout Analysis'!$C$46,0) -> 0.99837392 | E11: =C11-D11 -> 0 | G11: Total additional standalone revenue ÷ Keystone run-rate revenue at close
B12: Keystone 5-Yr Revenue Increase — Partnership (% of Start) | C12: =IFERROR('Partnership Analysis'!$C$42/'Partnership Analysis'!$C$47,0) -> 1.6639565 | D12: =IFERROR('100% Buyout Analysis'!$C$41/'100% Buyout Analysis'!$C$46,0) -> 1.6639565 | E12: =C12-D12 -> 0 | G12: Total additional partnership revenue ÷ Keystone run-rate revenue at close
B13: Keystone Initial Revenue Multiple | C13: 1 | D13: =C13 -> 1 | E13: =C13-D13 -> 0 | G13: Input — drives Partnership and Buyout tabs (D = C)
B14: Keystone Scaled Revenue Multiple | C14: 1.25 | D14: =C14 -> 1.25 | E14: =C14-D14 -> 0 | G14: Input — drives Partnership and Buyout tabs (D = C)
B15: Keystone Software-Integration Revenue Multiple | C15: 2 | D15: =C15 -> 2 | E15: =C15-D15 -> 0 | G15: Input — drives Partnership and Buyout tabs (D = C)
B16: General Assumptions
B17: Ben's Rollover % — Keystone | C17: 0.3 | D17: 0 | E17: =C17-D17 -> 0.3 | G17: Input — share of Keystone Ben keeps (Partnership 30%; Buyout 0% = Topkey acquires 100%)
B18: Topkey - Current Monthly Revenue | C18: 261 | D18: =C18 -> 261 | E18: =C18-D18 -> 0 | G18: Input — drives Partnership and Buyout tabs (D = C). Topkey-provided monthly revenue ($000s); red = pending seller confirmation
B19: Topkey - Current Client Count | C19: 325 | D19: =C19 -> 325 | E19: =C19-D19 -> 0 | G19: Input — drives Partnership and Buyout tabs (D = C). Topkey-provided client count; red = pending seller confirmation
B20: Topkey - Annual Net Client Wins | C20: 65 | D20: =C20 -> 65 | E20: =C20-D20 -> 0 | G20: Input — drives Partnership and Buyout tabs (D = C). AMB placeholder; red = pending confirmation
B21: Cash at Close | C21: 650 | D21: ='100% Buyout Analysis'!$C$174 -> 500 | E21: =C21-D21 -> 150 | G21: Partnership cash at close set to cover Ben's tax situation
B22: Keystone Standalone Assumptions
B23: Avg. Revenue Per Client | C23: ='Steady-State Staffing'!$AB$8 -> 16.631473 | D23: =C23 -> 16.631473 | E23: =C23-D23 -> 0 | G23: Linked to Steady-State Staffing AB8 (Sep'26 annualized fee per non-tax client); drives both tabs (D = C)
B24: Improved Client Retention
B25: Target Monthly Net Client Wins | C25: 3 | D25: =C25 -> 3 | E25: =C25-D25 -> 0 | G25: Input — drives Partnership and Buyout tabs (D = C). AMB target pace; LTM actual is 26/yr (~2.2/month)
B26: Keystone Partnership Assumptions
B27: VR Platform Run-Rate Tech Cost | C27: 240 | D27: =C27 -> 240 | E27: =C27-D27 -> 0 | G27: Input — drives Partnership and Buyout tabs (D = C). Run-rate tech cost provided by the target; memo only
B28: Software-Enabled Price Increase / Client | C28: 0 | D28: =C28 -> 0 | E28: =C28-D28 -> 0 | G28: Input — drives Partnership and Buyout tabs (D = C). Only if Topkey software supports higher client fees
B29: Additional Annual Net Client Wins From Topkey | C29: 24 | D29: =C29 -> 24 | E29: =C29-D29 -> 0 | G29: Input — drives Partnership and Buyout tabs (D = C). Topkey-provided; red = pending seller confirmation
B31: Offer Structure | C31: Partnership | D31: 100% Buyout | E31: Variance
B32: Keystone Value Today (100%) | C32: ='Partnership Analysis'!$C$185 -> 3000 | D32: ='100% Buyout Analysis'!$C$173 -> 3000 | E32: =C32-D32 -> 0
B33: Ben's Rollover % — Keystone | C33: =C17 -> 0.3 | D33: =D17 -> 0 | E33: =C33-D33 -> 0.3 | G33: Linked to Ben's Rollover % input (row 17)
B34: Keystone Stake Acquired by Topkey | C34: ='Partnership Analysis'!$C$187 -> 0.7 | D34: ='100% Buyout Analysis'!$C$96 -> 1 | E34: =C34-D34 -> -0.3
B35: Price for Topkey's Stake (at Close) | C35: ='Partnership Analysis'!$C$188 -> 2100 | D35: ='100% Buyout Analysis'!$C$173 -> 3000 | E35: =C35-D35 -> -900
B36: Cash at Close | C36: ='Partnership Analysis'!$C$189 -> 650 | D36: ='100% Buyout Analysis'!$C$174 -> 500 | E36: =C36-D36 -> 150 | G36: Partnership cash of $650K is set to cover Ben's tax situation
B37: (+) Topkey Equity Issued to Ben | C37: ='Partnership Analysis'!$C$190 -> 1450 | D37: ='100% Buyout Analysis'!$C$175 -> 2500 | E37: =C37-D37 -> -1050
B38: (+) Target Cash Earnout (at 100% Achievement) — Year 3 | C38: ='Partnership Analysis'!$C$58 -> 0 | D38: ='100% Buyout Analysis'!$C$57 -> 500 | E38: =C38-D38 -> -500 | G38: Buyout: $500K target, capped at $750K (150% of target). Partnership: no earnout
B39: Total Consideration Paid by Topkey | C39: =SUM(C36:C38) -> 2100 | D39: =SUM(D36:D38) -> 3500 | E39: =C39-D39 -> -1400 | G39: Cash + equity issued + target earnout; tie-out to analysis tabs in row 38
B40: Tie Out — Consideration vs. Analysis Tab | C40: =C39-'Partnership Analysis'!$C$106 -> 0 | D40: =D39-'100% Buyout Analysis'!$C$95 -> 0 | G40: Must equal zero
B41: % of Consideration in Cash (incl. Earnout) | C41: =IFERROR((C36+C38)/C39,0) -> 0.30952381 | D41: =IFERROR((D36+D38)/D39,0) -> 0.28571429 | E41: =C41-D41 -> 0.023809524
B43: Where Ben's Year 5 Value Comes From | C43: Partnership | D43: 100% Buyout | E43: Variance
B45: Retained Keystone Stake (Direct) | C45: =IFERROR(C108/C$113,0) -> 0.57042373 | D45: =IFERROR(D108/D$113,0) -> 0 | E45: =C45-D45 -> 0.57042373
B46: Keystone via Topkey | C46: =IFERROR(C109/C$113,0) -> 0.035635314 | D46: =IFERROR(D109/D$113,0) -> 0.11654379 | E46: =C46-D46 -> -0.080908475
...

Sheet Partnership Analysis
B2: =Cover!$B$24 -> Keystone Bookkeepers
B3: Partnership Rollover Scenarios ($000s) | G3: Print | H3: 0
B5: Revenue Growth Assumptions | C5: Value | F5: Rationale / Notes
B6: General Assumptions
B7: Ben's Rollover % — Keystone | C7: ='Offer Comparison'!$C$17 -> 0.3 | F7: Input on Offer Comparison (C17). Share of Keystone Ben keeps; Topkey buys the rest for cash + Topkey equity
B8: Est. Topkey Dilution — Ben's Stake (Year 5) | C8: ='Offer Comparison'!$C$8 -> 0.05 | F8: Linked to Offer Comparison (C8). AMB estimate: future Topkey equity issuance (capital raise, option pool, acquisitions) reduces Ben's Topkey % by this share by Year 5
B9: Horizon (Years) | C9: ='Offer Comparison'!$C$7 -> 5 | F9: Linked to Offer Comparison (C7). Projection horizon for the Year 5 columns
B10: Topkey - Current Monthly Revenue | C10: ='Offer Comparison'!$C$18 -> 261 | F10: Input on Offer Comparison (C18). Topkey-provided monthly revenue ($000s); pending confirmation
B11: Topkey - Current Run-Rate Revenue | C11: =C10*12 -> 3132
B12: Topkey - Current Revenue Multiple | C12: =IFERROR(C191/C11,0) -> 15.96424 | F12: Implied: Topkey pre-deal valuation (C191) ÷ run-rate revenue (C11)
B13: Topkey - Future Revenue Multiple | C13: =C12 -> 15.96424 | F13: Held flat at the current implied multiple
B14: Topkey - Current Client Count | C14: ='Offer Comparison'!$C$19 -> 325 | F14: Input on Offer Comparison (C19). Topkey-provided client count; pending confirmation
B15: Topkey - Avg. Revenue Per Client | C15: =C11/C14 -> 9.6369231
B16: Topkey - Annual Net Client Wins | C16: ='Offer Comparison'!$C$20 -> 65 | F16: Input on Offer Comparison (C20). AMB placeholder; pending confirmation
B17: Total Net Client Wins | C17: =C16*$C$9 -> 325
B18: Total Additional Revenue | C18: =C17*C15 -> 3132
B19: ="Check - "&$C$9&" Year Topkey Valuation Growth" -> Check - 5 Year Topkey Valuation Growth | C19: =IFERROR(D81/C81-1,0) -> 1.0131712 | F19: % growth in Topkey ex-Keystone value (row 81), today → Year 5; value net of cash paid, not revenue
B21: Keystone Standalone Assumptions
B22: Revenue Multiple | C22: ='Offer Comparison'!$C$13 -> 1 | F22: Linked to Offer Comparison (C13). Keystone valued at 1.0x revenue today (offer implies ~1.0x)
B23: Scaled Revenue Multiple | C23: ='Offer Comparison'!$C$14 -> 1.25 | F23: Linked to Offer Comparison (C14). Keystone standalone revenue multiple at Year 5
B24: Avg. Revenue Per Client | C24: ='Offer Comparison'!$C$23 -> 16.631473 | F24: Input on Offer Comparison (C22). Sep'26 annualized fee per non-tax client (Steady-State Staffing AB8)
B25: Target Monthly Net Client Wins | C25: ='Offer Comparison'!$C$25 -> 3 | F25: Input on Offer Comparison (C23). AMB target pace; LTM actual is 26/yr (~2.2/month), see build at rows 200-204
B26: Annual Net Client Wins | C26: =C25*12 -> 36 | F26: Target monthly pace × 12
B27: Total Net Client Wins | C27: =C26*$C$9 -> 180
B28: Total Additional Revenue | C28: =C27*C24 -> 2993.6651
B30: Keystone Partnership Assumptions
B31: Software-Integration Revenue Multiple | C31: ='Offer Comparison'!$C$15 -> 2 | F31: Linked to Offer Comparison (C15). Revenue multiple with Topkey software integration
B32: VR Platform Run-Rate Tech Cost | C32: ='Offer Comparison'!$C$27 -> 240 | F32: Input on Offer Comparison (C25). Run-rate tech cost provided by the target; see platform-fee memo (rows 207-216)
B34: =+B24 -> Avg. Revenue Per Client | C34: =+C24 -> 16.631473
B35: (+) Software-Enabled Price Increase / Client | C35: ='Offer Comparison'!$C$28 -> 0 | F35: Input on Offer Comparison (C26). Only if Topkey software supports higher client fees; VR cost handled in the memo block (rows 207-216)
B36: Total Avg. Revenue Per Client | C36: =+C34+C35 -> 16.631473
B38: =+B26 -> Annual Net Client Wins | C38: =+C26 -> 36
B39: (+) Additional Annual Net Client Wins From Topkey | C39: ='Offer Comparison'!$C$29 -> 24 | F39: Input on Offer Comparison (C27). Topkey-provided; pending confirmation
B40: Total Annual Net Client Wins | C40: =SUM(C38:C39) -> 60
B41: Total Net Client Wins | C41: =C40*$C$9 -> 300
B42: Total Additional Revenue | C42: =C41*C36 -> 4989.4419
B43: Increase in Keystone Revenue vs. Standalone | C43: =C42-C28 -> 1995.7768
B45: Cash Earnout — Year 3 Keystone Revenue (Sliding Scale)
B46: Earnout Measurement Year | C46: 3 | F46: Earnout measured on Year 3 run-rate: average of months 34–36 × 12 (window in C57)
B47: Keystone Revenue at Close | C47: =C184 -> 2998.541 | F47: PF Jul'26 run-rate revenue at close (C184)
...

Sheet Partnership Sensitivity Tables
B2: =Cover!$B$24 -> Keystone Bookkeepers
B3: Partnership Sensitivity Tables ($000s) | N3: Print | O3: 1
B5: Ben's Return Profile Based on Partnering
B6: Ben's Net Returns Based on Topkey Growth & Rollover %
D8: Topkey ex-Keystone Value Growth (%) | S8: Helper: IRR Year Index | Z8: Helper: Unrounded Net Return
D9: =E9-$G$441 -> 0.013171226 | E9: =F9-$G$441 -> 0.26317123 | F9: =G9-$G$441 -> 0.51317123 | G9: =H9-$G$441 -> 0.76317123 | H9: =$G$440 -> 1.0131712 | I9: =H9+$G$441 -> 1.2631712 | J9: =I9+$G$441 -> 1.5131712 | K9: =J9+$G$441 -> 1.7631712 | L9: =K9+$G$441 -> 2.0131712 | N9: Helper: Rollover % | O9: Helper: Cash at Close | P9: Helper: Topkey Equity Issued | Q9: Helper: Topkey ex-Keystone Today | R9: Helper: Ben's Yr 5 Topkey % | S9: 0 | T9: =S9+1 -> 1 | U9: =T9+1 -> 2 | V9: =U9+1 -> 3 | W9: =V9+1 -> 4 | X9: =W9+1 -> 5 | Z9: =D$9 -> 0.013171226 | AA9: =E$9 -> 0.26317123 | AB9: =F$9 -> 0.51317123 | AC9: =G$9 -> 0.76317123 | AD9: =H$9 -> 1.0131712 | AE9: =I$9 -> 1.2631712 | AF9: =J$9 -> 1.5131712 | AG9: =K$9 -> 1.7631712 | AH9: =L$9 -> 2.0131712 | AT9: Helper: Gradient Band (0 = below $1M hurdle)
B10: Ben's Rollover % | C10: =C11-$G$439 -> 0.15 | D10: =ROUND(Z10,$G$452) -> 2300 | E10: =ROUND(AA10,$G$452) -> 2700 | F10: =ROUND(AB10,$G$452) -> 3100 | G10: =ROUND(AC10,$G$452) -> 3500 | H10: =ROUND(AD10,$G$452) -> 4000 | I10: =ROUND(AE10,$G$452) -> 4400 | J10: =ROUND(AF10,$G$452) -> 4800 | K10: =ROUND(AG10,$G$452) -> 5300 | L10: =ROUND(AH10,$G$452) -> 5700 | N10: =$C10 -> 0.15 | O10: =$G$433 -> 650 | P10: =$G$430*(1-N10)-O10 -> 1900 | Q10: =$G$432-O10 -> 49350 | R10: =IFERROR(P10/(Q10+$G$430*(1-N10)),0)*(1-$G$434) -> 0.03477842 | Z10: =$O10+$G$435+$N10*$G$431+$R10*($Q10*(1+D$9)+$G$431*(1-$N10))-$G$430 -> 2257.5919 | AA10: =$O10+$G$435+$N10*$G$431+$R10*($Q10*(1+E$9)+$G$431*(1-$N10))-$G$430 -> 2686.6707 | AB10: =$O10+$G$435+$N10*$G$431+$R10*($Q10*(1+F$9)+$G$431*(1-$N10))-$G$430 -> 3115.7494 | AC10: =$O10+$G$435+$N10*$G$431+$R10*($Q10*(1+G$9)+$G$431*(1-$N10))-$G$430 -> 3544.8282 | AD10: =$O10+$G$435+$N10*$G$431+$R10*($Q10*(1+H$9)+$G$431*(1-$N10))-$G$430 -> 3973.9069 | AE10: =$O10+$G$435+$N10*$G$431+$R10*($Q10*(1+I$9)+$G$431*(1-$N10))-$G$430 -> 4402.9857 | AF10: =$O10+$G$435+$N10*$G$431+$R10*($Q10*(1+J$9)+$G$431*(1-$N10))-$G$430 -> 4832.0644 | AG10: =$O10+$G$435+$N10*$G$431+$R10*($Q10*(1+K$9)+$G$431*(1-$N10))-$G$430 -> 5261.1432 | AH10: =$O10+$G$435+$N10*$G$431+$R10*($Q10*(1+L$9)+$G$431*(1-$N10))-$G$430 -> 5690.222 | AT10: =IF(Z50<$G$449,0,MIN($G$446,1+IFERROR(INT((Z50-$G$449)/$G$451),0))) -> 0 | AU10: =IF(AA50<$G$449,0,MIN($G$446,1+IFERROR(INT((AA50-$G$449)/$G$451),0))) -> 0 | AV10: =IF(AB50<$G$449,0,MIN($G$446,1+IFERROR(INT((AB50-$G$449)/$G$451),0))) -> 0 | AW10: =IF(AC50<$G$449,0,MIN($G$446,1+IFERROR(INT((AC50-$G$449)/$G$451),0))) -> 0 | AX10: =IF(AD50<$G$449,0,MIN($G$446,1+IFERROR(INT((AD50-$G$449)/$G$451),0))) -> 0 | AY10: =IF(AE50<$G$449,0,MIN($G$446,1+IFERROR(INT((AE50-$G$449)/$G$451),0))) -> 0 | AZ10: =IF(AF50<$G$449,0,MIN($G$446,1+IFERROR(INT((AF50-$G$449)/$G$451),0))) -> 0 | BA10: =IF(AG50<$G$449,0,MIN($G$446,1+IFERROR(INT((AG50-$G$449)/$G$451),0))) -> 0 | BB10: =IF(AH50<$G$449,0,MIN($G$446,1+IFERROR(INT((AH50-$G$449)/$G$451),0))) -> 1
C11: =C12-$G$439 -> 0.2 | D11: =ROUND(Z11,$G$452) -> 2900 | E11: =ROUND(AA11,$G$452) -> 3300 | F11: =ROUND(AB11,$G$452) -> 3700 | G11: =ROUND(AC11,$G$452) -> 4100 | H11: =ROUND(AD11,$G$452) -> 4400 | I11: =ROUND(AE11,$G$452) -> 4800 | J11: =ROUND(AF11,$G$452) -> 5200 | K11: =ROUND(AG11,$G$452) -> 5600 | L11: =ROUND(AH11,$G$452) -> 6000 | N11: =$C11 -> 0.2 | O11: =$G$433 -> 650 | P11: =$G$430*(1-N11)-O11 -> 1750 | Q11: =$G$432-O11 -> 49350 | R11: =IFERROR(P11/(Q11+$G$430*(1-N11)),0)*(1-$G$434) -> 0.032125604 | Z11: =$O11+$G$435+$N11*$G$431+$R11*($Q11*(1+D$9)+$G$431*(1-$N11))-$G$430 -> 2862.0634 | AA11: =$O11+$G$435+$N11*$G$431+$R11*($Q11*(1+E$9)+$G$431*(1-$N11))-$G$430 -> 3258.413 | AB11: =$O11+$G$435+$N11*$G$431+$R11*($Q11*(1+F$9)+$G$431*(1-$N11))-$G$430 -> 3654.7627 | AC11: =$O11+$G$435+$N11*$G$431+$R11*($Q11*(1+G$9)+$G$431*(1-$N11))-$G$430 -> 4051.1123 | AD11: =$O11+$G$435+$N11*$G$431+$R11*($Q11*(1+H$9)+$G$431*(1-$N11))-$G$430 -> 4447.462 | AE11: =$O11+$G$435+$N11*$G$431+$R11*($Q11*(1+I$9)+$G$431*(1-$N11))-$G$430 -> 4843.8116 | AF11: =$O11+$G$435+$N11*$G$431+$R11*($Q11*(1+J$9)+$G$431*(1-$N11))-$G$430 -> 5240.1612 | AG11: =$O11+$G$435+$N11*$G$431+$R11*($Q11*(1+K$9)+$G$431*(1-$N11))-$G$430 -> 5636.5109 | AH11: =$O11+$G$435+$N11*$G$431+$R11*($Q11*(1+L$9)+$G$431*(1-$N11))-$G$430 -> 6032.8605 | AT11: =IF(Z51<$G$449,0,MIN($G$446,1+IFERROR(INT((Z51-$G$449)/$G$451),0))) -> 0 | AU11: =IF(AA51<$G$449,0,MIN($G$446,1+IFERROR(INT((AA51-$G$449)/$G$451),0))) -> 0 | AV11: =IF(AB51<$G$449,0,MIN($G$446,1+IFERROR(INT((AB51-$G$449)/$G$451),0))) -> 0 | AW11: =IF(AC51<$G$449,0,MIN($G$446,1+IFERROR(INT((AC51-$G$449)/$G$451),0))) -> 0 | AX11: =IF(AD51<$G$449,0,MIN($G$446,1+IFERROR(INT((AD51-$G$449)/$G$451),0))) -> 0 | AY11: =IF(AE51<$G$449,0,MIN($G$446,1+IFERROR(INT((AE51-$G$449)/$G$451),0))) -> 0 | AZ11: =IF(AF51<$G$449,0,MIN($G$446,1+IFERROR(INT((AF51-$G$449)/$G$451),0))) -> 0 | BA11: =IF(AG51<$G$449,0,MIN($G$446,1+IFERROR(INT((AG51-$G$449)/$G$451),0))) -> 1 | BB11: =IF(AH51<$G$449,0,MIN($G$446,1+IFERROR(INT((AH51-$G$449)/$G$451),0))) -> 3
C12: =C13-$G$439 -> 0.25 | D12: =ROUND(Z12,$G$452) -> 3500 | E12: =ROUND(AA12,$G$452) -> 3800 | F12: =ROUND(AB12,$G$452) -> 4200 | G12: =ROUND(AC12,$G$452) -> 4600 | H12: =ROUND(AD12,$G$452) -> 4900 | I12: =ROUND(AE12,$G$452) -> 5300 | J12: =ROUND(AF12,$G$452) -> 5700 | K12: =ROUND(AG12,$G$452) -> 6000 | L12: =ROUND(AH12,$G$452) -> 6400 | N12: =$C12 -> 0.25 | O12: =$G$433 -> 650 | P12: =$G$430*(1-N12)-O12 -> 1600 | Q12: =$G$432-O12 -> 49350 | R12: =IFERROR(P12/(Q12+$G$430*(1-N12)),0)*(1-$G$434) -> 0.029457364 | Z12: =$O12+$G$435+$N12*$G$431+$R12*($Q12*(1+D$9)+$G$431*(1-$N12))-$G$430 -> 3469.8171 | AA12: =$O12+$G$435+$N12*$G$431+$R12*($Q12*(1+E$9)+$G$431*(1-$N12))-$G$430 -> 3833.2473 | AB12: =$O12+$G$435+$N12*$G$431+$R12*($Q12*(1+F$9)+$G$431*(1-$N12))-$G$430 -> 4196.6775 | AC12: =$O12+$G$435+$N12*$G$431+$R12*($Q12*(1+G$9)+$G$431*(1-$N12))-$G$430 -> 4560.1078 | AD12: =$O12+$G$435+$N12*$G$431+$R12*($Q12*(1+H$9)+$G$431*(1-$N12))-$G$430 -> 4923.538 | AE12: =$O12+$G$435+$N12*$G$431+$R12*($Q12*(1+I$9)+$G$431*(1-$N12))-$G$430 -> 5286.9682 | AF12: =$O12+$G$435+$N12*$G$431+$R12*($Q12*(1+J$9)+$G$431*(1-$N12))-$G$430 -> 5650.3985 | AG12: =$O12+$G$435+$N12*$G$431+$R12*($Q12*(1+K$9)+$G$431*(1-$N12))-$G$430 -> 6013.8287 | AH12: =$O12+$G$435+$N12*$G$431+$R12*($Q12*(1+L$9)+$G$431*(1-$N12))-$G$430 -> 6377.2589 | AT12: =IF(Z52<$G$449,0,MIN($G$446,1+IFERROR(INT((Z52-$G$449)/$G$451),0))) -> 0 | AU12: =IF(AA52<$G$449,0,MIN($G$446,1+IFERROR(INT((AA52-$G$449)/$G$451),0))) -> 0 | AV12: =IF(AB52<$G$449,0,MIN($G$446,1+IFERROR(INT((AB52-$G$449)/$G$451),0))) -> 0 | AW12: =IF(AC52<$G$449,0,MIN($G$446,1+IFERROR(INT((AC52-$G$449)/$G$451),0))) -> 0 | AX12: =IF(AD52<$G$449,0,MIN($G$446,1+IFERROR(INT((AD52-$G$449)/$G$451),0))) -> 0 | AY12: =IF(AE52<$G$449,0,MIN($G$446,1+IFERROR(INT((AE52-$G$449)/$G$451),0))) -> 0 | AZ12: =IF(AF52<$G$449,0,MIN($G$446,1+IFERROR(INT((AF52-$G$449)/$G$451),0))) -> 1 | BA12: =IF(AG52<$G$449,0,MIN($G$446,1+IFERROR(INT((AG52-$G$449)/$G$451),0))) -> 3 | BB12: =IF(AH52<$G$449,0,MIN($G$446,1+IFERROR(INT((AH52-$G$449)/$G$451),0))) -> 4
C13: =$G$438 -> 0.3 | D13: =ROUND(Z13,$G$452) -> 4100 | E13: =ROUND(AA13,$G$452) -> 4400 | F13: =ROUND(AB13,$G$452) -> 4700 | G13: =ROUND(AC13,$G$452) -> 5100 | H13: =ROUND(AD13,$G$452) -> 5400 | I13: =ROUND(AE13,$G$452) -> 5700 | J13: =ROUND(AF13,$G$452) -> 6100 | K13: =ROUND(AG13,$G$452) -> 6400 | L13: =ROUND(AH13,$G$452) -> 6700 | N13: =$C13 -> 0.3 | O13: =$G$433 -> 650 | P13: =$G$430*(1-N13)-O13 -> 1450 | Q13: =$G$432-O13 -> 49350 | R13: =IFERROR(P13/(Q13+$G$430*(1-N13)),0)*(1-$G$434) -> 0.026773567 | Z13: =$O13+$G$435+$N13*$G$431+$R13*($Q13*(1+D$9)+$G$431*(1-$N13))-$G$430 -> 4080.8816 | AA13: =$O13+$G$435+$N13*$G$431+$R13*($Q13*(1+E$9)+$G$431*(1-$N13))-$G$430 -> 4411.2005 | AB13: =$O13+$G$435+$N13*$G$431+$R13*($Q13*(1+F$9)+$G$431*(1-$N13))-$G$430 -> 4741.5193 | AC13: =$O13+$G$435+$N13*$G$431+$R13*($Q13*(1+G$9)+$G$431*(1-$N13))-$G$430 -> 5071.8382 | AD13: =$O13+$G$435+$N13*$G$431+$R13*($Q13*(1+H$9)+$G$431*(1-$N13))-$G$430 -> 5402.1571 | AE13: =$O13+$G$435+$N13*$G$431+$R13*($Q13*(1+I$9)+$G$431*(1-$N13))-$G$430 -> 5732.476 | AF13: =$O13+$G$435+$N13*$G$431+$R13*($Q13*(1+J$9)+$G$431*(1-$N13))-$G$430 -> 6062.7949 | AG13: =$O13+$G$435+$N13*$G$431+$R13*($Q13*(1+K$9)+$G$431*(1-$N13))-$G$430 -> 6393.1137 | AH13: =$O13+$G$435+$N13*$G$431+$R13*($Q13*(1+L$9)+$G$431*(1-$N13))-$G$430 -> 6723.4326 | AT13: =IF(Z53<$G$449,0,MIN($G$446,1+IFERROR(INT((Z53-$G$449)/$G$451),0))) -> 0 | AU13: =IF(AA53<$G$449,0,MIN($G$446,1+IFERROR(INT((AA53-$G$449)/$G$451),0))) -> 0 | AV13: =IF(AB53<$G$449,0,MIN($G$446,1+IFERROR(INT((AB53-$G$449)/$G$451),0))) -> 0 | AW13: =IF(AC53<$G$449,0,MIN($G$446,1+IFERROR(INT((AC53-$G$449)/$G$451),0))) -> 0 | AX13: =IF(AD53<$G$449,0,MIN($G$446,1+IFERROR(INT((AD53-$G$449)/$G$451),0))) -> 0 | AY13: =IF(AE53<$G$449,0,MIN($G$446,1+IFERROR(INT((AE53-$G$449)/$G$451),0))) -> 2 | AZ13: =IF(AF53<$G$449,0,MIN($G$446,1+IFERROR(INT((AF53-$G$449)/$G$451),0))) -> 3 | BA13: =IF(AG53<$G$449,0,MIN($G$446,1+IFERROR(INT((AG53-$G$449)/$G$451),0))) -> 4 | BB13: =IF(AH53<$G$449,0,MIN($G$446,1+IFERROR(INT((AH53-$G$449)/$G$451),0))) -> 6
C14: =C13+$G$439 -> 0.35 | D14: =ROUND(Z14,$G$452) -> 4700 | E14: =ROUND(AA14,$G$452) -> 5000 | F14: =ROUND(AB14,$G$452) -> 5300 | G14: =ROUND(AC14,$G$452) -> 5600 | H14: =ROUND(AD14,$G$452) -> 5900 | I14: =ROUND(AE14,$G$452) -> 6200 | J14: =ROUND(AF14,$G$452) -> 6500 | K14: =ROUND(AG14,$G$452) -> 6800 | L14: =ROUND(AH14,$G$452) -> 7100 | N14: =$C14 -> 0.35 | O14: =$G$433 -> 650 | P14: =$G$430*(1-N14)-O14 -> 1300 | Q14: =$G$432-O14 -> 49350 | R14: =IFERROR(P14/(Q14+$G$430*(1-N14)),0)*(1-$G$434) -> 0.024074074 | Z14: =$O14+$G$435+$N14*$G$431+$R14*($Q14*(1+D$9)+$G$431*(1-$N14))-$G$430 -> 4695.286 | AA14: =$O14+$G$435+$N14*$G$431+$R14*($Q14*(1+E$9)+$G$431*(1-$N14))-$G$430 -> 4992.2999 | AB14: =$O14+$G$435+$N14*$G$431+$R14*($Q14*(1+F$9)+$G$431*(1-$N14))-$G$430 -> 5289.3138 | AC14: =$O14+$G$435+$N14*$G$431+$R14*($Q14*(1+G$9)+$G$431*(1-$N14))-$G$430 -> 5586.3277 | AD14: =$O14+$G$435+$N14*$G$431+$R14*($Q14*(1+H$9)+$G$431*(1-$N14))-$G$430 -> 5883.3416 | AE14: =$O14+$G$435+$N14*$G$431+$R14*($Q14*(1+I$9)+$G$431*(1-$N14))-$G$430 -> 6180.3555 | AF14: =$O14+$G$435+$N14*$G$431+$R14*($Q14*(1+J$9)+$G$431*(1-$N14))-$G$430 -> 6477.3694 | AG14: =$O14+$G$435+$N14*$G$431+$R14*($Q14*(1+K$9)+$G$431*(1-$N14))-$G$430 -> 6774.3832 | AH14: =$O14+$G$435+$N14*$G$431+$R14*($Q14*(1+L$9)+$G$431*(1-$N14))-$G$430 -> 7071.3971 | AT14: =IF(Z54<$G$449,0,MIN($G$446,1+IFERROR(INT((Z54-$G$449)/$G$451),0))) -> 0 | AU14: =IF(AA54<$G$449,0,MIN($G$446,1+IFERROR(INT((AA54-$G$449)/$G$451),0))) -> 0 | AV14: =IF(AB54<$G$449,0,MIN($G$446,1+IFERROR(INT((AB54-$G$449)/$G$451),0))) -> 0 | AW14: =IF(AC54<$G$449,0,MIN($G$446,1+IFERROR(INT((AC54-$G$449)/$G$451),0))) -> 1 | AX14: =IF(AD54<$G$449,0,MIN($G$446,1+IFERROR(INT((AD54-$G$449)/$G$451),0))) -> 2 | AY14: =IF(AE54<$G$449,0,MIN($G$446,1+IFERROR(INT((AE54-$G$449)/$G$451),0))) -> 4 | AZ14: =IF(AF54<$G$449,0,MIN($G$446,1+IFERROR(INT((AF54-$G$449)/$G$451),0))) -> 5 | BA14: =IF(AG54<$G$449,0,MIN($G$446,1+IFERROR(INT((AG54-$G$449)/$G$451),0))) -> 6 | BB14: =IF(AH54<$G$449,0,MIN($G$446,1+IFERROR(INT((AH54-$G$449)/$G$451),0))) -> 7
C15: =C14+$G$439 -> 0.4 | D15: =ROUND(Z15,$G$452) -> 5300 | E15: =ROUND(AA15,$G$452) -> 5600 | F15: =ROUND(AB15,$G$452) -> 5800 | G15: =ROUND(AC15,$G$452) -> 6100 | H15: =ROUND(AD15,$G$452) -> 6400 | I15: =ROUND(AE15,$G$452) -> 6600 | J15: =ROUND(AF15,$G$452) -> 6900 | K15: =ROUND(AG15,$G$452) -> 7200 | L15: =ROUND(AH15,$G$452) -> 7400 | N15: =$C15 -> 0.4 | O15: =$G$433 -> 650 | P15: =$G$430*(1-N15)-O15 -> 1150 | Q15: =$G$432-O15 -> 49350 | R15: =IFERROR(P15/(Q15+$G$430*(1-N15)),0)*(1-$G$434) -> 0.021358749 | Z15: =$O15+$G$435+$N15*$G$431+$R15*($Q15*(1+D$9)+$G$431*(1-$N15))-$G$430 -> 5313.0598 | AA15: =$O15+$G$435+$N15*$G$431+$R15*($Q15*(1+E$9)+$G$431*(1-$N15))-$G$430 -> 5576.5733 | AB15: =$O15+$G$435+$N15*$G$431+$R15*($Q15*(1+F$9)+$G$431*(1-$N15))-$G$430 -> 5840.0869 | AC15: =$O15+$G$435+$N15*$G$431+$R15*($Q15*(1+G$9)+$G$431*(1-$N15))-$G$430 -> 6103.6004 | AD15: =$O15+$G$435+$N15*$G$431+$R15*($Q15*(1+H$9)+$G$431*(1-$N15))-$G$430 -> 6367.114 | AE15: =$O15+$G$435+$N15*$G$431+$R15*($Q15*(1+I$9)+$G$431*(1-$N15))-$G$430 -> 6630.6276 | AF15: =$O15+$G$435+$N15*$G$431+$R15*($Q15*(1+J$9)+$G$431*(1-$N15))-$G$430 -> 6894.1411 | AG15: =$O15+$G$435+$N15*$G$431+$R15*($Q15*(1+K$9)+$G$431*(1-$N15))-$G$430 -> 7157.6547 | AH15: =$O15+$G$435+$N15*$G$431+$R15*($Q15*(1+L$9)+$G$431*(1-$N15))-$G$430 -> 7421.1683 | AT15: =IF(Z55<$G$449,0,MIN($G$446,1+IFERROR(INT((Z55-$G$449)/$G$451),0))) -> 0 | AU15: =IF(AA55<$G$449,0,MIN($G$446,1+IFERROR(INT((AA55-$G$449)/$G$451),0))) -> 1 | AV15: =IF(AB55<$G$449,0,MIN($G$446,1+IFERROR(INT((AB55-$G$449)/$G$451),0))) -> 2 | AW15: =IF(AC55<$G$449,0,MIN($G$446,1+IFERROR(INT((AC55-$G$449)/$G$451),0))) -> 3 | AX15: =IF(AD55<$G$449,0,MIN($G$446,1+IFERROR(INT((AD55-$G$449)/$G$451),0))) -> 4 | AY15: =IF(AE55<$G$449,0,MIN($G$446,1+IFERROR(INT((AE55-$G$449)/$G$451),0))) -> 5 | AZ15: =IF(AF55<$G$449,0,MIN($G$446,1+IFERROR(INT((AF55-$G$449)/$G$451),0))) -> 7 | BA15: =IF(AG55<$G$449,0,MIN($G$446,1+IFERROR(INT((AG55-$G$449)/$G$451),0))) -> 8 | BB15: =IF(AH55<$G$449,0,MIN($G$446,1+IFERROR(INT((AH55-$G$449)/$G$451),0))) -> 9
C16: =C15+$G$439 -> 0.45 | D16: =ROUND(Z16,$G$452) -> 5900 | E16: =ROUND(AA16,$G$452) -> 6200 | F16: =ROUND(AB16,$G$452) -> 6400 | G16: =ROUND(AC16,$G$452) -> 6600 | H16: =ROUND(AD16,$G$452) -> 6900 | I16: =ROUND(AE16,$G$452) -> 7100 | J16: =ROUND(AF16,$G$452) -> 7300 | K16: =ROUND(AG16,$G$452) -> 7500 | L16: =ROUND(AH16,$G$452) -> 7800 | N16: =$C16 -> 0.45 | O16: =$G$433 -> 650 | P16: =$G$430*(1-N16)-O16 -> 1000 | Q16: =$G$432-O16 -> 49350 | R16: =IFERROR(P16/(Q16+$G$430*(1-N16)),0)*(1-$G$434) -> 0.018627451 | Z16: =$O16+$G$435+$N16*$G$431+$R16*($Q16*(1+D$9)+$G$431*(1-$N16))-$G$430 -> 5934.2325 | AA16: =$O16+$G$435+$N16*$G$431+$R16*($Q16*(1+E$9)+$G$431*(1-$N16))-$G$430 -> 6164.0487 | AB16: =$O16+$G$435+$N16*$G$431+$R16*($Q16*(1+F$9)+$G$431*(1-$N16))-$G$430 -> 6393.8649 | AC16: =$O16+$G$435+$N16*$G$431+$R16*($Q16*(1+G$9)+$G$431*(1-$N16))-$G$430 -> 6623.681 | AD16: =$O16+$G$435+$N16*$G$431+$R16*($Q16*(1+H$9)+$G$431*(1-$N16))-$G$430 -> 6853.4972 | AE16: =$O16+$G$435+$N16*$G$431+$R16*($Q16*(1+I$9)+$G$431*(1-$N16))-$G$430 -> 7083.3134 | AF16: =$O16+$G$435+$N16*$G$431+$R16*($Q16*(1+J$9)+$G$431*(1-$N16))-$G$430 -> 7313.1296 | AG16: =$O16+$G$435+$N16*$G$431+$R16*($Q16*(1+K$9)+$G$431*(1-$N16))-$G$430 -> 7542.9457 | AH16: =$O16+$G$435+$N16*$G$431+$R16*($Q16*(1+L$9)+$G$431*(1-$N16))-$G$430 -> 7772.7619 | AT16: =IF(Z56<$G$449,0,MIN($G$446,1+IFERROR(INT((Z56-$G$449)/$G$451),0))) -> 2 | AU16: =IF(AA56<$G$449,0,MIN($G$446,1+IFERROR(INT((AA56-$G$449)/$G$451),0))) -> 3 | AV16: =IF(AB56<$G$449,0,MIN($G$446,1+IFERROR(INT((AB56-$G$449)/$G$451),0))) -> 4 | AW16: =IF(AC56<$G$449,0,MIN($G$446,1+IFERROR(INT((AC56-$G$449)/$G$451),0))) -> 5 | AX16: =IF(AD56<$G$449,0,MIN($G$446,1+IFERROR(INT((AD56-$G$449)/$G$451),0))) -> 6 | AY16: =IF(AE56<$G$449,0,MIN($G$446,1+IFERROR(INT((AE56-$G$449)/$G$451),0))) -> 7 | AZ16: =IF(AF56<$G$449,0,MIN($G$446,1+IFERROR(INT((AF56-$G$449)/$G$451),0))) -> 8 | BA16: =IF(AG56<$G$449,0,MIN($G$446,1+IFERROR(INT((AG56-$G$449)/$G$451),0))) -> 9 | BB16: =IF(AH56<$G$449,0,MIN($G$446,1+IFERROR(INT((AH56-$G$449)/$G$451),0))) -> 10
B17: Ben's Year 5 value (cash at close + earnout + retained Keystone stake + Topkey stock, after dilution) less Keystone value today (G430)
N18: =$G$436 -> 0.3 | O18: =$G$433 -> 650 | P18: =$G$430*(1-N18)-O18 -> 1450 | Q18: =$G$432-O18 -> 49350 | R18: =IFERROR(P18/(Q18+$G$430*(1-N18)),0)*(1-$G$434) -> 0.026773567
B19: Ben's % Return on Keystone Value Based on Topkey Growth & Rollover %
D21: Topkey ex-Keystone Value Growth (%)
D22: =E22-$G$441 -> 0.013171226 | E22: =F22-$G$441 -> 0.26317123 | F22: =G22-$G$441 -> 0.51317123 | G22: =H22-$G$441 -> 0.76317123 | H22: =$G$440 -> 1.0131712 | I22: =H22+$G$441 -> 1.2631712 | J22: =I22+$G$441 -> 1.5131712 | K22: =J22+$G$441 -> 1.7631712 | L22: =K22+$G$441 -> 2.0131712 | AT22: Helper: Gradient Band (0 = below $1M hurdle)
B23: Ben's Rollover % | C23: =C24-$G$439 -> 0.15 | D23: =IFERROR(Z10/$G$430,0) -> 0.75253063 | E23: =IFERROR(AA10/$G$430,0) -> 0.89555689 | F23: =IFERROR(AB10/$G$430,0) -> 1.0385831 | G23: =IFERROR(AC10/$G$430,0) -> 1.1816094 | H23: =IFERROR(AD10/$G$430,0) -> 1.3246356 | I23: =IFERROR(AE10/$G$430,0) -> 1.4676619 | J23: =IFERROR(AF10/$G$430,0) -> 1.6106881 | K23: =IFERROR(AG10/$G$430,0) -> 1.7537144 | L23: =IFERROR(AH10/$G$430,0) -> 1.8967407 | AT23: =IF(Z50<$G$449,0,MIN($G$446,1+IFERROR(INT((Z50-$G$449)/$G$451),0))) -> 0 | AU23: =IF(AA50<$G$449,0,MIN($G$446,1+IFERROR(INT((AA50-$G$449)/$G$451),0))) -> 0 | AV23: =IF(AB50<$G$449,0,MIN($G$446,1+IFERROR(INT((AB50-$G$449)/$G$451),0))) -> 0 | AW23: =IF(AC50<$G$449,0,MIN($G$446,1+IFERROR(INT((AC50-$G$449)/$G$451),0))) -> 0 | AX23: =IF(AD50<$G$449,0,MIN($G$446,1+IFERROR(INT((AD50-$G$449)/$G$451),0))) -> 0 | AY23: =IF(AE50<$G$449,0,MIN($G$446,1+IFERROR(INT((AE50-$G$449)/$G$451),0))) -> 0 | AZ23: =IF(AF50<$G$449,0,MIN($G$446,1+IFERROR(INT((AF50-$G$449)/$G$451),0))) -> 0 | BA23: =IF(AG50<$G$449,0,MIN($G$446,1+IFERROR(INT((AG50-$G$449)/$G$451),0))) -> 0 | BB23: =IF(AH50<$G$449,0,MIN($G$446,1+IFERROR(INT((AH50-$G$449)/$G$451),0))) -> 1
C24: =C25-$G$439 -> 0.2 | D24: =IFERROR(Z11/$G$430,0) -> 0.95402113 | E24: =IFERROR(AA11/$G$430,0) -> 1.0861377 | F24: =IFERROR(AB11/$G$430,0) -> 1.2182542 | G24: =IFERROR(AC11/$G$430,0) -> 1.3503708 | H24: =IFERROR(AD11/$G$430,0) -> 1.4824873 | I24: =IFERROR(AE11/$G$430,0) -> 1.6146039 | J24: =IFERROR(AF11/$G$430,0) -> 1.7467204 | K24: =IFERROR(AG11/$G$430,0) -> 1.878837 | L24: =IFERROR(AH11/$G$430,0) -> 2.0109535 | AT24: =IF(Z51<$G$449,0,MIN($G$446,1+IFERROR(INT((Z51-$G$449)/$G$451),0))) -> 0 | AU24: =IF(AA51<$G$449,0,MIN($G$446,1+IFERROR(INT((AA51-$G$449)/$G$451),0))) -> 0 | AV24: =IF(AB51<$G$449,0,MIN($G$446,1+IFERROR(INT((AB51-$G$449)/$G$451),0))) -> 0 | AW24: =IF(AC51<$G$449,0,MIN($G$446,1+IFERROR(INT((AC51-$G$449)/$G$451),0))) -> 0 | AX24: =IF(AD51<$G$449,0,MIN($G$446,1+IFERROR(INT((AD51-$G$449)/$G$451),0))) -> 0 | AY24: =IF(AE51<$G$449,0,MIN($G$446,1+IFERROR(INT((AE51-$G$449)/$G$451),0))) -> 0 | AZ24: =IF(AF51<$G$449,0,MIN($G$446,1+IFERROR(INT((AF51-$G$449)/$G$451),0))) -> 0 | BA24: =IF(AG51<$G$449,0,MIN($G$446,1+IFERROR(INT((AG51-$G$449)/$G$451),0))) -> 1 | BB24: =IF(AH51<$G$449,0,MIN($G$446,1+IFERROR(INT((AH51-$G$449)/$G$451),0))) -> 3
C25: =C26-$G$439 -> 0.25 | D25: =IFERROR(Z12/$G$430,0) -> 1.1566057 | E25: =IFERROR(AA12/$G$430,0) -> 1.2777491 | F25: =IFERROR(AB12/$G$430,0) -> 1.3988925 | G25: =IFERROR(AC12/$G$430,0) -> 1.5200359 | H25: =IFERROR(AD12/$G$430,0) -> 1.6411793 | I25: =IFERROR(AE12/$G$430,0) -> 1.7623227 | J25: =IFERROR(AF12/$G$430,0) -> 1.8834662 | K25: =IFERROR(AG12/$G$430,0) -> 2.0046096 | L25: =IFERROR(AH12/$G$430,0) -> 2.125753 | AT25: =IF(Z52<$G$449,0,MIN($G$446,1+IFERROR(INT((Z52-$G$449)/$G$451),0))) -> 0 | AU25: =IF(AA52<$G$449,0,MIN($G$446,1+IFERROR(INT((AA52-$G$449)/$G$451),0))) -> 0 | AV25: =IF(AB52<$G$449,0,MIN($G$446,1+IFERROR(INT((AB52-$G$449)/$G$451),0))) -> 0 | AW25: =IF(AC52<$G$449,0,MIN($G$446,1+IFERROR(INT((AC52-$G$449)/$G$451),0))) -> 0 | AX25: =IF(AD52<$G$449,0,MIN($G$446,1+IFERROR(INT((AD52-$G$449)/$G$451),0))) -> 0 | AY25: =IF(AE52<$G$449,0,MIN($G$446,1+IFERROR(INT((AE52-$G$449)/$G$451),0))) -> 0 | AZ25: =IF(AF52<$G$449,0,MIN($G$446,1+IFERROR(INT((AF52-$G$449)/$G$451),0))) -> 1 | BA25: =IF(AG52<$G$449,0,MIN($G$446,1+IFERROR(INT((AG52-$G$449)/$G$451),0))) -> 3 | BB25: =IF(AH52<$G$449,0,MIN($G$446,1+IFERROR(INT((AH52-$G$449)/$G$451),0))) -> 4
