Workbook

Sheet Cover
B24: Sunshine Commercial Investments
B25: Diligence Workbook
B26: ="As of "&TEXT(TODAY(),"mm/dd/yy") -> As of 08/12/26

Sheet Valuation Overview
B2: =+Cover!B24 -> Sunshine Commercial Investments
B3: Valuation Overview ($000s) | H3: Print | I3: 1
C5: Current Valuation | D5: Clearing Price | E5: NNN Valuation | F5: Base-Rate Valuation
B7: Laundromat | C7: =ROUND(+'Laundromat Valuation'!F53,-2) -> 600 | D7: =C7 -> 600 | E7: =C7 -> 600 | F7: =E7 -> 600
B8: Commercial Real Estate | C8: =+'CRE P&L'!C100/1000 -> 718.4625 | D8: =+'CRE P&L'!D100/1000 -> 1000 | E8: =+'CRE P&L'!E100/1000 -> 518.4625 | F8: =+'CRE P&L'!F100/1000 -> 597.2125
B9: Total Valuation | C9: =+C8+C7 -> 1318.4625 | D9: =+D8+D7 -> 1600 | E9: =+E8+E7 -> 1118.4625 | F9: =+F8+F7 -> 1197.2125
B10: (-) Asking Price | C10: -1600 | D10: =C10 -> -1600 | E10: =C10 -> -1600 | F10: =E10 -> -1600
B11: Delta | C11: =+C9+C10 -> -281.5375 | D11: =+D9+D10 -> 0 | E11: =+E9+E10 -> -481.5375 | F11: =+F9+F10 -> -402.7875
B13: Annual Rent Impact
C15: =+C$5 -> Current Valuation | D15: =+D$5 -> Clearing Price | E15: =+E$5 -> NNN Valuation | F15: =+F$5 -> Base-Rate Valuation
B17: =+'Tennant View'!B18 -> Community Theater | C17: =+'Tennant View'!C28/1000 -> 21.6 | D17: =D$22*$H17 -> 29.588031 | E17: =E$22*$H17 -> 15.925123 | F17: =F$22*$H17 -> 24.118227 | H17: =C17/$C$22 -> 0.3546798
B18: =+'Tennant View'!B19 -> Laundromat | C18: =+'Tennant View'!C29/1000 -> 14.4 | D18: =D$22*$H18 -> 19.725354 | E18: =E$22*$H18 -> 10.616749 | F18: =F$22*$H18 -> 16.078818 | H18: =C18/$C$22 -> 0.2364532
B19: =+'Tennant View'!B20 -> Turnaround Testron* | C19: =+'Tennant View'!C30/1000 -> 9.3 | D19: =D$22*$H19 -> 12.739291 | E19: =E$22*$H19 -> 6.8566502 | F19: =F$22*$H19 -> 10.384236 | H19: =C19/$C$22 -> 0.15270936
B20: =+'Tennant View'!B21 -> Consignment Shop | C20: =+'Tennant View'!C31/1000 -> 8.4 | D20: =D$22*$H20 -> 11.506456 | E20: =E$22*$H20 -> 6.1931034 | F20: =F$22*$H20 -> 9.3793103 | H20: =C20/$C$22 -> 0.13793103
B21: =+'Tennant View'!B22 -> Book Store | C21: =+'Tennant View'!C32/1000 -> 7.2 | D21: =D$22*$H21 -> 9.862677 | E21: =E$22*$H21 -> 5.3083744 | F21: =F$22*$H21 -> 8.0394089 | H21: =C21/$C$22 -> 0.1182266
B22: Total Annual Rent | C22: =SUM(C17:C21) -> 60.9 | D22: =+'CRE P&L'!D83/1000 -> 83.42181 | E22: =+'CRE P&L'!E83/1000 -> 44.9 | F22: =+'CRE P&L'!G83/1000 -> 68
B23: % Increase | D23: =D22/$C$22-1 -> 0.36981625 | E23: =E22/$C$22-1 -> -0.26272578 | F23: =F22/$C$22-1 -> 0.11658456
B25: Monthly Rent Impact
C27: =+C$5 -> Current Valuation | D27: =+D$5 -> Clearing Price | E27: =+E$5 -> NNN Valuation | F27: =+F$5 -> Base-Rate Valuation
B29: =+B17 -> Community Theater | C29: =+'Tennant View'!C18 -> 1800 | D29: =D$34*$H29 -> 2465.6692 | E29: =E$34*$H29 -> 1327.0936 | F29: =F$34*$H29 -> 2009.8522 | H29: =C29/$C$34 -> 0.3546798
B30: =+B18 -> Laundromat | C30: =+'Tennant View'!C19 -> 1200 | D30: =D$34*$H30 -> 1643.7795 | E30: =E$34*$H30 -> 884.72906 | F30: =F$34*$H30 -> 1339.9015 | H30: =C30/$C$34 -> 0.2364532
B31: =+B19 -> Turnaround Testron* | C31: =+'Tennant View'!C20 -> 775 | D31: =D$34*$H31 -> 1061.6076 | E31: =E$34*$H31 -> 571.38752 | F31: =F$34*$H31 -> 865.35304 | H31: =C31/$C$34 -> 0.15270936
B32: =+B20 -> Consignment Shop | C32: =+'Tennant View'!C21 -> 700 | D32: =D$34*$H32 -> 958.87137 | E32: =E$34*$H32 -> 516.09195 | F32: =F$34*$H32 -> 781.6092 | H32: =C32/$C$34 -> 0.13793103
B33: =+B21 -> Book Store | C33: =+'Tennant View'!C22 -> 600 | D33: =D$34*$H33 -> 821.88975 | E33: =E$34*$H33 -> 442.36453 | F33: =F$34*$H33 -> 669.95074 | H33: =C33/$C$34 -> 0.1182266
B34: Total Monthly Rent | C34: =SUM(C29:C33) -> 5075 | D34: =+D22/12*1000 -> 6951.8175 | E34: =+E22/12*1000 -> 3741.6667 | F34: =+F22/12*1000 -> 5666.6667
B35: % Increase | D35: =D34/$C$34-1 -> 0.36981625 | E35: =E34/$C$34-1 -> -0.26272578 | F35: =F34/$C$34-1 -> 0.11658456
C72: Valuation | D72: % Delta | E72: % Delta
B73: Prior Transaction Consideration | C73: 580000
B74: County Cost-Approach | C74: 435734
B75: Precedent Transactions
B76: Average Valuation
B78: Income Capitalization Approach
B80: 2024 Net Income | C80: 128331
B81: Mortgage Interest | C81: 14670
B82: Total Earnings | C82: =+C80+C81 -> 143001
C83: 3
B84: Implied Valuation | C84: =C82*C83 -> 429003
B85: Less Accumulated Depreciation
B90: Depreciation | C90: 28555

Sheet CRE P&L
B2: =+Cover!B24 -> Sunshine Commercial Investments
B3: Commercial Real Estate Valuation ($) | K3: Print | L3: 0
B5: Pro Forma Rent Build
C7: FY25 | D7: NNN | E7: Low-End | F7: Base-Rate
B8: Base Rent | C8: =+'Tennant View'!C33 -> 60900 | D8: =C8 -> 60900
B9: (+) NNN Rent | C9: 0 | D9: =C44 -> 39437 | E9: =D9 -> 39437 | F9: =E9 -> 39437
B10: Total Rent | C10: =+C8+C9 -> 60900 | D10: =+D8+D9 -> 100337 | E10: =+E8+E9 -> 39437 | F10: =+F8+F9 -> 39437
B11: (-) Corporate NNN | C11: =-C44 -> -39437 | D11: 0 | E11: 0 | F11: 0
B12: (-) Corporate Expenses | C12: =-C59 -> -10435 | D12: =C12 -> -10435 | E12: =D12 -> -10435 | F12: =E12 -> -10435
B13: NOI | C13: =SUM(C10:C12) -> 11028 | D13: =SUM(D10:D12) -> 89902 | E13: =SUM(E10:E12) -> 29002 | F13: =SUM(F10:F12) -> 29002
C21: Estimated Pro Forma Rent Build
C22: Base Rent | D22: Insurance | E22: Taxes | F22: CAM | G22: Utilities | H22: Total Rent
B23: Current (FY25) Rent | C23: =+'Market Rent Analysis'!$C$8 -> 7.25 | D23: 0 | E23: 0 | F23: 0 | G23: 0 | H23: =SUM(C23:G23) -> 7.25
B24: NNN Rent | C24: =+'Market Rent Analysis'!$C$8 -> 7.25 | D24: =+D40 -> 1.1904762 | E24: =+D41 -> 1.5996429 | F24: =+D42 -> 1.1904762 | G24: =+D43 -> 0.71428571 | H24: =SUM(C24:G24) -> 11.944881
B25: NNN + Low-End Rent | D25: =D24 -> 1.1904762 | E25: =E24 -> 1.5996429 | F25: =F24 -> 1.1904762 | G25: =G24 -> 0.71428571 | H25: =SUM(C25:G25) -> 4.694881
B26: NNN + Base-Rate Rent | D26: =D25 -> 1.1904762 | E26: =E25 -> 1.5996429 | F26: =F25 -> 1.1904762 | G26: =G25 -> 0.71428571 | H26: =SUM(C26:G26) -> 4.694881
C28: Actual Pro Forma Rent Build
C29: Base Rent | D29: Insurance | E29: Taxes | F29: CAM | G29: Utilities | H29: Total Rent
B30: Current (FY25) Rent | C30: =+C23 -> 7.25 | D30: 0 | E30: 0 | F30: 0 | G30: 0 | H30: =SUM(C30:G30) -> 7.25
B31: Clearing Price Rent | C31: =+#REF! -> #REF! | D31: =+F40 -> 0 | E31: =+F41 -> 1.5996429 | F31: =+F42 -> 0 | G31: =+F43 -> 0 | H31: =SUM(C31:G31) -> #REF!
B32: NNN Rent | C32: =+C24 -> 7.25 | D32: =D31 -> 0 | E32: =E31 -> 1.5996429 | F32: =F31 -> 0 | G32: =G31 -> 0 | H32: =SUM(C32:G32) -> 8.8496429
B33: NNN + Low-End Rent | C33: =+C25 -> 0 | D33: =D32 -> 0 | E33: =E32 -> 1.5996429 | F33: =F32 -> 0 | G33: =G32 -> 0 | H33: =SUM(C33:G33) -> 1.5996429
B34: NNN + Base-Rate Rent | C34: =+C26 -> 0 | D34: =D33 -> 0 | E34: =E33 -> 1.5996429 | F34: =F33 -> 0 | G34: =G33 -> 0 | H34: =SUM(C34:G34) -> 1.5996429
B36: NNN Build
C38: NNN Allocation Overview
C39: Estimate | D39: Per Sq. Ft. | E39: Actuals | F39: Per Sq. Ft. | G39: Delta | H39: Per Sq. Ft.
B40: Insurance | C40: 10000 | D40: =C40/$C$71 -> 1.1904762 | F40: =E40/$C$71 -> 0 | G40: =E40-C40 -> -10000 | H40: =G40/$C$71 -> -1.1904762
B41: Taxes2 | C41: 13437 | D41: =C41/$C$71 -> 1.5996429 | E41: 13437 | F41: =E41/$C$71 -> 1.5996429 | G41: =E41-C41 -> 0 | H41: =G41/$C$71 -> 0 | J41: Based on this calculator (currently assumes $1M sale)
B42: Maintenance / CAM | C42: 10000 | D42: =C42/$C$71 -> 1.1904762 | F42: =E42/$C$71 -> 0 | G42: =E42-C42 -> -10000 | H42: =G42/$C$71 -> -1.1904762
B43: Utilities | C43: 6000 | D43: =C43/$C$71 -> 0.71428571 | F43: =E43/$C$71 -> 0 | G43: =E43-C43 -> -6000 | H43: =G43/$C$71 -> -0.71428571 | J43: Make sure this is allocated to laundromat in accordance with usage
B44: Total NNN Charges | C44: =SUM(C40:C43) -> 39437 | D44: =SUM(D40:D43) -> 4.694881 | E44: =SUM(E40:E43) -> 13437 | F44: =SUM(F40:F43) -> 1.5996429 | G44: =SUM(G40:G43) -> -26000 | H44: =SUM(H40:H43) -> -3.0952381
B45: 2) Assumes go-forward taxes at $1M valuation
B47: Corporate Expense Build
C49: CRE Corporate Expense Overview
C50: Estimate | D50: Per Sq. Ft. | E50: Actuals | F50: Per Sq. Ft. | G50: Delta | H50: Per Sq. Ft.
B51: Vacancy Allowance | C51: =C62*C63 -> 3045 | D51: =C51/$C$71 -> 0.3625 | F51: =E51/$C$71 -> 0 | G51: =E51-C51 -> -3045 | H51: =G51/$C$71 -> -0.3625
B52: Property Management Fee | C52: =+C64 -> 0 | D52: =C52/$C$71 -> 0 | E52: 0 | F52: =E52/$C$71 -> 0 | G52: =E52-C52 -> 0 | H52: =G52/$C$71 -> 0
B53: Capital Reserves | C53: =C65*$C$71 -> 1680 | D53: =C53/$C$71 -> 0.2 | F53: =E53/$C$71 -> 0 | G53: =E53-C53 -> -1680 | H53: =G53/$C$71 -> -0.2
B54: TI Reserves | C54: =C66*$C$71 -> 1260 | D54: =C54/$C$71 -> 0.15 | F54: =E54/$C$71 -> 0 | G54: =E54-C54 -> -1260 | H54: =G54/$C$71 -> -0.15
B55: Non-NNN Owner Insurance | C55: =+C67 -> 2500 | D55: =C55/$C$71 -> 0.29761905 | F55: =E55/$C$71 -> 0 | G55: =E55-C55 -> -2500 | H55: =G55/$C$71 -> -0.29761905
...

Sheet Tennant View
B2: =+Cover!B24 -> Sunshine Commercial Investments
B3: Commercial Real Estate Valuation ($) | K3: Print | L3: 0
B5: CRE Rent Overview
C7: Rent / Sq. Ft. For Each Scenario
C8: FY25 | D8: Clearing | E8: NNN | F8: Low-End | G8: Base-Rate
B9: Base Rent / Sq. Ft. | C9: =+'CRE P&L'!C23 -> 7.25 | E9: =+'CRE P&L'!C23 -> 7.25
B10: NNN Rent / Sq. Ft. | C10: 0 | E10: =+'CRE P&L'!D44 -> 4.694881 | F10: =E10 -> 4.694881 | G10: =F10 -> 4.694881
B11: Total Rent / Sq. Ft. | C11: =SUM(C9:C10) -> 7.25 | D11: =SUM(D9:D10) -> 0 | E11: =SUM(E9:E10) -> 11.944881 | F11: =SUM(F9:F10) -> 4.694881 | G11: =SUM(G9:G10) -> 4.694881
B13: Total Rent Increase | C13: ='CRE P&L'!C83/'CRE P&L'!$C$83-1 -> 0 | D13: ='CRE P&L'!D83/'CRE P&L'!$C$83-1 -> 0.36981625 | E13: ='CRE P&L'!E83/'CRE P&L'!$C$83-1 -> -0.26272578 | F13: ='CRE P&L'!F83/'CRE P&L'!$C$83-1 -> -0.1592775 | G13: ='CRE P&L'!G83/'CRE P&L'!$C$83-1 -> 0.11658456
C15: Total Monthly Rent (Base + NNN)
C16: FY25 | D16: Clearing | E16: NNN | F16: Low-End | G16: Base-Rate
B18: Community Theater | C18: 1800 | G18: =C18*(1+$G$13) -> 2009.8522
B19: Laundromat | C19: 1200 | G19: =C19*(1+$G$13) -> 1339.9015
B20: Turnaround Testron* | C20: 775 | G20: =C20*(1+$G$13) -> 865.35304 | K20: Make sure this is allocated to laundromat in accordance with usage
B21: Consignment Shop | C21: 700 | G21: =C21*(1+$G$13) -> 781.6092
B22: Book Store | C22: 600 | G22: =C22*(1+$G$13) -> 669.95074
B23: Total Current Rent | C23: =SUM(C18:C22) -> 5075 | D23: =SUM(D18:D22) -> 0 | E23: =SUM(E18:E22) -> 0 | F23: =SUM(F18:F22) -> 0 | G23: =SUM(G18:G22) -> 5666.6667
C25: Total Annual Rent (Base + NNN)
C26: FY25 | D26: Clearing | E26: NNN | F26: Low-End | G26: Base-Rate
B28: Community Theater | C28: =C18*12 -> 21600 | G28: =G18*12 -> 24118.227
B29: Laundromat | C29: =C19*12 -> 14400 | G29: =G19*12 -> 16078.818
B30: Turnaround Testron* | C30: =C20*12 -> 9300 | G30: =G20*12 -> 10384.236
B31: Consignment Shop | C31: =C21*12 -> 8400 | G31: =G21*12 -> 9379.3103
B32: Book Store | C32: =C22*12 -> 7200 | G32: =G22*12 -> 8039.4089
B33: Total Current Rent | C33: =SUM(C28:C32) -> 60900 | D33: =SUM(D28:D32) -> 0 | E33: =SUM(E28:E32) -> 0 | F33: =SUM(F28:F32) -> 0 | G33: =G23*12 -> 68000
B34: 1) Cannot verify through Google Maps -- appears to be Carrie’s Beauty Salon
B36: Breakdown base rent vs. the triple net cost allocation to each tennant
B49: Pro Forma Rent Build
C51: Estimated Pro Forma Rent Build
C52: Base Rent | D52: Insurance | E52: Taxes | F52: CAM | G52: Utilities | H52: Total Rent
B53: Current (FY25) Rent | C53: =+'Market Rent Analysis'!$C$8 -> 7.25 | D53: 0 | E53: 0 | F53: 0 | G53: 0 | H53: =SUM(C53:G53) -> 7.25
B54: Clearing Price Rent | D54: =+D69 -> 1.1904762 | E54: =+D70 -> 1.5996429 | F54: =+D71 -> 1.1904762 | G54: =+D72 -> 0.71428571 | H54: =SUM(C54:G54) -> 4.694881
B55: NNN Rent | C55: =+'Market Rent Analysis'!$C$8 -> 7.25 | D55: =D54 -> 1.1904762 | E55: =E54 -> 1.5996429 | F55: =F54 -> 1.1904762 | G55: =G54 -> 0.71428571 | H55: =SUM(C55:G55) -> 11.944881
B56: NNN + Low-End Rent | D56: =D55 -> 1.1904762 | E56: =E55 -> 1.5996429 | F56: =F55 -> 1.1904762 | G56: =G55 -> 0.71428571 | H56: =SUM(C56:G56) -> 4.694881
B57: NNN + Base-Rate Rent | D57: =D56 -> 1.1904762 | E57: =E56 -> 1.5996429 | F57: =F56 -> 1.1904762 | G57: =G56 -> 0.71428571 | H57: =SUM(C57:G57) -> 4.694881
C59: Actual Pro Forma Rent Build
C60: Base Rent | D60: Insurance | E60: Taxes | F60: CAM | G60: Utilities | H60: Total Rent
B61: Current (FY25) Rent | C61: =+C53 -> 7.25 | D61: 0 | E61: 0 | F61: 0 | G61: 0 | H61: =SUM(C61:G61) -> 7.25
B62: Clearing Price Rent | C62: =+C54 -> 0 | D62: =+F69 -> 0 | E62: =+F70 -> 1.5996429 | F62: =+F71 -> 0 | G62: =+F72 -> 0 | H62: =SUM(C62:G62) -> 1.5996429
B63: NNN Rent | C63: =+C55 -> 7.25 | D63: =D62 -> 0 | E63: =E62 -> 1.5996429 | F63: =F62 -> 0 | G63: =G62 -> 0 | H63: =SUM(C63:G63) -> 8.8496429
...

Sheet Sensitivity Analysis
B2: =+'CRE P&L'!B2 -> Sunshine Commercial Investments
B3: CRE Sensitivity Analysis | L3: Print | M3: 1
B5: Valuation Sensitivity Table
D7: Valuation Cap Rate Range | L7: Total Usable Sq. Ft. | N7: =+'Market Rent Analysis'!$C$7 -> 8400
D8: 0.07 | E8: =D8+0.5% -> 0.075 | F8: =E8+0.5% -> 0.08 | G8: =F8+0.5% -> 0.085 | H8: =G8+0.5% -> 0.09 | I8: =H8+0.5% -> 0.095 | J8: =I8+0.5% -> 0.1 | L8: Estimated Corporate Expenses | N8: =+'CRE P&L'!C59/1000 -> 10.435
B9: Net Operating Income Range ($000s) | C9: 20 | D9: =$C9/D$8 -> 285.71429 | E9: =$C9/E$8 -> 266.66667 | F9: =$C9/F$8 -> 250 | G9: =$C9/G$8 -> 235.29412 | H9: =$C9/H$8 -> 222.22222 | I9: =$C9/I$8 -> 210.52632 | J9: =$C9/J$8 -> 200
C10: =C9+10 -> 30 | D10: =$C10/D$8 -> 428.57143 | E10: =$C10/E$8 -> 400 | F10: =$C10/F$8 -> 375 | G10: =$C10/G$8 -> 352.94118 | H10: =$C10/H$8 -> 333.33333 | I10: =$C10/I$8 -> 315.78947 | J10: =$C10/J$8 -> 300
C11: =C10+10 -> 40 | D11: =$C11/D$8 -> 571.42857 | E11: =$C11/E$8 -> 533.33333 | F11: =$C11/F$8 -> 500 | G11: =$C11/G$8 -> 470.58824 | H11: =$C11/H$8 -> 444.44444 | I11: =$C11/I$8 -> 421.05263 | J11: =$C11/J$8 -> 400
C12: =C11+10 -> 50 | D12: =$C12/D$8 -> 714.28571 | E12: =$C12/E$8 -> 666.66667 | F12: =$C12/F$8 -> 625 | G12: =$C12/G$8 -> 588.23529 | H12: =$C12/H$8 -> 555.55556 | I12: =$C12/I$8 -> 526.31579 | J12: =$C12/J$8 -> 500
C13: =C12+10 -> 60 | D13: =$C13/D$8 -> 857.14286 | E13: =$C13/E$8 -> 800 | F13: =$C13/F$8 -> 750 | G13: =$C13/G$8 -> 705.88235 | H13: =$C13/H$8 -> 666.66667 | I13: =$C13/I$8 -> 631.57895 | J13: =$C13/J$8 -> 600
C14: =C13+10 -> 70 | D14: =$C14/D$8 -> 1000 | E14: =$C14/E$8 -> 933.33333 | F14: =$C14/F$8 -> 875 | G14: =$C14/G$8 -> 823.52941 | H14: =$C14/H$8 -> 777.77778 | I14: =$C14/I$8 -> 736.84211 | J14: =$C14/J$8 -> 700
C15: =C14+10 -> 80 | D15: =$C15/D$8 -> 1142.8571 | E15: =$C15/E$8 -> 1066.6667 | F15: =$C15/F$8 -> 1000 | G15: =$C15/G$8 -> 941.17647 | H15: =$C15/H$8 -> 888.88889 | I15: =$C15/I$8 -> 842.10526 | J15: =$C15/J$8 -> 800
C16: =C15+10 -> 90 | D16: =$C16/D$8 -> 1285.7143 | E16: =$C16/E$8 -> 1200 | F16: =$C16/F$8 -> 1125 | G16: =$C16/G$8 -> 1058.8235 | H16: =$C16/H$8 -> 1000 | I16: =$C16/I$8 -> 947.36842 | J16: =$C16/J$8 -> 900
C17: =C16+10 -> 100 | D17: =$C17/D$8 -> 1428.5714 | E17: =$C17/E$8 -> 1333.3333 | F17: =$C17/F$8 -> 1250 | G17: =$C17/G$8 -> 1176.4706 | H17: =$C17/H$8 -> 1111.1111 | I17: =$C17/I$8 -> 1052.6316 | J17: =$C17/J$8 -> 1000
B19: 8% Cap Rate - Clearance NOI Based on Extimated Expenses
D21: Total Rent Sq. Ft. Range
D22: % Inc. | E22: =E23/$D23-1 -> 0.16666667 | F22: =F23/$D23-1 -> 0.33333333 | G22: =G23/$D23-1 -> 0.5 | H22: =H23/$D23-1 -> 0.66666667 | I22: =I23/$D23-1 -> 0.83333333 | J22: =J23/$D23-1 -> 1
D23: 7.25 | E23: =($J$23-$D$23)/6+D23 -> 8.4583333 | F23: =($J$23-$D$23)/6+E23 -> 9.6666667 | G23: =($J$23-$D$23)/6+F23 -> 10.875 | H23: =($J$23-$D$23)/6+G23 -> 12.083333 | I23: =($J$23-$D$23)/6+H23 -> 13.291667 | J23: =D23*2 -> 14.5
B24: NNN + Corporate Cost Range ($000s) | C24: 20 | D24: =D$23*$N$7/1000-$C24 -> 40.9 | E24: =E$23*$N$7/1000-$C24 -> 51.05 | F24: =F$23*$N$7/1000-$C24 -> 61.2 | G24: =G$23*$N$7/1000-$C24 -> 71.35 | H24: =H$23*$N$7/1000-$C24 -> 81.5 | I24: =I$23*$N$7/1000-$C24 -> 91.65 | J24: =J$23*$N$7/1000-$C24 -> 101.8
C25: =($C$32-$C$24)/8+C24 -> 27.5 | D25: =D$23*$N$7/1000-$C25 -> 33.4 | E25: =E$23*$N$7/1000-$C25 -> 43.55 | F25: =F$23*$N$7/1000-$C25 -> 53.7 | G25: =G$23*$N$7/1000-$C25 -> 63.85 | H25: =H$23*$N$7/1000-$C25 -> 74 | I25: =I$23*$N$7/1000-$C25 -> 84.15 | J25: =J$23*$N$7/1000-$C25 -> 94.3
C26: =($C$32-$C$24)/8+C25 -> 35 | D26: =D$23*$N$7/1000-$C26 -> 25.9 | E26: =E$23*$N$7/1000-$C26 -> 36.05 | F26: =F$23*$N$7/1000-$C26 -> 46.2 | G26: =G$23*$N$7/1000-$C26 -> 56.35 | H26: =H$23*$N$7/1000-$C26 -> 66.5 | I26: =I$23*$N$7/1000-$C26 -> 76.65 | J26: =J$23*$N$7/1000-$C26 -> 86.8
C27: =($C$32-$C$24)/8+C26 -> 42.5 | D27: =D$23*$N$7/1000-$C27 -> 18.4 | E27: =E$23*$N$7/1000-$C27 -> 28.55 | F27: =F$23*$N$7/1000-$C27 -> 38.7 | G27: =G$23*$N$7/1000-$C27 -> 48.85 | H27: =H$23*$N$7/1000-$C27 -> 59 | I27: =I$23*$N$7/1000-$C27 -> 69.15 | J27: =J$23*$N$7/1000-$C27 -> 79.3
C28: =($C$32-$C$24)/8+C27 -> 50 | D28: =D$23*$N$7/1000-$C28 -> 10.9 | E28: =E$23*$N$7/1000-$C28 -> 21.05 | F28: =F$23*$N$7/1000-$C28 -> 31.2 | G28: =G$23*$N$7/1000-$C28 -> 41.35 | H28: =H$23*$N$7/1000-$C28 -> 51.5 | I28: =I$23*$N$7/1000-$C28 -> 61.65 | J28: =J$23*$N$7/1000-$C28 -> 71.8
C29: =($C$32-$C$24)/8+C28 -> 57.5 | D29: =D$23*$N$7/1000-$C29 -> 3.4 | E29: =E$23*$N$7/1000-$C29 -> 13.55 | F29: =F$23*$N$7/1000-$C29 -> 23.7 | G29: =G$23*$N$7/1000-$C29 -> 33.85 | H29: =H$23*$N$7/1000-$C29 -> 44 | I29: =I$23*$N$7/1000-$C29 -> 54.15 | J29: =J$23*$N$7/1000-$C29 -> 64.3
C30: =($C$32-$C$24)/8+C29 -> 65 | D30: =D$23*$N$7/1000-$C30 -> -4.1 | E30: =E$23*$N$7/1000-$C30 -> 6.05 | F30: =F$23*$N$7/1000-$C30 -> 16.2 | G30: =G$23*$N$7/1000-$C30 -> 26.35 | H30: =H$23*$N$7/1000-$C30 -> 36.5 | I30: =I$23*$N$7/1000-$C30 -> 46.65 | J30: =J$23*$N$7/1000-$C30 -> 56.8
C31: =($C$32-$C$24)/8+C30 -> 72.5 | D31: =D$23*$N$7/1000-$C31 -> -11.6 | E31: =E$23*$N$7/1000-$C31 -> -1.45 | F31: =F$23*$N$7/1000-$C31 -> 8.7 | G31: =G$23*$N$7/1000-$C31 -> 18.85 | H31: =H$23*$N$7/1000-$C31 -> 29 | I31: =I$23*$N$7/1000-$C31 -> 39.15 | J31: =J$23*$N$7/1000-$C31 -> 49.3
C32: 80 | D32: =D$23*$N$7/1000-$C32 -> -19.1 | E32: =E$23*$N$7/1000-$C32 -> -8.95 | F32: =F$23*$N$7/1000-$C32 -> 1.2 | G32: =G$23*$N$7/1000-$C32 -> 11.35 | H32: =H$23*$N$7/1000-$C32 -> 21.5 | I32: =I$23*$N$7/1000-$C32 -> 31.65 | J32: =J$23*$N$7/1000-$C32 -> 41.8
B34: 9% Cap Rate - Clearance NOI Based on Extimated Expenses
D36: Total Rent Sq. Ft. Range
D37: % Inc. | E37: =E38/$D38-1 -> 0.16666667 | F37: =F38/$D38-1 -> 0.33333333 | G37: =G38/$D38-1 -> 0.5 | H37: =H38/$D38-1 -> 0.66666667 | I37: =I38/$D38-1 -> 0.83333333 | J37: =J38/$D38-1 -> 1
D38: 7.25 | E38: =($J$23-$D$23)/6+D38 -> 8.4583333 | F38: =($J$23-$D$23)/6+E38 -> 9.6666667 | G38: =($J$23-$D$23)/6+F38 -> 10.875 | H38: =($J$23-$D$23)/6+G38 -> 12.083333 | I38: =($J$23-$D$23)/6+H38 -> 13.291667 | J38: =D38*2 -> 14.5
B39: NNN + Corporate Cost Range ($000s) | C39: 20 | D39: =D$23*$N$7/1000-$C39 -> 40.9 | E39: =E$23*$N$7/1000-$C39 -> 51.05 | F39: =F$23*$N$7/1000-$C39 -> 61.2 | G39: =G$23*$N$7/1000-$C39 -> 71.35 | H39: =H$23*$N$7/1000-$C39 -> 81.5 | I39: =I$23*$N$7/1000-$C39 -> 91.65 | J39: =J$23*$N$7/1000-$C39 -> 101.8
C40: =($C$32-$C$24)/8+C39 -> 27.5 | D40: =D$23*$N$7/1000-$C40 -> 33.4 | E40: =E$23*$N$7/1000-$C40 -> 43.55 | F40: =F$23*$N$7/1000-$C40 -> 53.7 | G40: =G$23*$N$7/1000-$C40 -> 63.85 | H40: =H$23*$N$7/1000-$C40 -> 74 | I40: =I$23*$N$7/1000-$C40 -> 84.15 | J40: =J$23*$N$7/1000-$C40 -> 94.3
C41: =($C$32-$C$24)/8+C40 -> 35 | D41: =D$23*$N$7/1000-$C41 -> 25.9 | E41: =E$23*$N$7/1000-$C41 -> 36.05 | F41: =F$23*$N$7/1000-$C41 -> 46.2 | G41: =G$23*$N$7/1000-$C41 -> 56.35 | H41: =H$23*$N$7/1000-$C41 -> 66.5 | I41: =I$23*$N$7/1000-$C41 -> 76.65 | J41: =J$23*$N$7/1000-$C41 -> 86.8
C42: =($C$32-$C$24)/8+C41 -> 42.5 | D42: =D$23*$N$7/1000-$C42 -> 18.4 | E42: =E$23*$N$7/1000-$C42 -> 28.55 | F42: =F$23*$N$7/1000-$C42 -> 38.7 | G42: =G$23*$N$7/1000-$C42 -> 48.85 | H42: =H$23*$N$7/1000-$C42 -> 59 | I42: =I$23*$N$7/1000-$C42 -> 69.15 | J42: =J$23*$N$7/1000-$C42 -> 79.3
C43: =($C$32-$C$24)/8+C42 -> 50 | D43: =D$23*$N$7/1000-$C43 -> 10.9 | E43: =E$23*$N$7/1000-$C43 -> 21.05 | F43: =F$23*$N$7/1000-$C43 -> 31.2 | G43: =G$23*$N$7/1000-$C43 -> 41.35 | H43: =H$23*$N$7/1000-$C43 -> 51.5 | I43: =I$23*$N$7/1000-$C43 -> 61.65 | J43: =J$23*$N$7/1000-$C43 -> 71.8
C44: =($C$32-$C$24)/8+C43 -> 57.5 | D44: =D$23*$N$7/1000-$C44 -> 3.4 | E44: =E$23*$N$7/1000-$C44 -> 13.55 | F44: =F$23*$N$7/1000-$C44 -> 23.7 | G44: =G$23*$N$7/1000-$C44 -> 33.85 | H44: =H$23*$N$7/1000-$C44 -> 44 | I44: =I$23*$N$7/1000-$C44 -> 54.15 | J44: =J$23*$N$7/1000-$C44 -> 64.3
C45: =($C$32-$C$24)/8+C44 -> 65 | D45: =D$23*$N$7/1000-$C45 -> -4.1 | E45: =E$23*$N$7/1000-$C45 -> 6.05 | F45: =F$23*$N$7/1000-$C45 -> 16.2 | G45: =G$23*$N$7/1000-$C45 -> 26.35 | H45: =H$23*$N$7/1000-$C45 -> 36.5 | I45: =I$23*$N$7/1000-$C45 -> 46.65 | J45: =J$23*$N$7/1000-$C45 -> 56.8
C46: =($C$32-$C$24)/8+C45 -> 72.5 | D46: =D$23*$N$7/1000-$C46 -> -11.6 | E46: =E$23*$N$7/1000-$C46 -> -1.45 | F46: =F$23*$N$7/1000-$C46 -> 8.7 | G46: =G$23*$N$7/1000-$C46 -> 18.85 | H46: =H$23*$N$7/1000-$C46 -> 29 | I46: =I$23*$N$7/1000-$C46 -> 39.15 | J46: =J$23*$N$7/1000-$C46 -> 49.3
C47: 80 | D47: =D$23*$N$7/1000-$C47 -> -19.1 | E47: =E$23*$N$7/1000-$C47 -> -8.95 | F47: =F$23*$N$7/1000-$C47 -> 1.2 | G47: =G$23*$N$7/1000-$C47 -> 11.35 | H47: =H$23*$N$7/1000-$C47 -> 21.5 | I47: =I$23*$N$7/1000-$C47 -> 31.65 | J47: =J$23*$N$7/1000-$C47 -> 41.8
...

Sheet Market Rent Analysis
B2: =+Cover!B24 -> Sunshine Commercial Investments
B3: CRE Market Rent Analysis ($)
K4: Print | L4: 1
B5: Current Rent / Sq. Ft.
B6: =+'Tennant View'!B23 -> Total Current Rent | C6: =+'Tennant View'!C33 -> 60900
B7: Total Leasable Square Footage | C7: 8400
B8: Current Rent / Sq. Ft. | C8: =C6/C7 -> 7.25
B10: Property | C10: City | D10: Size (SF) | E10: Built | F10: Type | G10: Base Rent | H10: NNN Rate | I10: Total Rent
B11: 2115 W 9 Mile Rd | C11: Pensacola | D11: 800 | E11: 1998 | F11: Retail | G11: 19.5 | H11: 4.97 | I11: 24.47 | N11: 2115 W 9 Mile Rd
B12: 4628 Summerdale Blvd | C12: Pace | D12: 1062 | E12: 2004 | F12: Office | G12: 18.5 | H12: - | I12: - | N12: 4628 Summerdale Blvd
B13: 6317–6327 Dogwood Dr | C13: Milton | D13: 1291 | E13: 2004 | F13: Retail/flex | G13: 18 | H13: 2.93 | I13: =G13+H13 -> 20.93 | N13: 6317–6327 Dogwood Dr
B14: 5118 Canal St | C14: Milton | D14: 3110 | E14: 1951 | F14: Retail | G14: 18 | H14: - | I14: - | N14: 5118 Canal St
B15: 5700 N Davis Hwy | C15: Pensacola | D15: 1452 | E15: 1987 | F15: Retail | G15: 17.5 | H15: 3.5 | I15: =G15+H15 -> 21 | N15: 5700 N Davis Hwy
B16: 7000 Pine Forest Rd | C16: Pensacola | D16: 1200 | E16: 1990 | F16: Retail | G16: 16.5 | H16: - | I16: - | N16: 7000 Pine Forest Rd
B17: Quietwater Bldg 1 Suite 360 | C17: Gulf Breeze | D17: 1861 | E17: 1985 | F17: Office | G17: 16 | H17: - | I17: - | N17: Quietwater Bldg 1 Suite 360
B18: 5022 W Fairfield Dr | C18: Pensacola | D18: 1100 | E18: 2004 | F18: Office | G18: 16 | H18: 4.5 | I18: 20.5 | N18: 5022 W Fairfield Dr
B19: 275 W Airport Blvd | C19: Pensacola | D19: 3600 | E19: 1995 | F19: Retail | G19: 15.25 | H19: 4 | I19: =H19+G19 -> 19.25 | N19: 275 W Airport Blvd
B20: 4848 Ward Basin Rd | C20: Milton | D20: 2147 | E20: 1960 | F20: Office/Retail | G20: 15 | H20: 2.25 | I20: =G20+H20 -> 17.25 | N20: 4848 Ward Basin Rd
B21: 8602-8612 Pensacola Blvd | C21: Pensacola | D21: 1300 | E21: 1974 | F21: Retail | G21: 14.5 | H21: - | I21: - | N21: 8602-8612 Pensacola Blvd
B22: 4455-4497 Mobile Hwy | C22: Pensacola | D22: 7800 | E22: 1985 | F22: Retail | G22: 14 | H22: 4.5 | I22: =+H22+G22 -> 18.5 | N22: 4455-4497 Mobile Hwy
B23: 3620-3642 Barrancas Ave | C23: Pensacola | D23: 900 | E23: 1952 | F23: Retail | G23: 13.5 | H23: 3.75 | I23: =+H23+G23 -> 17.25 | N23: 3620-3642 Barrancas Ave
B24: 3960 W Navy Blvd | C24: Pensacola | D24: 1300 | E24: 1984 | F24: Retail | G24: 13.5 | H24: 3 | I24: 16.5 | N24: 3960 W Navy Blvd
B25: Average | G25: =AVERAGE(G11:G24) -> 16.125 | H25: =AVERAGE(H11:H24) -> 3.7111111 | I25: =AVERAGE(I11:I24) -> 19.516667
B26: Target Property | C26: Milton | D26: =+C7 -> 8400 | E26: 1965 | F26: Retail | G26: 7.25 | H26: 0 | I26: 7.25
B28: Implied Upside ($000s)
C30: Current | D30: Pro Forma
C31: Total Rent | D31: Base Rent | E31: Total Rent
B32: Annual Rental Income | C32: =+C6/1000 -> 60.9 | D32: =$C$32*(1+D$33) -> 135.45 | E32: =$C$32*(1+E$33) -> 163.94
B33: % Increase | D33: =G25/G26-1 -> 1.2241379 | E33: =I25/I26-1 -> 1.691954
G37: 1000
G38: =G37/20 -> 50
B39: Market Rent Analysis | G39: =G37*0.065 -> 65 | AB39: Source
B40: Low-End Rate | C40: 8 | G40: =+G39+G38 -> 115
B41: Base-Rate | C41: 10
B42: High-End Rate | C42: 14
C44: Low-End | D44: Base-Rate
B45: Implied Annual Rent Calculation
B46: Estimated Rent / Sq. Ft | C46: =+'Market Rent Analysis'!C40 -> 8 | D46: =+'Market Rent Analysis'!C41 -> 10
B47: (x) Leasable Sq. Ft. | C47: =+'Market Rent Analysis'!C7 -> 8400 | D47: =C47 -> 8400
B48: Implied Annual Rent | C48: =C46*C47 -> 67200 | D48: =D46*D47 -> 84000
...

Sheet CRE Precident Transactions
B2: =+Cover!B24 -> Sunshine Commercial Investments
B3: CRE Market Rent Analysis ($)

Sheet Laundromat Valuation
B2: =+Cover!B24 -> Sunshine Commercial Investments
B3: Laundromat P&L Summary & Valuation ($000s) | H3: Print | I3: 0
B5: Laundromat P&L Summary
C7: FY22 | D7: FY23 | E7: FY24 | F7: Pro Forma
B9: Revenue | C9: 338.594 | D9: 357.943 | E9: 376.06 | F9: =E9*(1+C57) -> 376.06
B10: % Growth | D10: =D9/C9-1 -> 0.057145135 | E10: =E9/D9-1 -> 0.050614204 | F10: =F9/E9-1 -> 0
B12: Expenses
B13: Utilities | C13: 90.936 | D13: 91.989 | E13: 91.269 | F13: =F9*C58 -> 96.134332
B14: % Sales | C14: =C13/C$9 -> 0.26856944 | D14: =D13/D$9 -> 0.25699343 | E14: =E13/E$9 -> 0.24269797 | F14: =F13/F$9 -> 0.25563562
B15: Labor | C15: 0 | D15: 0 | E15: 55 | F15: =+C60 -> 55
B16: % Sales | C16: =C15/C$9 -> 0 | D16: =D15/D$9 -> 0 | E16: =E15/E$9 -> 0.14625326 | F16: =F15/F$9 -> 0.14625326
B17: Repairs & Maintenance | C17: 22.728 | D17: 46.544 | E17: 30.54 | F17: =+C61 -> 33.270667
B18: % Sales | C18: =C17/C$9 -> 0.067124639 | D18: =D17/D$9 -> 0.13003188 | E18: =E17/E$9 -> 0.081210445 | F18: =F17/F$9 -> 0.088471698
B19: Lease | C19: 14.4 | D19: 13.2 | E19: 14.412 | F19: =+C62 -> 16.078818
B20: % Sales | C20: =C19/C$9 -> 0.04252881 | D20: =D19/D$9 -> 0.03687738 | E20: =E19/E$9 -> 0.038323672 | F20: =F19/F$9 -> 0.04275599
B21: Insurance | C21: 0 | D21: 14.958 | E21: 4.384 | F21: =+C64 -> 4.384
B22: % Sales | C22: =C21/C$9 -> 0 | D22: =D21/D$9 -> 0.041788776 | E22: =E21/E$9 -> 0.011657714 | F22: =F21/F$9 -> 0.011657714
B23: Debt Servicing | C23: 0 | D23: 12.608 | E23: 14.67 | F23: =(C71/C72)+(C71*C73) -> 57.336475 | H23: Note: The increased interest is due to including half of the total mortgage interest allocated to the laundromat
B24: % Sales | C24: =C23/C$9 -> 0 | D24: =D23/D$9 -> 0.035223485 | E24: =E23/E$9 -> 0.039009732 | F24: =F23/F$9 -> 0.15246629
B25: Depreciation | C25: 8.661 | D25: 27.542 | E25: 28.555 | F25: =+C63 -> 8.661 | H25: Note: The increased depreciation is due to acquiring the CRE in Feb'23
B26: % Sales | C26: =C25/C$9 -> 0.025579307 | D26: =D25/D$9 -> 0.076945212 | E26: =E25/E$9 -> 0.075932032 | F26: =F25/F$9 -> 0.023030899
B27: Taxes | C27: 0 | D27: 0 | E27: 0 | F27: =+F9*C66 -> 0
B28: % Sales | C28: =C27/C$9 -> 0 | D28: =D27/D$9 -> 0 | E28: =E27/E$9 -> 0 | F28: =F27/F$9 -> 0
B29: Other Expenses | C29: =+C31-C25-C23-C21-C19-C17-C15-C13-C27 -> 10.552 | D29: =+D31-D25-D23-D21-D19-D17-D15-D13-D27 -> 9.92 | E29: =+E31-E25-E23-E21-E19-E17-E15-E13-E27 -> 8.899 | F29: =+C67 -> 9.7903333
B30: % Sales | C30: =C29/C$9 -> 0.031164167 | D30: =D29/D$9 -> 0.02771391 | E30: =E29/E$9 -> 0.023663777 | F30: =F29/F$9 -> 0.026033966
B31: Total Expenses | C31: 147.277 | D31: 216.761 | E31: 247.729 | F31: =+F29+F25+F23+F21+F19+F17+F15+F13 -> 280.65562
B32: % Sales | C32: =C31/C$9 -> 0.43496636 | D32: =D31/D$9 -> 0.60557407 | E32: =E31/E$9 -> 0.6587486 | F32: =F31/F$9 -> 0.74630544
B34: Reported Net Income | C34: =+C9-C31 -> 191.317 | D34: =+D9-D31 -> 141.182 | E34: =+E9-E31 -> 128.331 | F34: =+F9-F31 -> 95.404376
B36: EBITDA Bridge
B37: Net Income | C37: =+C34 -> 191.317 | D37: =+D34 -> 141.182 | E37: =+E34 -> 128.331 | F37: =+F34 -> 95.404376
B38: (+) Interest | C38: =+C23 -> 0 | D38: =+D23 -> 12.608 | E38: =+E23 -> 14.67 | F38: =+F23 -> 57.336475
B39: (+) Depreciation | C39: =+C25 -> 8.661 | D39: =+D25 -> 27.542 | E39: =+E25 -> 28.555 | F39: =+F25 -> 8.661
B40: (-) Capital Reserve | C40: =-$C$63 -> -8.661 | D40: =-$C$63 -> -8.661 | E40: =-$C$63 -> -8.661 | F40: =-$C$63 -> -8.661
B41: (+) Taxes | C41: =+C27 -> 0 | D41: =+D27 -> 0 | E41: =+E27 -> 0 | F41: =+F27 -> 0
B42: Adj. EBITDA | C42: =SUM(C37:C41) -> 191.317 | D42: =SUM(D37:D41) -> 172.671 | E42: =SUM(E37:E41) -> 162.895 | F42: =SUM(F37:F41) -> 152.74085
B43: % Margin | C43: =C42/C$9 -> 0.56503364 | D43: =D42/D$9 -> 0.48239804 | E43: =E42/E$9 -> 0.43316226 | F43: =F42/F$9 -> 0.40616085
B45: (+) Owner Compensation | C45: =+C15 -> 0 | D45: =+D15 -> 0 | E45: =+E15 -> 55 | F45: =+F15 -> 55
B47: SDE | C47: =+C42+C45 -> 191.317 | D47: =+D42+D45 -> 172.671 | E47: =+E42+E45 -> 217.895 | F47: =+F42+F45 -> 207.74085
B48: % Margin | C48: =C47/C$9 -> 0.56503364 | D48: =D47/D$9 -> 0.48239804 | E48: =E47/E$9 -> 0.57941552 | F48: =F47/F$9 -> 0.55241411
B50: Business Valuation
...
