Workbook

Sheet Cover
B24: Sunshine Commercial Investments
B25: Diligence Workbook
B26: ="As of "&TEXT(TODAY(),"mm/dd/yy") -> As of 08/06/26

Sheet Valuation Overview
B2: =+Cover!B24 -> Sunshine Commercial Investments
B3: Valuation Overview ($000s) | H3: Print | I3: 1
C5: Current Valuation | D5: Clearing Price | E5: NNN Valuation | F5: Base-Rate Valuation
B7: Laundromat | C7: =ROUND(+'Laundromat Valuation'!F53,-2) -> 600 | D7: =C7 -> 600 | E7: =C7 -> 600 | F7: =E7 -> 600
B8: Commercial Real Estate | C8: =+'CRE Income Capitalization'!C57/1000 -> 395.275 | D8: =+'CRE Income Capitalization'!D57/1000 -> 1000 | E8: =+'CRE Income Capitalization'!E57/1000 -> 1036.425 | F8: =+'CRE Income Capitalization'!F57/1000 -> 1115.175
B9: Total Valuation | C9: =+C8+C7 -> 995.275 | D9: =+D8+D7 -> 1600 | E9: =+E8+E7 -> 1636.425 | F9: =+F8+F7 -> 1715.175
B10: (-) Asking Price | C10: -1600 | D10: =C10 -> -1600 | E10: =C10 -> -1600 | F10: =E10 -> -1600
B11: Delta | C11: =+C9+C10 -> -604.725 | D11: =+D9+D10 -> 0 | E11: =+E9+E10 -> 36.425 | F11: =+F9+F10 -> 115.175
B13: Annual Rent Impact
C15: =+C$5 -> Current Valuation | D15: =+D$5 -> Clearing Price | E15: =+E$5 -> NNN Valuation | F15: =+F$5 -> Base-Rate Valuation
B17: =+'CRE Income Capitalization'!B10 -> Community Theater | C17: =+'CRE Income Capitalization'!D10/1000 -> 21.6 | D17: =D$22*$H17 -> 31.007172 | E17: =E$22*$H17 -> 32.040709 | F17: =F$22*$H17 -> 40.233813 | H17: =C17/$C$22 -> 0.3546798
B18: =+'CRE Income Capitalization'!B11 -> Laundromat | C18: =+'CRE Income Capitalization'!D11/1000 -> 14.4 | D18: =D$22*$H18 -> 20.671448 | E18: =E$22*$H18 -> 21.360473 | F18: =F$22*$H18 -> 26.822542 | H18: =C18/$C$22 -> 0.2364532
B19: =+'CRE Income Capitalization'!B12 -> Turnaround Testron* | C19: =+'CRE Income Capitalization'!D12/1000 -> 9.3 | D19: =D$22*$H19 -> 13.35031 | E19: =E$22*$H19 -> 13.795305 | F19: =F$22*$H19 -> 17.322892 | H19: =C19/$C$22 -> 0.15270936
B20: =+'CRE Income Capitalization'!B13 -> Consignment Shop | C20: =+'CRE Income Capitalization'!D13/1000 -> 8.4 | D20: =D$22*$H20 -> 12.058345 | E20: =E$22*$H20 -> 12.460276 | F20: =F$22*$H20 -> 15.646483 | H20: =C20/$C$22 -> 0.13793103
B21: =+'CRE Income Capitalization'!B14 -> Book Store | C21: =+'CRE Income Capitalization'!D14/1000 -> 7.2 | D21: =D$22*$H21 -> 10.335724 | E21: =E$22*$H21 -> 10.680236 | F21: =F$22*$H21 -> 13.411271 | H21: =C21/$C$22 -> 0.1182266
B22: Total Annual Rent | C22: =SUM(C17:C21) -> 60.9 | D22: =+'CRE Income Capitalization'!D40/1000 -> 87.423 | E22: =+'CRE Income Capitalization'!E40/1000 -> 90.337 | F22: =+'CRE Income Capitalization'!G40/1000 -> 113.437
B23: % Increase | D23: =D22/$C$22-1 -> 0.43551724 | E23: =E22/$C$22-1 -> 0.48336617 | F23: =F22/$C$22-1 -> 0.86267652
B25: Monthly Rent Impact
C27: =+C$5 -> Current Valuation | D27: =+D$5 -> Clearing Price | E27: =+E$5 -> NNN Valuation | F27: =+F$5 -> Base-Rate Valuation
B29: =+B17 -> Community Theater | C29: =+'CRE Income Capitalization'!C10 -> 1800 | D29: =D$34*$H29 -> 2583.931 | E29: =E$34*$H29 -> 2670.0591 | F29: =F$34*$H29 -> 3352.8177 | H29: =C29/$C$34 -> 0.3546798
B30: =+B18 -> Laundromat | C30: =+'CRE Income Capitalization'!C11 -> 1200 | D30: =D$34*$H30 -> 1722.6207 | E30: =E$34*$H30 -> 1780.0394 | F30: =F$34*$H30 -> 2235.2118 | H30: =C30/$C$34 -> 0.2364532
B31: =+B19 -> Turnaround Testron* | C31: =+'CRE Income Capitalization'!C12 -> 775 | D31: =D$34*$H31 -> 1112.5259 | E31: =E$34*$H31 -> 1149.6088 | F31: =F$34*$H31 -> 1443.5743 | H31: =C31/$C$34 -> 0.15270936
B32: =+B20 -> Consignment Shop | C32: =+'CRE Income Capitalization'!C13 -> 700 | D32: =D$34*$H32 -> 1004.8621 | E32: =E$34*$H32 -> 1038.3563 | F32: =F$34*$H32 -> 1303.8736 | H32: =C32/$C$34 -> 0.13793103
B33: =+B21 -> Book Store | C33: =+'CRE Income Capitalization'!C14 -> 600 | D33: =D$34*$H33 -> 861.31034 | E33: =E$34*$H33 -> 890.0197 | F33: =F$34*$H33 -> 1117.6059 | H33: =C33/$C$34 -> 0.1182266
B34: Total Monthly Rent | C34: =SUM(C29:C33) -> 5075 | D34: =+D22/12*1000 -> 7285.25 | E34: =+E22/12*1000 -> 7528.0833 | F34: =+F22/12*1000 -> 9453.0833
B35: % Increase | D35: =D34/$C$34-1 -> 0.43551724 | E35: =E34/$C$34-1 -> 0.48336617 | F35: =F34/$C$34-1 -> 0.86267652
C72: Valuation | D72: % Delta | E72: % Delta
B73: Prior Transaction Consideration | C73: 580000
B74: County Cost-Approach | C74: 435734
B75: Precedent Transactions
B76: Average Valuation
B78: Income Capitalization Approach
B80: 2024 Net Income | C80: 128331
B81: Mortgage Interest | C81: 14670
B82: Total Earnings | C82: =+C80+C81 -> 143001
C83: 3
B84: Implied Valuation | C84: =C82*C83 -> 429003
B85: Less Accumulated Depreciation
B90: Depreciation | C90: 28555

Sheet CRE Income Capitalization
B2: =+Cover!B24 -> Sunshine Commercial Investments
B3: Commercial Real Estate Valuation ($) | N3: Print | O3: 1
B5: CRE Rent Overview
C7: Current Rent | I7: Pro Forma Rent ($)
C8: Monthly | D8: Annual | I8: Monthly | J8: Annual
B10: Community Theater | C10: 1800 | D10: =C10*12 -> 21600 | I10: =C10*(1+$G$48) -> 3352.8177 | J10: =I10*12 -> 40233.813
B11: Laundromat | C11: 1200 | D11: =C11*12 -> 14400 | I11: =C11*(1+$G$48) -> 2235.2118 | J11: =I11*12 -> 26822.542
B12: Turnaround Testron* | C12: 775 | D12: =C12*12 -> 9300 | I12: =C12*(1+$G$48) -> 1443.5743 | J12: =I12*12 -> 17322.892
B13: Consignment Shop | C13: 700 | D13: =C13*12 -> 8400 | I13: =C13*(1+$G$48) -> 1303.8736 | J13: =I13*12 -> 15646.483
B14: Book Store | C14: 600 | D14: =C14*12 -> 7200 | I14: =C14*(1+$G$48) -> 1117.6059 | J14: =I14*12 -> 13411.271 | AA14: Source
B15: Total Current Rent | C15: =SUM(C10:C14) -> 5075 | D15: =SUM(D10:D14) -> 60900 | I15: =SUM(I10:I14) -> 9453.0833 | J15: =I15*12 -> 113437
B17: *Cannot verify through Google Maps -- appears to be Carrie’s Beauty Salon
B19: Current Rent / Sq. Ft.
B20: =+B15 -> Total Current Rent | C20: =+D15 -> 60900
B21: Total Leasable Square Footage | C21: 8400
B22: Current Rent / Sq. Ft. | C22: =C20/C21 -> 7.25
B24: Market Rent Analysis
B25: Low-End Rate | C25: 8
B26: Base-Rate | C26: 10
B27: High-End Rate | C27: 14
C29: Low-End | D29: Base-Rate
B30: Implied Annual Rent Calculation
B31: Estimated Rent / Sq. Ft | C31: =+C25 -> 8 | D31: =+C26 -> 10
B32: (x) Leasable Sq. Ft. | C32: =+C21 -> 8400 | D32: =C32 -> 8400
B33: Implied Annual Rent | C33: =C31*C32 -> 67200 | D33: =D31*D32 -> 84000
B34: % Increase | C34: =C33/$C$20-1 -> 0.10344828 | D34: =D33/$C$20-1 -> 0.37931034
B36: Estimated NOI
C38: FY25 | D38: Clearing | E38: NNN | F38: Low-End | G38: Base-Rate
B40: =+B15 -> Total Current Rent | C40: =+D15 -> 60900 | D40: =D55-D44-D43 -> 87423 | E40: =+D15-$C$41-$O$42-$C$45 -> 90337 | F40: =+C33-$C$41-$O$42-$C$45 -> 96637 | G40: =+D33-$C$41-$O$42-$C$45 -> 113437
B41: (-) Insurance | C41: -10000 | D41: 0 | E41: 0 | F41: 0 | G41: 0
B42: (-) Taxes | C42: -5855 | D42: 0 | E42: 0 | F42: 0 | G42: 0 | J42: Based on this calculator (currently assumes $1M sale) | O42: -13437
B43: (-) Property Management | C43: -3423 | D43: =C43 -> -3423 | E43: =C43 -> -3423 | F43: =E43 -> -3423 | G43: =F43 -> -3423
B44: (-) Maintenance | C44: -4000 | D44: =C44 -> -4000 | E44: =C44 -> -4000 | F44: =E44 -> -4000 | G44: =F44 -> -4000
B45: (-) Utilities | C45: -6000 | D45: 0 | E45: 0 | F45: 0 | G45: 0
B46: Net Operating Income | C46: =SUM(C40:C45) -> 31622 | D46: =SUM(D40:D45) -> 80000 | E46: =SUM(E40:E45) -> 82914 | F46: =SUM(F40:F45) -> 89214 | G46: =SUM(G40:G45) -> 106014 | J46: Assumes NNN structure
B48: Implied Rent Increase for NNN | C48: =C40/$C$40-1 -> 0 | D48: =D40/$C$40-1 -> 0.43551724 | E48: =E40/$C$40-1 -> 0.48336617 | F48: =F40/$C$40-1 -> 0.58681445 | G48: =G40/$C$40-1 -> 0.86267652
B50: =+B46 -> Net Operating Income | C50: =+C46 -> 31622 | D50: =+D46 -> 80000 | E50: =+E46 -> 82914 | F50: =+F46 -> 89214 | G50: =+G46 -> 106014
B51: (/) Prior Transaction Value | C51: 580000 | D51: =C51 -> 580000 | E51: =C51 -> 580000 | F51: =E51 -> 580000 | G51: =F51 -> 580000
B52: Implied Cap Rate | C52: =C50/C51 -> 0.05452069 | D52: =D50/D51 -> 0.13793103 | E52: =E50/E51 -> 0.14295517 | F52: =F50/F51 -> 0.15381724 | G52: =G50/G51 -> 0.18278276
C54: =+C38 -> FY25 | D54: =+D38 -> Clearing | E54: =+E38 -> NNN | F54: =+F38 -> Low-End | G54: =+G38 -> Base-Rate
...

Sheet Laundromat Valuation
B2: =+Cover!B24 -> Sunshine Commercial Investments
B3: Laundromat P&L Summary & Valuation ($000s) | H3: Print | I3: 1
B5: Laundromat P&L Summary
C7: FY22 | D7: FY23 | E7: FY24 | F7: Pro Forma
B9: Revenue | C9: 338.594 | D9: 357.943 | E9: 376.06 | F9: =E9*(1+C57) -> 376.06
B10: % Growth | D10: =D9/C9-1 -> 0.057145135 | E10: =E9/D9-1 -> 0.050614204 | F10: =F9/E9-1 -> 0
B12: Expenses
B13: Utilities | C13: 90.936 | D13: 91.989 | E13: 91.269 | F13: =F9*C58 -> 96.134332
B14: % Sales | C14: =C13/C$9 -> 0.26856944 | D14: =D13/D$9 -> 0.25699343 | E14: =E13/E$9 -> 0.24269797 | F14: =F13/F$9 -> 0.25563562
B15: Labor | C15: 0 | D15: 0 | E15: 55 | F15: =+C60 -> 55
B16: % Sales | C16: =C15/C$9 -> 0 | D16: =D15/D$9 -> 0 | E16: =E15/E$9 -> 0.14625326 | F16: =F15/F$9 -> 0.14625326
B17: Repairs & Maintenance | C17: 22.728 | D17: 46.544 | E17: 30.54 | F17: =+C61 -> 33.270667
B18: % Sales | C18: =C17/C$9 -> 0.067124639 | D18: =D17/D$9 -> 0.13003188 | E18: =E17/E$9 -> 0.081210445 | F18: =F17/F$9 -> 0.088471698
B19: Lease | C19: 14.4 | D19: 13.2 | E19: 14.412 | F19: =+C62 -> 26.822542
B20: % Sales | C20: =C19/C$9 -> 0.04252881 | D20: =D19/D$9 -> 0.03687738 | E20: =E19/E$9 -> 0.038323672 | F20: =F19/F$9 -> 0.071325166
B21: Insurance | C21: 0 | D21: 14.958 | E21: 4.384 | F21: =+C64 -> 4.384
B22: % Sales | C22: =C21/C$9 -> 0 | D22: =D21/D$9 -> 0.041788776 | E22: =E21/E$9 -> 0.011657714 | F22: =F21/F$9 -> 0.011657714
B23: Debt Servicing | C23: 0 | D23: 12.608 | E23: 14.67 | F23: =(C71/C72)+(C71*C73) -> 54.371207 | H23: Note: The increased interest is due to including half of the total mortgage interest allocated to the laundromat
B24: % Sales | C24: =C23/C$9 -> 0 | D24: =D23/D$9 -> 0.035223485 | E24: =E23/E$9 -> 0.039009732 | F24: =F23/F$9 -> 0.1445812
B25: Depreciation | C25: 8.661 | D25: 27.542 | E25: 28.555 | F25: =+C63 -> 8.661 | H25: Note: The increased depreciation is due to acquiring the CRE in Feb'23
B26: % Sales | C26: =C25/C$9 -> 0.025579307 | D26: =D25/D$9 -> 0.076945212 | E26: =E25/E$9 -> 0.075932032 | F26: =F25/F$9 -> 0.023030899
B27: Taxes | C27: 0 | D27: 0 | E27: 0 | F27: =+F9*C66 -> 0
B28: % Sales | C28: =C27/C$9 -> 0 | D28: =D27/D$9 -> 0 | E28: =E27/E$9 -> 0 | F28: =F27/F$9 -> 0
B29: Other Expenses | C29: =+C31-C25-C23-C21-C19-C17-C15-C13-C27 -> 10.552 | D29: =+D31-D25-D23-D21-D19-D17-D15-D13-D27 -> 9.92 | E29: =+E31-E25-E23-E21-E19-E17-E15-E13-E27 -> 8.899 | F29: =+C67 -> 9.7903333
B30: % Sales | C30: =C29/C$9 -> 0.031164167 | D30: =D29/D$9 -> 0.02771391 | E30: =E29/E$9 -> 0.023663777 | F30: =F29/F$9 -> 0.026033966
B31: Total Expenses | C31: 147.277 | D31: 216.761 | E31: 247.729 | F31: =+F29+F25+F23+F21+F19+F17+F15+F13 -> 288.43408
B32: % Sales | C32: =C31/C$9 -> 0.43496636 | D32: =D31/D$9 -> 0.60557407 | E32: =E31/E$9 -> 0.6587486 | F32: =F31/F$9 -> 0.76698952
B34: Reported Net Income | C34: =+C9-C31 -> 191.317 | D34: =+D9-D31 -> 141.182 | E34: =+E9-E31 -> 128.331 | F34: =+F9-F31 -> 87.62592
B36: EBITDA Bridge
B37: Net Income | C37: =+C34 -> 191.317 | D37: =+D34 -> 141.182 | E37: =+E34 -> 128.331 | F37: =+F34 -> 87.62592
B38: (+) Interest | C38: =+C23 -> 0 | D38: =+D23 -> 12.608 | E38: =+E23 -> 14.67 | F38: =+F23 -> 54.371207
B39: (+) Depreciation | C39: =+C25 -> 8.661 | D39: =+D25 -> 27.542 | E39: =+E25 -> 28.555 | F39: =+F25 -> 8.661
B40: (-) Capital Reserve | C40: =-$C$63 -> -8.661 | D40: =-$C$63 -> -8.661 | E40: =-$C$63 -> -8.661 | F40: =-$C$63 -> -8.661
B41: (+) Taxes | C41: =+C27 -> 0 | D41: =+D27 -> 0 | E41: =+E27 -> 0 | F41: =+F27 -> 0
B42: Adj. EBITDA | C42: =SUM(C37:C41) -> 191.317 | D42: =SUM(D37:D41) -> 172.671 | E42: =SUM(E37:E41) -> 162.895 | F42: =SUM(F37:F41) -> 141.99713
B43: % Margin | C43: =C42/C$9 -> 0.56503364 | D43: =D42/D$9 -> 0.48239804 | E43: =E42/E$9 -> 0.43316226 | F43: =F42/F$9 -> 0.37759168
B45: (+) Owner Compensation | C45: =+C15 -> 0 | D45: =+D15 -> 0 | E45: =+E15 -> 55 | F45: =+F15 -> 55
B47: SDE | C47: =+C42+C45 -> 191.317 | D47: =+D42+D45 -> 172.671 | E47: =+E42+E45 -> 217.895 | F47: =+F42+F45 -> 196.99713
B48: % Margin | C48: =C47/C$9 -> 0.56503364 | D48: =D47/D$9 -> 0.48239804 | E48: =E47/E$9 -> 0.57941552 | F48: =F47/F$9 -> 0.52384494
B50: Business Valuation
...
