Workbook

Sheet Cover
B24: Keystone Bookkeepers
B25: Initial Financial Review
B26: ="As of "&TEXT(TODAY(),"mm/dd/yy") -> As of 09/03/26

Sheet P&L Overview
B2: =+Cover!B24 -> Keystone Bookkeepers
B3: Summary P&L Overview ($000s)
B5: P&L Summary ($000s) | C5: FY2024 | D5: FY2025 | F5: July'25 YTD | G5: July'26 YTD | I5: Jul'25 LTM | J5: Jul'26 LTM | L5: 45292 | M5: =EOMONTH(L5,0)+1 -> 45323 | N5: =EOMONTH(M5,0)+1 -> 45352 | O5: =EOMONTH(N5,0)+1 -> 45383 | P5: =EOMONTH(O5,0)+1 -> 45413 | Q5: =EOMONTH(P5,0)+1 -> 45444 | R5: =EOMONTH(Q5,0)+1 -> 45474 | S5: =EOMONTH(R5,0)+1 -> 45505 | T5: =EOMONTH(S5,0)+1 -> 45536 | ... AP5: =EOMONTH(AO5,0)+1 -> 46204
B6: Revenue
B7: STR Subscription | C7: =SUMIFS($L7:$AP7,$L$5:$AP$5,">"&C$42,$L$5:$AP$5,"<"&C$43) -> 793.47225 | D7: =SUMIFS($L7:$AP7,$L$5:$AP$5,">"&D$42,$L$5:$AP$5,"<"&D$43) -> 1450.4923 | F7: =SUMIFS($L7:$AP7,$L$5:$AP$5,">"&F$42,$L$5:$AP$5,"<"&F$43) -> 751.5286 | G7: =SUMIFS($L7:$AP7,$L$5:$AP$5,">"&G$42,$L$5:$AP$5,"<"&G$43) -> 1261.4769 | I7: =SUMIFS($L7:$AP7,$L$5:$AP$5,">"&I$42,$L$5:$AP$5,"<"&I$43) -> 1098.5075 | J7: =SUMIFS($L7:$AP7,$L$5:$AP$5,">"&J$42,$L$5:$AP$5,"<"&J$43) -> 1881.6971 | L7: =SUMIFS('Combined P&L'!N:N,'Combined P&L'!$C:$C,'P&L Overview'!$B7) -> 44.6835 | M7: =SUMIFS('Combined P&L'!O:O,'Combined P&L'!$C:$C,'P&L Overview'!$B7) -> 47.046 | N7: =SUMIFS('Combined P&L'!P:P,'Combined P&L'!$C:$C,'P&L Overview'!$B7) -> 52.47 | O7: =SUMIFS('Combined P&L'!Q:Q,'Combined P&L'!$C:$C,'P&L Overview'!$B7) -> 57.1697 | P7: =SUMIFS('Combined P&L'!R:R,'Combined P&L'!$C:$C,'P&L Overview'!$B7) -> 57.51415 | Q7: =SUMIFS('Combined P&L'!S:S,'Combined P&L'!$C:$C,'P&L Overview'!$B7) -> 65.516 | R7: =SUMIFS('Combined P&L'!T:T,'Combined P&L'!$C:$C,'P&L Overview'!$B7) -> 68.28125 | S7: =SUMIFS('Combined P&L'!U:U,'Combined P&L'!$C:$C,'P&L Overview'!$B7) -> 73.25135 | T7: =SUMIFS('Combined P&L'!V:V,'Combined P&L'!$C:$C,'P&L Overview'!$B7) -> 75.5517 | U7: =SUMIFS('Combined P&L'!W:W,'Combined P&L'!$C:$C,'P&L Overview'!$B7) -> 79.11325 | V7: =SUMIFS('Combined P&L'!X:X,'Combined P&L'!$C:$C,'P&L Overview'!$B7) -> 83.2908 | W7: =SUMIFS('Combined P&L'!Y:Y,'Combined P&L'!$C:$C,'P&L Overview'!$B7) -> 89.58455 | X7: =SUMIFS('Combined P&L'!Z:Z,'Combined P&L'!$C:$C,'P&L Overview'!$B7) -> 92.4189 | Y7: =SUMIFS('Combined P&L'!AA:AA,'Combined P&L'!$C:$C,'P&L Overview'!$B7) -> 94.00215 | Z7: =SUMIFS('Combined P&L'!AB:AB,'Combined P&L'!$C:$C,'P&L Overview'!$B7) -> 101.50605 | AA7: =SUMIFS('Combined P&L'!AC:AC,'Combined P&L'!$C:$C,'P&L Overview'!$B7) -> 106.1375 | AB7: =SUMIFS('Combined P&L'!AD:AD,'Combined P&L'!$C:$C,'P&L Overview'!$B7) -> 115.93875 | AC7: =SUMIFS('Combined P&L'!AE:AE,'Combined P&L'!$C:$C,'P&L Overview'!$B7) -> 119.43125 | AD7: =SUMIFS('Combined P&L'!AF:AF,'Combined P&L'!$C:$C,'P&L Overview'!$B7) -> 122.094 | AE7: =SUMIFS('Combined P&L'!AG:AG,'Combined P&L'!$C:$C,'P&L Overview'!$B7) -> 130.08525 | AF7: =SUMIFS('Combined P&L'!AH:AH,'Combined P&L'!$C:$C,'P&L Overview'!$B7) -> 133.5905 | AG7: =SUMIFS('Combined P&L'!AI:AI,'Combined P&L'!$C:$C,'P&L Overview'!$B7) -> 139.609 | AH7: =SUMIFS('Combined P&L'!AJ:AJ,'Combined P&L'!$C:$C,'P&L Overview'!$B7) -> 145.28075 | AI7: =SUMIFS('Combined P&L'!AK:AK,'Combined P&L'!$C:$C,'P&L Overview'!$B7) -> 150.39825 | AJ7: =SUMIFS('Combined P&L'!AL:AL,'Combined P&L'!$C:$C,'P&L Overview'!$B7) -> 156.5388 | AK7: =SUMIFS('Combined P&L'!AM:AM,'Combined P&L'!$C:$C,'P&L Overview'!$B7) -> 164.9034 | AL7: =SUMIFS('Combined P&L'!AN:AN,'Combined P&L'!$C:$C,'P&L Overview'!$B7) -> 170.34425 | AM7: =SUMIFS('Combined P&L'!AO:AO,'Combined P&L'!$C:$C,'P&L Overview'!$B7) -> 183.662 | AN7: =SUMIFS('Combined P&L'!AP:AP,'Combined P&L'!$C:$C,'P&L Overview'!$B7) -> 190.7844 | AO7: =SUMIFS('Combined P&L'!AQ:AQ,'Combined P&L'!$C:$C,'P&L Overview'!$B7) -> 194.4065 | AP7: =SUMIFS('Combined P&L'!AR:AR,'Combined P&L'!$C:$C,'P&L Overview'!$B7) -> 200.8375
B8: SMB Subscription | C8: =SUMIFS($L8:$AP8,$L$5:$AP$5,">"&C$42,$L$5:$AP$5,"<"&C$43) -> 224.791 | D8: =SUMIFS($L8:$AP8,$L$5:$AP$5,">"&D$42,$L$5:$AP$5,"<"&D$43) -> 149.77 | F8: =SUMIFS($L8:$AP8,$L$5:$AP$5,">"&F$42,$L$5:$AP$5,"<"&F$43) -> 90.4525 | G8: =SUMIFS($L8:$AP8,$L$5:$AP$5,">"&G$42,$L$5:$AP$5,"<"&G$43) -> 73.4185 | I8: =SUMIFS($L8:$AP8,$L$5:$AP$5,">"&I$42,$L$5:$AP$5,"<"&I$43) -> 174.63 | J8: =SUMIFS($L8:$AP8,$L$5:$AP$5,">"&J$42,$L$5:$AP$5,"<"&J$43) -> 135.298 | L8: =SUMIFS('Combined P&L'!N:N,'Combined P&L'!$C:$C,'P&L Overview'!$B8) -> 22.001 | M8: =SUMIFS('Combined P&L'!O:O,'Combined P&L'!$C:$C,'P&L Overview'!$B8) -> 22.036 | N8: =SUMIFS('Combined P&L'!P:P,'Combined P&L'!$C:$C,'P&L Overview'!$B8) -> 22.111 | O8: =SUMIFS('Combined P&L'!Q:Q,'Combined P&L'!$C:$C,'P&L Overview'!$B8) -> 22.146 | P8: =SUMIFS('Combined P&L'!R:R,'Combined P&L'!$C:$C,'P&L Overview'!$B8) -> 21.966 | Q8: =SUMIFS('Combined P&L'!S:S,'Combined P&L'!$C:$C,'P&L Overview'!$B8) -> 17.816 | R8: =SUMIFS('Combined P&L'!T:T,'Combined P&L'!$C:$C,'P&L Overview'!$B8) -> 17.621 | S8: =SUMIFS('Combined P&L'!U:U,'Combined P&L'!$C:$C,'P&L Overview'!$B8) -> 17.536 | T8: =SUMIFS('Combined P&L'!V:V,'Combined P&L'!$C:$C,'P&L Overview'!$B8) -> 16.426 | U8: =SUMIFS('Combined P&L'!W:W,'Combined P&L'!$C:$C,'P&L Overview'!$B8) -> 15.381 | V8: =SUMIFS('Combined P&L'!X:X,'Combined P&L'!$C:$C,'P&L Overview'!$B8) -> 14.6755 | W8: =SUMIFS('Combined P&L'!Y:Y,'Combined P&L'!$C:$C,'P&L Overview'!$B8) -> 15.0755 | X8: =SUMIFS('Combined P&L'!Z:Z,'Combined P&L'!$C:$C,'P&L Overview'!$B8) -> 14.5625 | Y8: =SUMIFS('Combined P&L'!AA:AA,'Combined P&L'!$C:$C,'P&L Overview'!$B8) -> 12.8025 | Z8: =SUMIFS('Combined P&L'!AB:AB,'Combined P&L'!$C:$C,'P&L Overview'!$B8) -> 12.4025 | AA8: =SUMIFS('Combined P&L'!AC:AC,'Combined P&L'!$C:$C,'P&L Overview'!$B8) -> 12.6025 | AB8: =SUMIFS('Combined P&L'!AD:AD,'Combined P&L'!$C:$C,'P&L Overview'!$B8) -> 12.7525 | AC8: =SUMIFS('Combined P&L'!AE:AE,'Combined P&L'!$C:$C,'P&L Overview'!$B8) -> 12.7925 | AD8: =SUMIFS('Combined P&L'!AF:AF,'Combined P&L'!$C:$C,'P&L Overview'!$B8) -> 12.5375 | AE8: =SUMIFS('Combined P&L'!AG:AG,'Combined P&L'!$C:$C,'P&L Overview'!$B8) -> 11.8575 | AF8: =SUMIFS('Combined P&L'!AH:AH,'Combined P&L'!$C:$C,'P&L Overview'!$B8) -> 12.3025 | AG8: =SUMIFS('Combined P&L'!AI:AI,'Combined P&L'!$C:$C,'P&L Overview'!$B8) -> 11.6925 | AH8: =SUMIFS('Combined P&L'!AJ:AJ,'Combined P&L'!$C:$C,'P&L Overview'!$B8) -> 11.7175 | AI8: =SUMIFS('Combined P&L'!AK:AK,'Combined P&L'!$C:$C,'P&L Overview'!$B8) -> 11.7475 | AJ8: =SUMIFS('Combined P&L'!AL:AL,'Combined P&L'!$C:$C,'P&L Overview'!$B8) -> 11.2805 | AK8: =SUMIFS('Combined P&L'!AM:AM,'Combined P&L'!$C:$C,'P&L Overview'!$B8) -> 10.9305 | AL8: =SUMIFS('Combined P&L'!AN:AN,'Combined P&L'!$C:$C,'P&L Overview'!$B8) -> 10.6255 | AM8: =SUMIFS('Combined P&L'!AO:AO,'Combined P&L'!$C:$C,'P&L Overview'!$B8) -> 10.3155 | AN8: =SUMIFS('Combined P&L'!AP:AP,'Combined P&L'!$C:$C,'P&L Overview'!$B8) -> 10.3155 | AO8: =SUMIFS('Combined P&L'!AQ:AQ,'Combined P&L'!$C:$C,'P&L Overview'!$B8) -> 9.9755 | AP8: =SUMIFS('Combined P&L'!AR:AR,'Combined P&L'!$C:$C,'P&L Overview'!$B8) -> 9.9755
B9: Occupancy Taxes | C9: =SUMIFS($L9:$AP9,$L$5:$AP$5,">"&C$42,$L$5:$AP$5,"<"&C$43) -> 0.56 | D9: =SUMIFS($L9:$AP9,$L$5:$AP$5,">"&D$42,$L$5:$AP$5,"<"&D$43) -> 55.0805 | F9: =SUMIFS($L9:$AP9,$L$5:$AP$5,">"&F$42,$L$5:$AP$5,"<"&F$43) -> 23.2255 | G9: =SUMIFS($L9:$AP9,$L$5:$AP$5,">"&G$42,$L$5:$AP$5,"<"&G$43) -> 91.65114 | I9: =SUMIFS($L9:$AP9,$L$5:$AP$5,">"&I$42,$L$5:$AP$5,"<"&I$43) -> 18.727 | J9: =SUMIFS($L9:$AP9,$L$5:$AP$5,">"&J$42,$L$5:$AP$5,"<"&J$43) -> 112.49549 | L9: =SUMIFS('Combined P&L'!N:N,'Combined P&L'!$C:$C,'P&L Overview'!$B9) -> 0 | M9: =SUMIFS('Combined P&L'!O:O,'Combined P&L'!$C:$C,'P&L Overview'!$B9) -> 0 | N9: =SUMIFS('Combined P&L'!P:P,'Combined P&L'!$C:$C,'P&L Overview'!$B9) -> 0 | O9: =SUMIFS('Combined P&L'!Q:Q,'Combined P&L'!$C:$C,'P&L Overview'!$B9) -> 0 | P9: =SUMIFS('Combined P&L'!R:R,'Combined P&L'!$C:$C,'P&L Overview'!$B9) -> 0 | Q9: =SUMIFS('Combined P&L'!S:S,'Combined P&L'!$C:$C,'P&L Overview'!$B9) -> 0 | R9: =SUMIFS('Combined P&L'!T:T,'Combined P&L'!$C:$C,'P&L Overview'!$B9) -> 0 | S9: =SUMIFS('Combined P&L'!U:U,'Combined P&L'!$C:$C,'P&L Overview'!$B9) -> 0 | T9: =SUMIFS('Combined P&L'!V:V,'Combined P&L'!$C:$C,'P&L Overview'!$B9) -> 0 | U9: =SUMIFS('Combined P&L'!W:W,'Combined P&L'!$C:$C,'P&L Overview'!$B9) -> 0 | V9: =SUMIFS('Combined P&L'!X:X,'Combined P&L'!$C:$C,'P&L Overview'!$B9) -> 0.08 | W9: =SUMIFS('Combined P&L'!Y:Y,'Combined P&L'!$C:$C,'P&L Overview'!$B9) -> 0.48 | X9: =SUMIFS('Combined P&L'!Z:Z,'Combined P&L'!$C:$C,'P&L Overview'!$B9) -> 1.13 | Y9: =SUMIFS('Combined P&L'!AA:AA,'Combined P&L'!$C:$C,'P&L Overview'!$B9) -> 2.14 | Z9: =SUMIFS('Combined P&L'!AB:AB,'Combined P&L'!$C:$C,'P&L Overview'!$B9) -> 2.66 | AA9: =SUMIFS('Combined P&L'!AC:AC,'Combined P&L'!$C:$C,'P&L Overview'!$B9) -> 3.65 | AB9: =SUMIFS('Combined P&L'!AD:AD,'Combined P&L'!$C:$C,'P&L Overview'!$B9) -> 3.623 | AC9: =SUMIFS('Combined P&L'!AE:AE,'Combined P&L'!$C:$C,'P&L Overview'!$B9) -> 4.964 | AD9: =SUMIFS('Combined P&L'!AF:AF,'Combined P&L'!$C:$C,'P&L Overview'!$B9) -> 5.0585 | AE9: =SUMIFS('Combined P&L'!AG:AG,'Combined P&L'!$C:$C,'P&L Overview'!$B9) -> 4.73 | AF9: =SUMIFS('Combined P&L'!AH:AH,'Combined P&L'!$C:$C,'P&L Overview'!$B9) -> 4.82 | AG9: =SUMIFS('Combined P&L'!AI:AI,'Combined P&L'!$C:$C,'P&L Overview'!$B9) -> 5.37 | AH9: =SUMIFS('Combined P&L'!AJ:AJ,'Combined P&L'!$C:$C,'P&L Overview'!$B9) -> 8.05 | AI9: =SUMIFS('Combined P&L'!AK:AK,'Combined P&L'!$C:$C,'P&L Overview'!$B9) -> 8.885 | AJ9: =SUMIFS('Combined P&L'!AL:AL,'Combined P&L'!$C:$C,'P&L Overview'!$B9) -> 10.90952 | AK9: =SUMIFS('Combined P&L'!AM:AM,'Combined P&L'!$C:$C,'P&L Overview'!$B9) -> 10.33497 | AL9: =SUMIFS('Combined P&L'!AN:AN,'Combined P&L'!$C:$C,'P&L Overview'!$B9) -> 11.175 | AM9: =SUMIFS('Combined P&L'!AO:AO,'Combined P&L'!$C:$C,'P&L Overview'!$B9) -> 11.95311 | AN9: =SUMIFS('Combined P&L'!AP:AP,'Combined P&L'!$C:$C,'P&L Overview'!$B9) -> 15.04071 | AO9: =SUMIFS('Combined P&L'!AQ:AQ,'Combined P&L'!$C:$C,'P&L Overview'!$B9) -> 16.16868 | AP9: =SUMIFS('Combined P&L'!AR:AR,'Combined P&L'!$C:$C,'P&L Overview'!$B9) -> 16.06915
B10: Onboarding | C10: =SUMIFS($L10:$AP10,$L$5:$AP$5,">"&C$42,$L$5:$AP$5,"<"&C$43) -> 44.0585 | D10: =SUMIFS($L10:$AP10,$L$5:$AP$5,">"&D$42,$L$5:$AP$5,"<"&D$43) -> 74.5193 | F10: =SUMIFS($L10:$AP10,$L$5:$AP$5,">"&F$42,$L$5:$AP$5,"<"&F$43) -> 42.25405 | G10: =SUMIFS($L10:$AP10,$L$5:$AP$5,">"&G$42,$L$5:$AP$5,"<"&G$43) -> 59.055 | I10: =SUMIFS($L10:$AP10,$L$5:$AP$5,">"&I$42,$L$5:$AP$5,"<"&I$43) -> 55.66055 | J10: =SUMIFS($L10:$AP10,$L$5:$AP$5,">"&J$42,$L$5:$AP$5,"<"&J$43) -> 91.65575 | L10: =SUMIFS('Combined P&L'!N:N,'Combined P&L'!$C:$C,'P&L Overview'!$B10) -> 5.465 | M10: =SUMIFS('Combined P&L'!O:O,'Combined P&L'!$C:$C,'P&L Overview'!$B10) -> 3.9 | N10: =SUMIFS('Combined P&L'!P:P,'Combined P&L'!$C:$C,'P&L Overview'!$B10) -> 2.755 | O10: =SUMIFS('Combined P&L'!Q:Q,'Combined P&L'!$C:$C,'P&L Overview'!$B10) -> 3.502 | P10: =SUMIFS('Combined P&L'!R:R,'Combined P&L'!$C:$C,'P&L Overview'!$B10) -> 4.659 | Q10: =SUMIFS('Combined P&L'!S:S,'Combined P&L'!$C:$C,'P&L Overview'!$B10) -> 3.937 | R10: =SUMIFS('Combined P&L'!T:T,'Combined P&L'!$C:$C,'P&L Overview'!$B10) -> 4.602 | S10: =SUMIFS('Combined P&L'!U:U,'Combined P&L'!$C:$C,'P&L Overview'!$B10) -> 4.738 | T10: =SUMIFS('Combined P&L'!V:V,'Combined P&L'!$C:$C,'P&L Overview'!$B10) -> 2.119 | U10: =SUMIFS('Combined P&L'!W:W,'Combined P&L'!$C:$C,'P&L Overview'!$B10) -> 2.064 | V10: =SUMIFS('Combined P&L'!X:X,'Combined P&L'!$C:$C,'P&L Overview'!$B10) -> 3.0125 | W10: =SUMIFS('Combined P&L'!Y:Y,'Combined P&L'!$C:$C,'P&L Overview'!$B10) -> 3.305 | X10: =SUMIFS('Combined P&L'!Z:Z,'Combined P&L'!$C:$C,'P&L Overview'!$B10) -> 3.079 | Y10: =SUMIFS('Combined P&L'!AA:AA,'Combined P&L'!$C:$C,'P&L Overview'!$B10) -> 0.7 | Z10: =SUMIFS('Combined P&L'!AB:AB,'Combined P&L'!$C:$C,'P&L Overview'!$B10) -> 10.43855 | AA10: =SUMIFS('Combined P&L'!AC:AC,'Combined P&L'!$C:$C,'P&L Overview'!$B10) -> 4.3 | AB10: =SUMIFS('Combined P&L'!AD:AD,'Combined P&L'!$C:$C,'P&L Overview'!$B10) -> 11.14 | AC10: =SUMIFS('Combined P&L'!AE:AE,'Combined P&L'!$C:$C,'P&L Overview'!$B10) -> 6.1625 | AD10: =SUMIFS('Combined P&L'!AF:AF,'Combined P&L'!$C:$C,'P&L Overview'!$B10) -> 6.434 | AE10: =SUMIFS('Combined P&L'!AG:AG,'Combined P&L'!$C:$C,'P&L Overview'!$B10) -> 3.965 | AF10: =SUMIFS('Combined P&L'!AH:AH,'Combined P&L'!$C:$C,'P&L Overview'!$B10) -> 3.92 | AG10: =SUMIFS('Combined P&L'!AI:AI,'Combined P&L'!$C:$C,'P&L Overview'!$B10) -> 9.1365 | AH10: =SUMIFS('Combined P&L'!AJ:AJ,'Combined P&L'!$C:$C,'P&L Overview'!$B10) -> 5.25375 | AI10: =SUMIFS('Combined P&L'!AK:AK,'Combined P&L'!$C:$C,'P&L Overview'!$B10) -> 9.99 | AJ10: =SUMIFS('Combined P&L'!AL:AL,'Combined P&L'!$C:$C,'P&L Overview'!$B10) -> 10.2105 | AK10: =SUMIFS('Combined P&L'!AM:AM,'Combined P&L'!$C:$C,'P&L Overview'!$B10) -> 6.675 | AL10: =SUMIFS('Combined P&L'!AN:AN,'Combined P&L'!$C:$C,'P&L Overview'!$B10) -> 9.099 | AM10: =SUMIFS('Combined P&L'!AO:AO,'Combined P&L'!$C:$C,'P&L Overview'!$B10) -> 8.9545 | AN10: =SUMIFS('Combined P&L'!AP:AP,'Combined P&L'!$C:$C,'P&L Overview'!$B10) -> 12.606 | AO10: =SUMIFS('Combined P&L'!AQ:AQ,'Combined P&L'!$C:$C,'P&L Overview'!$B10) -> 5.4115 | AP10: =SUMIFS('Combined P&L'!AR:AR,'Combined P&L'!$C:$C,'P&L Overview'!$B10) -> 6.0985
B11: STR Bill Pay | C11: =SUMIFS($L11:$AP11,$L$5:$AP$5,">"&C$42,$L$5:$AP$5,"<"&C$43) -> 0.06 | D11: =SUMIFS($L11:$AP11,$L$5:$AP$5,">"&D$42,$L$5:$AP$5,"<"&D$43) -> 36.6065 | F11: =SUMIFS($L11:$AP11,$L$5:$AP$5,">"&F$42,$L$5:$AP$5,"<"&F$43) -> 15.4915 | G11: =SUMIFS($L11:$AP11,$L$5:$AP$5,">"&G$42,$L$5:$AP$5,"<"&G$43) -> 45.13 | I11: =SUMIFS($L11:$AP11,$L$5:$AP$5,">"&I$42,$L$5:$AP$5,"<"&I$43) -> 11.6315 | J11: =SUMIFS($L11:$AP11,$L$5:$AP$5,">"&J$42,$L$5:$AP$5,"<"&J$43) -> 63.21 | L11: =SUMIFS('Combined P&L'!N:N,'Combined P&L'!$C:$C,'P&L Overview'!$B11) -> 0 | M11: =SUMIFS('Combined P&L'!O:O,'Combined P&L'!$C:$C,'P&L Overview'!$B11) -> 0 | N11: =SUMIFS('Combined P&L'!P:P,'Combined P&L'!$C:$C,'P&L Overview'!$B11) -> 0 | O11: =SUMIFS('Combined P&L'!Q:Q,'Combined P&L'!$C:$C,'P&L Overview'!$B11) -> 0 | P11: =SUMIFS('Combined P&L'!R:R,'Combined P&L'!$C:$C,'P&L Overview'!$B11) -> 0 | Q11: =SUMIFS('Combined P&L'!S:S,'Combined P&L'!$C:$C,'P&L Overview'!$B11) -> 0 | R11: =SUMIFS('Combined P&L'!T:T,'Combined P&L'!$C:$C,'P&L Overview'!$B11) -> 0 | S11: =SUMIFS('Combined P&L'!U:U,'Combined P&L'!$C:$C,'P&L Overview'!$B11) -> 0 | T11: =SUMIFS('Combined P&L'!V:V,'Combined P&L'!$C:$C,'P&L Overview'!$B11) -> 0 | U11: =SUMIFS('Combined P&L'!W:W,'Combined P&L'!$C:$C,'P&L Overview'!$B11) -> 0 | V11: =SUMIFS('Combined P&L'!X:X,'Combined P&L'!$C:$C,'P&L Overview'!$B11) -> 0 | W11: =SUMIFS('Combined P&L'!Y:Y,'Combined P&L'!$C:$C,'P&L Overview'!$B11) -> 0.06 | X11: =SUMIFS('Combined P&L'!Z:Z,'Combined P&L'!$C:$C,'P&L Overview'!$B11) -> 0.97 | Y11: =SUMIFS('Combined P&L'!AA:AA,'Combined P&L'!$C:$C,'P&L Overview'!$B11) -> 1.1 | Z11: =SUMIFS('Combined P&L'!AB:AB,'Combined P&L'!$C:$C,'P&L Overview'!$B11) -> 1.735 | AA11: =SUMIFS('Combined P&L'!AC:AC,'Combined P&L'!$C:$C,'P&L Overview'!$B11) -> 2.14 | AB11: =SUMIFS('Combined P&L'!AD:AD,'Combined P&L'!$C:$C,'P&L Overview'!$B11) -> 2.363 | AC11: =SUMIFS('Combined P&L'!AE:AE,'Combined P&L'!$C:$C,'P&L Overview'!$B11) -> 3.2635 | AD11: =SUMIFS('Combined P&L'!AF:AF,'Combined P&L'!$C:$C,'P&L Overview'!$B11) -> 3.92 | AE11: =SUMIFS('Combined P&L'!AG:AG,'Combined P&L'!$C:$C,'P&L Overview'!$B11) -> 3.905 | AF11: =SUMIFS('Combined P&L'!AH:AH,'Combined P&L'!$C:$C,'P&L Overview'!$B11) -> 3.78 | AG11: =SUMIFS('Combined P&L'!AI:AI,'Combined P&L'!$C:$C,'P&L Overview'!$B11) -> 3.795 | AH11: =SUMIFS('Combined P&L'!AJ:AJ,'Combined P&L'!$C:$C,'P&L Overview'!$B11) -> 4.33 | AI11: =SUMIFS('Combined P&L'!AK:AK,'Combined P&L'!$C:$C,'P&L Overview'!$B11) -> 5.305 | AJ11: =SUMIFS('Combined P&L'!AL:AL,'Combined P&L'!$C:$C,'P&L Overview'!$B11) -> 6.3 | AK11: =SUMIFS('Combined P&L'!AM:AM,'Combined P&L'!$C:$C,'P&L Overview'!$B11) -> 6.39 | AL11: =SUMIFS('Combined P&L'!AN:AN,'Combined P&L'!$C:$C,'P&L Overview'!$B11) -> 6.425 | AM11: =SUMIFS('Combined P&L'!AO:AO,'Combined P&L'!$C:$C,'P&L Overview'!$B11) -> 6.08 | AN11: =SUMIFS('Combined P&L'!AP:AP,'Combined P&L'!$C:$C,'P&L Overview'!$B11) -> 6.325 | AO11: =SUMIFS('Combined P&L'!AQ:AQ,'Combined P&L'!$C:$C,'P&L Overview'!$B11) -> 6.655 | AP11: =SUMIFS('Combined P&L'!AR:AR,'Combined P&L'!$C:$C,'P&L Overview'!$B11) -> 6.955
B12: Topkey Subscription | C12: =SUMIFS($L12:$AP12,$L$5:$AP$5,">"&C$42,$L$5:$AP$5,"<"&C$43) -> 0 | D12: =SUMIFS($L12:$AP12,$L$5:$AP$5,">"&D$42,$L$5:$AP$5,"<"&D$43) -> 9.947 | F12: =SUMIFS($L12:$AP12,$L$5:$AP$5,">"&F$42,$L$5:$AP$5,"<"&F$43) -> 0 | G12: =SUMIFS($L12:$AP12,$L$5:$AP$5,">"&G$42,$L$5:$AP$5,"<"&G$43) -> 45.086 | I12: =SUMIFS($L12:$AP12,$L$5:$AP$5,">"&I$42,$L$5:$AP$5,"<"&I$43) -> 0 | J12: =SUMIFS($L12:$AP12,$L$5:$AP$5,">"&J$42,$L$5:$AP$5,"<"&J$43) -> 47.13 | L12: =SUMIFS('Combined P&L'!N:N,'Combined P&L'!$C:$C,'P&L Overview'!$B12) -> 0 | M12: =SUMIFS('Combined P&L'!O:O,'Combined P&L'!$C:$C,'P&L Overview'!$B12) -> 0 | N12: =SUMIFS('Combined P&L'!P:P,'Combined P&L'!$C:$C,'P&L Overview'!$B12) -> 0 | O12: =SUMIFS('Combined P&L'!Q:Q,'Combined P&L'!$C:$C,'P&L Overview'!$B12) -> 0 | P12: =SUMIFS('Combined P&L'!R:R,'Combined P&L'!$C:$C,'P&L Overview'!$B12) -> 0 | Q12: =SUMIFS('Combined P&L'!S:S,'Combined P&L'!$C:$C,'P&L Overview'!$B12) -> 0 | R12: =SUMIFS('Combined P&L'!T:T,'Combined P&L'!$C:$C,'P&L Overview'!$B12) -> 0 | S12: =SUMIFS('Combined P&L'!U:U,'Combined P&L'!$C:$C,'P&L Overview'!$B12) -> 0 | T12: =SUMIFS('Combined P&L'!V:V,'Combined P&L'!$C:$C,'P&L Overview'!$B12) -> 0 | U12: =SUMIFS('Combined P&L'!W:W,'Combined P&L'!$C:$C,'P&L Overview'!$B12) -> 0 | V12: =SUMIFS('Combined P&L'!X:X,'Combined P&L'!$C:$C,'P&L Overview'!$B12) -> 0 | W12: =SUMIFS('Combined P&L'!Y:Y,'Combined P&L'!$C:$C,'P&L Overview'!$B12) -> 0 | X12: =SUMIFS('Combined P&L'!Z:Z,'Combined P&L'!$C:$C,'P&L Overview'!$B12) -> 0 | Y12: =SUMIFS('Combined P&L'!AA:AA,'Combined P&L'!$C:$C,'P&L Overview'!$B12) -> 0 | Z12: =SUMIFS('Combined P&L'!AB:AB,'Combined P&L'!$C:$C,'P&L Overview'!$B12) -> 0 | AA12: =SUMIFS('Combined P&L'!AC:AC,'Combined P&L'!$C:$C,'P&L Overview'!$B12) -> 0 | AB12: =SUMIFS('Combined P&L'!AD:AD,'Combined P&L'!$C:$C,'P&L Overview'!$B12) -> 0 | AC12: =SUMIFS('Combined P&L'!AE:AE,'Combined P&L'!$C:$C,'P&L Overview'!$B12) -> 0 | AD12: =SUMIFS('Combined P&L'!AF:AF,'Combined P&L'!$C:$C,'P&L Overview'!$B12) -> 0 | AE12: =SUMIFS('Combined P&L'!AG:AG,'Combined P&L'!$C:$C,'P&L Overview'!$B12) -> 0 | AF12: =SUMIFS('Combined P&L'!AH:AH,'Combined P&L'!$C:$C,'P&L Overview'!$B12) -> 0.52 | AG12: =SUMIFS('Combined P&L'!AI:AI,'Combined P&L'!$C:$C,'P&L Overview'!$B12) -> 2.357 | AH12: =SUMIFS('Combined P&L'!AJ:AJ,'Combined P&L'!$C:$C,'P&L Overview'!$B12) -> 2.811 | AI12: =SUMIFS('Combined P&L'!AK:AK,'Combined P&L'!$C:$C,'P&L Overview'!$B12) -> 4.259 | AJ12: =SUMIFS('Combined P&L'!AL:AL,'Combined P&L'!$C:$C,'P&L Overview'!$B12) -> 5.254 | AK12: =SUMIFS('Combined P&L'!AM:AM,'Combined P&L'!$C:$C,'P&L Overview'!$B12) -> 5.652 | AL12: =SUMIFS('Combined P&L'!AN:AN,'Combined P&L'!$C:$C,'P&L Overview'!$B12) -> 5.324 | AM12: =SUMIFS('Combined P&L'!AO:AO,'Combined P&L'!$C:$C,'P&L Overview'!$B12) -> 6.321 | AN12: =SUMIFS('Combined P&L'!AP:AP,'Combined P&L'!$C:$C,'P&L Overview'!$B12) -> 6.959 | AO12: =SUMIFS('Combined P&L'!AQ:AQ,'Combined P&L'!$C:$C,'P&L Overview'!$B12) -> 7.673 | AP12: =SUMIFS('Combined P&L'!AR:AR,'Combined P&L'!$C:$C,'P&L Overview'!$B12) -> 7.903
B13: Controller Services | C13: =SUMIFS($L13:$AP13,$L$5:$AP$5,">"&C$42,$L$5:$AP$5,"<"&C$43) -> 13.75 | D13: =SUMIFS($L13:$AP13,$L$5:$AP$5,">"&D$42,$L$5:$AP$5,"<"&D$43) -> 46.4 | F13: =SUMIFS($L13:$AP13,$L$5:$AP$5,">"&F$42,$L$5:$AP$5,"<"&F$43) -> 31.5 | G13: =SUMIFS($L13:$AP13,$L$5:$AP$5,">"&G$42,$L$5:$AP$5,"<"&G$43) -> 24.25 | I13: =SUMIFS($L13:$AP13,$L$5:$AP$5,">"&I$42,$L$5:$AP$5,"<"&I$43) -> 41.25 | J13: =SUMIFS($L13:$AP13,$L$5:$AP$5,">"&J$42,$L$5:$AP$5,"<"&J$43) -> 39.65 | L13: =SUMIFS('Combined P&L'!N:N,'Combined P&L'!$C:$C,'P&L Overview'!$B13) -> 0 | M13: =SUMIFS('Combined P&L'!O:O,'Combined P&L'!$C:$C,'P&L Overview'!$B13) -> 0 | N13: =SUMIFS('Combined P&L'!P:P,'Combined P&L'!$C:$C,'P&L Overview'!$B13) -> 0 | O13: =SUMIFS('Combined P&L'!Q:Q,'Combined P&L'!$C:$C,'P&L Overview'!$B13) -> 0 | P13: =SUMIFS('Combined P&L'!R:R,'Combined P&L'!$C:$C,'P&L Overview'!$B13) -> 0 | Q13: =SUMIFS('Combined P&L'!S:S,'Combined P&L'!$C:$C,'P&L Overview'!$B13) -> 0 | R13: =SUMIFS('Combined P&L'!T:T,'Combined P&L'!$C:$C,'P&L Overview'!$B13) -> 1.25 | S13: =SUMIFS('Combined P&L'!U:U,'Combined P&L'!$C:$C,'P&L Overview'!$B13) -> 1.25 | T13: =SUMIFS('Combined P&L'!V:V,'Combined P&L'!$C:$C,'P&L Overview'!$B13) -> 1.25 | U13: =SUMIFS('Combined P&L'!W:W,'Combined P&L'!$C:$C,'P&L Overview'!$B13) -> 1.25 | V13: =SUMIFS('Combined P&L'!X:X,'Combined P&L'!$C:$C,'P&L Overview'!$B13) -> 5.75 | W13: =SUMIFS('Combined P&L'!Y:Y,'Combined P&L'!$C:$C,'P&L Overview'!$B13) -> 3 | X13: =SUMIFS('Combined P&L'!Z:Z,'Combined P&L'!$C:$C,'P&L Overview'!$B13) -> 4.45 | Y13: =SUMIFS('Combined P&L'!AA:AA,'Combined P&L'!$C:$C,'P&L Overview'!$B13) -> 3.45 | Z13: =SUMIFS('Combined P&L'!AB:AB,'Combined P&L'!$C:$C,'P&L Overview'!$B13) -> 3.45 | AA13: =SUMIFS('Combined P&L'!AC:AC,'Combined P&L'!$C:$C,'P&L Overview'!$B13) -> 5.95 | AB13: =SUMIFS('Combined P&L'!AD:AD,'Combined P&L'!$C:$C,'P&L Overview'!$B13) -> 5.2 | AC13: =SUMIFS('Combined P&L'!AE:AE,'Combined P&L'!$C:$C,'P&L Overview'!$B13) -> 5 | AD13: =SUMIFS('Combined P&L'!AF:AF,'Combined P&L'!$C:$C,'P&L Overview'!$B13) -> 4 | AE13: =SUMIFS('Combined P&L'!AG:AG,'Combined P&L'!$C:$C,'P&L Overview'!$B13) -> 2.95 | AF13: =SUMIFS('Combined P&L'!AH:AH,'Combined P&L'!$C:$C,'P&L Overview'!$B13) -> 3.025 | AG13: =SUMIFS('Combined P&L'!AI:AI,'Combined P&L'!$C:$C,'P&L Overview'!$B13) -> 3.025 | AH13: =SUMIFS('Combined P&L'!AJ:AJ,'Combined P&L'!$C:$C,'P&L Overview'!$B13) -> 2.95 | AI13: =SUMIFS('Combined P&L'!AK:AK,'Combined P&L'!$C:$C,'P&L Overview'!$B13) -> 2.95 | AJ13: =SUMIFS('Combined P&L'!AL:AL,'Combined P&L'!$C:$C,'P&L Overview'!$B13) -> 2.75 | AK13: =SUMIFS('Combined P&L'!AM:AM,'Combined P&L'!$C:$C,'P&L Overview'!$B13) -> 3.5 | AL13: =SUMIFS('Combined P&L'!AN:AN,'Combined P&L'!$C:$C,'P&L Overview'!$B13) -> 2.75 | AM13: =SUMIFS('Combined P&L'!AO:AO,'Combined P&L'!$C:$C,'P&L Overview'!$B13) -> 4.75 | AN13: =SUMIFS('Combined P&L'!AP:AP,'Combined P&L'!$C:$C,'P&L Overview'!$B13) -> 3.5 | AO13: =SUMIFS('Combined P&L'!AQ:AQ,'Combined P&L'!$C:$C,'P&L Overview'!$B13) -> 3.5 | AP13: =SUMIFS('Combined P&L'!AR:AR,'Combined P&L'!$C:$C,'P&L Overview'!$B13) -> 3.5
B14: Historical Cleanup | C14: =SUMIFS($L14:$AP14,$L$5:$AP$5,">"&C$42,$L$5:$AP$5,"<"&C$43) -> 17.624 | D14: =SUMIFS($L14:$AP14,$L$5:$AP$5,">"&D$42,$L$5:$AP$5,"<"&D$43) -> 5.03375 | F14: =SUMIFS($L14:$AP14,$L$5:$AP$5,">"&F$42,$L$5:$AP$5,"<"&F$43) -> 4.43875 | G14: =SUMIFS($L14:$AP14,$L$5:$AP$5,">"&G$42,$L$5:$AP$5,"<"&G$43) -> 0 | I14: =SUMIFS($L14:$AP14,$L$5:$AP$5,">"&I$42,$L$5:$AP$5,"<"&I$43) -> 14.30525 | J14: =SUMIFS($L14:$AP14,$L$5:$AP$5,">"&J$42,$L$5:$AP$5,"<"&J$43) -> 0.595 | L14: =SUMIFS('Combined P&L'!N:N,'Combined P&L'!$C:$C,'P&L Overview'!$B14) -> 1.2 | M14: =SUMIFS('Combined P&L'!O:O,'Combined P&L'!$C:$C,'P&L Overview'!$B14) -> 1.7625 | N14: =SUMIFS('Combined P&L'!P:P,'Combined P&L'!$C:$C,'P&L Overview'!$B14) -> 0.66 | O14: =SUMIFS('Combined P&L'!Q:Q,'Combined P&L'!$C:$C,'P&L Overview'!$B14) -> 0.395 | P14: =SUMIFS('Combined P&L'!R:R,'Combined P&L'!$C:$C,'P&L Overview'!$B14) -> 2.465 | Q14: =SUMIFS('Combined P&L'!S:S,'Combined P&L'!$C:$C,'P&L Overview'!$B14) -> 1.275 | R14: =SUMIFS('Combined P&L'!T:T,'Combined P&L'!$C:$C,'P&L Overview'!$B14) -> 1.4625 | S14: =SUMIFS('Combined P&L'!U:U,'Combined P&L'!$C:$C,'P&L Overview'!$B14) -> 0 | T14: =SUMIFS('Combined P&L'!V:V,'Combined P&L'!$C:$C,'P&L Overview'!$B14) -> 1.14525 | U14: =SUMIFS('Combined P&L'!W:W,'Combined P&L'!$C:$C,'P&L Overview'!$B14) -> 1.35525 | V14: =SUMIFS('Combined P&L'!X:X,'Combined P&L'!$C:$C,'P&L Overview'!$B14) -> 1.9035 | W14: =SUMIFS('Combined P&L'!Y:Y,'Combined P&L'!$C:$C,'P&L Overview'!$B14) -> 4 | X14: =SUMIFS('Combined P&L'!Z:Z,'Combined P&L'!$C:$C,'P&L Overview'!$B14) -> 1.08375 | Y14: =SUMIFS('Combined P&L'!AA:AA,'Combined P&L'!$C:$C,'P&L Overview'!$B14) -> 2 | Z14: =SUMIFS('Combined P&L'!AB:AB,'Combined P&L'!$C:$C,'P&L Overview'!$B14) -> 1.355 | AA14: =SUMIFS('Combined P&L'!AC:AC,'Combined P&L'!$C:$C,'P&L Overview'!$B14) -> 0 | AB14: =SUMIFS('Combined P&L'!AD:AD,'Combined P&L'!$C:$C,'P&L Overview'!$B14) -> 0 | AC14: =SUMIFS('Combined P&L'!AE:AE,'Combined P&L'!$C:$C,'P&L Overview'!$B14) -> 0 | AD14: =SUMIFS('Combined P&L'!AF:AF,'Combined P&L'!$C:$C,'P&L Overview'!$B14) -> 0 | AE14: =SUMIFS('Combined P&L'!AG:AG,'Combined P&L'!$C:$C,'P&L Overview'!$B14) -> 0 | AF14: =SUMIFS('Combined P&L'!AH:AH,'Combined P&L'!$C:$C,'P&L Overview'!$B14) -> 0 | AG14: =SUMIFS('Combined P&L'!AI:AI,'Combined P&L'!$C:$C,'P&L Overview'!$B14) -> 0.595 | AH14: =SUMIFS('Combined P&L'!AJ:AJ,'Combined P&L'!$C:$C,'P&L Overview'!$B14) -> 0 | AI14: =SUMIFS('Combined P&L'!AK:AK,'Combined P&L'!$C:$C,'P&L Overview'!$B14) -> 0 | AJ14: =SUMIFS('Combined P&L'!AL:AL,'Combined P&L'!$C:$C,'P&L Overview'!$B14) -> 0 | AK14: =SUMIFS('Combined P&L'!AM:AM,'Combined P&L'!$C:$C,'P&L Overview'!$B14) -> 0 | AL14: =SUMIFS('Combined P&L'!AN:AN,'Combined P&L'!$C:$C,'P&L Overview'!$B14) -> 0 | AM14: =SUMIFS('Combined P&L'!AO:AO,'Combined P&L'!$C:$C,'P&L Overview'!$B14) -> 0 | AN14: =SUMIFS('Combined P&L'!AP:AP,'Combined P&L'!$C:$C,'P&L Overview'!$B14) -> 0 | AO14: =SUMIFS('Combined P&L'!AQ:AQ,'Combined P&L'!$C:$C,'P&L Overview'!$B14) -> 0 | AP14: =SUMIFS('Combined P&L'!AR:AR,'Combined P&L'!$C:$C,'P&L Overview'!$B14) -> 0
B15: Total Recurring Revenue | C15: =SUM(C7:C14) -> 1094.3157 | D15: =SUM(D7:D14) -> 1827.8494 | F15: =SUM(F7:F14) -> 958.8909 | G15: =SUM(G7:G14) -> 1600.0675 | I15: =SUM(I7:I14) -> 1414.7118 | J15: =SUM(J7:J14) -> 2371.7313 | L15: =SUM(L7:L14) -> 73.3495 | M15: =SUM(M7:M14) -> 74.7445 | N15: =SUM(N7:N14) -> 77.996 | O15: =SUM(O7:O14) -> 83.2127 | P15: =SUM(P7:P14) -> 86.60415 | Q15: =SUM(Q7:Q14) -> 88.544 | R15: =SUM(R7:R14) -> 93.21675 | S15: =SUM(S7:S14) -> 96.77535 | ... AP15: =SUM(AP7:AP14) -> 251.33865
B17: 1099 Filing | C17: =SUMIFS($L17:$AP17,$L$5:$AP$5,">"&C$42,$L$5:$AP$5,"<"&C$43) -> 10.475 | D17: =SUMIFS($L17:$AP17,$L$5:$AP$5,">"&D$42,$L$5:$AP$5,"<"&D$43) -> 23.55 | F17: =SUMIFS($L17:$AP17,$L$5:$AP$5,">"&F$42,$L$5:$AP$5,"<"&F$43) -> 23.49 | G17: =SUMIFS($L17:$AP17,$L$5:$AP$5,">"&G$42,$L$5:$AP$5,"<"&G$43) -> 38.7015 | I17: =SUMIFS($L17:$AP17,$L$5:$AP$5,">"&I$42,$L$5:$AP$5,"<"&I$43) -> 23.52 | J17: =SUMIFS($L17:$AP17,$L$5:$AP$5,">"&J$42,$L$5:$AP$5,"<"&J$43) -> 38.7615 | L17: =SUMIFS('Combined P&L'!N:N,'Combined P&L'!$C:$C,'P&L Overview'!$B17) -> 6.945 | M17: =SUMIFS('Combined P&L'!O:O,'Combined P&L'!$C:$C,'P&L Overview'!$B17) -> 3.38 | N17: =SUMIFS('Combined P&L'!P:P,'Combined P&L'!$C:$C,'P&L Overview'!$B17) -> 0.045 | O17: =SUMIFS('Combined P&L'!Q:Q,'Combined P&L'!$C:$C,'P&L Overview'!$B17) -> 0.06 | P17: =SUMIFS('Combined P&L'!R:R,'Combined P&L'!$C:$C,'P&L Overview'!$B17) -> 0.015 | Q17: =SUMIFS('Combined P&L'!S:S,'Combined P&L'!$C:$C,'P&L Overview'!$B17) -> 0 | R17: =SUMIFS('Combined P&L'!T:T,'Combined P&L'!$C:$C,'P&L Overview'!$B17) -> 0 | S17: =SUMIFS('Combined P&L'!U:U,'Combined P&L'!$C:$C,'P&L Overview'!$B17) -> 0.015 | T17: =SUMIFS('Combined P&L'!V:V,'Combined P&L'!$C:$C,'P&L Overview'!$B17) -> 0 | U17: =SUMIFS('Combined P&L'!W:W,'Combined P&L'!$C:$C,'P&L Overview'!$B17) -> 0 | V17: =SUMIFS('Combined P&L'!X:X,'Combined P&L'!$C:$C,'P&L Overview'!$B17) -> 0.015 | W17: =SUMIFS('Combined P&L'!Y:Y,'Combined P&L'!$C:$C,'P&L Overview'!$B17) -> 0 | X17: =SUMIFS('Combined P&L'!Z:Z,'Combined P&L'!$C:$C,'P&L Overview'!$B17) -> 13.485 | Y17: =SUMIFS('Combined P&L'!AA:AA,'Combined P&L'!$C:$C,'P&L Overview'!$B17) -> 9.915 | Z17: =SUMIFS('Combined P&L'!AB:AB,'Combined P&L'!$C:$C,'P&L Overview'!$B17) -> 0.06 | AA17: =SUMIFS('Combined P&L'!AC:AC,'Combined P&L'!$C:$C,'P&L Overview'!$B17) -> 0.03 | AB17: =SUMIFS('Combined P&L'!AD:AD,'Combined P&L'!$C:$C,'P&L Overview'!$B17) -> 0 | AC17: =SUMIFS('Combined P&L'!AE:AE,'Combined P&L'!$C:$C,'P&L Overview'!$B17) -> 0 | AD17: =SUMIFS('Combined P&L'!AF:AF,'Combined P&L'!$C:$C,'P&L Overview'!$B17) -> 0 | AE17: =SUMIFS('Combined P&L'!AG:AG,'Combined P&L'!$C:$C,'P&L Overview'!$B17) -> 0.03 | AF17: =SUMIFS('Combined P&L'!AH:AH,'Combined P&L'!$C:$C,'P&L Overview'!$B17) -> 0.03 | AG17: =SUMIFS('Combined P&L'!AI:AI,'Combined P&L'!$C:$C,'P&L Overview'!$B17) -> 0 | AH17: =SUMIFS('Combined P&L'!AJ:AJ,'Combined P&L'!$C:$C,'P&L Overview'!$B17) -> 0 | AI17: =SUMIFS('Combined P&L'!AK:AK,'Combined P&L'!$C:$C,'P&L Overview'!$B17) -> 0 | AJ17: =SUMIFS('Combined P&L'!AL:AL,'Combined P&L'!$C:$C,'P&L Overview'!$B17) -> 6.105 | AK17: =SUMIFS('Combined P&L'!AM:AM,'Combined P&L'!$C:$C,'P&L Overview'!$B17) -> 31.1565 | AL17: =SUMIFS('Combined P&L'!AN:AN,'Combined P&L'!$C:$C,'P&L Overview'!$B17) -> 1.26 | AM17: =SUMIFS('Combined P&L'!AO:AO,'Combined P&L'!$C:$C,'P&L Overview'!$B17) -> 0.18 | AN17: =SUMIFS('Combined P&L'!AP:AP,'Combined P&L'!$C:$C,'P&L Overview'!$B17) -> 0 | AO17: =SUMIFS('Combined P&L'!AQ:AQ,'Combined P&L'!$C:$C,'P&L Overview'!$B17) -> 0 | AP17: =SUMIFS('Combined P&L'!AR:AR,'Combined P&L'!$C:$C,'P&L Overview'!$B17) -> 0
B18: Income Tax | C18: =SUMIFS($L18:$AP18,$L$5:$AP$5,">"&C$42,$L$5:$AP$5,"<"&C$43) -> 0 | D18: =SUMIFS($L18:$AP18,$L$5:$AP$5,">"&D$42,$L$5:$AP$5,"<"&D$43) -> 3.4 | F18: =SUMIFS($L18:$AP18,$L$5:$AP$5,">"&F$42,$L$5:$AP$5,"<"&F$43) -> 0 | G18: =SUMIFS($L18:$AP18,$L$5:$AP$5,">"&G$42,$L$5:$AP$5,"<"&G$43) -> 23.915 | I18: =SUMIFS($L18:$AP18,$L$5:$AP$5,">"&I$42,$L$5:$AP$5,"<"&I$43) -> 0 | J18: =SUMIFS($L18:$AP18,$L$5:$AP$5,">"&J$42,$L$5:$AP$5,"<"&J$43) -> 27.315 | L18: =SUMIFS('Combined P&L'!N:N,'Combined P&L'!$C:$C,'P&L Overview'!$B18) -> 0 | M18: =SUMIFS('Combined P&L'!O:O,'Combined P&L'!$C:$C,'P&L Overview'!$B18) -> 0 | N18: =SUMIFS('Combined P&L'!P:P,'Combined P&L'!$C:$C,'P&L Overview'!$B18) -> 0 | O18: =SUMIFS('Combined P&L'!Q:Q,'Combined P&L'!$C:$C,'P&L Overview'!$B18) -> 0 | P18: =SUMIFS('Combined P&L'!R:R,'Combined P&L'!$C:$C,'P&L Overview'!$B18) -> 0 | Q18: =SUMIFS('Combined P&L'!S:S,'Combined P&L'!$C:$C,'P&L Overview'!$B18) -> 0 | R18: =SUMIFS('Combined P&L'!T:T,'Combined P&L'!$C:$C,'P&L Overview'!$B18) -> 0 | S18: =SUMIFS('Combined P&L'!U:U,'Combined P&L'!$C:$C,'P&L Overview'!$B18) -> 0 | T18: =SUMIFS('Combined P&L'!V:V,'Combined P&L'!$C:$C,'P&L Overview'!$B18) -> 0 | U18: =SUMIFS('Combined P&L'!W:W,'Combined P&L'!$C:$C,'P&L Overview'!$B18) -> 0 | V18: =SUMIFS('Combined P&L'!X:X,'Combined P&L'!$C:$C,'P&L Overview'!$B18) -> 0 | W18: =SUMIFS('Combined P&L'!Y:Y,'Combined P&L'!$C:$C,'P&L Overview'!$B18) -> 0 | X18: =SUMIFS('Combined P&L'!Z:Z,'Combined P&L'!$C:$C,'P&L Overview'!$B18) -> 0 | Y18: =SUMIFS('Combined P&L'!AA:AA,'Combined P&L'!$C:$C,'P&L Overview'!$B18) -> 0 | Z18: =SUMIFS('Combined P&L'!AB:AB,'Combined P&L'!$C:$C,'P&L Overview'!$B18) -> 0 | AA18: =SUMIFS('Combined P&L'!AC:AC,'Combined P&L'!$C:$C,'P&L Overview'!$B18) -> 0 | AB18: =SUMIFS('Combined P&L'!AD:AD,'Combined P&L'!$C:$C,'P&L Overview'!$B18) -> 0 | AC18: =SUMIFS('Combined P&L'!AE:AE,'Combined P&L'!$C:$C,'P&L Overview'!$B18) -> 0 | AD18: =SUMIFS('Combined P&L'!AF:AF,'Combined P&L'!$C:$C,'P&L Overview'!$B18) -> 0 | AE18: =SUMIFS('Combined P&L'!AG:AG,'Combined P&L'!$C:$C,'P&L Overview'!$B18) -> 0 | AF18: =SUMIFS('Combined P&L'!AH:AH,'Combined P&L'!$C:$C,'P&L Overview'!$B18) -> 0.875 | AG18: =SUMIFS('Combined P&L'!AI:AI,'Combined P&L'!$C:$C,'P&L Overview'!$B18) -> 1.65 | AH18: =SUMIFS('Combined P&L'!AJ:AJ,'Combined P&L'!$C:$C,'P&L Overview'!$B18) -> 0 | AI18: =SUMIFS('Combined P&L'!AK:AK,'Combined P&L'!$C:$C,'P&L Overview'!$B18) -> 0.875 | AJ18: =SUMIFS('Combined P&L'!AL:AL,'Combined P&L'!$C:$C,'P&L Overview'!$B18) -> 0 | AK18: =SUMIFS('Combined P&L'!AM:AM,'Combined P&L'!$C:$C,'P&L Overview'!$B18) -> 0 | AL18: =SUMIFS('Combined P&L'!AN:AN,'Combined P&L'!$C:$C,'P&L Overview'!$B18) -> 14.19 | AM18: =SUMIFS('Combined P&L'!AO:AO,'Combined P&L'!$C:$C,'P&L Overview'!$B18) -> 6.625 | AN18: =SUMIFS('Combined P&L'!AP:AP,'Combined P&L'!$C:$C,'P&L Overview'!$B18) -> 0 | AO18: =SUMIFS('Combined P&L'!AQ:AQ,'Combined P&L'!$C:$C,'P&L Overview'!$B18) -> 3.1 | AP18: =SUMIFS('Combined P&L'!AR:AR,'Combined P&L'!$C:$C,'P&L Overview'!$B18) -> 0
B19: Profit Share | C19: =SUMIFS($L19:$AP19,$L$5:$AP$5,">"&C$42,$L$5:$AP$5,"<"&C$43) -> 6.2004 | D19: =SUMIFS($L19:$AP19,$L$5:$AP$5,">"&D$42,$L$5:$AP$5,"<"&D$43) -> 23.26179 | F19: =SUMIFS($L19:$AP19,$L$5:$AP$5,">"&F$42,$L$5:$AP$5,"<"&F$43) -> 14.50495 | G19: =SUMIFS($L19:$AP19,$L$5:$AP$5,">"&G$42,$L$5:$AP$5,"<"&G$43) -> 8.07938 | I19: =SUMIFS($L19:$AP19,$L$5:$AP$5,">"&I$42,$L$5:$AP$5,"<"&I$43) -> 17.94788 | J19: =SUMIFS($L19:$AP19,$L$5:$AP$5,">"&J$42,$L$5:$AP$5,"<"&J$43) -> 17.79609 | L19: =SUMIFS('Combined P&L'!N:N,'Combined P&L'!$C:$C,'P&L Overview'!$B19) -> 0.0686 | M19: =SUMIFS('Combined P&L'!O:O,'Combined P&L'!$C:$C,'P&L Overview'!$B19) -> 0.1312 | N19: =SUMIFS('Combined P&L'!P:P,'Combined P&L'!$C:$C,'P&L Overview'!$B19) -> 0.0712 | O19: =SUMIFS('Combined P&L'!Q:Q,'Combined P&L'!$C:$C,'P&L Overview'!$B19) -> 0.0556 | P19: =SUMIFS('Combined P&L'!R:R,'Combined P&L'!$C:$C,'P&L Overview'!$B19) -> 0.577 | Q19: =SUMIFS('Combined P&L'!S:S,'Combined P&L'!$C:$C,'P&L Overview'!$B19) -> 0.8068 | R19: =SUMIFS('Combined P&L'!T:T,'Combined P&L'!$C:$C,'P&L Overview'!$B19) -> 0.6656 | S19: =SUMIFS('Combined P&L'!U:U,'Combined P&L'!$C:$C,'P&L Overview'!$B19) -> 0.8264 | T19: =SUMIFS('Combined P&L'!V:V,'Combined P&L'!$C:$C,'P&L Overview'!$B19) -> 1.3808 | U19: =SUMIFS('Combined P&L'!W:W,'Combined P&L'!$C:$C,'P&L Overview'!$B19) -> 0.8604 | V19: =SUMIFS('Combined P&L'!X:X,'Combined P&L'!$C:$C,'P&L Overview'!$B19) -> 0.51 | W19: =SUMIFS('Combined P&L'!Y:Y,'Combined P&L'!$C:$C,'P&L Overview'!$B19) -> 0.2468 | X19: =SUMIFS('Combined P&L'!Z:Z,'Combined P&L'!$C:$C,'P&L Overview'!$B19) -> 7.3584 | Y19: =SUMIFS('Combined P&L'!AA:AA,'Combined P&L'!$C:$C,'P&L Overview'!$B19) -> 1.29335 | Z19: =SUMIFS('Combined P&L'!AB:AB,'Combined P&L'!$C:$C,'P&L Overview'!$B19) -> 0.96833 | AA19: =SUMIFS('Combined P&L'!AC:AC,'Combined P&L'!$C:$C,'P&L Overview'!$B19) -> 1.1656 | AB19: =SUMIFS('Combined P&L'!AD:AD,'Combined P&L'!$C:$C,'P&L Overview'!$B19) -> 0.96093 | AC19: =SUMIFS('Combined P&L'!AE:AE,'Combined P&L'!$C:$C,'P&L Overview'!$B19) -> 1.71127 | AD19: =SUMIFS('Combined P&L'!AF:AF,'Combined P&L'!$C:$C,'P&L Overview'!$B19) -> 1.04707 | AE19: =SUMIFS('Combined P&L'!AG:AG,'Combined P&L'!$C:$C,'P&L Overview'!$B19) -> 2.04088 | AF19: =SUMIFS('Combined P&L'!AH:AH,'Combined P&L'!$C:$C,'P&L Overview'!$B19) -> 1.13621 | AG19: =SUMIFS('Combined P&L'!AI:AI,'Combined P&L'!$C:$C,'P&L Overview'!$B19) -> 2.01424 | AH19: =SUMIFS('Combined P&L'!AJ:AJ,'Combined P&L'!$C:$C,'P&L Overview'!$B19) -> 1.29758 | AI19: =SUMIFS('Combined P&L'!AK:AK,'Combined P&L'!$C:$C,'P&L Overview'!$B19) -> 2.26793 | AJ19: =SUMIFS('Combined P&L'!AL:AL,'Combined P&L'!$C:$C,'P&L Overview'!$B19) -> 2.67784 | AK19: =SUMIFS('Combined P&L'!AM:AM,'Combined P&L'!$C:$C,'P&L Overview'!$B19) -> 2.35401 | AL19: =SUMIFS('Combined P&L'!AN:AN,'Combined P&L'!$C:$C,'P&L Overview'!$B19) -> 0.2276 | AM19: =SUMIFS('Combined P&L'!AO:AO,'Combined P&L'!$C:$C,'P&L Overview'!$B19) -> 1.47836 | AN19: =SUMIFS('Combined P&L'!AP:AP,'Combined P&L'!$C:$C,'P&L Overview'!$B19) -> 0.66824 | AO19: =SUMIFS('Combined P&L'!AQ:AQ,'Combined P&L'!$C:$C,'P&L Overview'!$B19) -> 0.58613 | AP19: =SUMIFS('Combined P&L'!AR:AR,'Combined P&L'!$C:$C,'P&L Overview'!$B19) -> 0.0872
B20: Billable Expense Income | C20: =SUMIFS($L20:$AP20,$L$5:$AP$5,">"&C$42,$L$5:$AP$5,"<"&C$43) -> 0.3747 | D20: =SUMIFS($L20:$AP20,$L$5:$AP$5,">"&D$42,$L$5:$AP$5,"<"&D$43) -> 1.12194 | F20: =SUMIFS($L20:$AP20,$L$5:$AP$5,">"&F$42,$L$5:$AP$5,"<"&F$43) -> 0.78725 | G20: =SUMIFS($L20:$AP20,$L$5:$AP$5,">"&G$42,$L$5:$AP$5,"<"&G$43) -> 0.25783 | I20: =SUMIFS($L20:$AP20,$L$5:$AP$5,">"&I$42,$L$5:$AP$5,"<"&I$43) -> 0.79724 | J20: =SUMIFS($L20:$AP20,$L$5:$AP$5,">"&J$42,$L$5:$AP$5,"<"&J$43) -> 0.88223 | L20: =SUMIFS('Combined P&L'!N:N,'Combined P&L'!$C:$C,'P&L Overview'!$B20) -> 0.05 | M20: =SUMIFS('Combined P&L'!O:O,'Combined P&L'!$C:$C,'P&L Overview'!$B20) -> 0 | N20: =SUMIFS('Combined P&L'!P:P,'Combined P&L'!$C:$C,'P&L Overview'!$B20) -> 0 | O20: =SUMIFS('Combined P&L'!Q:Q,'Combined P&L'!$C:$C,'P&L Overview'!$B20) -> 0.025 | P20: =SUMIFS('Combined P&L'!R:R,'Combined P&L'!$C:$C,'P&L Overview'!$B20) -> 0 | Q20: =SUMIFS('Combined P&L'!S:S,'Combined P&L'!$C:$C,'P&L Overview'!$B20) -> 0 | R20: =SUMIFS('Combined P&L'!T:T,'Combined P&L'!$C:$C,'P&L Overview'!$B20) -> 0.2997 | S20: =SUMIFS('Combined P&L'!U:U,'Combined P&L'!$C:$C,'P&L Overview'!$B20) -> 0 | T20: =SUMIFS('Combined P&L'!V:V,'Combined P&L'!$C:$C,'P&L Overview'!$B20) -> 0 | U20: =SUMIFS('Combined P&L'!W:W,'Combined P&L'!$C:$C,'P&L Overview'!$B20) -> 0 | V20: =SUMIFS('Combined P&L'!X:X,'Combined P&L'!$C:$C,'P&L Overview'!$B20) -> 0 | W20: =SUMIFS('Combined P&L'!Y:Y,'Combined P&L'!$C:$C,'P&L Overview'!$B20) -> 0 | X20: =SUMIFS('Combined P&L'!Z:Z,'Combined P&L'!$C:$C,'P&L Overview'!$B20) -> 0.025 | Y20: =SUMIFS('Combined P&L'!AA:AA,'Combined P&L'!$C:$C,'P&L Overview'!$B20) -> 0.3996 | Z20: =SUMIFS('Combined P&L'!AB:AB,'Combined P&L'!$C:$C,'P&L Overview'!$B20) -> 0 | AA20: =SUMIFS('Combined P&L'!AC:AC,'Combined P&L'!$C:$C,'P&L Overview'!$B20) -> 0 | AB20: =SUMIFS('Combined P&L'!AD:AD,'Combined P&L'!$C:$C,'P&L Overview'!$B20) -> 0.07294 | AC20: =SUMIFS('Combined P&L'!AE:AE,'Combined P&L'!$C:$C,'P&L Overview'!$B20) -> 0 | AD20: =SUMIFS('Combined P&L'!AF:AF,'Combined P&L'!$C:$C,'P&L Overview'!$B20) -> 0.28971 | AE20: =SUMIFS('Combined P&L'!AG:AG,'Combined P&L'!$C:$C,'P&L Overview'!$B20) -> 0.30969 | AF20: =SUMIFS('Combined P&L'!AH:AH,'Combined P&L'!$C:$C,'P&L Overview'!$B20) -> 0 | AG20: =SUMIFS('Combined P&L'!AI:AI,'Combined P&L'!$C:$C,'P&L Overview'!$B20) -> 0 | AH20: =SUMIFS('Combined P&L'!AJ:AJ,'Combined P&L'!$C:$C,'P&L Overview'!$B20) -> 0 | AI20: =SUMIFS('Combined P&L'!AK:AK,'Combined P&L'!$C:$C,'P&L Overview'!$B20) -> 0.025 | AJ20: =SUMIFS('Combined P&L'!AL:AL,'Combined P&L'!$C:$C,'P&L Overview'!$B20) -> 0.15984 | AK20: =SUMIFS('Combined P&L'!AM:AM,'Combined P&L'!$C:$C,'P&L Overview'!$B20) -> 0 | AL20: =SUMIFS('Combined P&L'!AN:AN,'Combined P&L'!$C:$C,'P&L Overview'!$B20) -> 0.075 | AM20: =SUMIFS('Combined P&L'!AO:AO,'Combined P&L'!$C:$C,'P&L Overview'!$B20) -> 0 | AN20: =SUMIFS('Combined P&L'!AP:AP,'Combined P&L'!$C:$C,'P&L Overview'!$B20) -> 0 | AO20: =SUMIFS('Combined P&L'!AQ:AQ,'Combined P&L'!$C:$C,'P&L Overview'!$B20) -> 0.02299 | AP20: =SUMIFS('Combined P&L'!AR:AR,'Combined P&L'!$C:$C,'P&L Overview'!$B20) -> 0
B21: Offshore Recruiting | C21: =SUMIFS($L21:$AP21,$L$5:$AP$5,">"&C$42,$L$5:$AP$5,"<"&C$43) -> 23.6 | D21: =SUMIFS($L21:$AP21,$L$5:$AP$5,">"&D$42,$L$5:$AP$5,"<"&D$43) -> 0.2 | F21: =SUMIFS($L21:$AP21,$L$5:$AP$5,">"&F$42,$L$5:$AP$5,"<"&F$43) -> 0.2 | G21: =SUMIFS($L21:$AP21,$L$5:$AP$5,">"&G$42,$L$5:$AP$5,"<"&G$43) -> 0 | I21: =SUMIFS($L21:$AP21,$L$5:$AP$5,">"&I$42,$L$5:$AP$5,"<"&I$43) -> 16.735 | J21: =SUMIFS($L21:$AP21,$L$5:$AP$5,">"&J$42,$L$5:$AP$5,"<"&J$43) -> 0 | L21: =SUMIFS('Combined P&L'!N:N,'Combined P&L'!$C:$C,'P&L Overview'!$B21) -> 0.5 | M21: =SUMIFS('Combined P&L'!O:O,'Combined P&L'!$C:$C,'P&L Overview'!$B21) -> 3 | N21: =SUMIFS('Combined P&L'!P:P,'Combined P&L'!$C:$C,'P&L Overview'!$B21) -> 0 | O21: =SUMIFS('Combined P&L'!Q:Q,'Combined P&L'!$C:$C,'P&L Overview'!$B21) -> 0 | P21: =SUMIFS('Combined P&L'!R:R,'Combined P&L'!$C:$C,'P&L Overview'!$B21) -> 3 | Q21: =SUMIFS('Combined P&L'!S:S,'Combined P&L'!$C:$C,'P&L Overview'!$B21) -> 0.565 | R21: =SUMIFS('Combined P&L'!T:T,'Combined P&L'!$C:$C,'P&L Overview'!$B21) -> 10.5 | S21: =SUMIFS('Combined P&L'!U:U,'Combined P&L'!$C:$C,'P&L Overview'!$B21) -> 6.5 | T21: =SUMIFS('Combined P&L'!V:V,'Combined P&L'!$C:$C,'P&L Overview'!$B21) -> 0.5 | U21: =SUMIFS('Combined P&L'!W:W,'Combined P&L'!$C:$C,'P&L Overview'!$B21) -> -0.965 | V21: =SUMIFS('Combined P&L'!X:X,'Combined P&L'!$C:$C,'P&L Overview'!$B21) -> 0 | W21: =SUMIFS('Combined P&L'!Y:Y,'Combined P&L'!$C:$C,'P&L Overview'!$B21) -> 0 | X21: =SUMIFS('Combined P&L'!Z:Z,'Combined P&L'!$C:$C,'P&L Overview'!$B21) -> 0.1 | Y21: =SUMIFS('Combined P&L'!AA:AA,'Combined P&L'!$C:$C,'P&L Overview'!$B21) -> 0 | Z21: =SUMIFS('Combined P&L'!AB:AB,'Combined P&L'!$C:$C,'P&L Overview'!$B21) -> 0.1 | AA21: =SUMIFS('Combined P&L'!AC:AC,'Combined P&L'!$C:$C,'P&L Overview'!$B21) -> 0 | AB21: =SUMIFS('Combined P&L'!AD:AD,'Combined P&L'!$C:$C,'P&L Overview'!$B21) -> 0 | AC21: =SUMIFS('Combined P&L'!AE:AE,'Combined P&L'!$C:$C,'P&L Overview'!$B21) -> 0 | AD21: =SUMIFS('Combined P&L'!AF:AF,'Combined P&L'!$C:$C,'P&L Overview'!$B21) -> 0 | AE21: =SUMIFS('Combined P&L'!AG:AG,'Combined P&L'!$C:$C,'P&L Overview'!$B21) -> 0 | AF21: =SUMIFS('Combined P&L'!AH:AH,'Combined P&L'!$C:$C,'P&L Overview'!$B21) -> 0 | AG21: =SUMIFS('Combined P&L'!AI:AI,'Combined P&L'!$C:$C,'P&L Overview'!$B21) -> 0 | AH21: =SUMIFS('Combined P&L'!AJ:AJ,'Combined P&L'!$C:$C,'P&L Overview'!$B21) -> 0 | AI21: =SUMIFS('Combined P&L'!AK:AK,'Combined P&L'!$C:$C,'P&L Overview'!$B21) -> 0 | AJ21: =SUMIFS('Combined P&L'!AL:AL,'Combined P&L'!$C:$C,'P&L Overview'!$B21) -> 0 | AK21: =SUMIFS('Combined P&L'!AM:AM,'Combined P&L'!$C:$C,'P&L Overview'!$B21) -> 0 | AL21: =SUMIFS('Combined P&L'!AN:AN,'Combined P&L'!$C:$C,'P&L Overview'!$B21) -> 0 | AM21: =SUMIFS('Combined P&L'!AO:AO,'Combined P&L'!$C:$C,'P&L Overview'!$B21) -> 0 | AN21: =SUMIFS('Combined P&L'!AP:AP,'Combined P&L'!$C:$C,'P&L Overview'!$B21) -> 0 | AO21: =SUMIFS('Combined P&L'!AQ:AQ,'Combined P&L'!$C:$C,'P&L Overview'!$B21) -> 0 | AP21: =SUMIFS('Combined P&L'!AR:AR,'Combined P&L'!$C:$C,'P&L Overview'!$B21) -> 0
B22: Total Recurring Revenue | C22: =SUM(C17:C21) -> 40.6501 | D22: =SUM(D17:D21) -> 51.53373 | F22: =SUM(F17:F21) -> 38.9822 | G22: =SUM(G17:G21) -> 70.95371 | I22: =SUM(I17:I21) -> 59.00012 | J22: =SUM(J17:J21) -> 84.75482 | L22: =SUM(L17:L21) -> 7.5636 | M22: =SUM(M17:M21) -> 6.5112 | N22: =SUM(N17:N21) -> 0.1162 | O22: =SUM(O17:O21) -> 0.1406 | P22: =SUM(P17:P21) -> 3.592 | Q22: =SUM(Q17:Q21) -> 1.3718 | R22: =SUM(R17:R21) -> 11.4653 | S22: =SUM(S17:S21) -> 7.3414 | ... AP22: =SUM(AP17:AP21) -> 0.0872
B24: Total Revenue | C24: =+C22+C15 -> 1134.9659 | D24: =+D22+D15 -> 1879.3831 | F24: =+F22+F15 -> 997.8731 | G24: =+G22+G15 -> 1671.0212 | I24: =+I22+I15 -> 1473.7119 | J24: =+J22+J15 -> 2456.4862 | L24: =+L22+L15 -> 80.9131 | M24: =+M22+M15 -> 81.2557 | N24: =+N22+N15 -> 78.1122 | O24: =+O22+O15 -> 83.3533 | P24: =+P22+P15 -> 90.19615 | Q24: =+Q22+Q15 -> 89.9158 | R24: =+R22+R15 -> 104.68205 | S24: =+S22+S15 -> 104.11675 | ... AP24: =+AP22+AP15 -> 251.42585
B26: Expenses
B27: Indirect Labor | C27: =SUMIFS($L27:$AP27,$L$5:$AP$5,">"&C$42,$L$5:$AP$5,"<"&C$43) -> 101.3752 | D27: =SUMIFS($L27:$AP27,$L$5:$AP$5,">"&D$42,$L$5:$AP$5,"<"&D$43) -> 281.24054 | F27: =SUMIFS($L27:$AP27,$L$5:$AP$5,">"&F$42,$L$5:$AP$5,"<"&F$43) -> 136.29648 | G27: =SUMIFS($L27:$AP27,$L$5:$AP$5,">"&G$42,$L$5:$AP$5,"<"&G$43) -> 357.27472 | I27: =SUMIFS($L27:$AP27,$L$5:$AP$5,">"&I$42,$L$5:$AP$5,"<"&I$43) -> 184.76374 | J27: =SUMIFS($L27:$AP27,$L$5:$AP$5,">"&J$42,$L$5:$AP$5,"<"&J$43) -> 466.92604 | L27: =SUMIFS('Combined P&L'!N:N,'Combined P&L'!$C:$C,'P&L Overview'!$B27) -> 3.09346 | M27: =SUMIFS('Combined P&L'!O:O,'Combined P&L'!$C:$C,'P&L Overview'!$B27) -> 4.63017 | N27: =SUMIFS('Combined P&L'!P:P,'Combined P&L'!$C:$C,'P&L Overview'!$B27) -> 4.39507 | O27: =SUMIFS('Combined P&L'!Q:Q,'Combined P&L'!$C:$C,'P&L Overview'!$B27) -> 5.86387 | P27: =SUMIFS('Combined P&L'!R:R,'Combined P&L'!$C:$C,'P&L Overview'!$B27) -> 7.37233 | Q27: =SUMIFS('Combined P&L'!S:S,'Combined P&L'!$C:$C,'P&L Overview'!$B27) -> 4.9504 | R27: =SUMIFS('Combined P&L'!T:T,'Combined P&L'!$C:$C,'P&L Overview'!$B27) -> 4.9504 | S27: =SUMIFS('Combined P&L'!U:U,'Combined P&L'!$C:$C,'P&L Overview'!$B27) -> 4.70035 | T27: =SUMIFS('Combined P&L'!V:V,'Combined P&L'!$C:$C,'P&L Overview'!$B27) -> 4.9504 | U27: =SUMIFS('Combined P&L'!W:W,'Combined P&L'!$C:$C,'P&L Overview'!$B27) -> 5.99987 | V27: =SUMIFS('Combined P&L'!X:X,'Combined P&L'!$C:$C,'P&L Overview'!$B27) -> 26.02876 | W27: =SUMIFS('Combined P&L'!Y:Y,'Combined P&L'!$C:$C,'P&L Overview'!$B27) -> 24.44012 | X27: =SUMIFS('Combined P&L'!Z:Z,'Combined P&L'!$C:$C,'P&L Overview'!$B27) -> 21.05234 | Y27: =SUMIFS('Combined P&L'!AA:AA,'Combined P&L'!$C:$C,'P&L Overview'!$B27) -> 19.91603 | Z27: =SUMIFS('Combined P&L'!AB:AB,'Combined P&L'!$C:$C,'P&L Overview'!$B27) -> 11.74387 | AA27: =SUMIFS('Combined P&L'!AC:AC,'Combined P&L'!$C:$C,'P&L Overview'!$B27) -> 19.61792 | AB27: =SUMIFS('Combined P&L'!AD:AD,'Combined P&L'!$C:$C,'P&L Overview'!$B27) -> 20.66978 | AC27: =SUMIFS('Combined P&L'!AE:AE,'Combined P&L'!$C:$C,'P&L Overview'!$B27) -> 20.6939 | AD27: =SUMIFS('Combined P&L'!AF:AF,'Combined P&L'!$C:$C,'P&L Overview'!$B27) -> 22.60264 | AE27: =SUMIFS('Combined P&L'!AG:AG,'Combined P&L'!$C:$C,'P&L Overview'!$B27) -> 19.96128 | AF27: =SUMIFS('Combined P&L'!AH:AH,'Combined P&L'!$C:$C,'P&L Overview'!$B27) -> 27.60563 | AG27: =SUMIFS('Combined P&L'!AI:AI,'Combined P&L'!$C:$C,'P&L Overview'!$B27) -> 34.18589 | AH27: =SUMIFS('Combined P&L'!AJ:AJ,'Combined P&L'!$C:$C,'P&L Overview'!$B27) -> 29.73157 | AI27: =SUMIFS('Combined P&L'!AK:AK,'Combined P&L'!$C:$C,'P&L Overview'!$B27) -> 33.45969 | AJ27: =SUMIFS('Combined P&L'!AL:AL,'Combined P&L'!$C:$C,'P&L Overview'!$B27) -> 36.2536 | AK27: =SUMIFS('Combined P&L'!AM:AM,'Combined P&L'!$C:$C,'P&L Overview'!$B27) -> 33.60751 | AL27: =SUMIFS('Combined P&L'!AN:AN,'Combined P&L'!$C:$C,'P&L Overview'!$B27) -> 57.19924 | AM27: =SUMIFS('Combined P&L'!AO:AO,'Combined P&L'!$C:$C,'P&L Overview'!$B27) -> 58.24595 | AN27: =SUMIFS('Combined P&L'!AP:AP,'Combined P&L'!$C:$C,'P&L Overview'!$B27) -> 54.06923 | AO27: =SUMIFS('Combined P&L'!AQ:AQ,'Combined P&L'!$C:$C,'P&L Overview'!$B27) -> 60.00381 | AP27: =SUMIFS('Combined P&L'!AR:AR,'Combined P&L'!$C:$C,'P&L Overview'!$B27) -> 57.89538
B28: Bookkeeper Wages | C28: =SUMIFS($L28:$AP28,$L$5:$AP$5,">"&C$42,$L$5:$AP$5,"<"&C$43) -> 183.36903 | D28: =SUMIFS($L28:$AP28,$L$5:$AP$5,">"&D$42,$L$5:$AP$5,"<"&D$43) -> 316.18462 | F28: =SUMIFS($L28:$AP28,$L$5:$AP$5,">"&F$42,$L$5:$AP$5,"<"&F$43) -> 147.26813 | G28: =SUMIFS($L28:$AP28,$L$5:$AP$5,">"&G$42,$L$5:$AP$5,"<"&G$43) -> 267.7574 | I28: =SUMIFS($L28:$AP28,$L$5:$AP$5,">"&I$42,$L$5:$AP$5,"<"&I$43) -> 226.32031 | J28: =SUMIFS($L28:$AP28,$L$5:$AP$5,">"&J$42,$L$5:$AP$5,"<"&J$43) -> 420.0952 | L28: =SUMIFS('Combined P&L'!N:N,'Combined P&L'!$C:$C,'P&L Overview'!$B28) -> 9.555 | M28: =SUMIFS('Combined P&L'!O:O,'Combined P&L'!$C:$C,'P&L Overview'!$B28) -> 9.555 | N28: =SUMIFS('Combined P&L'!P:P,'Combined P&L'!$C:$C,'P&L Overview'!$B28) -> 10.3972 | O28: =SUMIFS('Combined P&L'!Q:Q,'Combined P&L'!$C:$C,'P&L Overview'!$B28) -> 14.99967 | P28: =SUMIFS('Combined P&L'!R:R,'Combined P&L'!$C:$C,'P&L Overview'!$B28) -> 18.0098 | Q28: =SUMIFS('Combined P&L'!S:S,'Combined P&L'!$C:$C,'P&L Overview'!$B28) -> 13.89127 | R28: =SUMIFS('Combined P&L'!T:T,'Combined P&L'!$C:$C,'P&L Overview'!$B28) -> 14.04824 | S28: =SUMIFS('Combined P&L'!U:U,'Combined P&L'!$C:$C,'P&L Overview'!$B28) -> 13.39091 | T28: =SUMIFS('Combined P&L'!V:V,'Combined P&L'!$C:$C,'P&L Overview'!$B28) -> 14.66931 | U28: =SUMIFS('Combined P&L'!W:W,'Combined P&L'!$C:$C,'P&L Overview'!$B28) -> 15.88253 | V28: =SUMIFS('Combined P&L'!X:X,'Combined P&L'!$C:$C,'P&L Overview'!$B28) -> 27.18867 | W28: =SUMIFS('Combined P&L'!Y:Y,'Combined P&L'!$C:$C,'P&L Overview'!$B28) -> 21.78143 | X28: =SUMIFS('Combined P&L'!Z:Z,'Combined P&L'!$C:$C,'P&L Overview'!$B28) -> 19.40233 | Y28: =SUMIFS('Combined P&L'!AA:AA,'Combined P&L'!$C:$C,'P&L Overview'!$B28) -> 16.40053 | Z28: =SUMIFS('Combined P&L'!AB:AB,'Combined P&L'!$C:$C,'P&L Overview'!$B28) -> 19.56983 | AA28: =SUMIFS('Combined P&L'!AC:AC,'Combined P&L'!$C:$C,'P&L Overview'!$B28) -> 22.1542 | AB28: =SUMIFS('Combined P&L'!AD:AD,'Combined P&L'!$C:$C,'P&L Overview'!$B28) -> 20.79154 | AC28: =SUMIFS('Combined P&L'!AE:AE,'Combined P&L'!$C:$C,'P&L Overview'!$B28) -> 21.04079 | AD28: =SUMIFS('Combined P&L'!AF:AF,'Combined P&L'!$C:$C,'P&L Overview'!$B28) -> 27.90891 | AE28: =SUMIFS('Combined P&L'!AG:AG,'Combined P&L'!$C:$C,'P&L Overview'!$B28) -> 29.547 | AF28: =SUMIFS('Combined P&L'!AH:AH,'Combined P&L'!$C:$C,'P&L Overview'!$B28) -> 33.44727 | AG28: =SUMIFS('Combined P&L'!AI:AI,'Combined P&L'!$C:$C,'P&L Overview'!$B28) -> 37.79432 | AH28: =SUMIFS('Combined P&L'!AJ:AJ,'Combined P&L'!$C:$C,'P&L Overview'!$B28) -> 34.06332 | AI28: =SUMIFS('Combined P&L'!AK:AK,'Combined P&L'!$C:$C,'P&L Overview'!$B28) -> 34.06458 | AJ28: =SUMIFS('Combined P&L'!AL:AL,'Combined P&L'!$C:$C,'P&L Overview'!$B28) -> 38.37888 | AK28: =SUMIFS('Combined P&L'!AM:AM,'Combined P&L'!$C:$C,'P&L Overview'!$B28) -> 29.70152 | AL28: =SUMIFS('Combined P&L'!AN:AN,'Combined P&L'!$C:$C,'P&L Overview'!$B28) -> 37.4225 | AM28: =SUMIFS('Combined P&L'!AO:AO,'Combined P&L'!$C:$C,'P&L Overview'!$B28) -> 38.7723 | AN28: =SUMIFS('Combined P&L'!AP:AP,'Combined P&L'!$C:$C,'P&L Overview'!$B28) -> 38.29477 | AO28: =SUMIFS('Combined P&L'!AQ:AQ,'Combined P&L'!$C:$C,'P&L Overview'!$B28) -> 40.69983 | AP28: =SUMIFS('Combined P&L'!AR:AR,'Combined P&L'!$C:$C,'P&L Overview'!$B28) -> 44.4876
B29: Client Lead Wages | C29: =SUMIFS($L29:$AP29,$L$5:$AP$5,">"&C$42,$L$5:$AP$5,"<"&C$43) -> 286.16129 | D29: =SUMIFS($L29:$AP29,$L$5:$AP$5,">"&D$42,$L$5:$AP$5,"<"&D$43) -> 352.95844 | F29: =SUMIFS($L29:$AP29,$L$5:$AP$5,">"&F$42,$L$5:$AP$5,"<"&F$43) -> 201.27983 | G29: =SUMIFS($L29:$AP29,$L$5:$AP$5,">"&G$42,$L$5:$AP$5,"<"&G$43) -> 202.05309 | I29: =SUMIFS($L29:$AP29,$L$5:$AP$5,">"&I$42,$L$5:$AP$5,"<"&I$43) -> 351.95999 | J29: =SUMIFS($L29:$AP29,$L$5:$AP$5,">"&J$42,$L$5:$AP$5,"<"&J$43) -> 350.46762 | L29: =SUMIFS('Combined P&L'!N:N,'Combined P&L'!$C:$C,'P&L Overview'!$B29) -> 9.96108 | M29: =SUMIFS('Combined P&L'!O:O,'Combined P&L'!$C:$C,'P&L Overview'!$B29) -> 13.85026 | N29: =SUMIFS('Combined P&L'!P:P,'Combined P&L'!$C:$C,'P&L Overview'!$B29) -> 12.79054 | O29: =SUMIFS('Combined P&L'!Q:Q,'Combined P&L'!$C:$C,'P&L Overview'!$B29) -> 14.57145 | P29: =SUMIFS('Combined P&L'!R:R,'Combined P&L'!$C:$C,'P&L Overview'!$B29) -> 28.28563 | Q29: =SUMIFS('Combined P&L'!S:S,'Combined P&L'!$C:$C,'P&L Overview'!$B29) -> 26.54254 | R29: =SUMIFS('Combined P&L'!T:T,'Combined P&L'!$C:$C,'P&L Overview'!$B29) -> 28.31119 | S29: =SUMIFS('Combined P&L'!U:U,'Combined P&L'!$C:$C,'P&L Overview'!$B29) -> 28.18746 | T29: =SUMIFS('Combined P&L'!V:V,'Combined P&L'!$C:$C,'P&L Overview'!$B29) -> 30.86801 | U29: =SUMIFS('Combined P&L'!W:W,'Combined P&L'!$C:$C,'P&L Overview'!$B29) -> 31.62128 | V29: =SUMIFS('Combined P&L'!X:X,'Combined P&L'!$C:$C,'P&L Overview'!$B29) -> 28.44974 | W29: =SUMIFS('Combined P&L'!Y:Y,'Combined P&L'!$C:$C,'P&L Overview'!$B29) -> 32.72211 | X29: =SUMIFS('Combined P&L'!Z:Z,'Combined P&L'!$C:$C,'P&L Overview'!$B29) -> 32.78076 | Y29: =SUMIFS('Combined P&L'!AA:AA,'Combined P&L'!$C:$C,'P&L Overview'!$B29) -> 23.36184 | Z29: =SUMIFS('Combined P&L'!AB:AB,'Combined P&L'!$C:$C,'P&L Overview'!$B29) -> 26.91427 | AA29: =SUMIFS('Combined P&L'!AC:AC,'Combined P&L'!$C:$C,'P&L Overview'!$B29) -> 28.81298 | AB29: =SUMIFS('Combined P&L'!AD:AD,'Combined P&L'!$C:$C,'P&L Overview'!$B29) -> 30.65875 | AC29: =SUMIFS('Combined P&L'!AE:AE,'Combined P&L'!$C:$C,'P&L Overview'!$B29) -> 29.2716 | AD29: =SUMIFS('Combined P&L'!AF:AF,'Combined P&L'!$C:$C,'P&L Overview'!$B29) -> 29.47963 | AE29: =SUMIFS('Combined P&L'!AG:AG,'Combined P&L'!$C:$C,'P&L Overview'!$B29) -> 26.83064 | AF29: =SUMIFS('Combined P&L'!AH:AH,'Combined P&L'!$C:$C,'P&L Overview'!$B29) -> 29.78555 | AG29: =SUMIFS('Combined P&L'!AI:AI,'Combined P&L'!$C:$C,'P&L Overview'!$B29) -> 32.89937 | AH29: =SUMIFS('Combined P&L'!AJ:AJ,'Combined P&L'!$C:$C,'P&L Overview'!$B29) -> 29.49334 | AI29: =SUMIFS('Combined P&L'!AK:AK,'Combined P&L'!$C:$C,'P&L Overview'!$B29) -> 32.66971 | AJ29: =SUMIFS('Combined P&L'!AL:AL,'Combined P&L'!$C:$C,'P&L Overview'!$B29) -> 26.1149 | AK29: =SUMIFS('Combined P&L'!AM:AM,'Combined P&L'!$C:$C,'P&L Overview'!$B29) -> 21.9055 | AL29: =SUMIFS('Combined P&L'!AN:AN,'Combined P&L'!$C:$C,'P&L Overview'!$B29) -> 30.75844 | AM29: =SUMIFS('Combined P&L'!AO:AO,'Combined P&L'!$C:$C,'P&L Overview'!$B29) -> 31.59038 | AN29: =SUMIFS('Combined P&L'!AP:AP,'Combined P&L'!$C:$C,'P&L Overview'!$B29) -> 27.69992 | AO29: =SUMIFS('Combined P&L'!AQ:AQ,'Combined P&L'!$C:$C,'P&L Overview'!$B29) -> 31.24024 | AP29: =SUMIFS('Combined P&L'!AR:AR,'Combined P&L'!$C:$C,'P&L Overview'!$B29) -> 32.74371
B30: Onboarding Team Wages | C30: =SUMIFS($L30:$AP30,$L$5:$AP$5,">"&C$42,$L$5:$AP$5,"<"&C$43) -> 122.81255 | D30: =SUMIFS($L30:$AP30,$L$5:$AP$5,">"&D$42,$L$5:$AP$5,"<"&D$43) -> 152.16972 | F30: =SUMIFS($L30:$AP30,$L$5:$AP$5,">"&F$42,$L$5:$AP$5,"<"&F$43) -> 73.94962 | G30: =SUMIFS($L30:$AP30,$L$5:$AP$5,">"&G$42,$L$5:$AP$5,"<"&G$43) -> 111.27999 | I30: =SUMIFS($L30:$AP30,$L$5:$AP$5,">"&I$42,$L$5:$AP$5,"<"&I$43) -> 115.8168 | J30: =SUMIFS($L30:$AP30,$L$5:$AP$5,">"&J$42,$L$5:$AP$5,"<"&J$43) -> 186.54354 | L30: =SUMIFS('Combined P&L'!N:N,'Combined P&L'!$C:$C,'P&L Overview'!$B30) -> 9.13728 | M30: =SUMIFS('Combined P&L'!O:O,'Combined P&L'!$C:$C,'P&L Overview'!$B30) -> 8.96296 | N30: =SUMIFS('Combined P&L'!P:P,'Combined P&L'!$C:$C,'P&L Overview'!$B30) -> 10.19584 | O30: =SUMIFS('Combined P&L'!Q:Q,'Combined P&L'!$C:$C,'P&L Overview'!$B30) -> 15.04429 | P30: =SUMIFS('Combined P&L'!R:R,'Combined P&L'!$C:$C,'P&L Overview'!$B30) -> 16.63744 | Q30: =SUMIFS('Combined P&L'!S:S,'Combined P&L'!$C:$C,'P&L Overview'!$B30) -> 7.49499 | R30: =SUMIFS('Combined P&L'!T:T,'Combined P&L'!$C:$C,'P&L Overview'!$B30) -> 7.98202 | S30: =SUMIFS('Combined P&L'!U:U,'Combined P&L'!$C:$C,'P&L Overview'!$B30) -> 5.90274 | T30: =SUMIFS('Combined P&L'!V:V,'Combined P&L'!$C:$C,'P&L Overview'!$B30) -> 7.76763 | U30: =SUMIFS('Combined P&L'!W:W,'Combined P&L'!$C:$C,'P&L Overview'!$B30) -> 8.21417 | V30: =SUMIFS('Combined P&L'!X:X,'Combined P&L'!$C:$C,'P&L Overview'!$B30) -> 12.62272 | W30: =SUMIFS('Combined P&L'!Y:Y,'Combined P&L'!$C:$C,'P&L Overview'!$B30) -> 12.85047 | X30: =SUMIFS('Combined P&L'!Z:Z,'Combined P&L'!$C:$C,'P&L Overview'!$B30) -> 10.34556 | Y30: =SUMIFS('Combined P&L'!AA:AA,'Combined P&L'!$C:$C,'P&L Overview'!$B30) -> 8.08798 | Z30: =SUMIFS('Combined P&L'!AB:AB,'Combined P&L'!$C:$C,'P&L Overview'!$B30) -> 9.75287 | AA30: =SUMIFS('Combined P&L'!AC:AC,'Combined P&L'!$C:$C,'P&L Overview'!$B30) -> 10.28 | AB30: =SUMIFS('Combined P&L'!AD:AD,'Combined P&L'!$C:$C,'P&L Overview'!$B30) -> 11.13632 | AC30: =SUMIFS('Combined P&L'!AE:AE,'Combined P&L'!$C:$C,'P&L Overview'!$B30) -> 10.87432 | AD30: =SUMIFS('Combined P&L'!AF:AF,'Combined P&L'!$C:$C,'P&L Overview'!$B30) -> 13.47257 | AE30: =SUMIFS('Combined P&L'!AG:AG,'Combined P&L'!$C:$C,'P&L Overview'!$B30) -> 12.70407 | AF30: =SUMIFS('Combined P&L'!AH:AH,'Combined P&L'!$C:$C,'P&L Overview'!$B30) -> 14.69884 | AG30: =SUMIFS('Combined P&L'!AI:AI,'Combined P&L'!$C:$C,'P&L Overview'!$B30) -> 15.54306 | AH30: =SUMIFS('Combined P&L'!AJ:AJ,'Combined P&L'!$C:$C,'P&L Overview'!$B30) -> 14.34361 | AI30: =SUMIFS('Combined P&L'!AK:AK,'Combined P&L'!$C:$C,'P&L Overview'!$B30) -> 20.93052 | AJ30: =SUMIFS('Combined P&L'!AL:AL,'Combined P&L'!$C:$C,'P&L Overview'!$B30) -> 16.55394 | AK30: =SUMIFS('Combined P&L'!AM:AM,'Combined P&L'!$C:$C,'P&L Overview'!$B30) -> 11.52661 | AL30: =SUMIFS('Combined P&L'!AN:AN,'Combined P&L'!$C:$C,'P&L Overview'!$B30) -> 14.93883 | AM30: =SUMIFS('Combined P&L'!AO:AO,'Combined P&L'!$C:$C,'P&L Overview'!$B30) -> 15.58352 | AN30: =SUMIFS('Combined P&L'!AP:AP,'Combined P&L'!$C:$C,'P&L Overview'!$B30) -> 19.6034 | AO30: =SUMIFS('Combined P&L'!AQ:AQ,'Combined P&L'!$C:$C,'P&L Overview'!$B30) -> 16.64457 | AP30: =SUMIFS('Combined P&L'!AR:AR,'Combined P&L'!$C:$C,'P&L Overview'!$B30) -> 16.42912
B31: Owner Wages | C31: =SUMIFS($L31:$AP31,$L$5:$AP$5,">"&C$42,$L$5:$AP$5,"<"&C$43) -> 0 | D31: =SUMIFS($L31:$AP31,$L$5:$AP$5,">"&D$42,$L$5:$AP$5,"<"&D$43) -> 90.66704 | F31: =SUMIFS($L31:$AP31,$L$5:$AP$5,">"&F$42,$L$5:$AP$5,"<"&F$43) -> 45.46612 | G31: =SUMIFS($L31:$AP31,$L$5:$AP$5,">"&G$42,$L$5:$AP$5,"<"&G$43) -> 63.14302 | I31: =SUMIFS($L31:$AP31,$L$5:$AP$5,">"&I$42,$L$5:$AP$5,"<"&I$43) -> 35.94325 | J31: =SUMIFS($L31:$AP31,$L$5:$AP$5,">"&J$42,$L$5:$AP$5,"<"&J$43) -> 108.34394 | L31: =SUMIFS('Combined P&L'!N:N,'Combined P&L'!$C:$C,'P&L Overview'!$B31) -> 0 | M31: =SUMIFS('Combined P&L'!O:O,'Combined P&L'!$C:$C,'P&L Overview'!$B31) -> 0 | N31: =SUMIFS('Combined P&L'!P:P,'Combined P&L'!$C:$C,'P&L Overview'!$B31) -> 0 | O31: =SUMIFS('Combined P&L'!Q:Q,'Combined P&L'!$C:$C,'P&L Overview'!$B31) -> 0 | P31: =SUMIFS('Combined P&L'!R:R,'Combined P&L'!$C:$C,'P&L Overview'!$B31) -> 0 | Q31: =SUMIFS('Combined P&L'!S:S,'Combined P&L'!$C:$C,'P&L Overview'!$B31) -> 0 | R31: =SUMIFS('Combined P&L'!T:T,'Combined P&L'!$C:$C,'P&L Overview'!$B31) -> 0 | S31: =SUMIFS('Combined P&L'!U:U,'Combined P&L'!$C:$C,'P&L Overview'!$B31) -> 0 | T31: =SUMIFS('Combined P&L'!V:V,'Combined P&L'!$C:$C,'P&L Overview'!$B31) -> 0 | U31: =SUMIFS('Combined P&L'!W:W,'Combined P&L'!$C:$C,'P&L Overview'!$B31) -> 0 | V31: =SUMIFS('Combined P&L'!X:X,'Combined P&L'!$C:$C,'P&L Overview'!$B31) -> 0 | W31: =SUMIFS('Combined P&L'!Y:Y,'Combined P&L'!$C:$C,'P&L Overview'!$B31) -> 0 | X31: =SUMIFS('Combined P&L'!Z:Z,'Combined P&L'!$C:$C,'P&L Overview'!$B31) -> 0 | Y31: =SUMIFS('Combined P&L'!AA:AA,'Combined P&L'!$C:$C,'P&L Overview'!$B31) -> 0 | Z31: =SUMIFS('Combined P&L'!AB:AB,'Combined P&L'!$C:$C,'P&L Overview'!$B31) -> 8.90639 | AA31: =SUMIFS('Combined P&L'!AC:AC,'Combined P&L'!$C:$C,'P&L Overview'!$B31) -> 9.23323 | AB31: =SUMIFS('Combined P&L'!AD:AD,'Combined P&L'!$C:$C,'P&L Overview'!$B31) -> 9.10884 | AC31: =SUMIFS('Combined P&L'!AE:AE,'Combined P&L'!$C:$C,'P&L Overview'!$B31) -> 8.69479 | AD31: =SUMIFS('Combined P&L'!AF:AF,'Combined P&L'!$C:$C,'P&L Overview'!$B31) -> 9.52287 | AE31: =SUMIFS('Combined P&L'!AG:AG,'Combined P&L'!$C:$C,'P&L Overview'!$B31) -> 8.69481 | AF31: =SUMIFS('Combined P&L'!AH:AH,'Combined P&L'!$C:$C,'P&L Overview'!$B31) -> 9.10884 | AG31: =SUMIFS('Combined P&L'!AI:AI,'Combined P&L'!$C:$C,'P&L Overview'!$B31) -> 9.52287 | AH31: =SUMIFS('Combined P&L'!AJ:AJ,'Combined P&L'!$C:$C,'P&L Overview'!$B31) -> 8.28076 | AI31: =SUMIFS('Combined P&L'!AK:AK,'Combined P&L'!$C:$C,'P&L Overview'!$B31) -> 9.59364 | AJ31: =SUMIFS('Combined P&L'!AL:AL,'Combined P&L'!$C:$C,'P&L Overview'!$B31) -> 9.27621 | AK31: =SUMIFS('Combined P&L'!AM:AM,'Combined P&L'!$C:$C,'P&L Overview'!$B31) -> 8.32263 | AL31: =SUMIFS('Combined P&L'!AN:AN,'Combined P&L'!$C:$C,'P&L Overview'!$B31) -> 9.10883 | AM31: =SUMIFS('Combined P&L'!AO:AO,'Combined P&L'!$C:$C,'P&L Overview'!$B31) -> 9.10883 | AN31: =SUMIFS('Combined P&L'!AP:AP,'Combined P&L'!$C:$C,'P&L Overview'!$B31) -> 8.69481 | AO31: =SUMIFS('Combined P&L'!AQ:AQ,'Combined P&L'!$C:$C,'P&L Overview'!$B31) -> 9.10884 | AP31: =SUMIFS('Combined P&L'!AR:AR,'Combined P&L'!$C:$C,'P&L Overview'!$B31) -> 9.52287
