Workbook

Sheet Cover
B24: Keystone Bookkeepers
B25: Pre-LOI Business Analysis
B26: ="As of "&TEXT(TODAY(),"mm/dd/yy") -> As of 09/24/26

Sheet Offer Overview
B2: =Cover!$B$24 -> Keystone Bookkeepers
B3: Offer & Equity Upside Scenarios ($000s) | G3: Print | H3: 1
B5: Offer Breakdown | C5: Today
B6: Run-Rate Revenue (PF Jul'26) | C6: ='P&L Overview'!$K$16 -> 2998.541
B7: (x) Revenue Multiple — Implied | C7: =IFERROR($C$8/$C$6,0) -> 1.0004866
B8: Total Valuation — Offer Price | C8: 3000
B9: (-) Cash at Close | C9: 650
B10: Topkey Equity Consideration | C10: =C8-C9 -> 2350
B12: Topkey Pre-Deal Valuation | C12: ='Offer Comparison'!$C$9 -> 60000
B13: (+) Keystone Value Acquired | C13: =$C$8 -> 3000
B14: (-) Cash Paid at Close | C14: =$C$9 -> 650
B15: Topkey Post-Money Valuation | C15: =C12+C13-C14 -> 62350
B16: Ben's Implied Topkey Ownership % | C16: =IFERROR($C$10/$C$15,0) -> 0.037690457
B17: Keystone Enterprise Value Today | C17: =$C$8 -> 3000
B18: Existing Shareholders' Value Post-Close | C18: =(1-$C$16)*$C$15 -> 60000
B20: Topkey Pre-Deal Valuation | C20: =$C$12 -> 60000
B21: (-) Cash Paid at Close | C21: =$C$14 -> 650
B22: Topkey ex-Keystone Growth Base | C22: =C20-C21 -> 59350
B24: Scenario 1 — Ben Retains 100% of Keystone | C24: Today | D24: 2.0x Valuation | E24: 3.0x Valuation
B25: Keystone Growth Multiple | C25: 1 | D25: 2 | E25: 3
B26: Keystone Enterprise Value | C26: =$C$17*C$25 -> 3000 | D26: =$C$17*D$25 -> 6000 | E26: =$C$17*E$25 -> 9000
B27: Ben's Ownership % — Keystone | C27: 1 | D27: =$C$27 -> 1 | E27: =$C$27 -> 1
B28: Ben's Keystone Equity Value | C28: =C26*$C$27 -> 3000 | D28: =D26*$C$27 -> 6000 | E28: =E26*$C$27 -> 9000
B29: (-) Value at Offer Today | C29: =$C$28 -> 3000 | D29: =$C$28 -> 3000 | E29: =$C$28 -> 3000
B30: Ben's Net Gain vs. Today | C30: =C28-C29 -> 0 | D30: =D28-D29 -> 3000 | E30: =E28-E29 -> 6000
B32: Combined Topkey + Keystone TEV | C32: Growth (ex-Keystone) | D32: =D$24 -> 2.0x Valuation | E32: =E$24 -> 3.0x Valuation
B33: Topkey Grows Half as Fast as Keystone | C33: 0.5 | D33: =$C$22*(1+(D$25-1)*$C33)+$C$17*D$25 -> 95025 | E33: =$C$22*(1+(E$25-1)*$C33)+$C$17*E$25 -> 127700
B34: Topkey Keeps Pace with Keystone | C34: 1 | D34: =$C$22*(1+(D$25-1)*$C34)+$C$17*D$25 -> 124700 | E34: =$C$22*(1+(E$25-1)*$C34)+$C$17*E$25 -> 187050
B35: Topkey Outgrows Keystone | C35: 1.5 | D35: =$C$22*(1+(D$25-1)*$C35)+$C$17*D$25 -> 154375 | E35: =$C$22*(1+(E$25-1)*$C35)+$C$17*E$25 -> 246400
B37: Ben's Total Value — Cash + Topkey Equity | D37: =+D$32 -> 2.0x Valuation | E37: =+E$32 -> 3.0x Valuation
B38: =$B33 -> Topkey Grows Half as Fast as Keystone | D38: =$C$9+$C$16*D33 -> 4231.5357 | E38: =$C$9+$C$16*E33 -> 5463.0714
B39: =$B34 -> Topkey Keeps Pace with Keystone | D39: =$C$9+$C$16*D34 -> 5350 | E39: =$C$9+$C$16*E34 -> 7700
B40: =$B35 -> Topkey Outgrows Keystone | D40: =$C$9+$C$16*D35 -> 6468.4643 | E40: =$C$9+$C$16*E35 -> 9936.9286
B42: Delta vs. Scenario 1 | D42: =+D$32 -> 2.0x Valuation | E42: =+E$32 -> 3.0x Valuation
B43: =$B33 -> Topkey Grows Half as Fast as Keystone | D43: =D38-D$28 -> -1768.4643 | E43: =E38-E$28 -> -3536.9286
B44: =$B34 -> Topkey Keeps Pace with Keystone | D44: =D39-D$28 -> -650 | E44: =E39-E$28 -> -1300
B45: =$B35 -> Topkey Outgrows Keystone | D45: =D40-D$28 -> 468.46431 | E45: =E40-E$28 -> 936.92863
B47: Topkey Growth Required for Parity | D47: =+D$32 -> 2.0x Valuation | E47: =+E$32 -> 3.0x Valuation
B48: Ben's Value — Scenario 1 (Retain 100%) | D48: =D$28 -> 6000 | E48: =E$28 -> 9000
B49: (-) Ben's Cash at Close | D49: =$C$9 -> 650 | E49: =$C$9 -> 650
...

Sheet Offer Comparison
B2: =Cover!$B$24 -> Keystone Bookkeepers
B3: Offer Comparison — Partnership vs. 100% Buyout ($000s) | H3: Print | I3: 1
B5: Deal Assumptions | C5: Partnership | D5: 100% Buyout | E5: Variance | G5: Notes
B7: Horizon (Years) | C7: 5 | D7: =C7 -> 5 | E7: =C7-D7 -> 0 | G7: Input — drives Partnership and Buyout tabs (D = C)
B8: Est. Topkey Dilution — Ben's Stake (Year 5) | C8: 0.05 | D8: =C8 -> 0.05 | E8: =C8-D8 -> 0 | G8: Input — drives Partnership and Buyout tabs (D = C)
B9: Topkey Valuation Today — Pre-Deal | C9: 60000 | D9: =C9 -> 60000 | E9: =C9-D9 -> 0 | G9: Input — single Topkey valuation; drives Offer Overview, Partnership and Buyout tabs
B10: Topkey 5-Year Valuation Growth (ex-Keystone) | C10: ='Partnership Analysis'!$C$19 -> 2.021904 | D10: ='100% Buyout Analysis'!$C$18 -> 2.0084034 | E10: =C10-D10 -> 0.013500598 | G10: Differs because each offer's cash at close is netted from Topkey's ex-Keystone base; measures value growth, not revenue
B11: Keystone 5-Yr Revenue Increase — Standalone (% of Start) | C11: =IFERROR('Partnership Analysis'!$C$28/'Partnership Analysis'!$C$47,0) -> 0.99837392 | D11: =IFERROR('100% Buyout Analysis'!$C$27/'100% Buyout Analysis'!$C$46,0) -> 0.99837392 | E11: =C11-D11 -> 0 | G11: Total additional standalone revenue ÷ Keystone run-rate revenue at close
B12: Keystone 5-Yr Revenue Increase — Partnership (% of Start) | C12: =IFERROR('Partnership Analysis'!$C$42/'Partnership Analysis'!$C$47,0) -> 1.3311652 | D12: =IFERROR('100% Buyout Analysis'!$C$41/'100% Buyout Analysis'!$C$46,0) -> 1.3311652 | E12: =C12-D12 -> 0 | G12: Total additional partnership revenue ÷ Keystone run-rate revenue at close
B13: Keystone Initial Revenue Multiple | C13: 1 | D13: =C13 -> 1 | E13: =C13-D13 -> 0 | G13: Input — drives Partnership and Buyout tabs (D = C)
B14: Keystone Scaled Revenue Multiple | C14: 1.25 | D14: =C14 -> 1.25 | E14: =C14-D14 -> 0 | G14: Input — drives Partnership and Buyout tabs (D = C)
B15: Keystone Software-Integration Revenue Multiple | C15: 2 | D15: =C15 -> 2 | E15: =C15-D15 -> 0 | G15: Input — drives Partnership and Buyout tabs (D = C)
B16: General Assumptions
B17: Ben's Rollover % — Keystone | C17: 0.3 | D17: 0 | E17: =C17-D17 -> 0.3 | G17: Input — share of Keystone Ben keeps (Partnership 30%; Buyout 0% = Topkey acquires 100%)
B18: Topkey - Current Monthly Revenue | C18: 261 | D18: =C18 -> 261 | E18: =C18-D18 -> 0 | G18: Input — drives Partnership and Buyout tabs (D = C). Topkey-provided monthly revenue ($000s); red = pending seller confirmation
B19: Topkey - Current Client Count | C19: 325 | D19: =C19 -> 325 | E19: =C19-D19 -> 0 | G19: Input — drives Partnership and Buyout tabs (D = C). Topkey-provided client count; red = pending seller confirmation
B20: Topkey - Annual Net Client Wins | C20: 130 | D20: =C20 -> 130 | E20: =C20-D20 -> 0 | G20: Input — drives Partnership and Buyout tabs (D = C). AMB placeholder; red = pending confirmation
B21: Keystone Standalone Assumptions
B22: Avg. Revenue Per Client | C22: ='Steady-State Staffing'!$AB$8 -> 16.631473 | D22: =C22 -> 16.631473 | E22: =C22-D22 -> 0 | G22: Linked to Steady-State Staffing AB8 (Sep'26 annualized fee per non-tax client); drives both tabs (D = C)
B23: Target Monthly Net Client Wins | C23: 3 | D23: =C23 -> 3 | E23: =C23-D23 -> 0 | G23: Input — drives Partnership and Buyout tabs (D = C). AMB target pace; LTM actual is 26/yr (~2.2/month)
B24: Keystone Partnership Assumptions
B25: VR Platform Run-Rate Tech Cost | C25: 240 | D25: =C25 -> 240 | E25: =C25-D25 -> 0 | G25: Input — drives Partnership and Buyout tabs (D = C). Run-rate tech cost provided by the target; memo only
B26: Software-Enabled Price Increase / Client | C26: 0 | D26: =C26 -> 0 | E26: =C26-D26 -> 0 | G26: Input — drives Partnership and Buyout tabs (D = C). Only if Topkey software supports higher client fees
B27: Additional Annual Net Client Wins From Topkey | C27: 12 | D27: =C27 -> 12 | E27: =C27-D27 -> 0 | G27: Input — drives Partnership and Buyout tabs (D = C). Topkey-provided; red = pending seller confirmation
B29: Offer Structure | C29: Partnership | D29: 100% Buyout | E29: Variance
B30: Keystone Value Today (100%) | C30: ='Partnership Analysis'!$C$185 -> 3000 | D30: ='100% Buyout Analysis'!$C$173 -> 3000 | E30: =C30-D30 -> 0
B31: Ben's Rollover % — Keystone | C31: =C17 -> 0.3 | D31: =D17 -> 0 | E31: =C31-D31 -> 0.3 | G31: Linked to Ben's Rollover % input (row 17)
B32: Keystone Stake Acquired by Topkey | C32: ='Partnership Analysis'!$C$187 -> 0.7 | D32: ='100% Buyout Analysis'!$C$96 -> 1 | E32: =C32-D32 -> -0.3
B33: Price for Topkey's Stake (at Close) | C33: ='Partnership Analysis'!$C$188 -> 2100 | D33: ='100% Buyout Analysis'!$C$173 -> 3000 | E33: =C33-D33 -> -900
B34: Cash at Close | C34: ='Partnership Analysis'!$C$189 -> 650 | D34: ='100% Buyout Analysis'!$C$174 -> 500 | E34: =C34-D34 -> 150 | G34: Partnership cash of $650K is set to cover Ben's tax situation
B35: (+) Topkey Equity Issued to Ben | C35: ='Partnership Analysis'!$C$190 -> 1450 | D35: ='100% Buyout Analysis'!$C$175 -> 2500 | E35: =C35-D35 -> -1050
B36: (+) Target Cash Earnout (at 100% Achievement) — Year 3 | C36: ='Partnership Analysis'!$C$58 -> 0 | D36: ='100% Buyout Analysis'!$C$57 -> 500 | E36: =C36-D36 -> -500 | G36: Buyout: $500K target, capped at $750K (150% of target). Partnership: no earnout
B37: Total Consideration Paid by Topkey | C37: =SUM(C34:C36) -> 2100 | D37: =SUM(D34:D36) -> 3500 | E37: =C37-D37 -> -1400 | G37: Cash + equity issued + target earnout; tie-out to analysis tabs in row 38
B38: Tie Out — Consideration vs. Analysis Tab | C38: =C37-'Partnership Analysis'!$C$106 -> 0 | D38: =D37-'100% Buyout Analysis'!$C$95 -> 0 | G38: Must equal zero
B39: % of Consideration in Cash (incl. Earnout) | C39: =IFERROR((C34+C36)/C37,0) -> 0.30952381 | D39: =IFERROR((D34+D36)/D37,0) -> 0.28571429 | E39: =C39-D39 -> 0.023809524
B41: Where Ben's Year 5 Value Comes From | C41: Partnership | D41: 100% Buyout | E41: Variance
B43: Retained Keystone Stake (Direct) | C43: =IFERROR(C106/C$111,0) -> 0.46170498 | D43: =IFERROR(D106/D$111,0) -> 0 | E43: =C43-D43 -> 0.46170498
B44: Keystone via Topkey | C44: =IFERROR(C107/C$111,0) -> 0.024149662 | D44: =IFERROR(D107/D$111,0) -> 0.063750321 | E44: =C44-D44 -> -0.039600659
B45: Topkey ex-Keystone | C45: =IFERROR(C108/C$111,0) -> 0.44258976 | D45: =IFERROR(D108/D$111,0) -> 0.81624844 | E45: =C45-D45 -> -0.37365868
B46: Cash at Close | C46: =IFERROR(C109/C$111,0) -> 0.071555598 | D46: =IFERROR(D109/D$111,0) -> 0.06000062 | E46: =C46-D46 -> 0.011554978
...

Sheet Partnership Sensitivity Tables
B2: =Cover!$B$24 -> Keystone Bookkeepers
B3: Partnership Sensitivity Tables ($000s) | N3: Print | O3: 1
B5: Ben's Return Profile Based on Partnering
B6: Ben's Net Returns Based on Topkey Growth & Rollover %
D8: Topkey ex-Keystone Value Growth (%) | S8: Helper: IRR Year Index | Z8: Helper: Unrounded Net Return
D9: =E9-$G$441 -> 1.021904 | E9: =F9-$G$441 -> 1.271904 | F9: =G9-$G$441 -> 1.521904 | G9: =H9-$G$441 -> 1.771904 | H9: =$G$440 -> 2.021904 | I9: =H9+$G$441 -> 2.271904 | J9: =I9+$G$441 -> 2.521904 | K9: =J9+$G$441 -> 2.771904 | L9: =K9+$G$441 -> 3.021904 | N9: Helper: Rollover % | O9: Helper: Cash at Close | P9: Helper: Topkey Equity Issued | Q9: Helper: Topkey ex-Keystone Today | R9: Helper: Ben's Yr 5 Topkey % | S9: 0 | T9: =S9+1 -> 1 | U9: =T9+1 -> 2 | V9: =U9+1 -> 3 | W9: =V9+1 -> 4 | X9: =W9+1 -> 5 | Z9: =D$9 -> 1.021904 | AA9: =E$9 -> 1.271904 | AB9: =F$9 -> 1.521904 | AC9: =G$9 -> 1.771904 | AD9: =H$9 -> 2.021904 | AE9: =I$9 -> 2.271904 | AF9: =J$9 -> 2.521904 | AG9: =K$9 -> 2.771904 | AH9: =L$9 -> 3.021904 | AT9: Helper: Gradient Band (0 = below $1M hurdle)
B10: Ben's Rollover % | C10: =C11-$G$439 -> 0.15 | D10: =ROUND(Z10,$G$452) -> 3600 | E10: =ROUND(AA10,$G$452) -> 4000 | F10: =ROUND(AB10,$G$452) -> 4500 | G10: =ROUND(AC10,$G$452) -> 4900 | H10: =ROUND(AD10,$G$452) -> 5300 | I10: =ROUND(AE10,$G$452) -> 5800 | J10: =ROUND(AF10,$G$452) -> 6200 | K10: =ROUND(AG10,$G$452) -> 6600 | L10: =ROUND(AH10,$G$452) -> 7100 | N10: =$C10 -> 0.15 | O10: =$G$433 -> 650 | P10: =$G$430*(1-N10)-O10 -> 1900 | Q10: =$G$432-O10 -> 59350 | R10: =IFERROR(P10/(Q10+$G$430*(1-N10)),0)*(1-$G$434) -> 0.029159935 | Z10: =$O10+$G$435+$N10*$G$431+$R10*($Q10*(1+D$9)+$G$431*(1-$N10))-$G$430 -> 3592.7328 | AA10: =$O10+$G$435+$N10*$G$431+$R10*($Q10*(1+E$9)+$G$431*(1-$N10))-$G$430 -> 4025.3933 | AB10: =$O10+$G$435+$N10*$G$431+$R10*($Q10*(1+F$9)+$G$431*(1-$N10))-$G$430 -> 4458.0539 | AC10: =$O10+$G$435+$N10*$G$431+$R10*($Q10*(1+G$9)+$G$431*(1-$N10))-$G$430 -> 4890.7144 | AD10: =$O10+$G$435+$N10*$G$431+$R10*($Q10*(1+H$9)+$G$431*(1-$N10))-$G$430 -> 5323.375 | AE10: =$O10+$G$435+$N10*$G$431+$R10*($Q10*(1+I$9)+$G$431*(1-$N10))-$G$430 -> 5756.0355 | AF10: =$O10+$G$435+$N10*$G$431+$R10*($Q10*(1+J$9)+$G$431*(1-$N10))-$G$430 -> 6188.6961 | AG10: =$O10+$G$435+$N10*$G$431+$R10*($Q10*(1+K$9)+$G$431*(1-$N10))-$G$430 -> 6621.3566 | AH10: =$O10+$G$435+$N10*$G$431+$R10*($Q10*(1+L$9)+$G$431*(1-$N10))-$G$430 -> 7054.0171 | AT10: =IF(Z50<$G$449,0,MIN($G$446,1+IFERROR(INT((Z50-$G$449)/$G$451),0))) -> 0 | AU10: =IF(AA50<$G$449,0,MIN($G$446,1+IFERROR(INT((AA50-$G$449)/$G$451),0))) -> 0 | AV10: =IF(AB50<$G$449,0,MIN($G$446,1+IFERROR(INT((AB50-$G$449)/$G$451),0))) -> 0 | AW10: =IF(AC50<$G$449,0,MIN($G$446,1+IFERROR(INT((AC50-$G$449)/$G$451),0))) -> 0 | AX10: =IF(AD50<$G$449,0,MIN($G$446,1+IFERROR(INT((AD50-$G$449)/$G$451),0))) -> 0 | AY10: =IF(AE50<$G$449,0,MIN($G$446,1+IFERROR(INT((AE50-$G$449)/$G$451),0))) -> 2 | AZ10: =IF(AF50<$G$449,0,MIN($G$446,1+IFERROR(INT((AF50-$G$449)/$G$451),0))) -> 4 | BA10: =IF(AG50<$G$449,0,MIN($G$446,1+IFERROR(INT((AG50-$G$449)/$G$451),0))) -> 5 | BB10: =IF(AH50<$G$449,0,MIN($G$446,1+IFERROR(INT((AH50-$G$449)/$G$451),0))) -> 7
C11: =C12-$G$439 -> 0.2 | D11: =ROUND(Z11,$G$452) -> 4000 | E11: =ROUND(AA11,$G$452) -> 4400 | F11: =ROUND(AB11,$G$452) -> 4800 | G11: =ROUND(AC11,$G$452) -> 5200 | H11: =ROUND(AD11,$G$452) -> 5600 | I11: =ROUND(AE11,$G$452) -> 6000 | J11: =ROUND(AF11,$G$452) -> 6400 | K11: =ROUND(AG11,$G$452) -> 6800 | L11: =ROUND(AH11,$G$452) -> 7200 | N11: =$C11 -> 0.2 | O11: =$G$433 -> 650 | P11: =$G$430*(1-N11)-O11 -> 1750 | Q11: =$G$432-O11 -> 59350 | R11: =IFERROR(P11/(Q11+$G$430*(1-N11)),0)*(1-$G$434) -> 0.026923077 | Z11: =$O11+$G$435+$N11*$G$431+$R11*($Q11*(1+D$9)+$G$431*(1-$N11))-$G$430 -> 3977.9188 | AA11: =$O11+$G$435+$N11*$G$431+$R11*($Q11*(1+E$9)+$G$431*(1-$N11))-$G$430 -> 4377.39 | AB11: =$O11+$G$435+$N11*$G$431+$R11*($Q11*(1+F$9)+$G$431*(1-$N11))-$G$430 -> 4776.8611 | AC11: =$O11+$G$435+$N11*$G$431+$R11*($Q11*(1+G$9)+$G$431*(1-$N11))-$G$430 -> 5176.3323 | AD11: =$O11+$G$435+$N11*$G$431+$R11*($Q11*(1+H$9)+$G$431*(1-$N11))-$G$430 -> 5575.8034 | AE11: =$O11+$G$435+$N11*$G$431+$R11*($Q11*(1+I$9)+$G$431*(1-$N11))-$G$430 -> 5975.2746 | AF11: =$O11+$G$435+$N11*$G$431+$R11*($Q11*(1+J$9)+$G$431*(1-$N11))-$G$430 -> 6374.7457 | AG11: =$O11+$G$435+$N11*$G$431+$R11*($Q11*(1+K$9)+$G$431*(1-$N11))-$G$430 -> 6774.2169 | AH11: =$O11+$G$435+$N11*$G$431+$R11*($Q11*(1+L$9)+$G$431*(1-$N11))-$G$430 -> 7173.688 | AT11: =IF(Z51<$G$449,0,MIN($G$446,1+IFERROR(INT((Z51-$G$449)/$G$451),0))) -> 0 | AU11: =IF(AA51<$G$449,0,MIN($G$446,1+IFERROR(INT((AA51-$G$449)/$G$451),0))) -> 0 | AV11: =IF(AB51<$G$449,0,MIN($G$446,1+IFERROR(INT((AB51-$G$449)/$G$451),0))) -> 0 | AW11: =IF(AC51<$G$449,0,MIN($G$446,1+IFERROR(INT((AC51-$G$449)/$G$451),0))) -> 0 | AX11: =IF(AD51<$G$449,0,MIN($G$446,1+IFERROR(INT((AD51-$G$449)/$G$451),0))) -> 1 | AY11: =IF(AE51<$G$449,0,MIN($G$446,1+IFERROR(INT((AE51-$G$449)/$G$451),0))) -> 3 | AZ11: =IF(AF51<$G$449,0,MIN($G$446,1+IFERROR(INT((AF51-$G$449)/$G$451),0))) -> 4 | BA11: =IF(AG51<$G$449,0,MIN($G$446,1+IFERROR(INT((AG51-$G$449)/$G$451),0))) -> 6 | BB11: =IF(AH51<$G$449,0,MIN($G$446,1+IFERROR(INT((AH51-$G$449)/$G$451),0))) -> 8
C12: =C13-$G$439 -> 0.25 | D12: =ROUND(Z12,$G$452) -> 4400 | E12: =ROUND(AA12,$G$452) -> 4700 | F12: =ROUND(AB12,$G$452) -> 5100 | G12: =ROUND(AC12,$G$452) -> 5500 | H12: =ROUND(AD12,$G$452) -> 5800 | I12: =ROUND(AE12,$G$452) -> 6200 | J12: =ROUND(AF12,$G$452) -> 6600 | K12: =ROUND(AG12,$G$452) -> 6900 | L12: =ROUND(AH12,$G$452) -> 7300 | N12: =$C12 -> 0.25 | O12: =$G$433 -> 650 | P12: =$G$430*(1-N12)-O12 -> 1600 | Q12: =$G$432-O12 -> 59350 | R12: =IFERROR(P12/(Q12+$G$430*(1-N12)),0)*(1-$G$434) -> 0.024675325 | Z12: =$O12+$G$435+$N12*$G$431+$R12*($Q12*(1+D$9)+$G$431*(1-$N12))-$G$430 -> 4364.8105 | AA12: =$O12+$G$435+$N12*$G$431+$R12*($Q12*(1+E$9)+$G$431*(1-$N12))-$G$430 -> 4730.9306 | AB12: =$O12+$G$435+$N12*$G$431+$R12*($Q12*(1+F$9)+$G$431*(1-$N12))-$G$430 -> 5097.0508 | AC12: =$O12+$G$435+$N12*$G$431+$R12*($Q12*(1+G$9)+$G$431*(1-$N12))-$G$430 -> 5463.1709 | AD12: =$O12+$G$435+$N12*$G$431+$R12*($Q12*(1+H$9)+$G$431*(1-$N12))-$G$430 -> 5829.291 | AE12: =$O12+$G$435+$N12*$G$431+$R12*($Q12*(1+I$9)+$G$431*(1-$N12))-$G$430 -> 6195.4112 | AF12: =$O12+$G$435+$N12*$G$431+$R12*($Q12*(1+J$9)+$G$431*(1-$N12))-$G$430 -> 6561.5313 | AG12: =$O12+$G$435+$N12*$G$431+$R12*($Q12*(1+K$9)+$G$431*(1-$N12))-$G$430 -> 6927.6514 | AH12: =$O12+$G$435+$N12*$G$431+$R12*($Q12*(1+L$9)+$G$431*(1-$N12))-$G$430 -> 7293.7715 | AT12: =IF(Z52<$G$449,0,MIN($G$446,1+IFERROR(INT((Z52-$G$449)/$G$451),0))) -> 0 | AU12: =IF(AA52<$G$449,0,MIN($G$446,1+IFERROR(INT((AA52-$G$449)/$G$451),0))) -> 0 | AV12: =IF(AB52<$G$449,0,MIN($G$446,1+IFERROR(INT((AB52-$G$449)/$G$451),0))) -> 0 | AW12: =IF(AC52<$G$449,0,MIN($G$446,1+IFERROR(INT((AC52-$G$449)/$G$451),0))) -> 0 | AX12: =IF(AD52<$G$449,0,MIN($G$446,1+IFERROR(INT((AD52-$G$449)/$G$451),0))) -> 2 | AY12: =IF(AE52<$G$449,0,MIN($G$446,1+IFERROR(INT((AE52-$G$449)/$G$451),0))) -> 4 | AZ12: =IF(AF52<$G$449,0,MIN($G$446,1+IFERROR(INT((AF52-$G$449)/$G$451),0))) -> 5 | BA12: =IF(AG52<$G$449,0,MIN($G$446,1+IFERROR(INT((AG52-$G$449)/$G$451),0))) -> 7 | BB12: =IF(AH52<$G$449,0,MIN($G$446,1+IFERROR(INT((AH52-$G$449)/$G$451),0))) -> 8
C13: =$G$438 -> 0.3 | D13: =ROUND(Z13,$G$452) -> 4800 | E13: =ROUND(AA13,$G$452) -> 5100 | F13: =ROUND(AB13,$G$452) -> 5400 | G13: =ROUND(AC13,$G$452) -> 5800 | H13: =ROUND(AD13,$G$452) -> 6100 | I13: =ROUND(AE13,$G$452) -> 6400 | J13: =ROUND(AF13,$G$452) -> 6700 | K13: =ROUND(AG13,$G$452) -> 7100 | L13: =ROUND(AH13,$G$452) -> 7400 | N13: =$C13 -> 0.3 | O13: =$G$433 -> 650 | P13: =$G$430*(1-N13)-O13 -> 1450 | Q13: =$G$432-O13 -> 59350 | R13: =IFERROR(P13/(Q13+$G$430*(1-N13)),0)*(1-$G$434) -> 0.022416599 | Z13: =$O13+$G$435+$N13*$G$431+$R13*($Q13*(1+D$9)+$G$431*(1-$N13))-$G$430 -> 4753.4204 | AA13: =$O13+$G$435+$N13*$G$431+$R13*($Q13*(1+E$9)+$G$431*(1-$N13))-$G$430 -> 5086.0267 | AB13: =$O13+$G$435+$N13*$G$431+$R13*($Q13*(1+F$9)+$G$431*(1-$N13))-$G$430 -> 5418.633 | AC13: =$O13+$G$435+$N13*$G$431+$R13*($Q13*(1+G$9)+$G$431*(1-$N13))-$G$430 -> 5751.2392 | AD13: =$O13+$G$435+$N13*$G$431+$R13*($Q13*(1+H$9)+$G$431*(1-$N13))-$G$430 -> 6083.8455 | AE13: =$O13+$G$435+$N13*$G$431+$R13*($Q13*(1+I$9)+$G$431*(1-$N13))-$G$430 -> 6416.4518 | AF13: =$O13+$G$435+$N13*$G$431+$R13*($Q13*(1+J$9)+$G$431*(1-$N13))-$G$430 -> 6749.0581 | AG13: =$O13+$G$435+$N13*$G$431+$R13*($Q13*(1+K$9)+$G$431*(1-$N13))-$G$430 -> 7081.6644 | AH13: =$O13+$G$435+$N13*$G$431+$R13*($Q13*(1+L$9)+$G$431*(1-$N13))-$G$430 -> 7414.2707 | AT13: =IF(Z53<$G$449,0,MIN($G$446,1+IFERROR(INT((Z53-$G$449)/$G$451),0))) -> 0 | AU13: =IF(AA53<$G$449,0,MIN($G$446,1+IFERROR(INT((AA53-$G$449)/$G$451),0))) -> 0 | AV13: =IF(AB53<$G$449,0,MIN($G$446,1+IFERROR(INT((AB53-$G$449)/$G$451),0))) -> 0 | AW13: =IF(AC53<$G$449,0,MIN($G$446,1+IFERROR(INT((AC53-$G$449)/$G$451),0))) -> 2 | AX13: =IF(AD53<$G$449,0,MIN($G$446,1+IFERROR(INT((AD53-$G$449)/$G$451),0))) -> 3 | AY13: =IF(AE53<$G$449,0,MIN($G$446,1+IFERROR(INT((AE53-$G$449)/$G$451),0))) -> 5 | AZ13: =IF(AF53<$G$449,0,MIN($G$446,1+IFERROR(INT((AF53-$G$449)/$G$451),0))) -> 6 | BA13: =IF(AG53<$G$449,0,MIN($G$446,1+IFERROR(INT((AG53-$G$449)/$G$451),0))) -> 7 | BB13: =IF(AH53<$G$449,0,MIN($G$446,1+IFERROR(INT((AH53-$G$449)/$G$451),0))) -> 9
C14: =C13+$G$439 -> 0.35 | D14: =ROUND(Z14,$G$452) -> 5100 | E14: =ROUND(AA14,$G$452) -> 5400 | F14: =ROUND(AB14,$G$452) -> 5700 | G14: =ROUND(AC14,$G$452) -> 6000 | H14: =ROUND(AD14,$G$452) -> 6300 | I14: =ROUND(AE14,$G$452) -> 6600 | J14: =ROUND(AF14,$G$452) -> 6900 | K14: =ROUND(AG14,$G$452) -> 7200 | L14: =ROUND(AH14,$G$452) -> 7500 | N14: =$C14 -> 0.35 | O14: =$G$433 -> 650 | P14: =$G$430*(1-N14)-O14 -> 1300 | Q14: =$G$432-O14 -> 59350 | R14: =IFERROR(P14/(Q14+$G$430*(1-N14)),0)*(1-$G$434) -> 0.020146819 | Z14: =$O14+$G$435+$N14*$G$431+$R14*($Q14*(1+D$9)+$G$431*(1-$N14))-$G$430 -> 5143.7611 | AA14: =$O14+$G$435+$N14*$G$431+$R14*($Q14*(1+E$9)+$G$431*(1-$N14))-$G$430 -> 5442.6895 | AB14: =$O14+$G$435+$N14*$G$431+$R14*($Q14*(1+F$9)+$G$431*(1-$N14))-$G$430 -> 5741.6179 | AC14: =$O14+$G$435+$N14*$G$431+$R14*($Q14*(1+G$9)+$G$431*(1-$N14))-$G$430 -> 6040.5463 | AD14: =$O14+$G$435+$N14*$G$431+$R14*($Q14*(1+H$9)+$G$431*(1-$N14))-$G$430 -> 6339.4748 | AE14: =$O14+$G$435+$N14*$G$431+$R14*($Q14*(1+I$9)+$G$431*(1-$N14))-$G$430 -> 6638.4032 | AF14: =$O14+$G$435+$N14*$G$431+$R14*($Q14*(1+J$9)+$G$431*(1-$N14))-$G$430 -> 6937.3316 | AG14: =$O14+$G$435+$N14*$G$431+$R14*($Q14*(1+K$9)+$G$431*(1-$N14))-$G$430 -> 7236.26 | AH14: =$O14+$G$435+$N14*$G$431+$R14*($Q14*(1+L$9)+$G$431*(1-$N14))-$G$430 -> 7535.1885 | AT14: =IF(Z54<$G$449,0,MIN($G$446,1+IFERROR(INT((Z54-$G$449)/$G$451),0))) -> 0 | AU14: =IF(AA54<$G$449,0,MIN($G$446,1+IFERROR(INT((AA54-$G$449)/$G$451),0))) -> 0 | AV14: =IF(AB54<$G$449,0,MIN($G$446,1+IFERROR(INT((AB54-$G$449)/$G$451),0))) -> 2 | AW14: =IF(AC54<$G$449,0,MIN($G$446,1+IFERROR(INT((AC54-$G$449)/$G$451),0))) -> 3 | AX14: =IF(AD54<$G$449,0,MIN($G$446,1+IFERROR(INT((AD54-$G$449)/$G$451),0))) -> 4 | AY14: =IF(AE54<$G$449,0,MIN($G$446,1+IFERROR(INT((AE54-$G$449)/$G$451),0))) -> 6 | AZ14: =IF(AF54<$G$449,0,MIN($G$446,1+IFERROR(INT((AF54-$G$449)/$G$451),0))) -> 7 | BA14: =IF(AG54<$G$449,0,MIN($G$446,1+IFERROR(INT((AG54-$G$449)/$G$451),0))) -> 8 | BB14: =IF(AH54<$G$449,0,MIN($G$446,1+IFERROR(INT((AH54-$G$449)/$G$451),0))) -> 9
C15: =C14+$G$439 -> 0.4 | D15: =ROUND(Z15,$G$452) -> 5500 | E15: =ROUND(AA15,$G$452) -> 5800 | F15: =ROUND(AB15,$G$452) -> 6100 | G15: =ROUND(AC15,$G$452) -> 6300 | H15: =ROUND(AD15,$G$452) -> 6600 | I15: =ROUND(AE15,$G$452) -> 6900 | J15: =ROUND(AF15,$G$452) -> 7100 | K15: =ROUND(AG15,$G$452) -> 7400 | L15: =ROUND(AH15,$G$452) -> 7700 | N15: =$C15 -> 0.4 | O15: =$G$433 -> 650 | P15: =$G$430*(1-N15)-O15 -> 1150 | Q15: =$G$432-O15 -> 59350 | R15: =IFERROR(P15/(Q15+$G$430*(1-N15)),0)*(1-$G$434) -> 0.017865904 | Z15: =$O15+$G$435+$N15*$G$431+$R15*($Q15*(1+D$9)+$G$431*(1-$N15))-$G$430 -> 5535.8453 | AA15: =$O15+$G$435+$N15*$G$431+$R15*($Q15*(1+E$9)+$G$431*(1-$N15))-$G$430 -> 5800.9306 | AB15: =$O15+$G$435+$N15*$G$431+$R15*($Q15*(1+F$9)+$G$431*(1-$N15))-$G$430 -> 6066.016 | AC15: =$O15+$G$435+$N15*$G$431+$R15*($Q15*(1+G$9)+$G$431*(1-$N15))-$G$430 -> 6331.1013 | AD15: =$O15+$G$435+$N15*$G$431+$R15*($Q15*(1+H$9)+$G$431*(1-$N15))-$G$430 -> 6596.1867 | AE15: =$O15+$G$435+$N15*$G$431+$R15*($Q15*(1+I$9)+$G$431*(1-$N15))-$G$430 -> 6861.272 | AF15: =$O15+$G$435+$N15*$G$431+$R15*($Q15*(1+J$9)+$G$431*(1-$N15))-$G$430 -> 7126.3573 | AG15: =$O15+$G$435+$N15*$G$431+$R15*($Q15*(1+K$9)+$G$431*(1-$N15))-$G$430 -> 7391.4427 | AH15: =$O15+$G$435+$N15*$G$431+$R15*($Q15*(1+L$9)+$G$431*(1-$N15))-$G$430 -> 7656.528 | AT15: =IF(Z55<$G$449,0,MIN($G$446,1+IFERROR(INT((Z55-$G$449)/$G$451),0))) -> 1 | AU15: =IF(AA55<$G$449,0,MIN($G$446,1+IFERROR(INT((AA55-$G$449)/$G$451),0))) -> 2 | AV15: =IF(AB55<$G$449,0,MIN($G$446,1+IFERROR(INT((AB55-$G$449)/$G$451),0))) -> 3 | AW15: =IF(AC55<$G$449,0,MIN($G$446,1+IFERROR(INT((AC55-$G$449)/$G$451),0))) -> 4 | AX15: =IF(AD55<$G$449,0,MIN($G$446,1+IFERROR(INT((AD55-$G$449)/$G$451),0))) -> 5 | AY15: =IF(AE55<$G$449,0,MIN($G$446,1+IFERROR(INT((AE55-$G$449)/$G$451),0))) -> 6 | AZ15: =IF(AF55<$G$449,0,MIN($G$446,1+IFERROR(INT((AF55-$G$449)/$G$451),0))) -> 8 | BA15: =IF(AG55<$G$449,0,MIN($G$446,1+IFERROR(INT((AG55-$G$449)/$G$451),0))) -> 9 | BB15: =IF(AH55<$G$449,0,MIN($G$446,1+IFERROR(INT((AH55-$G$449)/$G$451),0))) -> 10
C16: =C15+$G$439 -> 0.45 | D16: =ROUND(Z16,$G$452) -> 5900 | E16: =ROUND(AA16,$G$452) -> 6200 | F16: =ROUND(AB16,$G$452) -> 6400 | G16: =ROUND(AC16,$G$452) -> 6600 | H16: =ROUND(AD16,$G$452) -> 6900 | I16: =ROUND(AE16,$G$452) -> 7100 | J16: =ROUND(AF16,$G$452) -> 7300 | K16: =ROUND(AG16,$G$452) -> 7500 | L16: =ROUND(AH16,$G$452) -> 7800 | N16: =$C16 -> 0.45 | O16: =$G$433 -> 650 | P16: =$G$430*(1-N16)-O16 -> 1000 | Q16: =$G$432-O16 -> 59350 | R16: =IFERROR(P16/(Q16+$G$430*(1-N16)),0)*(1-$G$434) -> 0.01557377 | Z16: =$O16+$G$435+$N16*$G$431+$R16*($Q16*(1+D$9)+$G$431*(1-$N16))-$G$430 -> 5929.6859 | AA16: =$O16+$G$435+$N16*$G$431+$R16*($Q16*(1+E$9)+$G$431*(1-$N16))-$G$430 -> 6160.7617 | AB16: =$O16+$G$435+$N16*$G$431+$R16*($Q16*(1+F$9)+$G$431*(1-$N16))-$G$430 -> 6391.8375 | AC16: =$O16+$G$435+$N16*$G$431+$R16*($Q16*(1+G$9)+$G$431*(1-$N16))-$G$430 -> 6622.9133 | AD16: =$O16+$G$435+$N16*$G$431+$R16*($Q16*(1+H$9)+$G$431*(1-$N16))-$G$430 -> 6853.9892 | AE16: =$O16+$G$435+$N16*$G$431+$R16*($Q16*(1+I$9)+$G$431*(1-$N16))-$G$430 -> 7085.065 | AF16: =$O16+$G$435+$N16*$G$431+$R16*($Q16*(1+J$9)+$G$431*(1-$N16))-$G$430 -> 7316.1408 | AG16: =$O16+$G$435+$N16*$G$431+$R16*($Q16*(1+K$9)+$G$431*(1-$N16))-$G$430 -> 7547.2166 | AH16: =$O16+$G$435+$N16*$G$431+$R16*($Q16*(1+L$9)+$G$431*(1-$N16))-$G$430 -> 7778.2924 | AT16: =IF(Z56<$G$449,0,MIN($G$446,1+IFERROR(INT((Z56-$G$449)/$G$451),0))) -> 2 | AU16: =IF(AA56<$G$449,0,MIN($G$446,1+IFERROR(INT((AA56-$G$449)/$G$451),0))) -> 3 | AV16: =IF(AB56<$G$449,0,MIN($G$446,1+IFERROR(INT((AB56-$G$449)/$G$451),0))) -> 4 | AW16: =IF(AC56<$G$449,0,MIN($G$446,1+IFERROR(INT((AC56-$G$449)/$G$451),0))) -> 5 | AX16: =IF(AD56<$G$449,0,MIN($G$446,1+IFERROR(INT((AD56-$G$449)/$G$451),0))) -> 6 | AY16: =IF(AE56<$G$449,0,MIN($G$446,1+IFERROR(INT((AE56-$G$449)/$G$451),0))) -> 7 | AZ16: =IF(AF56<$G$449,0,MIN($G$446,1+IFERROR(INT((AF56-$G$449)/$G$451),0))) -> 8 | BA16: =IF(AG56<$G$449,0,MIN($G$446,1+IFERROR(INT((AG56-$G$449)/$G$451),0))) -> 9 | BB16: =IF(AH56<$G$449,0,MIN($G$446,1+IFERROR(INT((AH56-$G$449)/$G$451),0))) -> 10
B17: Ben's Year 5 value (cash at close + earnout + retained Keystone stake + Topkey stock, after dilution) less Keystone value today (G430)
N18: =$G$436 -> 0.3 | O18: =$G$433 -> 650 | P18: =$G$430*(1-N18)-O18 -> 1450 | Q18: =$G$432-O18 -> 59350 | R18: =IFERROR(P18/(Q18+$G$430*(1-N18)),0)*(1-$G$434) -> 0.022416599
B19: Ben's % Return on Keystone Value Based on Topkey Growth & Rollover %
D21: Topkey ex-Keystone Value Growth (%)
D22: =E22-$G$441 -> 1.021904 | E22: =F22-$G$441 -> 1.271904 | F22: =G22-$G$441 -> 1.521904 | G22: =H22-$G$441 -> 1.771904 | H22: =$G$440 -> 2.021904 | I22: =H22+$G$441 -> 2.271904 | J22: =I22+$G$441 -> 2.521904 | K22: =J22+$G$441 -> 2.771904 | L22: =K22+$G$441 -> 3.021904 | AT22: Helper: Gradient Band (0 = below $1M hurdle)
B23: Ben's Rollover % | C23: =C24-$G$439 -> 0.15 | D23: =IFERROR(Z10/$G$430,0) -> 1.1975776 | E23: =IFERROR(AA10/$G$430,0) -> 1.3417978 | F23: =IFERROR(AB10/$G$430,0) -> 1.486018 | G23: =IFERROR(AC10/$G$430,0) -> 1.6302381 | H23: =IFERROR(AD10/$G$430,0) -> 1.7744583 | I23: =IFERROR(AE10/$G$430,0) -> 1.9186785 | J23: =IFERROR(AF10/$G$430,0) -> 2.0628987 | K23: =IFERROR(AG10/$G$430,0) -> 2.2071189 | L23: =IFERROR(AH10/$G$430,0) -> 2.351339 | AT23: =IF(Z50<$G$449,0,MIN($G$446,1+IFERROR(INT((Z50-$G$449)/$G$451),0))) -> 0 | AU23: =IF(AA50<$G$449,0,MIN($G$446,1+IFERROR(INT((AA50-$G$449)/$G$451),0))) -> 0 | AV23: =IF(AB50<$G$449,0,MIN($G$446,1+IFERROR(INT((AB50-$G$449)/$G$451),0))) -> 0 | AW23: =IF(AC50<$G$449,0,MIN($G$446,1+IFERROR(INT((AC50-$G$449)/$G$451),0))) -> 0 | AX23: =IF(AD50<$G$449,0,MIN($G$446,1+IFERROR(INT((AD50-$G$449)/$G$451),0))) -> 0 | AY23: =IF(AE50<$G$449,0,MIN($G$446,1+IFERROR(INT((AE50-$G$449)/$G$451),0))) -> 2 | AZ23: =IF(AF50<$G$449,0,MIN($G$446,1+IFERROR(INT((AF50-$G$449)/$G$451),0))) -> 4 | BA23: =IF(AG50<$G$449,0,MIN($G$446,1+IFERROR(INT((AG50-$G$449)/$G$451),0))) -> 5 | BB23: =IF(AH50<$G$449,0,MIN($G$446,1+IFERROR(INT((AH50-$G$449)/$G$451),0))) -> 7
C24: =C25-$G$439 -> 0.2 | D24: =IFERROR(Z11/$G$430,0) -> 1.3259729 | E24: =IFERROR(AA11/$G$430,0) -> 1.45913 | F24: =IFERROR(AB11/$G$430,0) -> 1.592287 | G24: =IFERROR(AC11/$G$430,0) -> 1.7254441 | H24: =IFERROR(AD11/$G$430,0) -> 1.8586011 | I24: =IFERROR(AE11/$G$430,0) -> 1.9917582 | J24: =IFERROR(AF11/$G$430,0) -> 2.1249152 | K24: =IFERROR(AG11/$G$430,0) -> 2.2580723 | L24: =IFERROR(AH11/$G$430,0) -> 2.3912293 | AT24: =IF(Z51<$G$449,0,MIN($G$446,1+IFERROR(INT((Z51-$G$449)/$G$451),0))) -> 0 | AU24: =IF(AA51<$G$449,0,MIN($G$446,1+IFERROR(INT((AA51-$G$449)/$G$451),0))) -> 0 | AV24: =IF(AB51<$G$449,0,MIN($G$446,1+IFERROR(INT((AB51-$G$449)/$G$451),0))) -> 0 | AW24: =IF(AC51<$G$449,0,MIN($G$446,1+IFERROR(INT((AC51-$G$449)/$G$451),0))) -> 0 | AX24: =IF(AD51<$G$449,0,MIN($G$446,1+IFERROR(INT((AD51-$G$449)/$G$451),0))) -> 1 | AY24: =IF(AE51<$G$449,0,MIN($G$446,1+IFERROR(INT((AE51-$G$449)/$G$451),0))) -> 3 | AZ24: =IF(AF51<$G$449,0,MIN($G$446,1+IFERROR(INT((AF51-$G$449)/$G$451),0))) -> 4 | BA24: =IF(AG51<$G$449,0,MIN($G$446,1+IFERROR(INT((AG51-$G$449)/$G$451),0))) -> 6 | BB24: =IF(AH51<$G$449,0,MIN($G$446,1+IFERROR(INT((AH51-$G$449)/$G$451),0))) -> 8
C25: =C26-$G$439 -> 0.25 | D25: =IFERROR(Z12/$G$430,0) -> 1.4549368 | E25: =IFERROR(AA12/$G$430,0) -> 1.5769769 | F25: =IFERROR(AB12/$G$430,0) -> 1.6990169 | G25: =IFERROR(AC12/$G$430,0) -> 1.821057 | H25: =IFERROR(AD12/$G$430,0) -> 1.943097 | I25: =IFERROR(AE12/$G$430,0) -> 2.0651371 | J25: =IFERROR(AF12/$G$430,0) -> 2.1871771 | K25: =IFERROR(AG12/$G$430,0) -> 2.3092171 | L25: =IFERROR(AH12/$G$430,0) -> 2.4312572 | AT25: =IF(Z52<$G$449,0,MIN($G$446,1+IFERROR(INT((Z52-$G$449)/$G$451),0))) -> 0 | AU25: =IF(AA52<$G$449,0,MIN($G$446,1+IFERROR(INT((AA52-$G$449)/$G$451),0))) -> 0 | AV25: =IF(AB52<$G$449,0,MIN($G$446,1+IFERROR(INT((AB52-$G$449)/$G$451),0))) -> 0 | AW25: =IF(AC52<$G$449,0,MIN($G$446,1+IFERROR(INT((AC52-$G$449)/$G$451),0))) -> 0 | AX25: =IF(AD52<$G$449,0,MIN($G$446,1+IFERROR(INT((AD52-$G$449)/$G$451),0))) -> 2 | AY25: =IF(AE52<$G$449,0,MIN($G$446,1+IFERROR(INT((AE52-$G$449)/$G$451),0))) -> 4 | AZ25: =IF(AF52<$G$449,0,MIN($G$446,1+IFERROR(INT((AF52-$G$449)/$G$451),0))) -> 5 | BA25: =IF(AG52<$G$449,0,MIN($G$446,1+IFERROR(INT((AG52-$G$449)/$G$451),0))) -> 7 | BB25: =IF(AH52<$G$449,0,MIN($G$446,1+IFERROR(INT((AH52-$G$449)/$G$451),0))) -> 8
C26: =$G$438 -> 0.3 | D26: =IFERROR(Z13/$G$430,0) -> 1.5844735 | E26: =IFERROR(AA13/$G$430,0) -> 1.6953422 | F26: =IFERROR(AB13/$G$430,0) -> 1.806211 | G26: =IFERROR(AC13/$G$430,0) -> 1.9170797 | H26: =IFERROR(AD13/$G$430,0) -> 2.0279485 | I26: =IFERROR(AE13/$G$430,0) -> 2.1388173 | J26: =IFERROR(AF13/$G$430,0) -> 2.249686 | K26: =IFERROR(AG13/$G$430,0) -> 2.3605548 | L26: =IFERROR(AH13/$G$430,0) -> 2.4714236 | AT26: =IF(Z53<$G$449,0,MIN($G$446,1+IFERROR(INT((Z53-$G$449)/$G$451),0))) -> 0 | AU26: =IF(AA53<$G$449,0,MIN($G$446,1+IFERROR(INT((AA53-$G$449)/$G$451),0))) -> 0 | AV26: =IF(AB53<$G$449,0,MIN($G$446,1+IFERROR(INT((AB53-$G$449)/$G$451),0))) -> 0 | AW26: =IF(AC53<$G$449,0,MIN($G$446,1+IFERROR(INT((AC53-$G$449)/$G$451),0))) -> 2 | AX26: =IF(AD53<$G$449,0,MIN($G$446,1+IFERROR(INT((AD53-$G$449)/$G$451),0))) -> 3 | AY26: =IF(AE53<$G$449,0,MIN($G$446,1+IFERROR(INT((AE53-$G$449)/$G$451),0))) -> 5 | AZ26: =IF(AF53<$G$449,0,MIN($G$446,1+IFERROR(INT((AF53-$G$449)/$G$451),0))) -> 6 | BA26: =IF(AG53<$G$449,0,MIN($G$446,1+IFERROR(INT((AG53-$G$449)/$G$451),0))) -> 7 | BB26: =IF(AH53<$G$449,0,MIN($G$446,1+IFERROR(INT((AH53-$G$449)/$G$451),0))) -> 9
C27: =C26+$G$439 -> 0.35 | D27: =IFERROR(Z14/$G$430,0) -> 1.714587 | E27: =IFERROR(AA14/$G$430,0) -> 1.8142298 | F27: =IFERROR(AB14/$G$430,0) -> 1.9138726 | G27: =IFERROR(AC14/$G$430,0) -> 2.0135154 | H27: =IFERROR(AD14/$G$430,0) -> 2.1131583 | I27: =IFERROR(AE14/$G$430,0) -> 2.2128011 | J27: =IFERROR(AF14/$G$430,0) -> 2.3124439 | K27: =IFERROR(AG14/$G$430,0) -> 2.4120867 | L27: =IFERROR(AH14/$G$430,0) -> 2.5117295 | AT27: =IF(Z54<$G$449,0,MIN($G$446,1+IFERROR(INT((Z54-$G$449)/$G$451),0))) -> 0 | AU27: =IF(AA54<$G$449,0,MIN($G$446,1+IFERROR(INT((AA54-$G$449)/$G$451),0))) -> 0 | AV27: =IF(AB54<$G$449,0,MIN($G$446,1+IFERROR(INT((AB54-$G$449)/$G$451),0))) -> 2 | AW27: =IF(AC54<$G$449,0,MIN($G$446,1+IFERROR(INT((AC54-$G$449)/$G$451),0))) -> 3 | AX27: =IF(AD54<$G$449,0,MIN($G$446,1+IFERROR(INT((AD54-$G$449)/$G$451),0))) -> 4 | AY27: =IF(AE54<$G$449,0,MIN($G$446,1+IFERROR(INT((AE54-$G$449)/$G$451),0))) -> 6 | AZ27: =IF(AF54<$G$449,0,MIN($G$446,1+IFERROR(INT((AF54-$G$449)/$G$451),0))) -> 7 | BA27: =IF(AG54<$G$449,0,MIN($G$446,1+IFERROR(INT((AG54-$G$449)/$G$451),0))) -> 8 | BB27: =IF(AH54<$G$449,0,MIN($G$446,1+IFERROR(INT((AH54-$G$449)/$G$451),0))) -> 9
C28: =C27+$G$439 -> 0.4 | D28: =IFERROR(Z15/$G$430,0) -> 1.8452818 | E28: =IFERROR(AA15/$G$430,0) -> 1.9336435 | F28: =IFERROR(AB15/$G$430,0) -> 2.0220053 | G28: =IFERROR(AC15/$G$430,0) -> 2.1103671 | H28: =IFERROR(AD15/$G$430,0) -> 2.1987289 | I28: =IFERROR(AE15/$G$430,0) -> 2.2870907 | J28: =IFERROR(AF15/$G$430,0) -> 2.3754524 | K28: =IFERROR(AG15/$G$430,0) -> 2.4638142 | L28: =IFERROR(AH15/$G$430,0) -> 2.552176 | AT28: =IF(Z55<$G$449,0,MIN($G$446,1+IFERROR(INT((Z55-$G$449)/$G$451),0))) -> 1 | AU28: =IF(AA55<$G$449,0,MIN($G$446,1+IFERROR(INT((AA55-$G$449)/$G$451),0))) -> 2 | AV28: =IF(AB55<$G$449,0,MIN($G$446,1+IFERROR(INT((AB55-$G$449)/$G$451),0))) -> 3 | AW28: =IF(AC55<$G$449,0,MIN($G$446,1+IFERROR(INT((AC55-$G$449)/$G$451),0))) -> 4 | AX28: =IF(AD55<$G$449,0,MIN($G$446,1+IFERROR(INT((AD55-$G$449)/$G$451),0))) -> 5 | AY28: =IF(AE55<$G$449,0,MIN($G$446,1+IFERROR(INT((AE55-$G$449)/$G$451),0))) -> 6 | AZ28: =IF(AF55<$G$449,0,MIN($G$446,1+IFERROR(INT((AF55-$G$449)/$G$451),0))) -> 8 | BA28: =IF(AG55<$G$449,0,MIN($G$446,1+IFERROR(INT((AG55-$G$449)/$G$451),0))) -> 9 | BB28: =IF(AH55<$G$449,0,MIN($G$446,1+IFERROR(INT((AH55-$G$449)/$G$451),0))) -> 10
C29: =C28+$G$439 -> 0.45 | D29: =IFERROR(Z16/$G$430,0) -> 1.976562 | E29: =IFERROR(AA16/$G$430,0) -> 2.0535872 | F29: =IFERROR(AB16/$G$430,0) -> 2.1306125 | G29: =IFERROR(AC16/$G$430,0) -> 2.2076378 | H29: =IFERROR(AD16/$G$430,0) -> 2.2846631 | I29: =IFERROR(AE16/$G$430,0) -> 2.3616883 | J29: =IFERROR(AF16/$G$430,0) -> 2.4387136 | K29: =IFERROR(AG16/$G$430,0) -> 2.5157389 | L29: =IFERROR(AH16/$G$430,0) -> 2.5927641 | AT29: =IF(Z56<$G$449,0,MIN($G$446,1+IFERROR(INT((Z56-$G$449)/$G$451),0))) -> 2 | AU29: =IF(AA56<$G$449,0,MIN($G$446,1+IFERROR(INT((AA56-$G$449)/$G$451),0))) -> 3 | AV29: =IF(AB56<$G$449,0,MIN($G$446,1+IFERROR(INT((AB56-$G$449)/$G$451),0))) -> 4 | AW29: =IF(AC56<$G$449,0,MIN($G$446,1+IFERROR(INT((AC56-$G$449)/$G$451),0))) -> 5 | AX29: =IF(AD56<$G$449,0,MIN($G$446,1+IFERROR(INT((AD56-$G$449)/$G$451),0))) -> 6 | AY29: =IF(AE56<$G$449,0,MIN($G$446,1+IFERROR(INT((AE56-$G$449)/$G$451),0))) -> 7 | AZ29: =IF(AF56<$G$449,0,MIN($G$446,1+IFERROR(INT((AF56-$G$449)/$G$451),0))) -> 8 | BA29: =IF(AG56<$G$449,0,MIN($G$446,1+IFERROR(INT((AG56-$G$449)/$G$451),0))) -> 9 | BB29: =IF(AH56<$G$449,0,MIN($G$446,1+IFERROR(INT((AH56-$G$449)/$G$451),0))) -> 10
B30: Ben's Year 5 total value ÷ Keystone value today (G430), less 1
B32: Ben's IRR Based on Topkey Growth & Rollover %
D34: Topkey ex-Keystone Value Growth (%) | BD34: Helper: IRR CF — Col D | BJ34: Helper: IRR CF — Col E | BP34: Helper: IRR CF — Col F | BV34: Helper: IRR CF — Col G | CB34: Helper: IRR CF — Col H | CH34: Helper: IRR CF — Col I | CN34: Helper: IRR CF — Col J | CT34: Helper: IRR CF — Col K | CZ34: Helper: IRR CF — Col L
D35: =E35-$G$441 -> 1.021904 | E35: =F35-$G$441 -> 1.271904 | F35: =G35-$G$441 -> 1.521904 | G35: =H35-$G$441 -> 1.771904 | H35: =$G$440 -> 2.021904 | I35: =H35+$G$441 -> 2.271904 | J35: =I35+$G$441 -> 2.521904 | K35: =J35+$G$441 -> 2.771904 | L35: =K35+$G$441 -> 3.021904 | AT35: Helper: Gradient Band (0 = below $1M hurdle) | BD35: =$S$9 -> 0 | BE35: =$T$9 -> 1 | BF35: =$U$9 -> 2 | BG35: =$V$9 -> 3 | BH35: =$W$9 -> 4 | BI35: =$X$9 -> 5 | BJ35: =$S$9 -> 0 | BK35: =$T$9 -> 1 | BL35: =$U$9 -> 2 | BM35: =$V$9 -> 3 | BN35: =$W$9 -> 4 | BO35: =$X$9 -> 5 | BP35: =$S$9 -> 0 | BQ35: =$T$9 -> 1 | BR35: =$U$9 -> 2 | BS35: =$V$9 -> 3 | BT35: =$W$9 -> 4 | BU35: =$X$9 -> 5 | BV35: =$S$9 -> 0 | BW35: =$T$9 -> 1 | BX35: =$U$9 -> 2 | BY35: =$V$9 -> 3 | BZ35: =$W$9 -> 4 | CA35: =$X$9 -> 5 | CB35: =$S$9 -> 0 | CC35: =$T$9 -> 1 | CD35: =$U$9 -> 2 | CE35: =$V$9 -> 3 | CF35: =$W$9 -> 4 | CG35: =$X$9 -> 5 | CH35: =$S$9 -> 0 | CI35: =$T$9 -> 1 | CJ35: =$U$9 -> 2 | CK35: =$V$9 -> 3 | CL35: =$W$9 -> 4 | CM35: =$X$9 -> 5 | CN35: =$S$9 -> 0 | CO35: =$T$9 -> 1 | CP35: =$U$9 -> 2 | CQ35: =$V$9 -> 3 | CR35: =$W$9 -> 4 | CS35: =$X$9 -> 5 | CT35: =$S$9 -> 0 | CU35: =$T$9 -> 1 | CV35: =$U$9 -> 2 | CW35: =$V$9 -> 3 | CX35: =$W$9 -> 4 | CY35: =$X$9 -> 5 | CZ35: =$S$9 -> 0 | DA35: =$T$9 -> 1 | DB35: =$U$9 -> 2 | DC35: =$V$9 -> 3 | DD35: =$W$9 -> 4 | DE35: =$X$9 -> 5
B36: Ben's Rollover % | C36: =C37-$G$439 -> 0.15 | D36: =IFERROR(IRR(BD36:BI36),0) -> 0.2038813 | E36: =IFERROR(IRR(BJ36:BO36),0) -> 0.22092173 | F36: =IFERROR(IRR(BP36:BU36),0) -> 0.23706074 | G36: =IFERROR(IRR(BV36:CA36),0) -> 0.252399 | H36: =IFERROR(IRR(CB36:CG36),0) -> 0.2670207 | I36: =IFERROR(IRR(CH36:CM36),0) -> 0.28099705 | J36: =IFERROR(IRR(CN36:CS36),0) -> 0.29438878 | K36: =IFERROR(IRR(CT36:CY36),0) -> 0.3072482 | L36: =IFERROR(IRR(CZ36:DE36),0) -> 0.31962067 | AT36: =IF(Z50<$G$449,0,MIN($G$446,1+IFERROR(INT((Z50-$G$449)/$G$451),0))) -> 0 | AU36: =IF(AA50<$G$449,0,MIN($G$446,1+IFERROR(INT((AA50-$G$449)/$G$451),0))) -> 0 | AV36: =IF(AB50<$G$449,0,MIN($G$446,1+IFERROR(INT((AB50-$G$449)/$G$451),0))) -> 0 | AW36: =IF(AC50<$G$449,0,MIN($G$446,1+IFERROR(INT((AC50-$G$449)/$G$451),0))) -> 0 | AX36: =IF(AD50<$G$449,0,MIN($G$446,1+IFERROR(INT((AD50-$G$449)/$G$451),0))) -> 0 | AY36: =IF(AE50<$G$449,0,MIN($G$446,1+IFERROR(INT((AE50-$G$449)/$G$451),0))) -> 2 | AZ36: =IF(AF50<$G$449,0,MIN($G$446,1+IFERROR(INT((AF50-$G$449)/$G$451),0))) -> 4 | BA36: =IF(AG50<$G$449,0,MIN($G$446,1+IFERROR(INT((AG50-$G$449)/$G$451),0))) -> 5 | BB36: =IF(AH50<$G$449,0,MIN($G$446,1+IFERROR(INT((AH50-$G$449)/$G$451),0))) -> 7 | BD36: =(BD$35=0)*($O10-$G$430)+(BD$35=$G$444)*$G$435+(BD$35=$G$445)*(Z10+$G$430-$O10-$G$435) -> -2350 | BE36: =(BE$35=0)*($O10-$G$430)+(BE$35=$G$444)*$G$435+(BE$35=$G$445)*(Z10+$G$430-$O10-$G$435) -> 0 | BF36: =(BF$35=0)*($O10-$G$430)+(BF$35=$G$444)*$G$435+(BF$35=$G$445)*(Z10+$G$430-$O10-$G$435) -> 0 | BG36: =(BG$35=0)*($O10-$G$430)+(BG$35=$G$444)*$G$435+(BG$35=$G$445)*(Z10+$G$430-$O10-$G$435) -> 0 | BH36: =(BH$35=0)*($O10-$G$430)+(BH$35=$G$444)*$G$435+(BH$35=$G$445)*(Z10+$G$430-$O10-$G$435) -> 0 | BI36: =(BI$35=0)*($O10-$G$430)+(BI$35=$G$444)*$G$435+(BI$35=$G$445)*(Z10+$G$430-$O10-$G$435) -> 5942.7328 | BJ36: =(BJ$35=0)*($O10-$G$430)+(BJ$35=$G$444)*$G$435+(BJ$35=$G$445)*(AA10+$G$430-$O10-$G$435) -> -2350 | BK36: =(BK$35=0)*($O10-$G$430)+(BK$35=$G$444)*$G$435+(BK$35=$G$445)*(AA10+$G$430-$O10-$G$435) -> 0 | BL36: =(BL$35=0)*($O10-$G$430)+(BL$35=$G$444)*$G$435+(BL$35=$G$445)*(AA10+$G$430-$O10-$G$435) -> 0 | BM36: =(BM$35=0)*($O10-$G$430)+(BM$35=$G$444)*$G$435+(BM$35=$G$445)*(AA10+$G$430-$O10-$G$435) -> 0 | BN36: =(BN$35=0)*($O10-$G$430)+(BN$35=$G$444)*$G$435+(BN$35=$G$445)*(AA10+$G$430-$O10-$G$435) -> 0 | BO36: =(BO$35=0)*($O10-$G$430)+(BO$35=$G$444)*$G$435+(BO$35=$G$445)*(AA10+$G$430-$O10-$G$435) -> 6375.3933 | BP36: =(BP$35=0)*($O10-$G$430)+(BP$35=$G$444)*$G$435+(BP$35=$G$445)*(AB10+$G$430-$O10-$G$435) -> -2350 | BQ36: =(BQ$35=0)*($O10-$G$430)+(BQ$35=$G$444)*$G$435+(BQ$35=$G$445)*(AB10+$G$430-$O10-$G$435) -> 0 | BR36: =(BR$35=0)*($O10-$G$430)+(BR$35=$G$444)*$G$435+(BR$35=$G$445)*(AB10+$G$430-$O10-$G$435) -> 0 | BS36: =(BS$35=0)*($O10-$G$430)+(BS$35=$G$444)*$G$435+(BS$35=$G$445)*(AB10+$G$430-$O10-$G$435) -> 0 | BT36: =(BT$35=0)*($O10-$G$430)+(BT$35=$G$444)*$G$435+(BT$35=$G$445)*(AB10+$G$430-$O10-$G$435) -> 0 | BU36: =(BU$35=0)*($O10-$G$430)+(BU$35=$G$444)*$G$435+(BU$35=$G$445)*(AB10+$G$430-$O10-$G$435) -> 6808.0539 | BV36: =(BV$35=0)*($O10-$G$430)+(BV$35=$G$444)*$G$435+(BV$35=$G$445)*(AC10+$G$430-$O10-$G$435) -> -2350 | BW36: =(BW$35=0)*($O10-$G$430)+(BW$35=$G$444)*$G$435+(BW$35=$G$445)*(AC10+$G$430-$O10-$G$435) -> 0 | BX36: =(BX$35=0)*($O10-$G$430)+(BX$35=$G$444)*$G$435+(BX$35=$G$445)*(AC10+$G$430-$O10-$G$435) -> 0 | BY36: =(BY$35=0)*($O10-$G$430)+(BY$35=$G$444)*$G$435+(BY$35=$G$445)*(AC10+$G$430-$O10-$G$435) -> 0 | BZ36: =(BZ$35=0)*($O10-$G$430)+(BZ$35=$G$444)*$G$435+(BZ$35=$G$445)*(AC10+$G$430-$O10-$G$435) -> 0 | CA36: =(CA$35=0)*($O10-$G$430)+(CA$35=$G$444)*$G$435+(CA$35=$G$445)*(AC10+$G$430-$O10-$G$435) -> 7240.7144 | CB36: =(CB$35=0)*($O10-$G$430)+(CB$35=$G$444)*$G$435+(CB$35=$G$445)*(AD10+$G$430-$O10-$G$435) -> -2350 | CC36: =(CC$35=0)*($O10-$G$430)+(CC$35=$G$444)*$G$435+(CC$35=$G$445)*(AD10+$G$430-$O10-$G$435) -> 0 | CD36: =(CD$35=0)*($O10-$G$430)+(CD$35=$G$444)*$G$435+(CD$35=$G$445)*(AD10+$G$430-$O10-$G$435) -> 0 | CE36: =(CE$35=0)*($O10-$G$430)+(CE$35=$G$444)*$G$435+(CE$35=$G$445)*(AD10+$G$430-$O10-$G$435) -> 0 | CF36: =(CF$35=0)*($O10-$G$430)+(CF$35=$G$444)*$G$435+(CF$35=$G$445)*(AD10+$G$430-$O10-$G$435) -> 0 | CG36: =(CG$35=0)*($O10-$G$430)+(CG$35=$G$444)*$G$435+(CG$35=$G$445)*(AD10+$G$430-$O10-$G$435) -> 7673.375 | CH36: =(CH$35=0)*($O10-$G$430)+(CH$35=$G$444)*$G$435+(CH$35=$G$445)*(AE10+$G$430-$O10-$G$435) -> -2350 | CI36: =(CI$35=0)*($O10-$G$430)+(CI$35=$G$444)*$G$435+(CI$35=$G$445)*(AE10+$G$430-$O10-$G$435) -> 0 | CJ36: =(CJ$35=0)*($O10-$G$430)+(CJ$35=$G$444)*$G$435+(CJ$35=$G$445)*(AE10+$G$430-$O10-$G$435) -> 0 | CK36: =(CK$35=0)*($O10-$G$430)+(CK$35=$G$444)*$G$435+(CK$35=$G$445)*(AE10+$G$430-$O10-$G$435) -> 0 | CL36: =(CL$35=0)*($O10-$G$430)+(CL$35=$G$444)*$G$435+(CL$35=$G$445)*(AE10+$G$430-$O10-$G$435) -> 0 | CM36: =(CM$35=0)*($O10-$G$430)+(CM$35=$G$444)*$G$435+(CM$35=$G$445)*(AE10+$G$430-$O10-$G$435) -> 8106.0355 | CN36: =(CN$35=0)*($O10-$G$430)+(CN$35=$G$444)*$G$435+(CN$35=$G$445)*(AF10+$G$430-$O10-$G$435) -> -2350 | CO36: =(CO$35=0)*($O10-$G$430)+(CO$35=$G$444)*$G$435+(CO$35=$G$445)*(AF10+$G$430-$O10-$G$435) -> 0 | CP36: =(CP$35=0)*($O10-$G$430)+(CP$35=$G$444)*$G$435+(CP$35=$G$445)*(AF10+$G$430-$O10-$G$435) -> 0 | CQ36: =(CQ$35=0)*($O10-$G$430)+(CQ$35=$G$444)*$G$435+(CQ$35=$G$445)*(AF10+$G$430-$O10-$G$435) -> 0 | CR36: =(CR$35=0)*($O10-$G$430)+(CR$35=$G$444)*$G$435+(CR$35=$G$445)*(AF10+$G$430-$O10-$G$435) -> 0 | CS36: =(CS$35=0)*($O10-$G$430)+(CS$35=$G$444)*$G$435+(CS$35=$G$445)*(AF10+$G$430-$O10-$G$435) -> 8538.6961 | CT36: =(CT$35=0)*($O10-$G$430)+(CT$35=$G$444)*$G$435+(CT$35=$G$445)*(AG10+$G$430-$O10-$G$435) -> -2350 | CU36: =(CU$35=0)*($O10-$G$430)+(CU$35=$G$444)*$G$435+(CU$35=$G$445)*(AG10+$G$430-$O10-$G$435) -> 0 | CV36: =(CV$35=0)*($O10-$G$430)+(CV$35=$G$444)*$G$435+(CV$35=$G$445)*(AG10+$G$430-$O10-$G$435) -> 0 | CW36: =(CW$35=0)*($O10-$G$430)+(CW$35=$G$444)*$G$435+(CW$35=$G$445)*(AG10+$G$430-$O10-$G$435) -> 0 | CX36: =(CX$35=0)*($O10-$G$430)+(CX$35=$G$444)*$G$435+(CX$35=$G$445)*(AG10+$G$430-$O10-$G$435) -> 0 | CY36: =(CY$35=0)*($O10-$G$430)+(CY$35=$G$444)*$G$435+(CY$35=$G$445)*(AG10+$G$430-$O10-$G$435) -> 8971.3566 | CZ36: =(CZ$35=0)*($O10-$G$430)+(CZ$35=$G$444)*$G$435+(CZ$35=$G$445)*(AH10+$G$430-$O10-$G$435) -> -2350 | DA36: =(DA$35=0)*($O10-$G$430)+(DA$35=$G$444)*$G$435+(DA$35=$G$445)*(AH10+$G$430-$O10-$G$435) -> 0 | DB36: =(DB$35=0)*($O10-$G$430)+(DB$35=$G$444)*$G$435+(DB$35=$G$445)*(AH10+$G$430-$O10-$G$435) -> 0 | DC36: =(DC$35=0)*($O10-$G$430)+(DC$35=$G$444)*$G$435+(DC$35=$G$445)*(AH10+$G$430-$O10-$G$435) -> 0 | DD36: =(DD$35=0)*($O10-$G$430)+(DD$35=$G$444)*$G$435+(DD$35=$G$445)*(AH10+$G$430-$O10-$G$435) -> 0 | DE36: =(DE$35=0)*($O10-$G$430)+(DE$35=$G$444)*$G$435+(DE$35=$G$445)*(AH10+$G$430-$O10-$G$435) -> 9404.0171
C37: =C38-$G$439 -> 0.2 | D37: =IFERROR(IRR(BD37:BI37),0) -> 0.21909797 | E37: =IFERROR(IRR(BJ37:BO37),0) -> 0.23411533 | F37: =IFERROR(IRR(BP37:BU37),0) -> 0.24843543 | G37: =IFERROR(IRR(BV37:CA37),0) -> 0.26212714 | H37: =IFERROR(IRR(CB37:CG37),0) -> 0.27524928 | I37: =IFERROR(IRR(CH37:CM37),0) -> 0.28785255 | J37: =IFERROR(IRR(CN37:CS37),0) -> 0.29998094 | K37: =IFERROR(IRR(CT37:CY37),0) -> 0.31167291 | L37: =IFERROR(IRR(CZ37:DE37),0) -> 0.32296227 | AT37: =IF(Z51<$G$449,0,MIN($G$446,1+IFERROR(INT((Z51-$G$449)/$G$451),0))) -> 0 | AU37: =IF(AA51<$G$449,0,MIN($G$446,1+IFERROR(INT((AA51-$G$449)/$G$451),0))) -> 0 | AV37: =IF(AB51<$G$449,0,MIN($G$446,1+IFERROR(INT((AB51-$G$449)/$G$451),0))) -> 0 | AW37: =IF(AC51<$G$449,0,MIN($G$446,1+IFERROR(INT((AC51-$G$449)/$G$451),0))) -> 0 | AX37: =IF(AD51<$G$449,0,MIN($G$446,1+IFERROR(INT((AD51-$G$449)/$G$451),0))) -> 1 | AY37: =IF(AE51<$G$449,0,MIN($G$446,1+IFERROR(INT((AE51-$G$449)/$G$451),0))) -> 3 | AZ37: =IF(AF51<$G$449,0,MIN($G$446,1+IFERROR(INT((AF51-$G$449)/$G$451),0))) -> 4 | BA37: =IF(AG51<$G$449,0,MIN($G$446,1+IFERROR(INT((AG51-$G$449)/$G$451),0))) -> 6 | BB37: =IF(AH51<$G$449,0,MIN($G$446,1+IFERROR(INT((AH51-$G$449)/$G$451),0))) -> 8 | BD37: =(BD$35=0)*($O11-$G$430)+(BD$35=$G$444)*$G$435+(BD$35=$G$445)*(Z11+$G$430-$O11-$G$435) -> -2350 | BE37: =(BE$35=0)*($O11-$G$430)+(BE$35=$G$444)*$G$435+(BE$35=$G$445)*(Z11+$G$430-$O11-$G$435) -> 0 | BF37: =(BF$35=0)*($O11-$G$430)+(BF$35=$G$444)*$G$435+(BF$35=$G$445)*(Z11+$G$430-$O11-$G$435) -> 0 | BG37: =(BG$35=0)*($O11-$G$430)+(BG$35=$G$444)*$G$435+(BG$35=$G$445)*(Z11+$G$430-$O11-$G$435) -> 0 | BH37: =(BH$35=0)*($O11-$G$430)+(BH$35=$G$444)*$G$435+(BH$35=$G$445)*(Z11+$G$430-$O11-$G$435) -> 0 | BI37: =(BI$35=0)*($O11-$G$430)+(BI$35=$G$444)*$G$435+(BI$35=$G$445)*(Z11+$G$430-$O11-$G$435) -> 6327.9188 | BJ37: =(BJ$35=0)*($O11-$G$430)+(BJ$35=$G$444)*$G$435+(BJ$35=$G$445)*(AA11+$G$430-$O11-$G$435) -> -2350 | BK37: =(BK$35=0)*($O11-$G$430)+(BK$35=$G$444)*$G$435+(BK$35=$G$445)*(AA11+$G$430-$O11-$G$435) -> 0 | BL37: =(BL$35=0)*($O11-$G$430)+(BL$35=$G$444)*$G$435+(BL$35=$G$445)*(AA11+$G$430-$O11-$G$435) -> 0 | BM37: =(BM$35=0)*($O11-$G$430)+(BM$35=$G$444)*$G$435+(BM$35=$G$445)*(AA11+$G$430-$O11-$G$435) -> 0 | BN37: =(BN$35=0)*($O11-$G$430)+(BN$35=$G$444)*$G$435+(BN$35=$G$445)*(AA11+$G$430-$O11-$G$435) -> 0 | BO37: =(BO$35=0)*($O11-$G$430)+(BO$35=$G$444)*$G$435+(BO$35=$G$445)*(AA11+$G$430-$O11-$G$435) -> 6727.39 | BP37: =(BP$35=0)*($O11-$G$430)+(BP$35=$G$444)*$G$435+(BP$35=$G$445)*(AB11+$G$430-$O11-$G$435) -> -2350 | BQ37: =(BQ$35=0)*($O11-$G$430)+(BQ$35=$G$444)*$G$435+(BQ$35=$G$445)*(AB11+$G$430-$O11-$G$435) -> 0 | BR37: =(BR$35=0)*($O11-$G$430)+(BR$35=$G$444)*$G$435+(BR$35=$G$445)*(AB11+$G$430-$O11-$G$435) -> 0 | BS37: =(BS$35=0)*($O11-$G$430)+(BS$35=$G$444)*$G$435+(BS$35=$G$445)*(AB11+$G$430-$O11-$G$435) -> 0 | BT37: =(BT$35=0)*($O11-$G$430)+(BT$35=$G$444)*$G$435+(BT$35=$G$445)*(AB11+$G$430-$O11-$G$435) -> 0 | BU37: =(BU$35=0)*($O11-$G$430)+(BU$35=$G$444)*$G$435+(BU$35=$G$445)*(AB11+$G$430-$O11-$G$435) -> 7126.8611 | BV37: =(BV$35=0)*($O11-$G$430)+(BV$35=$G$444)*$G$435+(BV$35=$G$445)*(AC11+$G$430-$O11-$G$435) -> -2350 | BW37: =(BW$35=0)*($O11-$G$430)+(BW$35=$G$444)*$G$435+(BW$35=$G$445)*(AC11+$G$430-$O11-$G$435) -> 0 | BX37: =(BX$35=0)*($O11-$G$430)+(BX$35=$G$444)*$G$435+(BX$35=$G$445)*(AC11+$G$430-$O11-$G$435) -> 0 | BY37: =(BY$35=0)*($O11-$G$430)+(BY$35=$G$444)*$G$435+(BY$35=$G$445)*(AC11+$G$430-$O11-$G$435) -> 0 | BZ37: =(BZ$35=0)*($O11-$G$430)+(BZ$35=$G$444)*$G$435+(BZ$35=$G$445)*(AC11+$G$430-$O11-$G$435) -> 0 | CA37: =(CA$35=0)*($O11-$G$430)+(CA$35=$G$444)*$G$435+(CA$35=$G$445)*(AC11+$G$430-$O11-$G$435) -> 7526.3323 | CB37: =(CB$35=0)*($O11-$G$430)+(CB$35=$G$444)*$G$435+(CB$35=$G$445)*(AD11+$G$430-$O11-$G$435) -> -2350 | CC37: =(CC$35=0)*($O11-$G$430)+(CC$35=$G$444)*$G$435+(CC$35=$G$445)*(AD11+$G$430-$O11-$G$435) -> 0 | CD37: =(CD$35=0)*($O11-$G$430)+(CD$35=$G$444)*$G$435+(CD$35=$G$445)*(AD11+$G$430-$O11-$G$435) -> 0 | CE37: =(CE$35=0)*($O11-$G$430)+(CE$35=$G$444)*$G$435+(CE$35=$G$445)*(AD11+$G$430-$O11-$G$435) -> 0 | CF37: =(CF$35=0)*($O11-$G$430)+(CF$35=$G$444)*$G$435+(CF$35=$G$445)*(AD11+$G$430-$O11-$G$435) -> 0 | CG37: =(CG$35=0)*($O11-$G$430)+(CG$35=$G$444)*$G$435+(CG$35=$G$445)*(AD11+$G$430-$O11-$G$435) -> 7925.8034 | CH37: =(CH$35=0)*($O11-$G$430)+(CH$35=$G$444)*$G$435+(CH$35=$G$445)*(AE11+$G$430-$O11-$G$435) -> -2350 | CI37: =(CI$35=0)*($O11-$G$430)+(CI$35=$G$444)*$G$435+(CI$35=$G$445)*(AE11+$G$430-$O11-$G$435) -> 0 | CJ37: =(CJ$35=0)*($O11-$G$430)+(CJ$35=$G$444)*$G$435+(CJ$35=$G$445)*(AE11+$G$430-$O11-$G$435) -> 0 | CK37: =(CK$35=0)*($O11-$G$430)+(CK$35=$G$444)*$G$435+(CK$35=$G$445)*(AE11+$G$430-$O11-$G$435) -> 0 | CL37: =(CL$35=0)*($O11-$G$430)+(CL$35=$G$444)*$G$435+(CL$35=$G$445)*(AE11+$G$430-$O11-$G$435) -> 0 | CM37: =(CM$35=0)*($O11-$G$430)+(CM$35=$G$444)*$G$435+(CM$35=$G$445)*(AE11+$G$430-$O11-$G$435) -> 8325.2746 | CN37: =(CN$35=0)*($O11-$G$430)+(CN$35=$G$444)*$G$435+(CN$35=$G$445)*(AF11+$G$430-$O11-$G$435) -> -2350 | CO37: =(CO$35=0)*($O11-$G$430)+(CO$35=$G$444)*$G$435+(CO$35=$G$445)*(AF11+$G$430-$O11-$G$435) -> 0 | CP37: =(CP$35=0)*($O11-$G$430)+(CP$35=$G$444)*$G$435+(CP$35=$G$445)*(AF11+$G$430-$O11-$G$435) -> 0 | CQ37: =(CQ$35=0)*($O11-$G$430)+(CQ$35=$G$444)*$G$435+(CQ$35=$G$445)*(AF11+$G$430-$O11-$G$435) -> 0 | CR37: =(CR$35=0)*($O11-$G$430)+(CR$35=$G$444)*$G$435+(CR$35=$G$445)*(AF11+$G$430-$O11-$G$435) -> 0 | CS37: =(CS$35=0)*($O11-$G$430)+(CS$35=$G$444)*$G$435+(CS$35=$G$445)*(AF11+$G$430-$O11-$G$435) -> 8724.7457 | CT37: =(CT$35=0)*($O11-$G$430)+(CT$35=$G$444)*$G$435+(CT$35=$G$445)*(AG11+$G$430-$O11-$G$435) -> -2350 | CU37: =(CU$35=0)*($O11-$G$430)+(CU$35=$G$444)*$G$435+(CU$35=$G$445)*(AG11+$G$430-$O11-$G$435) -> 0 | CV37: =(CV$35=0)*($O11-$G$430)+(CV$35=$G$444)*$G$435+(CV$35=$G$445)*(AG11+$G$430-$O11-$G$435) -> 0 | CW37: =(CW$35=0)*($O11-$G$430)+(CW$35=$G$444)*$G$435+(CW$35=$G$445)*(AG11+$G$430-$O11-$G$435) -> 0 | CX37: =(CX$35=0)*($O11-$G$430)+(CX$35=$G$444)*$G$435+(CX$35=$G$445)*(AG11+$G$430-$O11-$G$435) -> 0 | CY37: =(CY$35=0)*($O11-$G$430)+(CY$35=$G$444)*$G$435+(CY$35=$G$445)*(AG11+$G$430-$O11-$G$435) -> 9124.2169 | CZ37: =(CZ$35=0)*($O11-$G$430)+(CZ$35=$G$444)*$G$435+(CZ$35=$G$445)*(AH11+$G$430-$O11-$G$435) -> -2350 | DA37: =(DA$35=0)*($O11-$G$430)+(DA$35=$G$444)*$G$435+(DA$35=$G$445)*(AH11+$G$430-$O11-$G$435) -> 0 | DB37: =(DB$35=0)*($O11-$G$430)+(DB$35=$G$444)*$G$435+(DB$35=$G$445)*(AH11+$G$430-$O11-$G$435) -> 0 | DC37: =(DC$35=0)*($O11-$G$430)+(DC$35=$G$444)*$G$435+(DC$35=$G$445)*(AH11+$G$430-$O11-$G$435) -> 0 | DD37: =(DD$35=0)*($O11-$G$430)+(DD$35=$G$444)*$G$435+(DD$35=$G$445)*(AH11+$G$430-$O11-$G$435) -> 0 | DE37: =(DE$35=0)*($O11-$G$430)+(DE$35=$G$444)*$G$435+(DE$35=$G$445)*(AH11+$G$430-$O11-$G$435) -> 9523.688
C38: =C39-$G$439 -> 0.25 | D38: =IFERROR(IRR(BD38:BI38),0) -> 0.23365346 | E38: =IFERROR(IRR(BJ38:BO38),0) -> 0.24682211 | F38: =IFERROR(IRR(BP38:BU38),0) -> 0.25945684 | G38: =IFERROR(IRR(BV38:CA38),0) -> 0.27160402 | H38: =IFERROR(IRR(CB38:CG38),0) -> 0.28330403 | I38: =IFERROR(IRR(CH38:CM38),0) -> 0.2945923 | J38: =IFERROR(IRR(CN38:CS38),0) -> 0.30550006 | K38: =IFERROR(IRR(CT38:CY38),0) -> 0.31605499 | L38: =IFERROR(IRR(CZ38:DE38),0) -> 0.3262818 | AT38: =IF(Z52<$G$449,0,MIN($G$446,1+IFERROR(INT((Z52-$G$449)/$G$451),0))) -> 0 | AU38: =IF(AA52<$G$449,0,MIN($G$446,1+IFERROR(INT((AA52-$G$449)/$G$451),0))) -> 0 | AV38: =IF(AB52<$G$449,0,MIN($G$446,1+IFERROR(INT((AB52-$G$449)/$G$451),0))) -> 0 | AW38: =IF(AC52<$G$449,0,MIN($G$446,1+IFERROR(INT((AC52-$G$449)/$G$451),0))) -> 0 | AX38: =IF(AD52<$G$449,0,MIN($G$446,1+IFERROR(INT((AD52-$G$449)/$G$451),0))) -> 2 | AY38: =IF(AE52<$G$449,0,MIN($G$446,1+IFERROR(INT((AE52-$G$449)/$G$451),0))) -> 4 | AZ38: =IF(AF52<$G$449,0,MIN($G$446,1+IFERROR(INT((AF52-$G$449)/$G$451),0))) -> 5 | BA38: =IF(AG52<$G$449,0,MIN($G$446,1+IFERROR(INT((AG52-$G$449)/$G$451),0))) -> 7 | BB38: =IF(AH52<$G$449,0,MIN($G$446,1+IFERROR(INT((AH52-$G$449)/$G$451),0))) -> 8 | BD38: =(BD$35=0)*($O12-$G$430)+(BD$35=$G$444)*$G$435+(BD$35=$G$445)*(Z12+$G$430-$O12-$G$435) -> -2350 | BE38: =(BE$35=0)*($O12-$G$430)+(BE$35=$G$444)*$G$435+(BE$35=$G$445)*(Z12+$G$430-$O12-$G$435) -> 0 | BF38: =(BF$35=0)*($O12-$G$430)+(BF$35=$G$444)*$G$435+(BF$35=$G$445)*(Z12+$G$430-$O12-$G$435) -> 0 | BG38: =(BG$35=0)*($O12-$G$430)+(BG$35=$G$444)*$G$435+(BG$35=$G$445)*(Z12+$G$430-$O12-$G$435) -> 0 | BH38: =(BH$35=0)*($O12-$G$430)+(BH$35=$G$444)*$G$435+(BH$35=$G$445)*(Z12+$G$430-$O12-$G$435) -> 0 | BI38: =(BI$35=0)*($O12-$G$430)+(BI$35=$G$444)*$G$435+(BI$35=$G$445)*(Z12+$G$430-$O12-$G$435) -> 6714.8105 | BJ38: =(BJ$35=0)*($O12-$G$430)+(BJ$35=$G$444)*$G$435+(BJ$35=$G$445)*(AA12+$G$430-$O12-$G$435) -> -2350 | BK38: =(BK$35=0)*($O12-$G$430)+(BK$35=$G$444)*$G$435+(BK$35=$G$445)*(AA12+$G$430-$O12-$G$435) -> 0 | BL38: =(BL$35=0)*($O12-$G$430)+(BL$35=$G$444)*$G$435+(BL$35=$G$445)*(AA12+$G$430-$O12-$G$435) -> 0 | BM38: =(BM$35=0)*($O12-$G$430)+(BM$35=$G$444)*$G$435+(BM$35=$G$445)*(AA12+$G$430-$O12-$G$435) -> 0 | BN38: =(BN$35=0)*($O12-$G$430)+(BN$35=$G$444)*$G$435+(BN$35=$G$445)*(AA12+$G$430-$O12-$G$435) -> 0 | BO38: =(BO$35=0)*($O12-$G$430)+(BO$35=$G$444)*$G$435+(BO$35=$G$445)*(AA12+$G$430-$O12-$G$435) -> 7080.9306 | BP38: =(BP$35=0)*($O12-$G$430)+(BP$35=$G$444)*$G$435+(BP$35=$G$445)*(AB12+$G$430-$O12-$G$435) -> -2350 | BQ38: =(BQ$35=0)*($O12-$G$430)+(BQ$35=$G$444)*$G$435+(BQ$35=$G$445)*(AB12+$G$430-$O12-$G$435) -> 0 | BR38: =(BR$35=0)*($O12-$G$430)+(BR$35=$G$444)*$G$435+(BR$35=$G$445)*(AB12+$G$430-$O12-$G$435) -> 0 | BS38: =(BS$35=0)*($O12-$G$430)+(BS$35=$G$444)*$G$435+(BS$35=$G$445)*(AB12+$G$430-$O12-$G$435) -> 0 | BT38: =(BT$35=0)*($O12-$G$430)+(BT$35=$G$444)*$G$435+(BT$35=$G$445)*(AB12+$G$430-$O12-$G$435) -> 0 | BU38: =(BU$35=0)*($O12-$G$430)+(BU$35=$G$444)*$G$435+(BU$35=$G$445)*(AB12+$G$430-$O12-$G$435) -> 7447.0508 | BV38: =(BV$35=0)*($O12-$G$430)+(BV$35=$G$444)*$G$435+(BV$35=$G$445)*(AC12+$G$430-$O12-$G$435) -> -2350 | BW38: =(BW$35=0)*($O12-$G$430)+(BW$35=$G$444)*$G$435+(BW$35=$G$445)*(AC12+$G$430-$O12-$G$435) -> 0 | BX38: =(BX$35=0)*($O12-$G$430)+(BX$35=$G$444)*$G$435+(BX$35=$G$445)*(AC12+$G$430-$O12-$G$435) -> 0 | BY38: =(BY$35=0)*($O12-$G$430)+(BY$35=$G$444)*$G$435+(BY$35=$G$445)*(AC12+$G$430-$O12-$G$435) -> 0 | BZ38: =(BZ$35=0)*($O12-$G$430)+(BZ$35=$G$444)*$G$435+(BZ$35=$G$445)*(AC12+$G$430-$O12-$G$435) -> 0 | CA38: =(CA$35=0)*($O12-$G$430)+(CA$35=$G$444)*$G$435+(CA$35=$G$445)*(AC12+$G$430-$O12-$G$435) -> 7813.1709 | CB38: =(CB$35=0)*($O12-$G$430)+(CB$35=$G$444)*$G$435+(CB$35=$G$445)*(AD12+$G$430-$O12-$G$435) -> -2350 | CC38: =(CC$35=0)*($O12-$G$430)+(CC$35=$G$444)*$G$435+(CC$35=$G$445)*(AD12+$G$430-$O12-$G$435) -> 0 | CD38: =(CD$35=0)*($O12-$G$430)+(CD$35=$G$444)*$G$435+(CD$35=$G$445)*(AD12+$G$430-$O12-$G$435) -> 0 | CE38: =(CE$35=0)*($O12-$G$430)+(CE$35=$G$444)*$G$435+(CE$35=$G$445)*(AD12+$G$430-$O12-$G$435) -> 0 | CF38: =(CF$35=0)*($O12-$G$430)+(CF$35=$G$444)*$G$435+(CF$35=$G$445)*(AD12+$G$430-$O12-$G$435) -> 0 | CG38: =(CG$35=0)*($O12-$G$430)+(CG$35=$G$444)*$G$435+(CG$35=$G$445)*(AD12+$G$430-$O12-$G$435) -> 8179.291 | CH38: =(CH$35=0)*($O12-$G$430)+(CH$35=$G$444)*$G$435+(CH$35=$G$445)*(AE12+$G$430-$O12-$G$435) -> -2350 | CI38: =(CI$35=0)*($O12-$G$430)+(CI$35=$G$444)*$G$435+(CI$35=$G$445)*(AE12+$G$430-$O12-$G$435) -> 0 | CJ38: =(CJ$35=0)*($O12-$G$430)+(CJ$35=$G$444)*$G$435+(CJ$35=$G$445)*(AE12+$G$430-$O12-$G$435) -> 0 | CK38: =(CK$35=0)*($O12-$G$430)+(CK$35=$G$444)*$G$435+(CK$35=$G$445)*(AE12+$G$430-$O12-$G$435) -> 0 | CL38: =(CL$35=0)*($O12-$G$430)+(CL$35=$G$444)*$G$435+(CL$35=$G$445)*(AE12+$G$430-$O12-$G$435) -> 0 | CM38: =(CM$35=0)*($O12-$G$430)+(CM$35=$G$444)*$G$435+(CM$35=$G$445)*(AE12+$G$430-$O12-$G$435) -> 8545.4112 | CN38: =(CN$35=0)*($O12-$G$430)+(CN$35=$G$444)*$G$435+(CN$35=$G$445)*(AF12+$G$430-$O12-$G$435) -> -2350 | CO38: =(CO$35=0)*($O12-$G$430)+(CO$35=$G$444)*$G$435+(CO$35=$G$445)*(AF12+$G$430-$O12-$G$435) -> 0 | CP38: =(CP$35=0)*($O12-$G$430)+(CP$35=$G$444)*$G$435+(CP$35=$G$445)*(AF12+$G$430-$O12-$G$435) -> 0 | CQ38: =(CQ$35=0)*($O12-$G$430)+(CQ$35=$G$444)*$G$435+(CQ$35=$G$445)*(AF12+$G$430-$O12-$G$435) -> 0 | CR38: =(CR$35=0)*($O12-$G$430)+(CR$35=$G$444)*$G$435+(CR$35=$G$445)*(AF12+$G$430-$O12-$G$435) -> 0 | CS38: =(CS$35=0)*($O12-$G$430)+(CS$35=$G$444)*$G$435+(CS$35=$G$445)*(AF12+$G$430-$O12-$G$435) -> 8911.5313 | CT38: =(CT$35=0)*($O12-$G$430)+(CT$35=$G$444)*$G$435+(CT$35=$G$445)*(AG12+$G$430-$O12-$G$435) -> -2350 | CU38: =(CU$35=0)*($O12-$G$430)+(CU$35=$G$444)*$G$435+(CU$35=$G$445)*(AG12+$G$430-$O12-$G$435) -> 0 | CV38: =(CV$35=0)*($O12-$G$430)+(CV$35=$G$444)*$G$435+(CV$35=$G$445)*(AG12+$G$430-$O12-$G$435) -> 0 | CW38: =(CW$35=0)*($O12-$G$430)+(CW$35=$G$444)*$G$435+(CW$35=$G$445)*(AG12+$G$430-$O12-$G$435) -> 0 | CX38: =(CX$35=0)*($O12-$G$430)+(CX$35=$G$444)*$G$435+(CX$35=$G$445)*(AG12+$G$430-$O12-$G$435) -> 0 | CY38: =(CY$35=0)*($O12-$G$430)+(CY$35=$G$444)*$G$435+(CY$35=$G$445)*(AG12+$G$430-$O12-$G$435) -> 9277.6514 | CZ38: =(CZ$35=0)*($O12-$G$430)+(CZ$35=$G$444)*$G$435+(CZ$35=$G$445)*(AH12+$G$430-$O12-$G$435) -> -2350 | DA38: =(DA$35=0)*($O12-$G$430)+(DA$35=$G$444)*$G$435+(DA$35=$G$445)*(AH12+$G$430-$O12-$G$435) -> 0 | DB38: =(DB$35=0)*($O12-$G$430)+(DB$35=$G$444)*$G$435+(DB$35=$G$445)*(AH12+$G$430-$O12-$G$435) -> 0 | DC38: =(DC$35=0)*($O12-$G$430)+(DC$35=$G$444)*$G$435+(DC$35=$G$445)*(AH12+$G$430-$O12-$G$435) -> 0 | DD38: =(DD$35=0)*($O12-$G$430)+(DD$35=$G$444)*$G$435+(DD$35=$G$445)*(AH12+$G$430-$O12-$G$435) -> 0 | DE38: =(DE$35=0)*($O12-$G$430)+(DE$35=$G$444)*$G$435+(DE$35=$G$445)*(AH12+$G$430-$O12-$G$435) -> 9643.7715
