Workbook

Sheet Cover
B24: Keystone Bookkeepers
B25: Pre-LOI Business Analysis
B26: ="As of "&TEXT(TODAY(),"mm/dd/yy") -> As of 09/24/26

Sheet Offer Overview
B2: =Cover!$B$24 -> Keystone Bookkeepers
B3: Offer & Equity Upside Scenarios ($000s) | G3: Print | H3: 1
B5: Offer Breakdown | C5: Today
B6: Recurring Revenue (PF Jul'26) | C6: ='Revenue Analysis'!$E$16 -> 2942.9433
B7: (x) Revenue Multiple — Implied | C7: =IFERROR($C$8/$C$6,0) -> 1.0193876
B8: Total Valuation — Offer Price | C8: 3000
B9: (-) Cash at Close | C9: 500
B10: Topkey Equity Consideration | C10: =C8-C9 -> 2500
B12: Topkey Pre-Deal Valuation | C12: 60000
B13: (+) Keystone Value Acquired | C13: =$C$8 -> 3000
B14: (-) Cash Paid at Close | C14: =$C$9 -> 500
B15: Topkey Post-Money Valuation | C15: =C12+C13-C14 -> 62500
B16: Ben's Implied Topkey Ownership % | C16: =IFERROR($C$10/$C$15,0) -> 0.04
B17: Keystone Enterprise Value Today | C17: =$C$8 -> 3000
B18: Existing Shareholders' Value Post-Close | C18: =(1-$C$16)*$C$15 -> 60000
B20: Topkey Pre-Deal Valuation | C20: =$C$12 -> 60000
B21: (-) Cash Paid at Close | C21: =$C$14 -> 500
B22: Topkey ex-Keystone Growth Base | C22: =C20-C21 -> 59500
B24: Scenario 1 — Ben Retains 100% of Keystone | C24: Today | D24: 2.0x Valuation | E24: 3.0x Valuation
B25: Keystone Growth Multiple | C25: 1 | D25: 2 | E25: 3
B26: Keystone Enterprise Value | C26: =$C$17*C$25 -> 3000 | D26: =$C$17*D$25 -> 6000 | E26: =$C$17*E$25 -> 9000
B27: Ben's Ownership % — Keystone | C27: 1 | D27: =$C$27 -> 1 | E27: =$C$27 -> 1
B28: Ben's Keystone Equity Value | C28: =C26*$C$27 -> 3000 | D28: =D26*$C$27 -> 6000 | E28: =E26*$C$27 -> 9000
B29: (-) Value at Offer Today | C29: =$C$28 -> 3000 | D29: =$C$28 -> 3000 | E29: =$C$28 -> 3000
B30: Ben's Net Gain vs. Today | C30: =C28-C29 -> 0 | D30: =D28-D29 -> 3000 | E30: =E28-E29 -> 6000
B32: Combined Topkey + Keystone TEV | C32: Growth (ex-Keystone) | D32: =D$24 -> 2.0x Valuation | E32: =E$24 -> 3.0x Valuation
B33: Topkey Grows Half as Fast as Keystone | C33: 0.5 | D33: =$C$22*(1+(D$25-1)*$C33)+$C$17*D$25 -> 95250 | E33: =$C$22*(1+(E$25-1)*$C33)+$C$17*E$25 -> 128000
B34: Topkey Keeps Pace with Keystone | C34: 1 | D34: =$C$22*(1+(D$25-1)*$C34)+$C$17*D$25 -> 125000 | E34: =$C$22*(1+(E$25-1)*$C34)+$C$17*E$25 -> 187500
B35: Topkey Outgrows Keystone | C35: 1.5 | D35: =$C$22*(1+(D$25-1)*$C35)+$C$17*D$25 -> 154750 | E35: =$C$22*(1+(E$25-1)*$C35)+$C$17*E$25 -> 247000
B37: Ben's Total Value — Cash + Topkey Equity | D37: =+D$32 -> 2.0x Valuation | E37: =+E$32 -> 3.0x Valuation
B38: =$B33 -> Topkey Grows Half as Fast as Keystone | D38: =$C$9+$C$16*D33 -> 4310 | E38: =$C$9+$C$16*E33 -> 5620
B39: =$B34 -> Topkey Keeps Pace with Keystone | D39: =$C$9+$C$16*D34 -> 5500 | E39: =$C$9+$C$16*E34 -> 8000
B40: =$B35 -> Topkey Outgrows Keystone | D40: =$C$9+$C$16*D35 -> 6690 | E40: =$C$9+$C$16*E35 -> 10380
B42: Delta vs. Scenario 1 | D42: =+D$32 -> 2.0x Valuation | E42: =+E$32 -> 3.0x Valuation
B43: =$B33 -> Topkey Grows Half as Fast as Keystone | D43: =D38-D$28 -> -1690 | E43: =E38-E$28 -> -3380
B44: =$B34 -> Topkey Keeps Pace with Keystone | D44: =D39-D$28 -> -500 | E44: =E39-E$28 -> -1000
B45: =$B35 -> Topkey Outgrows Keystone | D45: =D40-D$28 -> 690 | E45: =E40-E$28 -> 1380
B47: Topkey Growth Required for Parity | D47: =+D$32 -> 2.0x Valuation | E47: =+E$32 -> 3.0x Valuation
B48: Ben's Value — Scenario 1 (Retain 100%) | D48: =D$28 -> 6000 | E48: =E$28 -> 9000
B49: (-) Ben's Cash at Close | D49: =$C$9 -> 500 | E49: =$C$9 -> 500
...

Sheet 100% Buyout Analysis
B2: =Cover!$B$24 -> Keystone Bookkeepers
B3: Valuation Growth Scenarios ($000s) | G3: Print | H3: 1
B5: Revenue Growth Assumptions | C5: Value | F5: Rationale / Notes
B6: General Assumptions
B7: Horizon (Years) | C7: 5 | F7: Projection horizon for Year 5 columns
B8: Topkey - Current Monthly Revenue | C8: 261 | F8: Topkey-provided monthly revenue ($000s). Red: source pending confirmation
B9: Topkey - Current Run-Rate Revenue | C9: =C8*12 -> 3132
B10: Topkey - Current Revenue Multiple | C10: =IFERROR(C156/C9,0) -> 19.157088 | F10: Implied multiple: Topkey pre-deal valuation (C156) ÷ run-rate revenue (C9)
B11: Topkey - Future Revenue Multiple | C11: =C10 -> 19.157088 | F11: Assumed flat at current multiple
B12: Topkey - Current Client Count | C12: 325 | F12: Topkey-provided client count. Red: source pending confirmation
B13: Topkey - Avg. Revenue Per Client | C13: =C9/C12 -> 9.6369231
B14: Topkey - Annual Net Client Wins | C14: 130 | F14: AMB placeholder. Red: source pending confirmation
B15: Total Net Client Wins | C15: =C14*$C$7 -> 650
B16: Total Additional Revenue | C16: =C15*C13 -> 6264
B18: Keystone Standalone Assumptions
B19: Revenue Multiple | C19: 1 | F19: Keystone standalone valued at 1.0x revenue (offer implies ~1.02x)
B20: Scaled Revenue Multiple | C20: 1.25 | F20: Future revenue multiple for Keystone
B21: Avg. Revenue Per Client | C21: =+'Steady-State Staffing'!AB8 -> 16.631473 | F21: Sep'26 annualized fee per non-tax client (Steady-State Staffing AB8)
B22: Target Monthly Net Client Wins | C22: 3 | F22: Target pace per AMB; LTM actual is 26/yr (~2.2/month), see build at rows 163-168
B23: Annual Net Client Wins | C23: =C22*12 -> 36 | F23: Target monthly pace × 12
B24: Total Net Client Wins | C24: =C23*$C$7 -> 180
B25: Total Additional Revenue | C25: =C24*C21 -> 2993.6651
B27: Keystone Partnership Assumptions
B28: Software-Integration Revenue Multiple | C28: 3 | F28: Assumed revenue multiple for software-integrated partnership
B29: VR Platform Run-Rate Tech Cost | C29: 240 | F29: Run-rate tech cost provided by the target; memo only — VR savings assumed captured in the 25% partnership margin and revenue multiple
B31: =+B21 -> Avg. Revenue Per Client | C31: =+C21 -> 16.631473
B32: (+) Software-Enabled Price Increase / Client | C32: 0 | F32: Only if Topkey software supports higher client fees; VR platform cost no longer added to revenue per client
B33: Total Avg. Revenue Per Client | C33: =+C31+C32 -> 16.631473
B35: =+B23 -> Annual Net Client Wins | C35: =+C23 -> 36
B36: (+) Additional Annual Net Client Wins From Topkey | C36: 12 | F36: Topkey-provided. Red: source pending confirmation
B37: Total Annual Net Client Wins | C37: =SUM(C35:C36) -> 48
B38: Total Net Client Wins | C38: =C37*$C$7 -> 240
B39: Total Additional Revenue | C39: =C38*C33 -> 3991.5535
B40: Increase in Keystone Revenue vs. Standalone | C40: =C39-C25 -> 997.88838
B42: Cash Earnout — Year 3 Keystone Revenue (Sliding Scale)
B43: Earnout Measurement Year | C43: 3 | F43: Earnout measured on Year 3 run-rate: average of months 34–36 × 12 (see C54)
B44: Keystone Revenue at Close | C44: =C152 -> 2998.541 | F44: PF Jul'26 run-rate revenue at close (C152); unchanged
B45: Year 3 Run-Rate Revenue Target | C45: =C44+C39*(C43-(C54-1)/2/12)/C7 -> 5326.9472 | F45: Run-rate at close + partnership added revenue ramped to the midpoint of the averaging window (month 35 ÷ 60); same basis as the earnout measurement
B46: (x) Achievement vs. Target | C46: 1 | F46: Base case assumes the model's Year 3 revenue is achieved; flex to test payout
B47: Year 3 Run-Rate Revenue — Achieved | C47: =C45*C46 -> 5326.9472
...

Sheet Partnership Analysis
B2: =Cover!$B$24 -> Keystone Bookkeepers
B3: Partnership Rollover Scenarios ($000s) | G3: Print | H3: 1
B5: Revenue Growth Assumptions | C5: Value | F5: Rationale / Notes
B6: General Assumptions
B7: Ben's Rollover % — Keystone | C7: 0.3 | F7: Share of Keystone Ben keeps; Topkey buys the rest for cash + Topkey equity (per AMB)
B8: Horizon (Years) | C8: 5 | F8: Projection horizon for Year 5 columns
B9: Topkey - Current Monthly Revenue | C9: 261 | F9: Topkey-provided monthly revenue ($000s). Red: source pending confirmation
B10: Topkey - Current Run-Rate Revenue | C10: =C9*12 -> 3132
B11: Topkey - Current Revenue Multiple | C11: =IFERROR(C167/C10,0) -> 19.157088 | F11: Implied multiple: Topkey pre-deal valuation (C167) ÷ run-rate revenue (C10)
B12: Topkey - Future Revenue Multiple | C12: =C11 -> 19.157088 | F12: Assumed flat at current multiple
B13: Topkey - Current Client Count | C13: 325 | F13: Topkey-provided client count. Red: source pending confirmation
B14: Topkey - Avg. Revenue Per Client | C14: =C10/C13 -> 9.6369231
B15: Topkey - Annual Net Client Wins | C15: 130 | F15: AMB placeholder. Red: source pending confirmation
B16: Total Net Client Wins | C16: =C15*$C$8 -> 650
B17: Total Additional Revenue | C17: =C16*C14 -> 6264
B19: Keystone Standalone Assumptions
B20: Revenue Multiple | C20: 1 | F20: Keystone standalone valued at 1.0x revenue (offer implies ~1.02x)
B21: Scaled Revenue Multiple | C21: 1.25 | F21: Future revenue multiple for Keystone
B22: Avg. Revenue Per Client | C22: =+'Steady-State Staffing'!AB8 -> 16.631473 | F22: Sep'26 annualized fee per non-tax client (Steady-State Staffing AB8)
B23: Target Monthly Net Client Wins | C23: 3 | F23: Target pace per AMB; LTM actual is 26/yr (~2.2/month), see build at rows 175-180
B24: Annual Net Client Wins | C24: =C23*12 -> 36 | F24: Target monthly pace × 12
B25: Total Net Client Wins | C25: =C24*$C$8 -> 180
B26: Total Additional Revenue | C26: =C25*C22 -> 2993.6651
B28: Keystone Partnership Assumptions
B29: Software-Integration Revenue Multiple | C29: 2 | F29: Assumed revenue multiple for software-integrated partnership
B30: VR Platform Run-Rate Tech Cost | C30: 240 | F30: Run-rate tech cost provided by the target
B32: =+B22 -> Avg. Revenue Per Client | C32: =+C22 -> 16.631473
B33: (+) Software-Enabled Price Increase / Client | C33: 0 | F33: Only if Topkey software supports higher client fees; VR cost treated as a cost (memo block at rows 182-192)
B34: Total Avg. Revenue Per Client | C34: =+C32+C33 -> 16.631473
B36: =+B24 -> Annual Net Client Wins | C36: =+C24 -> 36
B37: (+) Additional Annual Net Client Wins From Topkey | C37: 12 | F37: Topkey-provided. Red: source pending confirmation
B38: Total Annual Net Client Wins | C38: =SUM(C36:C37) -> 48
B39: Total Net Client Wins | C39: =C38*$C$8 -> 240
B40: Total Additional Revenue | C40: =C39*C34 -> 3991.5535
B41: Increase in Keystone Revenue vs. Standalone | C41: =C40-C26 -> 997.88838
B43: Cash Earnout — Year 3 Keystone Revenue (Sliding Scale)
B44: Earnout Measurement Year | C44: 3 | F44: Earnout measured on Year 3 run-rate: average of months 34–36 × 12 (see C55)
B45: Keystone Revenue at Close | C45: =C160 -> 2998.541 | F45: PF Jul'26 run-rate revenue at close (C160); unchanged
B46: Year 3 Run-Rate Revenue Target | C46: =C45+C40*(C44-(C55-1)/2/12)/C8 -> 5326.9472 | F46: Run-rate at close + partnership added revenue ramped to the midpoint of the averaging window (month 35 ÷ 60); same basis as the earnout measurement
B47: (x) Achievement vs. Target | C47: 1 | F47: Base case assumes the model's Year 3 revenue is achieved; flex to test payout
...

Sheet Valuation Growth Tables
B2: =Cover!$B$24 -> Keystone Bookkeepers
B3: Valuation Growth Sensitivity Tables ($000s) | I3: Print | J3: 1
B5: ="Table 1 — Ben's Net Gain: Scenario 2 vs. Scenario 1, Year "&$C$31&" ($000s)" -> Table 1 — Ben's Net Gain: Scenario 2 vs. Scenario 1, Year 5 ($000s)
B6: Standalone Multiple ↓ | Partnership Multiple → | C6: =D6-$C$44 -> 2 | D6: =E6-$C$44 -> 2.5 | E6: =$C$38 -> 3 | F6: =E6+$C$44 -> 3.5 | G6: =F6+$C$44 -> 4
B7: =B8-$C$45 -> 0.75 | C7: =$C$42*($C$41+$C$50*C$6)+$C$43-$C$51*$B7*$C$34 -> 4225.0529 | D7: =$C$42*($C$41+$C$50*D$6)+$C$43-$C$51*$B7*$C$34 -> 4364.8548 | E7: =$C$42*($C$41+$C$50*E$6)+$C$43-$C$51*$B7*$C$34 -> 4504.6567 | F7: =$C$42*($C$41+$C$50*F$6)+$C$43-$C$51*$B7*$C$34 -> 4644.4586 | G7: =$C$42*($C$41+$C$50*G$6)+$C$43-$C$51*$B7*$C$34 -> 4784.2605
B8: =B9-$C$45 -> 1 | C8: =$C$42*($C$41+$C$50*C$6)+$C$43-$C$51*$B8*$C$34 -> 2727.0014 | D8: =$C$42*($C$41+$C$50*D$6)+$C$43-$C$51*$B8*$C$34 -> 2866.8033 | E8: =$C$42*($C$41+$C$50*E$6)+$C$43-$C$51*$B8*$C$34 -> 3006.6052 | F8: =$C$42*($C$41+$C$50*F$6)+$C$43-$C$51*$B8*$C$34 -> 3146.4071 | G8: =$C$42*($C$41+$C$50*G$6)+$C$43-$C$51*$B8*$C$34 -> 3286.209
B9: =$C$35 -> 1.25 | C9: =$C$42*($C$41+$C$50*C$6)+$C$43-$C$51*$B9*$C$34 -> 1228.9499 | D9: =$C$42*($C$41+$C$50*D$6)+$C$43-$C$51*$B9*$C$34 -> 1368.7518 | E9: =$C$42*($C$41+$C$50*E$6)+$C$43-$C$51*$B9*$C$34 -> 1508.5536 | F9: =$C$42*($C$41+$C$50*F$6)+$C$43-$C$51*$B9*$C$34 -> 1648.3555 | G9: =$C$42*($C$41+$C$50*G$6)+$C$43-$C$51*$B9*$C$34 -> 1788.1574
B10: =B9+$C$45 -> 1.5 | C10: =$C$42*($C$41+$C$50*C$6)+$C$43-$C$51*$B10*$C$34 -> -269.10168 | D10: =$C$42*($C$41+$C$50*D$6)+$C$43-$C$51*$B10*$C$34 -> -129.29978 | E10: =$C$42*($C$41+$C$50*E$6)+$C$43-$C$51*$B10*$C$34 -> 10.502106 | F10: =$C$42*($C$41+$C$50*F$6)+$C$43-$C$51*$B10*$C$34 -> 150.304 | G10: =$C$42*($C$41+$C$50*G$6)+$C$43-$C$51*$B10*$C$34 -> 290.10589
B11: =B10+$C$45 -> 1.75 | C11: =$C$42*($C$41+$C$50*C$6)+$C$43-$C$51*$B11*$C$34 -> -1767.1532 | D11: =$C$42*($C$41+$C$50*D$6)+$C$43-$C$51*$B11*$C$34 -> -1627.3513 | E11: =$C$42*($C$41+$C$50*E$6)+$C$43-$C$51*$B11*$C$34 -> -1487.5494 | F11: =$C$42*($C$41+$C$50*F$6)+$C$43-$C$51*$B11*$C$34 -> -1347.7475 | G11: =$C$42*($C$41+$C$50*G$6)+$C$43-$C$51*$B11*$C$34 -> -1207.9457
B13: ="Table 2 — Partnership Value Increase vs. Base Standalone Increase, Year "&$C$31&" ($000s)" -> Table 2 — Partnership Value Increase vs. Base Standalone Increase, Year 5 ($000s)
B14: Avg. Rev. / Client ↓ | Annual Net Wins → | C14: =D14-$C$46 -> 38 | D14: =E14-$C$46 -> 43 | E14: =$C$40 -> 48 | F14: =E14+$C$46 -> 53 | G14: =F14+$C$46 -> 58
B15: =B16-$C$47 -> 14.631473 | C15: =($C$32+C$14*$C$31*$B15)*$C$38-$C$33-$C$52 -> 9845.305 | D15: =($C$32+D$14*$C$31*$B15)*$C$38-$C$33-$C$52 -> 10942.665 | E15: =($C$32+E$14*$C$31*$B15)*$C$38-$C$33-$C$52 -> 12040.026 | F15: =($C$32+F$14*$C$31*$B15)*$C$38-$C$33-$C$52 -> 13137.386 | G15: =($C$32+G$14*$C$31*$B15)*$C$38-$C$33-$C$52 -> 14234.747
B16: =B17-$C$47 -> 15.631473 | C16: =($C$32+C$14*$C$31*$B16)*$C$38-$C$33-$C$52 -> 10415.305 | D16: =($C$32+D$14*$C$31*$B16)*$C$38-$C$33-$C$52 -> 11587.665 | E16: =($C$32+E$14*$C$31*$B16)*$C$38-$C$33-$C$52 -> 12760.026 | F16: =($C$32+F$14*$C$31*$B16)*$C$38-$C$33-$C$52 -> 13932.386 | G16: =($C$32+G$14*$C$31*$B16)*$C$38-$C$33-$C$52 -> 15104.747
B17: =$C$39 -> 16.631473 | C17: =($C$32+C$14*$C$31*$B17)*$C$38-$C$33-$C$52 -> 10985.305 | D17: =($C$32+D$14*$C$31*$B17)*$C$38-$C$33-$C$52 -> 12232.665 | E17: =($C$32+E$14*$C$31*$B17)*$C$38-$C$33-$C$52 -> 13480.026 | F17: =($C$32+F$14*$C$31*$B17)*$C$38-$C$33-$C$52 -> 14727.386 | G17: =($C$32+G$14*$C$31*$B17)*$C$38-$C$33-$C$52 -> 15974.747
B18: =B17+$C$47 -> 17.631473 | C18: =($C$32+C$14*$C$31*$B18)*$C$38-$C$33-$C$52 -> 11555.305 | D18: =($C$32+D$14*$C$31*$B18)*$C$38-$C$33-$C$52 -> 12877.665 | E18: =($C$32+E$14*$C$31*$B18)*$C$38-$C$33-$C$52 -> 14200.026 | F18: =($C$32+F$14*$C$31*$B18)*$C$38-$C$33-$C$52 -> 15522.386 | G18: =($C$32+G$14*$C$31*$B18)*$C$38-$C$33-$C$52 -> 16844.747
B19: =B18+$C$47 -> 18.631473 | C19: =($C$32+C$14*$C$31*$B19)*$C$38-$C$33-$C$52 -> 12125.305 | D19: =($C$32+D$14*$C$31*$B19)*$C$38-$C$33-$C$52 -> 13522.665 | E19: =($C$32+E$14*$C$31*$B19)*$C$38-$C$33-$C$52 -> 14920.026 | F19: =($C$32+F$14*$C$31*$B19)*$C$38-$C$33-$C$52 -> 16317.386 | G19: =($C$32+G$14*$C$31*$B19)*$C$38-$C$33-$C$52 -> 17714.747
B21: ="Table 3 — Standalone: Keystone Value Increase vs. Today, Year "&$C$31&" ($000s)" -> Table 3 — Standalone: Keystone Value Increase vs. Today, Year 5 ($000s)
B22: Avg. Rev. / Client ↓ | Annual Net Wins → | C22: =D22-$C$46 -> 26 | D22: =E22-$C$46 -> 31 | E22: =$C$37 -> 36 | F22: =E22+$C$46 -> 41 | G22: =F22+$C$46 -> 46
B23: =B24-$C$47 -> 14.631473 | C23: =($C$32+C$22*$C$31*$B23)*$C$35-$C$33 -> 3125.7906 | D23: =($C$32+D$22*$C$31*$B23)*$C$35-$C$33 -> 3583.0242 | E23: =($C$32+E$22*$C$31*$B23)*$C$35-$C$33 -> 4040.2577 | F23: =($C$32+F$22*$C$31*$B23)*$C$35-$C$33 -> 4497.4912 | G23: =($C$32+G$22*$C$31*$B23)*$C$35-$C$33 -> 4954.7248
B24: =B25-$C$47 -> 15.631473 | C24: =($C$32+C$22*$C$31*$B24)*$C$35-$C$33 -> 3288.2906 | D24: =($C$32+D$22*$C$31*$B24)*$C$35-$C$33 -> 3776.7742 | E24: =($C$32+E$22*$C$31*$B24)*$C$35-$C$33 -> 4265.2577 | F24: =($C$32+F$22*$C$31*$B24)*$C$35-$C$33 -> 4753.7412 | G24: =($C$32+G$22*$C$31*$B24)*$C$35-$C$33 -> 5242.2248
B25: =$C$36 -> 16.631473 | C25: =($C$32+C$22*$C$31*$B25)*$C$35-$C$33 -> 3450.7906 | D25: =($C$32+D$22*$C$31*$B25)*$C$35-$C$33 -> 3970.5242 | E25: =($C$32+E$22*$C$31*$B25)*$C$35-$C$33 -> 4490.2577 | F25: =($C$32+F$22*$C$31*$B25)*$C$35-$C$33 -> 5009.9912 | G25: =($C$32+G$22*$C$31*$B25)*$C$35-$C$33 -> 5529.7248
B26: =B25+$C$47 -> 17.631473 | C26: =($C$32+C$22*$C$31*$B26)*$C$35-$C$33 -> 3613.2906 | D26: =($C$32+D$22*$C$31*$B26)*$C$35-$C$33 -> 4164.2742 | E26: =($C$32+E$22*$C$31*$B26)*$C$35-$C$33 -> 4715.2577 | F26: =($C$32+F$22*$C$31*$B26)*$C$35-$C$33 -> 5266.2412 | G26: =($C$32+G$22*$C$31*$B26)*$C$35-$C$33 -> 5817.2248
B27: =B26+$C$47 -> 18.631473 | C27: =($C$32+C$22*$C$31*$B27)*$C$35-$C$33 -> 3775.7906 | D27: =($C$32+D$22*$C$31*$B27)*$C$35-$C$33 -> 4358.0242 | E27: =($C$32+E$22*$C$31*$B27)*$C$35-$C$33 -> 4940.2577 | F27: =($C$32+F$22*$C$31*$B27)*$C$35-$C$33 -> 5522.4912 | G27: =($C$32+G$22*$C$31*$B27)*$C$35-$C$33 -> 6104.7248
B29: Sensitivity Assumptions
B30: Assumption | C30: Value | D30: Rationale
B31: Horizon (Years) | C31: ='100% Buyout Analysis'!$C$7 -> 5 | D31: Linked from Valuation Growth C7
B32: Keystone Revenue Today | C32: ='100% Buyout Analysis'!$C$152 -> 2998.541 | D32: Linked from 100% Buyout Analysis C125
B33: Keystone Value Today | C33: ='100% Buyout Analysis'!$C$153 -> 3000 | D33: Linked from 100% Buyout Analysis C126
B34: Ben's Ownership % — Keystone | C34: ='100% Buyout Analysis'!$C$62 -> 1 | D34: Linked from Valuation Growth C44
B35: Standalone Revenue Multiple (Year 5) | C35: ='100% Buyout Analysis'!$C$20 -> 1.25 | D35: Linked from Valuation Growth C20 (Scaled Revenue Multiple)
B36: Standalone Avg. Revenue Per Client | C36: ='100% Buyout Analysis'!$C$21 -> 16.631473 | D36: Linked from Valuation Growth C21
B37: Standalone Annual Net Client Wins | C37: ='100% Buyout Analysis'!$C$23 -> 36 | D37: Linked from Valuation Growth C23
B38: Partnership Revenue Multiple | C38: ='100% Buyout Analysis'!$C$28 -> 3 | D38: Linked from Valuation Growth C28
B39: Partnership Total Avg. Revenue Per Client | C39: ='100% Buyout Analysis'!$C$33 -> 16.631473 | D39: Linked from Valuation Growth C33
B40: Partnership Total Annual Net Client Wins | C40: ='100% Buyout Analysis'!$C$37 -> 48 | D40: Linked from Valuation Growth C37
B41: Topkey ex-Keystone Value — Year 5 | C41: ='100% Buyout Analysis'!$D$66 -> 179000 | D41: Linked from 100% Buyout Analysis D66 (net of cash and earnout paid)
B42: Ben's Topkey Ownership % | C42: ='100% Buyout Analysis'!$C$158 -> 0.04 | D42: Linked from 100% Buyout Analysis C151
B43: Cash at Close + Earnout | C43: ='100% Buyout Analysis'!$C$154+'100% Buyout Analysis'!$C$55 -> 1000 | D43: Linked from 100% Buyout Analysis C147 + C55 (Year 3 cash earnout)
B44: Step — Partnership Multiple (x) | C44: 0.5 | D44: ="Gives "&TEXT($C$38-2*$C$44,"0.00")&"x–"&TEXT($C$38+2*$C$44,"0.00")&"x around the "&TEXT($C$38,"0.00")&"x base" -> Gives 2.00x–4.00x around the 3.00x base
B45: Step — Standalone Multiple (x) | C45: 0.25 | D45: ="Gives "&TEXT($C$35-2*$C$45,"0.00")&"x–"&TEXT($C$35+2*$C$45,"0.00")&"x around the "&TEXT($C$35,"0.00")&"x base" -> Gives 0.75x–1.75x around the 1.25x base
...

Sheet P&L Overview
B2: =+Cover!B24 -> Keystone Bookkeepers
B3: Summary P&L Overview ($000s) | P3: Print | Q3: 1
C5: Full Year | F5: YTD | I5: LTM | K5: PF | M5: PF Delta
B6: P&L Summary | C6: 2024 | D6: 2025 | F6: July'25 | G6: July'26 | I6: July'25 | J6: July'26 | K6: July'26 | M6: ($) | N6: (%)
B7: Revenue
B8: =+'P&L Forecast'!B7 -> STR Subscription | C8: =+'P&L Forecast'!C7 -> 793.47225 | D8: =+'P&L Forecast'!D7 -> 1450.4923 | F8: =+'P&L Forecast'!F7 -> 751.5286 | G8: =+'P&L Forecast'!G7 -> 1261.4769 | I8: =+'P&L Forecast'!I7 -> 1152.3203 | J8: =+'P&L Forecast'!J7 -> 1960.4406 | K8: =+'P&L Forecast'!K7 -> 2410.05 | M8: =K8-J8 -> 449.6094 | N8: =IFERROR(K8/J8-1,0) -> 0.229341
B9: =+'P&L Forecast'!B8 -> Occupancy Taxes | C9: =+'P&L Forecast'!C8 -> 0.56 | D9: =+'P&L Forecast'!D8 -> 55.0805 | F9: =+'P&L Forecast'!F8 -> 23.2255 | G9: =+'P&L Forecast'!G8 -> 91.65114 | I9: =+'P&L Forecast'!I8 -> 23.7855 | J9: =+'P&L Forecast'!J8 -> 123.50614 | K9: =+'P&L Forecast'!K8 -> 192.8298 | M9: =K9-J9 -> 69.32366 | N9: =IFERROR(K9/J9-1,0) -> 0.56129728
B10: =+'P&L Forecast'!B9 -> SMB Subscription | C10: =+'P&L Forecast'!C9 -> 224.791 | D10: =+'P&L Forecast'!D9 -> 149.77 | F10: =+'P&L Forecast'!F9 -> 90.4525 | G10: =+'P&L Forecast'!G9 -> 73.4185 | I10: =+'P&L Forecast'!I9 -> 169.5465 | J10: =+'P&L Forecast'!J9 -> 132.736 | K10: =+'P&L Forecast'!K9 -> 16.2 | M10: =K10-J10 -> -116.536 | N10: =IFERROR(K10/J10-1,0) -> -0.87795323
B11: =+'P&L Forecast'!B10 -> Onboarding | C11: =+'P&L Forecast'!C10 -> 44.0585 | D11: =+'P&L Forecast'!D10 -> 74.5193 | F11: =+'P&L Forecast'!F10 -> 42.25405 | G11: =+'P&L Forecast'!G10 -> 59.055 | I11: =+'P&L Forecast'!I10 -> 57.49255 | J11: =+'P&L Forecast'!J10 -> 91.32025 | K11: =+'P&L Forecast'!K10 -> 103.5675 | M11: =K11-J11 -> 12.24725 | N11: =IFERROR(K11/J11-1,0) -> 0.13411319
B12: =+'P&L Forecast'!B11 -> Topkey Subscription | C12: =+'P&L Forecast'!C11 -> 0 | D12: =+'P&L Forecast'!D11 -> 9.947 | F12: =+'P&L Forecast'!F11 -> 0 | G12: =+'P&L Forecast'!G11 -> 45.086 | I12: =+'P&L Forecast'!I11 -> 0 | J12: =+'P&L Forecast'!J11 -> 55.033 | K12: =+'P&L Forecast'!K11 -> 94.836 | M12: =K12-J12 -> 39.803 | N12: =IFERROR(K12/J12-1,0) -> 0.72325695
B13: =+'P&L Forecast'!B12 -> STR Bill Pay | C13: =+'P&L Forecast'!C12 -> 0.06 | D13: =+'P&L Forecast'!D12 -> 36.6065 | F13: =+'P&L Forecast'!F12 -> 15.4915 | G13: =+'P&L Forecast'!G12 -> 45.13 | I13: =+'P&L Forecast'!I12 -> 15.5515 | J13: =+'P&L Forecast'!J12 -> 66.245 | K13: =+'P&L Forecast'!K12 -> 83.46 | M13: =K13-J13 -> 17.215 | N13: =IFERROR(K13/J13-1,0) -> 0.25986867
B14: =+'P&L Forecast'!B13 -> Controller Services | C14: =+'P&L Forecast'!C13 -> 13.75 | D14: =+'P&L Forecast'!D13 -> 46.4 | F14: =+'P&L Forecast'!F13 -> 31.5 | G14: =+'P&L Forecast'!G13 -> 24.25 | I14: =+'P&L Forecast'!I13 -> 44 | J14: =+'P&L Forecast'!J13 -> 39.15 | K14: =+'P&L Forecast'!K13 -> 42 | M14: =K14-J14 -> 2.85 | N14: =IFERROR(K14/J14-1,0) -> 0.072796935
B15: Other Revenue | C15: =+C16-SUM(C8:C14) -> 58.2741 | D15: =+D16-SUM(D8:D14) -> 56.56748 | F15: =+F16-SUM(F8:F14) -> 43.42095 | G15: =+G16-SUM(G8:G14) -> 70.95371 | I15: =+I16-SUM(I8:I14) -> 61.71435 | J15: =+J16-SUM(J8:J14) -> 84.10024 | K15: =+K16-SUM(K8:K14) -> 55.59772 | M15: =K15-J15 -> -28.50252 | N15: =IFERROR(K15/J15-1,0) -> -0.33891128
B16: Total Run-Rate Revenue | C16: =+'P&L Forecast'!C24 -> 1134.9659 | D16: =+'P&L Forecast'!D24 -> 1879.3831 | F16: =+'P&L Forecast'!F24 -> 997.8731 | G16: =+'P&L Forecast'!G24 -> 1671.0212 | I16: =+'P&L Forecast'!I24 -> 1524.4107 | J16: =+'P&L Forecast'!J24 -> 2552.5312 | K16: =+'P&L Forecast'!K24 -> 2998.541 | M16: =SUM(M8:M15) -> 446.00979 | N16: =IFERROR(K16/J16-1,0) -> 0.17473235
B17: Unclassified Active Client Revenue | C17: =+'P&L Forecast'!C26 -> 0 | D17: =+'P&L Forecast'!D26 -> 0 | F17: =+'P&L Forecast'!F26 -> 0 | G17: =+'P&L Forecast'!G26 -> 0 | I17: =+'P&L Forecast'!I26 -> 0 | J17: =+'P&L Forecast'!J26 -> 0 | K17: =+'P&L Forecast'!K26 -> 93.9827 | M17: =K17-J17 -> 93.9827 | N17: =IFERROR(K17/J17-1,0) -> 0
B18: Total Adj. Revenue | C18: =+'P&L Forecast'!C28 -> 1134.9659 | D18: =+'P&L Forecast'!D28 -> 1879.3831 | F18: =+'P&L Forecast'!F28 -> 997.8731 | G18: =+'P&L Forecast'!G28 -> 1671.0212 | I18: =+'P&L Forecast'!I28 -> 1524.4107 | J18: =+'P&L Forecast'!J28 -> 2552.5312 | K18: =+'P&L Forecast'!K28 -> 3092.5237 | M18: =SUM(M16:M17) -> 539.99249 | N18: =IFERROR(K18/J18-1,0) -> 0.21155177
B20: Expenses
B21: =+'P&L Forecast'!B31 -> Indirect Labor | C21: =+'P&L Forecast'!C31 -> 101.3752 | D21: =+'P&L Forecast'!D31 -> 281.24054 | F21: =+'P&L Forecast'!F31 -> 136.29648 | G21: =+'P&L Forecast'!G31 -> 357.27472 | I21: =+'P&L Forecast'!I31 -> 202.41598 | J21: =+'P&L Forecast'!J31 -> 502.21878 | K21: =+'P&L Forecast'!K31 -> 681.3 | M21: =K21-J21 -> 179.08122 | N21: =IFERROR(K21/J21-1,0) -> 0.35658009 | P21: =K21/$K$30 -> 0.32533849
B22: =+'P&L Forecast'!B32 -> Bookkeeper Wages | C22: =+'P&L Forecast'!C32 -> 183.36903 | D22: =+'P&L Forecast'!D32 -> 316.18462 | F22: =+'P&L Forecast'!F32 -> 147.26813 | G22: =+'P&L Forecast'!G32 -> 267.7574 | I22: =+'P&L Forecast'!I32 -> 240.18098 | J22: =+'P&L Forecast'!J32 -> 436.67389 | K22: =+'P&L Forecast'!K32 -> 492.6 | M22: =K22-J22 -> 55.92611 | N22: =IFERROR(K22/J22-1,0) -> 0.12807294 | P22: =K22/$K$30 -> 0.23522933
B23: =+'P&L Forecast'!B33 -> Client Lead Wages | C23: =+'P&L Forecast'!C33 -> 286.16129 | D23: =+'P&L Forecast'!D33 -> 352.95844 | F23: =+'P&L Forecast'!F33 -> 201.27983 | G23: =+'P&L Forecast'!G33 -> 202.05309 | I23: =+'P&L Forecast'!I33 -> 353.12843 | J23: =+'P&L Forecast'!J33 -> 353.7317 | K23: =+'P&L Forecast'!K33 -> 392.92452 | M23: =K23-J23 -> 39.19282 | N23: =IFERROR(K23/J23-1,0) -> 0.11079816 | P23: =K23/$K$30 -> 0.18763169
B24: =+'P&L Forecast'!B34 -> Onboarding Team Wages | C24: =+'P&L Forecast'!C34 -> 122.81255 | D24: =+'P&L Forecast'!D34 -> 152.16972 | F24: =+'P&L Forecast'!F34 -> 73.94962 | G24: =+'P&L Forecast'!G34 -> 111.27999 | I24: =+'P&L Forecast'!I34 -> 121.30735 | J24: =+'P&L Forecast'!J34 -> 189.50009 | K24: =+'P&L Forecast'!K34 -> 197.14944 | M24: =K24-J24 -> 7.64935 | N24: =IFERROR(K24/J24-1,0) -> 0.040365944 | P24: =K24/$K$30 -> 0.094143992
B25: =+'P&L Forecast'!B35 -> Owner Wages | C25: =+'P&L Forecast'!C35 -> 0 | D25: =+'P&L Forecast'!D35 -> 90.66704 | F25: =+'P&L Forecast'!F35 -> 45.46612 | G25: =+'P&L Forecast'!G35 -> 63.14302 | I25: =+'P&L Forecast'!I35 -> 45.46612 | J25: =+'P&L Forecast'!J35 -> 108.34394 | K25: =+'P&L Forecast'!K35 -> 108.34394 | M25: =K25-J25 -> 0 | N25: =IFERROR(K25/J25-1,0) -> 0 | P25: =K25/$K$30 -> 0.051737053
B26: =+'P&L Forecast'!B36 -> S&M Wages | C26: =+'P&L Forecast'!C36 -> 0 | D26: =+'P&L Forecast'!D36 -> 19.14963 | F26: =+'P&L Forecast'!F36 -> 3.09945 | G26: =+'P&L Forecast'!G36 -> 51.94131 | I26: =+'P&L Forecast'!I36 -> 3.09945 | J26: =+'P&L Forecast'!J36 -> 67.99149 | K26: =+'P&L Forecast'!K36 -> 98.34912 | M26: =K26-J26 -> 30.35763 | N26: =IFERROR(K26/J26-1,0) -> 0.44649161 | P26: =K26/$K$30 -> 0.046964266
B27: =+'P&L Forecast'!B37 -> Occupancy Tax Specialist | C27: =+'P&L Forecast'!C37 -> 1.11335 | D27: =+'P&L Forecast'!D37 -> 29.56415 | F27: =+'P&L Forecast'!F37 -> 14.27585 | G27: =+'P&L Forecast'!G37 -> 42.08505 | I27: =+'P&L Forecast'!I37 -> 15.3892 | J27: =+'P&L Forecast'!J37 -> 57.37335 | K27: =+'P&L Forecast'!K37 -> 58.2 | M27: =K27-J27 -> 0.82665 | N27: =IFERROR(K27/J27-1,0) -> 0.014408257 | P27: =K27/$K$30 -> 0.027792016
B28: =+'P&L Forecast'!B38 -> Sr. Client Lead Wages | C28: =+'P&L Forecast'!C38 -> 0 | D28: =+'P&L Forecast'!D38 -> 0 | F28: =+'P&L Forecast'!F38 -> 0 | G28: =+'P&L Forecast'!G38 -> 7.995 | I28: =+'P&L Forecast'!I38 -> 0 | J28: =+'P&L Forecast'!J38 -> 7.995 | K28: =+'P&L Forecast'!K38 -> 33.08124 | M28: =K28-J28 -> 25.08624 | N28: =IFERROR(K28/J28-1,0) -> 3.1377411 | P28: =K28/$K$30 -> 0.015797154
B29: =+'P&L Forecast'!B39 -> Employee Benefits | C29: =+'P&L Forecast'!C39 -> 5.37405 | D29: =+'P&L Forecast'!D39 -> 19.23245 | F29: =+'P&L Forecast'!F39 -> 9.02166 | G29: =+'P&L Forecast'!G39 -> 17.36251 | I29: =+'P&L Forecast'!I39 -> 12.16686 | J29: =+'P&L Forecast'!J39 -> 27.5733 | K29: =+'P&L Forecast'!K39 -> 32.17836 | M29: =K29-J29 -> 4.60506 | N29: =IFERROR(K29/J29-1,0) -> 0.16701157 | P29: =K29/$K$30 -> 0.015366005
B30: =+'P&L Forecast'!B40 -> Total Payroll Expenses | C30: =SUM(C21:C29) -> 700.20547 | D30: =SUM(D21:D29) -> 1261.1666 | F30: =SUM(F21:F29) -> 630.65714 | G30: =SUM(G21:G29) -> 1120.8921 | I30: =SUM(I21:I29) -> 993.15437 | J30: =SUM(J21:J29) -> 1751.4015 | K30: =SUM(K21:K29) -> 2094.1266 | M30: =SUM(M21:M29) -> 342.72508 | N30: =K30/J30-1 -> 0.19568618
B32: =+'P&L Forecast'!B42 -> Software & Apps - COGS | C32: =+'P&L Forecast'!C42 -> 114.42269 | D32: =+'P&L Forecast'!D42 -> 157.49471 | F32: =+'P&L Forecast'!F42 -> 84.96859 | G32: =+'P&L Forecast'!G42 -> 152.28157 | I32: =+'P&L Forecast'!I42 -> 142.28345 | J32: =+'P&L Forecast'!J42 -> 224.80769 | K32: =+'P&L Forecast'!K42 -> 335.70816 | M32: =K32-J32 -> 110.90047 | N32: =IFERROR(K32/J32-1,0) -> 0.49331262
B33: =+'P&L Forecast'!B43 -> Software & Apps - G&A | C33: =+'P&L Forecast'!C43 -> 60.91594 | D33: =+'P&L Forecast'!D43 -> 117.05866 | F33: =+'P&L Forecast'!F43 -> 56.8115 | G33: =+'P&L Forecast'!G43 -> 97.04798 | I33: =+'P&L Forecast'!I43 -> 86.51489 | J33: =+'P&L Forecast'!J43 -> 157.29514 | K33: =+'P&L Forecast'!K43 -> 155.82264 | M33: =K33-J33 -> -1.4725 | N33: =IFERROR(K33/J33-1,0) -> -0.0093613827
B34: =+'P&L Forecast'!B44 -> Software & Apps - Topkey | C34: =+'P&L Forecast'!C44 -> 0 | D34: =+'P&L Forecast'!D44 -> 7.14125 | F34: =+'P&L Forecast'!F44 -> 0 | G34: =+'P&L Forecast'!G44 -> 28.82775 | I34: =+'P&L Forecast'!I44 -> 0 | J34: =+'P&L Forecast'!J44 -> 35.969 | K34: =+'P&L Forecast'!K44 -> 60.84 | M34: =K34-J34 -> 24.871 | N34: =IFERROR(K34/J34-1,0) -> 0.69145653
B35: =+'P&L Forecast'!B45 -> Software & Apps - AI tools | C35: =+'P&L Forecast'!C45 -> 0 | D35: =+'P&L Forecast'!D45 -> 0 | F35: =+'P&L Forecast'!F45 -> 0 | G35: =+'P&L Forecast'!G45 -> 6.52752 | I35: =+'P&L Forecast'!I45 -> 0 | J35: =+'P&L Forecast'!J45 -> 6.52752 | K35: =+'P&L Forecast'!K45 -> 15.74376 | M35: =K35-J35 -> 9.21624 | N35: =IFERROR(K35/J35-1,0) -> 1.4119053
B36: =+'P&L Forecast'!B46 -> Total Software Expenses | C36: =SUM(C32:C35) -> 175.33863 | D36: =SUM(D32:D35) -> 281.69462 | F36: =SUM(F32:F35) -> 141.78009 | G36: =SUM(G32:G35) -> 284.68482 | I36: =SUM(I32:I35) -> 228.79834 | J36: =SUM(J32:J35) -> 424.59935 | K36: =SUM(K32:K35) -> 568.11456 | M36: =SUM(M32:M35) -> 143.51521 | N36: =K36/J36-1 -> 0.33800148
B38: =+'P&L Forecast'!B48 -> Other Professional Fees | C38: =+'P&L Forecast'!C48 -> 18.23425 | D38: =+'P&L Forecast'!D48 -> 27.04095 | F38: =+'P&L Forecast'!F48 -> 12.014 | G38: =+'P&L Forecast'!G48 -> 57.55 | I38: =+'P&L Forecast'!I48 -> 21.74858 | J38: =+'P&L Forecast'!J48 -> 72.57695 | K38: =+'P&L Forecast'!K48 -> 72.57695 | M38: =K38-J38 -> 0 | N38: =IFERROR(K38/J38-1,0) -> 0
B39: =+'P&L Forecast'!B49 -> Referral Fees | C39: =+'P&L Forecast'!C49 -> 24.82 | D39: =+'P&L Forecast'!D49 -> 27.15374 | F39: =+'P&L Forecast'!F49 -> 17.0895 | G39: =+'P&L Forecast'!G49 -> 20.62969 | I39: =+'P&L Forecast'!I49 -> 26.2095 | J39: =+'P&L Forecast'!J49 -> 30.69393 | K39: =+'P&L Forecast'!K49 -> 30.69393 | M39: =K39-J39 -> 0 | N39: =IFERROR(K39/J39-1,0) -> 0
B40: =+'P&L Forecast'!B50 -> Travel, Meals & Entertainment | C40: =+'P&L Forecast'!C50 -> 0 | D40: =+'P&L Forecast'!D50 -> 29.76122 | F40: =+'P&L Forecast'!F50 -> 22.29558 | G40: =+'P&L Forecast'!G50 -> 20.68542 | I40: =+'P&L Forecast'!I50 -> 22.29558 | J40: =+'P&L Forecast'!J50 -> 28.15106 | K40: =+'P&L Forecast'!K50 -> 28.15106 | M40: =K40-J40 -> 0 | N40: =IFERROR(K40/J40-1,0) -> 0
B41: =+'P&L Forecast'!B51 -> Payment Collection Fees | C41: =+'P&L Forecast'!C51 -> 8.67099 | D41: =+'P&L Forecast'!D51 -> 13.35153 | F41: =+'P&L Forecast'!F51 -> 6.80445 | G41: =+'P&L Forecast'!G51 -> 9.02684 | I41: =+'P&L Forecast'!I51 -> 10.54373 | J41: =+'P&L Forecast'!J51 -> 15.57392 | K41: =+'P&L Forecast'!K51 -> 15.57392 | M41: =K41-J41 -> 0 | N41: =IFERROR(K41/J41-1,0) -> 0
B42: =+'P&L Forecast'!B52 -> Professional Organizations | C42: =+'P&L Forecast'!C52 -> 5.44332 | D42: =+'P&L Forecast'!D52 -> 11.22296 | F42: =+'P&L Forecast'!F52 -> 6.191 | G42: =+'P&L Forecast'!G52 -> 6.57881 | I42: =+'P&L Forecast'!I52 -> 9.53268 | J42: =+'P&L Forecast'!J52 -> 11.61077 | K42: =+'P&L Forecast'!K52 -> 11.61077 | M42: =K42-J42 -> 0 | N42: =IFERROR(K42/J42-1,0) -> 0
B43: =+'P&L Forecast'!B53 -> S&M Events | C43: =+'P&L Forecast'!C53 -> 0 | D43: =+'P&L Forecast'!D53 -> 11.4983 | F43: =+'P&L Forecast'!F53 -> 0 | G43: =+'P&L Forecast'!G53 -> 11.84548 | I43: =+'P&L Forecast'!I53 -> 0 | J43: =+'P&L Forecast'!J53 -> 23.34378 | K43: =+'P&L Forecast'!K53 -> 23.34378 | M43: =K43-J43 -> 0 | N43: =IFERROR(K43/J43-1,0) -> 0
B44: =+'P&L Forecast'!B54 -> Contract Labor - Tax | C44: =+'P&L Forecast'!C54 -> 0 | D44: =+'P&L Forecast'!D54 -> 1.5875 | F44: =+'P&L Forecast'!F54 -> 0 | G44: =+'P&L Forecast'!G54 -> 30.5155 | I44: =+'P&L Forecast'!I54 -> 0 | J44: =+'P&L Forecast'!J54 -> 32.103 | K44: =+'P&L Forecast'!K54 -> 38.7615 | M44: =K44-J44 -> 6.6585 | N44: =IFERROR(K44/J44-1,0) -> 0.20741052
B45: =+'P&L Forecast'!B55 -> Recruiting Fees | C45: =+'P&L Forecast'!C55 -> 14.90205 | D45: =+'P&L Forecast'!D55 -> 31.6041 | F45: =+'P&L Forecast'!F55 -> 28.29994 | G45: =+'P&L Forecast'!G55 -> 5.5646 | I45: =+'P&L Forecast'!I55 -> 35.34606 | J45: =+'P&L Forecast'!J55 -> 8.86876 | K45: =+'P&L Forecast'!K55 -> 8.86876 | M45: =K45-J45 -> 0 | N45: =IFERROR(K45/J45-1,0) -> 0
...

Sheet Software Overview
B2: =+Cover!B24 -> Keystone Bookkeepers
B3: Software Utilization Overview ($)
B5: Software Utilization | C5: Current Clients | G5: Former Clients | K5: Total
B6: Bill Pay | C6: Clients | D6: Properties | E6: Avg. Monthly Fee | G6: Clients | H6: Properties | I6: Avg. Monthly Fee | K6: Clients | L6: Properties | M6: % of Clients
B7: Yes | C7: =COUNTIFS('Customer List w Software'!$B$4:$B$310,"<>Former client",'Customer List w Software'!$V$4:$V$310,$B7) -> 41 | D7: =SUMIFS('Customer List w Software'!$K$4:$K$310,'Customer List w Software'!$B$4:$B$310,"<>Former client",'Customer List w Software'!$V$4:$V$310,$B7) -> 1285 | E7: =IFERROR(AVERAGEIFS('Customer List w Software'!$J$4:$J$310,'Customer List w Software'!$B$4:$B$310,"<>Former client",'Customer List w Software'!$V$4:$V$310,$B7),0) -> 2011.8227 | G7: =COUNTIFS('Customer List w Software'!$B$4:$B$310,"Former client",'Customer List w Software'!$V$4:$V$310,$B7) -> 4 | H7: =SUMIFS('Customer List w Software'!$K$4:$K$310,'Customer List w Software'!$B$4:$B$310,"Former client",'Customer List w Software'!$V$4:$V$310,$B7) -> 72 | I7: =IFERROR(AVERAGEIFS('Customer List w Software'!$J$4:$J$310,'Customer List w Software'!$B$4:$B$310,"Former client",'Customer List w Software'!$V$4:$V$310,$B7),0) -> 1602.6667 | K7: =C7+G7 -> 45 | L7: =D7+H7 -> 1357 | M7: =K7/K$10 -> 0.1465798
B8: No | C8: =COUNTIFS('Customer List w Software'!$B$4:$B$310,"<>Former client",'Customer List w Software'!$V$4:$V$310,$B8) -> 133 | D8: =SUMIFS('Customer List w Software'!$K$4:$K$310,'Customer List w Software'!$B$4:$B$310,"<>Former client",'Customer List w Software'!$V$4:$V$310,$B8) -> 2472 | E8: =IFERROR(AVERAGEIFS('Customer List w Software'!$J$4:$J$310,'Customer List w Software'!$B$4:$B$310,"<>Former client",'Customer List w Software'!$V$4:$V$310,$B8),0) -> 1186.0576 | G8: =COUNTIFS('Customer List w Software'!$B$4:$B$310,"Former client",'Customer List w Software'!$V$4:$V$310,$B8) -> 52 | H8: =SUMIFS('Customer List w Software'!$K$4:$K$310,'Customer List w Software'!$B$4:$B$310,"Former client",'Customer List w Software'!$V$4:$V$310,$B8) -> 352 | I8: =IFERROR(AVERAGEIFS('Customer List w Software'!$J$4:$J$310,'Customer List w Software'!$B$4:$B$310,"Former client",'Customer List w Software'!$V$4:$V$310,$B8),0) -> 631.64103 | K8: =C8+G8 -> 185 | L8: =D8+H8 -> 2824 | M8: =K8/K$10 -> 0.60260586
B9: Not Designated | C9: =COUNTIFS('Customer List w Software'!$B$4:$B$310,"<>Former client",'Customer List w Software'!$V$4:$V$310,"") -> 0 | D9: =SUMIFS('Customer List w Software'!$K$4:$K$310,'Customer List w Software'!$B$4:$B$310,"<>Former client",'Customer List w Software'!$V$4:$V$310,"") -> 0 | E9: =IFERROR(AVERAGEIFS('Customer List w Software'!$J$4:$J$310,'Customer List w Software'!$B$4:$B$310,"<>Former client",'Customer List w Software'!$V$4:$V$310,""),0) -> 0 | G9: =COUNTIFS('Customer List w Software'!$B$4:$B$310,"Former client",'Customer List w Software'!$V$4:$V$310,"") -> 77 | H9: =SUMIFS('Customer List w Software'!$K$4:$K$310,'Customer List w Software'!$B$4:$B$310,"Former client",'Customer List w Software'!$V$4:$V$310,"") -> 30 | I9: =IFERROR(AVERAGEIFS('Customer List w Software'!$J$4:$J$310,'Customer List w Software'!$B$4:$B$310,"Former client",'Customer List w Software'!$V$4:$V$310,""),0) -> 592.10266 | K9: =C9+G9 -> 77 | L9: =D9+H9 -> 30 | M9: =K9/K$10 -> 0.25081433
B10: Total Clients | C10: =COUNTIFS('Customer List w Software'!$B$4:$B$310,"<>Former client") -> 174 | D10: =SUMIFS('Customer List w Software'!$K$4:$K$310,'Customer List w Software'!$B$4:$B$310,"<>Former client") -> 3757 | E10: =AVERAGEIFS('Customer List w Software'!$J$4:$J$310,'Customer List w Software'!$B$4:$B$310,"<>Former client") -> 1380.6344 | G10: =COUNTIFS('Customer List w Software'!$B$4:$B$310,"Former client") -> 133 | H10: =SUMIFS('Customer List w Software'!$K$4:$K$310,'Customer List w Software'!$B$4:$B$310,"Former client") -> 454 | I10: =AVERAGEIFS('Customer List w Software'!$J$4:$J$310,'Customer List w Software'!$B$4:$B$310,"Former client") -> 637.95417 | K10: =C10+G10 -> 307 | L10: =D10+H10 -> 4211 | M10: =K10/K$10 -> 1
B12: Trust / Accounting Software
B13: VRT | C13: =COUNTIFS('Customer List w Software'!$B$4:$B$310,"<>Former client",'Customer List w Software'!$W$4:$W$310,$B13) -> 117 | D13: =SUMIFS('Customer List w Software'!$K$4:$K$310,'Customer List w Software'!$B$4:$B$310,"<>Former client",'Customer List w Software'!$W$4:$W$310,$B13) -> 2999 | E13: =IFERROR(AVERAGEIFS('Customer List w Software'!$J$4:$J$310,'Customer List w Software'!$B$4:$B$310,"<>Former client",'Customer List w Software'!$W$4:$W$310,$B13),0) -> 1521.7699 | G13: =COUNTIFS('Customer List w Software'!$B$4:$B$310,"Former client",'Customer List w Software'!$W$4:$W$310,$B13) -> 6 | H13: =SUMIFS('Customer List w Software'!$K$4:$K$310,'Customer List w Software'!$B$4:$B$310,"Former client",'Customer List w Software'!$W$4:$W$310,$B13) -> 84 | I13: =IFERROR(AVERAGEIFS('Customer List w Software'!$J$4:$J$310,'Customer List w Software'!$B$4:$B$310,"Former client",'Customer List w Software'!$W$4:$W$310,$B13),0) -> 1230.2222 | K13: =C13+G13 -> 123 | L13: =D13+H13 -> 3083 | M13: =K13/K$18 -> 0.40065147
B14: VRP | C14: =COUNTIFS('Customer List w Software'!$B$4:$B$310,"<>Former client",'Customer List w Software'!$W$4:$W$310,$B14) -> 36 | D14: =SUMIFS('Customer List w Software'!$K$4:$K$310,'Customer List w Software'!$B$4:$B$310,"<>Former client",'Customer List w Software'!$W$4:$W$310,$B14) -> 659 | E14: =IFERROR(AVERAGEIFS('Customer List w Software'!$J$4:$J$310,'Customer List w Software'!$B$4:$B$310,"<>Former client",'Customer List w Software'!$W$4:$W$310,$B14),0) -> 1378.1986 | G14: =COUNTIFS('Customer List w Software'!$B$4:$B$310,"Former client",'Customer List w Software'!$W$4:$W$310,$B14) -> 8 | H14: =SUMIFS('Customer List w Software'!$K$4:$K$310,'Customer List w Software'!$B$4:$B$310,"Former client",'Customer List w Software'!$W$4:$W$310,$B14) -> 123 | I14: =IFERROR(AVERAGEIFS('Customer List w Software'!$J$4:$J$310,'Customer List w Software'!$B$4:$B$310,"Former client",'Customer List w Software'!$W$4:$W$310,$B14),0) -> 1073.6042 | K14: =C14+G14 -> 44 | L14: =D14+H14 -> 782 | M14: =K14/K$18 -> 0.14332248
B15: Guesty | C15: =COUNTIFS('Customer List w Software'!$B$4:$B$310,"<>Former client",'Customer List w Software'!$W$4:$W$310,$B15) -> 2 | D15: =SUMIFS('Customer List w Software'!$K$4:$K$310,'Customer List w Software'!$B$4:$B$310,"<>Former client",'Customer List w Software'!$W$4:$W$310,$B15) -> 47 | E15: =IFERROR(AVERAGEIFS('Customer List w Software'!$J$4:$J$310,'Customer List w Software'!$B$4:$B$310,"<>Former client",'Customer List w Software'!$W$4:$W$310,$B15),0) -> 1226.1667 | G15: =COUNTIFS('Customer List w Software'!$B$4:$B$310,"Former client",'Customer List w Software'!$W$4:$W$310,$B15) -> 2 | H15: =SUMIFS('Customer List w Software'!$K$4:$K$310,'Customer List w Software'!$B$4:$B$310,"Former client",'Customer List w Software'!$W$4:$W$310,$B15) -> 17 | I15: =IFERROR(AVERAGEIFS('Customer List w Software'!$J$4:$J$310,'Customer List w Software'!$B$4:$B$310,"Former client",'Customer List w Software'!$W$4:$W$310,$B15),0) -> 841.83333 | K15: =C15+G15 -> 4 | L15: =D15+H15 -> 64 | M15: =K15/K$18 -> 0.013029316
B16: Clearing | C16: =COUNTIFS('Customer List w Software'!$B$4:$B$310,"<>Former client",'Customer List w Software'!$W$4:$W$310,$B16) -> 1 | D16: =SUMIFS('Customer List w Software'!$K$4:$K$310,'Customer List w Software'!$B$4:$B$310,"<>Former client",'Customer List w Software'!$W$4:$W$310,$B16) -> 15 | E16: =IFERROR(AVERAGEIFS('Customer List w Software'!$J$4:$J$310,'Customer List w Software'!$B$4:$B$310,"<>Former client",'Customer List w Software'!$W$4:$W$310,$B16),0) -> 1662.5 | G16: =COUNTIFS('Customer List w Software'!$B$4:$B$310,"Former client",'Customer List w Software'!$W$4:$W$310,$B16) -> 3 | H16: =SUMIFS('Customer List w Software'!$K$4:$K$310,'Customer List w Software'!$B$4:$B$310,"Former client",'Customer List w Software'!$W$4:$W$310,$B16) -> 34 | I16: =IFERROR(AVERAGEIFS('Customer List w Software'!$J$4:$J$310,'Customer List w Software'!$B$4:$B$310,"Former client",'Customer List w Software'!$W$4:$W$310,$B16),0) -> 723.22222 | K16: =C16+G16 -> 4 | L16: =D16+H16 -> 49 | M16: =K16/K$18 -> 0.013029316
B17: None | C17: =COUNTIFS('Customer List w Software'!$B$4:$B$310,"<>Former client",'Customer List w Software'!$W$4:$W$310,"") -> 18 | D17: =SUMIFS('Customer List w Software'!$K$4:$K$310,'Customer List w Software'!$B$4:$B$310,"<>Former client",'Customer List w Software'!$W$4:$W$310,"") -> 37 | E17: =IFERROR(AVERAGEIFS('Customer List w Software'!$J$4:$J$310,'Customer List w Software'!$B$4:$B$310,"<>Former client",'Customer List w Software'!$W$4:$W$310,""),0) -> 469.62963 | G17: =COUNTIFS('Customer List w Software'!$B$4:$B$310,"Former client",'Customer List w Software'!$W$4:$W$310,"") -> 114 | H17: =SUMIFS('Customer List w Software'!$K$4:$K$310,'Customer List w Software'!$B$4:$B$310,"Former client",'Customer List w Software'!$W$4:$W$310,"") -> 196 | I17: =IFERROR(AVERAGEIFS('Customer List w Software'!$J$4:$J$310,'Customer List w Software'!$B$4:$B$310,"Former client",'Customer List w Software'!$W$4:$W$310,""),0) -> 570.38952 | K17: =C17+G17 -> 132 | L17: =D17+H17 -> 233 | M17: =K17/K$18 -> 0.42996743
B18: Total Clients | C18: =COUNTIFS('Customer List w Software'!$B$4:$B$310,"<>Former client") -> 174 | D18: =SUMIFS('Customer List w Software'!$K$4:$K$310,'Customer List w Software'!$B$4:$B$310,"<>Former client") -> 3757 | E18: =AVERAGEIFS('Customer List w Software'!$J$4:$J$310,'Customer List w Software'!$B$4:$B$310,"<>Former client") -> 1380.6344 | G18: =COUNTIFS('Customer List w Software'!$B$4:$B$310,"Former client") -> 133 | H18: =SUMIFS('Customer List w Software'!$K$4:$K$310,'Customer List w Software'!$B$4:$B$310,"Former client") -> 454 | I18: =AVERAGEIFS('Customer List w Software'!$J$4:$J$310,'Customer List w Software'!$B$4:$B$310,"Former client") -> 637.95417 | K18: =C18+G18 -> 307 | L18: =D18+H18 -> 4211 | M18: =K18/K$18 -> 1
B20: Property Management System (PMS)
B21: Guesty | C21: =COUNTIFS('Customer List w Software'!$B$4:$B$310,"<>Former client",'Customer List w Software'!$X$4:$X$310,$B21) -> 51 | D21: =SUMIFS('Customer List w Software'!$K$4:$K$310,'Customer List w Software'!$B$4:$B$310,"<>Former client",'Customer List w Software'!$X$4:$X$310,$B21) -> 1338 | E21: =IFERROR(AVERAGEIFS('Customer List w Software'!$J$4:$J$310,'Customer List w Software'!$B$4:$B$310,"<>Former client",'Customer List w Software'!$X$4:$X$310,$B21),0) -> 1661.0776 | G21: =COUNTIFS('Customer List w Software'!$B$4:$B$310,"Former client",'Customer List w Software'!$X$4:$X$310,$B21) -> 6 | H21: =SUMIFS('Customer List w Software'!$K$4:$K$310,'Customer List w Software'!$B$4:$B$310,"Former client",'Customer List w Software'!$X$4:$X$310,$B21) -> 70 | I21: =IFERROR(AVERAGEIFS('Customer List w Software'!$J$4:$J$310,'Customer List w Software'!$B$4:$B$310,"Former client",'Customer List w Software'!$X$4:$X$310,$B21),0) -> 976.33333 | K21: =C21+G21 -> 57 | L21: =D21+H21 -> 1408 | M21: =K21/K$29 -> 0.18566775
B22: Hospitable | C22: =COUNTIFS('Customer List w Software'!$B$4:$B$310,"<>Former client",'Customer List w Software'!$X$4:$X$310,$B22) -> 48 | D22: =SUMIFS('Customer List w Software'!$K$4:$K$310,'Customer List w Software'!$B$4:$B$310,"<>Former client",'Customer List w Software'!$X$4:$X$310,$B22) -> 829 | E22: =IFERROR(AVERAGEIFS('Customer List w Software'!$J$4:$J$310,'Customer List w Software'!$B$4:$B$310,"<>Former client",'Customer List w Software'!$X$4:$X$310,$B22),0) -> 1090.3717 | G22: =COUNTIFS('Customer List w Software'!$B$4:$B$310,"Former client",'Customer List w Software'!$X$4:$X$310,$B22) -> 2 | H22: =SUMIFS('Customer List w Software'!$K$4:$K$310,'Customer List w Software'!$B$4:$B$310,"Former client",'Customer List w Software'!$X$4:$X$310,$B22) -> 0 | I22: =IFERROR(AVERAGEIFS('Customer List w Software'!$J$4:$J$310,'Customer List w Software'!$B$4:$B$310,"Former client",'Customer List w Software'!$X$4:$X$310,$B22),0) -> 459 | K22: =C22+G22 -> 50 | L22: =D22+H22 -> 829 | M22: =K22/K$29 -> 0.16286645
B23: OwnerRez | C23: =COUNTIFS('Customer List w Software'!$B$4:$B$310,"<>Former client",'Customer List w Software'!$X$4:$X$310,$B23) -> 24 | D23: =SUMIFS('Customer List w Software'!$K$4:$K$310,'Customer List w Software'!$B$4:$B$310,"<>Former client",'Customer List w Software'!$X$4:$X$310,$B23) -> 438 | E23: =IFERROR(AVERAGEIFS('Customer List w Software'!$J$4:$J$310,'Customer List w Software'!$B$4:$B$310,"<>Former client",'Customer List w Software'!$X$4:$X$310,$B23),0) -> 1275.3854 | G23: =COUNTIFS('Customer List w Software'!$B$4:$B$310,"Former client",'Customer List w Software'!$X$4:$X$310,$B23) -> 5 | H23: =SUMIFS('Customer List w Software'!$K$4:$K$310,'Customer List w Software'!$B$4:$B$310,"Former client",'Customer List w Software'!$X$4:$X$310,$B23) -> 48 | I23: =IFERROR(AVERAGEIFS('Customer List w Software'!$J$4:$J$310,'Customer List w Software'!$B$4:$B$310,"Former client",'Customer List w Software'!$X$4:$X$310,$B23),0) -> 833.16667 | K23: =C23+G23 -> 29 | L23: =D23+H23 -> 486 | M23: =K23/K$29 -> 0.094462541
B24: Hostaway | C24: =COUNTIFS('Customer List w Software'!$B$4:$B$310,"<>Former client",'Customer List w Software'!$X$4:$X$310,$B24) -> 20 | D24: =SUMIFS('Customer List w Software'!$K$4:$K$310,'Customer List w Software'!$B$4:$B$310,"<>Former client",'Customer List w Software'!$X$4:$X$310,$B24) -> 544 | E24: =IFERROR(AVERAGEIFS('Customer List w Software'!$J$4:$J$310,'Customer List w Software'!$B$4:$B$310,"<>Former client",'Customer List w Software'!$X$4:$X$310,$B24),0) -> 1667.55 | G24: =COUNTIFS('Customer List w Software'!$B$4:$B$310,"Former client",'Customer List w Software'!$X$4:$X$310,$B24) -> 2 | H24: =SUMIFS('Customer List w Software'!$K$4:$K$310,'Customer List w Software'!$B$4:$B$310,"Former client",'Customer List w Software'!$X$4:$X$310,$B24) -> 29 | I24: =IFERROR(AVERAGEIFS('Customer List w Software'!$J$4:$J$310,'Customer List w Software'!$B$4:$B$310,"Former client",'Customer List w Software'!$X$4:$X$310,$B24),0) -> 375 | K24: =C24+G24 -> 22 | L24: =D24+H24 -> 573 | M24: =K24/K$29 -> 0.071661238
B25: Hostfully | C25: =COUNTIFS('Customer List w Software'!$B$4:$B$310,"<>Former client",'Customer List w Software'!$X$4:$X$310,$B25) -> 8 | D25: =SUMIFS('Customer List w Software'!$K$4:$K$310,'Customer List w Software'!$B$4:$B$310,"<>Former client",'Customer List w Software'!$X$4:$X$310,$B25) -> 152 | E25: =IFERROR(AVERAGEIFS('Customer List w Software'!$J$4:$J$310,'Customer List w Software'!$B$4:$B$310,"<>Former client",'Customer List w Software'!$X$4:$X$310,$B25),0) -> 1303.4375 | G25: =COUNTIFS('Customer List w Software'!$B$4:$B$310,"Former client",'Customer List w Software'!$X$4:$X$310,$B25) -> 0 | H25: =SUMIFS('Customer List w Software'!$K$4:$K$310,'Customer List w Software'!$B$4:$B$310,"Former client",'Customer List w Software'!$X$4:$X$310,$B25) -> 0 | I25: =IFERROR(AVERAGEIFS('Customer List w Software'!$J$4:$J$310,'Customer List w Software'!$B$4:$B$310,"Former client",'Customer List w Software'!$X$4:$X$310,$B25),0) -> 0 | K25: =C25+G25 -> 8 | L25: =D25+H25 -> 152 | M25: =K25/K$29 -> 0.026058632
B26: Lodgify | C26: =COUNTIFS('Customer List w Software'!$B$4:$B$310,"<>Former client",'Customer List w Software'!$X$4:$X$310,$B26) -> 1 | D26: =SUMIFS('Customer List w Software'!$K$4:$K$310,'Customer List w Software'!$B$4:$B$310,"<>Former client",'Customer List w Software'!$X$4:$X$310,$B26) -> 29 | E26: =IFERROR(AVERAGEIFS('Customer List w Software'!$J$4:$J$310,'Customer List w Software'!$B$4:$B$310,"<>Former client",'Customer List w Software'!$X$4:$X$310,$B26),0) -> 2639 | G26: =COUNTIFS('Customer List w Software'!$B$4:$B$310,"Former client",'Customer List w Software'!$X$4:$X$310,$B26) -> 0 | H26: =SUMIFS('Customer List w Software'!$K$4:$K$310,'Customer List w Software'!$B$4:$B$310,"Former client",'Customer List w Software'!$X$4:$X$310,$B26) -> 0 | I26: =IFERROR(AVERAGEIFS('Customer List w Software'!$J$4:$J$310,'Customer List w Software'!$B$4:$B$310,"Former client",'Customer List w Software'!$X$4:$X$310,$B26),0) -> 0 | K26: =C26+G26 -> 1 | L26: =D26+H26 -> 29 | M26: =K26/K$29 -> 0.003257329
B27: Multiple Platforms | C27: =COUNTIFS('Customer List w Software'!$B$4:$B$310,"<>Former client",'Customer List w Software'!$X$4:$X$310,"*,*") -> 4 | D27: =SUMIFS('Customer List w Software'!$K$4:$K$310,'Customer List w Software'!$B$4:$B$310,"<>Former client",'Customer List w Software'!$X$4:$X$310,"*,*") -> 98 | E27: =IFERROR(AVERAGEIFS('Customer List w Software'!$J$4:$J$310,'Customer List w Software'!$B$4:$B$310,"<>Former client",'Customer List w Software'!$X$4:$X$310,"*,*"),0) -> 1695.7042 | G27: =COUNTIFS('Customer List w Software'!$B$4:$B$310,"Former client",'Customer List w Software'!$X$4:$X$310,"*,*") -> 0 | H27: =SUMIFS('Customer List w Software'!$K$4:$K$310,'Customer List w Software'!$B$4:$B$310,"Former client",'Customer List w Software'!$X$4:$X$310,"*,*") -> 0 | I27: =IFERROR(AVERAGEIFS('Customer List w Software'!$J$4:$J$310,'Customer List w Software'!$B$4:$B$310,"Former client",'Customer List w Software'!$X$4:$X$310,"*,*"),0) -> 0 | K27: =C27+G27 -> 4 | L27: =D27+H27 -> 98 | M27: =K27/K$29 -> 0.013029316
B28: None | C28: =COUNTIFS('Customer List w Software'!$B$4:$B$310,"<>Former client",'Customer List w Software'!$X$4:$X$310,"") -> 18 | D28: =SUMIFS('Customer List w Software'!$K$4:$K$310,'Customer List w Software'!$B$4:$B$310,"<>Former client",'Customer List w Software'!$X$4:$X$310,"") -> 329 | E28: =IFERROR(AVERAGEIFS('Customer List w Software'!$J$4:$J$310,'Customer List w Software'!$B$4:$B$310,"<>Former client",'Customer List w Software'!$X$4:$X$310,""),0) -> 1076.0017 | G28: =COUNTIFS('Customer List w Software'!$B$4:$B$310,"Former client",'Customer List w Software'!$X$4:$X$310,"") -> 118 | H28: =SUMIFS('Customer List w Software'!$K$4:$K$310,'Customer List w Software'!$B$4:$B$310,"Former client",'Customer List w Software'!$X$4:$X$310,"") -> 307 | I28: =IFERROR(AVERAGEIFS('Customer List w Software'!$J$4:$J$310,'Customer List w Software'!$B$4:$B$310,"Former client",'Customer List w Software'!$X$4:$X$310,""),0) -> 619.96671 | K28: =C28+G28 -> 136 | L28: =D28+H28 -> 636 | M28: =K28/K$29 -> 0.44299674
B29: Total Clients | C29: =COUNTIFS('Customer List w Software'!$B$4:$B$310,"<>Former client") -> 174 | D29: =SUMIFS('Customer List w Software'!$K$4:$K$310,'Customer List w Software'!$B$4:$B$310,"<>Former client") -> 3757 | E29: =AVERAGEIFS('Customer List w Software'!$J$4:$J$310,'Customer List w Software'!$B$4:$B$310,"<>Former client") -> 1380.6344 | G29: =COUNTIFS('Customer List w Software'!$B$4:$B$310,"Former client") -> 133 | H29: =SUMIFS('Customer List w Software'!$K$4:$K$310,'Customer List w Software'!$B$4:$B$310,"Former client") -> 454 | I29: =AVERAGEIFS('Customer List w Software'!$J$4:$J$310,'Customer List w Software'!$B$4:$B$310,"Former client") -> 637.95417 | K29: =C29+G29 -> 307 | L29: =D29+H29 -> 4211 | M29: =K29/K$29 -> 1
B31: Expense Tool
B32: Topkey | C32: =COUNTIFS('Customer List w Software'!$B$4:$B$310,"<>Former client",'Customer List w Software'!$Y$4:$Y$310,$B32) -> 48 | D32: =SUMIFS('Customer List w Software'!$K$4:$K$310,'Customer List w Software'!$B$4:$B$310,"<>Former client",'Customer List w Software'!$Y$4:$Y$310,$B32) -> 1841 | E32: =IFERROR(AVERAGEIFS('Customer List w Software'!$J$4:$J$310,'Customer List w Software'!$B$4:$B$310,"<>Former client",'Customer List w Software'!$Y$4:$Y$310,$B32),0) -> 2389.2051 | G32: =COUNTIFS('Customer List w Software'!$B$4:$B$310,"Former client",'Customer List w Software'!$Y$4:$Y$310,$B32) -> 4 | H32: =SUMIFS('Customer List w Software'!$K$4:$K$310,'Customer List w Software'!$B$4:$B$310,"Former client",'Customer List w Software'!$Y$4:$Y$310,$B32) -> 120 | I32: =IFERROR(AVERAGEIFS('Customer List w Software'!$J$4:$J$310,'Customer List w Software'!$B$4:$B$310,"Former client",'Customer List w Software'!$Y$4:$Y$310,$B32),0) -> 2159.8333 | K32: =C32+G32 -> 52 | L32: =D32+H32 -> 1961 | M32: =K32/K$36 -> 0.16938111
B33: Bill.com | C33: =COUNTIFS('Customer List w Software'!$B$4:$B$310,"<>Former client",'Customer List w Software'!$Y$4:$Y$310,$B33) -> 12 | D33: =SUMIFS('Customer List w Software'!$K$4:$K$310,'Customer List w Software'!$B$4:$B$310,"<>Former client",'Customer List w Software'!$Y$4:$Y$310,$B33) -> 231 | E33: =IFERROR(AVERAGEIFS('Customer List w Software'!$J$4:$J$310,'Customer List w Software'!$B$4:$B$310,"<>Former client",'Customer List w Software'!$Y$4:$Y$310,$B33),0) -> 1409.9444 | G33: =COUNTIFS('Customer List w Software'!$B$4:$B$310,"Former client",'Customer List w Software'!$Y$4:$Y$310,$B33) -> 1 | H33: =SUMIFS('Customer List w Software'!$K$4:$K$310,'Customer List w Software'!$B$4:$B$310,"Former client",'Customer List w Software'!$Y$4:$Y$310,$B33) -> 0 | I33: =IFERROR(AVERAGEIFS('Customer List w Software'!$J$4:$J$310,'Customer List w Software'!$B$4:$B$310,"Former client",'Customer List w Software'!$Y$4:$Y$310,$B33),0) -> 540 | K33: =C33+G33 -> 13 | L33: =D33+H33 -> 231 | M33: =K33/K$36 -> 0.042345277
B34: Ramp | C34: =COUNTIFS('Customer List w Software'!$B$4:$B$310,"<>Former client",'Customer List w Software'!$Y$4:$Y$310,$B34) -> 0 | D34: =SUMIFS('Customer List w Software'!$K$4:$K$310,'Customer List w Software'!$B$4:$B$310,"<>Former client",'Customer List w Software'!$Y$4:$Y$310,$B34) -> 0 | E34: =IFERROR(AVERAGEIFS('Customer List w Software'!$J$4:$J$310,'Customer List w Software'!$B$4:$B$310,"<>Former client",'Customer List w Software'!$Y$4:$Y$310,$B34),0) -> 0 | G34: =COUNTIFS('Customer List w Software'!$B$4:$B$310,"Former client",'Customer List w Software'!$Y$4:$Y$310,$B34) -> 1 | H34: =SUMIFS('Customer List w Software'!$K$4:$K$310,'Customer List w Software'!$B$4:$B$310,"Former client",'Customer List w Software'!$Y$4:$Y$310,$B34) -> 0 | I34: =IFERROR(AVERAGEIFS('Customer List w Software'!$J$4:$J$310,'Customer List w Software'!$B$4:$B$310,"Former client",'Customer List w Software'!$Y$4:$Y$310,$B34),0) -> 486.33333 | K34: =C34+G34 -> 1 | L34: =D34+H34 -> 0 | M34: =K34/K$36 -> 0.003257329
B35: None | C35: =COUNTIFS('Customer List w Software'!$B$4:$B$310,"<>Former client",'Customer List w Software'!$Y$4:$Y$310,"") -> 114 | D35: =SUMIFS('Customer List w Software'!$K$4:$K$310,'Customer List w Software'!$B$4:$B$310,"<>Former client",'Customer List w Software'!$Y$4:$Y$310,"") -> 1685 | E35: =IFERROR(AVERAGEIFS('Customer List w Software'!$J$4:$J$310,'Customer List w Software'!$B$4:$B$310,"<>Former client",'Customer List w Software'!$Y$4:$Y$310,""),0) -> 952.88787 | G35: =COUNTIFS('Customer List w Software'!$B$4:$B$310,"Former client",'Customer List w Software'!$Y$4:$Y$310,"") -> 127 | H35: =SUMIFS('Customer List w Software'!$K$4:$K$310,'Customer List w Software'!$B$4:$B$310,"Former client",'Customer List w Software'!$Y$4:$Y$310,"") -> 334 | I35: =IFERROR(AVERAGEIFS('Customer List w Software'!$J$4:$J$310,'Customer List w Software'!$B$4:$B$310,"Former client",'Customer List w Software'!$Y$4:$Y$310,""),0) -> 591.98613 | K35: =C35+G35 -> 241 | L35: =D35+H35 -> 2019 | M35: =K35/K$36 -> 0.78501629
B36: Total Clients | C36: =COUNTIFS('Customer List w Software'!$B$4:$B$310,"<>Former client") -> 174 | D36: =SUMIFS('Customer List w Software'!$K$4:$K$310,'Customer List w Software'!$B$4:$B$310,"<>Former client") -> 3757 | E36: =AVERAGEIFS('Customer List w Software'!$J$4:$J$310,'Customer List w Software'!$B$4:$B$310,"<>Former client") -> 1380.6344 | G36: =COUNTIFS('Customer List w Software'!$B$4:$B$310,"Former client") -> 133 | H36: =SUMIFS('Customer List w Software'!$K$4:$K$310,'Customer List w Software'!$B$4:$B$310,"Former client") -> 454 | I36: =AVERAGEIFS('Customer List w Software'!$J$4:$J$310,'Customer List w Software'!$B$4:$B$310,"Former client") -> 637.95417 | K36: =C36+G36 -> 307 | L36: =D36+H36 -> 4211 | M36: =K36/K$36 -> 1
B38: Reference
B39: Current clients = status "Active" or "Onboarding"; Former clients = status "Former client"
B40: Active clients | C40: =COUNTIFS('Customer List w Software'!$B$4:$B$310,"Active") -> 163
B41: Onboarding clients | C41: =COUNTIFS('Customer List w Software'!$B$4:$B$310,"Onboarding") -> 11
B42: Note: "Multiple Platforms" captures clients listing two PMS platforms; property counts are blank for clients with no listing data, so Properties will understate for those rows.
B44: Tie-Out: Avg. Fee per Current Client | C44: Monthly | D44: Annual
B45: Software Overview — current clients (row 10) | C45: =+E10 -> 1380.6344 | D45: =C45*12 -> 16567.613
B46: Client Retention $ — avg. annual fee per client (Sep-26) | C46: =D46/12 -> 1355.1213 | D46: =+'Client Retention $'!AD16*1000 -> 16261.456
B47: Variance | C47: =C45-C46 -> 25.513115 | D47: =D45-D46 -> 306.15738
...

Sheet Earnings Sensitivity Table
B2: =+Cover!B24 -> Keystone Bookkeepers
B3: Earnings & Valuation Sensitivity ($000s)
B5: Base Case Inputs
B6: Steady-State Adj. EBITDA (PF July'26) | C6: ='P&L Forecast'!$K$106 -> 468.56306
B7: Normalized Bookkeeper Staffing Cost | C7: ='P&L Forecast'!$C$185 -> 272.46938
B8: Current Bookkeeping Clients | C8: ='P&L Forecast'!$C$181 -> 177
B9: Target Load (Clients per Bookkeeper) | C9: ='P&L Forecast'!$C$182 -> 8
B10: Avg. Bookkeeper Compensation | C10: ='P&L Forecast'!$C$184 -> 12.315
B11: EV / EBITDA Multiple (base) | C11: 7
B13: Implied Valuation — Steady-State Adj. EBITDA × Multiple
C14: Steady-State Bookkeeper Load (Clients per Bookkeeper)
B15: EV / EBITDA Multiple | C15: =$C$9-3 -> 5 | D15: =$C$9-2 -> 6 | E15: =$C$9-1 -> 7 | F15: =$C$9+0 -> 8 | G15: =$C$9+1 -> 9 | H15: =$C$9+2 -> 10 | I15: =$C$9+3 -> 11
B16: =$C$11-2 -> 5 | C16: =($C$6+$C$7-($C$8/C$15)*$C$10)*$B16 -> 1525.4072 | D16: =($C$6+$C$7-($C$8/D$15)*$C$10)*$B16 -> 1888.6997 | E16: =($C$6+$C$7-($C$8/E$15)*$C$10)*$B16 -> 2148.1943 | F16: =($C$6+$C$7-($C$8/F$15)*$C$10)*$B16 -> 2342.8153 | G16: =($C$6+$C$7-($C$8/G$15)*$C$10)*$B16 -> 2494.1872 | H16: =($C$6+$C$7-($C$8/H$15)*$C$10)*$B16 -> 2615.2847 | I16: =($C$6+$C$7-($C$8/I$15)*$C$10)*$B16 -> 2714.3644
B17: =$C$11-1 -> 6 | C17: =($C$6+$C$7-($C$8/C$15)*$C$10)*$B17 -> 1830.4886 | D17: =($C$6+$C$7-($C$8/D$15)*$C$10)*$B17 -> 2266.4396 | E17: =($C$6+$C$7-($C$8/E$15)*$C$10)*$B17 -> 2577.8332 | F17: =($C$6+$C$7-($C$8/F$15)*$C$10)*$B17 -> 2811.3783 | G17: =($C$6+$C$7-($C$8/G$15)*$C$10)*$B17 -> 2993.0246 | H17: =($C$6+$C$7-($C$8/H$15)*$C$10)*$B17 -> 3138.3416 | I17: =($C$6+$C$7-($C$8/I$15)*$C$10)*$B17 -> 3257.2373
B18: =$C$11+0 -> 7 | C18: =($C$6+$C$7-($C$8/C$15)*$C$10)*$B18 -> 2135.57 | D18: =($C$6+$C$7-($C$8/D$15)*$C$10)*$B18 -> 2644.1795 | E18: =($C$6+$C$7-($C$8/E$15)*$C$10)*$B18 -> 3007.472 | F18: =($C$6+$C$7-($C$8/F$15)*$C$10)*$B18 -> 3279.9414 | G18: =($C$6+$C$7-($C$8/G$15)*$C$10)*$B18 -> 3491.862 | H18: =($C$6+$C$7-($C$8/H$15)*$C$10)*$B18 -> 3661.3985 | I18: =($C$6+$C$7-($C$8/I$15)*$C$10)*$B18 -> 3800.1102
B19: =$C$11+1 -> 8 | C19: =($C$6+$C$7-($C$8/C$15)*$C$10)*$B19 -> 2440.6515 | D19: =($C$6+$C$7-($C$8/D$15)*$C$10)*$B19 -> 3021.9195 | E19: =($C$6+$C$7-($C$8/E$15)*$C$10)*$B19 -> 3437.1109 | F19: =($C$6+$C$7-($C$8/F$15)*$C$10)*$B19 -> 3748.5045 | G19: =($C$6+$C$7-($C$8/G$15)*$C$10)*$B19 -> 3990.6995 | H19: =($C$6+$C$7-($C$8/H$15)*$C$10)*$B19 -> 4184.4555 | I19: =($C$6+$C$7-($C$8/I$15)*$C$10)*$B19 -> 4342.9831
