Workbook

Sheet Cover
B24: Keystone Bookkeepers
B25: Pre-LOI Business Analysis
B26: ="As of "&TEXT(TODAY(),"mm/dd/yy") -> As of 09/24/26

Sheet Offer Overview
B2: =Cover!$B$24 -> Keystone Bookkeepers
B3: Offer & Equity Upside Scenarios ($000s) | G3: Print | H3: 1
B5: Offer Breakdown | C5: Today
B6: Run-Rate Revenue (PF Jul'26) | C6: ='P&L Overview'!$K$16 -> 2998.541
B7: (x) Revenue Multiple — Implied | C7: =IFERROR($C$8/$C$6,0) -> 1.0004866
B8: Total Valuation — Offer Price | C8: 3000
B9: (-) Cash at Close | C9: 650
B10: Topkey Equity Consideration | C10: =C8-C9 -> 2350
B12: Topkey Pre-Deal Valuation | C12: ='Offer Comparison'!$C$9 -> 60000
B13: (+) Keystone Value Acquired | C13: =$C$8 -> 3000
B14: (-) Cash Paid at Close | C14: =$C$9 -> 650
B15: Topkey Post-Money Valuation | C15: =C12+C13-C14 -> 62350
B16: Ben's Implied Topkey Ownership % | C16: =IFERROR($C$10/$C$15,0) -> 0.037690457
B17: Keystone Enterprise Value Today | C17: =$C$8 -> 3000
B18: Existing Shareholders' Value Post-Close | C18: =(1-$C$16)*$C$15 -> 60000
B20: Topkey Pre-Deal Valuation | C20: =$C$12 -> 60000
B21: (-) Cash Paid at Close | C21: =$C$14 -> 650
B22: Topkey ex-Keystone Growth Base | C22: =C20-C21 -> 59350
B24: Scenario 1 — Ben Retains 100% of Keystone | C24: Today | D24: 2.0x Valuation | E24: 3.0x Valuation
B25: Keystone Growth Multiple | C25: 1 | D25: 2 | E25: 3
B26: Keystone Enterprise Value | C26: =$C$17*C$25 -> 3000 | D26: =$C$17*D$25 -> 6000 | E26: =$C$17*E$25 -> 9000
B27: Ben's Ownership % — Keystone | C27: 1 | D27: =$C$27 -> 1 | E27: =$C$27 -> 1
B28: Ben's Keystone Equity Value | C28: =C26*$C$27 -> 3000 | D28: =D26*$C$27 -> 6000 | E28: =E26*$C$27 -> 9000
B29: (-) Value at Offer Today | C29: =$C$28 -> 3000 | D29: =$C$28 -> 3000 | E29: =$C$28 -> 3000
B30: Ben's Net Gain vs. Today | C30: =C28-C29 -> 0 | D30: =D28-D29 -> 3000 | E30: =E28-E29 -> 6000
B32: Combined Topkey + Keystone TEV | C32: Growth (ex-Keystone) | D32: =D$24 -> 2.0x Valuation | E32: =E$24 -> 3.0x Valuation
B33: Topkey Grows Half as Fast as Keystone | C33: 0.5 | D33: =$C$22*(1+(D$25-1)*$C33)+$C$17*D$25 -> 95025 | E33: =$C$22*(1+(E$25-1)*$C33)+$C$17*E$25 -> 127700
B34: Topkey Keeps Pace with Keystone | C34: 1 | D34: =$C$22*(1+(D$25-1)*$C34)+$C$17*D$25 -> 124700 | E34: =$C$22*(1+(E$25-1)*$C34)+$C$17*E$25 -> 187050
B35: Topkey Outgrows Keystone | C35: 1.5 | D35: =$C$22*(1+(D$25-1)*$C35)+$C$17*D$25 -> 154375 | E35: =$C$22*(1+(E$25-1)*$C35)+$C$17*E$25 -> 246400
B37: Ben's Total Value — Cash + Topkey Equity | D37: =+D$32 -> 2.0x Valuation | E37: =+E$32 -> 3.0x Valuation
B38: =$B33 -> Topkey Grows Half as Fast as Keystone | D38: =$C$9+$C$16*D33 -> 4231.5357 | E38: =$C$9+$C$16*E33 -> 5463.0714
B39: =$B34 -> Topkey Keeps Pace with Keystone | D39: =$C$9+$C$16*D34 -> 5350 | E39: =$C$9+$C$16*E34 -> 7700
B40: =$B35 -> Topkey Outgrows Keystone | D40: =$C$9+$C$16*D35 -> 6468.4643 | E40: =$C$9+$C$16*E35 -> 9936.9286
B42: Delta vs. Scenario 1 | D42: =+D$32 -> 2.0x Valuation | E42: =+E$32 -> 3.0x Valuation
B43: =$B33 -> Topkey Grows Half as Fast as Keystone | D43: =D38-D$28 -> -1768.4643 | E43: =E38-E$28 -> -3536.9286
B44: =$B34 -> Topkey Keeps Pace with Keystone | D44: =D39-D$28 -> -650 | E44: =E39-E$28 -> -1300
B45: =$B35 -> Topkey Outgrows Keystone | D45: =D40-D$28 -> 468.46431 | E45: =E40-E$28 -> 936.92863
B47: Topkey Growth Required for Parity | D47: =+D$32 -> 2.0x Valuation | E47: =+E$32 -> 3.0x Valuation
B48: Ben's Value — Scenario 1 (Retain 100%) | D48: =D$28 -> 6000 | E48: =E$28 -> 9000
B49: (-) Ben's Cash at Close | D49: =$C$9 -> 650 | E49: =$C$9 -> 650
...

Sheet Offer Comparison
B2: =Cover!$B$24 -> Keystone Bookkeepers
B3: Offer Comparison — Partnership vs. 100% Buyout ($000s) | H3: Print | I3: 0
B5: Offer Comparison | C5: Partnership | D5: 100% Buyout | E5: Variance | G5: Notes
B6: Deal Assumptions
B7: Horizon (Years) | C7: 5 | D7: =C7 -> 5 | E7: =C7-D7 -> 0 | G7: Input — drives Partnership and Buyout tabs (D = C)
B8: Est. Topkey Dilution — Ben's Stake (Year 5) | C8: 0.05 | D8: =C8 -> 0.05 | E8: =C8-D8 -> 0 | G8: Input — drives Partnership and Buyout tabs (D = C)
B9: Topkey Valuation Today — Pre-Deal | C9: 60000 | D9: =C9 -> 60000 | E9: =C9-D9 -> 0 | G9: Input — single Topkey valuation; drives Offer Overview, Partnership and Buyout tabs
B10: Topkey 5-Year Valuation Growth (ex-Keystone) | C10: ='Partnership Analysis'!$C$19 -> 2.021904 | D10: ='100% Buyout Analysis'!$C$18 -> 2.0084034 | E10: =C10-D10 -> 0.013500598 | G10: Differs because the ex-Keystone base is net of each offer's cash at close
B11: Keystone 5-Yr Revenue Increase — Standalone (% of Start) | C11: =IFERROR('Partnership Analysis'!$C$28/'Partnership Analysis'!$C$47,0) -> 0.99837392 | D11: =IFERROR('100% Buyout Analysis'!$C$27/'100% Buyout Analysis'!$C$46,0) -> 0.99837392 | E11: =C11-D11 -> 0 | G11: Total additional revenue ÷ Keystone revenue at close ($2,999)
B12: Keystone 5-Yr Revenue Increase — Partnership (% of Start) | C12: =IFERROR('Partnership Analysis'!$C$42/'Partnership Analysis'!$C$47,0) -> 1.3311652 | D12: =IFERROR('100% Buyout Analysis'!$C$41/'100% Buyout Analysis'!$C$46,0) -> 1.3311652 | E12: =C12-D12 -> 0 | G12: Total additional revenue ÷ Keystone revenue at close ($2,999)
B13: Keystone Initial Revenue Multiple | C13: 1 | D13: =C13 -> 1 | E13: =C13-D13 -> 0 | G13: Input — drives Partnership and Buyout tabs (D = C)
B14: Keystone Scaled Revenue Multiple | C14: 1.25 | D14: =C14 -> 1.25 | E14: =C14-D14 -> 0 | G14: Input — drives Partnership and Buyout tabs (D = C)
B15: Keystone Software-Integration Revenue Multiple | C15: 2 | D15: =C15 -> 2 | E15: =C15-D15 -> 0 | G15: Input — drives Partnership and Buyout tabs (D = C)
B17: Offer Structure
B18: Keystone Value Today (100%) | C18: ='Partnership Analysis'!$C$185 -> 3000 | D18: ='100% Buyout Analysis'!$C$173 -> 3000 | E18: =C18-D18 -> 0
B19: Ben's Rollover % — Keystone | C19: ='Partnership Analysis'!$C$186 -> 0.3 | D19: =1-'100% Buyout Analysis'!$C$96 -> 0 | E19: =C19-D19 -> 0.3 | G19: Buyout: 1 − Topkey stake acquired
B20: Keystone Stake Acquired by Topkey | C20: ='Partnership Analysis'!$C$187 -> 0.7 | D20: ='100% Buyout Analysis'!$C$96 -> 1 | E20: =C20-D20 -> -0.3
B21: Price for Topkey's Stake | C21: ='Partnership Analysis'!$C$188 -> 2100 | D21: ='100% Buyout Analysis'!$C$173 -> 3000 | E21: =C21-D21 -> -900
B22: (-) Cash at Close | C22: ='Partnership Analysis'!$C$189 -> 650 | D22: ='100% Buyout Analysis'!$C$174 -> 500 | E22: =C22-D22 -> 150
B23: Topkey Equity Issued to Ben | C23: ='Partnership Analysis'!$C$190 -> 1450 | D23: ='100% Buyout Analysis'!$C$175 -> 2500 | E23: =C23-D23 -> -1050
B24: (+) Target Cash Earnout (at 100% Achievement) — Year 3 | C24: ='Partnership Analysis'!$C$58 -> 0 | D24: ='100% Buyout Analysis'!$C$57 -> 500 | E24: =C24-D24 -> -500 | G24: Buyout: target $500K; capped at $750K. Partnership: no earnout
B25: (+) Cash at Close | C25: =C22 -> 650 | D25: =D22 -> 500 | E25: =C25-D25 -> 150 | G25: Note the $650K covers Ben's tax situation
B26: Total Consideration Paid by Topkey | C26: ='Partnership Analysis'!$C$106 -> 2100 | D26: ='100% Buyout Analysis'!$C$95 -> 3500 | E26: =C26-D26 -> -1400 | G26: Cash at close + equity issued + target earnout (at 100% achievement)
B27: % of Consideration in Cash (incl. Earnout) | C27: =IFERROR((C22+C24)/C26,0) -> 0.30952381 | D27: =IFERROR((D22+D24)/D26,0) -> 0.28571429 | E27: =C27-D27 -> 0.023809524
B29: Where Ben's Year 5 Value Comes From
B31: Retained Keystone Stake (Direct) | C31: =IFERROR(C94/C$99,0) -> 0.46170498 | D31: =IFERROR(D94/D$99,0) -> 0 | E31: =C31-D31 -> 0.46170498
B32: Keystone via Topkey | C32: =IFERROR(C95/C$99,0) -> 0.024149662 | D32: =IFERROR(D95/D$99,0) -> 0.063750321 | E32: =C32-D32 -> -0.039600659
B33: Topkey ex-Keystone | C33: =IFERROR(C96/C$99,0) -> 0.44258976 | D33: =IFERROR(D96/D$99,0) -> 0.81624844 | E33: =C33-D33 -> -0.37365868
B34: Cash at Close | C34: =IFERROR(C97/C$99,0) -> 0.071555598 | D34: =IFERROR(D97/D$99,0) -> 0.06000062 | E34: =C34-D34 -> 0.011554978
B35: Cash Earnout — Year 3 | C35: =IFERROR(C98/C$99,0) -> 0 | D35: =IFERROR(D98/D$99,0) -> 0.06000062 | E35: =C35-D35 -> -0.06000062
B37: Return Profile — Jon (Topkey) | K37: Helper: Year | L37: 0 | M37: 1 | N37: 2 | O37: 3 | P37: 4 | Q37: 5
B38: Cash at Close (Year 0) | C38: =C22 -> 650 | D38: =D22 -> 500 | E38: =C38-D38 -> 150 | K38: Helper: Partnership CF | L38: =-(L$37=0)*($C$22+$C$23)-(L$37=$L$40)*$C$24+(L$37=$C$7)*$C$42 -> -2100 | M38: =-(M$37=0)*($C$22+$C$23)-(M$37=$L$40)*$C$24+(M$37=$C$7)*$C$42 -> 0 | N38: =-(N$37=0)*($C$22+$C$23)-(N$37=$L$40)*$C$24+(N$37=$C$7)*$C$42 -> 0 | O38: =-(O$37=0)*($C$22+$C$23)-(O$37=$L$40)*$C$24+(O$37=$C$7)*$C$42 -> 0 | P38: =-(P$37=0)*($C$22+$C$23)-(P$37=$L$40)*$C$24+(P$37=$C$7)*$C$42 -> 0 | Q38: =-(Q$37=0)*($C$22+$C$23)-(Q$37=$L$40)*$C$24+(Q$37=$C$7)*$C$42 -> 9786.1324
B39: (+) Equity Issued to Ben (Year 0) | C39: =C23 -> 1450 | D39: =D23 -> 2500 | E39: =C39-D39 -> -1050 | K39: Helper: Buyout CF | L39: =-(L$37=0)*($D$22+$D$23)-(L$37=$L$40)*$D$24+(L$37=$D$7)*$D$42 -> -3000 | M39: =-(M$37=0)*($D$22+$D$23)-(M$37=$L$40)*$D$24+(M$37=$D$7)*$D$42 -> 0 | N39: =-(N$37=0)*($D$22+$D$23)-(N$37=$L$40)*$D$24+(N$37=$D$7)*$D$42 -> 0 | O39: =-(O$37=0)*($D$22+$D$23)-(O$37=$L$40)*$D$24+(O$37=$D$7)*$D$42 -> -500 | P39: =-(P$37=0)*($D$22+$D$23)-(P$37=$L$40)*$D$24+(P$37=$D$7)*$D$42 -> 0 | Q39: =-(Q$37=0)*($D$22+$D$23)-(Q$37=$L$40)*$D$24+(Q$37=$D$7)*$D$42 -> 13980.189
B40: (+) Target Cash Earnout (at 100% Achievement) (Year 3) | C40: =C24 -> 0 | D40: =D24 -> 500 | E40: =C40-D40 -> -500 | K40: Helper: Earnout Year | L40: ='100% Buyout Analysis'!$C$45 -> 3 | M40: Year the target earnout is paid — linked to 100% Buyout Analysis (Earnout Measurement Year)
B41: Total Invested by Jon (Topkey) | C41: =SUM(C38:C40) -> 2100 | D41: =SUM(D38:D40) -> 3500 | E41: =C41-D41 -> -1400 | G41: Ties to Total Consideration (row 26)
B42: Topkey's Keystone Stake — Year 5 Value | C42: ='Partnership Analysis'!$D$82 -> 9786.1324 | D42: ='100% Buyout Analysis'!$D$76 -> 13980.189 | E42: =C42-D42 -> -4194.0567 | G42: 70% (Partnership) or 100% (Buyout) of Keystone's Year 5 value
B43: Deal MOIC | C43: =IFERROR(C42/C41,0) -> 4.660063 | D43: =IFERROR(D42/D41,0) -> 3.9943397 | E43: =C43-D43 -> 0.66572329 | G43: Standard acquirer view: stake value ÷ consideration at issue price
B44: Deal IRR | C44: =IFERROR(IRR($L38:$Q38),0) -> 0.36043676 | D44: =IFERROR(IRR($L39:$Q39),0) -> 0.34242961 | E44: =C44-D44 -> 0.018007148 | G44: Cash-flow IRR; see helper cash flows in L38:Q39
B45: (-) Hurdle MOIC — Break-Even | C45: =IFERROR(C119/(C38+C39),0) -> 2.3809524 | D45: =IFERROR(D119/(D38+D39),0) -> 2.6666667 | E45: =C45-D45 -> -0.28571429 | G45: Break-even stake value (row 119) ÷ cash + stock; no earnout paid at break-even
B46: (-) Hurdle IRR — Break-Even | C46: =IFERROR(C45^(1/C$7)-1,0) -> 0.18946082 | D46: =IFERROR(D45^(1/D$7)-1,0) -> 0.21672868 | E46: =C46-D46 -> -0.027267862 | G46: Blended cost of Jon's currency: cash at 1.0x, stock at Topkey's 5-year growth
...

Sheet Partnership Sensitivity Tables
B2: =Cover!$B$24 -> Keystone Bookkeepers
B3: Partnership Sensitivity Tables ($000s) | N3: Print | O3: 0
B5: Ben's Return Profile Based on Partnerning
B6: Ben's Net Returns Based on Topkey Growth & Rollover %
D8: Topkey ex-Keystone Value Growth (%) | S8: Helper: IRR Year Index | Z8: Helper: Unrounded Net Return
D9: =E9-$G$274 -> 1 | E9: =F9-$G$274 -> 1.25 | F9: =G9-$G$274 -> 1.5 | G9: =H9-$G$274 -> 1.75 | H9: =$G$273 -> 2 | I9: =H9+$G$274 -> 2.25 | J9: =I9+$G$274 -> 2.5 | K9: =J9+$G$274 -> 2.75 | L9: =K9+$G$274 -> 3 | N9: Helper: Rollover % | O9: Helper: Cash at Close | P9: Helper: Topkey Equity Issued | Q9: Helper: Topkey ex-Keystone Today | R9: Helper: Ben's Yr 5 Topkey % | S9: 0 | T9: =S9+1 -> 1 | U9: =T9+1 -> 2 | V9: =U9+1 -> 3 | W9: =V9+1 -> 4 | X9: =W9+1 -> 5 | Z9: =D$9 -> 1 | AA9: =E$9 -> 1.25 | AB9: =F$9 -> 1.5 | AC9: =G$9 -> 1.75 | AD9: =H$9 -> 2 | AE9: =I$9 -> 2.25 | AF9: =J$9 -> 2.5 | AG9: =K$9 -> 2.75 | AH9: =L$9 -> 3 | AT9: Helper: Gradient Band (0 = below $1M hurdle)
B10: Ben's Rollover % | C10: =C11-$G$272 -> 0.15 | D10: =ROUND(Z10,$G$285) -> 3400 | E10: =ROUND(AA10,$G$285) -> 3800 | F10: =ROUND(AB10,$G$285) -> 4200 | G10: =ROUND(AC10,$G$285) -> 4600 | H10: =ROUND(AD10,$G$285) -> 5000 | I10: =ROUND(AE10,$G$285) -> 5400 | J10: =ROUND(AF10,$G$285) -> 5800 | K10: =ROUND(AG10,$G$285) -> 6200 | L10: =ROUND(AH10,$G$285) -> 6600 | N10: =$C10 -> 0.15 | O10: =$G$263*(1-N10)*$G$266 -> 789.28571 | P10: =$G$263*(1-N10)-O10 -> 1760.7143 | Q10: =$G$265-O10 -> 59210.714 | R10: =IFERROR(P10/(Q10+$G$263*(1-N10)),0)*(1-$G$267) -> 0.027083213 | Z10: =$O10+$G$268+$N10*$G$264+$R10*($Q10*(1+D$9)+$G$264*(1-$N10))-$G$263 -> 3415.381 | AA10: =$O10+$G$268+$N10*$G$264+$R10*($Q10*(1+E$9)+$G$264*(1-$N10))-$G$263 -> 3816.2851 | AB10: =$O10+$G$268+$N10*$G$264+$R10*($Q10*(1+F$9)+$G$264*(1-$N10))-$G$263 -> 4217.1892 | AC10: =$O10+$G$268+$N10*$G$264+$R10*($Q10*(1+G$9)+$G$264*(1-$N10))-$G$263 -> 4618.0933 | AD10: =$O10+$G$268+$N10*$G$264+$R10*($Q10*(1+H$9)+$G$264*(1-$N10))-$G$263 -> 5018.9974 | AE10: =$O10+$G$268+$N10*$G$264+$R10*($Q10*(1+I$9)+$G$264*(1-$N10))-$G$263 -> 5419.9015 | AF10: =$O10+$G$268+$N10*$G$264+$R10*($Q10*(1+J$9)+$G$264*(1-$N10))-$G$263 -> 5820.8056 | AG10: =$O10+$G$268+$N10*$G$264+$R10*($Q10*(1+K$9)+$G$264*(1-$N10))-$G$263 -> 6221.7097 | AH10: =$O10+$G$268+$N10*$G$264+$R10*($Q10*(1+L$9)+$G$264*(1-$N10))-$G$263 -> 6622.6138 | AT10: =IF(Z50<$G$282,0,MIN($G$279,1+IFERROR(INT((Z50-$G$282)/$G$284),0))) -> 0 | AU10: =IF(AA50<$G$282,0,MIN($G$279,1+IFERROR(INT((AA50-$G$282)/$G$284),0))) -> 0 | AV10: =IF(AB50<$G$282,0,MIN($G$279,1+IFERROR(INT((AB50-$G$282)/$G$284),0))) -> 0 | AW10: =IF(AC50<$G$282,0,MIN($G$279,1+IFERROR(INT((AC50-$G$282)/$G$284),0))) -> 0 | AX10: =IF(AD50<$G$282,0,MIN($G$279,1+IFERROR(INT((AD50-$G$282)/$G$284),0))) -> 0 | AY10: =IF(AE50<$G$282,0,MIN($G$279,1+IFERROR(INT((AE50-$G$282)/$G$284),0))) -> 0 | AZ10: =IF(AF50<$G$282,0,MIN($G$279,1+IFERROR(INT((AF50-$G$282)/$G$284),0))) -> 2 | BA10: =IF(AG50<$G$282,0,MIN($G$279,1+IFERROR(INT((AG50-$G$282)/$G$284),0))) -> 3 | BB10: =IF(AH50<$G$282,0,MIN($G$279,1+IFERROR(INT((AH50-$G$282)/$G$284),0))) -> 5
C11: =C12-$G$272 -> 0.2 | D11: =ROUND(Z11,$G$285) -> 3900 | E11: =ROUND(AA11,$G$285) -> 4200 | F11: =ROUND(AB11,$G$285) -> 4600 | G11: =ROUND(AC11,$G$285) -> 5000 | H11: =ROUND(AD11,$G$285) -> 5400 | I11: =ROUND(AE11,$G$285) -> 5700 | J11: =ROUND(AF11,$G$285) -> 6100 | K11: =ROUND(AG11,$G$285) -> 6500 | L11: =ROUND(AH11,$G$285) -> 6900 | N11: =$C11 -> 0.2 | O11: =$G$263*(1-N11)*$G$266 -> 742.85714 | P11: =$G$263*(1-N11)-O11 -> 1657.1429 | Q11: =$G$265-O11 -> 59257.143 | R11: =IFERROR(P11/(Q11+$G$263*(1-N11)),0)*(1-$G$267) -> 0.025532901 | Z11: =$O11+$G$268+$N11*$G$264+$R11*($Q11*(1+D$9)+$G$264*(1-$N11))-$G$263 -> 3850.4723 | AA11: =$O11+$G$268+$N11*$G$264+$R11*($Q11*(1+E$9)+$G$264*(1-$N11))-$G$263 -> 4228.724 | AB11: =$O11+$G$268+$N11*$G$264+$R11*($Q11*(1+F$9)+$G$264*(1-$N11))-$G$263 -> 4606.9757 | AC11: =$O11+$G$268+$N11*$G$264+$R11*($Q11*(1+G$9)+$G$264*(1-$N11))-$G$263 -> 4985.2274 | AD11: =$O11+$G$268+$N11*$G$264+$R11*($Q11*(1+H$9)+$G$264*(1-$N11))-$G$263 -> 5363.479 | AE11: =$O11+$G$268+$N11*$G$264+$R11*($Q11*(1+I$9)+$G$264*(1-$N11))-$G$263 -> 5741.7307 | AF11: =$O11+$G$268+$N11*$G$264+$R11*($Q11*(1+J$9)+$G$264*(1-$N11))-$G$263 -> 6119.9824 | AG11: =$O11+$G$268+$N11*$G$264+$R11*($Q11*(1+K$9)+$G$264*(1-$N11))-$G$263 -> 6498.2341 | AH11: =$O11+$G$268+$N11*$G$264+$R11*($Q11*(1+L$9)+$G$264*(1-$N11))-$G$263 -> 6876.4858 | AT11: =IF(Z51<$G$282,0,MIN($G$279,1+IFERROR(INT((Z51-$G$282)/$G$284),0))) -> 0 | AU11: =IF(AA51<$G$282,0,MIN($G$279,1+IFERROR(INT((AA51-$G$282)/$G$284),0))) -> 0 | AV11: =IF(AB51<$G$282,0,MIN($G$279,1+IFERROR(INT((AB51-$G$282)/$G$284),0))) -> 0 | AW11: =IF(AC51<$G$282,0,MIN($G$279,1+IFERROR(INT((AC51-$G$282)/$G$284),0))) -> 0 | AX11: =IF(AD51<$G$282,0,MIN($G$279,1+IFERROR(INT((AD51-$G$282)/$G$284),0))) -> 0 | AY11: =IF(AE51<$G$282,0,MIN($G$279,1+IFERROR(INT((AE51-$G$282)/$G$284),0))) -> 1 | AZ11: =IF(AF51<$G$282,0,MIN($G$279,1+IFERROR(INT((AF51-$G$282)/$G$284),0))) -> 3 | BA11: =IF(AG51<$G$282,0,MIN($G$279,1+IFERROR(INT((AG51-$G$282)/$G$284),0))) -> 4 | BB11: =IF(AH51<$G$282,0,MIN($G$279,1+IFERROR(INT((AH51-$G$282)/$G$284),0))) -> 6
C12: =C13-$G$272 -> 0.25 | D12: =ROUND(Z12,$G$285) -> 4300 | E12: =ROUND(AA12,$G$285) -> 4600 | F12: =ROUND(AB12,$G$285) -> 5000 | G12: =ROUND(AC12,$G$285) -> 5400 | H12: =ROUND(AD12,$G$285) -> 5700 | I12: =ROUND(AE12,$G$285) -> 6100 | J12: =ROUND(AF12,$G$285) -> 6400 | K12: =ROUND(AG12,$G$285) -> 6800 | L12: =ROUND(AH12,$G$285) -> 7100 | N12: =$C12 -> 0.25 | O12: =$G$263*(1-N12)*$G$266 -> 696.42857 | P12: =$G$263*(1-N12)-O12 -> 1553.5714 | Q12: =$G$265-O12 -> 59303.571 | R12: =IFERROR(P12/(Q12+$G$263*(1-N12)),0)*(1-$G$267) -> 0.023977372 | Z12: =$O12+$G$268+$N12*$G$264+$R12*($Q12*(1+D$9)+$G$264*(1-$N12))-$G$263 -> 4286.7695 | AA12: =$O12+$G$268+$N12*$G$264+$R12*($Q12*(1+E$9)+$G$264*(1-$N12))-$G$263 -> 4642.2555 | AB12: =$O12+$G$268+$N12*$G$264+$R12*($Q12*(1+F$9)+$G$264*(1-$N12))-$G$263 -> 4997.7414 | AC12: =$O12+$G$268+$N12*$G$264+$R12*($Q12*(1+G$9)+$G$264*(1-$N12))-$G$263 -> 5353.2274 | AD12: =$O12+$G$268+$N12*$G$264+$R12*($Q12*(1+H$9)+$G$264*(1-$N12))-$G$263 -> 5708.7133 | AE12: =$O12+$G$268+$N12*$G$264+$R12*($Q12*(1+I$9)+$G$264*(1-$N12))-$G$263 -> 6064.1992 | AF12: =$O12+$G$268+$N12*$G$264+$R12*($Q12*(1+J$9)+$G$264*(1-$N12))-$G$263 -> 6419.6852 | AG12: =$O12+$G$268+$N12*$G$264+$R12*($Q12*(1+K$9)+$G$264*(1-$N12))-$G$263 -> 6775.1711 | AH12: =$O12+$G$268+$N12*$G$264+$R12*($Q12*(1+L$9)+$G$264*(1-$N12))-$G$263 -> 7130.6571 | AT12: =IF(Z52<$G$282,0,MIN($G$279,1+IFERROR(INT((Z52-$G$282)/$G$284),0))) -> 0 | AU12: =IF(AA52<$G$282,0,MIN($G$279,1+IFERROR(INT((AA52-$G$282)/$G$284),0))) -> 0 | AV12: =IF(AB52<$G$282,0,MIN($G$279,1+IFERROR(INT((AB52-$G$282)/$G$284),0))) -> 0 | AW12: =IF(AC52<$G$282,0,MIN($G$279,1+IFERROR(INT((AC52-$G$282)/$G$284),0))) -> 0 | AX12: =IF(AD52<$G$282,0,MIN($G$279,1+IFERROR(INT((AD52-$G$282)/$G$284),0))) -> 1 | AY12: =IF(AE52<$G$282,0,MIN($G$279,1+IFERROR(INT((AE52-$G$282)/$G$284),0))) -> 3 | AZ12: =IF(AF52<$G$282,0,MIN($G$279,1+IFERROR(INT((AF52-$G$282)/$G$284),0))) -> 4 | BA12: =IF(AG52<$G$282,0,MIN($G$279,1+IFERROR(INT((AG52-$G$282)/$G$284),0))) -> 5 | BB12: =IF(AH52<$G$282,0,MIN($G$279,1+IFERROR(INT((AH52-$G$282)/$G$284),0))) -> 7
C13: =$G$271 -> 0.3 | D13: =ROUND(Z13,$G$285) -> 4700 | E13: =ROUND(AA13,$G$285) -> 5100 | F13: =ROUND(AB13,$G$285) -> 5400 | G13: =ROUND(AC13,$G$285) -> 5700 | H13: =ROUND(AD13,$G$285) -> 6100 | I13: =ROUND(AE13,$G$285) -> 6400 | J13: =ROUND(AF13,$G$285) -> 6700 | K13: =ROUND(AG13,$G$285) -> 7100 | L13: =ROUND(AH13,$G$285) -> 7400 | N13: =$C13 -> 0.3 | O13: =$G$263*(1-N13)*$G$266 -> 650 | P13: =$G$263*(1-N13)-O13 -> 1450 | Q13: =$G$265-O13 -> 59350 | R13: =IFERROR(P13/(Q13+$G$263*(1-N13)),0)*(1-$G$267) -> 0.022416599 | Z13: =$O13+$G$268+$N13*$G$264+$R13*($Q13*(1+D$9)+$G$264*(1-$N13))-$G$263 -> 4724.2788 | AA13: =$O13+$G$268+$N13*$G$264+$R13*($Q13*(1+E$9)+$G$264*(1-$N13))-$G$263 -> 5056.8851 | AB13: =$O13+$G$268+$N13*$G$264+$R13*($Q13*(1+F$9)+$G$264*(1-$N13))-$G$263 -> 5389.4914 | AC13: =$O13+$G$268+$N13*$G$264+$R13*($Q13*(1+G$9)+$G$264*(1-$N13))-$G$263 -> 5722.0977 | AD13: =$O13+$G$268+$N13*$G$264+$R13*($Q13*(1+H$9)+$G$264*(1-$N13))-$G$263 -> 6054.704 | AE13: =$O13+$G$268+$N13*$G$264+$R13*($Q13*(1+I$9)+$G$264*(1-$N13))-$G$263 -> 6387.3102 | AF13: =$O13+$G$268+$N13*$G$264+$R13*($Q13*(1+J$9)+$G$264*(1-$N13))-$G$263 -> 6719.9165 | AG13: =$O13+$G$268+$N13*$G$264+$R13*($Q13*(1+K$9)+$G$264*(1-$N13))-$G$263 -> 7052.5228 | AH13: =$O13+$G$268+$N13*$G$264+$R13*($Q13*(1+L$9)+$G$264*(1-$N13))-$G$263 -> 7385.1291 | AT13: =IF(Z53<$G$282,0,MIN($G$279,1+IFERROR(INT((Z53-$G$282)/$G$284),0))) -> 0 | AU13: =IF(AA53<$G$282,0,MIN($G$279,1+IFERROR(INT((AA53-$G$282)/$G$284),0))) -> 0 | AV13: =IF(AB53<$G$282,0,MIN($G$279,1+IFERROR(INT((AB53-$G$282)/$G$284),0))) -> 0 | AW13: =IF(AC53<$G$282,0,MIN($G$279,1+IFERROR(INT((AC53-$G$282)/$G$284),0))) -> 1 | AX13: =IF(AD53<$G$282,0,MIN($G$279,1+IFERROR(INT((AD53-$G$282)/$G$284),0))) -> 3 | AY13: =IF(AE53<$G$282,0,MIN($G$279,1+IFERROR(INT((AE53-$G$282)/$G$284),0))) -> 4 | AZ13: =IF(AF53<$G$282,0,MIN($G$279,1+IFERROR(INT((AF53-$G$282)/$G$284),0))) -> 5 | BA13: =IF(AG53<$G$282,0,MIN($G$279,1+IFERROR(INT((AG53-$G$282)/$G$284),0))) -> 6 | BB13: =IF(AH53<$G$282,0,MIN($G$279,1+IFERROR(INT((AH53-$G$282)/$G$284),0))) -> 8
C14: =C13+$G$272 -> 0.35 | D14: =ROUND(Z14,$G$285) -> 5200 | E14: =ROUND(AA14,$G$285) -> 5500 | F14: =ROUND(AB14,$G$285) -> 5800 | G14: =ROUND(AC14,$G$285) -> 6100 | H14: =ROUND(AD14,$G$285) -> 6400 | I14: =ROUND(AE14,$G$285) -> 6700 | J14: =ROUND(AF14,$G$285) -> 7000 | K14: =ROUND(AG14,$G$285) -> 7300 | L14: =ROUND(AH14,$G$285) -> 7600 | N14: =$C14 -> 0.35 | O14: =$G$263*(1-N14)*$G$266 -> 603.57143 | P14: =$G$263*(1-N14)-O14 -> 1346.4286 | Q14: =$G$265-O14 -> 59396.429 | R14: =IFERROR(P14/(Q14+$G$263*(1-N14)),0)*(1-$G$267) -> 0.020850556 | Z14: =$O14+$G$268+$N14*$G$264+$R14*($Q14*(1+D$9)+$G$264*(1-$N14))-$G$263 -> 5163.0063 | AA14: =$O14+$G$268+$N14*$G$264+$R14*($Q14*(1+E$9)+$G$264*(1-$N14))-$G$263 -> 5472.6184 | AB14: =$O14+$G$268+$N14*$G$264+$R14*($Q14*(1+F$9)+$G$264*(1-$N14))-$G$263 -> 5782.2306 | AC14: =$O14+$G$268+$N14*$G$264+$R14*($Q14*(1+G$9)+$G$264*(1-$N14))-$G$263 -> 6091.8427 | AD14: =$O14+$G$268+$N14*$G$264+$R14*($Q14*(1+H$9)+$G$264*(1-$N14))-$G$263 -> 6401.4548 | AE14: =$O14+$G$268+$N14*$G$264+$R14*($Q14*(1+I$9)+$G$264*(1-$N14))-$G$263 -> 6711.067 | AF14: =$O14+$G$268+$N14*$G$264+$R14*($Q14*(1+J$9)+$G$264*(1-$N14))-$G$263 -> 7020.6791 | AG14: =$O14+$G$268+$N14*$G$264+$R14*($Q14*(1+K$9)+$G$264*(1-$N14))-$G$263 -> 7330.2913 | AH14: =$O14+$G$268+$N14*$G$264+$R14*($Q14*(1+L$9)+$G$264*(1-$N14))-$G$263 -> 7639.9034 | AT14: =IF(Z54<$G$282,0,MIN($G$279,1+IFERROR(INT((Z54-$G$282)/$G$284),0))) -> 0 | AU14: =IF(AA54<$G$282,0,MIN($G$279,1+IFERROR(INT((AA54-$G$282)/$G$284),0))) -> 0 | AV14: =IF(AB54<$G$282,0,MIN($G$279,1+IFERROR(INT((AB54-$G$282)/$G$284),0))) -> 2 | AW14: =IF(AC54<$G$282,0,MIN($G$279,1+IFERROR(INT((AC54-$G$282)/$G$284),0))) -> 3 | AX14: =IF(AD54<$G$282,0,MIN($G$279,1+IFERROR(INT((AD54-$G$282)/$G$284),0))) -> 4 | AY14: =IF(AE54<$G$282,0,MIN($G$279,1+IFERROR(INT((AE54-$G$282)/$G$284),0))) -> 5 | AZ14: =IF(AF54<$G$282,0,MIN($G$279,1+IFERROR(INT((AF54-$G$282)/$G$284),0))) -> 6 | BA14: =IF(AG54<$G$282,0,MIN($G$279,1+IFERROR(INT((AG54-$G$282)/$G$284),0))) -> 7 | BB14: =IF(AH54<$G$282,0,MIN($G$279,1+IFERROR(INT((AH54-$G$282)/$G$284),0))) -> 9
C15: =C14+$G$272 -> 0.4 | D15: =ROUND(Z15,$G$285) -> 5600 | E15: =ROUND(AA15,$G$285) -> 5900 | F15: =ROUND(AB15,$G$285) -> 6200 | G15: =ROUND(AC15,$G$285) -> 6500 | H15: =ROUND(AD15,$G$285) -> 6700 | I15: =ROUND(AE15,$G$285) -> 7000 | J15: =ROUND(AF15,$G$285) -> 7300 | K15: =ROUND(AG15,$G$285) -> 7600 | L15: =ROUND(AH15,$G$285) -> 7900 | N15: =$C15 -> 0.4 | O15: =$G$263*(1-N15)*$G$266 -> 557.14286 | P15: =$G$263*(1-N15)-O15 -> 1242.8571 | Q15: =$G$265-O15 -> 59442.857 | R15: =IFERROR(P15/(Q15+$G$263*(1-N15)),0)*(1-$G$267) -> 0.019279216 | Z15: =$O15+$G$268+$N15*$G$264+$R15*($Q15*(1+D$9)+$G$264*(1-$N15))-$G$263 -> 5602.9581 | AA15: =$O15+$G$268+$N15*$G$264+$R15*($Q15*(1+E$9)+$G$264*(1-$N15))-$G$263 -> 5889.4611 | AB15: =$O15+$G$268+$N15*$G$264+$R15*($Q15*(1+F$9)+$G$264*(1-$N15))-$G$263 -> 6175.964 | AC15: =$O15+$G$268+$N15*$G$264+$R15*($Q15*(1+G$9)+$G$264*(1-$N15))-$G$263 -> 6462.4669 | AD15: =$O15+$G$268+$N15*$G$264+$R15*($Q15*(1+H$9)+$G$264*(1-$N15))-$G$263 -> 6748.9698 | AE15: =$O15+$G$268+$N15*$G$264+$R15*($Q15*(1+I$9)+$G$264*(1-$N15))-$G$263 -> 7035.4728 | AF15: =$O15+$G$268+$N15*$G$264+$R15*($Q15*(1+J$9)+$G$264*(1-$N15))-$G$263 -> 7321.9757 | AG15: =$O15+$G$268+$N15*$G$264+$R15*($Q15*(1+K$9)+$G$264*(1-$N15))-$G$263 -> 7608.4786 | AH15: =$O15+$G$268+$N15*$G$264+$R15*($Q15*(1+L$9)+$G$264*(1-$N15))-$G$263 -> 7894.9815 | AT15: =IF(Z55<$G$282,0,MIN($G$279,1+IFERROR(INT((Z55-$G$282)/$G$284),0))) -> 1 | AU15: =IF(AA55<$G$282,0,MIN($G$279,1+IFERROR(INT((AA55-$G$282)/$G$284),0))) -> 2 | AV15: =IF(AB55<$G$282,0,MIN($G$279,1+IFERROR(INT((AB55-$G$282)/$G$284),0))) -> 3 | AW15: =IF(AC55<$G$282,0,MIN($G$279,1+IFERROR(INT((AC55-$G$282)/$G$284),0))) -> 4 | AX15: =IF(AD55<$G$282,0,MIN($G$279,1+IFERROR(INT((AD55-$G$282)/$G$284),0))) -> 5 | AY15: =IF(AE55<$G$282,0,MIN($G$279,1+IFERROR(INT((AE55-$G$282)/$G$284),0))) -> 6 | AZ15: =IF(AF55<$G$282,0,MIN($G$279,1+IFERROR(INT((AF55-$G$282)/$G$284),0))) -> 7 | BA15: =IF(AG55<$G$282,0,MIN($G$279,1+IFERROR(INT((AG55-$G$282)/$G$284),0))) -> 8 | BB15: =IF(AH55<$G$282,0,MIN($G$279,1+IFERROR(INT((AH55-$G$282)/$G$284),0))) -> 10
C16: =C15+$G$272 -> 0.45 | D16: =ROUND(Z16,$G$285) -> 6000 | E16: =ROUND(AA16,$G$285) -> 6300 | F16: =ROUND(AB16,$G$285) -> 6600 | G16: =ROUND(AC16,$G$285) -> 6800 | H16: =ROUND(AD16,$G$285) -> 7100 | I16: =ROUND(AE16,$G$285) -> 7400 | J16: =ROUND(AF16,$G$285) -> 7600 | K16: =ROUND(AG16,$G$285) -> 7900 | L16: =ROUND(AH16,$G$285) -> 8200 | N16: =$C16 -> 0.45 | O16: =$G$263*(1-N16)*$G$266 -> 510.71429 | P16: =$G$263*(1-N16)-O16 -> 1139.2857 | Q16: =$G$265-O16 -> 59489.286 | R16: =IFERROR(P16/(Q16+$G$263*(1-N16)),0)*(1-$G$267) -> 0.017702553 | Z16: =$O16+$G$268+$N16*$G$264+$R16*($Q16*(1+D$9)+$G$264*(1-$N16))-$G$263 -> 6044.1406 | AA16: =$O16+$G$268+$N16*$G$264+$R16*($Q16*(1+E$9)+$G$264*(1-$N16))-$G$263 -> 6307.4186 | AB16: =$O16+$G$268+$N16*$G$264+$R16*($Q16*(1+F$9)+$G$264*(1-$N16))-$G$263 -> 6570.6967 | AC16: =$O16+$G$268+$N16*$G$264+$R16*($Q16*(1+G$9)+$G$264*(1-$N16))-$G$263 -> 6833.9747 | AD16: =$O16+$G$268+$N16*$G$264+$R16*($Q16*(1+H$9)+$G$264*(1-$N16))-$G$263 -> 7097.2528 | AE16: =$O16+$G$268+$N16*$G$264+$R16*($Q16*(1+I$9)+$G$264*(1-$N16))-$G$263 -> 7360.5308 | AF16: =$O16+$G$268+$N16*$G$264+$R16*($Q16*(1+J$9)+$G$264*(1-$N16))-$G$263 -> 7623.8089 | AG16: =$O16+$G$268+$N16*$G$264+$R16*($Q16*(1+K$9)+$G$264*(1-$N16))-$G$263 -> 7887.087 | AH16: =$O16+$G$268+$N16*$G$264+$R16*($Q16*(1+L$9)+$G$264*(1-$N16))-$G$263 -> 8150.365 | AT16: =IF(Z56<$G$282,0,MIN($G$279,1+IFERROR(INT((Z56-$G$282)/$G$284),0))) -> 3 | AU16: =IF(AA56<$G$282,0,MIN($G$279,1+IFERROR(INT((AA56-$G$282)/$G$284),0))) -> 4 | AV16: =IF(AB56<$G$282,0,MIN($G$279,1+IFERROR(INT((AB56-$G$282)/$G$284),0))) -> 5 | AW16: =IF(AC56<$G$282,0,MIN($G$279,1+IFERROR(INT((AC56-$G$282)/$G$284),0))) -> 6 | AX16: =IF(AD56<$G$282,0,MIN($G$279,1+IFERROR(INT((AD56-$G$282)/$G$284),0))) -> 7 | AY16: =IF(AE56<$G$282,0,MIN($G$279,1+IFERROR(INT((AE56-$G$282)/$G$284),0))) -> 8 | AZ16: =IF(AF56<$G$282,0,MIN($G$279,1+IFERROR(INT((AF56-$G$282)/$G$284),0))) -> 9 | BA16: =IF(AG56<$G$282,0,MIN($G$279,1+IFERROR(INT((AG56-$G$282)/$G$284),0))) -> 10 | BB16: =IF(AH56<$G$282,0,MIN($G$279,1+IFERROR(INT((AH56-$G$282)/$G$284),0))) -> 10
B17: Ben's Year 5 value (cash at close + earnout + retained Keystone stake + Topkey stock, after dilution) less Keystone value today (G263)
N18: =$G$269 -> 0.3 | O18: =$G$263*(1-N18)*$G$266 -> 650 | P18: =$G$263*(1-N18)-O18 -> 1450 | Q18: =$G$265-O18 -> 59350 | R18: =IFERROR(P18/(Q18+$G$263*(1-N18)),0)*(1-$G$267) -> 0.022416599
B19: Ben's % Return on Keystone Value Based on Topkey Growth & Rollover %
D21: Topkey ex-Keystone Value Growth (%)
D22: =E22-$G$274 -> 1 | E22: =F22-$G$274 -> 1.25 | F22: =G22-$G$274 -> 1.5 | G22: =H22-$G$274 -> 1.75 | H22: =$G$273 -> 2 | I22: =H22+$G$274 -> 2.25 | J22: =I22+$G$274 -> 2.5 | K22: =J22+$G$274 -> 2.75 | L22: =K22+$G$274 -> 3 | AT22: Helper: Gradient Band (0 = below $1M hurdle)
B23: Ben's Rollover % | C23: =C24-$G$272 -> 0.15 | D23: =IFERROR(Z10/$G$263,0) -> 1.1384603 | E23: =IFERROR(AA10/$G$263,0) -> 1.272095 | F23: =IFERROR(AB10/$G$263,0) -> 1.4057297 | G23: =IFERROR(AC10/$G$263,0) -> 1.5393644 | H23: =IFERROR(AD10/$G$263,0) -> 1.6729991 | I23: =IFERROR(AE10/$G$263,0) -> 1.8066338 | J23: =IFERROR(AF10/$G$263,0) -> 1.9402685 | K23: =IFERROR(AG10/$G$263,0) -> 2.0739032 | L23: =IFERROR(AH10/$G$263,0) -> 2.2075379 | AT23: =IF(Z50<$G$282,0,MIN($G$279,1+IFERROR(INT((Z50-$G$282)/$G$284),0))) -> 0 | AU23: =IF(AA50<$G$282,0,MIN($G$279,1+IFERROR(INT((AA50-$G$282)/$G$284),0))) -> 0 | AV23: =IF(AB50<$G$282,0,MIN($G$279,1+IFERROR(INT((AB50-$G$282)/$G$284),0))) -> 0 | AW23: =IF(AC50<$G$282,0,MIN($G$279,1+IFERROR(INT((AC50-$G$282)/$G$284),0))) -> 0 | AX23: =IF(AD50<$G$282,0,MIN($G$279,1+IFERROR(INT((AD50-$G$282)/$G$284),0))) -> 0 | AY23: =IF(AE50<$G$282,0,MIN($G$279,1+IFERROR(INT((AE50-$G$282)/$G$284),0))) -> 0 | AZ23: =IF(AF50<$G$282,0,MIN($G$279,1+IFERROR(INT((AF50-$G$282)/$G$284),0))) -> 2 | BA23: =IF(AG50<$G$282,0,MIN($G$279,1+IFERROR(INT((AG50-$G$282)/$G$284),0))) -> 3 | BB23: =IF(AH50<$G$282,0,MIN($G$279,1+IFERROR(INT((AH50-$G$282)/$G$284),0))) -> 5
C24: =C25-$G$272 -> 0.2 | D24: =IFERROR(Z11/$G$263,0) -> 1.2834908 | E24: =IFERROR(AA11/$G$263,0) -> 1.4095747 | F24: =IFERROR(AB11/$G$263,0) -> 1.5356586 | G24: =IFERROR(AC11/$G$263,0) -> 1.6617425 | H24: =IFERROR(AD11/$G$263,0) -> 1.7878263 | I24: =IFERROR(AE11/$G$263,0) -> 1.9139102 | J24: =IFERROR(AF11/$G$263,0) -> 2.0399941 | K24: =IFERROR(AG11/$G$263,0) -> 2.166078 | L24: =IFERROR(AH11/$G$263,0) -> 2.2921619 | AT24: =IF(Z51<$G$282,0,MIN($G$279,1+IFERROR(INT((Z51-$G$282)/$G$284),0))) -> 0 | AU24: =IF(AA51<$G$282,0,MIN($G$279,1+IFERROR(INT((AA51-$G$282)/$G$284),0))) -> 0 | AV24: =IF(AB51<$G$282,0,MIN($G$279,1+IFERROR(INT((AB51-$G$282)/$G$284),0))) -> 0 | AW24: =IF(AC51<$G$282,0,MIN($G$279,1+IFERROR(INT((AC51-$G$282)/$G$284),0))) -> 0 | AX24: =IF(AD51<$G$282,0,MIN($G$279,1+IFERROR(INT((AD51-$G$282)/$G$284),0))) -> 0 | AY24: =IF(AE51<$G$282,0,MIN($G$279,1+IFERROR(INT((AE51-$G$282)/$G$284),0))) -> 1 | AZ24: =IF(AF51<$G$282,0,MIN($G$279,1+IFERROR(INT((AF51-$G$282)/$G$284),0))) -> 3 | BA24: =IF(AG51<$G$282,0,MIN($G$279,1+IFERROR(INT((AG51-$G$282)/$G$284),0))) -> 4 | BB24: =IF(AH51<$G$282,0,MIN($G$279,1+IFERROR(INT((AH51-$G$282)/$G$284),0))) -> 6
C25: =C26-$G$272 -> 0.25 | D25: =IFERROR(Z12/$G$263,0) -> 1.4289232 | E25: =IFERROR(AA12/$G$263,0) -> 1.5474185 | F25: =IFERROR(AB12/$G$263,0) -> 1.6659138 | G25: =IFERROR(AC12/$G$263,0) -> 1.7844091 | H25: =IFERROR(AD12/$G$263,0) -> 1.9029044 | I25: =IFERROR(AE12/$G$263,0) -> 2.0213997 | J25: =IFERROR(AF12/$G$263,0) -> 2.1398951 | K25: =IFERROR(AG12/$G$263,0) -> 2.2583904 | L25: =IFERROR(AH12/$G$263,0) -> 2.3768857 | AT25: =IF(Z52<$G$282,0,MIN($G$279,1+IFERROR(INT((Z52-$G$282)/$G$284),0))) -> 0 | AU25: =IF(AA52<$G$282,0,MIN($G$279,1+IFERROR(INT((AA52-$G$282)/$G$284),0))) -> 0 | AV25: =IF(AB52<$G$282,0,MIN($G$279,1+IFERROR(INT((AB52-$G$282)/$G$284),0))) -> 0 | AW25: =IF(AC52<$G$282,0,MIN($G$279,1+IFERROR(INT((AC52-$G$282)/$G$284),0))) -> 0 | AX25: =IF(AD52<$G$282,0,MIN($G$279,1+IFERROR(INT((AD52-$G$282)/$G$284),0))) -> 1 | AY25: =IF(AE52<$G$282,0,MIN($G$279,1+IFERROR(INT((AE52-$G$282)/$G$284),0))) -> 3 | AZ25: =IF(AF52<$G$282,0,MIN($G$279,1+IFERROR(INT((AF52-$G$282)/$G$284),0))) -> 4 | BA25: =IF(AG52<$G$282,0,MIN($G$279,1+IFERROR(INT((AG52-$G$282)/$G$284),0))) -> 5 | BB25: =IF(AH52<$G$282,0,MIN($G$279,1+IFERROR(INT((AH52-$G$282)/$G$284),0))) -> 7
C26: =$G$271 -> 0.3 | D26: =IFERROR(Z13/$G$263,0) -> 1.5747596 | E26: =IFERROR(AA13/$G$263,0) -> 1.6856284 | F26: =IFERROR(AB13/$G$263,0) -> 1.7964971 | G26: =IFERROR(AC13/$G$263,0) -> 1.9073659 | H26: =IFERROR(AD13/$G$263,0) -> 2.0182347 | I26: =IFERROR(AE13/$G$263,0) -> 2.1291034 | J26: =IFERROR(AF13/$G$263,0) -> 2.2399722 | K26: =IFERROR(AG13/$G$263,0) -> 2.3508409 | L26: =IFERROR(AH13/$G$263,0) -> 2.4617097 | AT26: =IF(Z53<$G$282,0,MIN($G$279,1+IFERROR(INT((Z53-$G$282)/$G$284),0))) -> 0 | AU26: =IF(AA53<$G$282,0,MIN($G$279,1+IFERROR(INT((AA53-$G$282)/$G$284),0))) -> 0 | AV26: =IF(AB53<$G$282,0,MIN($G$279,1+IFERROR(INT((AB53-$G$282)/$G$284),0))) -> 0 | AW26: =IF(AC53<$G$282,0,MIN($G$279,1+IFERROR(INT((AC53-$G$282)/$G$284),0))) -> 1 | AX26: =IF(AD53<$G$282,0,MIN($G$279,1+IFERROR(INT((AD53-$G$282)/$G$284),0))) -> 3 | AY26: =IF(AE53<$G$282,0,MIN($G$279,1+IFERROR(INT((AE53-$G$282)/$G$284),0))) -> 4 | AZ26: =IF(AF53<$G$282,0,MIN($G$279,1+IFERROR(INT((AF53-$G$282)/$G$284),0))) -> 5 | BA26: =IF(AG53<$G$282,0,MIN($G$279,1+IFERROR(INT((AG53-$G$282)/$G$284),0))) -> 6 | BB26: =IF(AH53<$G$282,0,MIN($G$279,1+IFERROR(INT((AH53-$G$282)/$G$284),0))) -> 8
C27: =C26+$G$272 -> 0.35 | D27: =IFERROR(Z14/$G$263,0) -> 1.7210021 | E27: =IFERROR(AA14/$G$263,0) -> 1.8242061 | F27: =IFERROR(AB14/$G$263,0) -> 1.9274102 | G27: =IFERROR(AC14/$G$263,0) -> 2.0306142 | H27: =IFERROR(AD14/$G$263,0) -> 2.1338183 | I27: =IFERROR(AE14/$G$263,0) -> 2.2370223 | J27: =IFERROR(AF14/$G$263,0) -> 2.3402264 | K27: =IFERROR(AG14/$G$263,0) -> 2.4434304 | L27: =IFERROR(AH14/$G$263,0) -> 2.5466345 | AT27: =IF(Z54<$G$282,0,MIN($G$279,1+IFERROR(INT((Z54-$G$282)/$G$284),0))) -> 0 | AU27: =IF(AA54<$G$282,0,MIN($G$279,1+IFERROR(INT((AA54-$G$282)/$G$284),0))) -> 0 | AV27: =IF(AB54<$G$282,0,MIN($G$279,1+IFERROR(INT((AB54-$G$282)/$G$284),0))) -> 2 | AW27: =IF(AC54<$G$282,0,MIN($G$279,1+IFERROR(INT((AC54-$G$282)/$G$284),0))) -> 3 | AX27: =IF(AD54<$G$282,0,MIN($G$279,1+IFERROR(INT((AD54-$G$282)/$G$284),0))) -> 4 | AY27: =IF(AE54<$G$282,0,MIN($G$279,1+IFERROR(INT((AE54-$G$282)/$G$284),0))) -> 5 | AZ27: =IF(AF54<$G$282,0,MIN($G$279,1+IFERROR(INT((AF54-$G$282)/$G$284),0))) -> 6 | BA27: =IF(AG54<$G$282,0,MIN($G$279,1+IFERROR(INT((AG54-$G$282)/$G$284),0))) -> 7 | BB27: =IF(AH54<$G$282,0,MIN($G$279,1+IFERROR(INT((AH54-$G$282)/$G$284),0))) -> 9
C28: =C27+$G$272 -> 0.4 | D28: =IFERROR(Z15/$G$263,0) -> 1.8676527 | E28: =IFERROR(AA15/$G$263,0) -> 1.9631537 | F28: =IFERROR(AB15/$G$263,0) -> 2.0586547 | G28: =IFERROR(AC15/$G$263,0) -> 2.1541556 | H28: =IFERROR(AD15/$G$263,0) -> 2.2496566 | I28: =IFERROR(AE15/$G$263,0) -> 2.3451576 | J28: =IFERROR(AF15/$G$263,0) -> 2.4406586 | K28: =IFERROR(AG15/$G$263,0) -> 2.5361595 | L28: =IFERROR(AH15/$G$263,0) -> 2.6316605 | AT28: =IF(Z55<$G$282,0,MIN($G$279,1+IFERROR(INT((Z55-$G$282)/$G$284),0))) -> 1 | AU28: =IF(AA55<$G$282,0,MIN($G$279,1+IFERROR(INT((AA55-$G$282)/$G$284),0))) -> 2 | AV28: =IF(AB55<$G$282,0,MIN($G$279,1+IFERROR(INT((AB55-$G$282)/$G$284),0))) -> 3 | AW28: =IF(AC55<$G$282,0,MIN($G$279,1+IFERROR(INT((AC55-$G$282)/$G$284),0))) -> 4 | AX28: =IF(AD55<$G$282,0,MIN($G$279,1+IFERROR(INT((AD55-$G$282)/$G$284),0))) -> 5 | AY28: =IF(AE55<$G$282,0,MIN($G$279,1+IFERROR(INT((AE55-$G$282)/$G$284),0))) -> 6 | AZ28: =IF(AF55<$G$282,0,MIN($G$279,1+IFERROR(INT((AF55-$G$282)/$G$284),0))) -> 7 | BA28: =IF(AG55<$G$282,0,MIN($G$279,1+IFERROR(INT((AG55-$G$282)/$G$284),0))) -> 8 | BB28: =IF(AH55<$G$282,0,MIN($G$279,1+IFERROR(INT((AH55-$G$282)/$G$284),0))) -> 10
C29: =C28+$G$272 -> 0.45 | D29: =IFERROR(Z16/$G$263,0) -> 2.0147135 | E29: =IFERROR(AA16/$G$263,0) -> 2.1024729 | F29: =IFERROR(AB16/$G$263,0) -> 2.1902322 | G29: =IFERROR(AC16/$G$263,0) -> 2.2779916 | H29: =IFERROR(AD16/$G$263,0) -> 2.3657509 | I29: =IFERROR(AE16/$G$263,0) -> 2.4535103 | J29: =IFERROR(AF16/$G$263,0) -> 2.5412696 | K29: =IFERROR(AG16/$G$263,0) -> 2.629029 | L29: =IFERROR(AH16/$G$263,0) -> 2.7167883 | AT29: =IF(Z56<$G$282,0,MIN($G$279,1+IFERROR(INT((Z56-$G$282)/$G$284),0))) -> 3 | AU29: =IF(AA56<$G$282,0,MIN($G$279,1+IFERROR(INT((AA56-$G$282)/$G$284),0))) -> 4 | AV29: =IF(AB56<$G$282,0,MIN($G$279,1+IFERROR(INT((AB56-$G$282)/$G$284),0))) -> 5 | AW29: =IF(AC56<$G$282,0,MIN($G$279,1+IFERROR(INT((AC56-$G$282)/$G$284),0))) -> 6 | AX29: =IF(AD56<$G$282,0,MIN($G$279,1+IFERROR(INT((AD56-$G$282)/$G$284),0))) -> 7 | AY29: =IF(AE56<$G$282,0,MIN($G$279,1+IFERROR(INT((AE56-$G$282)/$G$284),0))) -> 8 | AZ29: =IF(AF56<$G$282,0,MIN($G$279,1+IFERROR(INT((AF56-$G$282)/$G$284),0))) -> 9 | BA29: =IF(AG56<$G$282,0,MIN($G$279,1+IFERROR(INT((AG56-$G$282)/$G$284),0))) -> 10 | BB29: =IF(AH56<$G$282,0,MIN($G$279,1+IFERROR(INT((AH56-$G$282)/$G$284),0))) -> 10
B30: Ben's Year 5 total value ÷ Keystone value today (G263), less 1
B32: Ben's IRR Based on Topkey Growth & Rollover %
D34: Topkey ex-Keystone Value Growth (%)
D35: =E35-$G$274 -> 1 | E35: =F35-$G$274 -> 1.25 | F35: =G35-$G$274 -> 1.5 | G35: =H35-$G$274 -> 1.75 | H35: =$G$273 -> 2 | I35: =H35+$G$274 -> 2.25 | J35: =I35+$G$274 -> 2.5 | K35: =J35+$G$274 -> 2.75 | L35: =K35+$G$274 -> 3 | AT35: Helper: Gradient Band (0 = below $1M hurdle)
B36: Ben's Rollover % | C36: =C37-$G$272 -> 0.15 | D36: {=IFERROR(IRR(IF($S$9:$X$9=0,$O10-$G$263,0)+IF($S$9:$X$9=$G$277,$G$268,0)+IF($S$9:$X$9=$G$278,Z10+$G$263-$O10-$G$268,0)),0)} -> 0.20541029 | E36: {=IFERROR(IRR(IF($S$9:$X$9=0,$O10-$G$263,0)+IF($S$9:$X$9=$G$277,$G$268,0)+IF($S$9:$X$9=$G$278,AA10+$G$263-$O10-$G$268,0)),0)} -> 0.22211959 | F36: {=IFERROR(IRR(IF($S$9:$X$9=0,$O10-$G$263,0)+IF($S$9:$X$9=$G$277,$G$268,0)+IF($S$9:$X$9=$G$278,AB10+$G$263-$O10-$G$268,0)),0)} -> 0.23796209 | G36: {=IFERROR(IRR(IF($S$9:$X$9=0,$O10-$G$263,0)+IF($S$9:$X$9=$G$277,$G$268,0)+IF($S$9:$X$9=$G$278,AC10+$G$263-$O10-$G$268,0)),0)} -> 0.25303283 | H36: {=IFERROR(IRR(IF($S$9:$X$9=0,$O10-$G$263,0)+IF($S$9:$X$9=$G$277,$G$268,0)+IF($S$9:$X$9=$G$278,AD10+$G$263-$O10-$G$268,0)),0)} -> 0.26741158 | I36: {=IFERROR(IRR(IF($S$9:$X$9=0,$O10-$G$263,0)+IF($S$9:$X$9=$G$277,$G$268,0)+IF($S$9:$X$9=$G$278,AE10+$G$263-$O10-$G$268,0)),0)} -> 0.28116597 | J36: {=IFERROR(IRR(IF($S$9:$X$9=0,$O10-$G$263,0)+IF($S$9:$X$9=$G$277,$G$268,0)+IF($S$9:$X$9=$G$278,AF10+$G$263-$O10-$G$268,0)),0)} -> 0.29435386 | K36: {=IFERROR(IRR(IF($S$9:$X$9=0,$O10-$G$263,0)+IF($S$9:$X$9=$G$277,$G$268,0)+IF($S$9:$X$9=$G$278,AG10+$G$263-$O10-$G$268,0)),0)} -> 0.30702521 | L36: {=IFERROR(IRR(IF($S$9:$X$9=0,$O10-$G$263,0)+IF($S$9:$X$9=$G$277,$G$268,0)+IF($S$9:$X$9=$G$278,AH10+$G$263-$O10-$G$268,0)),0)} -> 0.31922341 | AT36: =IF(Z50<$G$282,0,MIN($G$279,1+IFERROR(INT((Z50-$G$282)/$G$284),0))) -> 0 | AU36: =IF(AA50<$G$282,0,MIN($G$279,1+IFERROR(INT((AA50-$G$282)/$G$284),0))) -> 0 | AV36: =IF(AB50<$G$282,0,MIN($G$279,1+IFERROR(INT((AB50-$G$282)/$G$284),0))) -> 0 | AW36: =IF(AC50<$G$282,0,MIN($G$279,1+IFERROR(INT((AC50-$G$282)/$G$284),0))) -> 0 | AX36: =IF(AD50<$G$282,0,MIN($G$279,1+IFERROR(INT((AD50-$G$282)/$G$284),0))) -> 0 | AY36: =IF(AE50<$G$282,0,MIN($G$279,1+IFERROR(INT((AE50-$G$282)/$G$284),0))) -> 0 | AZ36: =IF(AF50<$G$282,0,MIN($G$279,1+IFERROR(INT((AF50-$G$282)/$G$284),0))) -> 2 | BA36: =IF(AG50<$G$282,0,MIN($G$279,1+IFERROR(INT((AG50-$G$282)/$G$284),0))) -> 3 | BB36: =IF(AH50<$G$282,0,MIN($G$279,1+IFERROR(INT((AH50-$G$282)/$G$284),0))) -> 5
C37: =C38-$G$272 -> 0.2 | D37: {=IFERROR(IRR(IF($S$9:$X$9=0,$O11-$G$263,0)+IF($S$9:$X$9=$G$277,$G$268,0)+IF($S$9:$X$9=$G$278,Z11+$G$263-$O11-$G$268,0)),0)} -> 0.22028851 | E37: {=IFERROR(IRR(IF($S$9:$X$9=0,$O11-$G$263,0)+IF($S$9:$X$9=$G$277,$G$268,0)+IF($S$9:$X$9=$G$278,AA11+$G$263-$O11-$G$268,0)),0)} -> 0.2350422 | F37: {=IFERROR(IRR(IF($S$9:$X$9=0,$O11-$G$263,0)+IF($S$9:$X$9=$G$277,$G$268,0)+IF($S$9:$X$9=$G$278,AB11+$G$263-$O11-$G$268,0)),0)} -> 0.24912283 | G37: {=IFERROR(IRR(IF($S$9:$X$9=0,$O11-$G$263,0)+IF($S$9:$X$9=$G$277,$G$268,0)+IF($S$9:$X$9=$G$278,AC11+$G$263-$O11-$G$268,0)),0)} -> 0.26259578 | H37: {=IFERROR(IRR(IF($S$9:$X$9=0,$O11-$G$263,0)+IF($S$9:$X$9=$G$277,$G$268,0)+IF($S$9:$X$9=$G$278,AD11+$G$263-$O11-$G$268,0)),0)} -> 0.27551707 | I37: {=IFERROR(IRR(IF($S$9:$X$9=0,$O11-$G$263,0)+IF($S$9:$X$9=$G$277,$G$268,0)+IF($S$9:$X$9=$G$278,AE11+$G$263-$O11-$G$268,0)),0)} -> 0.28793504 | J37: {=IFERROR(IRR(IF($S$9:$X$9=0,$O11-$G$263,0)+IF($S$9:$X$9=$G$277,$G$268,0)+IF($S$9:$X$9=$G$278,AF11+$G$263-$O11-$G$268,0)),0)} -> 0.29989177 | K37: {=IFERROR(IRR(IF($S$9:$X$9=0,$O11-$G$263,0)+IF($S$9:$X$9=$G$277,$G$268,0)+IF($S$9:$X$9=$G$278,AG11+$G$263-$O11-$G$268,0)),0)} -> 0.3114241 | L37: {=IFERROR(IRR(IF($S$9:$X$9=0,$O11-$G$263,0)+IF($S$9:$X$9=$G$277,$G$268,0)+IF($S$9:$X$9=$G$278,AH11+$G$263-$O11-$G$268,0)),0)} -> 0.3225645 | AT37: =IF(Z51<$G$282,0,MIN($G$279,1+IFERROR(INT((Z51-$G$282)/$G$284),0))) -> 0 | AU37: =IF(AA51<$G$282,0,MIN($G$279,1+IFERROR(INT((AA51-$G$282)/$G$284),0))) -> 0 | AV37: =IF(AB51<$G$282,0,MIN($G$279,1+IFERROR(INT((AB51-$G$282)/$G$284),0))) -> 0 | AW37: =IF(AC51<$G$282,0,MIN($G$279,1+IFERROR(INT((AC51-$G$282)/$G$284),0))) -> 0 | AX37: =IF(AD51<$G$282,0,MIN($G$279,1+IFERROR(INT((AD51-$G$282)/$G$284),0))) -> 0 | AY37: =IF(AE51<$G$282,0,MIN($G$279,1+IFERROR(INT((AE51-$G$282)/$G$284),0))) -> 1 | AZ37: =IF(AF51<$G$282,0,MIN($G$279,1+IFERROR(INT((AF51-$G$282)/$G$284),0))) -> 3 | BA37: =IF(AG51<$G$282,0,MIN($G$279,1+IFERROR(INT((AG51-$G$282)/$G$284),0))) -> 4 | BB37: =IF(AH51<$G$282,0,MIN($G$279,1+IFERROR(INT((AH51-$G$282)/$G$284),0))) -> 6
C38: =C39-$G$272 -> 0.25 | D38: {=IFERROR(IRR(IF($S$9:$X$9=0,$O12-$G$263,0)+IF($S$9:$X$9=$G$277,$G$268,0)+IF($S$9:$X$9=$G$278,Z12+$G$263-$O12-$G$268,0)),0)} -> 0.23396045 | E38: {=IFERROR(IRR(IF($S$9:$X$9=0,$O12-$G$263,0)+IF($S$9:$X$9=$G$277,$G$268,0)+IF($S$9:$X$9=$G$278,AA12+$G$263-$O12-$G$268,0)),0)} -> 0.24699426 | F38: {=IFERROR(IRR(IF($S$9:$X$9=0,$O12-$G$263,0)+IF($S$9:$X$9=$G$277,$G$268,0)+IF($S$9:$X$9=$G$278,AB12+$G$263-$O12-$G$268,0)),0)} -> 0.25950488 | G38: {=IFERROR(IRR(IF($S$9:$X$9=0,$O12-$G$263,0)+IF($S$9:$X$9=$G$277,$G$268,0)+IF($S$9:$X$9=$G$278,AC12+$G$263-$O12-$G$268,0)),0)} -> 0.27153732 | H38: {=IFERROR(IRR(IF($S$9:$X$9=0,$O12-$G$263,0)+IF($S$9:$X$9=$G$277,$G$268,0)+IF($S$9:$X$9=$G$278,AD12+$G$263-$O12-$G$268,0)),0)} -> 0.28313082 | I38: {=IFERROR(IRR(IF($S$9:$X$9=0,$O12-$G$263,0)+IF($S$9:$X$9=$G$277,$G$268,0)+IF($S$9:$X$9=$G$278,AE12+$G$263-$O12-$G$268,0)),0)} -> 0.29431987 | J38: {=IFERROR(IRR(IF($S$9:$X$9=0,$O12-$G$263,0)+IF($S$9:$X$9=$G$277,$G$268,0)+IF($S$9:$X$9=$G$278,AF12+$G$263-$O12-$G$268,0)),0)} -> 0.30513487 | K38: {=IFERROR(IRR(IF($S$9:$X$9=0,$O12-$G$263,0)+IF($S$9:$X$9=$G$277,$G$268,0)+IF($S$9:$X$9=$G$278,AG12+$G$263-$O12-$G$268,0)),0)} -> 0.31560284 | L38: {=IFERROR(IRR(IF($S$9:$X$9=0,$O12-$G$263,0)+IF($S$9:$X$9=$G$277,$G$268,0)+IF($S$9:$X$9=$G$278,AH12+$G$263-$O12-$G$268,0)),0)} -> 0.32574788 | AT38: =IF(Z52<$G$282,0,MIN($G$279,1+IFERROR(INT((Z52-$G$282)/$G$284),0))) -> 0 | AU38: =IF(AA52<$G$282,0,MIN($G$279,1+IFERROR(INT((AA52-$G$282)/$G$284),0))) -> 0 | AV38: =IF(AB52<$G$282,0,MIN($G$279,1+IFERROR(INT((AB52-$G$282)/$G$284),0))) -> 0 | AW38: =IF(AC52<$G$282,0,MIN($G$279,1+IFERROR(INT((AC52-$G$282)/$G$284),0))) -> 0 | AX38: =IF(AD52<$G$282,0,MIN($G$279,1+IFERROR(INT((AD52-$G$282)/$G$284),0))) -> 1 | AY38: =IF(AE52<$G$282,0,MIN($G$279,1+IFERROR(INT((AE52-$G$282)/$G$284),0))) -> 3 | AZ38: =IF(AF52<$G$282,0,MIN($G$279,1+IFERROR(INT((AF52-$G$282)/$G$284),0))) -> 4 | BA38: =IF(AG52<$G$282,0,MIN($G$279,1+IFERROR(INT((AG52-$G$282)/$G$284),0))) -> 5 | BB38: =IF(AH52<$G$282,0,MIN($G$279,1+IFERROR(INT((AH52-$G$282)/$G$284),0))) -> 7
C39: =$G$271 -> 0.3 | D39: {=IFERROR(IRR(IF($S$9:$X$9=0,$O13-$G$263,0)+IF($S$9:$X$9=$G$277,$G$268,0)+IF($S$9:$X$9=$G$278,Z13+$G$263-$O13-$G$268,0)),0)} -> 0.24658777 | E39: {=IFERROR(IRR(IF($S$9:$X$9=0,$O13-$G$263,0)+IF($S$9:$X$9=$G$277,$G$268,0)+IF($S$9:$X$9=$G$278,AA13+$G$263-$O13-$G$268,0)),0)} -> 0.25809533 | F39: {=IFERROR(IRR(IF($S$9:$X$9=0,$O13-$G$263,0)+IF($S$9:$X$9=$G$277,$G$268,0)+IF($S$9:$X$9=$G$278,AB13+$G$263-$O13-$G$268,0)),0)} -> 0.26919663 | G39: {=IFERROR(IRR(IF($S$9:$X$9=0,$O13-$G$263,0)+IF($S$9:$X$9=$G$277,$G$268,0)+IF($S$9:$X$9=$G$278,AC13+$G$263-$O13-$G$268,0)),0)} -> 0.2799226 | H39: {=IFERROR(IRR(IF($S$9:$X$9=0,$O13-$G$263,0)+IF($S$9:$X$9=$G$277,$G$268,0)+IF($S$9:$X$9=$G$278,AD13+$G$263-$O13-$G$268,0)),0)} -> 0.29030064 | I39: {=IFERROR(IRR(IF($S$9:$X$9=0,$O13-$G$263,0)+IF($S$9:$X$9=$G$277,$G$268,0)+IF($S$9:$X$9=$G$278,AE13+$G$263-$O13-$G$268,0)),0)} -> 0.30035514 | J39: {=IFERROR(IRR(IF($S$9:$X$9=0,$O13-$G$263,0)+IF($S$9:$X$9=$G$277,$G$268,0)+IF($S$9:$X$9=$G$278,AF13+$G$263-$O13-$G$268,0)),0)} -> 0.31010796 | K39: {=IFERROR(IRR(IF($S$9:$X$9=0,$O13-$G$263,0)+IF($S$9:$X$9=$G$277,$G$268,0)+IF($S$9:$X$9=$G$278,AG13+$G$263-$O13-$G$268,0)),0)} -> 0.31957873 | L39: {=IFERROR(IRR(IF($S$9:$X$9=0,$O13-$G$263,0)+IF($S$9:$X$9=$G$277,$G$268,0)+IF($S$9:$X$9=$G$278,AH13+$G$263-$O13-$G$268,0)),0)} -> 0.32878516 | AT39: =IF(Z53<$G$282,0,MIN($G$279,1+IFERROR(INT((Z53-$G$282)/$G$284),0))) -> 0 | AU39: =IF(AA53<$G$282,0,MIN($G$279,1+IFERROR(INT((AA53-$G$282)/$G$284),0))) -> 0 | AV39: =IF(AB53<$G$282,0,MIN($G$279,1+IFERROR(INT((AB53-$G$282)/$G$284),0))) -> 0 | AW39: =IF(AC53<$G$282,0,MIN($G$279,1+IFERROR(INT((AC53-$G$282)/$G$284),0))) -> 1 | AX39: =IF(AD53<$G$282,0,MIN($G$279,1+IFERROR(INT((AD53-$G$282)/$G$284),0))) -> 3 | AY39: =IF(AE53<$G$282,0,MIN($G$279,1+IFERROR(INT((AE53-$G$282)/$G$284),0))) -> 4 | AZ39: =IF(AF53<$G$282,0,MIN($G$279,1+IFERROR(INT((AF53-$G$282)/$G$284),0))) -> 5 | BA39: =IF(AG53<$G$282,0,MIN($G$279,1+IFERROR(INT((AG53-$G$282)/$G$284),0))) -> 6 | BB39: =IF(AH53<$G$282,0,MIN($G$279,1+IFERROR(INT((AH53-$G$282)/$G$284),0))) -> 8
C40: =C39+$G$272 -> 0.35 | D40: {=IFERROR(IRR(IF($S$9:$X$9=0,$O14-$G$263,0)+IF($S$9:$X$9=$G$277,$G$268,0)+IF($S$9:$X$9=$G$278,Z14+$G$263-$O14-$G$268,0)),0)} -> 0.25830224 | E40: {=IFERROR(IRR(IF($S$9:$X$9=0,$O14-$G$263,0)+IF($S$9:$X$9=$G$277,$G$268,0)+IF($S$9:$X$9=$G$278,AA14+$G$263-$O14-$G$268,0)),0)} -> 0.26844468 | F40: {=IFERROR(IRR(IF($S$9:$X$9=0,$O14-$G$263,0)+IF($S$9:$X$9=$G$277,$G$268,0)+IF($S$9:$X$9=$G$278,AB14+$G$263-$O14-$G$268,0)),0)} -> 0.27827273 | G40: {=IFERROR(IRR(IF($S$9:$X$9=0,$O14-$G$263,0)+IF($S$9:$X$9=$G$277,$G$268,0)+IF($S$9:$X$9=$G$278,AC14+$G$263-$O14-$G$268,0)),0)} -> 0.28780751 | H40: {=IFERROR(IRR(IF($S$9:$X$9=0,$O14-$G$263,0)+IF($S$9:$X$9=$G$277,$G$268,0)+IF($S$9:$X$9=$G$278,AD14+$G$263-$O14-$G$268,0)),0)} -> 0.29706799 | I40: {=IFERROR(IRR(IF($S$9:$X$9=0,$O14-$G$263,0)+IF($S$9:$X$9=$G$277,$G$268,0)+IF($S$9:$X$9=$G$278,AE14+$G$263-$O14-$G$268,0)),0)} -> 0.30607133 | J40: {=IFERROR(IRR(IF($S$9:$X$9=0,$O14-$G$263,0)+IF($S$9:$X$9=$G$277,$G$268,0)+IF($S$9:$X$9=$G$278,AF14+$G$263-$O14-$G$268,0)),0)} -> 0.31483304 | K40: {=IFERROR(IRR(IF($S$9:$X$9=0,$O14-$G$263,0)+IF($S$9:$X$9=$G$277,$G$268,0)+IF($S$9:$X$9=$G$278,AG14+$G$263-$O14-$G$268,0)),0)} -> 0.32336725 | L40: {=IFERROR(IRR(IF($S$9:$X$9=0,$O14-$G$263,0)+IF($S$9:$X$9=$G$277,$G$268,0)+IF($S$9:$X$9=$G$278,AH14+$G$263-$O14-$G$268,0)),0)} -> 0.33168683 | AT40: =IF(Z54<$G$282,0,MIN($G$279,1+IFERROR(INT((Z54-$G$282)/$G$284),0))) -> 0 | AU40: =IF(AA54<$G$282,0,MIN($G$279,1+IFERROR(INT((AA54-$G$282)/$G$284),0))) -> 0 | AV40: =IF(AB54<$G$282,0,MIN($G$279,1+IFERROR(INT((AB54-$G$282)/$G$284),0))) -> 2 | AW40: =IF(AC54<$G$282,0,MIN($G$279,1+IFERROR(INT((AC54-$G$282)/$G$284),0))) -> 3 | AX40: =IF(AD54<$G$282,0,MIN($G$279,1+IFERROR(INT((AD54-$G$282)/$G$284),0))) -> 4 | AY40: =IF(AE54<$G$282,0,MIN($G$279,1+IFERROR(INT((AE54-$G$282)/$G$284),0))) -> 5 | AZ40: =IF(AF54<$G$282,0,MIN($G$279,1+IFERROR(INT((AF54-$G$282)/$G$284),0))) -> 6 | BA40: =IF(AG54<$G$282,0,MIN($G$279,1+IFERROR(INT((AG54-$G$282)/$G$284),0))) -> 7 | BB40: =IF(AH54<$G$282,0,MIN($G$279,1+IFERROR(INT((AH54-$G$282)/$G$284),0))) -> 9
C41: =C40+$G$272 -> 0.4 | D41: {=IFERROR(IRR(IF($S$9:$X$9=0,$O15-$G$263,0)+IF($S$9:$X$9=$G$277,$G$268,0)+IF($S$9:$X$9=$G$278,Z15+$G$263-$O15-$G$268,0)),0)} -> 0.26921267 | E41: {=IFERROR(IRR(IF($S$9:$X$9=0,$O15-$G$263,0)+IF($S$9:$X$9=$G$277,$G$268,0)+IF($S$9:$X$9=$G$278,AA15+$G$263-$O15-$G$268,0)),0)} -> 0.27812566 | F41: {=IFERROR(IRR(IF($S$9:$X$9=0,$O15-$G$263,0)+IF($S$9:$X$9=$G$277,$G$268,0)+IF($S$9:$X$9=$G$278,AB15+$G$263-$O15-$G$268,0)),0)} -> 0.28679676 | G41: {=IFERROR(IRR(IF($S$9:$X$9=0,$O15-$G$263,0)+IF($S$9:$X$9=$G$277,$G$268,0)+IF($S$9:$X$9=$G$278,AC15+$G$263-$O15-$G$268,0)),0)} -> 0.29524025 | H41: {=IFERROR(IRR(IF($S$9:$X$9=0,$O15-$G$263,0)+IF($S$9:$X$9=$G$277,$G$268,0)+IF($S$9:$X$9=$G$278,AD15+$G$263-$O15-$G$268,0)),0)} -> 0.30346914 | I41: {=IFERROR(IRR(IF($S$9:$X$9=0,$O15-$G$263,0)+IF($S$9:$X$9=$G$277,$G$268,0)+IF($S$9:$X$9=$G$278,AE15+$G$263-$O15-$G$268,0)),0)} -> 0.31149533 | J41: {=IFERROR(IRR(IF($S$9:$X$9=0,$O15-$G$263,0)+IF($S$9:$X$9=$G$277,$G$268,0)+IF($S$9:$X$9=$G$278,AF15+$G$263-$O15-$G$268,0)),0)} -> 0.31932973 | K41: {=IFERROR(IRR(IF($S$9:$X$9=0,$O15-$G$263,0)+IF($S$9:$X$9=$G$277,$G$268,0)+IF($S$9:$X$9=$G$278,AG15+$G$263-$O15-$G$268,0)),0)} -> 0.32698234 | L41: {=IFERROR(IRR(IF($S$9:$X$9=0,$O15-$G$263,0)+IF($S$9:$X$9=$G$277,$G$268,0)+IF($S$9:$X$9=$G$278,AH15+$G$263-$O15-$G$268,0)),0)} -> 0.33446238 | AT41: =IF(Z55<$G$282,0,MIN($G$279,1+IFERROR(INT((Z55-$G$282)/$G$284),0))) -> 1 | AU41: =IF(AA55<$G$282,0,MIN($G$279,1+IFERROR(INT((AA55-$G$282)/$G$284),0))) -> 2 | AV41: =IF(AB55<$G$282,0,MIN($G$279,1+IFERROR(INT((AB55-$G$282)/$G$284),0))) -> 3 | AW41: =IF(AC55<$G$282,0,MIN($G$279,1+IFERROR(INT((AC55-$G$282)/$G$284),0))) -> 4 | AX41: =IF(AD55<$G$282,0,MIN($G$279,1+IFERROR(INT((AD55-$G$282)/$G$284),0))) -> 5 | AY41: =IF(AE55<$G$282,0,MIN($G$279,1+IFERROR(INT((AE55-$G$282)/$G$284),0))) -> 6 | AZ41: =IF(AF55<$G$282,0,MIN($G$279,1+IFERROR(INT((AF55-$G$282)/$G$284),0))) -> 7 | BA41: =IF(AG55<$G$282,0,MIN($G$279,1+IFERROR(INT((AG55-$G$282)/$G$284),0))) -> 8 | BB41: =IF(AH55<$G$282,0,MIN($G$279,1+IFERROR(INT((AH55-$G$282)/$G$284),0))) -> 10
C42: =C41+$G$272 -> 0.45 | D42: {=IFERROR(IRR(IF($S$9:$X$9=0,$O16-$G$263,0)+IF($S$9:$X$9=$G$277,$G$268,0)+IF($S$9:$X$9=$G$278,Z16+$G$263-$O16-$G$268,0)),0)} -> 0.27940999 | E42: {=IFERROR(IRR(IF($S$9:$X$9=0,$O16-$G$263,0)+IF($S$9:$X$9=$G$277,$G$268,0)+IF($S$9:$X$9=$G$278,AA16+$G$263-$O16-$G$268,0)),0)} -> 0.28720895 | F42: {=IFERROR(IRR(IF($S$9:$X$9=0,$O16-$G$263,0)+IF($S$9:$X$9=$G$277,$G$268,0)+IF($S$9:$X$9=$G$278,AB16+$G$263-$O16-$G$268,0)),0)} -> 0.29482335 | G42: {=IFERROR(IRR(IF($S$9:$X$9=0,$O16-$G$263,0)+IF($S$9:$X$9=$G$277,$G$268,0)+IF($S$9:$X$9=$G$278,AC16+$G$263-$O16-$G$268,0)),0)} -> 0.30226274 | H42: {=IFERROR(IRR(IF($S$9:$X$9=0,$O16-$G$263,0)+IF($S$9:$X$9=$G$277,$G$268,0)+IF($S$9:$X$9=$G$278,AD16+$G$263-$O16-$G$268,0)),0)} -> 0.30953592 | I42: {=IFERROR(IRR(IF($S$9:$X$9=0,$O16-$G$263,0)+IF($S$9:$X$9=$G$277,$G$268,0)+IF($S$9:$X$9=$G$278,AE16+$G$263-$O16-$G$268,0)),0)} -> 0.31665102 | J42: {=IFERROR(IRR(IF($S$9:$X$9=0,$O16-$G$263,0)+IF($S$9:$X$9=$G$277,$G$268,0)+IF($S$9:$X$9=$G$278,AF16+$G$263-$O16-$G$268,0)),0)} -> 0.32361556 | K42: {=IFERROR(IRR(IF($S$9:$X$9=0,$O16-$G$263,0)+IF($S$9:$X$9=$G$277,$G$268,0)+IF($S$9:$X$9=$G$278,AG16+$G$263-$O16-$G$268,0)),0)} -> 0.33043654 | L42: {=IFERROR(IRR(IF($S$9:$X$9=0,$O16-$G$263,0)+IF($S$9:$X$9=$G$277,$G$268,0)+IF($S$9:$X$9=$G$278,AH16+$G$263-$O16-$G$268,0)),0)} -> 0.33712043 | AT42: =IF(Z56<$G$282,0,MIN($G$279,1+IFERROR(INT((Z56-$G$282)/$G$284),0))) -> 3 | AU42: =IF(AA56<$G$282,0,MIN($G$279,1+IFERROR(INT((AA56-$G$282)/$G$284),0))) -> 4 | AV42: =IF(AB56<$G$282,0,MIN($G$279,1+IFERROR(INT((AB56-$G$282)/$G$284),0))) -> 5 | AW42: =IF(AC56<$G$282,0,MIN($G$279,1+IFERROR(INT((AC56-$G$282)/$G$284),0))) -> 6 | AX42: =IF(AD56<$G$282,0,MIN($G$279,1+IFERROR(INT((AD56-$G$282)/$G$284),0))) -> 7 | AY42: =IF(AE56<$G$282,0,MIN($G$279,1+IFERROR(INT((AE56-$G$282)/$G$284),0))) -> 8 | AZ42: =IF(AF56<$G$282,0,MIN($G$279,1+IFERROR(INT((AF56-$G$282)/$G$284),0))) -> 9 | BA42: =IF(AG56<$G$282,0,MIN($G$279,1+IFERROR(INT((AG56-$G$282)/$G$284),0))) -> 10 | BB42: =IF(AH56<$G$282,0,MIN($G$279,1+IFERROR(INT((AH56-$G$282)/$G$284),0))) -> 10
B43: IRR on Ben's cash flows: Yr 0 = cash at close less Keystone value today; earnout in Yr 3; Yr 5 = stake value
B45: Ben's Return Profile Based on Partnerning - Less Standalone
B46: Ben's Net Returns vs. Standalone Based on Topkey Growth & Rollover %
D48: Topkey ex-Keystone Value Growth (%) | Z48: Helper: Unrounded Net Return vs. Standalone
...

Sheet 100% Buyout Analysis
B2: =Cover!$B$24 -> Keystone Bookkeepers
B3: Valuation Growth Scenarios ($000s) | G3: Print | H3: 1
B5: Revenue Growth Assumptions | C5: Value | F5: Rationale / Notes
B6: General Assumptions
B7: Horizon (Years) | C7: ='Offer Comparison'!$D$7 -> 5 | F7: Projection horizon for Year 5 columns
B8: Est. Topkey Dilution — Ben's Stake (Year 5) | C8: ='Offer Comparison'!$D$8 -> 0.05 | F8: AMB estimate: future Topkey equity issuance (capital raise, option pool, acquisitions) reduces Ben's Topkey % by this share by Year 5
B9: Topkey - Current Monthly Revenue | C9: 261 | F9: Topkey-provided monthly revenue ($000s). Red: source pending confirmation
B10: Topkey - Current Run-Rate Revenue | C10: =C9*12 -> 3132
B11: Topkey - Current Revenue Multiple | C11: =IFERROR(C176/C10,0) -> 19.157088 | F11: Implied multiple: Topkey pre-deal valuation (C163) ÷ run-rate revenue (C9)
B12: Topkey - Future Revenue Multiple | C12: =C11 -> 19.157088 | F12: Assumed flat at current multiple
B13: Topkey - Current Client Count | C13: 325 | F13: Topkey-provided client count. Red: source pending confirmation
B14: Topkey - Avg. Revenue Per Client | C14: =C10/C13 -> 9.6369231
B15: Topkey - Annual Net Client Wins | C15: 130 | F15: AMB placeholder. Red: source pending confirmation
B16: Total Net Client Wins | C16: =C15*$C$7 -> 650
B17: Total Additional Revenue | C17: =C16*C14 -> 6264
B18: ="Check - "&$C$7&" Year Topkey Valuation Growth" -> Check - 5 Year Topkey Valuation Growth | C18: =IFERROR(D75/C75-1,0) -> 2.0084034 | F18: % growth in Topkey ex-Keystone Value (row 73), Today → Year N
B20: Keystone Standalone Assumptions
B21: Revenue Multiple | C21: ='Offer Comparison'!$D$13 -> 1 | F21: Keystone standalone valued at 1.0x revenue (offer implies ~1.00x)
B22: Scaled Revenue Multiple | C22: ='Offer Comparison'!$D$14 -> 1.25 | F22: Future revenue multiple for Keystone
B23: Avg. Revenue Per Client | C23: =+'Steady-State Staffing'!AB8 -> 16.631473 | F23: Sep'26 annualized fee per non-tax client (Steady-State Staffing AB8)
B24: Target Monthly Net Client Wins | C24: 3 | F24: Target pace per AMB; LTM actual is 26/yr (~2.2/month), see build at rows 170-175
B25: Annual Net Client Wins | C25: =C24*12 -> 36 | F25: Target monthly pace × 12
B26: Total Net Client Wins | C26: =C25*$C$7 -> 180
B27: Total Additional Revenue | C27: =C26*C23 -> 2993.6651
B29: Keystone Partnership Assumptions
B30: Software-Integration Revenue Multiple | C30: ='Offer Comparison'!$D$15 -> 2 | F30: Assumed revenue multiple for software-integrated partnership
B31: VR Platform Run-Rate Tech Cost | C31: 240 | F31: Run-rate tech cost provided by the target; memo only — VR savings assumed captured in the 20% partnership margin (C109) and revenue multiple
B33: =+B23 -> Avg. Revenue Per Client | C33: =+C23 -> 16.631473
B34: (+) Software-Enabled Price Increase / Client | C34: 0 | F34: Only if Topkey software supports higher client fees; VR platform cost no longer added to revenue per client
B35: Total Avg. Revenue Per Client | C35: =+C33+C34 -> 16.631473
B37: =+B25 -> Annual Net Client Wins | C37: =+C25 -> 36
B38: (+) Additional Annual Net Client Wins From Topkey | C38: 12 | F38: Topkey-provided. Red: source pending confirmation
B39: Total Annual Net Client Wins | C39: =SUM(C37:C38) -> 48
B40: Total Net Client Wins | C40: =C39*$C$7 -> 240
B41: Total Additional Revenue | C41: =C40*C35 -> 3991.5535
B42: Increase in Keystone Revenue vs. Standalone | C42: =C41-C27 -> 997.88838
B44: Cash Earnout — Year 3 Keystone Revenue (Sliding Scale)
B45: Earnout Measurement Year | C45: 3 | F45: Earnout measured on Year 3 run-rate: average of months 34–36 × 12 (see C54)
B46: Keystone Revenue at Close | C46: =C172 -> 2998.541 | F46: PF Jul'26 run-rate revenue at close (C159); unchanged
B47: Year 3 Run-Rate Revenue Target | C47: =C46+C41*(C45-(C56-1)/2/12)/C7 -> 5326.9472 | F47: Run-rate at close + partnership added revenue ramped to the midpoint of the averaging window (month 35 ÷ 60); same basis as the earnout measurement
...

Sheet Partnership Analysis
B2: =Cover!$B$24 -> Keystone Bookkeepers
B3: Partnership Rollover Scenarios ($000s) | G3: Print | H3: 1
B5: Revenue Growth Assumptions | C5: Value | F5: Rationale / Notes
B6: General Assumptions
B7: Ben's Rollover % — Keystone | C7: 0.3 | F7: Share of Keystone Ben keeps; Topkey buys the rest for cash + Topkey equity (per AMB)
B8: Est. Topkey Dilution — Ben's Stake (Year 5) | C8: ='Offer Comparison'!$C$8 -> 0.05 | F8: AMB estimate: future Topkey equity issuance (capital raise, option pool, acquisitions) reduces Ben's Topkey % by this share by Year 5
B9: Horizon (Years) | C9: ='Offer Comparison'!$C$7 -> 5 | F9: Projection horizon for Year 5 columns
B10: Topkey - Current Monthly Revenue | C10: 261 | F10: Topkey-provided monthly revenue ($000s). Red: source pending confirmation
B11: Topkey - Current Run-Rate Revenue | C11: =C10*12 -> 3132
B12: Topkey - Current Revenue Multiple | C12: =IFERROR(C191/C11,0) -> 19.157088 | F12: Implied multiple: Topkey pre-deal valuation (C175) ÷ run-rate revenue (C10)
B13: Topkey - Future Revenue Multiple | C13: =C12 -> 19.157088 | F13: Assumed flat at current multiple
B14: Topkey - Current Client Count | C14: 325 | F14: Topkey-provided client count. Red: source pending confirmation
B15: Topkey - Avg. Revenue Per Client | C15: =C11/C14 -> 9.6369231
B16: Topkey - Annual Net Client Wins | C16: 130 | F16: AMB placeholder. Red: source pending confirmation
B17: Total Net Client Wins | C17: =C16*$C$9 -> 650
B18: Total Additional Revenue | C18: =C17*C15 -> 6264
B19: ="Check - "&$C$9&" Year Topkey Valuation Growth" -> Check - 5 Year Topkey Valuation Growth | C19: =IFERROR(D81/C81-1,0) -> 2.021904 | F19: % growth in Topkey ex-Keystone Value (row 80), Today → Year N
B21: Keystone Standalone Assumptions
B22: Revenue Multiple | C22: ='Offer Comparison'!$C$13 -> 1 | F22: Keystone standalone valued at 1.0x revenue (offer implies ~1.00x)
B23: Scaled Revenue Multiple | C23: ='Offer Comparison'!$C$14 -> 1.25 | F23: Future revenue multiple for Keystone
B24: Avg. Revenue Per Client | C24: =+'Steady-State Staffing'!AB8 -> 16.631473 | F24: Sep'26 annualized fee per non-tax client (Steady-State Staffing AB8)
B25: Target Monthly Net Client Wins | C25: 3 | F25: Target pace per AMB; LTM actual is 26/yr (~2.2/month), see build at rows 183-188
B26: Annual Net Client Wins | C26: =C25*12 -> 36 | F26: Target monthly pace × 12
B27: Total Net Client Wins | C27: =C26*$C$9 -> 180
B28: Total Additional Revenue | C28: =C27*C24 -> 2993.6651
B30: Keystone Partnership Assumptions
B31: Software-Integration Revenue Multiple | C31: ='Offer Comparison'!$C$15 -> 2 | F31: Assumed revenue multiple for software-integrated partnership
B32: VR Platform Run-Rate Tech Cost | C32: 240 | F32: Run-rate tech cost provided by the target
B34: =+B24 -> Avg. Revenue Per Client | C34: =+C24 -> 16.631473
B35: (+) Software-Enabled Price Increase / Client | C35: 0 | F35: Only if Topkey software supports higher client fees; VR cost treated as a cost (memo block at rows 190-200)
B36: Total Avg. Revenue Per Client | C36: =+C34+C35 -> 16.631473
B38: =+B26 -> Annual Net Client Wins | C38: =+C26 -> 36
B39: (+) Additional Annual Net Client Wins From Topkey | C39: 12 | F39: Topkey-provided. Red: source pending confirmation
B40: Total Annual Net Client Wins | C40: =SUM(C38:C39) -> 48
B41: Total Net Client Wins | C41: =C40*$C$9 -> 240
B42: Total Additional Revenue | C42: =C41*C36 -> 3991.5535
B43: Increase in Keystone Revenue vs. Standalone | C43: =C42-C28 -> 997.88838
B45: Cash Earnout — Year 3 Keystone Revenue (Sliding Scale)
B46: Earnout Measurement Year | C46: 3 | F46: Earnout measured on Year 3 run-rate: average of months 34–36 × 12 (see C55)
B47: Keystone Revenue at Close | C47: =C184 -> 2998.541 | F47: PF Jul'26 run-rate revenue at close (C168); unchanged
...

Sheet P&L Overview
B2: =+Cover!B24 -> Keystone Bookkeepers
B3: Summary P&L Overview ($000s) | P3: Print | Q3: 1
C5: Full Year | F5: YTD | I5: LTM | K5: PF | M5: PF Delta
B6: P&L Summary | C6: 2024 | D6: 2025 | F6: July'25 | G6: July'26 | I6: July'25 | J6: July'26 | K6: July'26 | M6: ($) | N6: (%)
B7: Revenue
B8: =+'P&L Forecast'!B7 -> STR Subscription | C8: =+'P&L Forecast'!C7 -> 793.47225 | D8: =+'P&L Forecast'!D7 -> 1450.4923 | F8: =+'P&L Forecast'!F7 -> 751.5286 | G8: =+'P&L Forecast'!G7 -> 1261.4769 | I8: =+'P&L Forecast'!I7 -> 1152.3203 | J8: =+'P&L Forecast'!J7 -> 1960.4406 | K8: =+'P&L Forecast'!K7 -> 2410.05 | M8: =K8-J8 -> 449.6094 | N8: =IFERROR(K8/J8-1,0) -> 0.229341
B9: =+'P&L Forecast'!B8 -> Occupancy Taxes | C9: =+'P&L Forecast'!C8 -> 0.56 | D9: =+'P&L Forecast'!D8 -> 55.0805 | F9: =+'P&L Forecast'!F8 -> 23.2255 | G9: =+'P&L Forecast'!G8 -> 91.65114 | I9: =+'P&L Forecast'!I8 -> 23.7855 | J9: =+'P&L Forecast'!J8 -> 123.50614 | K9: =+'P&L Forecast'!K8 -> 192.8298 | M9: =K9-J9 -> 69.32366 | N9: =IFERROR(K9/J9-1,0) -> 0.56129728
