Workbook

Sheet Cover
B24: Keystone Bookkeepers
B25: Initial Financial Review
B26: ="As of "&TEXT(TODAY(),"mm/dd/yy") -> As of 09/08/26

Sheet P&L Overview
B2: =+Cover!B24 -> Keystone Bookkeepers
B3: Summary P&L Overview ($000s) | P3: Print | Q3: 1
C5: Full Year | F5: YTD | I5: LTM | K5: PF | M5: PF Delta
B6: P&L Summary | C6: 2024 | D6: 2025 | F6: July'25 | G6: July'26 | I6: July'25 | J6: July'26 | K6: July'26 | M6: ($) | N6: (%)
B7: Revenue
B8: =+'P&L Forecast'!B7 -> STR Subscription | C8: =+'P&L Forecast'!C7 -> 793.47225 | D8: =+'P&L Forecast'!D7 -> 1450.4923 | F8: =+'P&L Forecast'!F7 -> 751.5286 | G8: =+'P&L Forecast'!G7 -> 1261.4769 | I8: =+'P&L Forecast'!I7 -> 1152.3203 | J8: =+'P&L Forecast'!J7 -> 1960.4406 | K8: =+'P&L Forecast'!K7 -> 2410.05 | M8: =K8-J8 -> 449.6094 | N8: =IFERROR(K8/J8-1,0) -> 0.229341
B9: =+'P&L Forecast'!B8 -> Occupancy Taxes | C9: =+'P&L Forecast'!C8 -> 0.56 | D9: =+'P&L Forecast'!D8 -> 55.0805 | F9: =+'P&L Forecast'!F8 -> 23.2255 | G9: =+'P&L Forecast'!G8 -> 91.65114 | I9: =+'P&L Forecast'!I8 -> 23.7855 | J9: =+'P&L Forecast'!J8 -> 123.50614 | K9: =+'P&L Forecast'!K8 -> 192.8298 | M9: =K9-J9 -> 69.32366 | N9: =IFERROR(K9/J9-1,0) -> 0.56129728
B10: =+'P&L Forecast'!B9 -> SMB Subscription | C10: =+'P&L Forecast'!C9 -> 224.791 | D10: =+'P&L Forecast'!D9 -> 149.77 | F10: =+'P&L Forecast'!F9 -> 90.4525 | G10: =+'P&L Forecast'!G9 -> 73.4185 | I10: =+'P&L Forecast'!I9 -> 169.5465 | J10: =+'P&L Forecast'!J9 -> 132.736 | K10: =+'P&L Forecast'!K9 -> 119.706 | M10: =K10-J10 -> -13.03 | N10: =IFERROR(K10/J10-1,0) -> -0.098164778
B11: =+'P&L Forecast'!B10 -> Onboarding | C11: =+'P&L Forecast'!C10 -> 44.0585 | D11: =+'P&L Forecast'!D10 -> 74.5193 | F11: =+'P&L Forecast'!F10 -> 42.25405 | G11: =+'P&L Forecast'!G10 -> 59.055 | I11: =+'P&L Forecast'!I10 -> 57.49255 | J11: =+'P&L Forecast'!J10 -> 91.32025 | K11: =+'P&L Forecast'!K10 -> 103.5675 | M11: =K11-J11 -> 12.24725 | N11: =IFERROR(K11/J11-1,0) -> 0.13411319
B12: =+'P&L Forecast'!B11 -> Topkey Subscription | C12: =+'P&L Forecast'!C11 -> 0 | D12: =+'P&L Forecast'!D11 -> 9.947 | F12: =+'P&L Forecast'!F11 -> 0 | G12: =+'P&L Forecast'!G11 -> 45.086 | I12: =+'P&L Forecast'!I11 -> 0 | J12: =+'P&L Forecast'!J11 -> 55.033 | K12: =+'P&L Forecast'!K11 -> 94.836 | M12: =K12-J12 -> 39.803 | N12: =IFERROR(K12/J12-1,0) -> 0.72325695
B13: =+'P&L Forecast'!B12 -> STR Bill Pay | C13: =+'P&L Forecast'!C12 -> 0.06 | D13: =+'P&L Forecast'!D12 -> 36.6065 | F13: =+'P&L Forecast'!F12 -> 15.4915 | G13: =+'P&L Forecast'!G12 -> 45.13 | I13: =+'P&L Forecast'!I12 -> 15.5515 | J13: =+'P&L Forecast'!J12 -> 66.245 | K13: =+'P&L Forecast'!K12 -> 83.46 | M13: =K13-J13 -> 17.215 | N13: =IFERROR(K13/J13-1,0) -> 0.25986867
B14: =+'P&L Forecast'!B13 -> Controller Services | C14: =+'P&L Forecast'!C13 -> 13.75 | D14: =+'P&L Forecast'!D13 -> 46.4 | F14: =+'P&L Forecast'!F13 -> 31.5 | G14: =+'P&L Forecast'!G13 -> 24.25 | I14: =+'P&L Forecast'!I13 -> 44 | J14: =+'P&L Forecast'!J13 -> 39.15 | K14: =+'P&L Forecast'!K13 -> 42 | M14: =K14-J14 -> 2.85 | N14: =IFERROR(K14/J14-1,0) -> 0.072796935
B15: Other Revenue | C15: =+C16-SUM(C8:C14) -> 58.2741 | D15: =+D16-SUM(D8:D14) -> 56.56748 | F15: =+F16-SUM(F8:F14) -> 43.42095 | G15: =+G16-SUM(G8:G14) -> 70.95371 | I15: =+I16-SUM(I8:I14) -> 61.71435 | J15: =+J16-SUM(J8:J14) -> 84.10024 | K15: =+K16-SUM(K8:K14) -> 26.83622 | M15: =K15-J15 -> -57.26402 | N15: =IFERROR(K15/J15-1,0) -> -0.68090198
B16: Total Revenue | C16: =+'P&L Forecast'!C24 -> 1134.9659 | D16: =+'P&L Forecast'!D24 -> 1879.3831 | F16: =+'P&L Forecast'!F24 -> 997.8731 | G16: =+'P&L Forecast'!G24 -> 1671.0212 | I16: =+'P&L Forecast'!I24 -> 1524.4107 | J16: =+'P&L Forecast'!J24 -> 2552.5312 | K16: =+'P&L Forecast'!K24 -> 3073.2855 | M16: =SUM(M8:M15) -> 520.75429 | N16: =IFERROR(K16/J16-1,0) -> 0.20401486
B18: Expenses
B19: =+'P&L Forecast'!B27 -> Indirect Labor | C19: =+'P&L Forecast'!C27 -> 101.3752 | D19: =+'P&L Forecast'!D27 -> 281.24054 | F19: =+'P&L Forecast'!F27 -> 136.29648 | G19: =+'P&L Forecast'!G27 -> 357.27472 | I19: =+'P&L Forecast'!I27 -> 202.41598 | J19: =+'P&L Forecast'!J27 -> 502.21878 | K19: =+'P&L Forecast'!K27 -> 694.74456 | M19: =K19-J19 -> 192.52578 | N19: =IFERROR(K19/J19-1,0) -> 0.38335042 | P19: =K19/$K$28 -> 0.32182939
B20: =+'P&L Forecast'!B28 -> Bookkeeper Wages | C20: =+'P&L Forecast'!C28 -> 183.36903 | D20: =+'P&L Forecast'!D28 -> 316.18462 | F20: =+'P&L Forecast'!F28 -> 147.26813 | G20: =+'P&L Forecast'!G28 -> 267.7574 | I20: =+'P&L Forecast'!I28 -> 240.18098 | J20: =+'P&L Forecast'!J28 -> 436.67389 | K20: =+'P&L Forecast'!K28 -> 533.8512 | M20: =K20-J20 -> 97.17731 | N20: =IFERROR(K20/J20-1,0) -> 0.22253978 | P20: =K20/$K$28 -> 0.2472981
B21: =+'P&L Forecast'!B29 -> Client Lead Wages | C21: =+'P&L Forecast'!C29 -> 286.16129 | D21: =+'P&L Forecast'!D29 -> 352.95844 | F21: =+'P&L Forecast'!F29 -> 201.27983 | G21: =+'P&L Forecast'!G29 -> 202.05309 | I21: =+'P&L Forecast'!I29 -> 353.12843 | J21: =+'P&L Forecast'!J29 -> 353.7317 | K21: =+'P&L Forecast'!K29 -> 392.92452 | M21: =K21-J21 -> 39.19282 | N21: =IFERROR(K21/J21-1,0) -> 0.11079816 | P21: =K21/$K$28 -> 0.18201605
B22: =+'P&L Forecast'!B30 -> Onboarding Team Wages | C22: =+'P&L Forecast'!C30 -> 122.81255 | D22: =+'P&L Forecast'!D30 -> 152.16972 | F22: =+'P&L Forecast'!F30 -> 73.94962 | G22: =+'P&L Forecast'!G30 -> 111.27999 | I22: =+'P&L Forecast'!I30 -> 121.30735 | J22: =+'P&L Forecast'!J30 -> 189.50009 | K22: =+'P&L Forecast'!K30 -> 197.14944 | M22: =K22-J22 -> 7.64935 | N22: =IFERROR(K22/J22-1,0) -> 0.040365944 | P22: =K22/$K$28 -> 0.091326349
B23: =+'P&L Forecast'!B31 -> Owner Wages | C23: =+'P&L Forecast'!C31 -> 0 | D23: =+'P&L Forecast'!D31 -> 90.66704 | F23: =+'P&L Forecast'!F31 -> 45.46612 | G23: =+'P&L Forecast'!G31 -> 63.14302 | I23: =+'P&L Forecast'!I31 -> 45.46612 | J23: =+'P&L Forecast'!J31 -> 108.34394 | K23: =+'P&L Forecast'!K31 -> 108.34394 | M23: =K23-J23 -> 0 | N23: =IFERROR(K23/J23-1,0) -> 0 | P23: =K23/$K$28 -> 0.050188611
B24: =+'P&L Forecast'!B32 -> S&M Wages | C24: =+'P&L Forecast'!C32 -> 0 | D24: =+'P&L Forecast'!D32 -> 19.14963 | F24: =+'P&L Forecast'!F32 -> 3.09945 | G24: =+'P&L Forecast'!G32 -> 51.94131 | I24: =+'P&L Forecast'!I32 -> 3.09945 | J24: =+'P&L Forecast'!J32 -> 67.99149 | K24: =+'P&L Forecast'!K32 -> 98.34912 | M24: =K24-J24 -> 30.35763 | N24: =IFERROR(K24/J24-1,0) -> 0.44649161 | P24: =K24/$K$28 -> 0.045558669
B25: =+'P&L Forecast'!B33 -> Occupancy Tax Specialist | C25: =+'P&L Forecast'!C33 -> 1.11335 | D25: =+'P&L Forecast'!D33 -> 29.56415 | F25: =+'P&L Forecast'!F33 -> 14.27585 | G25: =+'P&L Forecast'!G33 -> 42.08505 | I25: =+'P&L Forecast'!I33 -> 15.3892 | J25: =+'P&L Forecast'!J33 -> 57.37335 | K25: =+'P&L Forecast'!K33 -> 68.1132 | M25: =K25-J25 -> 10.73985 | N25: =IFERROR(K25/J25-1,0) -> 0.18719231 | P25: =K25/$K$28 -> 0.031552359
B26: =+'P&L Forecast'!B34 -> Sr. Client Lead Wages | C26: =+'P&L Forecast'!C34 -> 0 | D26: =+'P&L Forecast'!D34 -> 0 | F26: =+'P&L Forecast'!F34 -> 0 | G26: =+'P&L Forecast'!G34 -> 7.995 | I26: =+'P&L Forecast'!I34 -> 0 | J26: =+'P&L Forecast'!J34 -> 7.995 | K26: =+'P&L Forecast'!K34 -> 33.08124 | M26: =K26-J26 -> 25.08624 | N26: =IFERROR(K26/J26-1,0) -> 3.1377411 | P26: =K26/$K$28 -> 0.015324359
B27: =+'P&L Forecast'!B35 -> Employee Benefits | C27: =+'P&L Forecast'!C35 -> 5.37405 | D27: =+'P&L Forecast'!D35 -> 19.23245 | F27: =+'P&L Forecast'!F35 -> 9.02166 | G27: =+'P&L Forecast'!G35 -> 17.36251 | I27: =+'P&L Forecast'!I35 -> 12.16686 | J27: =+'P&L Forecast'!J35 -> 27.5733 | K27: =+'P&L Forecast'!K35 -> 32.17836 | M27: =K27-J27 -> 4.60506 | N27: =IFERROR(K27/J27-1,0) -> 0.16701157 | P27: =K27/$K$28 -> 0.014906115
B28: =+'P&L Forecast'!B36 -> Total Payroll Expenses | C28: =SUM(C19:C27) -> 700.20547 | D28: =SUM(D19:D27) -> 1261.1666 | F28: =SUM(F19:F27) -> 630.65714 | G28: =SUM(G19:G27) -> 1120.8921 | I28: =SUM(I19:I27) -> 993.15437 | J28: =SUM(J19:J27) -> 1751.4015 | K28: =SUM(K19:K27) -> 2158.7356 | M28: =SUM(M19:M27) -> 407.33404 | N28: =K28/J28-1 -> 0.23257604
B30: =+'P&L Forecast'!B38 -> Software & Apps - COGS | C30: =+'P&L Forecast'!C38 -> 114.42269 | D30: =+'P&L Forecast'!D38 -> 157.49471 | F30: =+'P&L Forecast'!F38 -> 84.96859 | G30: =+'P&L Forecast'!G38 -> 152.28157 | I30: =+'P&L Forecast'!I38 -> 142.28345 | J30: =+'P&L Forecast'!J38 -> 224.80769 | K30: =+'P&L Forecast'!K38 -> 335.70816 | M30: =K30-J30 -> 110.90047 | N30: =IFERROR(K30/J30-1,0) -> 0.49331262
B31: =+'P&L Forecast'!B39 -> Software & Apps - G&A | C31: =+'P&L Forecast'!C39 -> 60.91594 | D31: =+'P&L Forecast'!D39 -> 117.05866 | F31: =+'P&L Forecast'!F39 -> 56.8115 | G31: =+'P&L Forecast'!G39 -> 97.04798 | I31: =+'P&L Forecast'!I39 -> 86.51489 | J31: =+'P&L Forecast'!J39 -> 157.29514 | K31: =+'P&L Forecast'!K39 -> 155.82264 | M31: =K31-J31 -> -1.4725 | N31: =IFERROR(K31/J31-1,0) -> -0.0093613827
B32: =+'P&L Forecast'!B40 -> Software & Apps - Topkey | C32: =+'P&L Forecast'!C40 -> 0 | D32: =+'P&L Forecast'!D40 -> 7.14125 | F32: =+'P&L Forecast'!F40 -> 0 | G32: =+'P&L Forecast'!G40 -> 28.82775 | I32: =+'P&L Forecast'!I40 -> 0 | J32: =+'P&L Forecast'!J40 -> 35.969 | K32: =+'P&L Forecast'!K40 -> 60.84 | M32: =K32-J32 -> 24.871 | N32: =IFERROR(K32/J32-1,0) -> 0.69145653
B33: =+'P&L Forecast'!B41 -> Software & Apps - AI tools | C33: =+'P&L Forecast'!C41 -> 0 | D33: =+'P&L Forecast'!D41 -> 0 | F33: =+'P&L Forecast'!F41 -> 0 | G33: =+'P&L Forecast'!G41 -> 6.52752 | I33: =+'P&L Forecast'!I41 -> 0 | J33: =+'P&L Forecast'!J41 -> 6.52752 | K33: =+'P&L Forecast'!K41 -> 15.74376 | M33: =K33-J33 -> 9.21624 | N33: =IFERROR(K33/J33-1,0) -> 1.4119053
B34: =+'P&L Forecast'!B42 -> Total Software Expenses | C34: =SUM(C30:C33) -> 175.33863 | D34: =SUM(D30:D33) -> 281.69462 | F34: =SUM(F30:F33) -> 141.78009 | G34: =SUM(G30:G33) -> 284.68482 | I34: =SUM(I30:I33) -> 228.79834 | J34: =SUM(J30:J33) -> 424.59935 | K34: =SUM(K30:K33) -> 568.11456 | M34: =SUM(M30:M33) -> 143.51521 | N34: =K34/J34-1 -> 0.33800148
B36: =+'P&L Forecast'!B44 -> Other Professional Fees | C36: =+'P&L Forecast'!C44 -> 18.23425 | D36: =+'P&L Forecast'!D44 -> 27.04095 | F36: =+'P&L Forecast'!F44 -> 12.014 | G36: =+'P&L Forecast'!G44 -> 57.55 | I36: =+'P&L Forecast'!I44 -> 21.74858 | J36: =+'P&L Forecast'!J44 -> 72.57695 | K36: =+'P&L Forecast'!K44 -> 72.57695 | M36: =K36-J36 -> 0 | N36: =IFERROR(K36/J36-1,0) -> 0
B37: =+'P&L Forecast'!B45 -> Referral Fees | C37: =+'P&L Forecast'!C45 -> 24.82 | D37: =+'P&L Forecast'!D45 -> 27.15374 | F37: =+'P&L Forecast'!F45 -> 17.0895 | G37: =+'P&L Forecast'!G45 -> 20.62969 | I37: =+'P&L Forecast'!I45 -> 26.2095 | J37: =+'P&L Forecast'!J45 -> 30.69393 | K37: =+'P&L Forecast'!K45 -> 30.69393 | M37: =K37-J37 -> 0 | N37: =IFERROR(K37/J37-1,0) -> 0
B38: =+'P&L Forecast'!B46 -> Travel, Meals & Entertainment | C38: =+'P&L Forecast'!C46 -> 0 | D38: =+'P&L Forecast'!D46 -> 29.76122 | F38: =+'P&L Forecast'!F46 -> 22.29558 | G38: =+'P&L Forecast'!G46 -> 20.68542 | I38: =+'P&L Forecast'!I46 -> 22.29558 | J38: =+'P&L Forecast'!J46 -> 28.15106 | K38: =+'P&L Forecast'!K46 -> 28.15106 | M38: =K38-J38 -> 0 | N38: =IFERROR(K38/J38-1,0) -> 0
B39: =+'P&L Forecast'!B47 -> Payment Collection Fees | C39: =+'P&L Forecast'!C47 -> 8.67099 | D39: =+'P&L Forecast'!D47 -> 13.35153 | F39: =+'P&L Forecast'!F47 -> 6.80445 | G39: =+'P&L Forecast'!G47 -> 9.02684 | I39: =+'P&L Forecast'!I47 -> 10.54373 | J39: =+'P&L Forecast'!J47 -> 15.57392 | K39: =+'P&L Forecast'!K47 -> 15.57392 | M39: =K39-J39 -> 0 | N39: =IFERROR(K39/J39-1,0) -> 0
B40: =+'P&L Forecast'!B48 -> Professional Organizations | C40: =+'P&L Forecast'!C48 -> 5.44332 | D40: =+'P&L Forecast'!D48 -> 11.22296 | F40: =+'P&L Forecast'!F48 -> 6.191 | G40: =+'P&L Forecast'!G48 -> 6.57881 | I40: =+'P&L Forecast'!I48 -> 9.53268 | J40: =+'P&L Forecast'!J48 -> 11.61077 | K40: =+'P&L Forecast'!K48 -> 11.61077 | M40: =K40-J40 -> 0 | N40: =IFERROR(K40/J40-1,0) -> 0
B41: =+'P&L Forecast'!B49 -> S&M Events | C41: =+'P&L Forecast'!C49 -> 0 | D41: =+'P&L Forecast'!D49 -> 11.4983 | F41: =+'P&L Forecast'!F49 -> 0 | G41: =+'P&L Forecast'!G49 -> 11.84548 | I41: =+'P&L Forecast'!I49 -> 0 | J41: =+'P&L Forecast'!J49 -> 23.34378 | K41: =+'P&L Forecast'!K49 -> 23.34378 | M41: =K41-J41 -> 0 | N41: =IFERROR(K41/J41-1,0) -> 0
B42: =+'P&L Forecast'!B50 -> Contract Labor - Tax | C42: =+'P&L Forecast'!C50 -> 0 | D42: =+'P&L Forecast'!D50 -> 1.5875 | F42: =+'P&L Forecast'!F50 -> 0 | G42: =+'P&L Forecast'!G50 -> 30.5155 | I42: =+'P&L Forecast'!I50 -> 0 | J42: =+'P&L Forecast'!J50 -> 32.103 | K42: =+'P&L Forecast'!K50 -> 10 | M42: =K42-J42 -> -22.103 | N42: =IFERROR(K42/J42-1,0) -> -0.68850263
B43: =+'P&L Forecast'!B51 -> Recruiting Fees | C43: =+'P&L Forecast'!C51 -> 14.90205 | D43: =+'P&L Forecast'!D51 -> 31.6041 | F43: =+'P&L Forecast'!F51 -> 28.29994 | G43: =+'P&L Forecast'!G51 -> 5.5646 | I43: =+'P&L Forecast'!I51 -> 35.34606 | J43: =+'P&L Forecast'!J51 -> 8.86876 | K43: =+'P&L Forecast'!K51 -> 8.86876 | M43: =K43-J43 -> 0 | N43: =IFERROR(K43/J43-1,0) -> 0
B44: Other Expenses | C44: =+C45-SUM(C36:C43) -> 41.87929 | D44: =+D45-SUM(D36:D43) -> 52.32132 | F44: =+F45-SUM(F36:F43) -> 28.90542 | G44: =+G45-SUM(G36:G43) -> 26.90445 | I44: =+I45-SUM(I36:I43) -> 41.76881 | J44: =+J45-SUM(J36:J43) -> 50.32035 | K44: =+K45-SUM(K36:K43) -> 49.10777 | M44: =K44-J44 -> -1.21258 | N44: =IFERROR(K44/J44-1,0) -> -0.024097209
B45: Total Overhead | C45: =+'P&L Forecast'!C62 -> 113.9499 | D45: =+'P&L Forecast'!D62 -> 205.54162 | F45: =+'P&L Forecast'!F62 -> 121.59989 | G45: =+'P&L Forecast'!G62 -> 189.30079 | I45: =+'P&L Forecast'!I62 -> 167.44494 | J45: =+'P&L Forecast'!J62 -> 273.24252 | K45: =+'P&L Forecast'!K62 -> 249.92694 | M45: =SUM(M36:M44) -> -23.31558 | N45: =K45/J45-1 -> -0.085329253
...

Sheet P&L Overview (Target Version)
B2: =+Cover!B24 -> Keystone Bookkeepers
B3: Summary P&L Overview ($000s) | P3: Print | Q3: 1
C5: Full Year | F5: YTD | I5: LTM | K5: PF | M5: PF Delta
B6: P&L Summary | C6: 2024 | D6: 2025 | F6: July'25 | G6: July'26 | I6: July'25 | J6: July'26 | K6: July'26 | M6: ($) | N6: (%)
B7: Revenue
B8: =+'P&L Forecast'!B7 -> STR Subscription | C8: =+'P&L Forecast'!C7 -> 793.47225 | D8: =+'P&L Forecast'!D7 -> 1450.4923 | F8: =+'P&L Forecast'!F7 -> 751.5286 | G8: =+'P&L Forecast'!G7 -> 1261.4769 | I8: =+'P&L Forecast'!I7 -> 1152.3203 | J8: =+'P&L Forecast'!J7 -> 1960.4406 | K8: =+'P&L Forecast'!K7 -> 2410.05 | M8: =K8-J8 -> 449.6094 | N8: =IFERROR(K8/J8-1,0) -> 0.229341
B9: =+'P&L Forecast'!B8 -> Occupancy Taxes | C9: =+'P&L Forecast'!C8 -> 0.56 | D9: =+'P&L Forecast'!D8 -> 55.0805 | F9: =+'P&L Forecast'!F8 -> 23.2255 | G9: =+'P&L Forecast'!G8 -> 91.65114 | I9: =+'P&L Forecast'!I8 -> 23.7855 | J9: =+'P&L Forecast'!J8 -> 123.50614 | K9: =+'P&L Forecast'!K8 -> 192.8298 | M9: =K9-J9 -> 69.32366 | N9: =IFERROR(K9/J9-1,0) -> 0.56129728
B10: =+'P&L Forecast'!B9 -> SMB Subscription | C10: =+'P&L Forecast'!C9 -> 224.791 | D10: =+'P&L Forecast'!D9 -> 149.77 | F10: =+'P&L Forecast'!F9 -> 90.4525 | G10: =+'P&L Forecast'!G9 -> 73.4185 | I10: =+'P&L Forecast'!I9 -> 169.5465 | J10: =+'P&L Forecast'!J9 -> 132.736 | K10: =+'P&L Forecast'!K9 -> 119.706 | M10: =K10-J10 -> -13.03 | N10: =IFERROR(K10/J10-1,0) -> -0.098164778
B11: =+'P&L Forecast'!B10 -> Onboarding | C11: =+'P&L Forecast'!C10 -> 44.0585 | D11: =+'P&L Forecast'!D10 -> 74.5193 | F11: =+'P&L Forecast'!F10 -> 42.25405 | G11: =+'P&L Forecast'!G10 -> 59.055 | I11: =+'P&L Forecast'!I10 -> 57.49255 | J11: =+'P&L Forecast'!J10 -> 91.32025 | K11: =+'P&L Forecast'!K10 -> 103.5675 | M11: =K11-J11 -> 12.24725 | N11: =IFERROR(K11/J11-1,0) -> 0.13411319
B12: =+'P&L Forecast'!B11 -> Topkey Subscription | C12: =+'P&L Forecast'!C11 -> 0 | D12: =+'P&L Forecast'!D11 -> 9.947 | F12: =+'P&L Forecast'!F11 -> 0 | G12: =+'P&L Forecast'!G11 -> 45.086 | I12: =+'P&L Forecast'!I11 -> 0 | J12: =+'P&L Forecast'!J11 -> 55.033 | K12: =+'P&L Forecast'!K11 -> 94.836 | M12: =K12-J12 -> 39.803 | N12: =IFERROR(K12/J12-1,0) -> 0.72325695
B13: =+'P&L Forecast'!B12 -> STR Bill Pay | C13: =+'P&L Forecast'!C12 -> 0.06 | D13: =+'P&L Forecast'!D12 -> 36.6065 | F13: =+'P&L Forecast'!F12 -> 15.4915 | G13: =+'P&L Forecast'!G12 -> 45.13 | I13: =+'P&L Forecast'!I12 -> 15.5515 | J13: =+'P&L Forecast'!J12 -> 66.245 | K13: =+'P&L Forecast'!K12 -> 83.46 | M13: =K13-J13 -> 17.215 | N13: =IFERROR(K13/J13-1,0) -> 0.25986867
B14: =+'P&L Forecast'!B13 -> Controller Services | C14: =+'P&L Forecast'!C13 -> 13.75 | D14: =+'P&L Forecast'!D13 -> 46.4 | F14: =+'P&L Forecast'!F13 -> 31.5 | G14: =+'P&L Forecast'!G13 -> 24.25 | I14: =+'P&L Forecast'!I13 -> 44 | J14: =+'P&L Forecast'!J13 -> 39.15 | K14: =+'P&L Forecast'!K13 -> 42 | M14: =K14-J14 -> 2.85 | N14: =IFERROR(K14/J14-1,0) -> 0.072796935
B15: Other Revenue | C15: =+C16-SUM(C8:C14) -> 58.2741 | D15: =+D16-SUM(D8:D14) -> 56.56748 | F15: =+F16-SUM(F8:F14) -> 43.42095 | G15: =+G16-SUM(G8:G14) -> 70.95371 | I15: =+I16-SUM(I8:I14) -> 61.71435 | J15: =+J16-SUM(J8:J14) -> 84.10024 | K15: =+K16-SUM(K8:K14) -> 26.83622 | M15: =K15-J15 -> -57.26402 | N15: =IFERROR(K15/J15-1,0) -> -0.68090198
B16: Total Revenue | C16: =+'P&L Forecast'!C24 -> 1134.9659 | D16: =+'P&L Forecast'!D24 -> 1879.3831 | F16: =+'P&L Forecast'!F24 -> 997.8731 | G16: =+'P&L Forecast'!G24 -> 1671.0212 | I16: =+'P&L Forecast'!I24 -> 1524.4107 | J16: =+'P&L Forecast'!J24 -> 2552.5312 | K16: =+'P&L Forecast'!K24 -> 3073.2855 | M16: =SUM(M8:M15) -> 520.75429 | N16: =IFERROR(K16/J16-1,0) -> 0.20401486
B18: Expenses
B19: =+'P&L Forecast'!B27 -> Indirect Labor | C19: =+'P&L Forecast'!C27 -> 101.3752 | D19: =+'P&L Forecast'!D27 -> 281.24054 | F19: =+'P&L Forecast'!F27 -> 136.29648 | G19: =+'P&L Forecast'!G27 -> 357.27472 | I19: =+'P&L Forecast'!I27 -> 202.41598 | J19: =+'P&L Forecast'!J27 -> 502.21878 | K19: =+'P&L Forecast'!K27 -> 694.74456 | M19: =K19-J19 -> 192.52578 | N19: =IFERROR(K19/J19-1,0) -> 0.38335042 | P19: =K19/$K$28 -> 0.32182939
B20: =+'P&L Forecast'!B28 -> Bookkeeper Wages | C20: =+'P&L Forecast'!C28 -> 183.36903 | D20: =+'P&L Forecast'!D28 -> 316.18462 | F20: =+'P&L Forecast'!F28 -> 147.26813 | G20: =+'P&L Forecast'!G28 -> 267.7574 | I20: =+'P&L Forecast'!I28 -> 240.18098 | J20: =+'P&L Forecast'!J28 -> 436.67389 | K20: =+'P&L Forecast'!K28 -> 533.8512 | M20: =K20-J20 -> 97.17731 | N20: =IFERROR(K20/J20-1,0) -> 0.22253978 | P20: =K20/$K$28 -> 0.2472981
B21: =+'P&L Forecast'!B29 -> Client Lead Wages | C21: =+'P&L Forecast'!C29 -> 286.16129 | D21: =+'P&L Forecast'!D29 -> 352.95844 | F21: =+'P&L Forecast'!F29 -> 201.27983 | G21: =+'P&L Forecast'!G29 -> 202.05309 | I21: =+'P&L Forecast'!I29 -> 353.12843 | J21: =+'P&L Forecast'!J29 -> 353.7317 | K21: =+'P&L Forecast'!K29 -> 392.92452 | M21: =K21-J21 -> 39.19282 | N21: =IFERROR(K21/J21-1,0) -> 0.11079816 | P21: =K21/$K$28 -> 0.18201605
B22: =+'P&L Forecast'!B30 -> Onboarding Team Wages | C22: =+'P&L Forecast'!C30 -> 122.81255 | D22: =+'P&L Forecast'!D30 -> 152.16972 | F22: =+'P&L Forecast'!F30 -> 73.94962 | G22: =+'P&L Forecast'!G30 -> 111.27999 | I22: =+'P&L Forecast'!I30 -> 121.30735 | J22: =+'P&L Forecast'!J30 -> 189.50009 | K22: =+'P&L Forecast'!K30 -> 197.14944 | M22: =K22-J22 -> 7.64935 | N22: =IFERROR(K22/J22-1,0) -> 0.040365944 | P22: =K22/$K$28 -> 0.091326349
B23: =+'P&L Forecast'!B31 -> Owner Wages | C23: =+'P&L Forecast'!C31 -> 0 | D23: =+'P&L Forecast'!D31 -> 90.66704 | F23: =+'P&L Forecast'!F31 -> 45.46612 | G23: =+'P&L Forecast'!G31 -> 63.14302 | I23: =+'P&L Forecast'!I31 -> 45.46612 | J23: =+'P&L Forecast'!J31 -> 108.34394 | K23: =+'P&L Forecast'!K31 -> 108.34394 | M23: =K23-J23 -> 0 | N23: =IFERROR(K23/J23-1,0) -> 0 | P23: =K23/$K$28 -> 0.050188611
B24: =+'P&L Forecast'!B32 -> S&M Wages | C24: =+'P&L Forecast'!C32 -> 0 | D24: =+'P&L Forecast'!D32 -> 19.14963 | F24: =+'P&L Forecast'!F32 -> 3.09945 | G24: =+'P&L Forecast'!G32 -> 51.94131 | I24: =+'P&L Forecast'!I32 -> 3.09945 | J24: =+'P&L Forecast'!J32 -> 67.99149 | K24: =+'P&L Forecast'!K32 -> 98.34912 | M24: =K24-J24 -> 30.35763 | N24: =IFERROR(K24/J24-1,0) -> 0.44649161 | P24: =K24/$K$28 -> 0.045558669
B25: =+'P&L Forecast'!B33 -> Occupancy Tax Specialist | C25: =+'P&L Forecast'!C33 -> 1.11335 | D25: =+'P&L Forecast'!D33 -> 29.56415 | F25: =+'P&L Forecast'!F33 -> 14.27585 | G25: =+'P&L Forecast'!G33 -> 42.08505 | I25: =+'P&L Forecast'!I33 -> 15.3892 | J25: =+'P&L Forecast'!J33 -> 57.37335 | K25: =+'P&L Forecast'!K33 -> 68.1132 | M25: =K25-J25 -> 10.73985 | N25: =IFERROR(K25/J25-1,0) -> 0.18719231 | P25: =K25/$K$28 -> 0.031552359
B26: =+'P&L Forecast'!B34 -> Sr. Client Lead Wages | C26: =+'P&L Forecast'!C34 -> 0 | D26: =+'P&L Forecast'!D34 -> 0 | F26: =+'P&L Forecast'!F34 -> 0 | G26: =+'P&L Forecast'!G34 -> 7.995 | I26: =+'P&L Forecast'!I34 -> 0 | J26: =+'P&L Forecast'!J34 -> 7.995 | K26: =+'P&L Forecast'!K34 -> 33.08124 | M26: =K26-J26 -> 25.08624 | N26: =IFERROR(K26/J26-1,0) -> 3.1377411 | P26: =K26/$K$28 -> 0.015324359
B27: =+'P&L Forecast'!B35 -> Employee Benefits | C27: =+'P&L Forecast'!C35 -> 5.37405 | D27: =+'P&L Forecast'!D35 -> 19.23245 | F27: =+'P&L Forecast'!F35 -> 9.02166 | G27: =+'P&L Forecast'!G35 -> 17.36251 | I27: =+'P&L Forecast'!I35 -> 12.16686 | J27: =+'P&L Forecast'!J35 -> 27.5733 | K27: =+'P&L Forecast'!K35 -> 32.17836 | M27: =K27-J27 -> 4.60506 | N27: =IFERROR(K27/J27-1,0) -> 0.16701157 | P27: =K27/$K$28 -> 0.014906115
B28: =+'P&L Forecast'!B36 -> Total Payroll Expenses | C28: =SUM(C19:C27) -> 700.20547 | D28: =SUM(D19:D27) -> 1261.1666 | F28: =SUM(F19:F27) -> 630.65714 | G28: =SUM(G19:G27) -> 1120.8921 | I28: =SUM(I19:I27) -> 993.15437 | J28: =SUM(J19:J27) -> 1751.4015 | K28: =SUM(K19:K27) -> 2158.7356 | M28: =SUM(M19:M27) -> 407.33404 | N28: =K28/J28-1 -> 0.23257604
B30: =+'P&L Forecast'!B38 -> Software & Apps - COGS | C30: =+'P&L Forecast'!C38 -> 114.42269 | D30: =+'P&L Forecast'!D38 -> 157.49471 | F30: =+'P&L Forecast'!F38 -> 84.96859 | G30: =+'P&L Forecast'!G38 -> 152.28157 | I30: =+'P&L Forecast'!I38 -> 142.28345 | J30: =+'P&L Forecast'!J38 -> 224.80769 | K30: =+'P&L Forecast'!K38 -> 335.70816 | M30: =K30-J30 -> 110.90047 | N30: =IFERROR(K30/J30-1,0) -> 0.49331262
B31: =+'P&L Forecast'!B39 -> Software & Apps - G&A | C31: =+'P&L Forecast'!C39 -> 60.91594 | D31: =+'P&L Forecast'!D39 -> 117.05866 | F31: =+'P&L Forecast'!F39 -> 56.8115 | G31: =+'P&L Forecast'!G39 -> 97.04798 | I31: =+'P&L Forecast'!I39 -> 86.51489 | J31: =+'P&L Forecast'!J39 -> 157.29514 | K31: =+'P&L Forecast'!K39 -> 155.82264 | M31: =K31-J31 -> -1.4725 | N31: =IFERROR(K31/J31-1,0) -> -0.0093613827
B32: =+'P&L Forecast'!B40 -> Software & Apps - Topkey | C32: =+'P&L Forecast'!C40 -> 0 | D32: =+'P&L Forecast'!D40 -> 7.14125 | F32: =+'P&L Forecast'!F40 -> 0 | G32: =+'P&L Forecast'!G40 -> 28.82775 | I32: =+'P&L Forecast'!I40 -> 0 | J32: =+'P&L Forecast'!J40 -> 35.969 | K32: =+'P&L Forecast'!K40 -> 60.84 | M32: =K32-J32 -> 24.871 | N32: =IFERROR(K32/J32-1,0) -> 0.69145653
B33: =+'P&L Forecast'!B41 -> Software & Apps - AI tools | C33: =+'P&L Forecast'!C41 -> 0 | D33: =+'P&L Forecast'!D41 -> 0 | F33: =+'P&L Forecast'!F41 -> 0 | G33: =+'P&L Forecast'!G41 -> 6.52752 | I33: =+'P&L Forecast'!I41 -> 0 | J33: =+'P&L Forecast'!J41 -> 6.52752 | K33: =+'P&L Forecast'!K41 -> 15.74376 | M33: =K33-J33 -> 9.21624 | N33: =IFERROR(K33/J33-1,0) -> 1.4119053
B34: =+'P&L Forecast'!B42 -> Total Software Expenses | C34: =SUM(C30:C33) -> 175.33863 | D34: =SUM(D30:D33) -> 281.69462 | F34: =SUM(F30:F33) -> 141.78009 | G34: =SUM(G30:G33) -> 284.68482 | I34: =SUM(I30:I33) -> 228.79834 | J34: =SUM(J30:J33) -> 424.59935 | K34: =SUM(K30:K33) -> 568.11456 | M34: =SUM(M30:M33) -> 143.51521 | N34: =K34/J34-1 -> 0.33800148
B36: =+'P&L Forecast'!B44 -> Other Professional Fees | C36: =+'P&L Forecast'!C44 -> 18.23425 | D36: =+'P&L Forecast'!D44 -> 27.04095 | F36: =+'P&L Forecast'!F44 -> 12.014 | G36: =+'P&L Forecast'!G44 -> 57.55 | I36: =+'P&L Forecast'!I44 -> 21.74858 | J36: =+'P&L Forecast'!J44 -> 72.57695 | K36: =+'P&L Forecast'!K44 -> 72.57695 | M36: =K36-J36 -> 0 | N36: =IFERROR(K36/J36-1,0) -> 0
B37: =+'P&L Forecast'!B45 -> Referral Fees | C37: =+'P&L Forecast'!C45 -> 24.82 | D37: =+'P&L Forecast'!D45 -> 27.15374 | F37: =+'P&L Forecast'!F45 -> 17.0895 | G37: =+'P&L Forecast'!G45 -> 20.62969 | I37: =+'P&L Forecast'!I45 -> 26.2095 | J37: =+'P&L Forecast'!J45 -> 30.69393 | K37: =+'P&L Forecast'!K45 -> 30.69393 | M37: =K37-J37 -> 0 | N37: =IFERROR(K37/J37-1,0) -> 0
B38: =+'P&L Forecast'!B46 -> Travel, Meals & Entertainment | C38: =+'P&L Forecast'!C46 -> 0 | D38: =+'P&L Forecast'!D46 -> 29.76122 | F38: =+'P&L Forecast'!F46 -> 22.29558 | G38: =+'P&L Forecast'!G46 -> 20.68542 | I38: =+'P&L Forecast'!I46 -> 22.29558 | J38: =+'P&L Forecast'!J46 -> 28.15106 | K38: =+'P&L Forecast'!K46 -> 28.15106 | M38: =K38-J38 -> 0 | N38: =IFERROR(K38/J38-1,0) -> 0
B39: =+'P&L Forecast'!B47 -> Payment Collection Fees | C39: =+'P&L Forecast'!C47 -> 8.67099 | D39: =+'P&L Forecast'!D47 -> 13.35153 | F39: =+'P&L Forecast'!F47 -> 6.80445 | G39: =+'P&L Forecast'!G47 -> 9.02684 | I39: =+'P&L Forecast'!I47 -> 10.54373 | J39: =+'P&L Forecast'!J47 -> 15.57392 | K39: =+'P&L Forecast'!K47 -> 15.57392 | M39: =K39-J39 -> 0 | N39: =IFERROR(K39/J39-1,0) -> 0
B40: =+'P&L Forecast'!B48 -> Professional Organizations | C40: =+'P&L Forecast'!C48 -> 5.44332 | D40: =+'P&L Forecast'!D48 -> 11.22296 | F40: =+'P&L Forecast'!F48 -> 6.191 | G40: =+'P&L Forecast'!G48 -> 6.57881 | I40: =+'P&L Forecast'!I48 -> 9.53268 | J40: =+'P&L Forecast'!J48 -> 11.61077 | K40: =+'P&L Forecast'!K48 -> 11.61077 | M40: =K40-J40 -> 0 | N40: =IFERROR(K40/J40-1,0) -> 0
B41: =+'P&L Forecast'!B49 -> S&M Events | C41: =+'P&L Forecast'!C49 -> 0 | D41: =+'P&L Forecast'!D49 -> 11.4983 | F41: =+'P&L Forecast'!F49 -> 0 | G41: =+'P&L Forecast'!G49 -> 11.84548 | I41: =+'P&L Forecast'!I49 -> 0 | J41: =+'P&L Forecast'!J49 -> 23.34378 | K41: =+'P&L Forecast'!K49 -> 23.34378 | M41: =K41-J41 -> 0 | N41: =IFERROR(K41/J41-1,0) -> 0
B42: =+'P&L Forecast'!B50 -> Contract Labor - Tax | C42: =+'P&L Forecast'!C50 -> 0 | D42: =+'P&L Forecast'!D50 -> 1.5875 | F42: =+'P&L Forecast'!F50 -> 0 | G42: =+'P&L Forecast'!G50 -> 30.5155 | I42: =+'P&L Forecast'!I50 -> 0 | J42: =+'P&L Forecast'!J50 -> 32.103 | K42: =+'P&L Forecast'!K50 -> 10 | M42: =K42-J42 -> -22.103 | N42: =IFERROR(K42/J42-1,0) -> -0.68850263
B43: =+'P&L Forecast'!B51 -> Recruiting Fees | C43: =+'P&L Forecast'!C51 -> 14.90205 | D43: =+'P&L Forecast'!D51 -> 31.6041 | F43: =+'P&L Forecast'!F51 -> 28.29994 | G43: =+'P&L Forecast'!G51 -> 5.5646 | I43: =+'P&L Forecast'!I51 -> 35.34606 | J43: =+'P&L Forecast'!J51 -> 8.86876 | K43: =+'P&L Forecast'!K51 -> 8.86876 | M43: =K43-J43 -> 0 | N43: =IFERROR(K43/J43-1,0) -> 0
B44: Other Expenses | C44: =+C45-SUM(C36:C43) -> 41.87929 | D44: =+D45-SUM(D36:D43) -> 52.32132 | F44: =+F45-SUM(F36:F43) -> 28.90542 | G44: =+G45-SUM(G36:G43) -> 26.90445 | I44: =+I45-SUM(I36:I43) -> 41.76881 | J44: =+J45-SUM(J36:J43) -> 50.32035 | K44: =+K45-SUM(K36:K43) -> 49.10777 | M44: =K44-J44 -> -1.21258 | N44: =IFERROR(K44/J44-1,0) -> -0.024097209
B45: Total Overhead | C45: =+'P&L Forecast'!C62 -> 113.9499 | D45: =+'P&L Forecast'!D62 -> 205.54162 | F45: =+'P&L Forecast'!F62 -> 121.59989 | G45: =+'P&L Forecast'!G62 -> 189.30079 | I45: =+'P&L Forecast'!I62 -> 167.44494 | J45: =+'P&L Forecast'!J62 -> 273.24252 | K45: =+'P&L Forecast'!K62 -> 249.92694 | M45: =SUM(M36:M44) -> -23.31558 | N45: =K45/J45-1 -> -0.085329253
...

Sheet P&L Forecast
B2: =+Cover!B24 -> Keystone Bookkeepers
B3: Pre-LOI P&L Forecast ($000s)
B5: P&L Summary ($000s) | C5: FY2024 | D5: FY2025 | F5: July'25 YTD | G5: July'26 YTD | I5: Jul'25 LTM | J5: Jul'26 LTM | K5: Jul'26 PF | M5: Delta ($) | N5: Delta (%) | P5: 45292 | Q5: =EOMONTH(P5,0)+1 -> 45323 | R5: =EOMONTH(Q5,0)+1 -> 45352 | S5: =EOMONTH(R5,0)+1 -> 45383 | T5: =EOMONTH(S5,0)+1 -> 45413 | U5: =EOMONTH(T5,0)+1 -> 45444 | V5: =EOMONTH(U5,0)+1 -> 45474 | W5: =EOMONTH(V5,0)+1 -> 45505 | X5: =EOMONTH(W5,0)+1 -> 45536 | ... AT5: =EOMONTH(AS5,0)+1 -> 46204
A6: x | B6: Revenue
B7: STR Subscription | C7: =SUMIFS($P7:$AT7,$P$5:$AT$5,">"&C$172,$P$5:$AT$5,"<"&C$173) -> 793.47225 | D7: =SUMIFS($P7:$AT7,$P$5:$AT$5,">"&D$172,$P$5:$AT$5,"<"&D$173) -> 1450.4923 | F7: =SUMIFS($P7:$AT7,$P$5:$AT$5,">"&F$172,$P$5:$AT$5,"<"&F$173) -> 751.5286 | G7: =SUMIFS($P7:$AT7,$P$5:$AT$5,">"&G$172,$P$5:$AT$5,"<"&G$173) -> 1261.4769 | I7: =SUMIFS($P7:$AT7,$P$5:$AT$5,">"&I$172,$P$5:$AT$5,"<"&I$173) -> 1152.3203 | J7: =SUMIFS($P7:$AT7,$P$5:$AT$5,">"&J$172,$P$5:$AT$5,"<"&J$173) -> 1960.4406 | K7: =+C108 -> 2410.05 | M7: =K7-J7 -> 449.6094 | N7: =IFERROR(K7/J7-1,0) -> 0.229341 | P7: =SUMIFS('Combined P&L'!N:N,'Combined P&L'!$C:$C,'P&L Forecast'!$B7) -> 44.6835 | Q7: =SUMIFS('Combined P&L'!O:O,'Combined P&L'!$C:$C,'P&L Forecast'!$B7) -> 47.046 | R7: =SUMIFS('Combined P&L'!P:P,'Combined P&L'!$C:$C,'P&L Forecast'!$B7) -> 52.47 | S7: =SUMIFS('Combined P&L'!Q:Q,'Combined P&L'!$C:$C,'P&L Forecast'!$B7) -> 57.1697 | T7: =SUMIFS('Combined P&L'!R:R,'Combined P&L'!$C:$C,'P&L Forecast'!$B7) -> 57.51415 | U7: =SUMIFS('Combined P&L'!S:S,'Combined P&L'!$C:$C,'P&L Forecast'!$B7) -> 65.516 | V7: =SUMIFS('Combined P&L'!T:T,'Combined P&L'!$C:$C,'P&L Forecast'!$B7) -> 68.28125 | W7: =SUMIFS('Combined P&L'!U:U,'Combined P&L'!$C:$C,'P&L Forecast'!$B7) -> 73.25135 | X7: =SUMIFS('Combined P&L'!V:V,'Combined P&L'!$C:$C,'P&L Forecast'!$B7) -> 75.5517 | Y7: =SUMIFS('Combined P&L'!W:W,'Combined P&L'!$C:$C,'P&L Forecast'!$B7) -> 79.11325 | Z7: =SUMIFS('Combined P&L'!X:X,'Combined P&L'!$C:$C,'P&L Forecast'!$B7) -> 83.2908 | AA7: =SUMIFS('Combined P&L'!Y:Y,'Combined P&L'!$C:$C,'P&L Forecast'!$B7) -> 89.58455 | AB7: =SUMIFS('Combined P&L'!Z:Z,'Combined P&L'!$C:$C,'P&L Forecast'!$B7) -> 92.4189 | AC7: =SUMIFS('Combined P&L'!AA:AA,'Combined P&L'!$C:$C,'P&L Forecast'!$B7) -> 94.00215 | AD7: =SUMIFS('Combined P&L'!AB:AB,'Combined P&L'!$C:$C,'P&L Forecast'!$B7) -> 101.50605 | AE7: =SUMIFS('Combined P&L'!AC:AC,'Combined P&L'!$C:$C,'P&L Forecast'!$B7) -> 106.1375 | AF7: =SUMIFS('Combined P&L'!AD:AD,'Combined P&L'!$C:$C,'P&L Forecast'!$B7) -> 115.93875 | AG7: =SUMIFS('Combined P&L'!AE:AE,'Combined P&L'!$C:$C,'P&L Forecast'!$B7) -> 119.43125 | AH7: =SUMIFS('Combined P&L'!AF:AF,'Combined P&L'!$C:$C,'P&L Forecast'!$B7) -> 122.094 | AI7: =SUMIFS('Combined P&L'!AG:AG,'Combined P&L'!$C:$C,'P&L Forecast'!$B7) -> 130.08525 | AJ7: =SUMIFS('Combined P&L'!AH:AH,'Combined P&L'!$C:$C,'P&L Forecast'!$B7) -> 133.5905 | AK7: =SUMIFS('Combined P&L'!AI:AI,'Combined P&L'!$C:$C,'P&L Forecast'!$B7) -> 139.609 | AL7: =SUMIFS('Combined P&L'!AJ:AJ,'Combined P&L'!$C:$C,'P&L Forecast'!$B7) -> 145.28075 | AM7: =SUMIFS('Combined P&L'!AK:AK,'Combined P&L'!$C:$C,'P&L Forecast'!$B7) -> 150.39825 | AN7: =SUMIFS('Combined P&L'!AL:AL,'Combined P&L'!$C:$C,'P&L Forecast'!$B7) -> 156.5388 | AO7: =SUMIFS('Combined P&L'!AM:AM,'Combined P&L'!$C:$C,'P&L Forecast'!$B7) -> 164.9034 | AP7: =SUMIFS('Combined P&L'!AN:AN,'Combined P&L'!$C:$C,'P&L Forecast'!$B7) -> 170.34425 | AQ7: =SUMIFS('Combined P&L'!AO:AO,'Combined P&L'!$C:$C,'P&L Forecast'!$B7) -> 183.662 | AR7: =SUMIFS('Combined P&L'!AP:AP,'Combined P&L'!$C:$C,'P&L Forecast'!$B7) -> 190.7844 | AS7: =SUMIFS('Combined P&L'!AQ:AQ,'Combined P&L'!$C:$C,'P&L Forecast'!$B7) -> 194.4065 | AT7: =SUMIFS('Combined P&L'!AR:AR,'Combined P&L'!$C:$C,'P&L Forecast'!$B7) -> 200.8375
B8: Occupancy Taxes | C8: =SUMIFS($P8:$AT8,$P$5:$AT$5,">"&C$172,$P$5:$AT$5,"<"&C$173) -> 0.56 | D8: =SUMIFS($P8:$AT8,$P$5:$AT$5,">"&D$172,$P$5:$AT$5,"<"&D$173) -> 55.0805 | F8: =SUMIFS($P8:$AT8,$P$5:$AT$5,">"&F$172,$P$5:$AT$5,"<"&F$173) -> 23.2255 | G8: =SUMIFS($P8:$AT8,$P$5:$AT$5,">"&G$172,$P$5:$AT$5,"<"&G$173) -> 91.65114 | I8: =SUMIFS($P8:$AT8,$P$5:$AT$5,">"&I$172,$P$5:$AT$5,"<"&I$173) -> 23.7855 | J8: =SUMIFS($P8:$AT8,$P$5:$AT$5,">"&J$172,$P$5:$AT$5,"<"&J$173) -> 123.50614 | K8: =+C110 -> 192.8298 | M8: =K8-J8 -> 69.32366 | N8: =IFERROR(K8/J8-1,0) -> 0.56129728 | P8: =SUMIFS('Combined P&L'!N:N,'Combined P&L'!$C:$C,'P&L Forecast'!$B8) -> 0 | Q8: =SUMIFS('Combined P&L'!O:O,'Combined P&L'!$C:$C,'P&L Forecast'!$B8) -> 0 | R8: =SUMIFS('Combined P&L'!P:P,'Combined P&L'!$C:$C,'P&L Forecast'!$B8) -> 0 | S8: =SUMIFS('Combined P&L'!Q:Q,'Combined P&L'!$C:$C,'P&L Forecast'!$B8) -> 0 | T8: =SUMIFS('Combined P&L'!R:R,'Combined P&L'!$C:$C,'P&L Forecast'!$B8) -> 0 | U8: =SUMIFS('Combined P&L'!S:S,'Combined P&L'!$C:$C,'P&L Forecast'!$B8) -> 0 | V8: =SUMIFS('Combined P&L'!T:T,'Combined P&L'!$C:$C,'P&L Forecast'!$B8) -> 0 | W8: =SUMIFS('Combined P&L'!U:U,'Combined P&L'!$C:$C,'P&L Forecast'!$B8) -> 0 | X8: =SUMIFS('Combined P&L'!V:V,'Combined P&L'!$C:$C,'P&L Forecast'!$B8) -> 0 | Y8: =SUMIFS('Combined P&L'!W:W,'Combined P&L'!$C:$C,'P&L Forecast'!$B8) -> 0 | Z8: =SUMIFS('Combined P&L'!X:X,'Combined P&L'!$C:$C,'P&L Forecast'!$B8) -> 0.08 | AA8: =SUMIFS('Combined P&L'!Y:Y,'Combined P&L'!$C:$C,'P&L Forecast'!$B8) -> 0.48 | AB8: =SUMIFS('Combined P&L'!Z:Z,'Combined P&L'!$C:$C,'P&L Forecast'!$B8) -> 1.13 | AC8: =SUMIFS('Combined P&L'!AA:AA,'Combined P&L'!$C:$C,'P&L Forecast'!$B8) -> 2.14 | AD8: =SUMIFS('Combined P&L'!AB:AB,'Combined P&L'!$C:$C,'P&L Forecast'!$B8) -> 2.66 | AE8: =SUMIFS('Combined P&L'!AC:AC,'Combined P&L'!$C:$C,'P&L Forecast'!$B8) -> 3.65 | AF8: =SUMIFS('Combined P&L'!AD:AD,'Combined P&L'!$C:$C,'P&L Forecast'!$B8) -> 3.623 | AG8: =SUMIFS('Combined P&L'!AE:AE,'Combined P&L'!$C:$C,'P&L Forecast'!$B8) -> 4.964 | AH8: =SUMIFS('Combined P&L'!AF:AF,'Combined P&L'!$C:$C,'P&L Forecast'!$B8) -> 5.0585 | AI8: =SUMIFS('Combined P&L'!AG:AG,'Combined P&L'!$C:$C,'P&L Forecast'!$B8) -> 4.73 | AJ8: =SUMIFS('Combined P&L'!AH:AH,'Combined P&L'!$C:$C,'P&L Forecast'!$B8) -> 4.82 | AK8: =SUMIFS('Combined P&L'!AI:AI,'Combined P&L'!$C:$C,'P&L Forecast'!$B8) -> 5.37 | AL8: =SUMIFS('Combined P&L'!AJ:AJ,'Combined P&L'!$C:$C,'P&L Forecast'!$B8) -> 8.05 | AM8: =SUMIFS('Combined P&L'!AK:AK,'Combined P&L'!$C:$C,'P&L Forecast'!$B8) -> 8.885 | AN8: =SUMIFS('Combined P&L'!AL:AL,'Combined P&L'!$C:$C,'P&L Forecast'!$B8) -> 10.90952 | AO8: =SUMIFS('Combined P&L'!AM:AM,'Combined P&L'!$C:$C,'P&L Forecast'!$B8) -> 10.33497 | AP8: =SUMIFS('Combined P&L'!AN:AN,'Combined P&L'!$C:$C,'P&L Forecast'!$B8) -> 11.175 | AQ8: =SUMIFS('Combined P&L'!AO:AO,'Combined P&L'!$C:$C,'P&L Forecast'!$B8) -> 11.95311 | AR8: =SUMIFS('Combined P&L'!AP:AP,'Combined P&L'!$C:$C,'P&L Forecast'!$B8) -> 15.04071 | AS8: =SUMIFS('Combined P&L'!AQ:AQ,'Combined P&L'!$C:$C,'P&L Forecast'!$B8) -> 16.16868 | AT8: =SUMIFS('Combined P&L'!AR:AR,'Combined P&L'!$C:$C,'P&L Forecast'!$B8) -> 16.06915
B9: SMB Subscription | C9: =SUMIFS($P9:$AT9,$P$5:$AT$5,">"&C$172,$P$5:$AT$5,"<"&C$173) -> 224.791 | D9: =SUMIFS($P9:$AT9,$P$5:$AT$5,">"&D$172,$P$5:$AT$5,"<"&D$173) -> 149.77 | F9: =SUMIFS($P9:$AT9,$P$5:$AT$5,">"&F$172,$P$5:$AT$5,"<"&F$173) -> 90.4525 | G9: =SUMIFS($P9:$AT9,$P$5:$AT$5,">"&G$172,$P$5:$AT$5,"<"&G$173) -> 73.4185 | I9: =SUMIFS($P9:$AT9,$P$5:$AT$5,">"&I$172,$P$5:$AT$5,"<"&I$173) -> 169.5465 | J9: =SUMIFS($P9:$AT9,$P$5:$AT$5,">"&J$172,$P$5:$AT$5,"<"&J$173) -> 132.736 | K9: =+C109 -> 119.706 | M9: =K9-J9 -> -13.03 | N9: =IFERROR(K9/J9-1,0) -> -0.098164778 | P9: =SUMIFS('Combined P&L'!N:N,'Combined P&L'!$C:$C,'P&L Forecast'!$B9) -> 22.001 | Q9: =SUMIFS('Combined P&L'!O:O,'Combined P&L'!$C:$C,'P&L Forecast'!$B9) -> 22.036 | R9: =SUMIFS('Combined P&L'!P:P,'Combined P&L'!$C:$C,'P&L Forecast'!$B9) -> 22.111 | S9: =SUMIFS('Combined P&L'!Q:Q,'Combined P&L'!$C:$C,'P&L Forecast'!$B9) -> 22.146 | T9: =SUMIFS('Combined P&L'!R:R,'Combined P&L'!$C:$C,'P&L Forecast'!$B9) -> 21.966 | U9: =SUMIFS('Combined P&L'!S:S,'Combined P&L'!$C:$C,'P&L Forecast'!$B9) -> 17.816 | V9: =SUMIFS('Combined P&L'!T:T,'Combined P&L'!$C:$C,'P&L Forecast'!$B9) -> 17.621 | W9: =SUMIFS('Combined P&L'!U:U,'Combined P&L'!$C:$C,'P&L Forecast'!$B9) -> 17.536 | X9: =SUMIFS('Combined P&L'!V:V,'Combined P&L'!$C:$C,'P&L Forecast'!$B9) -> 16.426 | Y9: =SUMIFS('Combined P&L'!W:W,'Combined P&L'!$C:$C,'P&L Forecast'!$B9) -> 15.381 | Z9: =SUMIFS('Combined P&L'!X:X,'Combined P&L'!$C:$C,'P&L Forecast'!$B9) -> 14.6755 | AA9: =SUMIFS('Combined P&L'!Y:Y,'Combined P&L'!$C:$C,'P&L Forecast'!$B9) -> 15.0755 | AB9: =SUMIFS('Combined P&L'!Z:Z,'Combined P&L'!$C:$C,'P&L Forecast'!$B9) -> 14.5625 | AC9: =SUMIFS('Combined P&L'!AA:AA,'Combined P&L'!$C:$C,'P&L Forecast'!$B9) -> 12.8025 | AD9: =SUMIFS('Combined P&L'!AB:AB,'Combined P&L'!$C:$C,'P&L Forecast'!$B9) -> 12.4025 | AE9: =SUMIFS('Combined P&L'!AC:AC,'Combined P&L'!$C:$C,'P&L Forecast'!$B9) -> 12.6025 | AF9: =SUMIFS('Combined P&L'!AD:AD,'Combined P&L'!$C:$C,'P&L Forecast'!$B9) -> 12.7525 | AG9: =SUMIFS('Combined P&L'!AE:AE,'Combined P&L'!$C:$C,'P&L Forecast'!$B9) -> 12.7925 | AH9: =SUMIFS('Combined P&L'!AF:AF,'Combined P&L'!$C:$C,'P&L Forecast'!$B9) -> 12.5375 | AI9: =SUMIFS('Combined P&L'!AG:AG,'Combined P&L'!$C:$C,'P&L Forecast'!$B9) -> 11.8575 | AJ9: =SUMIFS('Combined P&L'!AH:AH,'Combined P&L'!$C:$C,'P&L Forecast'!$B9) -> 12.3025 | AK9: =SUMIFS('Combined P&L'!AI:AI,'Combined P&L'!$C:$C,'P&L Forecast'!$B9) -> 11.6925 | AL9: =SUMIFS('Combined P&L'!AJ:AJ,'Combined P&L'!$C:$C,'P&L Forecast'!$B9) -> 11.7175 | AM9: =SUMIFS('Combined P&L'!AK:AK,'Combined P&L'!$C:$C,'P&L Forecast'!$B9) -> 11.7475 | AN9: =SUMIFS('Combined P&L'!AL:AL,'Combined P&L'!$C:$C,'P&L Forecast'!$B9) -> 11.2805 | AO9: =SUMIFS('Combined P&L'!AM:AM,'Combined P&L'!$C:$C,'P&L Forecast'!$B9) -> 10.9305 | AP9: =SUMIFS('Combined P&L'!AN:AN,'Combined P&L'!$C:$C,'P&L Forecast'!$B9) -> 10.6255 | AQ9: =SUMIFS('Combined P&L'!AO:AO,'Combined P&L'!$C:$C,'P&L Forecast'!$B9) -> 10.3155 | AR9: =SUMIFS('Combined P&L'!AP:AP,'Combined P&L'!$C:$C,'P&L Forecast'!$B9) -> 10.3155 | AS9: =SUMIFS('Combined P&L'!AQ:AQ,'Combined P&L'!$C:$C,'P&L Forecast'!$B9) -> 9.9755 | AT9: =SUMIFS('Combined P&L'!AR:AR,'Combined P&L'!$C:$C,'P&L Forecast'!$B9) -> 9.9755
B10: Onboarding | C10: =SUMIFS($P10:$AT10,$P$5:$AT$5,">"&C$172,$P$5:$AT$5,"<"&C$173) -> 44.0585 | D10: =SUMIFS($P10:$AT10,$P$5:$AT$5,">"&D$172,$P$5:$AT$5,"<"&D$173) -> 74.5193 | F10: =SUMIFS($P10:$AT10,$P$5:$AT$5,">"&F$172,$P$5:$AT$5,"<"&F$173) -> 42.25405 | G10: =SUMIFS($P10:$AT10,$P$5:$AT$5,">"&G$172,$P$5:$AT$5,"<"&G$173) -> 59.055 | I10: =SUMIFS($P10:$AT10,$P$5:$AT$5,">"&I$172,$P$5:$AT$5,"<"&I$173) -> 57.49255 | J10: =SUMIFS($P10:$AT10,$P$5:$AT$5,">"&J$172,$P$5:$AT$5,"<"&J$173) -> 91.32025 | K10: =+C111 -> 103.5675 | M10: =K10-J10 -> 12.24725 | N10: =IFERROR(K10/J10-1,0) -> 0.13411319 | P10: =SUMIFS('Combined P&L'!N:N,'Combined P&L'!$C:$C,'P&L Forecast'!$B10) -> 5.465 | Q10: =SUMIFS('Combined P&L'!O:O,'Combined P&L'!$C:$C,'P&L Forecast'!$B10) -> 3.9 | R10: =SUMIFS('Combined P&L'!P:P,'Combined P&L'!$C:$C,'P&L Forecast'!$B10) -> 2.755 | S10: =SUMIFS('Combined P&L'!Q:Q,'Combined P&L'!$C:$C,'P&L Forecast'!$B10) -> 3.502 | T10: =SUMIFS('Combined P&L'!R:R,'Combined P&L'!$C:$C,'P&L Forecast'!$B10) -> 4.659 | U10: =SUMIFS('Combined P&L'!S:S,'Combined P&L'!$C:$C,'P&L Forecast'!$B10) -> 3.937 | V10: =SUMIFS('Combined P&L'!T:T,'Combined P&L'!$C:$C,'P&L Forecast'!$B10) -> 4.602 | W10: =SUMIFS('Combined P&L'!U:U,'Combined P&L'!$C:$C,'P&L Forecast'!$B10) -> 4.738 | X10: =SUMIFS('Combined P&L'!V:V,'Combined P&L'!$C:$C,'P&L Forecast'!$B10) -> 2.119 | Y10: =SUMIFS('Combined P&L'!W:W,'Combined P&L'!$C:$C,'P&L Forecast'!$B10) -> 2.064 | Z10: =SUMIFS('Combined P&L'!X:X,'Combined P&L'!$C:$C,'P&L Forecast'!$B10) -> 3.0125 | AA10: =SUMIFS('Combined P&L'!Y:Y,'Combined P&L'!$C:$C,'P&L Forecast'!$B10) -> 3.305 | AB10: =SUMIFS('Combined P&L'!Z:Z,'Combined P&L'!$C:$C,'P&L Forecast'!$B10) -> 3.079 | AC10: =SUMIFS('Combined P&L'!AA:AA,'Combined P&L'!$C:$C,'P&L Forecast'!$B10) -> 0.7 | AD10: =SUMIFS('Combined P&L'!AB:AB,'Combined P&L'!$C:$C,'P&L Forecast'!$B10) -> 10.43855 | AE10: =SUMIFS('Combined P&L'!AC:AC,'Combined P&L'!$C:$C,'P&L Forecast'!$B10) -> 4.3 | AF10: =SUMIFS('Combined P&L'!AD:AD,'Combined P&L'!$C:$C,'P&L Forecast'!$B10) -> 11.14 | AG10: =SUMIFS('Combined P&L'!AE:AE,'Combined P&L'!$C:$C,'P&L Forecast'!$B10) -> 6.1625 | AH10: =SUMIFS('Combined P&L'!AF:AF,'Combined P&L'!$C:$C,'P&L Forecast'!$B10) -> 6.434 | AI10: =SUMIFS('Combined P&L'!AG:AG,'Combined P&L'!$C:$C,'P&L Forecast'!$B10) -> 3.965 | AJ10: =SUMIFS('Combined P&L'!AH:AH,'Combined P&L'!$C:$C,'P&L Forecast'!$B10) -> 3.92 | AK10: =SUMIFS('Combined P&L'!AI:AI,'Combined P&L'!$C:$C,'P&L Forecast'!$B10) -> 9.1365 | AL10: =SUMIFS('Combined P&L'!AJ:AJ,'Combined P&L'!$C:$C,'P&L Forecast'!$B10) -> 5.25375 | AM10: =SUMIFS('Combined P&L'!AK:AK,'Combined P&L'!$C:$C,'P&L Forecast'!$B10) -> 9.99 | AN10: =SUMIFS('Combined P&L'!AL:AL,'Combined P&L'!$C:$C,'P&L Forecast'!$B10) -> 10.2105 | AO10: =SUMIFS('Combined P&L'!AM:AM,'Combined P&L'!$C:$C,'P&L Forecast'!$B10) -> 6.675 | AP10: =SUMIFS('Combined P&L'!AN:AN,'Combined P&L'!$C:$C,'P&L Forecast'!$B10) -> 9.099 | AQ10: =SUMIFS('Combined P&L'!AO:AO,'Combined P&L'!$C:$C,'P&L Forecast'!$B10) -> 8.9545 | AR10: =SUMIFS('Combined P&L'!AP:AP,'Combined P&L'!$C:$C,'P&L Forecast'!$B10) -> 12.606 | AS10: =SUMIFS('Combined P&L'!AQ:AQ,'Combined P&L'!$C:$C,'P&L Forecast'!$B10) -> 5.4115 | AT10: =SUMIFS('Combined P&L'!AR:AR,'Combined P&L'!$C:$C,'P&L Forecast'!$B10) -> 6.0985
B11: Topkey Subscription | C11: =SUMIFS($P11:$AT11,$P$5:$AT$5,">"&C$172,$P$5:$AT$5,"<"&C$173) -> 0 | D11: =SUMIFS($P11:$AT11,$P$5:$AT$5,">"&D$172,$P$5:$AT$5,"<"&D$173) -> 9.947 | F11: =SUMIFS($P11:$AT11,$P$5:$AT$5,">"&F$172,$P$5:$AT$5,"<"&F$173) -> 0 | G11: =SUMIFS($P11:$AT11,$P$5:$AT$5,">"&G$172,$P$5:$AT$5,"<"&G$173) -> 45.086 | I11: =SUMIFS($P11:$AT11,$P$5:$AT$5,">"&I$172,$P$5:$AT$5,"<"&I$173) -> 0 | J11: =SUMIFS($P11:$AT11,$P$5:$AT$5,">"&J$172,$P$5:$AT$5,"<"&J$173) -> 55.033 | K11: =+C113 -> 94.836 | M11: =K11-J11 -> 39.803 | N11: =IFERROR(K11/J11-1,0) -> 0.72325695 | P11: =SUMIFS('Combined P&L'!N:N,'Combined P&L'!$C:$C,'P&L Forecast'!$B11) -> 0 | Q11: =SUMIFS('Combined P&L'!O:O,'Combined P&L'!$C:$C,'P&L Forecast'!$B11) -> 0 | R11: =SUMIFS('Combined P&L'!P:P,'Combined P&L'!$C:$C,'P&L Forecast'!$B11) -> 0 | S11: =SUMIFS('Combined P&L'!Q:Q,'Combined P&L'!$C:$C,'P&L Forecast'!$B11) -> 0 | T11: =SUMIFS('Combined P&L'!R:R,'Combined P&L'!$C:$C,'P&L Forecast'!$B11) -> 0 | U11: =SUMIFS('Combined P&L'!S:S,'Combined P&L'!$C:$C,'P&L Forecast'!$B11) -> 0 | V11: =SUMIFS('Combined P&L'!T:T,'Combined P&L'!$C:$C,'P&L Forecast'!$B11) -> 0 | W11: =SUMIFS('Combined P&L'!U:U,'Combined P&L'!$C:$C,'P&L Forecast'!$B11) -> 0 | X11: =SUMIFS('Combined P&L'!V:V,'Combined P&L'!$C:$C,'P&L Forecast'!$B11) -> 0 | Y11: =SUMIFS('Combined P&L'!W:W,'Combined P&L'!$C:$C,'P&L Forecast'!$B11) -> 0 | Z11: =SUMIFS('Combined P&L'!X:X,'Combined P&L'!$C:$C,'P&L Forecast'!$B11) -> 0 | AA11: =SUMIFS('Combined P&L'!Y:Y,'Combined P&L'!$C:$C,'P&L Forecast'!$B11) -> 0 | AB11: =SUMIFS('Combined P&L'!Z:Z,'Combined P&L'!$C:$C,'P&L Forecast'!$B11) -> 0 | AC11: =SUMIFS('Combined P&L'!AA:AA,'Combined P&L'!$C:$C,'P&L Forecast'!$B11) -> 0 | AD11: =SUMIFS('Combined P&L'!AB:AB,'Combined P&L'!$C:$C,'P&L Forecast'!$B11) -> 0 | AE11: =SUMIFS('Combined P&L'!AC:AC,'Combined P&L'!$C:$C,'P&L Forecast'!$B11) -> 0 | AF11: =SUMIFS('Combined P&L'!AD:AD,'Combined P&L'!$C:$C,'P&L Forecast'!$B11) -> 0 | AG11: =SUMIFS('Combined P&L'!AE:AE,'Combined P&L'!$C:$C,'P&L Forecast'!$B11) -> 0 | AH11: =SUMIFS('Combined P&L'!AF:AF,'Combined P&L'!$C:$C,'P&L Forecast'!$B11) -> 0 | AI11: =SUMIFS('Combined P&L'!AG:AG,'Combined P&L'!$C:$C,'P&L Forecast'!$B11) -> 0 | AJ11: =SUMIFS('Combined P&L'!AH:AH,'Combined P&L'!$C:$C,'P&L Forecast'!$B11) -> 0.52 | AK11: =SUMIFS('Combined P&L'!AI:AI,'Combined P&L'!$C:$C,'P&L Forecast'!$B11) -> 2.357 | AL11: =SUMIFS('Combined P&L'!AJ:AJ,'Combined P&L'!$C:$C,'P&L Forecast'!$B11) -> 2.811 | AM11: =SUMIFS('Combined P&L'!AK:AK,'Combined P&L'!$C:$C,'P&L Forecast'!$B11) -> 4.259 | AN11: =SUMIFS('Combined P&L'!AL:AL,'Combined P&L'!$C:$C,'P&L Forecast'!$B11) -> 5.254 | AO11: =SUMIFS('Combined P&L'!AM:AM,'Combined P&L'!$C:$C,'P&L Forecast'!$B11) -> 5.652 | AP11: =SUMIFS('Combined P&L'!AN:AN,'Combined P&L'!$C:$C,'P&L Forecast'!$B11) -> 5.324 | AQ11: =SUMIFS('Combined P&L'!AO:AO,'Combined P&L'!$C:$C,'P&L Forecast'!$B11) -> 6.321 | AR11: =SUMIFS('Combined P&L'!AP:AP,'Combined P&L'!$C:$C,'P&L Forecast'!$B11) -> 6.959 | AS11: =SUMIFS('Combined P&L'!AQ:AQ,'Combined P&L'!$C:$C,'P&L Forecast'!$B11) -> 7.673 | AT11: =SUMIFS('Combined P&L'!AR:AR,'Combined P&L'!$C:$C,'P&L Forecast'!$B11) -> 7.903
B12: STR Bill Pay | C12: =SUMIFS($P12:$AT12,$P$5:$AT$5,">"&C$172,$P$5:$AT$5,"<"&C$173) -> 0.06 | D12: =SUMIFS($P12:$AT12,$P$5:$AT$5,">"&D$172,$P$5:$AT$5,"<"&D$173) -> 36.6065 | F12: =SUMIFS($P12:$AT12,$P$5:$AT$5,">"&F$172,$P$5:$AT$5,"<"&F$173) -> 15.4915 | G12: =SUMIFS($P12:$AT12,$P$5:$AT$5,">"&G$172,$P$5:$AT$5,"<"&G$173) -> 45.13 | I12: =SUMIFS($P12:$AT12,$P$5:$AT$5,">"&I$172,$P$5:$AT$5,"<"&I$173) -> 15.5515 | J12: =SUMIFS($P12:$AT12,$P$5:$AT$5,">"&J$172,$P$5:$AT$5,"<"&J$173) -> 66.245 | K12: =+C112 -> 83.46 | M12: =K12-J12 -> 17.215 | N12: =IFERROR(K12/J12-1,0) -> 0.25986867 | P12: =SUMIFS('Combined P&L'!N:N,'Combined P&L'!$C:$C,'P&L Forecast'!$B12) -> 0 | Q12: =SUMIFS('Combined P&L'!O:O,'Combined P&L'!$C:$C,'P&L Forecast'!$B12) -> 0 | R12: =SUMIFS('Combined P&L'!P:P,'Combined P&L'!$C:$C,'P&L Forecast'!$B12) -> 0 | S12: =SUMIFS('Combined P&L'!Q:Q,'Combined P&L'!$C:$C,'P&L Forecast'!$B12) -> 0 | T12: =SUMIFS('Combined P&L'!R:R,'Combined P&L'!$C:$C,'P&L Forecast'!$B12) -> 0 | U12: =SUMIFS('Combined P&L'!S:S,'Combined P&L'!$C:$C,'P&L Forecast'!$B12) -> 0 | V12: =SUMIFS('Combined P&L'!T:T,'Combined P&L'!$C:$C,'P&L Forecast'!$B12) -> 0 | W12: =SUMIFS('Combined P&L'!U:U,'Combined P&L'!$C:$C,'P&L Forecast'!$B12) -> 0 | X12: =SUMIFS('Combined P&L'!V:V,'Combined P&L'!$C:$C,'P&L Forecast'!$B12) -> 0 | Y12: =SUMIFS('Combined P&L'!W:W,'Combined P&L'!$C:$C,'P&L Forecast'!$B12) -> 0 | Z12: =SUMIFS('Combined P&L'!X:X,'Combined P&L'!$C:$C,'P&L Forecast'!$B12) -> 0 | AA12: =SUMIFS('Combined P&L'!Y:Y,'Combined P&L'!$C:$C,'P&L Forecast'!$B12) -> 0.06 | AB12: =SUMIFS('Combined P&L'!Z:Z,'Combined P&L'!$C:$C,'P&L Forecast'!$B12) -> 0.97 | AC12: =SUMIFS('Combined P&L'!AA:AA,'Combined P&L'!$C:$C,'P&L Forecast'!$B12) -> 1.1 | AD12: =SUMIFS('Combined P&L'!AB:AB,'Combined P&L'!$C:$C,'P&L Forecast'!$B12) -> 1.735 | AE12: =SUMIFS('Combined P&L'!AC:AC,'Combined P&L'!$C:$C,'P&L Forecast'!$B12) -> 2.14 | AF12: =SUMIFS('Combined P&L'!AD:AD,'Combined P&L'!$C:$C,'P&L Forecast'!$B12) -> 2.363 | AG12: =SUMIFS('Combined P&L'!AE:AE,'Combined P&L'!$C:$C,'P&L Forecast'!$B12) -> 3.2635 | AH12: =SUMIFS('Combined P&L'!AF:AF,'Combined P&L'!$C:$C,'P&L Forecast'!$B12) -> 3.92 | AI12: =SUMIFS('Combined P&L'!AG:AG,'Combined P&L'!$C:$C,'P&L Forecast'!$B12) -> 3.905 | AJ12: =SUMIFS('Combined P&L'!AH:AH,'Combined P&L'!$C:$C,'P&L Forecast'!$B12) -> 3.78 | AK12: =SUMIFS('Combined P&L'!AI:AI,'Combined P&L'!$C:$C,'P&L Forecast'!$B12) -> 3.795 | AL12: =SUMIFS('Combined P&L'!AJ:AJ,'Combined P&L'!$C:$C,'P&L Forecast'!$B12) -> 4.33 | AM12: =SUMIFS('Combined P&L'!AK:AK,'Combined P&L'!$C:$C,'P&L Forecast'!$B12) -> 5.305 | AN12: =SUMIFS('Combined P&L'!AL:AL,'Combined P&L'!$C:$C,'P&L Forecast'!$B12) -> 6.3 | AO12: =SUMIFS('Combined P&L'!AM:AM,'Combined P&L'!$C:$C,'P&L Forecast'!$B12) -> 6.39 | AP12: =SUMIFS('Combined P&L'!AN:AN,'Combined P&L'!$C:$C,'P&L Forecast'!$B12) -> 6.425 | AQ12: =SUMIFS('Combined P&L'!AO:AO,'Combined P&L'!$C:$C,'P&L Forecast'!$B12) -> 6.08 | AR12: =SUMIFS('Combined P&L'!AP:AP,'Combined P&L'!$C:$C,'P&L Forecast'!$B12) -> 6.325 | AS12: =SUMIFS('Combined P&L'!AQ:AQ,'Combined P&L'!$C:$C,'P&L Forecast'!$B12) -> 6.655 | AT12: =SUMIFS('Combined P&L'!AR:AR,'Combined P&L'!$C:$C,'P&L Forecast'!$B12) -> 6.955
B13: Controller Services | C13: =SUMIFS($P13:$AT13,$P$5:$AT$5,">"&C$172,$P$5:$AT$5,"<"&C$173) -> 13.75 | D13: =SUMIFS($P13:$AT13,$P$5:$AT$5,">"&D$172,$P$5:$AT$5,"<"&D$173) -> 46.4 | F13: =SUMIFS($P13:$AT13,$P$5:$AT$5,">"&F$172,$P$5:$AT$5,"<"&F$173) -> 31.5 | G13: =SUMIFS($P13:$AT13,$P$5:$AT$5,">"&G$172,$P$5:$AT$5,"<"&G$173) -> 24.25 | I13: =SUMIFS($P13:$AT13,$P$5:$AT$5,">"&I$172,$P$5:$AT$5,"<"&I$173) -> 44 | J13: =SUMIFS($P13:$AT13,$P$5:$AT$5,">"&J$172,$P$5:$AT$5,"<"&J$173) -> 39.15 | K13: =+C114 -> 42 | M13: =K13-J13 -> 2.85 | N13: =IFERROR(K13/J13-1,0) -> 0.072796935 | P13: =SUMIFS('Combined P&L'!N:N,'Combined P&L'!$C:$C,'P&L Forecast'!$B13) -> 0 | Q13: =SUMIFS('Combined P&L'!O:O,'Combined P&L'!$C:$C,'P&L Forecast'!$B13) -> 0 | R13: =SUMIFS('Combined P&L'!P:P,'Combined P&L'!$C:$C,'P&L Forecast'!$B13) -> 0 | S13: =SUMIFS('Combined P&L'!Q:Q,'Combined P&L'!$C:$C,'P&L Forecast'!$B13) -> 0 | T13: =SUMIFS('Combined P&L'!R:R,'Combined P&L'!$C:$C,'P&L Forecast'!$B13) -> 0 | U13: =SUMIFS('Combined P&L'!S:S,'Combined P&L'!$C:$C,'P&L Forecast'!$B13) -> 0 | V13: =SUMIFS('Combined P&L'!T:T,'Combined P&L'!$C:$C,'P&L Forecast'!$B13) -> 1.25 | W13: =SUMIFS('Combined P&L'!U:U,'Combined P&L'!$C:$C,'P&L Forecast'!$B13) -> 1.25 | X13: =SUMIFS('Combined P&L'!V:V,'Combined P&L'!$C:$C,'P&L Forecast'!$B13) -> 1.25 | Y13: =SUMIFS('Combined P&L'!W:W,'Combined P&L'!$C:$C,'P&L Forecast'!$B13) -> 1.25 | Z13: =SUMIFS('Combined P&L'!X:X,'Combined P&L'!$C:$C,'P&L Forecast'!$B13) -> 5.75 | AA13: =SUMIFS('Combined P&L'!Y:Y,'Combined P&L'!$C:$C,'P&L Forecast'!$B13) -> 3 | AB13: =SUMIFS('Combined P&L'!Z:Z,'Combined P&L'!$C:$C,'P&L Forecast'!$B13) -> 4.45 | AC13: =SUMIFS('Combined P&L'!AA:AA,'Combined P&L'!$C:$C,'P&L Forecast'!$B13) -> 3.45 | AD13: =SUMIFS('Combined P&L'!AB:AB,'Combined P&L'!$C:$C,'P&L Forecast'!$B13) -> 3.45 | AE13: =SUMIFS('Combined P&L'!AC:AC,'Combined P&L'!$C:$C,'P&L Forecast'!$B13) -> 5.95 | AF13: =SUMIFS('Combined P&L'!AD:AD,'Combined P&L'!$C:$C,'P&L Forecast'!$B13) -> 5.2 | AG13: =SUMIFS('Combined P&L'!AE:AE,'Combined P&L'!$C:$C,'P&L Forecast'!$B13) -> 5 | AH13: =SUMIFS('Combined P&L'!AF:AF,'Combined P&L'!$C:$C,'P&L Forecast'!$B13) -> 4 | AI13: =SUMIFS('Combined P&L'!AG:AG,'Combined P&L'!$C:$C,'P&L Forecast'!$B13) -> 2.95 | AJ13: =SUMIFS('Combined P&L'!AH:AH,'Combined P&L'!$C:$C,'P&L Forecast'!$B13) -> 3.025 | AK13: =SUMIFS('Combined P&L'!AI:AI,'Combined P&L'!$C:$C,'P&L Forecast'!$B13) -> 3.025 | AL13: =SUMIFS('Combined P&L'!AJ:AJ,'Combined P&L'!$C:$C,'P&L Forecast'!$B13) -> 2.95 | AM13: =SUMIFS('Combined P&L'!AK:AK,'Combined P&L'!$C:$C,'P&L Forecast'!$B13) -> 2.95 | AN13: =SUMIFS('Combined P&L'!AL:AL,'Combined P&L'!$C:$C,'P&L Forecast'!$B13) -> 2.75 | AO13: =SUMIFS('Combined P&L'!AM:AM,'Combined P&L'!$C:$C,'P&L Forecast'!$B13) -> 3.5 | AP13: =SUMIFS('Combined P&L'!AN:AN,'Combined P&L'!$C:$C,'P&L Forecast'!$B13) -> 2.75 | AQ13: =SUMIFS('Combined P&L'!AO:AO,'Combined P&L'!$C:$C,'P&L Forecast'!$B13) -> 4.75 | AR13: =SUMIFS('Combined P&L'!AP:AP,'Combined P&L'!$C:$C,'P&L Forecast'!$B13) -> 3.5 | AS13: =SUMIFS('Combined P&L'!AQ:AQ,'Combined P&L'!$C:$C,'P&L Forecast'!$B13) -> 3.5 | AT13: =SUMIFS('Combined P&L'!AR:AR,'Combined P&L'!$C:$C,'P&L Forecast'!$B13) -> 3.5
B14: Historical Cleanup | C14: =SUMIFS($P14:$AT14,$P$5:$AT$5,">"&C$172,$P$5:$AT$5,"<"&C$173) -> 17.624 | D14: =SUMIFS($P14:$AT14,$P$5:$AT$5,">"&D$172,$P$5:$AT$5,"<"&D$173) -> 5.03375 | F14: =SUMIFS($P14:$AT14,$P$5:$AT$5,">"&F$172,$P$5:$AT$5,"<"&F$173) -> 4.43875 | G14: =SUMIFS($P14:$AT14,$P$5:$AT$5,">"&G$172,$P$5:$AT$5,"<"&G$173) -> 0 | I14: =SUMIFS($P14:$AT14,$P$5:$AT$5,">"&I$172,$P$5:$AT$5,"<"&I$173) -> 12.84275 | J14: =SUMIFS($P14:$AT14,$P$5:$AT$5,">"&J$172,$P$5:$AT$5,"<"&J$173) -> 0.595 | K14: =+C115 -> 0 | M14: =K14-J14 -> -0.595 | N14: =IFERROR(K14/J14-1,0) -> -1 | P14: =SUMIFS('Combined P&L'!N:N,'Combined P&L'!$C:$C,'P&L Forecast'!$B14) -> 1.2 | Q14: =SUMIFS('Combined P&L'!O:O,'Combined P&L'!$C:$C,'P&L Forecast'!$B14) -> 1.7625 | R14: =SUMIFS('Combined P&L'!P:P,'Combined P&L'!$C:$C,'P&L Forecast'!$B14) -> 0.66 | S14: =SUMIFS('Combined P&L'!Q:Q,'Combined P&L'!$C:$C,'P&L Forecast'!$B14) -> 0.395 | T14: =SUMIFS('Combined P&L'!R:R,'Combined P&L'!$C:$C,'P&L Forecast'!$B14) -> 2.465 | U14: =SUMIFS('Combined P&L'!S:S,'Combined P&L'!$C:$C,'P&L Forecast'!$B14) -> 1.275 | V14: =SUMIFS('Combined P&L'!T:T,'Combined P&L'!$C:$C,'P&L Forecast'!$B14) -> 1.4625 | W14: =SUMIFS('Combined P&L'!U:U,'Combined P&L'!$C:$C,'P&L Forecast'!$B14) -> 0 | X14: =SUMIFS('Combined P&L'!V:V,'Combined P&L'!$C:$C,'P&L Forecast'!$B14) -> 1.14525 | Y14: =SUMIFS('Combined P&L'!W:W,'Combined P&L'!$C:$C,'P&L Forecast'!$B14) -> 1.35525 | Z14: =SUMIFS('Combined P&L'!X:X,'Combined P&L'!$C:$C,'P&L Forecast'!$B14) -> 1.9035 | AA14: =SUMIFS('Combined P&L'!Y:Y,'Combined P&L'!$C:$C,'P&L Forecast'!$B14) -> 4 | AB14: =SUMIFS('Combined P&L'!Z:Z,'Combined P&L'!$C:$C,'P&L Forecast'!$B14) -> 1.08375 | AC14: =SUMIFS('Combined P&L'!AA:AA,'Combined P&L'!$C:$C,'P&L Forecast'!$B14) -> 2 | AD14: =SUMIFS('Combined P&L'!AB:AB,'Combined P&L'!$C:$C,'P&L Forecast'!$B14) -> 1.355 | AE14: =SUMIFS('Combined P&L'!AC:AC,'Combined P&L'!$C:$C,'P&L Forecast'!$B14) -> 0 | AF14: =SUMIFS('Combined P&L'!AD:AD,'Combined P&L'!$C:$C,'P&L Forecast'!$B14) -> 0 | AG14: =SUMIFS('Combined P&L'!AE:AE,'Combined P&L'!$C:$C,'P&L Forecast'!$B14) -> 0 | AH14: =SUMIFS('Combined P&L'!AF:AF,'Combined P&L'!$C:$C,'P&L Forecast'!$B14) -> 0 | AI14: =SUMIFS('Combined P&L'!AG:AG,'Combined P&L'!$C:$C,'P&L Forecast'!$B14) -> 0 | AJ14: =SUMIFS('Combined P&L'!AH:AH,'Combined P&L'!$C:$C,'P&L Forecast'!$B14) -> 0 | AK14: =SUMIFS('Combined P&L'!AI:AI,'Combined P&L'!$C:$C,'P&L Forecast'!$B14) -> 0.595 | AL14: =SUMIFS('Combined P&L'!AJ:AJ,'Combined P&L'!$C:$C,'P&L Forecast'!$B14) -> 0 | AM14: =SUMIFS('Combined P&L'!AK:AK,'Combined P&L'!$C:$C,'P&L Forecast'!$B14) -> 0 | AN14: =SUMIFS('Combined P&L'!AL:AL,'Combined P&L'!$C:$C,'P&L Forecast'!$B14) -> 0 | AO14: =SUMIFS('Combined P&L'!AM:AM,'Combined P&L'!$C:$C,'P&L Forecast'!$B14) -> 0 | AP14: =SUMIFS('Combined P&L'!AN:AN,'Combined P&L'!$C:$C,'P&L Forecast'!$B14) -> 0 | AQ14: =SUMIFS('Combined P&L'!AO:AO,'Combined P&L'!$C:$C,'P&L Forecast'!$B14) -> 0 | AR14: =SUMIFS('Combined P&L'!AP:AP,'Combined P&L'!$C:$C,'P&L Forecast'!$B14) -> 0 | AS14: =SUMIFS('Combined P&L'!AQ:AQ,'Combined P&L'!$C:$C,'P&L Forecast'!$B14) -> 0 | AT14: =SUMIFS('Combined P&L'!AR:AR,'Combined P&L'!$C:$C,'P&L Forecast'!$B14) -> 0
B15: Total Recurring Revenue | C15: =SUM(C7:C14) -> 1094.3157 | D15: =SUM(D7:D14) -> 1827.8494 | F15: =SUM(F7:F14) -> 958.8909 | G15: =SUM(G7:G14) -> 1600.0675 | I15: =SUM(I7:I14) -> 1475.5391 | J15: =SUM(J7:J14) -> 2469.026 | K15: =SUM(K7:K14) -> 3046.4493 | M15: =SUM(M7:M14) -> 577.42331 | N15: =IFERROR(K15/J15-1,0) -> 0.23386684 | P15: =SUM(P7:P14) -> 73.3495 | Q15: =SUM(Q7:Q14) -> 74.7445 | R15: =SUM(R7:R14) -> 77.996 | S15: =SUM(S7:S14) -> 83.2127 | T15: =SUM(T7:T14) -> 86.60415 | U15: =SUM(U7:U14) -> 88.544 | V15: =SUM(V7:V14) -> 93.21675 | W15: =SUM(W7:W14) -> 96.77535 | ... AT15: =SUM(AT7:AT14) -> 251.33865
B17: Profit Share | C17: =SUMIFS($P17:$AT17,$P$5:$AT$5,">"&C$172,$P$5:$AT$5,"<"&C$173) -> 6.2004 | D17: =SUMIFS($P17:$AT17,$P$5:$AT$5,">"&D$172,$P$5:$AT$5,"<"&D$173) -> 23.26179 | F17: =SUMIFS($P17:$AT17,$P$5:$AT$5,">"&F$172,$P$5:$AT$5,"<"&F$173) -> 14.50495 | G17: =SUMIFS($P17:$AT17,$P$5:$AT$5,">"&G$172,$P$5:$AT$5,"<"&G$173) -> 8.07938 | I17: =SUMIFS($P17:$AT17,$P$5:$AT$5,">"&I$172,$P$5:$AT$5,"<"&I$173) -> 18.32935 | J17: =SUMIFS($P17:$AT17,$P$5:$AT$5,">"&J$172,$P$5:$AT$5,"<"&J$173) -> 16.83622 | K17: =+C120 -> 16.83622 | M17: =K17-J17 -> 0 | N17: =IFERROR(K17/J17-1,0) -> 0 | P17: =SUMIFS('Combined P&L'!N:N,'Combined P&L'!$C:$C,'P&L Forecast'!$B17) -> 0.0686 | Q17: =SUMIFS('Combined P&L'!O:O,'Combined P&L'!$C:$C,'P&L Forecast'!$B17) -> 0.1312 | R17: =SUMIFS('Combined P&L'!P:P,'Combined P&L'!$C:$C,'P&L Forecast'!$B17) -> 0.0712 | S17: =SUMIFS('Combined P&L'!Q:Q,'Combined P&L'!$C:$C,'P&L Forecast'!$B17) -> 0.0556 | T17: =SUMIFS('Combined P&L'!R:R,'Combined P&L'!$C:$C,'P&L Forecast'!$B17) -> 0.577 | U17: =SUMIFS('Combined P&L'!S:S,'Combined P&L'!$C:$C,'P&L Forecast'!$B17) -> 0.8068 | V17: =SUMIFS('Combined P&L'!T:T,'Combined P&L'!$C:$C,'P&L Forecast'!$B17) -> 0.6656 | W17: =SUMIFS('Combined P&L'!U:U,'Combined P&L'!$C:$C,'P&L Forecast'!$B17) -> 0.8264 | X17: =SUMIFS('Combined P&L'!V:V,'Combined P&L'!$C:$C,'P&L Forecast'!$B17) -> 1.3808 | Y17: =SUMIFS('Combined P&L'!W:W,'Combined P&L'!$C:$C,'P&L Forecast'!$B17) -> 0.8604 | Z17: =SUMIFS('Combined P&L'!X:X,'Combined P&L'!$C:$C,'P&L Forecast'!$B17) -> 0.51 | AA17: =SUMIFS('Combined P&L'!Y:Y,'Combined P&L'!$C:$C,'P&L Forecast'!$B17) -> 0.2468 | AB17: =SUMIFS('Combined P&L'!Z:Z,'Combined P&L'!$C:$C,'P&L Forecast'!$B17) -> 7.3584 | AC17: =SUMIFS('Combined P&L'!AA:AA,'Combined P&L'!$C:$C,'P&L Forecast'!$B17) -> 1.29335 | AD17: =SUMIFS('Combined P&L'!AB:AB,'Combined P&L'!$C:$C,'P&L Forecast'!$B17) -> 0.96833 | AE17: =SUMIFS('Combined P&L'!AC:AC,'Combined P&L'!$C:$C,'P&L Forecast'!$B17) -> 1.1656 | AF17: =SUMIFS('Combined P&L'!AD:AD,'Combined P&L'!$C:$C,'P&L Forecast'!$B17) -> 0.96093 | AG17: =SUMIFS('Combined P&L'!AE:AE,'Combined P&L'!$C:$C,'P&L Forecast'!$B17) -> 1.71127 | AH17: =SUMIFS('Combined P&L'!AF:AF,'Combined P&L'!$C:$C,'P&L Forecast'!$B17) -> 1.04707 | AI17: =SUMIFS('Combined P&L'!AG:AG,'Combined P&L'!$C:$C,'P&L Forecast'!$B17) -> 2.04088 | AJ17: =SUMIFS('Combined P&L'!AH:AH,'Combined P&L'!$C:$C,'P&L Forecast'!$B17) -> 1.13621 | AK17: =SUMIFS('Combined P&L'!AI:AI,'Combined P&L'!$C:$C,'P&L Forecast'!$B17) -> 2.01424 | AL17: =SUMIFS('Combined P&L'!AJ:AJ,'Combined P&L'!$C:$C,'P&L Forecast'!$B17) -> 1.29758 | AM17: =SUMIFS('Combined P&L'!AK:AK,'Combined P&L'!$C:$C,'P&L Forecast'!$B17) -> 2.26793 | AN17: =SUMIFS('Combined P&L'!AL:AL,'Combined P&L'!$C:$C,'P&L Forecast'!$B17) -> 2.67784 | AO17: =SUMIFS('Combined P&L'!AM:AM,'Combined P&L'!$C:$C,'P&L Forecast'!$B17) -> 2.35401 | AP17: =SUMIFS('Combined P&L'!AN:AN,'Combined P&L'!$C:$C,'P&L Forecast'!$B17) -> 0.2276 | AQ17: =SUMIFS('Combined P&L'!AO:AO,'Combined P&L'!$C:$C,'P&L Forecast'!$B17) -> 1.47836 | AR17: =SUMIFS('Combined P&L'!AP:AP,'Combined P&L'!$C:$C,'P&L Forecast'!$B17) -> 0.66824 | AS17: =SUMIFS('Combined P&L'!AQ:AQ,'Combined P&L'!$C:$C,'P&L Forecast'!$B17) -> 0.58613 | AT17: =SUMIFS('Combined P&L'!AR:AR,'Combined P&L'!$C:$C,'P&L Forecast'!$B17) -> 0.0872
