Workbook
Name _: #REF!
Name __: #REF!
Name __123Graph_A: #REF!
Name __123Graph_B: #REF!
Name __123Graph_C: #REF!
Name __123Graph_D: #REF!
Name __123Graph_E: #REF!
Name __123Graph_X: #REF!
Name __FDS_HYPERLINK_TOGGLE_STATE__: "ON"
Name __na2: "100"
Name __na3: "50"
Name __na4: "IQ_LTM_DATE"
Name __xlfn.IFERROR: #NAME?
Name _1__123Graph_ACHART_1: #REF!
Name _1_0_S: #REF!
Name _10__123Graph_LBL_ACHART_3: #REF!
Name _11__123Graph_LBL_ACHART_4: #REF!
Name _12__123Graph_LBL_BCHART_1: #REF!
Name _13__123Graph_LBL_BCHART_2: #REF!
Name _14__123Graph_LBL_BCHART_3: #REF!
Name _15__123Graph_XCHART_1: #REF!
Name _16__123Graph_XCHART_2: #REF!
Name _17__123Graph_XCHART_3: #REF!
Name _18__123Graph_XCHART_4: #REF!
Name _2__123Graph_ACHART_2: #REF!
Name _3__123Graph_ACHART_3: #REF!
Name _4__123Graph_ACHART_4: #REF!
Name _5__123Graph_BCHART_1: #REF!
Name _6__123Graph_BCHART_2: #REF!
Name _7__123Graph_BCHART_3: #REF!
Name _8__123Graph_LBL_ACHART_1: #REF!
Name _9__123Graph_LBL_ACHART_2: #REF!
Name _A11: {#N/A,#N/A,FALSE,"Umsatz 99";#N/A,#N/A,FALSE,"ER 99 "}
Name _AMO_UniqueIdentifier: "'5375716e-454b-48bf-b2c6-623a22f6f7fd'"
Name _bdm.1757E07DCDE14B2CAF7BB2CA0D3F723A.edm: #REF!
Name _bdm.25C474F2533C4648B6B616521128E386.edm: #REF!
Name _bdm.36877CD477D84DC5A3F38D89171D0D22.edm: #REF!
Name _bdm.6da9cae9ff3449b48ce2d389dda63d47.edm: #REF!
Name _bdm.77870AD72C96407A9B5ED0777264F7D7.edm: #REF!
Name _bdm.8334DA937680453BA4F84B81AA9001CA.edm: #REF!
Name _bdm.84CBA7F60F564A31A30CD3B6C0C78347.edm: #REF!
Name _bdm.AFEB21518FB449729F78288573165EF1.edm: #REF!
Name _bdm.CC661935DF52489B8A794A954D6DB48E.edm: #REF!
Name _bdm.CFE15DADEC4E48C8B2D052588431C1D1.edm: #REF!
Name _bdm.DC1E4912CA644367B8FB43181380FCAE.edm: #REF!
Name _BQ4.1: #REF!
Name _c: {"Fiesta Facer Page",#N/A,FALSE,"Q_C_S";"Fiesta Main Page",#N/A,FALSE,"V_L";"Fiesta 95BP Struct",#N/A,FALSE,"StructBP";"Fiesta Post 95BP Struct",#N/A,FALSE,"AdjStructBP"}
Name _Dist_Values: #REF!
Name _Fill: #REF!
Name _Key1: #REF!
Name _key10: #REF!
Name _Key13: #REF!
Name _Key2: #REF!
Name _na2: "100"
Name _na3: "50"
Name _na4: "IQ_LTM_DATE"
Name _Order1: 0
Name _Order2: 255
Name _q3: #REF!
Name _Regression_Int: 1

Sheet Sources & Uses
B2: Coral
B4: Sources & Uses
B6: Sources | H6: Uses
B8: Seller Note Amount | F8: =-L13 -> 575000 | H8: Total Aggregate Purchase Price | L8: 3850000
H9: Plus: Cash Amount | L9: 0
B10: Senior Secured Term Loan | F10: 0 | H10: Minus: Debt Amount | L10: =-J50 -> -447203.5
B11: Southfield Mezzanine Capital II LP | F11: =+F10*50% -> 0 | H11: Total | L11: =SUM(L8:L10) -> 3402796.5
B12: Entities representing Gladstone Capital Corporation | F12: =+F11 -> 0 | H12: Minus: Transaction Expenses Amount | L12: =+J62*-1 -> -1323350.8
H13: Minus: Seller Note Amount | L13: -575000
B14: Equity Contribution from Trowbridge CAM Holdings, Inc. | F14: =F28-F18-F10-F8-F22 -> 3654750 | H14: Minus: Tax Lien Holdback | L14: =-J40 -> 0
B15: LLM Acquisition, Inc. | F15: =+F14*100% -> 3654750 | H15: Minus: Reconciliation Holdback Amount | L15: =-J41 -> -201897
B16: Ellery Partners, LLC | F16: =+F14-F15 -> 0 | H16: Closing Cash Payment to Seller | L16: =SUM(L11:L15) -> 1302548.7
B18: Coral Balance Sheet Cash | F18: 0 | H18: Buyer Fees & Expenses | L18: =SUM(L19:L21) -> 379750
H19: Accounting Diligence - Moss Adams | L19: 73500
H20: Buyer's Acquisition Counsel - Gibson Dunn | L20: 210000
H21: Consulting Fee - Ellery Partners | L21: =+J67 -> 96250
B22: TCC Balance Sheet Cash | F22: 0
H24: Coral Debt Payoff | L24: =L10*-1 -> 447203.5
H26: Cash to TCC Balance Sheet | L26: 0
B28: Total | F28: =L28 -> 4229750 | H28: Total | L28: =L24+L18+L11+L26 -> 4229750
H30: Net Proceed Allocation
J31: Allocation | K31: Net Proceeds
H32: Sanford A. Fox | J32: 0.1666 | K32: =J32*$K$36 -> 433835.69
H33: Robert Hurwitz | J33: 0.1666 | K33: =J33*$K$36 -> 433835.69
H34: Alan H. Markowitz | J34: 0.1666 | K34: =J34*$K$36 -> 433835.69
H35: Peter Rubin | J35: =+J36-SUM(J32:J34) -> 0.5002 | K35: =J35*$K$36 -> 1302548.7
H36: Total | J36: 1 | K36: =SUM(L11,-J58,L13,L14,L15) -> 2604055.8
H38: Reconciliation Holdback Amount
J39: Amount
H40: Tax Liens | J40: 0
H41: One Month Mgmt. Fees | J41: 201897
H42: Total | J42: =SUM(J40:J41) -> 201897
H44: Debt Payoff Amount
J45: Amount
H46: Alliance Bank | J46: 346735.49
H47: Alliance Interest | J47: =48.07*7 -> 336.49 | K47: Assumes 7/3 payoff
H48: Peter Rubin | J48: 100000 | K48: Assumes 7/3 payoff
H49: Peter's Interest | J49: =21.92*6 -> 131.52
H50: Total | J50: =SUM(J46:J49) -> 447203.5
H54: Transaction Expenses Amount
...

Sheet Proceeds
B2: =+'Sources & Uses'!B2 -> Coral
B4: Proceeds Overview | G4: Notes | I4: Print | J4: 1
B6: Gross Cash Payment | E6: 3275000
B7: Plus: Seller Note Amount | E7: =+'Sources & Uses'!L13*-1 -> 575000
B8: Plus: Cash Amount | E8: =+'Sources & Uses'!L9 -> 0
B9: Minus: Debt Amount | E9: =+'Sources & Uses'!L10 -> -447203.5 | G9: $347K owed to Alliance Bank & $100K owed to Peter plus interest
B10: Minus: Transaction Expenses Amount | E10: =+'Sources & Uses'!L12 -> -1323350.8 | G10: Peter's legal fees and payments to former shareholders
B11: Estimated Purchase Price | E11: =SUM(E6:E10) -> 2079445.7
B12: Minus: Seller Note Amount | E12: ='Sources & Uses'!L13 -> -575000
B13: Minus: Reconciliation Holdback Amount | E13: =+'Sources & Uses'!L15 -> -201897 | G13: One month of management fees
B14: =+'Sources & Uses'!H14 -> Minus: Tax Lien Holdback | E14: =+'Sources & Uses'!L14 -> 0
B15: Closing Cash Payment to Seller | E15: =SUM(E11:E14) -> 1302548.7 | G15: Cash Proceeds to Peter
B17: Former Shareholder Allocation
D18: Allocation | E18: Net Proceeds
B19: Sanford A. Fox | D19: =+E19/E$24 -> 0.1666 | E19: =+'Sources & Uses'!J59 -> 433835.69
B20: Robert Hurwitz | D20: =+E20/E$24 -> 0.1666 | E20: =+'Sources & Uses'!J60 -> 433835.69
B21: Alan H. Markowitz | D21: =+E21/E$24 -> 0.1666 | E21: =+'Sources & Uses'!J61 -> 433835.69
B22: Total Cash to Former Shareholders | D22: =+E22/E$24 -> 0.4998 | E22: =SUM(E19:E21) -> 1301507.1
B23: Cash Proceeds to Peter | D23: =+E23/E$24 -> 0.5002 | E23: =+E15 -> 1302548.7
B24: Total Cash Proceeds to Current / Former Shareholders | E24: =SUM(E22:E23) -> 2604055.8
B26: Total Proceeds For Peter Rubin
B27: Closing Payment Amount | E27: =+E15 -> 1302548.7
B28: Shareholder Loan Payoff | E28: =SUM('Sources & Uses'!J48:J49) -> 100131.52
B29: Legal Retainer | E29: =+'Sources & Uses'!J57 -> 5000
B30: Total Cash Payment to Peter | E30: =SUM(E27:E29) -> 1407680.2

Sheet Flow of Funds
B2: =+'Sources & Uses'!B2 -> Coral
B4: Flow of Funds
B6: Payer | C6: Recipient | D6: Amount
B7: Gladstone Capital Corporation | C7: Trowbridge CAM Holdings, Inc. | D7: 0
B8: Southfield Mezzanine Capital II LP | C8: Trowbridge CAM Holdings, Inc. | D8: 0
B9: LLM Acquisition, Inc. | C9: Trowbridge CAM Holdings, Inc. | D9: ='Sources & Uses'!F15 -> 3654750
B10: Ellery Partners, LLC | C10: Trowbridge CAM Holdings, Inc. | D10: ='Sources & Uses'!F16 -> 0
B11: Total Inflows | D11: =SUM(D7:D10) -> 3654750
B13: Trowbridge CAM Holdings, Inc. | C13: Peter Rubin | D13: =+Proceeds!E30 -> 1407680.2
B14: Trowbridge CAM Holdings, Inc. | C14: =+Proceeds!B19 -> Sanford A. Fox | D14: =+Proceeds!E19 -> 433835.69
B15: Trowbridge CAM Holdings, Inc. | C15: =+Proceeds!B20 -> Robert Hurwitz | D15: =+Proceeds!E20 -> 433835.69
B16: Trowbridge CAM Holdings, Inc. | C16: =+Proceeds!B21 -> Alan H. Markowitz | D16: =+Proceeds!E21 -> 433835.69
B17: Trowbridge CAM Holdings, Inc. | C17: Coral NewCo | D17: =+'Sources & Uses'!J42 -> 201897
B18: Trowbridge CAM Holdings, Inc. | C18: Alliance Bank | D18: =SUM('Sources & Uses'!J46:J47) -> 347071.98
B19: Trowbridge CAM Holdings, Inc. | C19: Seller's Counsel - Kane Kessler | D19: =+'Sources & Uses'!J56 -> 16843.75
B20: Trowbridge CAM Holdings, Inc. | C20: Moss Adams | D20: =+'Sources & Uses'!L19 -> 73500
B21: Trowbridge CAM Holdings, Inc. | C21: Gibson Dunn | D21: ='Sources & Uses'!L20 -> 210000
B22: Trowbridge CAM Holdings, Inc. | C22: Ellery Partners | D22: ='Sources & Uses'!L21 -> 96250
B23: Total Outflows | D23: =SUM(D13:D22) -> 3654750
B25: Gross Balance | C25: Trowbridge CAM Holdings, Inc. | D25: =D11-D23 -> 0
B27: Balance Sheet Cash To TCC | D27: ='Sources & Uses'!L26 -> 0
C29: Net Balance | D29: =D25-D27 -> 0

Sheet Appendix>>

Sheet Wire Info
B2: Wire Info
B4: Name | C4: Entity | D4: Wire Information | E4: Wire Amount | F4: Confirm Date
B5: Gibson Dunn | C5: Gibson, Dunn & Crutcher LLP | D5: Bank Name: Wells Fargo Bank Account Name: Gibson, Dunn & Crutcher LLP Bank Address: 333 South Grand Avenue, Los Angeles, CA 90071‐1515 Account Number: 4600‐146039 ABA: 121000248 Invoice No: 2025061461 | E5: =+'Flow of Funds'!D21 -> 210000 | F5: 45833 | H5: Call 213-229-7333
B6: Moss Adams | C6: Baker Tilly Advisory Group, LP | D6: Bank: JPMorgan Chase Bank NA Address: 270 Park Avenue, New York, NY 10017 Routing #: 021000021 Account #: 791533875 Beneficiary Name: Moss Adams LLP Beneficiary Address: 999 Third Avenue, Suite 2800, Seattle, WA 98104 | E6: =+'Flow of Funds'!D20 -> 73500 | F6: 45833 | H6: Grace Luppi at (949) 680-8434
B7: Ellery Partners | C7: Ellery Partners LLC | D7: Bank: JP Morgan Chase Account #: 80010474916 Routing (Wire) #: 021000021 Routing (ACH) #: 021000021 | E7: =+'Flow of Funds'!D22 -> 96250 | F7: 45833
B8: Peter Rubin | C8: =B8 -> Peter Rubin | D8: Bank Name: US Bank Bank Address: 19825 Detroit Road, Rocky River, Ohio, 44116 Routing Number: 042000013 Account: 130118425086 Account Name: Peter Rubin | E8: =+'Flow of Funds'!D13 -> 1407680.2 | F8: 45833
B9: Sanford A. Fox | C9: =B9 -> Sanford A. Fox | D9: Bank: Key Bank Bank Address: 30100 Chagrin Blvd, Pepper Pike, OH, 44124 Account Number: 355732010986 Routing: 041001039 Account Name: Sanford Fox | E9: =+Proceeds!E19 -> 433835.69 | F9: 45838
B10: Robert Hurwitz | C10: =B10 -> Robert Hurwitz | D10: Bank: The Northern Trust Company Bank Address: 50 South La Salle Street, Chicago, IL, 60603 ABA: #071000152 Account: 35114149 BNF: The Glenmede Trust Company, N.A. For Further Credit Account Name: Robert Hurwitz IA Trust U/D 6/8/87 For Further Credit Glenmede Account Number: 4139-01-4/7 | E10: =+Proceeds!E20 -> 433835.69 | F10: 45838
B11: Alan H. Markowitz | C11: =B11 -> Alan H. Markowitz | D11: Bank: Bank of America Bank Address: 100 West 33rd Street, New York, NY, 10001 Account Name: Merrill Lynch Account Number: 6550113516 ABA: 026009593 For Further Credit: 6HJ-24407, DR ALAN H MARKOWITZ AND CATHY POLLARD | E11: =+Proceeds!E21 -> 433835.69 | F11: 45838
B12: Kane Kessler (Coral Counsel) | C12: Kane Kessler, P.C. | D12: Bank: Flagstar Bank Bank Address: 1400 Broadway 24th floor, New York, NY, 10018 Account / Beneficiary Name: Kane Kessler, P.C. Account Number: 150 565 2777 ABA: 026 013 576 Swift: SIGNUS33 | E12: =+'Flow of Funds'!D19 -> 16843.75 | F12: 45833 | H12: Call 212-541-6222
B13: Alliance Bank | C13: Western Alliance Bank | D13: Bank: Western Alliance Bank Account / Beneficiary Name: Western Alliance Bank Bank Address: 2700 West Sahara, Las Vegas, Nevada 89102 Account Number: 2890612002 ABA: 122401778 Loan Number: 4025200047-70001 | E13: =+'Flow of Funds'!D18 -> 347071.98 | F13: 45833 | H13: Call Maureen Smith 702-252-6144
B14: New Coral Entity | C14: Trowbridge CAM Holdings, Inc. | D14: Bank: JPMORGAN CHASE BANK, N.A. - ILLINOIS Account / Beneficiary Name: THE CORAL COMPANY Address: 817 Washington Blvd Unit 101, Chicago, IL 60607-2312 Account Number: 717251709 ABA / Routing Number: 021000021 Swift BIC: CHASUS33 | E14: =+'Flow of Funds'!D17+'Flow of Funds'!D27 -> 201897 | F14: 45833 | H14: Call Candace 317 767 8229
D16: Total | E16: =SUM(E5:E14) -> 3654750
D17: Check | E17: =E16-'Flow of Funds'!D23-'Flow of Funds'!D27 -> 4.6566129e-10
