Workbook

Sheet Read Me
A1: Keystone Partnership – Deal Checklist and Timeline
A2: Prepared by AMB Advisory Services LLC for Jon Sukhia / Topkey | September 24, 2026 | Confidential
A4: Targets
A5: LOI signed | B5: Friday, October 16, 2026
A6: Signing and escrow funding | B6: Friday, December 18, 2026
A7: Effective date | B7: Saturday, January 2, 2027 (wires Monday, January 4)
A9: How to use
A10: Status | B10: Edit the Status column on each checklist tab (drop-down). Everything else recalculates.
A11: Dates | B11: Start and Due dates are editable. The Timeline tab and Days to Due update automatically.
A12: Critical path | B12: 'Y' marks tasks that move the Dec 18 signing date if they slip.
A14: Priority
A15: P1 - Critical | B15: On the critical path or a deal-breaker if missed
A16: P2 - High | B16: Needed for signing but has some float
A17: P3 - Medium | B17: Needed but flexible, or post-close
A19: Difficulty
A20: High | B20: Third parties, negotiation or legal complexity; allow extra time
A21: Medium | B21: Several people, some judgment
A22: Low | B22: Straightforward, one owner
A24: People
A25: Jon | B25: Jon Sukhia – Topkey CEO
A26: Frank / Tereno | B26: AMB Advisory
A27: Josh | B27: Burkland – Topkey CFO
A28: Corey | B28: Topkey M&A / securities counsel
A29: Tax counsel | B29: Joint tax counsel with NH experience – to be engaged (PRE-03)
A30: Appraiser | B30: Topkey's 409A appraiser
A31: Pete / Darren | B31: Topkey engineering
A32: Ben | B32: Keystone owner; Ben's counsel and CPA as noted
A34: Sources | B34: LOI v13, Offer v15, Topkey Data Room Review, Series A Decision Options v2, Offer Review v3, deal-call transcripts

Sheet Milestones
A1: Key Milestones and Status
A2: Days remaining count from today.
A4: Milestone | B4: Target date | C4: Days remaining | D4: Linked task | E4: Owner | F4: Gate / what must be true
A5: Thread Bank status confirmed | B5: 46294 | C5: =B5-TODAY() -> 4 | D5: PRE-02 | E5: Jon | F5: Know whether the line is extended, repayable or in default
A6: Walk-through call with Ben | B6: 46297 | C6: =B6-TODAY() -> 7 | D6: PRE-12 | E6: Jon | F6: Open terms decided (PRE-04)
A7: Tax counsel engaged | B7: 46297 | C7: =B7-TODAY() -> 7 | D7: PRE-03 | E7: Jon | F7: Engagement letter signed
A8: LOI v14 / Offer v16 cleared by counsel | B8: 46304 | C8: =B8-TODAY() -> 14 | D8: PRE-21 | E8: Corey | F8: Decisions made; consents drafted
A9: LOI sent to Ben | B9: 46304 | C9: =B9-TODAY() -> 14 | D9: PRE-25 | E9: Jon | F9: Disclosure package ready or dated
A10: Stockholder consent signed | B10: 46311 | C10: =B10-TODAY() -> 21 | D10: PRE-24 | E10: Jon | F10: Felicis + a16z (or YC) = 55% of Preferred
A11: LOI signed | B11: 46311 | C11: =B11-TODAY() -> 21 | D11: PRE-27 | E11: Jon | F11: Exclusivity starts (90 days)
A12: Keystone data room complete | B12: 46325 | C12: =B12-TODAY() -> 35 | D12: POST-02 | E12: Ben
A13: First drafts: MIPA and Operating Agreement; tax memo | B13: 46339 | C13: =B13-TODAY() -> 49 | D13: POST-15 | E13: Corey | F13: Structure confirmed by tax counsel
A14: Diligence substantially complete (QoE) | B14: 46346 | C14: =B14-TODAY() -> 56 | D14: POST-09 | E14: Josh | F14: No price-changing findings
A15: Thread paid off and liens released | B15: 46356 | C15: =B15-TODAY() -> 66 | D15: POST-05 | E15: Jon | F15: Keystone not a co-borrower
A16: Final agreed documents | B16: 46367 | C16: =B16-TODAY() -> 77 | D16: POST-23 | E16: Corey | F16: Schedules and third-party consents in hand
A17: F-reorganization complete | B17: 46371 | C17: =B17-TODAY() -> 81 | D17: POST-21 | E17: Ben | F17: NewCo and QSub election in place
A18: Board approval | B18: 46373 | C18: =B18-TODAY() -> 83 | D18: POST-33 | E18: Jon | F18: Fair-value finding for shares
A19: SIGNING and escrow funded | B19: 46374 | C19: =B19-TODAY() -> 84 | D19: POST-34 | E19: Jon | F19: All P1 pre-signing tasks Done
A20: EFFECTIVE DATE | B20: 46389 | C20: =B20-TODAY() -> 99 | D20: POST-36 | E20: Jon | F20: Wires Monday Jan 4
A21: Exclusivity expiry (before extension) | B21: 46401 | C21: =B21-TODAY() -> 111 | D21: POST-35 | E21: Frank | F21: Closing must occur first
A24: Status summary
B25: Pre-LOI | C25: Post-LOI | D25: Total
A26: Not started | B26: =COUNTIF('Pre-LOI Checklist'!O5:O31,A26) -> 27 | C26: =COUNTIF('Post-LOI Checklist'!O5:O45,A26) -> 41 | D26: =B26+C26 -> 68
A27: In progress | B27: =COUNTIF('Pre-LOI Checklist'!O5:O31,A27) -> 0 | C27: =COUNTIF('Post-LOI Checklist'!O5:O45,A27) -> 0 | D27: =B27+C27 -> 0
A28: Done | B28: =COUNTIF('Pre-LOI Checklist'!O5:O31,A28) -> 0 | C28: =COUNTIF('Post-LOI Checklist'!O5:O45,A28) -> 0 | D28: =B28+C28 -> 0
A29: Blocked | B29: =COUNTIF('Pre-LOI Checklist'!O5:O31,A29) -> 0 | C29: =COUNTIF('Post-LOI Checklist'!O5:O45,A29) -> 0 | D29: =B29+C29 -> 0
A30: At risk | B30: =COUNTIF('Pre-LOI Checklist'!O5:O31,A30) -> 0 | C30: =COUNTIF('Post-LOI Checklist'!O5:O45,A30) -> 0 | D30: =B30+C30 -> 0
A31: Total tasks | B31: =SUM(B26:B30) -> 27 | C31: =SUM(C26:C30) -> 41 | D31: =B31+C31 -> 68
A32: % complete | B32: =IF(B31=0,0,B28/B31) -> 0 | C32: =IF(C31=0,0,C28/C31) -> 0 | D32: =IF(D31=0,0,D28/D31) -> 0
A33: P1 open (not Done) | B33: =COUNTIFS('Pre-LOI Checklist'!E5:E31,"P1*",'Pre-LOI Checklist'!O5:O31,"<>Done") -> 15 | C33: =COUNTIFS('Post-LOI Checklist'!E5:E45,"P1*",'Post-LOI Checklist'!O5:O45,"<>Done") -> 18 | D33: =B33+C33 -> 33
A34: Overdue (past due, not Done) | B34: =COUNTIFS('Pre-LOI Checklist'!J5:J31,"<"&TODAY(),'Pre-LOI Checklist'!O5:O31,"<>Done") -> 0 | C34: =COUNTIFS('Post-LOI Checklist'!J5:J45,"<"&TODAY(),'Post-LOI Checklist'!O5:O45,"<>Done") -> 0 | D34: =B34+C34 -> 0

Sheet Pre-LOI Checklist
A1: Pre-LOI Checklist – Sep 25 to Oct 16, 2026
A2: Edit Status (drop-down), Start and Due. Days to due is blank once Done.
A4: ID | B4: Workstream | C4: Task | D4: Detail / deliverable | E4: Priority | F4: Difficulty | G4: Owner | H4: Support | I4: Start | J4: Due | K4: Duration (days) | L4: Days to due | M4: Depends on | N4: Critical path | O4: Status | P4: Notes / source
A5: PRE-01 | B5: Diligence prep | C5: Request missing Topkey items | D5: Founder Voting Agreement, ROFR & Co-Sale Agreement, current 409A report, Thread documents after Aug 26 maturity, Burkland $60M SAFE, FY2025 audit status, Bryan Beshore's role | E5: P2 - High | F5: Low | G5: Frank | H5: Jon | I5: 46290 | J5: 46294 | K5: =J5-I5+1 -> 5 | L5: =IF(O5="Done","",J5-TODAY()) -> 4 | N5: N | O5: Not started | P5: Data Room Review §2 / §9 item 9
A6: PRE-02 | B6: Financing & consents | C6: Confirm Thread Bank line status after Aug 26, 2026 maturity | D6: Extended, paid off or in default? Are monthly compliance certificates and the FY2025 audit current? $500K drawn at 8/31 | E6: P1 - Critical | F6: Low | G6: Jon | H6: Josh | I6: 46290 | J6: 46294 | K6: =J6-I6+1 -> 5 | L6: =IF(O6="Done","",J6-TODAY()) -> 4 | N6: Y | O6: Not started | P6: LSA §§6.3, 6.8, 7.3, 7.7; Fourth Amendment
A7: PRE-03 | B7: Tax & structure | C7: Engage joint tax counsel (NH experience) | D7: Engagement letter and scope: F-reorg, Rev. Rul. 99-5, NH BPT, QSBS, §83 repurchase wording, Ben's residency, Form 8594, §754. Agree who pays | E7: P1 - Critical | F7: Medium | G7: Jon | H7: Frank, Josh | I7: 46290 | J7: 46297 | K7: =J7-I7+1 -> 8 | L7: =IF(O7="Done","",J7-TODAY()) -> 7 | N7: Y | O7: Not started | P7: Offer Review v3; Structures report §4
A8: PRE-04 | B8: Deal terms | C8: Jon decides open terms | D8: Series A options doc (14 decisions) and data-room decisions: Reference Valuation, Thread payoff vs consent, consent strategy, equity-protection fallback, cash timing, disclosure scope, board seat | E8: P1 - Critical | F8: Medium | G8: Jon | H8: Frank | I8: 46293 | J8: 46297 | K8: =J8-I8+1 -> 5 | L8: =IF(O8="Done","",J8-TODAY()) -> 7 | M8: PRE-02 | N8: Y | O8: Not started | P8: Options doc v2; Data Room Review §8
A9: PRE-05 | B9: Financing & consents | C9: Brief new Felicis partner and a16z (YC ES20 as backup) | D9: Explain partnership, request 55% Requisite Holder consent (§3.3.9, §3.3.8, §3.3.7) and IRA §4.1 ROFO waiver | E9: P1 - Critical | F9: Medium | G9: Jon | H9: Frank | I9: 46293 | J9: 46302 | K9: =J9-I9+1 -> 10 | L9: =IF(O9="Done","",J9-TODAY()) -> 12 | N9: Y | O9: Not started | P9: Charter Art. IV.B §3.3; IRA §6.6(b)
A10: PRE-06 | B10: Financing & consents | C10: Explore insider bridge SAFE ($1–2M) | D10: Felicis/YC bridge signed alongside the deal to restore runway and validate the reference price | E10: P2 - High | F10: High | G10: Jon | H10: Josh | I10: 46293 | J10: 46311 | K10: =J10-I10+1 -> 19 | L10: =IF(O10="Done","",J10-TODAY()) -> 21 | M10: PRE-05 | N10: N | O10: Not started | P10: Deal assessment – 'what would improve the odds'
A11: PRE-07 | B11: Tax & structure | C11: Confirm current 409A and engage appraiser | D11: Resolve $0.17 vs $0.22; indicative value of Ben's plain common as of Jan 2, 2027; scope the closing-date update | E11: P1 - Critical | F11: Medium | G11: Josh | H11: Appraiser | I11: 46293 | J11: 46304 | K11: =J11-I11+1 -> 12 | L11: =IF(O11="Done","",J11-TODAY()) -> 14 | N11: Y | O11: Not started | P11: Data Room Review §3.2
A12: PRE-08 | B12: Diligence prep | C12: Pro forma SAFE-conversion cap table | D12: At $50M and $60M reference; include Thread warrants (up to 42,500 sh) and Ben's shares | E12: P2 - High | F12: Low | G12: Josh | H12: Frank | I12: 46293 | J12: 46300 | K12: =J12-I12+1 -> 8 | L12: =IF(O12="Done","",J12-TODAY()) -> 10 | N12: N | O12: Not started | P12: Data Room Review §3.1
A13: PRE-09 | B13: Diligence prep | C13: ARR bridge | D13: Investor-update SaaS ARR ($3.06M) to GAAP revenue (Aug run-rate $3.14M all-in / $2.55M platform fees) | E13: P2 - High | F13: Medium | G13: Josh | H13: Frank | I13: 46293 | J13: 46302 | K13: =J13-I13+1 -> 10 | L13: =IF(O13="Done","",J13-TODAY()) -> 12 | N13: N | O13: Not started | P13: Data Room Review §3.5
A14: PRE-10 | B14: Financing & consents | C14: Fix Kindergarten SAFE cap wording; confirm Burkland SAFE | D14: Correct 'Pre-Money Valuation Cap'; confirm whether the $60M SAFE has closed and falls within the 2025 authorization ($2.5M) | E14: P2 - High | F14: Low | G14: Corey | H14: Josh | I14: 46293 | J14: 46302 | K14: =J14-I14+1 -> 10 | L14: =IF(O14="Done","",J14-TODAY()) -> 12 | N14: N | O14: Not started | P14: SAFE Summary items 1–2; 2025 consent
A15: PRE-11 | B15: Financing & consents | C15: Thread decision and next action | D15: Recommended: request payoff letter (LSA §2.6) and wind-down timeline. Alternative: written consent + §6.10 carve-out for Keystone | E15: P1 - Critical | F15: Medium | G15: Jon | H15: Josh, Corey | I15: 46294 | J15: 46304 | K15: =J15-I15+1 -> 11 | L15: =IF(O15="Done","",J15-TODAY()) -> 14 | M15: PRE-02 | N15: Y | O15: Not started | P15: Data Room Review Decision 1
A16: PRE-12 | B16: Seller | C16: Walk-through call with Ben | D16: Verbal offer: 70/30, $650K cash, plain common at reference valuation, preference stack, tax framing, timeline, consents | E16: P1 - Critical | F16: Medium | G16: Jon | H16: Frank | I16: 46295 | J16: 46297 | K16: =J16-I16+1 -> 3 | L16: =IF(O16="Done","",J16-TODAY()) -> 7 | M16: PRE-04 | N16: Y | O16: Not started | P16: Jon plans mid-week call
A17: PRE-13 | B17: Seller | C17: Send Ben tax questions and document request | D17: Offer Review v3 §8 questions; 1120-S, NH-1120/DP-80, 1040 Sch. D/E, S-election acceptance letter | E17: P2 - High | F17: Low | G17: Frank | H17: Tax counsel | I17: 46295 | J17: 46297 | K17: =J17-I17+1 -> 3 | L17: =IF(O17="Done","",J17-TODAY()) -> 7 | M17: PRE-03 | N17: N | O17: Not started | P17: Offer Review v3 §8
A18: PRE-14 | B18: Tax & structure | C18: Confirm Ben's residency plan | D18: NH vs Europe through 2027 and at exit; drives the whole tax analysis | E18: P1 - Critical | F18: Low | G18: Ben | H18: Tax counsel, Jon | I18: 46296 | J18: 46304 | K18: =J18-I18+1 -> 9 | L18: =IF(O18="Done","",J18-TODAY()) -> 14 | M18: PRE-12 | N18: N | O18: Not started | P18: Structures report §4
A19: PRE-15 | B19: Commercial | C19: Amanda / partner bookkeeping firm transition plan | D19: Reconcile Keystone exclusivity with the existing partner firm and Quantum SOW | E19: P2 - High | F19: Medium | G19: Darren | H19: Jon | I19: 46293 | J19: 46304 | K19: =J19-I19+1 -> 12 | L19: =IF(O19="Done","",J19-TODAY()) -> 14 | N19: N | O19: Not started | P19: Investor update (Bookkeeping)
A20: PRE-16 | B20: Governance | C20: Inform co-founder Bryan Beshore | D20: 24.5% FD holder and Key Holder; not required to consent but should hear it from Jon | E20: P3 - Medium | F20: Low | G20: Jon | I20: 46296 | J20: 46304 | K20: =J20-I20+1 -> 9 | L20: =IF(O20="Done","",J20-TODAY()) -> 14 | N20: N | O20: Not started | P20: Voting Agreement §3.2
A21: PRE-17 | B21: Financing & consents | C21: Draft omnibus stockholder consent | D21: Template: 7/1/25 SAFE consent. Covers §3.3.9 non-wholly-owned subsidiary, §3.3.8 related-party arrangements with Ben, §3.3.7 any deferred payment, ROFO waiver, $60M SAFE ratification if needed | E21: P1 - Critical | F21: Medium | G21: Corey | H21: Frank | I21: 46296 | J21: 46304 | K21: =J21-I21+1 -> 9 | L21: =IF(O21="Done","",J21-TODAY()) -> 14 | M21: PRE-05 | N21: Y | O21: Not started | P21: Data Room Review §5
A22: PRE-18 | B22: Governance | C22: Confirm board authority | D22: Can a single sitting director approve? Fill the vacant Common Director seat if needed; resolution authorizing LOI | E22: P2 - High | F22: Low | G22: Corey | H22: Jon | I22: 46296 | J22: 46304 | K22: =J22-I22+1 -> 9 | L22: =IF(O22="Done","",J22-TODAY()) -> 14 | N22: N | O22: Not started | P22: Voting Agreement §1.2; bylaws
A23: PRE-19 | B23: Documents | C23: Update LOI v14 and Offer v16 | D23: Apply Jon's decisions and data-room changes (closing conditions, consents, disclosure package, credit-support clause, $50M reference) | E23: P1 - Critical | F23: Low | G23: Frank | I23: 46297 | J23: 46301 | K23: =J23-I23+1 -> 5 | L23: =IF(O23="Done","",J23-TODAY()) -> 11 | M23: PRE-04 | N23: Y | O23: Not started | P23: Data Room Review §6–7
A24: PRE-20 | B24: Deal terms | C24: Re-run scenario model | D24: 12–15 month runway, $50M reference, 409A range for Ben's closing tax, 15–25% Series A dilution, after-tax rows | E24: P2 - High | F24: Medium | G24: Frank | H24: Josh | I24: 46297 | J24: 46303 | K24: =J24-I24+1 -> 7 | L24: =IF(O24="Done","",J24-TODAY()) -> 13 | M24: PRE-07 | N24: N | O24: Not started | P24: Data Room Review §9 item 10
A25: PRE-21 | B25: Documents | C25: Counsel review of LOI v14 / Offer v16 and Exhibit A | D25: Corey sign-off before release; include operating agreement term sheet | E25: P1 - Critical | F25: Medium | G25: Corey | H25: Frank | I25: 46301 | J25: 46304 | K25: =J25-I25+1 -> 4 | L25: =IF(O25="Done","",J25-TODAY()) -> 14 | M25: PRE-19 | N25: Y | O25: Not started
A26: PRE-22 | B26: Seller | C26: Topkey disclosure package for Ben | D26: Financials through 8/31/26, cap table, charter, SAFE and warrant schedule, Thread summary, ARR bridge; confirm NDA coverage | E26: P2 - High | F26: Medium | G26: Josh | H26: Frank | I26: 46300 | J26: 46307 | K26: =J26-I26+1 -> 8 | L26: =IF(O26="Done","",J26-TODAY()) -> 17 | M26: PRE-09 | N26: N | O26: Not started | P26: Data Room Review Decision 6
A27: PRE-23 | B27: Documents | C27: Accredited-investor questionnaire ready | D27: Rule 506(b) private placement to Ben | E27: P3 - Medium | F27: Low | G27: Corey | I27: 46300 | J27: 46307 | K27: =J27-I27+1 -> 8 | L27: =IF(O27="Done","",J27-TODAY()) -> 17 | N27: N | O27: Not started
A28: PRE-24 | B28: Financing & consents | C28: Stockholder consent executed (or LOI made conditional) | D28: Felicis + a16z (or YC) signatures; ROFO waiver | E28: P1 - Critical | F28: High | G28: Jon | H28: Felicis, a16z | I28: 46304 | J28: 46311 | K28: =J28-I28+1 -> 8 | L28: =IF(O28="Done","",J28-TODAY()) -> 21 | M28: PRE-17 | N28: Y | O28: Not started
A29: PRE-25 | B29: Documents | C29: Send LOI and Offer to Ben | D29: With disclosure package or a date for it | E29: P1 - Critical | F29: Low | G29: Jon | H29: Frank | I29: 46304 | J29: 46304 | K29: =J29-I29+1 -> 1 | L29: =IF(O29="Done","",J29-TODAY()) -> 14 | M29: PRE-21 | N29: Y | O29: Not started
A30: PRE-26 | B30: Seller | C30: Ben and his advisors review; negotiate LOI | D30: Expect pushback on stock value (409A gap) and cash after tax | E30: P1 - Critical | F30: High | G30: Ben | H30: Jon, Frank | I30: 46304 | J30: 46311 | K30: =J30-I30+1 -> 8 | L30: =IF(O30="Done","",J30-TODAY()) -> 21 | M30: PRE-25 | N30: Y | O30: Not started | P30: Deal assessment – concern #3
A31: PRE-27 | B31: Milestone | C31: LOI SIGNED | D31: Exclusivity (90 days) starts; target Friday Oct 16 | E31: P1 - Critical | F31: Medium | G31: Jon | H31: Ben | I31: 46311 | J31: 46311 | K31: =J31-I31+1 -> 1 | L31: =IF(O31="Done","",J31-TODAY()) -> 21 | M31: PRE-24, PRE-26 | N31: Y | O31: Not started

Sheet Post-LOI Checklist
A1: Post-LOI Checklist – Oct 19, 2026 to closing (Jan 2, 2027) and post-close
A2: Edit Status (drop-down), Start and Due. Days to due is blank once Done.
A4: ID | B4: Workstream | C4: Task | D4: Detail / deliverable | E4: Priority | F4: Difficulty | G4: Owner | H4: Support | I4: Start | J4: Due | K4: Duration (days) | L4: Days to due | M4: Depends on | N4: Critical path | O4: Status | P4: Notes / source
A5: POST-01 | B5: Project management | C5: Kickoff call, diligence request list, working-group list and calendar | D5: Weekly deal call through signing | E5: P1 - Critical | F5: Low | G5: Frank | H5: Tereno | I5: 46314 | J5: 46316 | K5: =J5-I5+1 -> 3 | L5: =IF(O5="Done","",J5-TODAY()) -> 26 | M5: PRE-27 | N5: Y | O5: Not started
A6: POST-02 | B6: Diligence | C6: Keystone target data room populated | D6: Financials, contracts, roster, vendor agreements, IP, tax filings | E6: P1 - Critical | F6: Medium | G6: Ben | H6: Frank | I6: 46314 | J6: 46325 | K6: =J6-I6+1 -> 12 | L6: =IF(O6="Done","",J6-TODAY()) -> 35 | M6: POST-01 | N6: Y | O6: Not started
A7: POST-03 | B7: Tax & structure | C7: Tax structure memo | D7: F-reorg, 99-5 treatment, NH BPT, QSBS opinion on Topkey shares, §83 repurchase, Form 8594 allocation, §754, tax distributions | E7: P1 - Critical | F7: High | G7: Tax counsel | H7: Josh, Frank | I7: 46314 | J7: 46339 | K7: =J7-I7+1 -> 26 | L7: =IF(O7="Done","",J7-TODAY()) -> 49 | M7: PRE-03 | N7: Y | O7: Not started
A8: POST-04 | B8: Diligence | C8: Entity and tax diligence | D8: Formation docs, S-election acceptance, stock basis/AAA, NH DP-80 apportionment, §174 treatment of Arch/portal | E8: P2 - High | F8: Medium | G8: Tax counsel | H8: Josh | I8: 46314 | J8: 46339 | K8: =J8-I8+1 -> 26 | L8: =IF(O8="Done","",J8-TODAY()) -> 49 | M8: POST-02 | N8: N | O8: Not started
A9: POST-05 | B9: Financing & consents | C9: Thread payoff executed | D9: Payoff letter, UCC-3 termination, DACA terminations (Mercury, Brex), warrant status | E9: P1 - Critical | F9: Medium | G9: Jon | H9: Josh, Corey | I9: 46314 | J9: 46356 | K9: =J9-I9+1 -> 43 | L9: =IF(O9="Done","",J9-TODAY()) -> 66 | M9: PRE-11 | N9: Y | O9: Not started | P9: LSA §2.6
A10: POST-06 | B10: Financing & consents | C10: Charge-card wind-down and reserve release | D10: Collect $779K receivables, release reserve and operational balances, settle $476K reward-points liability | E10: P2 - High | F10: Medium | G10: Josh | H10: Jon | I10: 46314 | J10: 46387 | K10: =J10-I10+1 -> 74 | L10: =IF(O10="Done","",J10-TODAY()) -> 97 | M10: POST-05 | N10: N | O10: Not started | P10: Financials 8/31/26
A11: POST-07 | B11: Financing & consents | C11: Insider bridge SAFE closed (if pursued) | D11: Restores runway before closing cash goes out | E11: P2 - High | F11: High | G11: Jon | H11: Josh, Corey | I11: 46314 | J11: 46367 | K11: =J11-I11+1 -> 54 | L11: =IF(O11="Done","",J11-TODAY()) -> 77 | M11: PRE-06 | N11: N | O11: Not started
A12: POST-08 | B12: Diligence | C12: Reverse diligence by Ben's advisors | D12: Q&A on Topkey package, preference stack, runway | E12: P2 - High | F12: Medium | G12: Ben | H12: Josh, Frank | I12: 46314 | J12: 46339 | K12: =J12-I12+1 -> 26 | L12: =IF(O12="Done","",J12-TODAY()) -> 49 | M12: PRE-22 | N12: N | O12: Not started
A13: POST-09 | B13: Diligence | C13: Quality of earnings and working-capital peg | D13: Normalized EBITDA ($470–500K), deferred revenue as operating liability, card/revolver balances cleared | E13: P1 - Critical | F13: High | G13: Josh | H13: Frank | I13: 46321 | J13: 46346 | K13: =J13-I13+1 -> 26 | L13: =IF(O13="Done","",J13-TODAY()) -> 56 | M13: POST-02 | N13: Y | O13: Not started
A14: POST-10 | B14: Diligence | C14: Client contracts, retention and churn | D14: Revenue per client, properties per client, SMB book sale, departures | E14: P2 - High | F14: Medium | G14: Frank | H14: Tereno | I14: 46321 | J14: 46339 | K14: =J14-I14+1 -> 19 | L14: =IF(O14="Done","",J14-TODAY()) -> 49 | M14: POST-02 | N14: N | O14: Not started
A15: POST-11 | B15: Diligence | C15: Offshore team classification and go-forward model | D15: Philippines counsel view; EOR for client leads and accounting staff; special indemnity scope | E15: P1 - Critical | F15: High | G15: Corey | H15: PH counsel, Ben | I15: 46321 | J15: 46351 | K15: =J15-I15+1 -> 31 | L15: =IF(O15="Done","",J15-TODAY()) -> 61 | M15: POST-02 | N15: Y | O15: Not started | P15: LOI 7(d); Options doc Decision 8
A16: POST-12 | B16: Diligence | C16: Vendor and software contract assignability | D16: VR Platform, Karbon (through Apr 2027), other tools | E16: P2 - High | F16: Medium | G16: Frank | H16: Corey | I16: 46321 | J16: 46339 | K16: =J16-I16+1 -> 19 | L16: =IF(O16="Done","",J16-TODAY()) -> 49 | M16: POST-02 | N16: N | O16: Not started
A17: POST-13 | B17: Diligence | C17: IP assignment confirmation | D17: Arch, client portal, developer work product assigned to Keystone | E17: P2 - High | F17: Medium | G17: Corey | H17: Ben | I17: 46321 | J17: 46339 | K17: =J17-I17+1 -> 19 | L17: =IF(O17="Done","",J17-TODAY()) -> 49 | M17: POST-02 | N17: N | O17: Not started
A18: POST-14 | B18: Diligence | C18: Franchise, marketplace and referral agreements | D18: PMI, PMS marketplaces, STR Secrets, commissions | E18: P2 - High | F18: Low | G18: Frank | I18: 46321 | J18: 46339 | K18: =J18-I18+1 -> 19 | L18: =IF(O18="Done","",J18-TODAY()) -> 49 | M18: POST-02 | N18: N | O18: Not started
A19: POST-15 | B19: Documents | C19: Membership interest purchase agreement – first draft | D19: Reps, indemnity (10% cap, 0.75% basket, 15 months), escrow, set-off, special indemnity, Topkey reps | E19: P1 - Critical | F19: High | G19: Corey | H19: Frank | I19: 46321 | J19: 46339 | K19: =J19-I19+1 -> 19 | L19: =IF(O19="Done","",J19-TODAY()) -> 49 | M19: PRE-27 | N19: Y | O19: Not started
A20: POST-16 | B20: Documents | C20: A&R Operating Agreement – first draft | D20: Board, consent rights, tax distributions, ROFR/tag/drag, call (yrs 3–5) and put (yr 5), Formula Price, credit-support limit | E20: P1 - Critical | F20: High | G20: Corey | H20: Frank | I20: 46321 | J20: 46339 | K20: =J20-I20+1 -> 19 | L20: =IF(O20="Done","",J20-TODAY()) -> 49 | M20: PRE-27 | N20: Y | O20: Not started | P20: LOI Exhibit A
A21: POST-17 | B21: Documents | C21: Services Schedule | D21: Topkey product pricing, engineering support and IP ownership/licence, referral fee | E21: P1 - Critical | F21: Medium | G21: Frank | H21: Jon, Corey | I21: 46328 | J21: 46346 | K21: =J21-I21+1 -> 19 | L21: =IF(O21="Done","",J21-TODAY()) -> 56 | M21: POST-16 | N21: N | O21: Not started | P21: LOI 7(b)
A22: POST-18 | B22: Integration | C22: Migration Protocol | D22: Readiness criteria, cohort sign-off by Ben, Jan–Feb blackout, trust accounts last; tied to trust-accounting general availability | E22: P2 - High | F22: Medium | G22: Pete | H22: Darren, Ben, Frank | I22: 46328 | J22: 46351 | K22: =J22-I22+1 -> 24 | L22: =IF(O22="Done","",J22-TODAY()) -> 61 | N22: N | O22: Not started
A23: POST-19 | B23: Documents | C23: Ben employment and restrictive-covenant agreements | D23: Title, bonus metrics, severance, Good Reason, non-compete (NH enforceability; Ben abroad) | E23: P1 - Critical | F23: Medium | G23: Corey | H23: Jon | I23: 46328 | J23: 46351 | K23: =J23-I23+1 -> 24 | L23: =IF(O23="Done","",J23-TODAY()) -> 61 | M23: PRE-27 | N23: N | O23: Not started
A24: POST-20 | B24: Documents | C24: Related-party recruiting agreement | D24: Arm's-length terms; approved in stockholder consent | E24: P3 - Medium | F24: Low | G24: Corey | H24: Ben | I24: 46342 | J24: 46360 | K24: =J24-I24+1 -> 19 | L24: =IF(O24="Done","",J24-TODAY()) -> 70 | N24: N | O24: Not started | P24: Charter §3.3.8
A25: POST-21 | B25: Tax & structure | C25: F-reorganization executed | D25: NewCo S corp formed, Keystone LLC contributed, QSub election (Form 8869), EINs, NewCo bank account | E25: P1 - Critical | F25: Medium | G25: Ben | H25: Ben's CPA, tax counsel | I25: 46342 | J25: 46371 | K25: =J25-I25+1 -> 30 | L25: =IF(O25="Done","",J25-TODAY()) -> 81 | M25: POST-03 | N25: Y | O25: Not started
A26: POST-22 | B26: Documents | C26: Disclosure schedules | D26: Seller schedules against MIPA reps | E26: P1 - Critical | F26: Medium | G26: Ben | H26: Corey | I26: 46342 | J26: 46367 | K26: =J26-I26+1 -> 26 | L26: =IF(O26="Done","",J26-TODAY()) -> 77 | M26: POST-15 | N26: Y | O26: Not started
A27: POST-23 | B27: Documents | C27: Document turns and negotiation | D27: 2–3 rounds with Ben's counsel on MIPA, Operating Agreement, employment, Services Schedule | E27: P1 - Critical | F27: High | G27: Corey | H27: Jon, Frank, Ben's counsel | I27: 46342 | J27: 46367 | K27: =J27-I27+1 -> 26 | L27: =IF(O27="Done","",J27-TODAY()) -> 77 | M27: POST-15, POST-16 | N27: Y | O27: Not started
A28: POST-24 | B28: Diligence | C28: Third-party consents | D28: VR Platform, Karbon, PMI, marketplaces, any lease | E28: P2 - High | F28: Medium | G28: Ben | H28: Frank | I28: 46342 | J28: 46367 | K28: =J28-I28+1 -> 26 | L28: =IF(O28="Done","",J28-TODAY()) -> 77 | M28: POST-12 | N28: N | O28: Not started
A29: POST-25 | B29: Tax & structure | C29: Closing-date 409A and appraisal of Ben's shares; agree Form 8594 allocation | D29: Both sides report the same value | E29: P1 - Critical | F29: Medium | G29: Josh | H29: Appraiser, tax counsel | I29: 46342 | J29: 46374 | K29: =J29-I29+1 -> 33 | L29: =IF(O29="Done","",J29-TODAY()) -> 84 | M29: PRE-07 | N29: Y | O29: Not started
A30: POST-26 | B30: Integration | C30: Day-1 and 100-day integration plan | D30: Two-segment reporting, monthly close, banking, brand ('Keystone, a Topkey company'), governance calendar | E30: P2 - High | F30: Medium | G30: Frank | H30: Tereno, Jon, Ben | I30: 46342 | J30: 46374 | K30: =J30-I30+1 -> 33 | L30: =IF(O30="Done","",J30-TODAY()) -> 84 | N30: N | O30: Not started
A31: POST-27 | B31: Documents | C31: Escrow agreement and agent | D31: $65K escrow, 15-month term | E31: P3 - Medium | F31: Low | G31: Corey | I31: 46349 | J31: 46367 | K31: =J31-I31+1 -> 19 | L31: =IF(O31="Done","",J31-TODAY()) -> 77 | N31: N | O31: Not started
A32: POST-28 | B32: Documents | C32: Securities documents | D32: Subscription, investor questionnaire, Voting Agreement adoption, ROFR/co-sale joinder, IRA stand-off, legends; Form D prep | E32: P2 - High | F32: Low | G32: Corey | I32: 46357 | J32: 46371 | K32: =J32-I32+1 -> 15 | L32: =IF(O32="Done","",J32-TODAY()) -> 81 | N32: N | O32: Not started | P32: Voting Agreement §7.1(b)
A33: POST-29 | B33: Governance | C33: Ben option grant | D33: Board approval at 409A strike | E33: P3 - Medium | F33: Low | G33: Corey | H33: Josh | I33: 46357 | J33: 46374 | K33: =J33-I33+1 -> 18 | L33: =IF(O33="Done","",J33-TODAY()) -> 84 | M33: POST-25 | N33: N | O33: Not started
A34: POST-30 | B34: Integration | C34: Client and team communications plan | D34: Announce after Jan 2; no disruption in 1099 season | E34: P2 - High | F34: Low | G34: Ben | H34: Jon | I34: 46363 | J34: 46374 | K34: =J34-I34+1 -> 12 | L34: =IF(O34="Done","",J34-TODAY()) -> 84 | N34: N | O34: Not started
A35: POST-31 | B35: Closing | C35: Funds-flow memo and wire verification | D35: Escrow $65K on 12/18; $585K to NewCo on first business day; call-back verification | E35: P1 - Critical | F35: Low | G35: Josh | H35: Corey | I35: 46363 | J35: 46373 | K35: =J35-I35+1 -> 11 | L35: =IF(O35="Done","",J35-TODAY()) -> 83 | N35: N | O35: Not started
A36: POST-32 | B36: Closing | C36: Confirm effective time and wire date | D36: Jan 2, 2027 is a Saturday – confirm effective time with tax counsel; wires on Mon Jan 4 | E36: P2 - High | F36: Low | G36: Corey | H36: Tax counsel | I36: 46357 | J36: 46367 | K36: =J36-I36+1 -> 11 | L36: =IF(O36="Done","",J36-TODAY()) -> 77 | N36: N | O36: Not started
A37: POST-33 | B37: Governance | C37: Final board approval and any bring-down consent | D37: Acquisition, share issuance with fair-value finding, employment, option grant, repurchase right | E37: P1 - Critical | F37: Low | G37: Jon | H37: Corey | I37: 46370 | J37: 46373 | K37: =J37-I37+1 -> 4 | L37: =IF(O37="Done","",J37-TODAY()) -> 83 | M37: POST-23 | N37: Y | O37: Not started | P37: Charter §4.4.5
A38: POST-34 | B38: Milestone | C38: SIGNING – definitive agreements executed; escrow funded | D38: Target Friday Dec 18, 2026 | E38: P1 - Critical | F38: Medium | G38: Jon | H38: Ben, Corey | I38: 46374 | J38: 46374 | K38: =J38-I38+1 -> 1 | L38: =IF(O38="Done","",J38-TODAY()) -> 84 | M38: POST-21, POST-22, POST-23, POST-33 | N38: Y | O38: Not started
A39: POST-35 | B39: Closing | C39: Exclusivity window check | D39: 90 days from LOI ≈ Jan 14, 2027; single automatic 30-day extension | E39: P2 - High | F39: Low | G39: Frank | I39: 46374 | J39: 46401 | K39: =J39-I39+1 -> 28 | L39: =IF(O39="Done","",J39-TODAY()) -> 111 | N39: N | O39: Not started | P39: LOI Agreement §1
A40: POST-36 | B40: Milestone | C40: EFFECTIVE DATE – closing | D40: Operating Agreement effective, shares issued, $585K wired Mon Jan 4 | E40: P1 - Critical | F40: Low | G40: Jon | H40: Josh, Corey | I40: 46389 | J40: 46391 | K40: =J40-I40+1 -> 3 | L40: =IF(O40="Done","",J40-TODAY()) -> 101 | M40: POST-34 | N40: Y | O40: Not started
A41: POST-37 | B41: Post-close | C41: Post-close filings | D41: Form D within 15 days, Pulley cap table, stock notices, blue sky | E41: P2 - High | F41: Low | G41: Corey | H41: Josh | I41: 46391 | J41: 46402 | K41: =J41-I41+1 -> 12 | L41: =IF(O41="Done","",J41-TODAY()) -> 112 | M41: POST-36 | N41: N | O41: Not started
...

Sheet Timeline
A1: Timeline – weekly view (weeks start Monday)
A2: Bars update from the Start and Due dates on the checklist tabs. Red columns: LOI signing (Oct 16), signing (Dec 18), effective date (Jan 2).
A4: ID | B4: Task | C4: Owner | D4: Priority | E4: Start | F4: Due | G4: Status | H4: 46286 | I4: 46293 | J4: 46300 | K4: 46307 | L4: 46314 | M4: 46321 | N4: 46328 | O4: 46335 | P4: 46342 | Q4: 46349 | R4: 46356 | S4: 46363 | T4: 46370 | U4: 46377 | V4: 46384 | W4: 46391 | X4: 46398 | Y4: 46405 | Z4: 46412 | AA4: 46419 | AB4: 46426 | AC4: 46433 | AD4: 46440 | AE4: 46447 | AF4: 46454 | AG4: 46461 | AH4: 46468 | AI4: 46475 | AJ4: 46482 | AK4: 46489
A5: PRE-LOI
A6: ='Pre-LOI Checklist'!A5 -> PRE-01 | B6: ='Pre-LOI Checklist'!C5 -> Request missing Topkey items | C6: ='Pre-LOI Checklist'!G5 -> Frank | D6: ='Pre-LOI Checklist'!E5 -> P2 - High | E6: ='Pre-LOI Checklist'!I5 -> 46290 | F6: ='Pre-LOI Checklist'!J5 -> 46294 | G6: ='Pre-LOI Checklist'!O5 -> Not started | H6: =IF(AND($E6<=H$4+6,$F6>=H$4),IF($E6=$F6,"◆","■"),"") -> ■ | I6: =IF(AND($E6<=I$4+6,$F6>=I$4),IF($E6=$F6,"◆","■"),"") -> ■ | J6: =IF(AND($E6<=J$4+6,$F6>=J$4),IF($E6=$F6,"◆","■"),"") | K6: =IF(AND($E6<=K$4+6,$F6>=K$4),IF($E6=$F6,"◆","■"),"") | L6: =IF(AND($E6<=L$4+6,$F6>=L$4),IF($E6=$F6,"◆","■"),"") | M6: =IF(AND($E6<=M$4+6,$F6>=M$4),IF($E6=$F6,"◆","■"),"") | N6: =IF(AND($E6<=N$4+6,$F6>=N$4),IF($E6=$F6,"◆","■"),"") | O6: =IF(AND($E6<=O$4+6,$F6>=O$4),IF($E6=$F6,"◆","■"),"") | ... AK6: =IF(AND($E6<=AK$4+6,$F6>=AK$4),IF($E6=$F6,"◆","■"),"")
A7: ='Pre-LOI Checklist'!A6 -> PRE-02 | B7: ='Pre-LOI Checklist'!C6 -> Confirm Thread Bank line status after Aug 26, 2026 maturity | C7: ='Pre-LOI Checklist'!G6 -> Jon | D7: ='Pre-LOI Checklist'!E6 -> P1 - Critical | E7: ='Pre-LOI Checklist'!I6 -> 46290 | F7: ='Pre-LOI Checklist'!J6 -> 46294 | G7: ='Pre-LOI Checklist'!O6 -> Not started | H7: =IF(AND($E7<=H$4+6,$F7>=H$4),IF($E7=$F7,"◆","■"),"") -> ■ | I7: =IF(AND($E7<=I$4+6,$F7>=I$4),IF($E7=$F7,"◆","■"),"") -> ■ | J7: =IF(AND($E7<=J$4+6,$F7>=J$4),IF($E7=$F7,"◆","■"),"") | K7: =IF(AND($E7<=K$4+6,$F7>=K$4),IF($E7=$F7,"◆","■"),"") | L7: =IF(AND($E7<=L$4+6,$F7>=L$4),IF($E7=$F7,"◆","■"),"") | M7: =IF(AND($E7<=M$4+6,$F7>=M$4),IF($E7=$F7,"◆","■"),"") | N7: =IF(AND($E7<=N$4+6,$F7>=N$4),IF($E7=$F7,"◆","■"),"") | O7: =IF(AND($E7<=O$4+6,$F7>=O$4),IF($E7=$F7,"◆","■"),"") | ... AK7: =IF(AND($E7<=AK$4+6,$F7>=AK$4),IF($E7=$F7,"◆","■"),"")
A8: ='Pre-LOI Checklist'!A7 -> PRE-03 | B8: ='Pre-LOI Checklist'!C7 -> Engage joint tax counsel (NH experience) | C8: ='Pre-LOI Checklist'!G7 -> Jon | D8: ='Pre-LOI Checklist'!E7 -> P1 - Critical | E8: ='Pre-LOI Checklist'!I7 -> 46290 | F8: ='Pre-LOI Checklist'!J7 -> 46297 | G8: ='Pre-LOI Checklist'!O7 -> Not started | H8: =IF(AND($E8<=H$4+6,$F8>=H$4),IF($E8=$F8,"◆","■"),"") -> ■ | I8: =IF(AND($E8<=I$4+6,$F8>=I$4),IF($E8=$F8,"◆","■"),"") -> ■ | J8: =IF(AND($E8<=J$4+6,$F8>=J$4),IF($E8=$F8,"◆","■"),"") | K8: =IF(AND($E8<=K$4+6,$F8>=K$4),IF($E8=$F8,"◆","■"),"") | L8: =IF(AND($E8<=L$4+6,$F8>=L$4),IF($E8=$F8,"◆","■"),"") | M8: =IF(AND($E8<=M$4+6,$F8>=M$4),IF($E8=$F8,"◆","■"),"") | N8: =IF(AND($E8<=N$4+6,$F8>=N$4),IF($E8=$F8,"◆","■"),"") | O8: =IF(AND($E8<=O$4+6,$F8>=O$4),IF($E8=$F8,"◆","■"),"") | ... AK8: =IF(AND($E8<=AK$4+6,$F8>=AK$4),IF($E8=$F8,"◆","■"),"")
A9: ='Pre-LOI Checklist'!A8 -> PRE-04 | B9: ='Pre-LOI Checklist'!C8 -> Jon decides open terms | C9: ='Pre-LOI Checklist'!G8 -> Jon | D9: ='Pre-LOI Checklist'!E8 -> P1 - Critical | E9: ='Pre-LOI Checklist'!I8 -> 46293 | F9: ='Pre-LOI Checklist'!J8 -> 46297 | G9: ='Pre-LOI Checklist'!O8 -> Not started | H9: =IF(AND($E9<=H$4+6,$F9>=H$4),IF($E9=$F9,"◆","■"),"") | I9: =IF(AND($E9<=I$4+6,$F9>=I$4),IF($E9=$F9,"◆","■"),"") -> ■ | J9: =IF(AND($E9<=J$4+6,$F9>=J$4),IF($E9=$F9,"◆","■"),"") | K9: =IF(AND($E9<=K$4+6,$F9>=K$4),IF($E9=$F9,"◆","■"),"") | L9: =IF(AND($E9<=L$4+6,$F9>=L$4),IF($E9=$F9,"◆","■"),"") | M9: =IF(AND($E9<=M$4+6,$F9>=M$4),IF($E9=$F9,"◆","■"),"") | N9: =IF(AND($E9<=N$4+6,$F9>=N$4),IF($E9=$F9,"◆","■"),"") | O9: =IF(AND($E9<=O$4+6,$F9>=O$4),IF($E9=$F9,"◆","■"),"") | ... AK9: =IF(AND($E9<=AK$4+6,$F9>=AK$4),IF($E9=$F9,"◆","■"),"")
A10: ='Pre-LOI Checklist'!A9 -> PRE-05 | B10: ='Pre-LOI Checklist'!C9 -> Brief new Felicis partner and a16z (YC ES20 as backup) | C10: ='Pre-LOI Checklist'!G9 -> Jon | D10: ='Pre-LOI Checklist'!E9 -> P1 - Critical | E10: ='Pre-LOI Checklist'!I9 -> 46293 | F10: ='Pre-LOI Checklist'!J9 -> 46302 | G10: ='Pre-LOI Checklist'!O9 -> Not started | H10: =IF(AND($E10<=H$4+6,$F10>=H$4),IF($E10=$F10,"◆","■"),"") | I10: =IF(AND($E10<=I$4+6,$F10>=I$4),IF($E10=$F10,"◆","■"),"") -> ■ | J10: =IF(AND($E10<=J$4+6,$F10>=J$4),IF($E10=$F10,"◆","■"),"") -> ■ | K10: =IF(AND($E10<=K$4+6,$F10>=K$4),IF($E10=$F10,"◆","■"),"") | L10: =IF(AND($E10<=L$4+6,$F10>=L$4),IF($E10=$F10,"◆","■"),"") | M10: =IF(AND($E10<=M$4+6,$F10>=M$4),IF($E10=$F10,"◆","■"),"") | N10: =IF(AND($E10<=N$4+6,$F10>=N$4),IF($E10=$F10,"◆","■"),"") | O10: =IF(AND($E10<=O$4+6,$F10>=O$4),IF($E10=$F10,"◆","■"),"") | ... AK10: =IF(AND($E10<=AK$4+6,$F10>=AK$4),IF($E10=$F10,"◆","■"),"")
A11: ='Pre-LOI Checklist'!A10 -> PRE-06 | B11: ='Pre-LOI Checklist'!C10 -> Explore insider bridge SAFE ($1–2M) | C11: ='Pre-LOI Checklist'!G10 -> Jon | D11: ='Pre-LOI Checklist'!E10 -> P2 - High | E11: ='Pre-LOI Checklist'!I10 -> 46293 | F11: ='Pre-LOI Checklist'!J10 -> 46311 | G11: ='Pre-LOI Checklist'!O10 -> Not started | H11: =IF(AND($E11<=H$4+6,$F11>=H$4),IF($E11=$F11,"◆","■"),"") | I11: =IF(AND($E11<=I$4+6,$F11>=I$4),IF($E11=$F11,"◆","■"),"") -> ■ | J11: =IF(AND($E11<=J$4+6,$F11>=J$4),IF($E11=$F11,"◆","■"),"") -> ■ | K11: =IF(AND($E11<=K$4+6,$F11>=K$4),IF($E11=$F11,"◆","■"),"") -> ■ | L11: =IF(AND($E11<=L$4+6,$F11>=L$4),IF($E11=$F11,"◆","■"),"") | M11: =IF(AND($E11<=M$4+6,$F11>=M$4),IF($E11=$F11,"◆","■"),"") | N11: =IF(AND($E11<=N$4+6,$F11>=N$4),IF($E11=$F11,"◆","■"),"") | O11: =IF(AND($E11<=O$4+6,$F11>=O$4),IF($E11=$F11,"◆","■"),"") | ... AK11: =IF(AND($E11<=AK$4+6,$F11>=AK$4),IF($E11=$F11,"◆","■"),"")
A12: ='Pre-LOI Checklist'!A11 -> PRE-07 | B12: ='Pre-LOI Checklist'!C11 -> Confirm current 409A and engage appraiser | C12: ='Pre-LOI Checklist'!G11 -> Josh | D12: ='Pre-LOI Checklist'!E11 -> P1 - Critical | E12: ='Pre-LOI Checklist'!I11 -> 46293 | F12: ='Pre-LOI Checklist'!J11 -> 46304 | G12: ='Pre-LOI Checklist'!O11 -> Not started | H12: =IF(AND($E12<=H$4+6,$F12>=H$4),IF($E12=$F12,"◆","■"),"") | I12: =IF(AND($E12<=I$4+6,$F12>=I$4),IF($E12=$F12,"◆","■"),"") -> ■ | J12: =IF(AND($E12<=J$4+6,$F12>=J$4),IF($E12=$F12,"◆","■"),"") -> ■ | K12: =IF(AND($E12<=K$4+6,$F12>=K$4),IF($E12=$F12,"◆","■"),"") | L12: =IF(AND($E12<=L$4+6,$F12>=L$4),IF($E12=$F12,"◆","■"),"") | M12: =IF(AND($E12<=M$4+6,$F12>=M$4),IF($E12=$F12,"◆","■"),"") | N12: =IF(AND($E12<=N$4+6,$F12>=N$4),IF($E12=$F12,"◆","■"),"") | O12: =IF(AND($E12<=O$4+6,$F12>=O$4),IF($E12=$F12,"◆","■"),"") | ... AK12: =IF(AND($E12<=AK$4+6,$F12>=AK$4),IF($E12=$F12,"◆","■"),"")
A13: ='Pre-LOI Checklist'!A12 -> PRE-08 | B13: ='Pre-LOI Checklist'!C12 -> Pro forma SAFE-conversion cap table | C13: ='Pre-LOI Checklist'!G12 -> Josh | D13: ='Pre-LOI Checklist'!E12 -> P2 - High | E13: ='Pre-LOI Checklist'!I12 -> 46293 | F13: ='Pre-LOI Checklist'!J12 -> 46300 | G13: ='Pre-LOI Checklist'!O12 -> Not started | H13: =IF(AND($E13<=H$4+6,$F13>=H$4),IF($E13=$F13,"◆","■"),"") | I13: =IF(AND($E13<=I$4+6,$F13>=I$4),IF($E13=$F13,"◆","■"),"") -> ■ | J13: =IF(AND($E13<=J$4+6,$F13>=J$4),IF($E13=$F13,"◆","■"),"") -> ■ | K13: =IF(AND($E13<=K$4+6,$F13>=K$4),IF($E13=$F13,"◆","■"),"") | L13: =IF(AND($E13<=L$4+6,$F13>=L$4),IF($E13=$F13,"◆","■"),"") | M13: =IF(AND($E13<=M$4+6,$F13>=M$4),IF($E13=$F13,"◆","■"),"") | N13: =IF(AND($E13<=N$4+6,$F13>=N$4),IF($E13=$F13,"◆","■"),"") | O13: =IF(AND($E13<=O$4+6,$F13>=O$4),IF($E13=$F13,"◆","■"),"") | ... AK13: =IF(AND($E13<=AK$4+6,$F13>=AK$4),IF($E13=$F13,"◆","■"),"")
A14: ='Pre-LOI Checklist'!A13 -> PRE-09 | B14: ='Pre-LOI Checklist'!C13 -> ARR bridge | C14: ='Pre-LOI Checklist'!G13 -> Josh | D14: ='Pre-LOI Checklist'!E13 -> P2 - High | E14: ='Pre-LOI Checklist'!I13 -> 46293 | F14: ='Pre-LOI Checklist'!J13 -> 46302 | G14: ='Pre-LOI Checklist'!O13 -> Not started | H14: =IF(AND($E14<=H$4+6,$F14>=H$4),IF($E14=$F14,"◆","■"),"") | I14: =IF(AND($E14<=I$4+6,$F14>=I$4),IF($E14=$F14,"◆","■"),"") -> ■ | J14: =IF(AND($E14<=J$4+6,$F14>=J$4),IF($E14=$F14,"◆","■"),"") -> ■ | K14: =IF(AND($E14<=K$4+6,$F14>=K$4),IF($E14=$F14,"◆","■"),"") | L14: =IF(AND($E14<=L$4+6,$F14>=L$4),IF($E14=$F14,"◆","■"),"") | M14: =IF(AND($E14<=M$4+6,$F14>=M$4),IF($E14=$F14,"◆","■"),"") | N14: =IF(AND($E14<=N$4+6,$F14>=N$4),IF($E14=$F14,"◆","■"),"") | O14: =IF(AND($E14<=O$4+6,$F14>=O$4),IF($E14=$F14,"◆","■"),"") | ... AK14: =IF(AND($E14<=AK$4+6,$F14>=AK$4),IF($E14=$F14,"◆","■"),"")
A15: ='Pre-LOI Checklist'!A14 -> PRE-10 | B15: ='Pre-LOI Checklist'!C14 -> Fix Kindergarten SAFE cap wording; confirm Burkland SAFE | C15: ='Pre-LOI Checklist'!G14 -> Corey | D15: ='Pre-LOI Checklist'!E14 -> P2 - High | E15: ='Pre-LOI Checklist'!I14 -> 46293 | F15: ='Pre-LOI Checklist'!J14 -> 46302 | G15: ='Pre-LOI Checklist'!O14 -> Not started | H15: =IF(AND($E15<=H$4+6,$F15>=H$4),IF($E15=$F15,"◆","■"),"") | I15: =IF(AND($E15<=I$4+6,$F15>=I$4),IF($E15=$F15,"◆","■"),"") -> ■ | J15: =IF(AND($E15<=J$4+6,$F15>=J$4),IF($E15=$F15,"◆","■"),"") -> ■ | K15: =IF(AND($E15<=K$4+6,$F15>=K$4),IF($E15=$F15,"◆","■"),"") | L15: =IF(AND($E15<=L$4+6,$F15>=L$4),IF($E15=$F15,"◆","■"),"") | M15: =IF(AND($E15<=M$4+6,$F15>=M$4),IF($E15=$F15,"◆","■"),"") | N15: =IF(AND($E15<=N$4+6,$F15>=N$4),IF($E15=$F15,"◆","■"),"") | O15: =IF(AND($E15<=O$4+6,$F15>=O$4),IF($E15=$F15,"◆","■"),"") | ... AK15: =IF(AND($E15<=AK$4+6,$F15>=AK$4),IF($E15=$F15,"◆","■"),"")
A16: ='Pre-LOI Checklist'!A15 -> PRE-11 | B16: ='Pre-LOI Checklist'!C15 -> Thread decision and next action | C16: ='Pre-LOI Checklist'!G15 -> Jon | D16: ='Pre-LOI Checklist'!E15 -> P1 - Critical | E16: ='Pre-LOI Checklist'!I15 -> 46294 | F16: ='Pre-LOI Checklist'!J15 -> 46304 | G16: ='Pre-LOI Checklist'!O15 -> Not started | H16: =IF(AND($E16<=H$4+6,$F16>=H$4),IF($E16=$F16,"◆","■"),"") | I16: =IF(AND($E16<=I$4+6,$F16>=I$4),IF($E16=$F16,"◆","■"),"") -> ■ | J16: =IF(AND($E16<=J$4+6,$F16>=J$4),IF($E16=$F16,"◆","■"),"") -> ■ | K16: =IF(AND($E16<=K$4+6,$F16>=K$4),IF($E16=$F16,"◆","■"),"") | L16: =IF(AND($E16<=L$4+6,$F16>=L$4),IF($E16=$F16,"◆","■"),"") | M16: =IF(AND($E16<=M$4+6,$F16>=M$4),IF($E16=$F16,"◆","■"),"") | N16: =IF(AND($E16<=N$4+6,$F16>=N$4),IF($E16=$F16,"◆","■"),"") | O16: =IF(AND($E16<=O$4+6,$F16>=O$4),IF($E16=$F16,"◆","■"),"") | ... AK16: =IF(AND($E16<=AK$4+6,$F16>=AK$4),IF($E16=$F16,"◆","■"),"")
A17: ='Pre-LOI Checklist'!A16 -> PRE-12 | B17: ='Pre-LOI Checklist'!C16 -> Walk-through call with Ben | C17: ='Pre-LOI Checklist'!G16 -> Jon | D17: ='Pre-LOI Checklist'!E16 -> P1 - Critical | E17: ='Pre-LOI Checklist'!I16 -> 46295 | F17: ='Pre-LOI Checklist'!J16 -> 46297 | G17: ='Pre-LOI Checklist'!O16 -> Not started | H17: =IF(AND($E17<=H$4+6,$F17>=H$4),IF($E17=$F17,"◆","■"),"") | I17: =IF(AND($E17<=I$4+6,$F17>=I$4),IF($E17=$F17,"◆","■"),"") -> ■ | J17: =IF(AND($E17<=J$4+6,$F17>=J$4),IF($E17=$F17,"◆","■"),"") | K17: =IF(AND($E17<=K$4+6,$F17>=K$4),IF($E17=$F17,"◆","■"),"") | L17: =IF(AND($E17<=L$4+6,$F17>=L$4),IF($E17=$F17,"◆","■"),"") | M17: =IF(AND($E17<=M$4+6,$F17>=M$4),IF($E17=$F17,"◆","■"),"") | N17: =IF(AND($E17<=N$4+6,$F17>=N$4),IF($E17=$F17,"◆","■"),"") | O17: =IF(AND($E17<=O$4+6,$F17>=O$4),IF($E17=$F17,"◆","■"),"") | ... AK17: =IF(AND($E17<=AK$4+6,$F17>=AK$4),IF($E17=$F17,"◆","■"),"")
... A32: ='Pre-LOI Checklist'!A31 -> PRE-27 | B32: ='Pre-LOI Checklist'!C31 -> LOI SIGNED | C32: ='Pre-LOI Checklist'!G31 -> Jon | D32: ='Pre-LOI Checklist'!E31 -> P1 - Critical | E32: ='Pre-LOI Checklist'!I31 -> 46311 | F32: ='Pre-LOI Checklist'!J31 -> 46311 | G32: ='Pre-LOI Checklist'!O31 -> Not started | H32: =IF(AND($E32<=H$4+6,$F32>=H$4),IF($E32=$F32,"◆","■"),"") | I32: =IF(AND($E32<=I$4+6,$F32>=I$4),IF($E32=$F32,"◆","■"),"") | J32: =IF(AND($E32<=J$4+6,$F32>=J$4),IF($E32=$F32,"◆","■"),"") | K32: =IF(AND($E32<=K$4+6,$F32>=K$4),IF($E32=$F32,"◆","■"),"") -> ◆ | L32: =IF(AND($E32<=L$4+6,$F32>=L$4),IF($E32=$F32,"◆","■"),"") | M32: =IF(AND($E32<=M$4+6,$F32>=M$4),IF($E32=$F32,"◆","■"),"") | N32: =IF(AND($E32<=N$4+6,$F32>=N$4),IF($E32=$F32,"◆","■"),"") | O32: =IF(AND($E32<=O$4+6,$F32>=O$4),IF($E32=$F32,"◆","■"),"") | ... AK32: =IF(AND($E32<=AK$4+6,$F32>=AK$4),IF($E32=$F32,"◆","■"),"")
A33: POST-LOI
A34: ='Post-LOI Checklist'!A5 -> POST-01 | B34: ='Post-LOI Checklist'!C5 -> Kickoff call, diligence request list, working-group list and calendar | C34: ='Post-LOI Checklist'!G5 -> Frank | D34: ='Post-LOI Checklist'!E5 -> P1 - Critical | E34: ='Post-LOI Checklist'!I5 -> 46314 | F34: ='Post-LOI Checklist'!J5 -> 46316 | G34: ='Post-LOI Checklist'!O5 -> Not started | H34: =IF(AND($E34<=H$4+6,$F34>=H$4),IF($E34=$F34,"◆","■"),"") | I34: =IF(AND($E34<=I$4+6,$F34>=I$4),IF($E34=$F34,"◆","■"),"") | J34: =IF(AND($E34<=J$4+6,$F34>=J$4),IF($E34=$F34,"◆","■"),"") | K34: =IF(AND($E34<=K$4+6,$F34>=K$4),IF($E34=$F34,"◆","■"),"") | L34: =IF(AND($E34<=L$4+6,$F34>=L$4),IF($E34=$F34,"◆","■"),"") -> ■ | M34: =IF(AND($E34<=M$4+6,$F34>=M$4),IF($E34=$F34,"◆","■"),"") | N34: =IF(AND($E34<=N$4+6,$F34>=N$4),IF($E34=$F34,"◆","■"),"") | O34: =IF(AND($E34<=O$4+6,$F34>=O$4),IF($E34=$F34,"◆","■"),"") | ... AK34: =IF(AND($E34<=AK$4+6,$F34>=AK$4),IF($E34=$F34,"◆","■"),"")
A35: ='Post-LOI Checklist'!A6 -> POST-02 | B35: ='Post-LOI Checklist'!C6 -> Keystone target data room populated | C35: ='Post-LOI Checklist'!G6 -> Ben | D35: ='Post-LOI Checklist'!E6 -> P1 - Critical | E35: ='Post-LOI Checklist'!I6 -> 46314 | F35: ='Post-LOI Checklist'!J6 -> 46325 | G35: ='Post-LOI Checklist'!O6 -> Not started | H35: =IF(AND($E35<=H$4+6,$F35>=H$4),IF($E35=$F35,"◆","■"),"") | I35: =IF(AND($E35<=I$4+6,$F35>=I$4),IF($E35=$F35,"◆","■"),"") | J35: =IF(AND($E35<=J$4+6,$F35>=J$4),IF($E35=$F35,"◆","■"),"") | K35: =IF(AND($E35<=K$4+6,$F35>=K$4),IF($E35=$F35,"◆","■"),"") | L35: =IF(AND($E35<=L$4+6,$F35>=L$4),IF($E35=$F35,"◆","■"),"") -> ■ | M35: =IF(AND($E35<=M$4+6,$F35>=M$4),IF($E35=$F35,"◆","■"),"") -> ■ | N35: =IF(AND($E35<=N$4+6,$F35>=N$4),IF($E35=$F35,"◆","■"),"") | O35: =IF(AND($E35<=O$4+6,$F35>=O$4),IF($E35=$F35,"◆","■"),"") | ... AK35: =IF(AND($E35<=AK$4+6,$F35>=AK$4),IF($E35=$F35,"◆","■"),"")
A36: ='Post-LOI Checklist'!A7 -> POST-03 | B36: ='Post-LOI Checklist'!C7 -> Tax structure memo | C36: ='Post-LOI Checklist'!G7 -> Tax counsel | D36: ='Post-LOI Checklist'!E7 -> P1 - Critical | E36: ='Post-LOI Checklist'!I7 -> 46314 | F36: ='Post-LOI Checklist'!J7 -> 46339 | G36: ='Post-LOI Checklist'!O7 -> Not started | H36: =IF(AND($E36<=H$4+6,$F36>=H$4),IF($E36=$F36,"◆","■"),"") | I36: =IF(AND($E36<=I$4+6,$F36>=I$4),IF($E36=$F36,"◆","■"),"") | J36: =IF(AND($E36<=J$4+6,$F36>=J$4),IF($E36=$F36,"◆","■"),"") | K36: =IF(AND($E36<=K$4+6,$F36>=K$4),IF($E36=$F36,"◆","■"),"") | L36: =IF(AND($E36<=L$4+6,$F36>=L$4),IF($E36=$F36,"◆","■"),"") -> ■ | M36: =IF(AND($E36<=M$4+6,$F36>=M$4),IF($E36=$F36,"◆","■"),"") -> ■ | N36: =IF(AND($E36<=N$4+6,$F36>=N$4),IF($E36=$F36,"◆","■"),"") -> ■ | O36: =IF(AND($E36<=O$4+6,$F36>=O$4),IF($E36=$F36,"◆","■"),"") -> ■ | ... AK36: =IF(AND($E36<=AK$4+6,$F36>=AK$4),IF($E36=$F36,"◆","■"),"")
A37: ='Post-LOI Checklist'!A8 -> POST-04 | B37: ='Post-LOI Checklist'!C8 -> Entity and tax diligence | C37: ='Post-LOI Checklist'!G8 -> Tax counsel | D37: ='Post-LOI Checklist'!E8 -> P2 - High | E37: ='Post-LOI Checklist'!I8 -> 46314 | F37: ='Post-LOI Checklist'!J8 -> 46339 | G37: ='Post-LOI Checklist'!O8 -> Not started | H37: =IF(AND($E37<=H$4+6,$F37>=H$4),IF($E37=$F37,"◆","■"),"") | I37: =IF(AND($E37<=I$4+6,$F37>=I$4),IF($E37=$F37,"◆","■"),"") | J37: =IF(AND($E37<=J$4+6,$F37>=J$4),IF($E37=$F37,"◆","■"),"") | K37: =IF(AND($E37<=K$4+6,$F37>=K$4),IF($E37=$F37,"◆","■"),"") | L37: =IF(AND($E37<=L$4+6,$F37>=L$4),IF($E37=$F37,"◆","■"),"") -> ■ | M37: =IF(AND($E37<=M$4+6,$F37>=M$4),IF($E37=$F37,"◆","■"),"") -> ■ | N37: =IF(AND($E37<=N$4+6,$F37>=N$4),IF($E37=$F37,"◆","■"),"") -> ■ | O37: =IF(AND($E37<=O$4+6,$F37>=O$4),IF($E37=$F37,"◆","■"),"") -> ■ | ... AK37: =IF(AND($E37<=AK$4+6,$F37>=AK$4),IF($E37=$F37,"◆","■"),"")
A38: ='Post-LOI Checklist'!A9 -> POST-05 | B38: ='Post-LOI Checklist'!C9 -> Thread payoff executed | C38: ='Post-LOI Checklist'!G9 -> Jon | D38: ='Post-LOI Checklist'!E9 -> P1 - Critical | E38: ='Post-LOI Checklist'!I9 -> 46314 | F38: ='Post-LOI Checklist'!J9 -> 46356 | G38: ='Post-LOI Checklist'!O9 -> Not started | H38: =IF(AND($E38<=H$4+6,$F38>=H$4),IF($E38=$F38,"◆","■"),"") | I38: =IF(AND($E38<=I$4+6,$F38>=I$4),IF($E38=$F38,"◆","■"),"") | J38: =IF(AND($E38<=J$4+6,$F38>=J$4),IF($E38=$F38,"◆","■"),"") | K38: =IF(AND($E38<=K$4+6,$F38>=K$4),IF($E38=$F38,"◆","■"),"") | L38: =IF(AND($E38<=L$4+6,$F38>=L$4),IF($E38=$F38,"◆","■"),"") -> ■ | M38: =IF(AND($E38<=M$4+6,$F38>=M$4),IF($E38=$F38,"◆","■"),"") -> ■ | N38: =IF(AND($E38<=N$4+6,$F38>=N$4),IF($E38=$F38,"◆","■"),"") -> ■ | O38: =IF(AND($E38<=O$4+6,$F38>=O$4),IF($E38=$F38,"◆","■"),"") -> ■ | ... AK38: =IF(AND($E38<=AK$4+6,$F38>=AK$4),IF($E38=$F38,"◆","■"),"")
A39: ='Post-LOI Checklist'!A10 -> POST-06 | B39: ='Post-LOI Checklist'!C10 -> Charge-card wind-down and reserve release | C39: ='Post-LOI Checklist'!G10 -> Josh | D39: ='Post-LOI Checklist'!E10 -> P2 - High | E39: ='Post-LOI Checklist'!I10 -> 46314 | F39: ='Post-LOI Checklist'!J10 -> 46387 | G39: ='Post-LOI Checklist'!O10 -> Not started | H39: =IF(AND($E39<=H$4+6,$F39>=H$4),IF($E39=$F39,"◆","■"),"") | I39: =IF(AND($E39<=I$4+6,$F39>=I$4),IF($E39=$F39,"◆","■"),"") | J39: =IF(AND($E39<=J$4+6,$F39>=J$4),IF($E39=$F39,"◆","■"),"") | K39: =IF(AND($E39<=K$4+6,$F39>=K$4),IF($E39=$F39,"◆","■"),"") | L39: =IF(AND($E39<=L$4+6,$F39>=L$4),IF($E39=$F39,"◆","■"),"") -> ■ | M39: =IF(AND($E39<=M$4+6,$F39>=M$4),IF($E39=$F39,"◆","■"),"") -> ■ | N39: =IF(AND($E39<=N$4+6,$F39>=N$4),IF($E39=$F39,"◆","■"),"") -> ■ | O39: =IF(AND($E39<=O$4+6,$F39>=O$4),IF($E39=$F39,"◆","■"),"") -> ■ | ... AK39: =IF(AND($E39<=AK$4+6,$F39>=AK$4),IF($E39=$F39,"◆","■"),"")
A40: ='Post-LOI Checklist'!A11 -> POST-07 | B40: ='Post-LOI Checklist'!C11 -> Insider bridge SAFE closed (if pursued) | C40: ='Post-LOI Checklist'!G11 -> Jon | D40: ='Post-LOI Checklist'!E11 -> P2 - High | E40: ='Post-LOI Checklist'!I11 -> 46314 | F40: ='Post-LOI Checklist'!J11 -> 46367 | G40: ='Post-LOI Checklist'!O11 -> Not started | H40: =IF(AND($E40<=H$4+6,$F40>=H$4),IF($E40=$F40,"◆","■"),"") | I40: =IF(AND($E40<=I$4+6,$F40>=I$4),IF($E40=$F40,"◆","■"),"") | J40: =IF(AND($E40<=J$4+6,$F40>=J$4),IF($E40=$F40,"◆","■"),"") | K40: =IF(AND($E40<=K$4+6,$F40>=K$4),IF($E40=$F40,"◆","■"),"") | L40: =IF(AND($E40<=L$4+6,$F40>=L$4),IF($E40=$F40,"◆","■"),"") -> ■ | M40: =IF(AND($E40<=M$4+6,$F40>=M$4),IF($E40=$F40,"◆","■"),"") -> ■ | N40: =IF(AND($E40<=N$4+6,$F40>=N$4),IF($E40=$F40,"◆","■"),"") -> ■ | O40: =IF(AND($E40<=O$4+6,$F40>=O$4),IF($E40=$F40,"◆","■"),"") -> ■ | ... AK40: =IF(AND($E40<=AK$4+6,$F40>=AK$4),IF($E40=$F40,"◆","■"),"")
A41: ='Post-LOI Checklist'!A12 -> POST-08 | B41: ='Post-LOI Checklist'!C12 -> Reverse diligence by Ben's advisors | C41: ='Post-LOI Checklist'!G12 -> Ben | D41: ='Post-LOI Checklist'!E12 -> P2 - High | E41: ='Post-LOI Checklist'!I12 -> 46314 | F41: ='Post-LOI Checklist'!J12 -> 46339 | G41: ='Post-LOI Checklist'!O12 -> Not started | H41: =IF(AND($E41<=H$4+6,$F41>=H$4),IF($E41=$F41,"◆","■"),"") | I41: =IF(AND($E41<=I$4+6,$F41>=I$4),IF($E41=$F41,"◆","■"),"") | J41: =IF(AND($E41<=J$4+6,$F41>=J$4),IF($E41=$F41,"◆","■"),"") | K41: =IF(AND($E41<=K$4+6,$F41>=K$4),IF($E41=$F41,"◆","■"),"") | L41: =IF(AND($E41<=L$4+6,$F41>=L$4),IF($E41=$F41,"◆","■"),"") -> ■ | M41: =IF(AND($E41<=M$4+6,$F41>=M$4),IF($E41=$F41,"◆","■"),"") -> ■ | N41: =IF(AND($E41<=N$4+6,$F41>=N$4),IF($E41=$F41,"◆","■"),"") -> ■ | O41: =IF(AND($E41<=O$4+6,$F41>=O$4),IF($E41=$F41,"◆","■"),"") -> ■ | ... AK41: =IF(AND($E41<=AK$4+6,$F41>=AK$4),IF($E41=$F41,"◆","■"),"")
A42: ='Post-LOI Checklist'!A13 -> POST-09 | B42: ='Post-LOI Checklist'!C13 -> Quality of earnings and working-capital peg | C42: ='Post-LOI Checklist'!G13 -> Josh | D42: ='Post-LOI Checklist'!E13 -> P1 - Critical | E42: ='Post-LOI Checklist'!I13 -> 46321 | F42: ='Post-LOI Checklist'!J13 -> 46346 | G42: ='Post-LOI Checklist'!O13 -> Not started | H42: =IF(AND($E42<=H$4+6,$F42>=H$4),IF($E42=$F42,"◆","■"),"") | I42: =IF(AND($E42<=I$4+6,$F42>=I$4),IF($E42=$F42,"◆","■"),"") | J42: =IF(AND($E42<=J$4+6,$F42>=J$4),IF($E42=$F42,"◆","■"),"") | K42: =IF(AND($E42<=K$4+6,$F42>=K$4),IF($E42=$F42,"◆","■"),"") | L42: =IF(AND($E42<=L$4+6,$F42>=L$4),IF($E42=$F42,"◆","■"),"") | M42: =IF(AND($E42<=M$4+6,$F42>=M$4),IF($E42=$F42,"◆","■"),"") -> ■ | N42: =IF(AND($E42<=N$4+6,$F42>=N$4),IF($E42=$F42,"◆","■"),"") -> ■ | O42: =IF(AND($E42<=O$4+6,$F42>=O$4),IF($E42=$F42,"◆","■"),"") -> ■ | ... AK42: =IF(AND($E42<=AK$4+6,$F42>=AK$4),IF($E42=$F42,"◆","■"),"")
A43: ='Post-LOI Checklist'!A14 -> POST-10 | B43: ='Post-LOI Checklist'!C14 -> Client contracts, retention and churn | C43: ='Post-LOI Checklist'!G14 -> Frank | D43: ='Post-LOI Checklist'!E14 -> P2 - High | E43: ='Post-LOI Checklist'!I14 -> 46321 | F43: ='Post-LOI Checklist'!J14 -> 46339 | G43: ='Post-LOI Checklist'!O14 -> Not started | H43: =IF(AND($E43<=H$4+6,$F43>=H$4),IF($E43=$F43,"◆","■"),"") | I43: =IF(AND($E43<=I$4+6,$F43>=I$4),IF($E43=$F43,"◆","■"),"") | J43: =IF(AND($E43<=J$4+6,$F43>=J$4),IF($E43=$F43,"◆","■"),"") | K43: =IF(AND($E43<=K$4+6,$F43>=K$4),IF($E43=$F43,"◆","■"),"") | L43: =IF(AND($E43<=L$4+6,$F43>=L$4),IF($E43=$F43,"◆","■"),"") | M43: =IF(AND($E43<=M$4+6,$F43>=M$4),IF($E43=$F43,"◆","■"),"") -> ■ | N43: =IF(AND($E43<=N$4+6,$F43>=N$4),IF($E43=$F43,"◆","■"),"") -> ■ | O43: =IF(AND($E43<=O$4+6,$F43>=O$4),IF($E43=$F43,"◆","■"),"") -> ■ | ... AK43: =IF(AND($E43<=AK$4+6,$F43>=AK$4),IF($E43=$F43,"◆","■"),"")
A44: ='Post-LOI Checklist'!A15 -> POST-11 | B44: ='Post-LOI Checklist'!C15 -> Offshore team classification and go-forward model | C44: ='Post-LOI Checklist'!G15 -> Corey | D44: ='Post-LOI Checklist'!E15 -> P1 - Critical | E44: ='Post-LOI Checklist'!I15 -> 46321 | F44: ='Post-LOI Checklist'!J15 -> 46351 | G44: ='Post-LOI Checklist'!O15 -> Not started | H44: =IF(AND($E44<=H$4+6,$F44>=H$4),IF($E44=$F44,"◆","■"),"") | I44: =IF(AND($E44<=I$4+6,$F44>=I$4),IF($E44=$F44,"◆","■"),"") | J44: =IF(AND($E44<=J$4+6,$F44>=J$4),IF($E44=$F44,"◆","■"),"") | K44: =IF(AND($E44<=K$4+6,$F44>=K$4),IF($E44=$F44,"◆","■"),"") | L44: =IF(AND($E44<=L$4+6,$F44>=L$4),IF($E44=$F44,"◆","■"),"") | M44: =IF(AND($E44<=M$4+6,$F44>=M$4),IF($E44=$F44,"◆","■"),"") -> ■ | N44: =IF(AND($E44<=N$4+6,$F44>=N$4),IF($E44=$F44,"◆","■"),"") -> ■ | O44: =IF(AND($E44<=O$4+6,$F44>=O$4),IF($E44=$F44,"◆","■"),"") -> ■ | ... AK44: =IF(AND($E44<=AK$4+6,$F44>=AK$4),IF($E44=$F44,"◆","■"),"")
A45: ='Post-LOI Checklist'!A16 -> POST-12 | B45: ='Post-LOI Checklist'!C16 -> Vendor and software contract assignability | C45: ='Post-LOI Checklist'!G16 -> Frank | D45: ='Post-LOI Checklist'!E16 -> P2 - High | E45: ='Post-LOI Checklist'!I16 -> 46321 | F45: ='Post-LOI Checklist'!J16 -> 46339 | G45: ='Post-LOI Checklist'!O16 -> Not started | H45: =IF(AND($E45<=H$4+6,$F45>=H$4),IF($E45=$F45,"◆","■"),"") | I45: =IF(AND($E45<=I$4+6,$F45>=I$4),IF($E45=$F45,"◆","■"),"") | J45: =IF(AND($E45<=J$4+6,$F45>=J$4),IF($E45=$F45,"◆","■"),"") | K45: =IF(AND($E45<=K$4+6,$F45>=K$4),IF($E45=$F45,"◆","■"),"") | L45: =IF(AND($E45<=L$4+6,$F45>=L$4),IF($E45=$F45,"◆","■"),"") | M45: =IF(AND($E45<=M$4+6,$F45>=M$4),IF($E45=$F45,"◆","■"),"") -> ■ | N45: =IF(AND($E45<=N$4+6,$F45>=N$4),IF($E45=$F45,"◆","■"),"") -> ■ | O45: =IF(AND($E45<=O$4+6,$F45>=O$4),IF($E45=$F45,"◆","■"),"") -> ■ | ... AK45: =IF(AND($E45<=AK$4+6,$F45>=AK$4),IF($E45=$F45,"◆","■"),"")
... A74: ='Post-LOI Checklist'!A45 -> POST-41 | B74: ='Post-LOI Checklist'!C45 -> Migration cohort 1 readiness review | C74: ='Post-LOI Checklist'!G45 -> Pete | D74: ='Post-LOI Checklist'!E45 -> P3 - Medium | E74: ='Post-LOI Checklist'!I45 -> 46447 | F74: ='Post-LOI Checklist'!J45 -> 46477 | G74: ='Post-LOI Checklist'!O45 -> Not started | H74: =IF(AND($E74<=H$4+6,$F74>=H$4),IF($E74=$F74,"◆","■"),"") | I74: =IF(AND($E74<=I$4+6,$F74>=I$4),IF($E74=$F74,"◆","■"),"") | J74: =IF(AND($E74<=J$4+6,$F74>=J$4),IF($E74=$F74,"◆","■"),"") | K74: =IF(AND($E74<=K$4+6,$F74>=K$4),IF($E74=$F74,"◆","■"),"") | L74: =IF(AND($E74<=L$4+6,$F74>=L$4),IF($E74=$F74,"◆","■"),"") | M74: =IF(AND($E74<=M$4+6,$F74>=M$4),IF($E74=$F74,"◆","■"),"") | N74: =IF(AND($E74<=N$4+6,$F74>=N$4),IF($E74=$F74,"◆","■"),"") | O74: =IF(AND($E74<=O$4+6,$F74>=O$4),IF($E74=$F74,"◆","■"),"") | ... AK74: =IF(AND($E74<=AK$4+6,$F74>=AK$4),IF($E74=$F74,"◆","■"),"")
