Workbook
Name PrintMode: Contents!$I$18
Name MasterCheck: Contents!$I$19
Name AsOfDate: Assumptions!$C$9
Name FYEMonth: Assumptions!$C$14
Name MainStreetMode: Assumptions!$C$18
Name DealForm: Assumptions!$C$20
Name LOIDate: Assumptions!$C$71
Name SigningDate: Assumptions!$C$73
Name EffectiveDate: Assumptions!$C$74
Name Rev_FY: 'P&L Summary'!$C$14:$E$14
Name GP_FY: 'P&L Summary'!$C$18:$E$18
Name RepEBITDA_FY: 'P&L Summary'!$C$32:$E$32
Name Rev_LTM: 'P&L Summary'!$K$14
Name GP_LTM: 'P&L Summary'!$K$18
Name RepEBITDA_LTM: 'P&L Summary'!$K$32
Name Rev_PF: 'P&L Summary'!$L$14
Name SDE_FY: 'Adj. EBITDA'!$C$24:$E$24
Name AdjEBITDA_FY: 'Adj. EBITDA'!$C$28:$E$28
Name SDE_LTM: 'Adj. EBITDA'!$K$24
Name AdjEBITDA_LTM: 'Adj. EBITDA'!$K$28
Name PFAdjEBITDA: 'Adj. EBITDA'!$L$32
Name ChartStart: 'Revenue Charts'!$C$45
Name ChartEnd: 'Revenue Charts'!$AL$45
Name Customers_Latest: 'Customer Overview'!$C$20
Name GDR_LTM: 'Customer Retention'!$E$29
Name NDR_LTM: 'Customer Retention'!$E$30
Name Top10Share_LTM: Concentration!$D$34
Name Headcount_Latest: Headcount!$C$12
Name NWC_Latest: NWC!$H$20
Name NWC_Peg: NWC!$G$20
Name NWC_vsPeg: NWC!$I$20
Name DefRev_Latest: NWC!$H$15
Name Offer_Reference: 'Deal Structure'!$C$5
Name Offer_Count: 'Deal Structure'!$C$28
Name Offer_Headline_1: 'Deal Structure'!$C$22
Name Offer_CashAtClose_1: 'Deal Structure'!$C$23
Name Monthly_Revenue: 'Monthly P&L'!$Q$14:$AZ$14
Name Monthly_GrossProfit: 'Monthly P&L'!$Q$18:$AZ$18
Name Monthly_RepEBITDA: 'Monthly P&L'!$Q$32:$AZ$32
Name Monthly_SDE: 'Monthly P&L'!$Q$51:$AZ$51
Name Monthly_AdjEBITDA: 'Monthly P&L'!$Q$55:$AZ$55

Sheet Cover
B24: Ridgeline Comfort Services LLC
B25: Financial Model
B26: ="As of "&TEXT('Assumptions'!$C$9,"mm/dd/yy") -> As of 12/31/25
B30: Prepared by AMB Advisory Services LLC for Ridgeline Comfort Services LLC | September 29, 2026 | Confidential

Sheet Contents
B2: =Cover!B24
B3: Contents
B5: # | C5: Tab | D5: Purpose | E5: Units | F5: Check | H5: Model information
B6: 1 | C6: =HYPERLINK("#'Cover'!A1","Cover") -> Cover | D6: Cover | F6: – | H6: Business name | I6: Ridgeline Comfort Services LLC
B7: 2 | C7: =HYPERLINK("#'Contents'!A1","Contents") -> Contents | D7: Index, model information, Print switch, master check, log | F7: – | H7: Code name | I7: Project Ridgeline
B8: 3 | C8: =HYPERLINK("#'Summary'!A1","Summary") -> Summary | D8: Key lines, condensed ladder, KPIs and valuation range | E8: $000s | F8: =IF(OR('Checks'!$G24="CHECK"),"CHECK","OK") -> OK | H8: Prepared by | I8: AMB Advisory Services
B9: 4 | C9: =HYPERLINK("#'Assumptions'!A1","Assumptions") -> Assumptions | D9: Every input, blue, with its source | E9: $ | F9: =IF(OR('Checks'!$G39="CHECK",'Checks'!$G24="CHECK"),"CHECK","OK") -> OK | H9: As-of date | I9: ='Assumptions'!$C$9 -> 46022
B10: 5 | C10: =HYPERLINK("#'P&L Summary'!A1","P&L Summary") -> P&L Summary | D10: Historical P&L by period with KPI block | E10: $000s | F10: =IF(OR('Checks'!$G11="CHECK",'Checks'!$G12="CHECK",'Checks'!$G25="CHECK",'Checks'!$G37="CHECK",'Checks'!$G24="CHECK"),"CHECK","OK") -> OK | H10: LTM period | I10: LTM Dec-25 (equals FY2025)
B11: 6 | C11: =HYPERLINK("#'Adj. EBITDA'!A1","Adj. EBITDA") -> Adj. EBITDA | D11: Reported EBITDA to SDE, Adj. and PF Adj. EBITDA, with refs | E11: $000s | F11: =IF(OR('Checks'!$G13="CHECK",'Checks'!$G14="CHECK",'Checks'!$G24="CHECK"),"CHECK","OK") -> OK | H11: Fiscal year-end | I11: December
B12: 7 | C12: =HYPERLINK("#'Adjustments'!A1","Adjustments") -> Adjustments | D12: The schedule: tier, category, basis, evidence, status | E12: $000s | F12: =IF(OR('Checks'!$G14="CHECK",'Checks'!$G24="CHECK"),"CHECK","OK") -> OK | H12: Mode | I12: Main Street: PF Adj. EBITDA before the reserve $453K vs. $1.0M
B13: 8 | C13: =HYPERLINK("#'Revenue Detail'!A1","Revenue Detail") -> Revenue Detail | D13: Revenue by line: $, % of total, % growth; LTM strip | E13: $000s | F13: =IF(OR('Checks'!$G45="CHECK",'Checks'!$G46="CHECK",'Checks'!$G24="CHECK"),"CHECK","OK") -> OK | H13: Deal form | I13: Asset purchase
B14: 9 | C14: =HYPERLINK("#'Revenue Charts'!A1","Revenue Charts") -> Revenue Charts | D14: Monthly revenue and revenue by line (MC-R1, MC-R2) | E14: #, $000s | F14: =IF(OR('Checks'!$G31="CHECK",'Checks'!$G32="CHECK",'Checks'!$G24="CHECK"),"CHECK","OK") -> OK | H14: Source, FY2023 | I14: P&L and balance sheet: QuickBooks export
B15: 10 | C15: =HYPERLINK("#'Expense Detail'!A1","Expense Detail") -> Expense Detail | D15: Cost and expense buckets: $, % of revenue, growth; LTM strip | E15: $000s | F15: =IF(OR('Checks'!$G45="CHECK",'Checks'!$G46="CHECK",'Checks'!$G24="CHECK"),"CHECK","OK") -> OK | H15: Source, FY2024 | I15: P&L and balance sheet: QuickBooks export
B16: 11 | C16: =HYPERLINK("#'Expense Charts'!A1","Expense Charts") -> Expense Charts | D16: Monthly payroll and largest expense, with % of revenue | E16: #, $000s | F16: =IF(OR('Checks'!$G31="CHECK",'Checks'!$G32="CHECK",'Checks'!$G24="CHECK"),"CHECK","OK") -> OK | H16: Source, FY2025 | I16: P&L and balance sheet: QuickBooks export
B17: 12 | C17: =HYPERLINK("#'Customer Overview'!A1","Customer Overview") -> Customer Overview | D17: Mix by type: count, revenue, average revenue | E17: #, $ | F17: =IF(OR('Checks'!$G21="CHECK",'Checks'!$G24="CHECK"),"CHECK","OK") -> OK | H17: Version | I17: v01
B18: 13 | C18: =HYPERLINK("#'Customer Retention'!A1","Customer Retention") -> Customer Retention | D18: Count and dollar roll-forwards, churn, GDR, NDR; monthly strip | E18: #, $ | F18: =IF(OR('Checks'!$G24="CHECK",COUNTIFS('Customer Retention'!$C$31:$E$31,">0.0005")+COUNTIFS('Customer Retention'!$C$31:$E$31,"<-0.0005")>0),"CHECK","OK") -> OK | H18: Print mode (1 = black fonts) | I18: 0
B19: 14 | C19: =HYPERLINK("#'Retention Charts'!A1","Retention Charts") -> Retention Charts | D19: Monthly wins and losses, by churn type and by segment | E19: #, $000s | F19: =IF(OR('Checks'!$G31="CHECK",'Checks'!$G32="CHECK",'Checks'!$G24="CHECK"),"CHECK","OK") -> OK | H19: Master check | I19: =IF(COUNTIF('Checks'!$G:$G,"CHECK")=0,IF(COUNTIF('Checks'!$G:$G,"Pending")=0,"All checks OK","All checks OK (render check pending)"),COUNTIF('Checks'!$G:$G,"CHECK")&IF(COUNTIF('Checks'!$G:$G,"CHECK")=1," check failing"," checks failing")) -> All checks OK
B20: 15 | C20: =HYPERLINK("#'Concentration'!A1","Concentration") -> Concentration | D20: Top 20 customers, coded, cumulative share, tenure | E20: $ | F20: =IF(OR('Checks'!$G24="CHECK"),"CHECK","OK") -> OK
B21: 16 | C21: =HYPERLINK("#'Cohorts'!A1","Cohorts") -> Cohorts | D21: Count and revenue cohort triangles | E21: #, $ | F21: =IF(OR('Checks'!$G24="CHECK",COUNTIFS('Cohorts'!$D$15:$F$15,">0.0005")+COUNTIFS('Cohorts'!$D$15:$F$15,"<-0.0005")>0,COUNTIFS('Cohorts'!$D$34:$F$34,">0.0005")+COUNTIFS('Cohorts'!$D$34:$F$34,"<-0.0005")>0),"CHECK","OK") -> OK
B22: 17 | C22: =HYPERLINK("#'Headcount'!A1","Headcount") -> Headcount | D22: By department; roll-forward; tenure at departure | E22: #, $ | F22: =IF(OR('Checks'!$G22="CHECK",'Checks'!$G24="CHECK"),"CHECK","OK") -> OK
B23: 18 | C23: =HYPERLINK("#'Headcount Charts'!A1","Headcount Charts") -> Headcount Charts | D23: Monthly hires and departures; tenure at departure | E23: #, $000s | F23: =IF(OR('Checks'!$G31="CHECK",'Checks'!$G32="CHECK",'Checks'!$G24="CHECK"),"CHECK","OK") -> OK
B24: 19 | C24: =HYPERLINK("#'Balance Sheet'!A1","Balance Sheet") -> Balance Sheet | D24: Condensed balance sheet at every statement date | E24: $000s | F24: =IF(OR('Checks'!$G15="CHECK",'Checks'!$G24="CHECK"),"CHECK","OK") -> OK
B25: 20 | C25: =HYPERLINK("#'NWC'!A1","NWC") -> NWC | D25: Net working capital by date, peg basis, ratios, transfers | E25: $000s | F25: =IF(OR('Checks'!$G16="CHECK",'Checks'!$G28="CHECK",'Checks'!$G29="CHECK",'Checks'!$G24="CHECK"),"CHECK","OK") -> OK
B26: 21 | C26: =HYPERLINK("#'Debt-Like Items'!A1","Debt-Like Items") -> Debt-Like Items | D26: Debt and debt-like items: treatment and status | E26: $000s | F26: =IF(OR('Checks'!$G28="CHECK",'Checks'!$G24="CHECK"),"CHECK","OK") -> OK
B27: 22 | C27: =HYPERLINK("#'Cash Flow'!A1","Cash Flow") -> Cash Flow | D27: Historical indirect cash flow, capex, free cash flow | E27: $000s | F27: =IF(OR('Checks'!$G17="CHECK",'Checks'!$G24="CHECK"),"CHECK","OK") -> OK
B28: 23 | C28: =HYPERLINK("#'Proof of Cash'!A1","Proof of Cash") -> Proof of Cash | D28: Monthly revenue vs bank deposits | E28: $000s | F28: =IF(OR('Checks'!$G23="CHECK",'Checks'!$G24="CHECK"),"CHECK","OK") -> OK
B29: 24 | C29: =HYPERLINK("#'Projections'!A1","Projections") -> Projections | D29: Five-year driver-based income statement, BS and cash flow | E29: $000s | F29: =IF(OR('Checks'!$G18="CHECK",'Checks'!$G24="CHECK"),"CHECK","OK") -> OK
B30: 25 | C30: =HYPERLINK("#'Opportunities'!A1","Opportunities") -> Opportunities | D30: One sizing grid per growth lever | E30: $000s | F30: =IF(OR('Checks'!$G24="CHECK"),"CHECK","OK") -> OK
B31: 26 | C31: =HYPERLINK("#'Valuation'!A1","Valuation") -> Valuation | D31: Valuation range, multiples, financing, DSCR (internal) | E31: $000s | F31: =IF(OR('Checks'!$G38="CHECK",'Checks'!$G40="CHECK",'Checks'!$G24="CHECK"),"CHECK","OK") -> OK
B32: 27 | C32: =HYPERLINK("#'Deal Structure'!A1","Deal Structure") -> Deal Structure | D32: Terms, sources and uses, seller proceeds, debt service | E32: $000s | F32: =IF(OR('Checks'!$G20="CHECK",'Checks'!$G38="CHECK",'Checks'!$G40="CHECK",'Checks'!$G47="CHECK",'Checks'!$G24="CHECK"),"CHECK","OK") -> OK
B33: 28 | C33: =HYPERLINK("#'Sensitivities'!A1","Sensitivities") -> Sensitivities | D33: Two-way grids centred on the base case | E33: $000s | F33: =IF(OR('Checks'!$G40="CHECK",'Checks'!$G24="CHECK"),"CHECK","OK") -> OK
B34: 29 | C34: =HYPERLINK("#'Checks'!A1","Checks") -> Checks | D34: Every check with difference, tolerance and status | F34: =IF(OR('Checks'!$G24="CHECK",'Checks'!$G26="CHECK",'Checks'!$G27="CHECK"),"CHECK","OK") -> OK
B35: 30 | C35: =HYPERLINK("#'Data -->'!A1","Data -->") -> Data --> | D35: Data tabs follow | F35: –
B36: 31 | C36: =HYPERLINK("#'Monthly P&L'!A1","Monthly P&L") -> Monthly P&L | D36: Category × month grid every period column reads | E36: $000s | F36: =IF(OR('Checks'!$G10="CHECK",'Checks'!$G12="CHECK",'Checks'!$G24="CHECK"),"CHECK","OK") -> OK
B37: 32 | C37: =HYPERLINK("#'Databook'!A1","Databook") -> Databook | D37: Account × period with mapping and the tie to raw exports | E37: $ | F37: =IF(OR('Checks'!$G9="CHECK",'Checks'!$G10="CHECK",'Checks'!$G24="CHECK"),"CHECK","OK") -> OK
B38: 33 | C38: =HYPERLINK("#'Mapping'!A1","Mapping") -> Mapping | D38: Account to AMB category and summary line | F38: =IF(OR('Checks'!$G24="CHECK"),"CHECK","OK") -> OK
B39: 34 | C39: =HYPERLINK("#'Raw - P&L'!A1","Raw - P&L") -> Raw - P&L | D39: P&L as exported | E39: $ | F39: =IF(OR('Checks'!$G9="CHECK"),"CHECK","OK") -> OK
B40: 35 | C40: =HYPERLINK("#'Raw - BS'!A1","Raw - BS") -> Raw - BS | D40: Balance sheet as exported | E40: $ | F40: =IF(OR('Checks'!$G9="CHECK"),"CHECK","OK") -> OK
B41: 36 | C41: =HYPERLINK("#'Raw - Bank'!A1","Raw - Bank") -> Raw - Bank | D41: Bank transactions as exported, classified | E41: $ | F41: =IF(OR('Checks'!$G23="CHECK"),"CHECK","OK") -> OK
B42: 37 | C42: =HYPERLINK("#'Raw - Customers'!A1","Raw - Customers") -> Raw - Customers | D42: Customer list with names (never leaves this tab) | E42: $ | F42: =IF(OR('Checks'!$G21="CHECK"),"CHECK","OK") -> OK
...

Sheet Summary
B2: =Cover!B24
B3: Summary ($000s) | J3: Print | K3: ='Contents'!$I$18
C5: Full Year | G5: LTM | H5: PF | J5: Notes
B6: Key figures | C6: ='P&L Summary'!C6 -> FY2023 | D6: ='P&L Summary'!D6 -> FY2024 | E6: ='P&L Summary'!E6 -> FY2025 | G6: ='P&L Summary'!K6 -> Dec-25 | H6: ='P&L Summary'!L6 -> Dec-25
B8: Income statement
B9: Total Revenue | C9: ='P&L Summary'!C14 -> 2406.8 | D9: ='P&L Summary'!D14 -> 2718.6 | E9: ='P&L Summary'!E14 -> 3040.8 | G9: ='P&L Summary'!K14 -> 3040.8 | H9: ='P&L Summary'!L14 -> 3040.8
B10: % Growth | C10: ='P&L Summary'!C15 -> n.a. | D10: ='P&L Summary'!D15 -> 0.12954961 | E10: ='P&L Summary'!E15 -> 0.11851688 | G10: ='P&L Summary'!K15 -> 0.11851688 | H10: ='P&L Summary'!L15 -> n.a.
B11: Gross Profit | C11: ='P&L Summary'!C18 -> 1468 | D11: ='P&L Summary'!D18 -> 1670.7 | E11: ='P&L Summary'!E18 -> 1881.9 | G11: ='P&L Summary'!K18 -> 1881.9 | H11: ='P&L Summary'!L18 -> 1881.9
B12: % Margin | C12: ='P&L Summary'!C19 -> 0.60993851 | D12: ='P&L Summary'!D19 -> 0.61454425 | E12: ='P&L Summary'!E19 -> 0.61888319 | G12: ='P&L Summary'!K19 -> 0.61888319 | H12: ='P&L Summary'!L19 -> 0.61888319
B13: Reported EBITDA | C13: ='P&L Summary'!C32 -> 158.2 | D13: ='P&L Summary'!D32 -> 214.64 | E13: ='P&L Summary'!E32 -> 319.515 | G13: ='P&L Summary'!K32 -> 319.515 | H13: ='P&L Summary'!L32 -> 319.515
B14: % Margin | C14: ='P&L Summary'!C33 -> 0.06573043 | D14: ='P&L Summary'!D33 -> 0.078952402 | E14: ='P&L Summary'!E33 -> 0.10507597 | G14: ='P&L Summary'!K33 -> 0.10507597 | H14: ='P&L Summary'!L33 -> 0.10507597
B15: Net Income | C15: ='P&L Summary'!C43 -> 74.6 | D15: ='P&L Summary'!D43 -> 129.24 | E15: ='P&L Summary'!E43 -> 232.815 | G15: ='P&L Summary'!K43 -> 232.815 | H15: ='P&L Summary'!L43 -> 232.815
B17: Adjusted EBITDA ladder (condensed)
B18: Reported EBITDA | C18: ='Adj. EBITDA'!C13 -> 158.2 | D18: ='Adj. EBITDA'!D13 -> 214.64 | E18: ='Adj. EBITDA'!E13 -> 319.515 | G18: ='Adj. EBITDA'!K13 -> 319.515 | H18: ='Adj. EBITDA'!L13 -> 319.515
B19: (+) / (-) Normalization Adjustments | C19: ='Adj. EBITDA'!C21 -> 19.8 | D19: ='Adj. EBITDA'!D21 -> 44.6 | E19: ='Adj. EBITDA'!E21 -> 28.4 | G19: ='Adj. EBITDA'!K21 -> 28.4 | H19: ='Adj. EBITDA'!L21 -> 28.4
B20: ='Adj. EBITDA'!$B$23 -> (+) Owner Compensation [S1] [S4] | C20: ='Adj. EBITDA'!C23 -> 192.584 | D20: ='Adj. EBITDA'!D23 -> 203.25 | E20: ='Adj. EBITDA'!E23 -> 213.86 | G20: ='Adj. EBITDA'!K23 -> 213.86 | H20: ='Adj. EBITDA'!L23 -> 213.86
B21: Seller's Discretionary Earnings (SDE) | C21: ='Adj. EBITDA'!C24 -> 370.584 | D21: ='Adj. EBITDA'!D24 -> 462.49 | E21: ='Adj. EBITDA'!E24 -> 561.775 | G21: ='Adj. EBITDA'!K24 -> 561.775 | H21: ='Adj. EBITDA'!L24 -> 561.775
B22: % Margin | C22: ='Adj. EBITDA'!C25 -> 0.15397374 | D22: ='Adj. EBITDA'!D25 -> 0.17012065 | E22: ='Adj. EBITDA'!E25 -> 0.18474579 | G22: ='Adj. EBITDA'!K25 -> 0.18474579 | H22: ='Adj. EBITDA'!L25 -> 0.18474579
B23: ='Adj. EBITDA'!$B$26 -> (-) Market Replacement Compensation [S2] | C23: ='Adj. EBITDA'!C26 -> -109.25 | D23: ='Adj. EBITDA'!D26 -> -109.25 | E23: ='Adj. EBITDA'!E26 -> -109.25 | G23: ='Adj. EBITDA'!K26 -> -109.25 | H23: ='Adj. EBITDA'!L26 -> -109.25
B24: ='Adj. EBITDA'!$B$27 -> (-) Capital Reserve (Maintenance Capex) [S3] | C24: ='Adj. EBITDA'!C27 -> -66.8 | D24: ='Adj. EBITDA'!D27 -> -66.8 | E24: ='Adj. EBITDA'!E27 -> -66.8 | G24: ='Adj. EBITDA'!K27 -> -66.8 | H24: ='Adj. EBITDA'!L27 -> -66.8
B25: Adj. EBITDA | C25: ='Adj. EBITDA'!C28 -> 194.534 | D25: ='Adj. EBITDA'!D28 -> 286.44 | E25: ='Adj. EBITDA'!E28 -> 385.725 | G25: ='Adj. EBITDA'!K28 -> 385.725 | H25: ='Adj. EBITDA'!L28 -> 385.725
B26: % Margin | C26: ='Adj. EBITDA'!C29 -> 0.080826824 | D26: ='Adj. EBITDA'!D29 -> 0.10536305 | E26: ='Adj. EBITDA'!E29 -> 0.12684984 | G26: ='Adj. EBITDA'!K29 -> 0.12684984 | H26: ='Adj. EBITDA'!L29 -> 0.12684984
B27: (+) / (-) Pro Forma Adjustments | C27: ='Adj. EBITDA'!C31 -> 0 | D27: ='Adj. EBITDA'!D31 -> 0 | E27: ='Adj. EBITDA'!E31 -> 0 | G27: ='Adj. EBITDA'!K31 -> 0 | H27: ='Adj. EBITDA'!L31 -> 0
B28: PF Adj. EBITDA | C28: ='Adj. EBITDA'!C32 -> 194.534 | D28: ='Adj. EBITDA'!D32 -> 286.44 | E28: ='Adj. EBITDA'!E32 -> 385.725 | G28: ='Adj. EBITDA'!K32 -> 385.725 | H28: ='Adj. EBITDA'!L32 -> 385.725
B29: % Margin | C29: ='Adj. EBITDA'!C33 -> 0.080826824 | D29: ='Adj. EBITDA'!D33 -> 0.10536305 | E29: ='Adj. EBITDA'!E33 -> 0.12684984 | G29: ='Adj. EBITDA'!K33 -> 0.12684984 | H29: ='Adj. EBITDA'!L33 -> 0.12684984
B31: Key performance indicators
B32: Customers, active at period end (#) | C32: ='P&L Summary'!C47 -> 44 | D32: ='P&L Summary'!D47 -> 49 | E32: ='P&L Summary'!E47 -> 52 | G32: ='P&L Summary'!K47 -> 52 | H32: ='P&L Summary'!L47 -> 52
B33: Employees, non-owner FTE at period end (#) | C33: ='P&L Summary'!C49 -> 21 | D33: ='P&L Summary'!D49 -> 23 | E33: ='P&L Summary'!E49 -> 23 | G33: ='P&L Summary'!K49 -> 23 | H33: ='P&L Summary'!L49 -> 23
B34: Revenue per employee ($) | C34: ='P&L Summary'!C50 -> 114609.52 | D34: ='P&L Summary'!D50 -> 118200 | E34: ='P&L Summary'!E50 -> 132208.7 | G34: ='P&L Summary'!K50 -> 132208.7 | H34: ='P&L Summary'!L50 -> 132208.7
B35: Labor cost, % of revenue (excludes owner) | C35: ='P&L Summary'!C51 -> 0.29832807 | D35: ='P&L Summary'!D51 -> 0.29605312 | E35: ='P&L Summary'!E51 -> 0.29296238 | G35: ='P&L Summary'!K51 -> 0.29296238 | H35: ='P&L Summary'!L51 -> 0.29296238
B36: Recurring revenue, % of total | C36: ='P&L Summary'!C52 -> 0.089164035 | D36: ='P&L Summary'!D52 -> 0.091333775 | E36: ='P&L Summary'!E52 -> 0.095172323 | G36: ='P&L Summary'!K52 -> 0.095172323 | H36: ='P&L Summary'!L52 -> 0.095172323
B38: At the as-of date (12/31/25)
B39: Top 10 customers, % of revenue | G39: ='Concentration'!$D$34 -> 0.19297553
B40: Adjusted NWC, latest | G40: ='NWC'!H20 -> 173.2 | J40: No peg: year-end balance sheets only
B41: Funded debt, latest | G41: ='Debt-Like Items'!$C$15 -> 279.4 | J41: Seller's; paid from proceeds at close
B42: Mode | G42: =IF('Assumptions'!$C$18=1,"Main Street","Lower middle market") -> Main Street | J42: $453K PF Adj. EBITDA vs. $1.0M threshold
B43: Deal form | G43: ='Assumptions'!$C$20 -> Asset purchase
B45: Operating facts per management (1)
B46: Active maintenance-agreement members (#) | G46: ='Assumptions'!$C$112 -> 1450 | J46: As of 09/21/26. Members with an active agreement: two tune-ups a year, priority scheduling, 15% repair discount
B47: Maintenance-agreement renewal rate | G47: ='Assumptions'!$C$113 -> 0.82 | J47: As of 09/21/26
...

Sheet Assumptions
B2: =Cover!B24
B3: Assumptions and Inputs ($ unless stated) | I3: Print | J3: ='Contents'!$I$18
C5: Inputs | I5: Source
B6: Assumption | C6: Value | I6: Source
B8: Model information
B9: As-of date (last full month of data) | C9: 46022 | I9: Monthly P&L to 2025-12; fixed by the bot, never TODAY()
B10: First data month | C10: 44927 | I10: First month of the Monthly P&L grid
B11: Source granularity | C11: Monthly | I11: Monthly when the books give 12 or more contiguous months
B12: Books basis | C12: Accrual | I12: Per the source report basis
B13: LTM end month | C13: =EOMONTH($C$9,0) -> 46022 | I13: Derived: EOMONTH(AsOfDate, 0)
B14: Fiscal year-end month (1-12) | C14: 12 | I14: Request list fiscal_year_end
B15: Latest full fiscal year | C15: =YEAR($C$9)+IF(MONTH($C$9)>$C$14,1,0)-IF(MONTH($C$9)=$C$14,0,1) -> 2025 | I15: Derived from the as-of date and fiscal year-end
B16: Units on analysis tabs | C16: $000s | I16: Databook divides raw dollars by 1,000
B17: Customer term | C17: Customer | I17: One term per deal, on every tab and in the CIM
B18: Main Street mode (1 = yes) | C18: 1 | I18: Rule: PF Adj. EBITDA before the capital reserve $452,525 (PF Dec-25) < $1,000,000 (AMB threshold)
B19: Main Street threshold (PF Adj. EBITDA before reserve) | C19: 1000000 | I19: Reference: below $1.0M the bot sets Main Street mode above (SDE in the CIM, capital reserve deducted); change the mode cell to override
B20: Deal form | C20: Asset purchase | I20: Intake notes: the owner prefers an asset sale; the Main Street default agrees
B22: Owner compensation and capital reserve
B23: Owner replacement salary | C23: 95000 | I23: Request list owner_replacement_salary ($95,000); intake notes: $95,000
B24: Payroll taxes and benefits burden | C24: 0.15 | I24: AMB default 15% for payroll taxes and benefits; confirm with the Seller
B25: Market replacement compensation [S2] | C25: =$C$23*(1+$C$24) -> 109250 | I25: Salary × (1 + burden); deducted below SDE
B26: Capital reserve (maintenance capex) [S3] | C26: 66800 | I26: Three-year average of depreciation expense, FY2023–FY2025
B27: Capital reserve basis | C27: D&A proxy | I27: Form 4562 equipment placed in service, else the three-year average of D&A flagged as a proxy
B29: Projection drivers
B30: Driver | C30: FY2026E | D30: FY2027E | E30: FY2028E | F30: FY2029E | G30: FY2030E
B31: Revenue growth | C31: 0.124 | D31: 0.1005 | E31: 0.077 | F31: 0.0535 | G31: 0.03 | I31: FY2023–FY2025 revenue CAGR of 12.4% (capped 0–15%), fading to 3% by year 5. Illustrative; replace with seller guidance.
B32: Cost of goods sold, % of revenue | C32: 0.3811 | D32: 0.3811 | E32: 0.3811 | F32: 0.3811 | G32: 0.3811 | I32: FY2025 % of revenue (latest-year run-rate); see P&L Summary for the trend.
B33: Salaries, wages and benefits, % of revenue | C33: 0.2975 | D33: 0.2975 | E33: 0.2975 | F33: 0.2975 | G33: 0.2975 | I33: FY2025 % of revenue (latest-year run-rate); see P&L Summary for the trend.
B34: Owner / officer compensation ($) | C34: 200000 | D34: 200000 | E34: 200000 | F34: 200000 | G34: 200000 | I34: Held at FY2025 level; the ladder normalises it to the replacement cost.
B35: Rent and occupancy, % of revenue | C35: 0.0251 | D35: 0.0251 | E35: 0.0251 | F35: 0.0251 | G35: 0.0251 | I35: FY2025 % of revenue (latest-year run-rate); see P&L Summary for the trend. Check the lease for scheduled escalations.
B36: Advertising and marketing, % of revenue | C36: 0.0262 | D36: 0.0262 | E36: 0.0262 | F36: 0.0262 | G36: 0.0262 | I36: FY2025 % of revenue (latest-year run-rate); see P&L Summary for the trend.
B37: Other operating expenses, % of revenue | C37: 0.1002 | D37: 0.1002 | E37: 0.1002 | F37: 0.1002 | G37: 0.1002 | I37: FY2025 % of revenue (latest-year run-rate); see P&L Summary for the trend.
B38: Depreciation and amortization, % of revenue | C38: 0.0238 | D38: 0.0238 | E38: 0.0238 | F38: 0.0238 | G38: 0.0238 | I38: FY2025 % of revenue (latest-year run-rate); see P&L Summary for the trend.
B39: Capital expenditures, % of revenue | C39: 0.0238 | D39: 0.0238 | E39: 0.0238 | F39: 0.0238 | G39: 0.0238 | I39: Set equal to D&A (maintenance capex). Raise for growth capex or a fleet refresh.
B40: Receivable days (DSO) | C40: 30 | D40: 30 | E40: 30 | F40: 30 | G40: 30 | I40: FY2025 receivables ÷ revenue × 365, per Balance Sheet.
B41: Inventory days (DIO) | C41: 30 | D41: 30 | E41: 30 | F41: 30 | G41: 30 | I41: FY2025 inventory ÷ COGS × 365, per Balance Sheet.
B42: Payable days (DPO) | C42: 37 | D42: 37 | E42: 37 | F42: 37 | G42: 37 | I42: FY2025 payables ÷ COGS × 365, per Balance Sheet.
... B46: Owner distributions, % of net income | C46: 0 | D46: 0 | E46: 0 | F46: 0 | G46: 0 | I46: Owner distributions as % of net income. 0% lets cash build (deals are cash-free, debt-free).
B48: Valuation multiples
B49: Multiple | C49: Low | D49: Mid | E49: High
...

Sheet P&L Summary
B2: =Cover!B24
B3: Historical P&L Summary ($000s) | N3: Print | O3: ='Contents'!$I$18
C5: Full Year | G5: YTD | J5: LTM | L5: PF | N5: PF vs. LTM | Q5: Basis
B6: Income Statement | C6: ="FY"&YEAR(C$59) -> FY2023 | D6: ="FY"&YEAR(D$59) -> FY2024 | E6: ="FY"&YEAR(E$59) -> FY2025 | G6: =TEXT(G$59,"mmm-yy") -> Dec-24 | H6: =TEXT(H$59,"mmm-yy") -> Dec-25 | J6: =TEXT(J$59,"mmm-yy") -> Dec-24 | K6: =TEXT(K$59,"mmm-yy") -> Dec-25 | L6: =TEXT(L$59,"mmm-yy") -> Dec-25 | N6: ($) | O6: (%) | Q6: Basis / notes
B8: Revenue
B9: Residential service and replacement | C9: =SUMIFS('Monthly P&L'!$Q$9:$AZ$9,'Monthly P&L'!$Q$6:$AZ$6,">="&C$58,'Monthly P&L'!$Q$6:$AZ$6,"<="&C$59) -> 1612.4 | D9: =SUMIFS('Monthly P&L'!$Q$9:$AZ$9,'Monthly P&L'!$Q$6:$AZ$6,">="&D$58,'Monthly P&L'!$Q$6:$AZ$6,"<="&D$59) -> 1788.9 | E9: =SUMIFS('Monthly P&L'!$Q$9:$AZ$9,'Monthly P&L'!$Q$6:$AZ$6,">="&E$58,'Monthly P&L'!$Q$6:$AZ$6,"<="&E$59) -> 1964.3 | G9: =SUMIFS('Monthly P&L'!$Q$9:$AZ$9,'Monthly P&L'!$Q$6:$AZ$6,">="&G$58,'Monthly P&L'!$Q$6:$AZ$6,"<="&G$59) -> 1788.9 | H9: =SUMIFS('Monthly P&L'!$Q$9:$AZ$9,'Monthly P&L'!$Q$6:$AZ$6,">="&H$58,'Monthly P&L'!$Q$6:$AZ$6,"<="&H$59) -> 1964.3 | J9: =SUMIFS('Monthly P&L'!$Q$9:$AZ$9,'Monthly P&L'!$Q$6:$AZ$6,">="&J$58,'Monthly P&L'!$Q$6:$AZ$6,"<="&J$59) -> 1788.9 | K9: =SUMIFS('Monthly P&L'!$Q$9:$AZ$9,'Monthly P&L'!$Q$6:$AZ$6,">="&K$58,'Monthly P&L'!$Q$6:$AZ$6,"<="&K$59) -> 1964.3 | L9: =SUMIFS('Monthly P&L'!$Q$9:$AZ$9,'Monthly P&L'!$Q$6:$AZ$6,">="&L$58,'Monthly P&L'!$Q$6:$AZ$6,"<="&L$59) -> 1964.3 | N9: =L9-K9 -> 0 | O9: =IFERROR(L9/K9-1,"n.a.") -> 0 | Q9: Account: Service Revenue - Residential
B10: Commercial service | C10: =SUMIFS('Monthly P&L'!$Q$10:$AZ$10,'Monthly P&L'!$Q$6:$AZ$6,">="&C$58,'Monthly P&L'!$Q$6:$AZ$6,"<="&C$59) -> 598.2 | D10: =SUMIFS('Monthly P&L'!$Q$10:$AZ$10,'Monthly P&L'!$Q$6:$AZ$6,">="&D$58,'Monthly P&L'!$Q$6:$AZ$6,"<="&D$59) -> 702.5 | E10: =SUMIFS('Monthly P&L'!$Q$10:$AZ$10,'Monthly P&L'!$Q$6:$AZ$6,">="&E$58,'Monthly P&L'!$Q$6:$AZ$6,"<="&E$59) -> 811.7 | G10: =SUMIFS('Monthly P&L'!$Q$10:$AZ$10,'Monthly P&L'!$Q$6:$AZ$6,">="&G$58,'Monthly P&L'!$Q$6:$AZ$6,"<="&G$59) -> 702.5 | H10: =SUMIFS('Monthly P&L'!$Q$10:$AZ$10,'Monthly P&L'!$Q$6:$AZ$6,">="&H$58,'Monthly P&L'!$Q$6:$AZ$6,"<="&H$59) -> 811.7 | J10: =SUMIFS('Monthly P&L'!$Q$10:$AZ$10,'Monthly P&L'!$Q$6:$AZ$6,">="&J$58,'Monthly P&L'!$Q$6:$AZ$6,"<="&J$59) -> 702.5 | K10: =SUMIFS('Monthly P&L'!$Q$10:$AZ$10,'Monthly P&L'!$Q$6:$AZ$6,">="&K$58,'Monthly P&L'!$Q$6:$AZ$6,"<="&K$59) -> 811.7 | L10: =SUMIFS('Monthly P&L'!$Q$10:$AZ$10,'Monthly P&L'!$Q$6:$AZ$6,">="&L$58,'Monthly P&L'!$Q$6:$AZ$6,"<="&L$59) -> 811.7 | N10: =L10-K10 -> 0 | O10: =IFERROR(L10/K10-1,"n.a.") -> 0 | Q10: Account: Service Revenue - Commercial
B11: Maintenance agreements | C11: =SUMIFS('Monthly P&L'!$Q$11:$AZ$11,'Monthly P&L'!$Q$6:$AZ$6,">="&C$58,'Monthly P&L'!$Q$6:$AZ$6,"<="&C$59) -> 214.6 | D11: =SUMIFS('Monthly P&L'!$Q$11:$AZ$11,'Monthly P&L'!$Q$6:$AZ$6,">="&D$58,'Monthly P&L'!$Q$6:$AZ$6,"<="&D$59) -> 248.3 | E11: =SUMIFS('Monthly P&L'!$Q$11:$AZ$11,'Monthly P&L'!$Q$6:$AZ$6,">="&E$58,'Monthly P&L'!$Q$6:$AZ$6,"<="&E$59) -> 289.4 | G11: =SUMIFS('Monthly P&L'!$Q$11:$AZ$11,'Monthly P&L'!$Q$6:$AZ$6,">="&G$58,'Monthly P&L'!$Q$6:$AZ$6,"<="&G$59) -> 248.3 | H11: =SUMIFS('Monthly P&L'!$Q$11:$AZ$11,'Monthly P&L'!$Q$6:$AZ$6,">="&H$58,'Monthly P&L'!$Q$6:$AZ$6,"<="&H$59) -> 289.4 | J11: =SUMIFS('Monthly P&L'!$Q$11:$AZ$11,'Monthly P&L'!$Q$6:$AZ$6,">="&J$58,'Monthly P&L'!$Q$6:$AZ$6,"<="&J$59) -> 248.3 | K11: =SUMIFS('Monthly P&L'!$Q$11:$AZ$11,'Monthly P&L'!$Q$6:$AZ$6,">="&K$58,'Monthly P&L'!$Q$6:$AZ$6,"<="&K$59) -> 289.4 | L11: =SUMIFS('Monthly P&L'!$Q$11:$AZ$11,'Monthly P&L'!$Q$6:$AZ$6,">="&L$58,'Monthly P&L'!$Q$6:$AZ$6,"<="&L$59) -> 289.4 | N11: =L11-K11 -> 0 | O11: =IFERROR(L11/K11-1,"n.a.") -> 0 | Q11: Account: Maintenance Agreements
B12: Less: discounts and refunds | C12: =SUMIFS('Monthly P&L'!$Q$12:$AZ$12,'Monthly P&L'!$Q$6:$AZ$6,">="&C$58,'Monthly P&L'!$Q$6:$AZ$6,"<="&C$59) -> -18.4 | D12: =SUMIFS('Monthly P&L'!$Q$12:$AZ$12,'Monthly P&L'!$Q$6:$AZ$6,">="&D$58,'Monthly P&L'!$Q$6:$AZ$6,"<="&D$59) -> -21.1 | E12: =SUMIFS('Monthly P&L'!$Q$12:$AZ$12,'Monthly P&L'!$Q$6:$AZ$6,">="&E$58,'Monthly P&L'!$Q$6:$AZ$6,"<="&E$59) -> -24.6 | G12: =SUMIFS('Monthly P&L'!$Q$12:$AZ$12,'Monthly P&L'!$Q$6:$AZ$6,">="&G$58,'Monthly P&L'!$Q$6:$AZ$6,"<="&G$59) -> -21.1 | H12: =SUMIFS('Monthly P&L'!$Q$12:$AZ$12,'Monthly P&L'!$Q$6:$AZ$6,">="&H$58,'Monthly P&L'!$Q$6:$AZ$6,"<="&H$59) -> -24.6 | J12: =SUMIFS('Monthly P&L'!$Q$12:$AZ$12,'Monthly P&L'!$Q$6:$AZ$6,">="&J$58,'Monthly P&L'!$Q$6:$AZ$6,"<="&J$59) -> -21.1 | K12: =SUMIFS('Monthly P&L'!$Q$12:$AZ$12,'Monthly P&L'!$Q$6:$AZ$6,">="&K$58,'Monthly P&L'!$Q$6:$AZ$6,"<="&K$59) -> -24.6 | L12: =SUMIFS('Monthly P&L'!$Q$12:$AZ$12,'Monthly P&L'!$Q$6:$AZ$6,">="&L$58,'Monthly P&L'!$Q$6:$AZ$6,"<="&L$59) -> -24.6 | N12: =L12-K12 -> 0 | O12: =IFERROR(L12/K12-1,"n.a.") -> 0 | Q12: Account: Discounts Given
B14: Total Revenue | C14: =SUM(C9:C12) -> 2406.8 | D14: =SUM(D9:D12) -> 2718.6 | E14: =SUM(E9:E12) -> 3040.8 | G14: =SUM(G9:G12) -> 2718.6 | H14: =SUM(H9:H12) -> 3040.8 | J14: =SUM(J9:J12) -> 2718.6 | K14: =SUM(K9:K12) -> 3040.8 | L14: =SUM(L9:L12) -> 3040.8 | N14: =L14-K14 -> 0 | O14: =IFERROR(L14/K14-1,"n.a.") -> 0 | Q14: Sum of the revenue lines
B15: % Growth | C15: n.a. | D15: =IFERROR(D14/C14-1,"n.a.") -> 0.12954961 | E15: =IFERROR(E14/D14-1,"n.a.") -> 0.11851688 | G15: =IFERROR(G14/SUMIFS('Monthly P&L'!$Q$14:$AZ$14,'Monthly P&L'!$Q$6:$AZ$6,">="&(EOMONTH(G$58,-13)+1),'Monthly P&L'!$Q$6:$AZ$6,"<="&EOMONTH(G$59,-12))-1,"n.a.") -> 0.12954961 | H15: =IFERROR(H14/G14-1,"n.a.") -> 0.11851688 | J15: =IFERROR(J14/SUMIFS('Monthly P&L'!$Q$14:$AZ$14,'Monthly P&L'!$Q$6:$AZ$6,">="&(EOMONTH(J$58,-13)+1),'Monthly P&L'!$Q$6:$AZ$6,"<="&EOMONTH(J$59,-12))-1,"n.a.") -> 0.12954961 | K15: =IFERROR(K14/J14-1,"n.a.") -> 0.11851688 | L15: n.a. | Q15: Against the same window a year earlier
B16: Cost of Revenue | C16: =SUMIFS('Monthly P&L'!$Q$16:$AZ$16,'Monthly P&L'!$Q$6:$AZ$6,">="&C$58,'Monthly P&L'!$Q$6:$AZ$6,"<="&C$59) -> 938.8 | D16: =SUMIFS('Monthly P&L'!$Q$16:$AZ$16,'Monthly P&L'!$Q$6:$AZ$6,">="&D$58,'Monthly P&L'!$Q$6:$AZ$6,"<="&D$59) -> 1047.9 | E16: =SUMIFS('Monthly P&L'!$Q$16:$AZ$16,'Monthly P&L'!$Q$6:$AZ$6,">="&E$58,'Monthly P&L'!$Q$6:$AZ$6,"<="&E$59) -> 1158.9 | G16: =SUMIFS('Monthly P&L'!$Q$16:$AZ$16,'Monthly P&L'!$Q$6:$AZ$6,">="&G$58,'Monthly P&L'!$Q$6:$AZ$6,"<="&G$59) -> 1047.9 | H16: =SUMIFS('Monthly P&L'!$Q$16:$AZ$16,'Monthly P&L'!$Q$6:$AZ$6,">="&H$58,'Monthly P&L'!$Q$6:$AZ$6,"<="&H$59) -> 1158.9 | J16: =SUMIFS('Monthly P&L'!$Q$16:$AZ$16,'Monthly P&L'!$Q$6:$AZ$6,">="&J$58,'Monthly P&L'!$Q$6:$AZ$6,"<="&J$59) -> 1047.9 | K16: =SUMIFS('Monthly P&L'!$Q$16:$AZ$16,'Monthly P&L'!$Q$6:$AZ$6,">="&K$58,'Monthly P&L'!$Q$6:$AZ$6,"<="&K$59) -> 1158.9 | L16: =SUMIFS('Monthly P&L'!$Q$16:$AZ$16,'Monthly P&L'!$Q$6:$AZ$6,">="&L$58,'Monthly P&L'!$Q$6:$AZ$6,"<="&L$59) -> 1158.9 | N16: =L16-K16 -> 0 | O16: =IFERROR(L16/K16-1,"n.a.") -> 0 | Q16: Accounts: Equipment & Materials and 1 more (Databook)
B18: Gross Profit | C18: =C14-C16 -> 1468 | D18: =D14-D16 -> 1670.7 | E18: =E14-E16 -> 1881.9 | G18: =G14-G16 -> 1670.7 | H18: =H14-H16 -> 1881.9 | J18: =J14-J16 -> 1670.7 | K18: =K14-K16 -> 1881.9 | L18: =L14-L16 -> 1881.9 | N18: =L18-K18 -> 0 | O18: =IFERROR(L18/K18-1,"n.a.") -> 0 | Q18: Total revenue less cost of revenue
B19: % Margin | C19: =IFERROR(C18/C14,"n.m.") -> 0.60993851 | D19: =IFERROR(D18/D14,"n.m.") -> 0.61454425 | E19: =IFERROR(E18/E14,"n.m.") -> 0.61888319 | G19: =IFERROR(G18/G14,"n.m.") -> 0.61454425 | H19: =IFERROR(H18/H14,"n.m.") -> 0.61888319 | J19: =IFERROR(J18/J14,"n.m.") -> 0.61454425 | K19: =IFERROR(K18/K14,"n.m.") -> 0.61888319 | L19: =IFERROR(L18/L14,"n.m.") -> 0.61888319 | Q19: Of total revenue
B21: Operating Expenses
B22: Salaries, Wages and Benefits | C22: =SUMIFS('Monthly P&L'!$Q$22:$AZ$22,'Monthly P&L'!$Q$6:$AZ$6,">="&C$58,'Monthly P&L'!$Q$6:$AZ$6,"<="&C$59) -> 730.6 | D22: =SUMIFS('Monthly P&L'!$Q$22:$AZ$22,'Monthly P&L'!$Q$6:$AZ$6,">="&D$58,'Monthly P&L'!$Q$6:$AZ$6,"<="&D$59) -> 818.1 | E22: =SUMIFS('Monthly P&L'!$Q$22:$AZ$22,'Monthly P&L'!$Q$6:$AZ$6,">="&E$58,'Monthly P&L'!$Q$6:$AZ$6,"<="&E$59) -> 904.7 | G22: =SUMIFS('Monthly P&L'!$Q$22:$AZ$22,'Monthly P&L'!$Q$6:$AZ$6,">="&G$58,'Monthly P&L'!$Q$6:$AZ$6,"<="&G$59) -> 818.1 | H22: =SUMIFS('Monthly P&L'!$Q$22:$AZ$22,'Monthly P&L'!$Q$6:$AZ$6,">="&H$58,'Monthly P&L'!$Q$6:$AZ$6,"<="&H$59) -> 904.7 | J22: =SUMIFS('Monthly P&L'!$Q$22:$AZ$22,'Monthly P&L'!$Q$6:$AZ$6,">="&J$58,'Monthly P&L'!$Q$6:$AZ$6,"<="&J$59) -> 818.1 | K22: =SUMIFS('Monthly P&L'!$Q$22:$AZ$22,'Monthly P&L'!$Q$6:$AZ$6,">="&K$58,'Monthly P&L'!$Q$6:$AZ$6,"<="&K$59) -> 904.7 | L22: =SUMIFS('Monthly P&L'!$Q$22:$AZ$22,'Monthly P&L'!$Q$6:$AZ$6,">="&L$58,'Monthly P&L'!$Q$6:$AZ$6,"<="&L$59) -> 904.7 | N22: =L22-K22 -> 0 | O22: =IFERROR(L22/K22-1,"n.a.") -> 0 | Q22: Accounts: Technician Wages, Office Wages and 2 more (Databook)
B23: Owner / Officer Compensation | C23: =SUMIFS('Monthly P&L'!$Q$23:$AZ$23,'Monthly P&L'!$Q$6:$AZ$6,">="&C$58,'Monthly P&L'!$Q$6:$AZ$6,"<="&C$59) -> 180 | D23: =SUMIFS('Monthly P&L'!$Q$23:$AZ$23,'Monthly P&L'!$Q$6:$AZ$6,">="&D$58,'Monthly P&L'!$Q$6:$AZ$6,"<="&D$59) -> 190 | E23: =SUMIFS('Monthly P&L'!$Q$23:$AZ$23,'Monthly P&L'!$Q$6:$AZ$6,">="&E$58,'Monthly P&L'!$Q$6:$AZ$6,"<="&E$59) -> 200 | G23: =SUMIFS('Monthly P&L'!$Q$23:$AZ$23,'Monthly P&L'!$Q$6:$AZ$6,">="&G$58,'Monthly P&L'!$Q$6:$AZ$6,"<="&G$59) -> 190 | H23: =SUMIFS('Monthly P&L'!$Q$23:$AZ$23,'Monthly P&L'!$Q$6:$AZ$6,">="&H$58,'Monthly P&L'!$Q$6:$AZ$6,"<="&H$59) -> 200 | J23: =SUMIFS('Monthly P&L'!$Q$23:$AZ$23,'Monthly P&L'!$Q$6:$AZ$6,">="&J$58,'Monthly P&L'!$Q$6:$AZ$6,"<="&J$59) -> 190 | K23: =SUMIFS('Monthly P&L'!$Q$23:$AZ$23,'Monthly P&L'!$Q$6:$AZ$6,">="&K$58,'Monthly P&L'!$Q$6:$AZ$6,"<="&K$59) -> 200 | L23: =SUMIFS('Monthly P&L'!$Q$23:$AZ$23,'Monthly P&L'!$Q$6:$AZ$6,">="&L$58,'Monthly P&L'!$Q$6:$AZ$6,"<="&L$59) -> 200 | N23: =L23-K23 -> 0 | O23: =IFERROR(L23/K23-1,"n.a.") -> 0 | Q23: Account: Officer Compensation
B24: Rent and Occupancy | C24: =SUMIFS('Monthly P&L'!$Q$24:$AZ$24,'Monthly P&L'!$Q$6:$AZ$6,">="&C$58,'Monthly P&L'!$Q$6:$AZ$6,"<="&C$59) -> 72 | D24: =SUMIFS('Monthly P&L'!$Q$24:$AZ$24,'Monthly P&L'!$Q$6:$AZ$6,">="&D$58,'Monthly P&L'!$Q$6:$AZ$6,"<="&D$59) -> 74.16 | E24: =SUMIFS('Monthly P&L'!$Q$24:$AZ$24,'Monthly P&L'!$Q$6:$AZ$6,">="&E$58,'Monthly P&L'!$Q$6:$AZ$6,"<="&E$59) -> 76.385 | G24: =SUMIFS('Monthly P&L'!$Q$24:$AZ$24,'Monthly P&L'!$Q$6:$AZ$6,">="&G$58,'Monthly P&L'!$Q$6:$AZ$6,"<="&G$59) -> 74.16 | H24: =SUMIFS('Monthly P&L'!$Q$24:$AZ$24,'Monthly P&L'!$Q$6:$AZ$6,">="&H$58,'Monthly P&L'!$Q$6:$AZ$6,"<="&H$59) -> 76.385 | J24: =SUMIFS('Monthly P&L'!$Q$24:$AZ$24,'Monthly P&L'!$Q$6:$AZ$6,">="&J$58,'Monthly P&L'!$Q$6:$AZ$6,"<="&J$59) -> 74.16 | K24: =SUMIFS('Monthly P&L'!$Q$24:$AZ$24,'Monthly P&L'!$Q$6:$AZ$6,">="&K$58,'Monthly P&L'!$Q$6:$AZ$6,"<="&K$59) -> 76.385 | L24: =SUMIFS('Monthly P&L'!$Q$24:$AZ$24,'Monthly P&L'!$Q$6:$AZ$6,">="&L$58,'Monthly P&L'!$Q$6:$AZ$6,"<="&L$59) -> 76.385 | N24: =L24-K24 -> 0 | O24: =IFERROR(L24/K24-1,"n.a.") -> 0 | Q24: Account: Rent - Shop & Office
B25: Advertising and Marketing | C25: =SUMIFS('Monthly P&L'!$Q$25:$AZ$25,'Monthly P&L'!$Q$6:$AZ$6,">="&C$58,'Monthly P&L'!$Q$6:$AZ$6,"<="&C$59) -> 64.8 | D25: =SUMIFS('Monthly P&L'!$Q$25:$AZ$25,'Monthly P&L'!$Q$6:$AZ$6,">="&D$58,'Monthly P&L'!$Q$6:$AZ$6,"<="&D$59) -> 71.2 | E25: =SUMIFS('Monthly P&L'!$Q$25:$AZ$25,'Monthly P&L'!$Q$6:$AZ$6,">="&E$58,'Monthly P&L'!$Q$6:$AZ$6,"<="&E$59) -> 79.6 | G25: =SUMIFS('Monthly P&L'!$Q$25:$AZ$25,'Monthly P&L'!$Q$6:$AZ$6,">="&G$58,'Monthly P&L'!$Q$6:$AZ$6,"<="&G$59) -> 71.2 | H25: =SUMIFS('Monthly P&L'!$Q$25:$AZ$25,'Monthly P&L'!$Q$6:$AZ$6,">="&H$58,'Monthly P&L'!$Q$6:$AZ$6,"<="&H$59) -> 79.6 | J25: =SUMIFS('Monthly P&L'!$Q$25:$AZ$25,'Monthly P&L'!$Q$6:$AZ$6,">="&J$58,'Monthly P&L'!$Q$6:$AZ$6,"<="&J$59) -> 71.2 | K25: =SUMIFS('Monthly P&L'!$Q$25:$AZ$25,'Monthly P&L'!$Q$6:$AZ$6,">="&K$58,'Monthly P&L'!$Q$6:$AZ$6,"<="&K$59) -> 79.6 | L25: =SUMIFS('Monthly P&L'!$Q$25:$AZ$25,'Monthly P&L'!$Q$6:$AZ$6,">="&L$58,'Monthly P&L'!$Q$6:$AZ$6,"<="&L$59) -> 79.6 | N25: =L25-K25 -> 0 | O25: =IFERROR(L25/K25-1,"n.a.") -> 0 | Q25: Account: Advertising & Marketing
B26: Other Operating Expenses | C26: =SUMIFS('Monthly P&L'!$Q$26:$AZ$26,'Monthly P&L'!$Q$6:$AZ$6,">="&C$58,'Monthly P&L'!$Q$6:$AZ$6,"<="&C$59) -> 263.6 | D26: =SUMIFS('Monthly P&L'!$Q$26:$AZ$26,'Monthly P&L'!$Q$6:$AZ$6,">="&D$58,'Monthly P&L'!$Q$6:$AZ$6,"<="&D$59) -> 305 | E26: =SUMIFS('Monthly P&L'!$Q$26:$AZ$26,'Monthly P&L'!$Q$6:$AZ$6,">="&E$58,'Monthly P&L'!$Q$6:$AZ$6,"<="&E$59) -> 304.8 | G26: =SUMIFS('Monthly P&L'!$Q$26:$AZ$26,'Monthly P&L'!$Q$6:$AZ$6,">="&G$58,'Monthly P&L'!$Q$6:$AZ$6,"<="&G$59) -> 305 | H26: =SUMIFS('Monthly P&L'!$Q$26:$AZ$26,'Monthly P&L'!$Q$6:$AZ$6,">="&H$58,'Monthly P&L'!$Q$6:$AZ$6,"<="&H$59) -> 304.8 | J26: =SUMIFS('Monthly P&L'!$Q$26:$AZ$26,'Monthly P&L'!$Q$6:$AZ$6,">="&J$58,'Monthly P&L'!$Q$6:$AZ$6,"<="&J$59) -> 305 | K26: =SUMIFS('Monthly P&L'!$Q$26:$AZ$26,'Monthly P&L'!$Q$6:$AZ$6,">="&K$58,'Monthly P&L'!$Q$6:$AZ$6,"<="&K$59) -> 304.8 | L26: =SUMIFS('Monthly P&L'!$Q$26:$AZ$26,'Monthly P&L'!$Q$6:$AZ$6,">="&L$58,'Monthly P&L'!$Q$6:$AZ$6,"<="&L$59) -> 304.8 | N26: =L26-K26 -> 0 | O26: =IFERROR(L26/K26-1,"n.a.") -> 0 | Q26: Accounts: Charitable Contributions, Fuel and 8 more (Databook)
B28: Total Operating Expenses | C28: =SUM(C22:C26) -> 1311 | D28: =SUM(D22:D26) -> 1458.46 | E28: =SUM(E22:E26) -> 1565.485 | G28: =SUM(G22:G26) -> 1458.46 | H28: =SUM(H22:H26) -> 1565.485 | J28: =SUM(J22:J26) -> 1458.46 | K28: =SUM(K22:K26) -> 1565.485 | L28: =SUM(L22:L26) -> 1565.485 | N28: =L28-K28 -> 0 | O28: =IFERROR(L28/K28-1,"n.a.") -> 0 | Q28: Sum of the operating expense lines
B29: Other Income | C29: =SUMIFS('Monthly P&L'!$Q$29:$AZ$29,'Monthly P&L'!$Q$6:$AZ$6,">="&C$58,'Monthly P&L'!$Q$6:$AZ$6,"<="&C$59) -> 1.2 | D29: =SUMIFS('Monthly P&L'!$Q$29:$AZ$29,'Monthly P&L'!$Q$6:$AZ$6,">="&D$58,'Monthly P&L'!$Q$6:$AZ$6,"<="&D$59) -> 2.4 | E29: =SUMIFS('Monthly P&L'!$Q$29:$AZ$29,'Monthly P&L'!$Q$6:$AZ$6,">="&E$58,'Monthly P&L'!$Q$6:$AZ$6,"<="&E$59) -> 3.1 | G29: =SUMIFS('Monthly P&L'!$Q$29:$AZ$29,'Monthly P&L'!$Q$6:$AZ$6,">="&G$58,'Monthly P&L'!$Q$6:$AZ$6,"<="&G$59) -> 2.4 | H29: =SUMIFS('Monthly P&L'!$Q$29:$AZ$29,'Monthly P&L'!$Q$6:$AZ$6,">="&H$58,'Monthly P&L'!$Q$6:$AZ$6,"<="&H$59) -> 3.1 | J29: =SUMIFS('Monthly P&L'!$Q$29:$AZ$29,'Monthly P&L'!$Q$6:$AZ$6,">="&J$58,'Monthly P&L'!$Q$6:$AZ$6,"<="&J$59) -> 2.4 | K29: =SUMIFS('Monthly P&L'!$Q$29:$AZ$29,'Monthly P&L'!$Q$6:$AZ$6,">="&K$58,'Monthly P&L'!$Q$6:$AZ$6,"<="&K$59) -> 3.1 | L29: =SUMIFS('Monthly P&L'!$Q$29:$AZ$29,'Monthly P&L'!$Q$6:$AZ$6,">="&L$58,'Monthly P&L'!$Q$6:$AZ$6,"<="&L$59) -> 3.1 | N29: =L29-K29 -> 0 | O29: =IFERROR(L29/K29-1,"n.a.") -> 0 | Q29: Account: Interest Income
B30: Other Expense (non-operating) | C30: =SUMIFS('Monthly P&L'!$Q$30:$AZ$30,'Monthly P&L'!$Q$6:$AZ$6,">="&C$58,'Monthly P&L'!$Q$6:$AZ$6,"<="&C$59) -> 0 | D30: =SUMIFS('Monthly P&L'!$Q$30:$AZ$30,'Monthly P&L'!$Q$6:$AZ$6,">="&D$58,'Monthly P&L'!$Q$6:$AZ$6,"<="&D$59) -> 0 | E30: =SUMIFS('Monthly P&L'!$Q$30:$AZ$30,'Monthly P&L'!$Q$6:$AZ$6,">="&E$58,'Monthly P&L'!$Q$6:$AZ$6,"<="&E$59) -> 0 | G30: =SUMIFS('Monthly P&L'!$Q$30:$AZ$30,'Monthly P&L'!$Q$6:$AZ$6,">="&G$58,'Monthly P&L'!$Q$6:$AZ$6,"<="&G$59) -> 0 | H30: =SUMIFS('Monthly P&L'!$Q$30:$AZ$30,'Monthly P&L'!$Q$6:$AZ$6,">="&H$58,'Monthly P&L'!$Q$6:$AZ$6,"<="&H$59) -> 0 | J30: =SUMIFS('Monthly P&L'!$Q$30:$AZ$30,'Monthly P&L'!$Q$6:$AZ$6,">="&J$58,'Monthly P&L'!$Q$6:$AZ$6,"<="&J$59) -> 0 | K30: =SUMIFS('Monthly P&L'!$Q$30:$AZ$30,'Monthly P&L'!$Q$6:$AZ$6,">="&K$58,'Monthly P&L'!$Q$6:$AZ$6,"<="&K$59) -> 0 | L30: =SUMIFS('Monthly P&L'!$Q$30:$AZ$30,'Monthly P&L'!$Q$6:$AZ$6,">="&L$58,'Monthly P&L'!$Q$6:$AZ$6,"<="&L$59) -> 0 | N30: =L30-K30 -> 0 | O30: =IFERROR(L30/K30-1,"n.a.") -> n.a.
B32: Reported EBITDA | C32: =C18-C28+C29-C30 -> 158.2 | D32: =D18-D28+D29-D30 -> 214.64 | E32: =E18-E28+E29-E30 -> 319.515 | G32: =G18-G28+G29-G30 -> 214.64 | H32: =H18-H28+H29-H30 -> 319.515 | J32: =J18-J28+J29-J30 -> 214.64 | K32: =K18-K28+K29-K30 -> 319.515 | L32: =L18-L28+L29-L30 -> 319.515 | N32: =L32-K32 -> 0 | O32: =IFERROR(L32/K32-1,"n.a.") -> 0 | Q32: Gross profit less opex, plus other income less other expense
B33: % Margin | C33: =IFERROR(C32/C14,"n.m.") -> 0.06573043 | D33: =IFERROR(D32/D14,"n.m.") -> 0.078952402 | E33: =IFERROR(E32/E14,"n.m.") -> 0.10507597 | G33: =IFERROR(G32/G14,"n.m.") -> 0.078952402 | H33: =IFERROR(H32/H14,"n.m.") -> 0.10507597 | J33: =IFERROR(J32/J14,"n.m.") -> 0.078952402 | K33: =IFERROR(K32/K14,"n.m.") -> 0.10507597 | L33: =IFERROR(L32/L14,"n.m.") -> 0.10507597 | Q33: Of total revenue
B35: Depreciation and Amortization | C35: =SUMIFS('Monthly P&L'!$Q$35:$AZ$35,'Monthly P&L'!$Q$6:$AZ$6,">="&C$58,'Monthly P&L'!$Q$6:$AZ$6,"<="&C$59) -> 61.2 | D35: =SUMIFS('Monthly P&L'!$Q$35:$AZ$35,'Monthly P&L'!$Q$6:$AZ$6,">="&D$58,'Monthly P&L'!$Q$6:$AZ$6,"<="&D$59) -> 66.8 | E35: =SUMIFS('Monthly P&L'!$Q$35:$AZ$35,'Monthly P&L'!$Q$6:$AZ$6,">="&E$58,'Monthly P&L'!$Q$6:$AZ$6,"<="&E$59) -> 72.4 | G35: =SUMIFS('Monthly P&L'!$Q$35:$AZ$35,'Monthly P&L'!$Q$6:$AZ$6,">="&G$58,'Monthly P&L'!$Q$6:$AZ$6,"<="&G$59) -> 66.8 | H35: =SUMIFS('Monthly P&L'!$Q$35:$AZ$35,'Monthly P&L'!$Q$6:$AZ$6,">="&H$58,'Monthly P&L'!$Q$6:$AZ$6,"<="&H$59) -> 72.4 | J35: =SUMIFS('Monthly P&L'!$Q$35:$AZ$35,'Monthly P&L'!$Q$6:$AZ$6,">="&J$58,'Monthly P&L'!$Q$6:$AZ$6,"<="&J$59) -> 66.8 | K35: =SUMIFS('Monthly P&L'!$Q$35:$AZ$35,'Monthly P&L'!$Q$6:$AZ$6,">="&K$58,'Monthly P&L'!$Q$6:$AZ$6,"<="&K$59) -> 72.4 | L35: =SUMIFS('Monthly P&L'!$Q$35:$AZ$35,'Monthly P&L'!$Q$6:$AZ$6,">="&L$58,'Monthly P&L'!$Q$6:$AZ$6,"<="&L$59) -> 72.4 | N35: =L35-K35 -> 0 | O35: =IFERROR(L35/K35-1,"n.a.") -> 0 | Q35: Account: Depreciation Expense
B37: EBIT | C37: =C32-C35 -> 97 | D37: =D32-D35 -> 147.84 | E37: =E32-E35 -> 247.115 | G37: =G32-G35 -> 147.84 | H37: =H32-H35 -> 247.115 | J37: =J32-J35 -> 147.84 | K37: =K32-K35 -> 247.115 | L37: =L32-L35 -> 247.115 | N37: =L37-K37 -> 0 | O37: =IFERROR(L37/K37-1,"n.a.") -> 0 | Q37: Reported EBITDA less depreciation and amortization
B38: Interest Expense | C38: =SUMIFS('Monthly P&L'!$Q$38:$AZ$38,'Monthly P&L'!$Q$6:$AZ$6,">="&C$58,'Monthly P&L'!$Q$6:$AZ$6,"<="&C$59) -> 22.4 | D38: =SUMIFS('Monthly P&L'!$Q$38:$AZ$38,'Monthly P&L'!$Q$6:$AZ$6,">="&D$58,'Monthly P&L'!$Q$6:$AZ$6,"<="&D$59) -> 18.6 | E38: =SUMIFS('Monthly P&L'!$Q$38:$AZ$38,'Monthly P&L'!$Q$6:$AZ$6,">="&E$58,'Monthly P&L'!$Q$6:$AZ$6,"<="&E$59) -> 14.3 | G38: =SUMIFS('Monthly P&L'!$Q$38:$AZ$38,'Monthly P&L'!$Q$6:$AZ$6,">="&G$58,'Monthly P&L'!$Q$6:$AZ$6,"<="&G$59) -> 18.6 | H38: =SUMIFS('Monthly P&L'!$Q$38:$AZ$38,'Monthly P&L'!$Q$6:$AZ$6,">="&H$58,'Monthly P&L'!$Q$6:$AZ$6,"<="&H$59) -> 14.3 | J38: =SUMIFS('Monthly P&L'!$Q$38:$AZ$38,'Monthly P&L'!$Q$6:$AZ$6,">="&J$58,'Monthly P&L'!$Q$6:$AZ$6,"<="&J$59) -> 18.6 | K38: =SUMIFS('Monthly P&L'!$Q$38:$AZ$38,'Monthly P&L'!$Q$6:$AZ$6,">="&K$58,'Monthly P&L'!$Q$6:$AZ$6,"<="&K$59) -> 14.3 | L38: =SUMIFS('Monthly P&L'!$Q$38:$AZ$38,'Monthly P&L'!$Q$6:$AZ$6,">="&L$58,'Monthly P&L'!$Q$6:$AZ$6,"<="&L$59) -> 14.3 | N38: =L38-K38 -> 0 | O38: =IFERROR(L38/K38-1,"n.a.") -> 0 | Q38: Account: Interest Expense
B40: Pre-Tax Income | C40: =C37-C38 -> 74.6 | D40: =D37-D38 -> 129.24 | E40: =E37-E38 -> 232.815 | G40: =G37-G38 -> 129.24 | H40: =H37-H38 -> 232.815 | J40: =J37-J38 -> 129.24 | K40: =K37-K38 -> 232.815 | L40: =L37-L38 -> 232.815 | N40: =L40-K40 -> 0 | O40: =IFERROR(L40/K40-1,"n.a.") -> 0 | Q40: EBIT less interest expense
B41: Income Taxes | C41: =SUMIFS('Monthly P&L'!$Q$41:$AZ$41,'Monthly P&L'!$Q$6:$AZ$6,">="&C$58,'Monthly P&L'!$Q$6:$AZ$6,"<="&C$59) -> 0 | D41: =SUMIFS('Monthly P&L'!$Q$41:$AZ$41,'Monthly P&L'!$Q$6:$AZ$6,">="&D$58,'Monthly P&L'!$Q$6:$AZ$6,"<="&D$59) -> 0 | E41: =SUMIFS('Monthly P&L'!$Q$41:$AZ$41,'Monthly P&L'!$Q$6:$AZ$6,">="&E$58,'Monthly P&L'!$Q$6:$AZ$6,"<="&E$59) -> 0 | G41: =SUMIFS('Monthly P&L'!$Q$41:$AZ$41,'Monthly P&L'!$Q$6:$AZ$6,">="&G$58,'Monthly P&L'!$Q$6:$AZ$6,"<="&G$59) -> 0 | H41: =SUMIFS('Monthly P&L'!$Q$41:$AZ$41,'Monthly P&L'!$Q$6:$AZ$6,">="&H$58,'Monthly P&L'!$Q$6:$AZ$6,"<="&H$59) -> 0 | J41: =SUMIFS('Monthly P&L'!$Q$41:$AZ$41,'Monthly P&L'!$Q$6:$AZ$6,">="&J$58,'Monthly P&L'!$Q$6:$AZ$6,"<="&J$59) -> 0 | K41: =SUMIFS('Monthly P&L'!$Q$41:$AZ$41,'Monthly P&L'!$Q$6:$AZ$6,">="&K$58,'Monthly P&L'!$Q$6:$AZ$6,"<="&K$59) -> 0 | L41: =SUMIFS('Monthly P&L'!$Q$41:$AZ$41,'Monthly P&L'!$Q$6:$AZ$6,">="&L$58,'Monthly P&L'!$Q$6:$AZ$6,"<="&L$59) -> 0 | N41: =L41-K41 -> 0 | O41: =IFERROR(L41/K41-1,"n.a.") -> n.a.
B43: Net Income | C43: =C40-C41 -> 74.6 | D43: =D40-D41 -> 129.24 | E43: =E40-E41 -> 232.815 | G43: =G40-G41 -> 129.24 | H43: =H40-H41 -> 232.815 | J43: =J40-J41 -> 129.24 | K43: =K40-K41 -> 232.815 | L43: =L40-L41 -> 232.815 | N43: =L43-K43 -> 0 | O43: =IFERROR(L43/K43-1,"n.a.") -> 0 | Q43: Pre-tax income less income taxes (C04 ties it to the grid)
B44: % Margin | C44: =IFERROR(C43/C14,"n.m.") -> 0.030995513 | D44: =IFERROR(D43/D14,"n.m.") -> 0.047539175 | E44: =IFERROR(E43/E14,"n.m.") -> 0.076563733 | G44: =IFERROR(G43/G14,"n.m.") -> 0.047539175 | H44: =IFERROR(H43/H14,"n.m.") -> 0.076563733 | J44: =IFERROR(J43/J14,"n.m.") -> 0.047539175 | K44: =IFERROR(K43/K14,"n.m.") -> 0.076563733 | L44: =IFERROR(L43/L14,"n.m.") -> 0.076563733 | Q44: Of total revenue
B46: Key Performance Indicators
B47: Customers, active at period end (#) | C47: =COUNTIFS('Raw - Customers'!$E:$E,"<="&C$59,'Raw - Customers'!$F:$F,"")+COUNTIFS('Raw - Customers'!$E:$E,"<="&C$59,'Raw - Customers'!$F:$F,">"&C$59)+COUNTIFS('Raw - Customers'!$E:$E,"",'Raw - Customers'!$I:$I,">0",'Raw - Customers'!$A:$A,"<>Residual") -> 44 | D47: =COUNTIFS('Raw - Customers'!$E:$E,"<="&D$59,'Raw - Customers'!$F:$F,"")+COUNTIFS('Raw - Customers'!$E:$E,"<="&D$59,'Raw - Customers'!$F:$F,">"&D$59)+COUNTIFS('Raw - Customers'!$E:$E,"",'Raw - Customers'!$J:$J,">0",'Raw - Customers'!$A:$A,"<>Residual") -> 49 | E47: =COUNTIFS('Raw - Customers'!$E:$E,"<="&E$59,'Raw - Customers'!$F:$F,"")+COUNTIFS('Raw - Customers'!$E:$E,"<="&E$59,'Raw - Customers'!$F:$F,">"&E$59)+COUNTIFS('Raw - Customers'!$E:$E,"",'Raw - Customers'!$K:$K,">0",'Raw - Customers'!$A:$A,"<>Residual") -> 52 | G47: =COUNTIFS('Raw - Customers'!$E:$E,"<="&G$59,'Raw - Customers'!$F:$F,"")+COUNTIFS('Raw - Customers'!$E:$E,"<="&G$59,'Raw - Customers'!$F:$F,">"&G$59)+COUNTIFS('Raw - Customers'!$E:$E,"",'Raw - Customers'!$J:$J,">0",'Raw - Customers'!$A:$A,"<>Residual") -> 49 | H47: =COUNTIFS('Raw - Customers'!$E:$E,"<="&H$59,'Raw - Customers'!$F:$F,"")+COUNTIFS('Raw - Customers'!$E:$E,"<="&H$59,'Raw - Customers'!$F:$F,">"&H$59)+COUNTIFS('Raw - Customers'!$E:$E,"",'Raw - Customers'!$K:$K,">0",'Raw - Customers'!$A:$A,"<>Residual") -> 52 | J47: =COUNTIFS('Raw - Customers'!$E:$E,"<="&J$59,'Raw - Customers'!$F:$F,"")+COUNTIFS('Raw - Customers'!$E:$E,"<="&J$59,'Raw - Customers'!$F:$F,">"&J$59)+COUNTIFS('Raw - Customers'!$E:$E,"",'Raw - Customers'!$J:$J,">0",'Raw - Customers'!$A:$A,"<>Residual") -> 49 | K47: =COUNTIFS('Raw - Customers'!$E:$E,"<="&K$59,'Raw - Customers'!$F:$F,"")+COUNTIFS('Raw - Customers'!$E:$E,"<="&K$59,'Raw - Customers'!$F:$F,">"&K$59)+COUNTIFS('Raw - Customers'!$E:$E,"",'Raw - Customers'!$K:$K,">0",'Raw - Customers'!$A:$A,"<>Residual") -> 52 | L47: =COUNTIFS('Raw - Customers'!$E:$E,"<="&L$59,'Raw - Customers'!$F:$F,"")+COUNTIFS('Raw - Customers'!$E:$E,"<="&L$59,'Raw - Customers'!$F:$F,">"&L$59)+COUNTIFS('Raw - Customers'!$E:$E,"",'Raw - Customers'!$K:$K,">0",'Raw - Customers'!$A:$A,"<>Residual") -> 52
B48: Revenue per listed customer ($) | C48: =IFERROR((SUMIFS('Raw - Customers'!$I:$I,'Raw - Customers'!$A:$A,"<>Residual")*C61+SUMIFS('Raw - Customers'!$J:$J,'Raw - Customers'!$A:$A,"<>Residual")*C62+SUMIFS('Raw - Customers'!$K:$K,'Raw - Customers'!$A:$A,"<>Residual")*C63)/C47,"n.a.") -> 13595.455 | D48: =IFERROR((SUMIFS('Raw - Customers'!$I:$I,'Raw - Customers'!$A:$A,"<>Residual")*D61+SUMIFS('Raw - Customers'!$J:$J,'Raw - Customers'!$A:$A,"<>Residual")*D62+SUMIFS('Raw - Customers'!$K:$K,'Raw - Customers'!$A:$A,"<>Residual")*D63)/D47,"n.a.") -> 14336.735 | E48: =IFERROR((SUMIFS('Raw - Customers'!$I:$I,'Raw - Customers'!$A:$A,"<>Residual")*E61+SUMIFS('Raw - Customers'!$J:$J,'Raw - Customers'!$A:$A,"<>Residual")*E62+SUMIFS('Raw - Customers'!$K:$K,'Raw - Customers'!$A:$A,"<>Residual")*E63)/E47,"n.a.") -> 15609.615 | G48: =IFERROR((SUMIFS('Raw - Customers'!$I:$I,'Raw - Customers'!$A:$A,"<>Residual")*G61+SUMIFS('Raw - Customers'!$J:$J,'Raw - Customers'!$A:$A,"<>Residual")*G62+SUMIFS('Raw - Customers'!$K:$K,'Raw - Customers'!$A:$A,"<>Residual")*G63)/G47,"n.a.") -> 14336.735 | H48: =IFERROR((SUMIFS('Raw - Customers'!$I:$I,'Raw - Customers'!$A:$A,"<>Residual")*H61+SUMIFS('Raw - Customers'!$J:$J,'Raw - Customers'!$A:$A,"<>Residual")*H62+SUMIFS('Raw - Customers'!$K:$K,'Raw - Customers'!$A:$A,"<>Residual")*H63)/H47,"n.a.") -> 15609.615 | J48: =IFERROR((SUMIFS('Raw - Customers'!$I:$I,'Raw - Customers'!$A:$A,"<>Residual")*J61+SUMIFS('Raw - Customers'!$J:$J,'Raw - Customers'!$A:$A,"<>Residual")*J62+SUMIFS('Raw - Customers'!$K:$K,'Raw - Customers'!$A:$A,"<>Residual")*J63)/J47,"n.a.") -> 14336.735 | K48: =IFERROR((SUMIFS('Raw - Customers'!$I:$I,'Raw - Customers'!$A:$A,"<>Residual")*K61+SUMIFS('Raw - Customers'!$J:$J,'Raw - Customers'!$A:$A,"<>Residual")*K62+SUMIFS('Raw - Customers'!$K:$K,'Raw - Customers'!$A:$A,"<>Residual")*K63)/K47,"n.a.") -> 15609.615 | L48: =IFERROR((SUMIFS('Raw - Customers'!$I:$I,'Raw - Customers'!$A:$A,"<>Residual")*L61+SUMIFS('Raw - Customers'!$J:$J,'Raw - Customers'!$A:$A,"<>Residual")*L62+SUMIFS('Raw - Customers'!$K:$K,'Raw - Customers'!$A:$A,"<>Residual")*L63)/L47,"n.a.") -> 15609.615
B49: Employees, non-owner FTE at period end (#) | C49: =SUMIFS('Raw - Payroll'!$Q:$Q,'Raw - Payroll'!$D:$D,"<="&C$59,'Raw - Payroll'!$O:$O,"No",'Raw - Payroll'!$E:$E,"")+SUMIFS('Raw - Payroll'!$Q:$Q,'Raw - Payroll'!$D:$D,"<="&C$59,'Raw - Payroll'!$O:$O,"No",'Raw - Payroll'!$E:$E,">"&C$59) -> 21 | D49: =SUMIFS('Raw - Payroll'!$Q:$Q,'Raw - Payroll'!$D:$D,"<="&D$59,'Raw - Payroll'!$O:$O,"No",'Raw - Payroll'!$E:$E,"")+SUMIFS('Raw - Payroll'!$Q:$Q,'Raw - Payroll'!$D:$D,"<="&D$59,'Raw - Payroll'!$O:$O,"No",'Raw - Payroll'!$E:$E,">"&D$59) -> 23 | E49: =SUMIFS('Raw - Payroll'!$Q:$Q,'Raw - Payroll'!$D:$D,"<="&E$59,'Raw - Payroll'!$O:$O,"No",'Raw - Payroll'!$E:$E,"")+SUMIFS('Raw - Payroll'!$Q:$Q,'Raw - Payroll'!$D:$D,"<="&E$59,'Raw - Payroll'!$O:$O,"No",'Raw - Payroll'!$E:$E,">"&E$59) -> 23 | G49: =SUMIFS('Raw - Payroll'!$Q:$Q,'Raw - Payroll'!$D:$D,"<="&G$59,'Raw - Payroll'!$O:$O,"No",'Raw - Payroll'!$E:$E,"")+SUMIFS('Raw - Payroll'!$Q:$Q,'Raw - Payroll'!$D:$D,"<="&G$59,'Raw - Payroll'!$O:$O,"No",'Raw - Payroll'!$E:$E,">"&G$59) -> 23 | H49: =SUMIFS('Raw - Payroll'!$Q:$Q,'Raw - Payroll'!$D:$D,"<="&H$59,'Raw - Payroll'!$O:$O,"No",'Raw - Payroll'!$E:$E,"")+SUMIFS('Raw - Payroll'!$Q:$Q,'Raw - Payroll'!$D:$D,"<="&H$59,'Raw - Payroll'!$O:$O,"No",'Raw - Payroll'!$E:$E,">"&H$59) -> 23 | J49: =SUMIFS('Raw - Payroll'!$Q:$Q,'Raw - Payroll'!$D:$D,"<="&J$59,'Raw - Payroll'!$O:$O,"No",'Raw - Payroll'!$E:$E,"")+SUMIFS('Raw - Payroll'!$Q:$Q,'Raw - Payroll'!$D:$D,"<="&J$59,'Raw - Payroll'!$O:$O,"No",'Raw - Payroll'!$E:$E,">"&J$59) -> 23 | K49: =SUMIFS('Raw - Payroll'!$Q:$Q,'Raw - Payroll'!$D:$D,"<="&K$59,'Raw - Payroll'!$O:$O,"No",'Raw - Payroll'!$E:$E,"")+SUMIFS('Raw - Payroll'!$Q:$Q,'Raw - Payroll'!$D:$D,"<="&K$59,'Raw - Payroll'!$O:$O,"No",'Raw - Payroll'!$E:$E,">"&K$59) -> 23 | L49: =SUMIFS('Raw - Payroll'!$Q:$Q,'Raw - Payroll'!$D:$D,"<="&L$59,'Raw - Payroll'!$O:$O,"No",'Raw - Payroll'!$E:$E,"")+SUMIFS('Raw - Payroll'!$Q:$Q,'Raw - Payroll'!$D:$D,"<="&L$59,'Raw - Payroll'!$O:$O,"No",'Raw - Payroll'!$E:$E,">"&L$59) -> 23
B50: Revenue per employee ($) | C50: =IFERROR(C14*1000/C49,"n.a.") -> 114609.52 | D50: =IFERROR(D14*1000/D49,"n.a.") -> 118200 | E50: =IFERROR(E14*1000/E49,"n.a.") -> 132208.7 | G50: =IFERROR(G14*1000/G49,"n.a.") -> 118200 | H50: =IFERROR(H14*1000/H49,"n.a.") -> 132208.7 | J50: =IFERROR(J14*1000/J49,"n.a.") -> 118200 | K50: =IFERROR(K14*1000/K49,"n.a.") -> 132208.7 | L50: =IFERROR(L14*1000/L49,"n.a.") -> 132208.7
B51: Labor cost, % of revenue (excludes owner) | C51: =IFERROR((C22-'Adjustments'!N44)/C14,"n.a.") -> 0.29832807 | D51: =IFERROR((D22-'Adjustments'!O44)/D14,"n.a.") -> 0.29605312 | E51: =IFERROR((E22-'Adjustments'!P44)/E14,"n.a.") -> 0.29296238 | G51: =IFERROR((G22-'Adjustments'!R44)/G14,"n.a.") -> 0.29605312 | H51: =IFERROR((H22-'Adjustments'!S44)/H14,"n.a.") -> 0.29296238 | J51: =IFERROR((J22-'Adjustments'!U44)/J14,"n.a.") -> 0.29605312 | K51: =IFERROR((K22-'Adjustments'!V44)/K14,"n.a.") -> 0.29296238 | L51: =IFERROR((L22-'Adjustments'!W44)/L14,"n.a.") -> 0.29296238
B52: Recurring revenue, % of total | C52: =IFERROR((C11)/C14,"n.a.") -> 0.089164035 | D52: =IFERROR((D11)/D14,"n.a.") -> 0.091333775 | E52: =IFERROR((E11)/E14,"n.a.") -> 0.095172323 | G52: =IFERROR((G11)/G14,"n.a.") -> 0.091333775 | H52: =IFERROR((H11)/H14,"n.a.") -> 0.095172323 | J52: =IFERROR((J11)/J14,"n.a.") -> 0.091333775 | K52: =IFERROR((K11)/K14,"n.a.") -> 0.095172323 | L52: =IFERROR((L11)/L14,"n.a.") -> 0.095172323
B54: Check: Net Income less Monthly P&L | C54: =ROUND(C43-'Monthly P&L'!C43,6) -> 0 | D54: =ROUND(D43-'Monthly P&L'!D43,6) -> 0 | E54: =ROUND(E43-'Monthly P&L'!E43,6) -> 0 | G54: =ROUND(G43-'Monthly P&L'!G43,6) -> 0 | H54: =ROUND(H43-'Monthly P&L'!H43,6) -> 0 | J54: =ROUND(J43-'Monthly P&L'!J43,6) -> 0 | K54: =ROUND(K43-'Monthly P&L'!K43,6) -> 0 | L54: =ROUND(L43-'Monthly P&L'!L43,6) -> 0
...

Sheet Adj. EBITDA
B2: =Cover!B24
B3: Adjusted EBITDA and SDE ($000s) | N3: Print | O3: ='Contents'!$I$18
C5: Full Year | G5: YTD | J5: LTM | L5: PF | N5: PF vs. LTM
B6: Adj. EBITDA | C6: ="FY"&YEAR(C$59) -> FY2023 | D6: ="FY"&YEAR(D$59) -> FY2024 | E6: ="FY"&YEAR(E$59) -> FY2025 | G6: =TEXT(G$59,"mmm-yy") -> Dec-24 | H6: =TEXT(H$59,"mmm-yy") -> Dec-25 | J6: =TEXT(J$59,"mmm-yy") -> Dec-24 | K6: =TEXT(K$59,"mmm-yy") -> Dec-25 | L6: =TEXT(L$59,"mmm-yy") -> Dec-25 | N6: ($) | O6: (%)
B8: Net Income | C8: ='P&L Summary'!C43 -> 74.6 | D8: ='P&L Summary'!D43 -> 129.24 | E8: ='P&L Summary'!E43 -> 232.815 | G8: ='P&L Summary'!G43 -> 129.24 | H8: ='P&L Summary'!H43 -> 232.815 | J8: ='P&L Summary'!J43 -> 129.24 | K8: ='P&L Summary'!K43 -> 232.815 | L8: ='P&L Summary'!K43 -> 232.815 | N8: =L8-K8 -> 0 | O8: =IFERROR(L8/K8-1,"n.a.") -> 0
B9: Definitional Adjustments
B10: ="(+) Interest Expense"&IF('Adjustments'!$I8="Accepted"," "&'Adjustments'!$B8,"") -> (+) Interest Expense [D1] | C10: =SUMIFS('Adjustments'!$N:$N,'Adjustments'!$D:$D,"Definitional",'Adjustments'!$E:$E,"Interest",'Adjustments'!$I:$I,"Accepted") -> 22.4 | D10: =SUMIFS('Adjustments'!$O:$O,'Adjustments'!$D:$D,"Definitional",'Adjustments'!$E:$E,"Interest",'Adjustments'!$I:$I,"Accepted") -> 18.6 | E10: =SUMIFS('Adjustments'!$P:$P,'Adjustments'!$D:$D,"Definitional",'Adjustments'!$E:$E,"Interest",'Adjustments'!$I:$I,"Accepted") -> 14.3 | G10: =SUMIFS('Adjustments'!$R:$R,'Adjustments'!$D:$D,"Definitional",'Adjustments'!$E:$E,"Interest",'Adjustments'!$I:$I,"Accepted") -> 18.6 | H10: =SUMIFS('Adjustments'!$S:$S,'Adjustments'!$D:$D,"Definitional",'Adjustments'!$E:$E,"Interest",'Adjustments'!$I:$I,"Accepted") -> 14.3 | J10: =SUMIFS('Adjustments'!$U:$U,'Adjustments'!$D:$D,"Definitional",'Adjustments'!$E:$E,"Interest",'Adjustments'!$I:$I,"Accepted") -> 18.6 | K10: =SUMIFS('Adjustments'!$V:$V,'Adjustments'!$D:$D,"Definitional",'Adjustments'!$E:$E,"Interest",'Adjustments'!$I:$I,"Accepted") -> 14.3 | L10: =SUMIFS('Adjustments'!$W:$W,'Adjustments'!$D:$D,"Definitional",'Adjustments'!$E:$E,"Interest",'Adjustments'!$I:$I,"Accepted") -> 14.3 | N10: =L10-K10 -> 0 | O10: =IFERROR(L10/K10-1,"n.a.") -> 0
B11: ="(+) Income Taxes"&IF('Adjustments'!$I9="Accepted"," "&'Adjustments'!$B9,"") -> (+) Income Taxes [D2] | C11: =SUMIFS('Adjustments'!$N:$N,'Adjustments'!$D:$D,"Definitional",'Adjustments'!$E:$E,"Taxes",'Adjustments'!$I:$I,"Accepted") -> 0 | D11: =SUMIFS('Adjustments'!$O:$O,'Adjustments'!$D:$D,"Definitional",'Adjustments'!$E:$E,"Taxes",'Adjustments'!$I:$I,"Accepted") -> 0 | E11: =SUMIFS('Adjustments'!$P:$P,'Adjustments'!$D:$D,"Definitional",'Adjustments'!$E:$E,"Taxes",'Adjustments'!$I:$I,"Accepted") -> 0 | G11: =SUMIFS('Adjustments'!$R:$R,'Adjustments'!$D:$D,"Definitional",'Adjustments'!$E:$E,"Taxes",'Adjustments'!$I:$I,"Accepted") -> 0 | H11: =SUMIFS('Adjustments'!$S:$S,'Adjustments'!$D:$D,"Definitional",'Adjustments'!$E:$E,"Taxes",'Adjustments'!$I:$I,"Accepted") -> 0 | J11: =SUMIFS('Adjustments'!$U:$U,'Adjustments'!$D:$D,"Definitional",'Adjustments'!$E:$E,"Taxes",'Adjustments'!$I:$I,"Accepted") -> 0 | K11: =SUMIFS('Adjustments'!$V:$V,'Adjustments'!$D:$D,"Definitional",'Adjustments'!$E:$E,"Taxes",'Adjustments'!$I:$I,"Accepted") -> 0 | L11: =SUMIFS('Adjustments'!$W:$W,'Adjustments'!$D:$D,"Definitional",'Adjustments'!$E:$E,"Taxes",'Adjustments'!$I:$I,"Accepted") -> 0 | N11: =L11-K11 -> 0 | O11: =IFERROR(L11/K11-1,"n.a.") -> n.a.
B12: ="(+) Depreciation & Amortization"&IF('Adjustments'!$I10="Accepted"," "&'Adjustments'!$B10,"") -> (+) Depreciation & Amortization [D3] | C12: =SUMIFS('Adjustments'!$N:$N,'Adjustments'!$D:$D,"Definitional",'Adjustments'!$E:$E,"D&A",'Adjustments'!$I:$I,"Accepted") -> 61.2 | D12: =SUMIFS('Adjustments'!$O:$O,'Adjustments'!$D:$D,"Definitional",'Adjustments'!$E:$E,"D&A",'Adjustments'!$I:$I,"Accepted") -> 66.8 | E12: =SUMIFS('Adjustments'!$P:$P,'Adjustments'!$D:$D,"Definitional",'Adjustments'!$E:$E,"D&A",'Adjustments'!$I:$I,"Accepted") -> 72.4 | G12: =SUMIFS('Adjustments'!$R:$R,'Adjustments'!$D:$D,"Definitional",'Adjustments'!$E:$E,"D&A",'Adjustments'!$I:$I,"Accepted") -> 66.8 | H12: =SUMIFS('Adjustments'!$S:$S,'Adjustments'!$D:$D,"Definitional",'Adjustments'!$E:$E,"D&A",'Adjustments'!$I:$I,"Accepted") -> 72.4 | J12: =SUMIFS('Adjustments'!$U:$U,'Adjustments'!$D:$D,"Definitional",'Adjustments'!$E:$E,"D&A",'Adjustments'!$I:$I,"Accepted") -> 66.8 | K12: =SUMIFS('Adjustments'!$V:$V,'Adjustments'!$D:$D,"Definitional",'Adjustments'!$E:$E,"D&A",'Adjustments'!$I:$I,"Accepted") -> 72.4 | L12: =SUMIFS('Adjustments'!$W:$W,'Adjustments'!$D:$D,"Definitional",'Adjustments'!$E:$E,"D&A",'Adjustments'!$I:$I,"Accepted") -> 72.4 | N12: =L12-K12 -> 0 | O12: =IFERROR(L12/K12-1,"n.a.") -> 0
B13: Reported EBITDA | C13: =C8+C10+C11+C12 -> 158.2 | D13: =D8+D10+D11+D12 -> 214.64 | E13: =E8+E10+E11+E12 -> 319.515 | G13: =G8+G10+G11+G12 -> 214.64 | H13: =H8+H10+H11+H12 -> 319.515 | J13: =J8+J10+J11+J12 -> 214.64 | K13: =K8+K10+K11+K12 -> 319.515 | L13: =L8+L10+L11+L12 -> 319.515 | N13: =L13-K13 -> 0 | O13: =IFERROR(L13/K13-1,"n.a.") -> 0
B14: % Margin | C14: =IFERROR(C13/'P&L Summary'!C14,"n.m.") -> 0.06573043 | D14: =IFERROR(D13/'P&L Summary'!D14,"n.m.") -> 0.078952402 | E14: =IFERROR(E13/'P&L Summary'!E14,"n.m.") -> 0.10507597 | G14: =IFERROR(G13/'P&L Summary'!G14,"n.m.") -> 0.078952402 | H14: =IFERROR(H13/'P&L Summary'!H14,"n.m.") -> 0.10507597 | J14: =IFERROR(J13/'P&L Summary'!J14,"n.m.") -> 0.078952402 | K14: =IFERROR(K13/'P&L Summary'!K14,"n.m.") -> 0.10507597 | L14: =IFERROR(L13/'P&L Summary'!L14,"n.m.") -> 0.10507597
B15: Normalization Adjustments
B16: =IF(SUM('Adjustments'!$N32:$P32)<0,"(-) ","(+) ")&'Adjustments'!$C11&" "&'Adjustments'!$B11 -> (+) Owner's personal vehicle [N1] | C16: =IF('Adjustments'!$I11="Accepted",N('Adjustments'!N32),0) -> 16 | D16: =IF('Adjustments'!$I11="Accepted",N('Adjustments'!O32),0) -> 17 | E16: =IF('Adjustments'!$I11="Accepted",N('Adjustments'!P32),0) -> 18 | G16: =IF('Adjustments'!$I11="Accepted",N('Adjustments'!R32),0) -> 17 | H16: =IF('Adjustments'!$I11="Accepted",N('Adjustments'!S32),0) -> 18 | J16: =IF('Adjustments'!$I11="Accepted",N('Adjustments'!U32),0) -> 17 | K16: =IF('Adjustments'!$I11="Accepted",N('Adjustments'!V32),0) -> 18 | L16: =IF('Adjustments'!$I11="Accepted",N('Adjustments'!W32),0) -> 18 | N16: =L16-K16 -> 0 | O16: =IFERROR(L16/K16-1,"n.a.") -> 0
B17: =IF(SUM('Adjustments'!$N33:$P33)<0,"(-) ","(+) ")&'Adjustments'!$C12&" "&'Adjustments'!$B12 -> (+) Legal fees: settled customer dispute [N2] | C17: =IF('Adjustments'!$I12="Accepted",N('Adjustments'!N33),0) -> 0 | D17: =IF('Adjustments'!$I12="Accepted",N('Adjustments'!O33),0) -> 24 | E17: =IF('Adjustments'!$I12="Accepted",N('Adjustments'!P33),0) -> 0 | G17: =IF('Adjustments'!$I12="Accepted",N('Adjustments'!R33),0) -> 24 | H17: =IF('Adjustments'!$I12="Accepted",N('Adjustments'!S33),0) -> 0 | J17: =IF('Adjustments'!$I12="Accepted",N('Adjustments'!U33),0) -> 24 | K17: =IF('Adjustments'!$I12="Accepted",N('Adjustments'!V33),0) -> 0 | L17: =IF('Adjustments'!$I12="Accepted",N('Adjustments'!W33),0) -> 0 | N17: =L17-K17 -> 0 | O17: =IFERROR(L17/K17-1,"n.a.") -> n.a.
B18: =IF(SUM('Adjustments'!$N34:$P34)<0,"(-) ","(+) ")&'Adjustments'!$C13&" "&'Adjustments'!$B13 -> (+) Owner family phones and meals [N3] | C18: =IF('Adjustments'!$I13="Accepted",N('Adjustments'!N34),0) -> 0 | D18: =IF('Adjustments'!$I13="Accepted",N('Adjustments'!O34),0) -> 0 | E18: =IF('Adjustments'!$I13="Accepted",N('Adjustments'!P34),0) -> 6 | G18: =IF('Adjustments'!$I13="Accepted",N('Adjustments'!R34),0) -> 0 | H18: =IF('Adjustments'!$I13="Accepted",N('Adjustments'!S34),0) -> 6 | J18: =IF('Adjustments'!$I13="Accepted",N('Adjustments'!U34),0) -> 0 | K18: =IF('Adjustments'!$I13="Accepted",N('Adjustments'!V34),0) -> 6 | L18: =IF('Adjustments'!$I13="Accepted",N('Adjustments'!W34),0) -> 6 | N18: =L18-K18 -> 0 | O18: =IFERROR(L18/K18-1,"n.a.") -> 0
